Workbook

Sheet cover
B6: JRC-IDEES-2021 - Integrated Database of the European Energy System
C10: Hungary
C15: Energy related CO2 Emission balances
L28: Prepared by JRC C.6
L30: 45432.786
L31: v2021-1.00
B33: Legal Notice
B35: The information made available is property of the Joint Research Centre of the European Commission.
B36: Neither the European Commission nor any person acting on behalf of the Commission is responsible for the use which might be made of this information.
B38: Use conditions
B39: This work is licensed under
B40: CC BY 4.0

Sheet index
A1: Hungary | B1: HU | C1: 2000 | D1: 2001 | E1: 2002 | F1: 2003 | G1: 2004 | H1: 2005 | I1: 2006 | J1: 2007 | K1: 2008 | L1: 2009 | M1: 2010 | N1: 2011 | O1: 2012 | P1: 2013 | Q1: 2014 | R1: 2015 | S1: 2016 | T1: 2017 | U1: 2018 | V1: 2019 | W1: 2020 | X1: 2021
B2: Click on the link to jump to the sheet
A3: Total | B3: kt CO2
A4: Gross available energy | B4: =HYPERLINK("#"&CELL("address",GAE!$X$2),"GAE") -> GAE | C4: =GAE!C$2 -> 54340.998 | D4: =GAE!D$2 -> 55975.525 | E4: =GAE!E$2 -> 55142.834 | F4: =GAE!F$2 -> 57616.893 | G4: =GAE!G$2 -> 55992.429 | H4: =GAE!H$2 -> 55746.15 | I4: =GAE!I$2 -> 55327.625 | J4: =GAE!J$2 -> 53335.519 | ... X4: =GAE!X$2 -> 45482.27
A5: International maritime bunkers | B5: =HYPERLINK("#"&CELL("address",INTMARB!$X$2),"INTMARB") -> INTMARB | C5: =INTMARB!C$2 -> 0 | D5: =INTMARB!D$2 -> 0 | E5: =INTMARB!E$2 -> 0 | F5: =INTMARB!F$2 -> 0 | G5: =INTMARB!G$2 -> 0 | H5: =INTMARB!H$2 -> 0 | I5: =INTMARB!I$2 -> 0 | J5: =INTMARB!J$2 -> 0 | ... X5: =INTMARB!X$2 -> 0
A6: International Intra-EEA maritime bunkers | B6: =HYPERLINK("#"&CELL("address",INTMARB_IN!$X$2),"INTMARB_IN") -> INTMARB_IN | C6: =INTMARB_IN!C$2 -> 0 | D6: =INTMARB_IN!D$2 -> 0 | E6: =INTMARB_IN!E$2 -> 0 | F6: =INTMARB_IN!F$2 -> 0 | G6: =INTMARB_IN!G$2 -> 0 | H6: =INTMARB_IN!H$2 -> 0 | I6: =INTMARB_IN!I$2 -> 0 | J6: =INTMARB_IN!J$2 -> 0 | ... X6: =INTMARB_IN!X$2 -> 0
A7: International Extra-EEA maritime bunkers | B7: =HYPERLINK("#"&CELL("address",INTMARB_EX!$X$2),"INTMARB_EX") -> INTMARB_EX | C7: =INTMARB_EX!C$2 -> 0 | D7: =INTMARB_EX!D$2 -> 0 | E7: =INTMARB_EX!E$2 -> 0 | F7: =INTMARB_EX!F$2 -> 0 | G7: =INTMARB_EX!G$2 -> 0 | H7: =INTMARB_EX!H$2 -> 0 | I7: =INTMARB_EX!I$2 -> 0 | J7: =INTMARB_EX!J$2 -> 0 | ... X7: =INTMARB_EX!X$2 -> 0
A8: Gross inland consumption | B8: =HYPERLINK("#"&CELL("address",GIC!$X$2),"GIC") -> GIC | C8: =GIC!C$2 -> 54340.998 | D8: =GIC!D$2 -> 55975.525 | E8: =GIC!E$2 -> 55142.834 | F8: =GIC!F$2 -> 57616.893 | G8: =GIC!G$2 -> 55992.429 | H8: =GIC!H$2 -> 55746.15 | I8: =GIC!I$2 -> 55327.625 | J8: =GIC!J$2 -> 53335.519 | ... X8: =GIC!X$2 -> 45482.27
A9: International aviation | B9: =HYPERLINK("#"&CELL("address",INTAVI!$X$2),"INTAVI") -> INTAVI | C9: =INTAVI!C$2 -> 722.6609 | D9: =INTAVI!D$2 -> 678.40945 | E9: =INTAVI!E$2 -> 640.35997 | F9: =INTAVI!F$2 -> 627.67681 | G9: =INTAVI!G$2 -> 679.15958 | H9: =INTAVI!H$2 -> 784.41462 | I9: =INTAVI!I$2 -> 797.2272 | J9: =INTAVI!J$2 -> 730.79151 | ... X9: =INTAVI!X$2 -> 370.66742
A10: International Intra-EEAwUK passenger aviation | B10: =HYPERLINK("#"&CELL("address",INTAVI_PA_IN!$X$2),"INTAVI_PA_IN") -> INTAVI_PA_IN | C10: =INTAVI_PA_IN!C$2 -> 442.31748 | D10: =INTAVI_PA_IN!D$2 -> 414.13155 | E10: =INTAVI_PA_IN!E$2 -> 395.48628 | F10: =INTAVI_PA_IN!F$2 -> 372.6761 | G10: =INTAVI_PA_IN!G$2 -> 434.2753 | H10: =INTAVI_PA_IN!H$2 -> 514.82868 | I10: =INTAVI_PA_IN!I$2 -> 519.91855 | J10: =INTAVI_PA_IN!J$2 -> 478.35519 | ... X10: =INTAVI_PA_IN!X$2 -> 222.4675
A11: International Extra-EEAwUK passenger aviation | B11: =HYPERLINK("#"&CELL("address",INTAVI_PA_EX!$X$2),"INTAVI_PA_EX") -> INTAVI_PA_EX | C11: =INTAVI_PA_EX!C$2 -> 266.51612 | D11: =INTAVI_PA_EX!D$2 -> 249.53915 | E11: =INTAVI_PA_EX!E$2 -> 227.96565 | F11: =INTAVI_PA_EX!F$2 -> 241.34997 | G11: =INTAVI_PA_EX!G$2 -> 233.28623 | H11: =INTAVI_PA_EX!H$2 -> 255.16675 | I11: =INTAVI_PA_EX!I$2 -> 259.86131 | J11: =INTAVI_PA_EX!J$2 -> 239.29258 | ... X11: =INTAVI_PA_EX!X$2 -> 125.56453
A12: International Intra-EEAwUK freight aviation | B12: =HYPERLINK("#"&CELL("address",INTAVI_FR_IN!$X$2),"INTAVI_FR_IN") -> INTAVI_FR_IN | C12: =INTAVI_FR_IN!C$2 -> 9.988578 | D12: =INTAVI_FR_IN!D$2 -> 11.184268 | E12: =INTAVI_FR_IN!E$2 -> 15.133667 | F12: =INTAVI_FR_IN!F$2 -> 11.885761 | G12: =INTAVI_FR_IN!G$2 -> 10.436293 | H12: =INTAVI_FR_IN!H$2 -> 12.884722 | I12: =INTAVI_FR_IN!I$2 -> 9.6839496 | J12: =INTAVI_FR_IN!J$2 -> 10.486611 | ... X12: =INTAVI_FR_IN!X$2 -> 16.690517
A13: International Extra-EEAwUK freight aviation | B13: =HYPERLINK("#"&CELL("address",INTAVI_FR_EX!$X$2),"INTAVI_FR_EX") -> INTAVI_FR_EX | C13: =INTAVI_FR_EX!C$2 -> 3.8387179 | D13: =INTAVI_FR_EX!D$2 -> 3.5544862 | E13: =INTAVI_FR_EX!E$2 -> 1.7743786 | F13: =INTAVI_FR_EX!F$2 -> 1.764976 | G13: =INTAVI_FR_EX!G$2 -> 1.1617601 | H13: =INTAVI_FR_EX!H$2 -> 1.5344689 | I13: =INTAVI_FR_EX!I$2 -> 7.7633851 | J13: =INTAVI_FR_EX!J$2 -> 2.6571279 | ... X13: =INTAVI_FR_EX!X$2 -> 5.9448789
A14: Total energy supply | B14: =HYPERLINK("#"&CELL("address",NRGSUP!$X$2),"NRGSUP") -> NRGSUP | C14: =NRGSUP!C$2 -> 53618.338 | D14: =NRGSUP!D$2 -> 55297.116 | E14: =NRGSUP!E$2 -> 54502.474 | F14: =NRGSUP!F$2 -> 56989.217 | G14: =NRGSUP!G$2 -> 55313.27 | H14: =NRGSUP!H$2 -> 54961.735 | I14: =NRGSUP!I$2 -> 54530.398 | J14: =NRGSUP!J$2 -> 52604.727 | ... X14: =NRGSUP!X$2 -> 45111.603
A15: Electricity & heat generation | B15: =HYPERLINK("#"&CELL("address",TI_EHG_E!$X$2),"TI_EHG_E") -> TI_EHG_E | C15: =TI_EHG_E!C$2 -> 22372.094 | D15: =TI_EHG_E!D$2 -> 22748.189 | E15: =TI_EHG_E!E$2 -> 21423.159 | F15: =TI_EHG_E!F$2 -> 22472.533 | G15: =TI_EHG_E!G$2 -> 20623.529 | H15: =TI_EHG_E!H$2 -> 18733.593 | I15: =TI_EHG_E!I$2 -> 18710.447 | J15: =TI_EHG_E!J$2 -> 19871.664 | ... X15: =TI_EHG_E!X$2 -> 10155.844
A16: Electricity only | B16: =HYPERLINK("#"&CELL("address",TI_EHG_E_E!$X$2),"TI_EHG_E_E") -> TI_EHG_E_E | C16: =TI_EHG_E_E!C$2 -> 14282.222 | D16: =TI_EHG_E_E!D$2 -> 14681.068 | E16: =TI_EHG_E_E!E$2 -> 13638.218 | F16: =TI_EHG_E_E!F$2 -> 14051.081 | G16: =TI_EHG_E_E!G$2 -> 12760.281 | H16: =TI_EHG_E_E!H$2 -> 10676.122 | I16: =TI_EHG_E_E!I$2 -> 10755.689 | J16: =TI_EHG_E_E!J$2 -> 11997.897 | ... X16: =TI_EHG_E_E!X$2 -> 5010.0846
A17: CHP | B17: =HYPERLINK("#"&CELL("address",TI_EHG_CHP_E!$X$2),"TI_EHG_CHP_E") -> TI_EHG_CHP_E | C17: =TI_EHG_CHP_E!C$2 -> 6984.6306 | D17: =TI_EHG_CHP_E!D$2 -> 6673.5099 | E17: =TI_EHG_CHP_E!E$2 -> 6390.8181 | F17: =TI_EHG_CHP_E!F$2 -> 6697.0251 | G17: =TI_EHG_CHP_E!G$2 -> 6057.3382 | H17: =TI_EHG_CHP_E!H$2 -> 6126.701 | I17: =TI_EHG_CHP_E!I$2 -> 6105.0234 | J17: =TI_EHG_CHP_E!J$2 -> 6087.822 | ... X17: =TI_EHG_CHP_E!X$2 -> 3523.0966
A18: Heat only | B18: =HYPERLINK("#"&CELL("address",TI_EHG_H_E!$X$2),"TI_EHG_H_E") -> TI_EHG_H_E | C18: =TI_EHG_H_E!C$2 -> 1105.242 | D18: =TI_EHG_H_E!D$2 -> 1393.6109 | E18: =TI_EHG_H_E!E$2 -> 1394.1233 | F18: =TI_EHG_H_E!F$2 -> 1724.4272 | G18: =TI_EHG_H_E!G$2 -> 1805.9096 | H18: =TI_EHG_H_E!H$2 -> 1930.7702 | I18: =TI_EHG_H_E!I$2 -> 1849.7349 | J18: =TI_EHG_H_E!J$2 -> 1785.9448 | ... X18: =TI_EHG_H_E!X$2 -> 1622.6624
A19: Energy sector | B19: =HYPERLINK("#"&CELL("address",NRG_E!$X$2),"NRG_E") -> NRG_E | C19: =NRG_E!C$2 -> 1757.9198 | D19: =NRG_E!D$2 -> 1596.3673 | E19: =NRG_E!E$2 -> 1462.9697 | F19: =NRG_E!F$2 -> 1279.2391 | G19: =NRG_E!G$2 -> 1229.6728 | H19: =NRG_E!H$2 -> 1214.7252 | I19: =NRG_E!I$2 -> 1671.2316 | J19: =NRG_E!J$2 -> 1331.6067 | ... X19: =NRG_E!X$2 -> 1931.8021
A20: Coal mines | B20: =HYPERLINK("#"&CELL("address",NRG_CM_E!$X$2),"NRG_CM_E") -> NRG_CM_E | C20: =NRG_CM_E!C$2 -> 0 | D20: =NRG_CM_E!D$2 -> 0 | E20: =NRG_CM_E!E$2 -> 0 | F20: =NRG_CM_E!F$2 -> 2.5923607 | G20: =NRG_CM_E!G$2 -> 8.8582364 | H20: =NRG_CM_E!H$2 -> 6.3582886 | I20: =NRG_CM_E!I$2 -> 6.4308398 | J20: =NRG_CM_E!J$2 -> 6.4364282 | ... X20: =NRG_CM_E!X$2 -> 0
A21: Oil & natural gas extraction plants | B21: =HYPERLINK("#"&CELL("address",NRG_OIL_NG_E!$X$2),"NRG_OIL_NG_E") -> NRG_OIL_NG_E | C21: =NRG_OIL_NG_E!C$2 -> 165.3735 | D21: =NRG_OIL_NG_E!D$2 -> 174.64449 | E21: =NRG_OIL_NG_E!E$2 -> 0 | F21: =NRG_OIL_NG_E!F$2 -> 0 | G21: =NRG_OIL_NG_E!G$2 -> 9.443929 | H21: =NRG_OIL_NG_E!H$2 -> 3.1861814 | I21: =NRG_OIL_NG_E!I$2 -> 6.1278214 | J21: =NRG_OIL_NG_E!J$2 -> 0 | ... X21: =NRG_OIL_NG_E!X$2 -> 89.26632
A22: Patent fuel plants | B22: =HYPERLINK("#"&CELL("address",NRG_PF_E!$X$2),"NRG_PF_E") -> NRG_PF_E | C22: =NRG_PF_E!C$2 -> 0 | D22: =NRG_PF_E!D$2 -> 0 | E22: =NRG_PF_E!E$2 -> 3.9929366 | F22: =NRG_PF_E!F$2 -> 0 | G22: =NRG_PF_E!G$2 -> 0 | H22: =NRG_PF_E!H$2 -> 0 | I22: =NRG_PF_E!I$2 -> 0 | J22: =NRG_PF_E!J$2 -> 0 | ... X22: =NRG_PF_E!X$2 -> 0
A23: Coke ovens | B23: =HYPERLINK("#"&CELL("address",NRG_CO_E!$X$2),"NRG_CO_E") -> NRG_CO_E | C23: =NRG_CO_E!C$2 -> 151.32852 | D23: =NRG_CO_E!D$2 -> 109.25064 | E23: =NRG_CO_E!E$2 -> 77.80212 | F23: =NRG_CO_E!F$2 -> 88.15176 | G23: =NRG_CO_E!G$2 -> 71.5284 | H23: =NRG_CO_E!H$2 -> 73.08684 | I23: =NRG_CO_E!I$2 -> 149.29056 | J23: =NRG_CO_E!J$2 -> 164.19564 | ... X23: =NRG_CO_E!X$2 -> 112.44744
A24: BKB & PB plants | B24: =HYPERLINK("#"&CELL("address",NRG_BKBPB_E!$X$2),"NRG_BKBPB_E") -> NRG_BKBPB_E | C24: =NRG_BKBPB_E!C$2 -> 0 | D24: =NRG_BKBPB_E!D$2 -> 0 | E24: =NRG_BKBPB_E!E$2 -> 0 | F24: =NRG_BKBPB_E!F$2 -> 0 | G24: =NRG_BKBPB_E!G$2 -> 0 | H24: =NRG_BKBPB_E!H$2 -> 0 | I24: =NRG_BKBPB_E!I$2 -> 0 | J24: =NRG_BKBPB_E!J$2 -> 0 | ... X24: =NRG_BKBPB_E!X$2 -> 0
A25: Gas works | B25: =HYPERLINK("#"&CELL("address",NRG_GW_E!$X$2),"NRG_GW_E") -> NRG_GW_E | C25: =NRG_GW_E!C$2 -> 0 | D25: =NRG_GW_E!D$2 -> 0 | E25: =NRG_GW_E!E$2 -> 0 | F25: =NRG_GW_E!F$2 -> 0 | G25: =NRG_GW_E!G$2 -> 0 | H25: =NRG_GW_E!H$2 -> 0 | I25: =NRG_GW_E!I$2 -> 0 | J25: =NRG_GW_E!J$2 -> 0 | ... X25: =NRG_GW_E!X$2 -> 0
A26: Blast furnaces | B26: =HYPERLINK("#"&CELL("address",NRG_BF_E!$X$2),"NRG_BF_E") -> NRG_BF_E | C26: =NRG_BF_E!C$2 -> 0 | D26: =NRG_BF_E!D$2 -> 0 | E26: =NRG_BF_E!E$2 -> 0 | F26: =NRG_BF_E!F$2 -> 0 | G26: =NRG_BF_E!G$2 -> 0 | H26: =NRG_BF_E!H$2 -> 0 | I26: =NRG_BF_E!I$2 -> 0 | J26: =NRG_BF_E!J$2 -> 0 | ... X26: =NRG_BF_E!X$2 -> 360.45904
A27: Petroleum refineries (oil refineries) | B27: =HYPERLINK("#"&CELL("address",NRG_PR_E!$X$2),"NRG_PR_E") -> NRG_PR_E | C27: =NRG_PR_E!C$2 -> 1441.2177 | D27: =NRG_PR_E!D$2 -> 1312.4722 | E27: =NRG_PR_E!E$2 -> 1381.1746 | F27: =NRG_PR_E!F$2 -> 1188.495 | G27: =NRG_PR_E!G$2 -> 1139.8422 | H27: =NRG_PR_E!H$2 -> 1132.0939 | I27: =NRG_PR_E!I$2 -> 1509.3824 | J27: =NRG_PR_E!J$2 -> 1160.9746 | ... X27: =NRG_PR_E!X$2 -> 1369.6293
A28: Nuclear industry | B28: =HYPERLINK("#"&CELL("address",NRG_NI_E!$X$2),"NRG_NI_E") -> NRG_NI_E | C28: =NRG_NI_E!C$2 -> 0 | D28: =NRG_NI_E!D$2 -> 0 | E28: =NRG_NI_E!E$2 -> 0 | F28: =NRG_NI_E!F$2 -> 0 | G28: =NRG_NI_E!G$2 -> 0 | H28: =NRG_NI_E!H$2 -> 0 | I28: =NRG_NI_E!I$2 -> 0 | J28: =NRG_NI_E!J$2 -> 0 | ... X28: =NRG_NI_E!X$2 -> 0
A29: Coal liquefaction plants | B29: =HYPERLINK("#"&CELL("address",NRG_CL_E!$X$2),"NRG_CL_E") -> NRG_CL_E | C29: =NRG_CL_E!C$2 -> 0 | D29: =NRG_CL_E!D$2 -> 0 | E29: =NRG_CL_E!E$2 -> 0 | F29: =NRG_CL_E!F$2 -> 0 | G29: =NRG_CL_E!G$2 -> 0 | H29: =NRG_CL_E!H$2 -> 0 | I29: =NRG_CL_E!I$2 -> 0 | J29: =NRG_CL_E!J$2 -> 0 | ... X29: =NRG_CL_E!X$2 -> 0
A30: Liquefaction & regasification plants (LNG) | B30: =HYPERLINK("#"&CELL("address",NRG_LNG_E!$X$2),"NRG_LNG_E") -> NRG_LNG_E | C30: =NRG_LNG_E!C$2 -> 0 | D30: =NRG_LNG_E!D$2 -> 0 | E30: =NRG_LNG_E!E$2 -> 0 | F30: =NRG_LNG_E!F$2 -> 0 | G30: =NRG_LNG_E!G$2 -> 0 | H30: =NRG_LNG_E!H$2 -> 0 | I30: =NRG_LNG_E!I$2 -> 0 | J30: =NRG_LNG_E!J$2 -> 0 | ... X30: =NRG_LNG_E!X$2 -> 0
A31: Gasification plants for biogas | B31: =HYPERLINK("#"&CELL("address",NRG_BIOG_E!$X$2),"NRG_BIOG_E") -> NRG_BIOG_E | C31: =NRG_BIOG_E!C$2 -> 0 | D31: =NRG_BIOG_E!D$2 -> 0 | E31: =NRG_BIOG_E!E$2 -> 0 | F31: =NRG_BIOG_E!F$2 -> 0 | G31: =NRG_BIOG_E!G$2 -> 0 | H31: =NRG_BIOG_E!H$2 -> 0 | I31: =NRG_BIOG_E!I$2 -> 0 | J31: =NRG_BIOG_E!J$2 -> 0 | ... X31: =NRG_BIOG_E!X$2 -> 0
A32: Gas-to-liquids (GTL) plants | B32: =HYPERLINK("#"&CELL("address",NRG_GTL_E!$X$2),"NRG_GTL_E") -> NRG_GTL_E | C32: =NRG_GTL_E!C$2 -> 0 | D32: =NRG_GTL_E!D$2 -> 0 | E32: =NRG_GTL_E!E$2 -> 0 | F32: =NRG_GTL_E!F$2 -> 0 | G32: =NRG_GTL_E!G$2 -> 0 | H32: =NRG_GTL_E!H$2 -> 0 | I32: =NRG_GTL_E!I$2 -> 0 | J32: =NRG_GTL_E!J$2 -> 0 | ... X32: =NRG_GTL_E!X$2 -> 0
A33: Charcoal production plants | B33: =HYPERLINK("#"&CELL("address",NRG_CPP_E!$X$2),"NRG_CPP_E") -> NRG_CPP_E | C33: =NRG_CPP_E!C$2 -> 0 | D33: =NRG_CPP_E!D$2 -> 0 | E33: =NRG_CPP_E!E$2 -> 0 | F33: =NRG_CPP_E!F$2 -> 0 | G33: =NRG_CPP_E!G$2 -> 0 | H33: =NRG_CPP_E!H$2 -> 0 | I33: =NRG_CPP_E!I$2 -> 0 | J33: =NRG_CPP_E!J$2 -> 0 | ... X33: =NRG_CPP_E!X$2 -> 0
A34: Not elsewhere specified (energy) | B34: =HYPERLINK("#"&CELL("address",NRG_NSP_E!$X$2),"NRG_NSP_E") -> NRG_NSP_E | C34: =NRG_NSP_E!C$2 -> 0 | D34: =NRG_NSP_E!D$2 -> 0 | E34: =NRG_NSP_E!E$2 -> 0 | F34: =NRG_NSP_E!F$2 -> 0 | G34: =NRG_NSP_E!G$2 -> 0 | H34: =NRG_NSP_E!H$2 -> 0 | I34: =NRG_NSP_E!I$2 -> 0 | J34: =NRG_NSP_E!J$2 -> 0 | ... X34: =NRG_NSP_E!X$2 -> 0
A35: Final energy consumption | B35: =HYPERLINK("#"&CELL("address",FC_E!$X$2),"FC_E") -> FC_E | C35: =FC_E!C$2 -> 29488.323 | D35: =FC_E!D$2 -> 30952.559 | E35: =FC_E!E$2 -> 31616.345 | F35: =FC_E!F$2 -> 33237.444 | G35: =FC_E!G$2 -> 33460.068 | H35: =FC_E!H$2 -> 35013.417 | I35: =FC_E!I$2 -> 34148.719 | J35: =FC_E!J$2 -> 31401.456 | ... X35: =FC_E!X$2 -> 33023.957
A36: Industry sector | B36: =HYPERLINK("#"&CELL("address",FC_IND_E!$X$2),"FC_IND_E") -> FC_IND_E | C36: =FC_IND_E!C$2 -> 5650.0074 | D36: =FC_IND_E!D$2 -> 5897.9993 | E36: =FC_IND_E!E$2 -> 5952.8707 | F36: =FC_IND_E!F$2 -> 5807.8116 | G36: =FC_IND_E!G$2 -> 5606.9162 | H36: =FC_IND_E!H$2 -> 5697.8534 | I36: =FC_IND_E!I$2 -> 5542.0513 | J36: =FC_IND_E!J$2 -> 5429.6425 | ... X36: =FC_IND_E!X$2 -> 6763.3963
A37: Iron & steel | B37: =HYPERLINK("#"&CELL("address",FC_IND_IS_E!$X$2),"FC_IND_IS_E") -> FC_IND_IS_E | C37: =FC_IND_IS_E!C$2 -> 1682.9101 | D37: =FC_IND_IS_E!D$2 -> 1483.2022 | E37: =FC_IND_IS_E!E$2 -> 1521.8449 | F37: =FC_IND_IS_E!F$2 -> 1493.5207 | G37: =FC_IND_IS_E!G$2 -> 1464.9732 | H37: =FC_IND_IS_E!H$2 -> 1397.6786 | I37: =FC_IND_IS_E!I$2 -> 1409.3991 | J37: =FC_IND_IS_E!J$2 -> 1367.6563 | ... X37: =FC_IND_IS_E!X$2 -> 270.81391
A38: Iron & steel - Integrated steelworks | B38: =HYPERLINK("#"&CELL("address",FC_IND_IS_BF_E!$X$2),"FC_IND_IS_BF_E") -> FC_IND_IS_BF_E | C38: =FC_IND_IS_BF_E!C$2 -> 1628.1958 | D38: =FC_IND_IS_BF_E!D$2 -> 1383.6973 | E38: =FC_IND_IS_BF_E!E$2 -> 1440.7127 | F38: =FC_IND_IS_BF_E!F$2 -> 1422.5957 | G38: =FC_IND_IS_BF_E!G$2 -> 1405.8214 | H38: =FC_IND_IS_BF_E!H$2 -> 1339.0715 | I38: =FC_IND_IS_BF_E!I$2 -> 1328.4274 | J38: =FC_IND_IS_BF_E!J$2 -> 1277.299 | ... X38: =FC_IND_IS_BF_E!X$2 -> 254.96231
A39: Iron & steel - Electric arc | B39: =HYPERLINK("#"&CELL("address",FC_IND_IS_EA_E!$X$2),"FC_IND_IS_EA_E") -> FC_IND_IS_EA_E | C39: =FC_IND_IS_EA_E!C$2 -> 54.714312 | D39: =FC_IND_IS_EA_E!D$2 -> 99.504849 | E39: =FC_IND_IS_EA_E!E$2 -> 81.132221 | F39: =FC_IND_IS_EA_E!F$2 -> 70.924982 | G39: =FC_IND_IS_EA_E!G$2 -> 59.151833 | H39: =FC_IND_IS_EA_E!H$2 -> 58.60711 | I39: =FC_IND_IS_EA_E!I$2 -> 80.971728 | J39: =FC_IND_IS_EA_E!J$2 -> 90.357271 | ... X39: =FC_IND_IS_EA_E!X$2 -> 15.851597
A40: Non-ferrous metals | B40: =HYPERLINK("#"&CELL("address",FC_IND_NFM_E!$X$2),"FC_IND_NFM_E") -> FC_IND_NFM_E | C40: =FC_IND_NFM_E!C$2 -> 251.71895 | D40: =FC_IND_NFM_E!D$2 -> 279.56496 | E40: =FC_IND_NFM_E!E$2 -> 284.63413 | F40: =FC_IND_NFM_E!F$2 -> 276.82086 | G40: =FC_IND_NFM_E!G$2 -> 273.06632 | H40: =FC_IND_NFM_E!H$2 -> 234.07164 | I40: =FC_IND_NFM_E!I$2 -> 244.73592 | J40: =FC_IND_NFM_E!J$2 -> 222.44085 | ... X40: =FC_IND_NFM_E!X$2 -> 164.49453
...

Sheet ef
A1: CO2 emission factors (t CO2 / toe) | B1: ef | C1: 2000 | D1: 2001 | E1: 2002 | F1: 2003 | G1: 2004 | H1: 2005 | I1: 2006 | J1: 2007 | K1: 2008 | L1: 2009 | M1: 2010 | N1: 2011 | O1: 2012 | P1: 2013 | Q1: 2014 | R1: 2015 | S1: 2016 | T1: 2017 | U1: 2018 | V1: 2019 | W1: 2020 | X1: 2021
A2: Total | B2: TOTAL
A3: Solid fossil fuels | B3: C0000X0350-0370
A4: Hard coal | B4: C0100
A5: Anthracite | B5: C0110 | C5: 4.1142288 | D5: 4.1142288 | E5: 4.1142288 | F5: 4.1142288 | G5: 4.1142288 | H5: 4.1142288 | I5: 4.1142288 | J5: 4.1142288 | K5: 4.1142288 | L5: 4.1142288 | M5: 4.1142288 | N5: 4.1142288 | O5: 4.1142288 | P5: 4.1142288 | Q5: 4.1142288 | R5: 4.1142288 | S5: 4.1142288 | T5: 4.1142288 | U5: 4.1142288 | V5: 4.1142288 | W5: 4.1142288 | X5: 4.1142288
A6: Coking coal | B6: C0121 | C6: 3.9607128 | D6: 3.9607128 | E6: 3.9607128 | F6: 3.9607128 | G6: 3.9607128 | H6: 3.9607128 | I6: 3.9607128 | J6: 3.9607128 | K6: 3.9607128 | L6: 3.9607128 | M6: 3.9607128 | N6: 3.9607128 | O6: 3.9607128 | P6: 3.9607128 | Q6: 3.9607128 | R6: 3.9607128 | S6: 3.9607128 | T6: 3.9607128 | U6: 3.9607128 | V6: 3.9607128 | W6: 3.9607128 | X6: 3.9607128
A7: Other bituminous coal | B7: C0129 | C7: 3.9607128 | D7: 3.9607128 | E7: 3.9607128 | F7: 3.9607128 | G7: 3.9607128 | H7: 3.9607128 | I7: 3.9607128 | J7: 3.9607128 | K7: 3.9607128 | L7: 3.9607128 | M7: 3.9607128 | N7: 3.9607128 | O7: 3.9607128 | P7: 3.9607128 | Q7: 3.9607128 | R7: 3.9607128 | S7: 3.9607128 | T7: 3.9607128 | U7: 3.9607128 | V7: 3.9607128 | W7: 3.9607128 | X7: 3.9607128
A8: Brown coal | B8: C0200
A9: Sub-bituminous coal | B9: C0210 | C9: 4.0221192 | D9: 4.0221192 | E9: 4.0221192 | F9: 4.0221192 | G9: 4.0221192 | H9: 4.0221192 | I9: 4.0221192 | J9: 4.0221192 | K9: 4.0221192 | L9: 4.0221192 | M9: 4.0221192 | N9: 4.0221192 | O9: 4.0221192 | P9: 4.0221192 | Q9: 4.0221192 | R9: 4.0221192 | S9: 4.0221192 | T9: 4.0221192 | U9: 4.0221192 | V9: 4.0221192 | W9: 4.0221192 | X9: 4.0221192
A10: Lignite | B10: C0220 | C10: 4.2689001 | D10: 4.2843846 | E10: 4.2858627 | F10: 4.3268018 | G10: 4.3947312 | H10: 4.4449926 | I10: 4.4613855 | J10: 4.4557374 | K10: 4.4431554 | L10: 4.498357 | M10: 4.5175705 | N10: 4.4997515 | O10: 4.5147149 | P10: 4.5188637 | Q10: 4.5266786 | R10: 4.5236236 | S10: 4.550136 | T10: 4.5165964 | U10: 4.4946052 | V10: 4.4652111 | W10: 4.4322586 | X10: 4.4233971
A11: Coal products | B11: C0300
A12: Patent fuel | B12: C0320 | C12: 4.0835256 | D12: 4.0835256 | E12: 4.0835256 | F12: 4.0835256 | G12: 4.0835256 | H12: 4.0835256 | I12: 4.0835256 | J12: 4.0835256 | K12: 4.0835256 | L12: 4.0835256 | M12: 4.0835256 | N12: 4.0835256 | O12: 4.0835256 | P12: 4.0835256 | Q12: 4.0835256 | R12: 4.0835256 | S12: 4.0835256 | T12: 4.0835256 | U12: 4.0835256 | V12: 4.0835256 | W12: 4.0835256 | X12: 4.0835256
A13: Coke oven coke | B13: C0311 | C13: 4.4826672 | D13: 4.4826672 | E13: 4.4826672 | F13: 4.4826672 | G13: 4.4826672 | H13: 4.4826672 | I13: 4.4826672 | J13: 4.4826672 | K13: 4.4826672 | L13: 4.4826672 | M13: 4.4826672 | N13: 4.4826672 | O13: 4.4826672 | P13: 4.4826672 | Q13: 4.4826672 | R13: 4.4826672 | S13: 4.4826672 | T13: 4.4826672 | U13: 4.4826672 | V13: 4.4826672 | W13: 4.4826672 | X13: 4.4826672
A14: Gas coke | B14: C0312 | C14: 4.4826672 | D14: 4.4826672 | E14: 4.4826672 | F14: 4.4826672 | G14: 4.4826672 | H14: 4.4826672 | I14: 4.4826672 | J14: 4.4826672 | K14: 4.4826672 | L14: 4.4826672 | M14: 4.4826672 | N14: 4.4826672 | O14: 4.4826672 | P14: 4.4826672 | Q14: 4.4826672 | R14: 4.4826672 | S14: 4.4826672 | T14: 4.4826672 | U14: 4.4826672 | V14: 4.4826672 | W14: 4.4826672 | X14: 4.4826672
A15: Coal tar | B15: C0340 | C15: 3.377352 | D15: 3.377352 | E15: 3.377352 | F15: 3.377352 | G15: 3.377352 | H15: 3.377352 | I15: 3.377352 | J15: 3.377352 | K15: 3.377352 | L15: 3.377352 | M15: 3.377352 | N15: 3.377352 | O15: 3.377352 | P15: 3.377352 | Q15: 3.377352 | R15: 3.377352 | S15: 3.377352 | T15: 3.377352 | U15: 3.377352 | V15: 3.377352 | W15: 3.377352 | X15: 3.377352
A16: Brown coal briquettes | B16: C0330 | C16: 4.0835256 | D16: 4.0835256 | E16: 4.0835256 | F16: 4.0835256 | G16: 4.0835256 | H16: 4.0835256 | I16: 4.0835256 | J16: 4.0835256 | K16: 4.0835256 | L16: 4.0835256 | M16: 4.0835256 | N16: 4.0835256 | O16: 4.0835256 | P16: 4.0835256 | Q16: 4.0835256 | R16: 4.0835256 | S16: 4.0835256 | T16: 4.0835256 | U16: 4.0835256 | V16: 4.0835256 | W16: 4.0835256 | X16: 4.0835256
A17: Manufactured gases | B17: C0350-0370
A18: Gas works gas | B18: C0360 | C18: 1.8589392 | D18: 1.8589392 | E18: 1.8589392 | F18: 1.8589392 | G18: 1.8589392 | H18: 1.8589392 | I18: 1.8589392 | J18: 1.8589392 | K18: 1.8589392 | L18: 1.8589392 | M18: 1.8589392 | N18: 1.8589392 | O18: 1.8589392 | P18: 1.8589392 | Q18: 1.8589392 | R18: 1.8589392 | S18: 1.8589392 | T18: 1.8589392 | U18: 1.8589392 | V18: 1.8589392 | W18: 1.8589392 | X18: 1.8589392
A19: Coke oven gas | B19: C0350 | C19: 1.8589392 | D19: 1.8589392 | E19: 1.8589392 | F19: 1.8589392 | G19: 1.8589392 | H19: 1.8589392 | I19: 1.8589392 | J19: 1.8589392 | K19: 1.8589392 | L19: 1.8589392 | M19: 1.8589392 | N19: 1.8589392 | O19: 1.8589392 | P19: 1.8589392 | Q19: 1.8589392 | R19: 1.8589392 | S19: 1.8589392 | T19: 1.8589392 | U19: 1.8589392 | V19: 1.8589392 | W19: 1.8589392 | X19: 1.8589392
A20: Blast furnace gas | B20: C0371 | C20: 10.88568 | D20: 10.88568 | E20: 10.88568 | F20: 10.88568 | G20: 10.88568 | H20: 10.88568 | I20: 10.88568 | J20: 10.88568 | K20: 10.88568 | L20: 10.88568 | M20: 10.88568 | N20: 10.88568 | O20: 10.88568 | P20: 10.88568 | Q20: 10.88568 | R20: 10.88568 | S20: 10.88568 | T20: 10.88568 | U20: 10.88568 | V20: 10.88568 | W20: 10.88568 | X20: 10.88568
A21: Other recovered gases | B21: C0379 | C21: 7.619976 | D21: 7.619976 | E21: 7.619976 | F21: 7.619976 | G21: 7.619976 | H21: 7.619976 | I21: 7.619976 | J21: 7.619976 | K21: 7.619976 | L21: 7.619976 | M21: 7.619976 | N21: 7.619976 | O21: 7.619976 | P21: 7.619976 | Q21: 7.619976 | R21: 7.619976 | S21: 7.619976 | T21: 7.619976 | U21: 7.619976 | V21: 7.619976 | W21: 7.619976 | X21: 7.619976
A22: Peat and peat products | B22: P1000
A23: Peat | B23: P1100 | C23: 4.4366124 | D23: 4.4366124 | E23: 4.4366124 | F23: 4.4366124 | G23: 4.4366124 | H23: 4.4366124 | I23: 4.4366124 | J23: 4.4366124 | K23: 4.4366124 | L23: 4.4366124 | M23: 4.4366124 | N23: 4.4366124 | O23: 4.4366124 | P23: 4.4366124 | Q23: 4.4366124 | R23: 4.4366124 | S23: 4.4366124 | T23: 4.4366124 | U23: 4.4366124 | V23: 4.4366124 | W23: 4.4366124 | X23: 4.4366124
A24: Peat products | B24: P1200 | C24: 4.4366124 | D24: 4.4366124 | E24: 4.4366124 | F24: 4.4366124 | G24: 4.4366124 | H24: 4.4366124 | I24: 4.4366124 | J24: 4.4366124 | K24: 4.4366124 | L24: 4.4366124 | M24: 4.4366124 | N24: 4.4366124 | O24: 4.4366124 | P24: 4.4366124 | Q24: 4.4366124 | R24: 4.4366124 | S24: 4.4366124 | T24: 4.4366124 | U24: 4.4366124 | V24: 4.4366124 | W24: 4.4366124 | X24: 4.4366124
A25: Oil shale and oil sands | B25: S2000 | C25: 4.4673156 | D25: 4.4673156 | E25: 4.4673156 | F25: 4.4673156 | G25: 4.4673156 | H25: 4.4673156 | I25: 4.4673156 | J25: 4.4673156 | K25: 4.4673156 | L25: 4.4673156 | M25: 4.4673156 | N25: 4.4673156 | O25: 4.4673156 | P25: 4.4673156 | Q25: 4.4673156 | R25: 4.4673156 | S25: 4.4673156 | T25: 4.4673156 | U25: 4.4673156 | V25: 4.4673156 | W25: 4.4673156 | X25: 4.4673156
A26: Oil and petroleum products | B26: O4000XBIO
A27: Crude oil, NGL, refinery feedstocks, additives and oxygenates and other hydrocarbons (excluding biofuel portion) | B27: O4100_TOT_4200-4500XBIO
A28: Crude oil | B28: O4100_TOT | C28: 3.0689244 | D28: 3.0689244 | E28: 3.0689244 | F28: 3.0689244 | G28: 3.0689244 | H28: 3.0689244 | I28: 3.0689244 | J28: 3.0689244 | K28: 3.0689244 | L28: 3.0689244 | M28: 3.0689244 | N28: 3.0689244 | O28: 3.0689244 | P28: 3.0689244 | Q28: 3.0689244 | R28: 3.0689244 | S28: 3.0689244 | T28: 3.0689244 | U28: 3.0689244 | V28: 3.0689244 | W28: 3.0689244 | X28: 3.0689244
A29: Natural gas liquids | B29: O4200 | C29: 2.6879256 | D29: 2.6879256 | E29: 2.6879256 | F29: 2.6879256 | G29: 2.6879256 | H29: 2.6879256 | I29: 2.6879256 | J29: 2.6879256 | K29: 2.6879256 | L29: 2.6879256 | M29: 2.6879256 | N29: 2.6879256 | O29: 2.6879256 | P29: 2.6879256 | Q29: 2.6879256 | R29: 2.6879256 | S29: 2.6879256 | T29: 2.6879256 | U29: 2.6879256 | V29: 2.6879256 | W29: 2.6879256 | X29: 2.6879256
A30: Refinery feedstocks | B30: O4300 | C30: 3.0689244 | D30: 3.0689244 | E30: 3.0689244 | F30: 3.0689244 | G30: 3.0689244 | H30: 3.0689244 | I30: 3.0689244 | J30: 3.0689244 | K30: 3.0689244 | L30: 3.0689244 | M30: 3.0689244 | N30: 3.0689244 | O30: 3.0689244 | P30: 3.0689244 | Q30: 3.0689244 | R30: 3.0689244 | S30: 3.0689244 | T30: 3.0689244 | U30: 3.0689244 | V30: 3.0689244 | W30: 3.0689244 | X30: 3.0689244
A31: Additives and oxygenates (excluding biofuel portion) | B31: O4400X4410 | C31: 3.0689244 | D31: 3.0689244 | E31: 3.0689244 | F31: 3.0689244 | G31: 3.0689244 | H31: 3.0689244 | I31: 3.0689244 | J31: 3.0689244 | K31: 3.0689244 | L31: 3.0689244 | M31: 3.0689244 | N31: 3.0689244 | O31: 3.0689244 | P31: 3.0689244 | Q31: 3.0689244 | R31: 3.0689244 | S31: 3.0689244 | T31: 3.0689244 | U31: 3.0689244 | V31: 3.0689244 | W31: 3.0689244 | X31: 3.0689244
A32: Other hydrocarbons | B32: O4500 | C32: 3.0689244 | D32: 3.0689244 | E32: 3.0689244 | F32: 3.0689244 | G32: 3.0689244 | H32: 3.0689244 | I32: 3.0689244 | J32: 3.0689244 | K32: 3.0689244 | L32: 3.0689244 | M32: 3.0689244 | N32: 3.0689244 | O32: 3.0689244 | P32: 3.0689244 | Q32: 3.0689244 | R32: 3.0689244 | S32: 3.0689244 | T32: 3.0689244 | U32: 3.0689244 | V32: 3.0689244 | W32: 3.0689244 | X32: 3.0689244
A33: Oil products (excluding biofuel portion) | B33: O4600XBIO
A34: Refinery gas | B34: O4610 | C34: 2.4115968 | D34: 2.4115968 | E34: 2.4115968 | F34: 2.4115968 | G34: 2.4115968 | H34: 2.4115968 | I34: 2.4115968 | J34: 2.4115968 | K34: 2.4115968 | L34: 2.4115968 | M34: 2.4115968 | N34: 2.4115968 | O34: 2.4115968 | P34: 2.4115968 | Q34: 2.4115968 | R34: 2.4115968 | S34: 2.4115968 | T34: 2.4115968 | U34: 2.4115968 | V34: 2.4115968 | W34: 2.4115968 | X34: 2.4115968
A35: Ethane | B35: O4620 | C35: 2.5790688 | D35: 2.5790688 | E35: 2.5790688 | F35: 2.5790688 | G35: 2.5790688 | H35: 2.5790688 | I35: 2.5790688 | J35: 2.5790688 | K35: 2.5790688 | L35: 2.5790688 | M35: 2.5790688 | N35: 2.5790688 | O35: 2.5790688 | P35: 2.5790688 | Q35: 2.5790688 | R35: 2.5790688 | S35: 2.5790688 | T35: 2.5790688 | U35: 2.5790688 | V35: 2.5790688 | W35: 2.5790688 | X35: 2.5790688
A36: Liquefied petroleum gases | B36: O4630 | C36: 2.6418708 | D36: 2.6418708 | E36: 2.6418708 | F36: 2.6418708 | G36: 2.6418708 | H36: 2.6418708 | I36: 2.6418708 | J36: 2.6418708 | K36: 2.6418708 | L36: 2.6418708 | M36: 2.6418708 | N36: 2.6418708 | O36: 2.6418708 | P36: 2.6418708 | Q36: 2.6418708 | R36: 2.6418708 | S36: 2.6418708 | T36: 2.6418708 | U36: 2.6418708 | V36: 2.6418708 | W36: 2.6418708 | X36: 2.6418708
A37: Motor gasoline (excluding biofuel portion) | B37: O4652XR5210B | C37: 2.9014524 | D37: 2.9014524 | E37: 2.9014524 | F37: 2.9014524 | G37: 2.9014524 | H37: 2.9014524 | I37: 2.9014524 | J37: 2.9014524 | K37: 2.9014524 | L37: 2.9014524 | M37: 2.9014524 | N37: 2.9014524 | O37: 2.9014524 | P37: 2.9014524 | Q37: 2.9014524 | R37: 2.9014524 | S37: 2.9014524 | T37: 2.9014524 | U37: 2.9014524 | V37: 2.9014524 | W37: 2.9014524 | X37: 2.9014524
A38: Aviation gasoline | B38: O4651 | C38: 2.93076 | D38: 2.93076 | E38: 2.93076 | F38: 2.93076 | G38: 2.93076 | H38: 2.93076 | I38: 2.93076 | J38: 2.93076 | K38: 2.93076 | L38: 2.93076 | M38: 2.93076 | N38: 2.93076 | O38: 2.93076 | P38: 2.93076 | Q38: 2.93076 | R38: 2.93076 | S38: 2.93076 | T38: 2.93076 | U38: 2.93076 | V38: 2.93076 | W38: 2.93076 | X38: 2.93076
A39: Gasoline-type jet fuel | B39: O4653 | C39: 3.0103092 | D39: 3.0103092 | E39: 3.0103092 | F39: 3.0103092 | G39: 3.0103092 | H39: 3.0103092 | I39: 3.0103092 | J39: 3.0103092 | K39: 3.0103092 | L39: 3.0103092 | M39: 3.0103092 | N39: 3.0103092 | O39: 3.0103092 | P39: 3.0103092 | Q39: 3.0103092 | R39: 3.0103092 | S39: 3.0103092 | T39: 3.0103092 | U39: 3.0103092 | V39: 3.0103092 | W39: 3.0103092 | X39: 3.0103092
A40: Kerosene-type jet fuel (excluding biofuel portion) | B40: O4661XR5230B | C40: 3.0103092 | D40: 3.0103092 | E40: 3.0103092 | F40: 3.0103092 | G40: 3.0103092 | H40: 3.0103092 | I40: 3.0103092 | J40: 3.0103092 | K40: 3.0103092 | L40: 3.0103092 | M40: 3.0103092 | N40: 3.0103092 | O40: 3.0103092 | P40: 3.0103092 | Q40: 3.0103092 | R40: 3.0103092 | S40: 3.0103092 | T40: 3.0103092 | U40: 3.0103092 | V40: 3.0103092 | W40: 3.0103092 | X40: 3.0103092
...

Sheet GAE
A1: Gross available energy | B1: GAE | C1: 2000 | D1: 2001 | E1: 2002 | F1: 2003 | G1: 2004 | H1: 2005 | I1: 2006 | J1: 2007 | K1: 2008 | L1: 2009 | M1: 2010 | N1: 2011 | O1: 2012 | P1: 2013 | Q1: 2014 | R1: 2015 | S1: 2016 | T1: 2017 | U1: 2018 | V1: 2019 | W1: 2020 | X1: 2021
A2: Total | B2: TOTAL | C2: =SUM(C3,C17,C22,C25,C26,C51,C52) -> 54340.998 | D2: =SUM(D3,D17,D22,D25,D26,D51,D52) -> 55975.525 | E2: =SUM(E3,E17,E22,E25,E26,E51,E52) -> 55142.834 | F2: =SUM(F3,F17,F22,F25,F26,F51,F52) -> 57616.893 | G2: =SUM(G3,G17,G22,G25,G26,G51,G52) -> 55992.429 | H2: =SUM(H3,H17,H22,H25,H26,H51,H52) -> 55746.15 | I2: =SUM(I3,I17,I22,I25,I26,I51,I52) -> 55327.625 | J2: =SUM(J3,J17,J22,J25,J26,J51,J52) -> 53335.519 | ... X2: =SUM(X3,X17,X22,X25,X26,X51,X52) -> 45482.27
A3: Solid fossil fuels | B3: C0000X0350-0370 | C3: =SUM(C4,C8,C11) -> 13447.258 | D3: =SUM(D4,D8,D11) -> 13239.17 | E3: =SUM(E4,E8,E11) -> 12845.876 | F3: =SUM(F4,F8,F11) -> 13306.185 | G3: =SUM(G4,G8,G11) -> 12721.055 | H3: =SUM(H4,H8,H11) -> 10751.982 | I3: =SUM(I4,I8,I11) -> 10256.578 | J3: =SUM(J4,J8,J11) -> 10276.268 | ... X3: =SUM(X4,X8,X11) -> 3889.0775
A4: Hard coal | B4: C0100 | C4: =SUM(C5:C7) -> 0 | D4: =SUM(D5:D7) -> 0 | E4: =SUM(E5:E7) -> 683.69463 | F4: =SUM(F5:F7) -> 869.81612 | G4: =SUM(G5:G7) -> 1071.3772 | H4: =SUM(H5:H7) -> 1208.9628 | I4: =SUM(I5:I7) -> 1233.6619 | J4: =SUM(J5:J7) -> 1208.0743 | ... X4: =SUM(X5:X7) -> 178.96376
A5: Anthracite | B5: C0110 | C5: =INTMARB!C5+GIC!C5 -> 0 | D5: =INTMARB!D5+GIC!D5 -> 0 | E5: =INTMARB!E5+GIC!E5 -> 0 | F5: =INTMARB!F5+GIC!F5 -> 0 | G5: =INTMARB!G5+GIC!G5 -> 0 | H5: =INTMARB!H5+GIC!H5 -> 0 | I5: =INTMARB!I5+GIC!I5 -> 0 | J5: =INTMARB!J5+GIC!J5 -> 0 | ... X5: =INTMARB!X5+GIC!X5 -> 7.3698821
A6: Coking coal | B6: C0121 | C6: =INTMARB!C6+GIC!C6 -> 0 | D6: =INTMARB!D6+GIC!D6 -> 0 | E6: =INTMARB!E6+GIC!E6 -> 0 | F6: =INTMARB!F6+GIC!F6 -> 37.596121 | G6: =INTMARB!G6+GIC!G6 -> 81.166005 | H6: =INTMARB!H6+GIC!H6 -> 0 | I6: =INTMARB!I6+GIC!I6 -> 0 | J6: =INTMARB!J6+GIC!J6 -> 0 | ... X6: =INTMARB!X6+GIC!X6 -> 0
A7: Other bituminous coal | B7: C0129 | C7: =INTMARB!C7+GIC!C7 -> 0 | D7: =INTMARB!D7+GIC!D7 -> 0 | E7: =INTMARB!E7+GIC!E7 -> 683.69463 | F7: =INTMARB!F7+GIC!F7 -> 832.22 | G7: =INTMARB!G7+GIC!G7 -> 990.21123 | H7: =INTMARB!H7+GIC!H7 -> 1208.9628 | I7: =INTMARB!I7+GIC!I7 -> 1233.6619 | J7: =INTMARB!J7+GIC!J7 -> 1208.0743 | ... X7: =INTMARB!X7+GIC!X7 -> 171.59388
A8: Brown coal | B8: C0200 | C8: =SUM(C9:C10) -> 12865.333 | D8: =SUM(D9:D10) -> 12627.404 | E8: =SUM(E9:E10) -> 11571.121 | F8: =SUM(F9:F10) -> 11697.967 | G8: =SUM(G9:G10) -> 10915.139 | H8: =SUM(H9:H10) -> 8987.204 | I8: =SUM(I9:I10) -> 8527.8106 | J8: =SUM(J9:J10) -> 8535.7052 | ... X8: =SUM(X9:X10) -> 3511.0606
A9: Sub-bituminous coal | B9: C0210 | C9: =INTMARB!C9+GIC!C9 -> 784.04591 | D9: =INTMARB!D9+GIC!D9 -> 753.77073 | E9: =INTMARB!E9+GIC!E9 -> 442.74886 | F9: =INTMARB!F9+GIC!F9 -> 523.2656 | G9: =INTMARB!G9+GIC!G9 -> 700.22363 | H9: =INTMARB!H9+GIC!H9 -> 1229.1451 | I9: =INTMARB!I9+GIC!I9 -> 1134.0557 | J9: =INTMARB!J9+GIC!J9 -> 944.43405 | ... X9: =INTMARB!X9+GIC!X9 -> 0
A10: Lignite | B10: C0220 | C10: =INTMARB!C10+GIC!C10 -> 12081.287 | D10: =INTMARB!D10+GIC!D10 -> 11873.633 | E10: =INTMARB!E10+GIC!E10 -> 11128.372 | F10: =INTMARB!F10+GIC!F10 -> 11174.702 | G10: =INTMARB!G10+GIC!G10 -> 10214.915 | H10: =INTMARB!H10+GIC!H10 -> 7758.0589 | I10: =INTMARB!I10+GIC!I10 -> 7393.7549 | J10: =INTMARB!J10+GIC!J10 -> 7591.2712 | ... X10: =INTMARB!X10+GIC!X10 -> 3511.0606
A11: Coal products | B11: C0300 | C11: =SUM(C12:C16) -> 581.92519 | D11: =SUM(D12:D16) -> 611.76572 | E11: =SUM(E12:E16) -> 591.06103 | F11: =SUM(F12:F16) -> 738.40098 | G11: =SUM(G12:G16) -> 734.5395 | H11: =SUM(H12:H16) -> 555.81512 | I11: =SUM(I12:I16) -> 495.10526 | J11: =SUM(J12:J16) -> 532.48806 | ... X11: =SUM(X12:X16) -> 199.05309
A12: Patent fuel | B12: C0320 | C12: =INTMARB!C12+GIC!C12 -> 137.49087 | D12: =INTMARB!D12+GIC!D12 -> 93.836118 | E12: =INTMARB!E12+GIC!E12 -> 91.839298 | F12: =INTMARB!F12+GIC!F12 -> 87.25332 | G12: =INTMARB!G12+GIC!G12 -> 57.14478 | H12: =INTMARB!H12+GIC!H12 -> 56.6181 | I12: =INTMARB!I12+GIC!I12 -> 49.352023 | J12: =INTMARB!J12+GIC!J12 -> 19.030704 | ... X12: =INTMARB!X12+GIC!X12 -> 0
A13: Coke oven coke | B13: C0311 | C13: =INTMARB!C13+GIC!C13 -> 427.10761 | D13: =INTMARB!D13+GIC!D13 -> 500.41714 | E13: =INTMARB!E13+GIC!E13 -> 466.06056 | F13: =INTMARB!F13+GIC!F13 -> 610.1839 | G13: =INTMARB!G13+GIC!G13 -> 652.03613 | H13: =INTMARB!H13+GIC!H13 -> 471.88725 | I13: =INTMARB!I13+GIC!I13 -> 416.49336 | J13: =INTMARB!J13+GIC!J13 -> 483.2454 | ... X13: =INTMARB!X13+GIC!X13 -> 125.86774
A14: Gas coke | B14: C0312 | C14: =INTMARB!C14+GIC!C14 -> 0 | D14: =INTMARB!D14+GIC!D14 -> 0 | E14: =INTMARB!E14+GIC!E14 -> 0 | F14: =INTMARB!F14+GIC!F14 -> 0 | G14: =INTMARB!G14+GIC!G14 -> 0 | H14: =INTMARB!H14+GIC!H14 -> 0 | I14: =INTMARB!I14+GIC!I14 -> 0 | J14: =INTMARB!J14+GIC!J14 -> 0 | ... X14: =INTMARB!X14+GIC!X14 -> 0
A15: Coal tar | B15: C0340 | C15: =INTMARB!C15+GIC!C15 -> 0 | D15: =INTMARB!D15+GIC!D15 -> 0 | E15: =INTMARB!E15+GIC!E15 -> 0 | F15: =INTMARB!F15+GIC!F15 -> 0 | G15: =INTMARB!G15+GIC!G15 -> 0 | H15: =INTMARB!H15+GIC!H15 -> 0 | I15: =INTMARB!I15+GIC!I15 -> 0 | J15: =INTMARB!J15+GIC!J15 -> 3.0654624 | ... X15: =INTMARB!X15+GIC!X15 -> 0
A16: Brown coal briquettes | B16: C0330 | C16: =INTMARB!C16+GIC!C16 -> 17.326719 | D16: =INTMARB!D16+GIC!D16 -> 17.512461 | E16: =INTMARB!E16+GIC!E16 -> 33.161177 | F16: =INTMARB!F16+GIC!F16 -> 40.963766 | G16: =INTMARB!G16+GIC!G16 -> 25.358589 | H16: =INTMARB!H16+GIC!H16 -> 27.309762 | I16: =INTMARB!I16+GIC!I16 -> 29.259883 | J16: =INTMARB!J16+GIC!J16 -> 27.146492 | ... X16: =INTMARB!X16+GIC!X16 -> 73.185346
A17: Manufactured gases | B17: C0350-0370 | C17: =SUM(C18:C21) -> 2291.4693 | D17: =SUM(D18:D21) -> 1930.7636 | E17: =SUM(E18:E21) -> 1996.7264 | F17: =SUM(F18:F21) -> 1866.9842 | G17: =SUM(G18:G21) -> 1976.4066 | H17: =SUM(H18:H21) -> 2003.8974 | I17: =SUM(I18:I21) -> 2140.6525 | J17: =SUM(J18:J21) -> 2167.8949 | ... X17: =SUM(X18:X21) -> 1277.4271
A18: Gas works gas | B18: C0360 | C18: =INTMARB!C18+GIC!C18 -> 0 | D18: =INTMARB!D18+GIC!D18 -> 0 | E18: =INTMARB!E18+GIC!E18 -> 0 | F18: =INTMARB!F18+GIC!F18 -> 0 | G18: =INTMARB!G18+GIC!G18 -> 0 | H18: =INTMARB!H18+GIC!H18 -> 0 | I18: =INTMARB!I18+GIC!I18 -> 0 | J18: =INTMARB!J18+GIC!J18 -> 0 | ... X18: =INTMARB!X18+GIC!X18 -> 0
A19: Coke oven gas | B19: C0350 | C19: =INTMARB!C19+GIC!C19 -> 311.04864 | D19: =INTMARB!D19+GIC!D19 -> 176.0238 | E19: =INTMARB!E19+GIC!E19 -> 113.80608 | F19: =INTMARB!F19+GIC!F19 -> 176.46336 | G19: =INTMARB!G19+GIC!G19 -> 173.30652 | H19: =INTMARB!H19+GIC!H19 -> 182.33748 | I19: =INTMARB!I19+GIC!I19 -> 327.672 | J19: =INTMARB!J19+GIC!J19 -> 364.79484 | ... X19: =INTMARB!X19+GIC!X19 -> 273.56616
A20: Blast furnace gas | B20: C0371 | C20: =INTMARB!C20+GIC!C20 -> 1980.4206 | D20: =INTMARB!D20+GIC!D20 -> 1754.7398 | E20: =INTMARB!E20+GIC!E20 -> 1882.9203 | F20: =INTMARB!F20+GIC!F20 -> 1690.5208 | G20: =INTMARB!G20+GIC!G20 -> 1803.1001 | H20: =INTMARB!H20+GIC!H20 -> 1821.5599 | I20: =INTMARB!I20+GIC!I20 -> 1812.9805 | J20: =INTMARB!J20+GIC!J20 -> 1803.1001 | ... X20: =INTMARB!X20+GIC!X20 -> 1003.8609
A21: Other recovered gases | B21: C0379 | C21: =INTMARB!C21+GIC!C21 -> 0 | D21: =INTMARB!D21+GIC!D21 -> 0 | E21: =INTMARB!E21+GIC!E21 -> 0 | F21: =INTMARB!F21+GIC!F21 -> 0 | G21: =INTMARB!G21+GIC!G21 -> 0 | H21: =INTMARB!H21+GIC!H21 -> 0 | I21: =INTMARB!I21+GIC!I21 -> 0 | J21: =INTMARB!J21+GIC!J21 -> 0 | ... X21: =INTMARB!X21+GIC!X21 -> 0
A22: Peat and peat products | B22: P1000 | C22: =SUM(C23:C24) -> 0 | D22: =SUM(D23:D24) -> 0 | E22: =SUM(E23:E24) -> 0 | F22: =SUM(F23:F24) -> 0 | G22: =SUM(G23:G24) -> 0 | H22: =SUM(H23:H24) -> 0 | I22: =SUM(I23:I24) -> 0 | J22: =SUM(J23:J24) -> 0 | ... X22: =SUM(X23:X24) -> 0
A23: Peat | B23: P1100 | C23: =INTMARB!C23+GIC!C23 -> 0 | D23: =INTMARB!D23+GIC!D23 -> 0 | E23: =INTMARB!E23+GIC!E23 -> 0 | F23: =INTMARB!F23+GIC!F23 -> 0 | G23: =INTMARB!G23+GIC!G23 -> 0 | H23: =INTMARB!H23+GIC!H23 -> 0 | I23: =INTMARB!I23+GIC!I23 -> 0 | J23: =INTMARB!J23+GIC!J23 -> 0 | ... X23: =INTMARB!X23+GIC!X23 -> 0
A24: Peat products | B24: P1200 | C24: =INTMARB!C24+GIC!C24 -> 0 | D24: =INTMARB!D24+GIC!D24 -> 0 | E24: =INTMARB!E24+GIC!E24 -> 0 | F24: =INTMARB!F24+GIC!F24 -> 0 | G24: =INTMARB!G24+GIC!G24 -> 0 | H24: =INTMARB!H24+GIC!H24 -> 0 | I24: =INTMARB!I24+GIC!I24 -> 0 | J24: =INTMARB!J24+GIC!J24 -> 0 | ... X24: =INTMARB!X24+GIC!X24 -> 0
A25: Oil shale and oil sands | B25: S2000 | C25: =INTMARB!C25+GIC!C25 -> 0 | D25: =INTMARB!D25+GIC!D25 -> 0 | E25: =INTMARB!E25+GIC!E25 -> 0 | F25: =INTMARB!F25+GIC!F25 -> 0 | G25: =INTMARB!G25+GIC!G25 -> 0 | H25: =INTMARB!H25+GIC!H25 -> 0 | I25: =INTMARB!I25+GIC!I25 -> 0 | J25: =INTMARB!J25+GIC!J25 -> 0 | ... X25: =INTMARB!X25+GIC!X25 -> 0
A26: Oil and petroleum products | B26: O4000XBIO | C26: =SUM(C27,C33) -> 17310.956 | D26: =SUM(D27,D33) -> 17079.581 | E26: =SUM(E27,E33) -> 16113.894 | F26: =SUM(F27,F33) -> 15955.244 | G26: =SUM(G27,G33) -> 15542.472 | H26: =SUM(H27,H33) -> 16052.416 | I26: =SUM(I27,I33) -> 17129.758 | J26: =SUM(J27,J33) -> 16769.262 | ... X26: =SUM(X27,X33) -> 18717.951
A27: Crude oil, NGL, refinery feedstocks, additives and oxygenates and other hydrocarbons (excluding biofuel portion) | B27: O4100_TOT_4200-4500XBIO | C27: =SUM(C28:C32) -> 162.38885 | D27: =SUM(D28:D32) -> 174.64449 | E27: =SUM(E28:E32) -> 0 | F27: =SUM(F28:F32) -> 0 | G27: =SUM(G28:G32) -> 3.0712993 | H27: =SUM(H28:H32) -> 0 | I27: =SUM(I28:I32) -> 6.1278214 | J27: =SUM(J28:J32) -> 0 | ... X27: =SUM(X28:X32) -> 0
A28: Crude oil | B28: O4100_TOT | C28: =INTMARB!C28+GIC!C28 -> 162.38885 | D28: =INTMARB!D28+GIC!D28 -> 174.64449 | E28: =INTMARB!E28+GIC!E28 -> 0 | F28: =INTMARB!F28+GIC!F28 -> 0 | G28: =INTMARB!G28+GIC!G28 -> 3.0712993 | H28: =INTMARB!H28+GIC!H28 -> 0 | I28: =INTMARB!I28+GIC!I28 -> 6.1278214 | J28: =INTMARB!J28+GIC!J28 -> 0 | ... X28: =INTMARB!X28+GIC!X28 -> 0
A29: Natural gas liquids | B29: O4200 | C29: =INTMARB!C29+GIC!C29 -> 0 | D29: =INTMARB!D29+GIC!D29 -> 0 | E29: =INTMARB!E29+GIC!E29 -> 0 | F29: =INTMARB!F29+GIC!F29 -> 0 | G29: =INTMARB!G29+GIC!G29 -> 0 | H29: =INTMARB!H29+GIC!H29 -> 0 | I29: =INTMARB!I29+GIC!I29 -> 0 | J29: =INTMARB!J29+GIC!J29 -> 0 | ... X29: =INTMARB!X29+GIC!X29 -> 0
A30: Refinery feedstocks | B30: O4300 | C30: =INTMARB!C30+GIC!C30 -> 0 | D30: =INTMARB!D30+GIC!D30 -> 0 | E30: =INTMARB!E30+GIC!E30 -> 0 | F30: =INTMARB!F30+GIC!F30 -> 0 | G30: =INTMARB!G30+GIC!G30 -> 0 | H30: =INTMARB!H30+GIC!H30 -> 0 | I30: =INTMARB!I30+GIC!I30 -> 0 | J30: =INTMARB!J30+GIC!J30 -> 0 | ... X30: =INTMARB!X30+GIC!X30 -> 0
A31: Additives and oxygenates (excluding biofuel portion) | B31: O4400X4410 | C31: =INTMARB!C31+GIC!C31 -> 0 | D31: =INTMARB!D31+GIC!D31 -> 0 | E31: =INTMARB!E31+GIC!E31 -> 0 | F31: =INTMARB!F31+GIC!F31 -> 0 | G31: =INTMARB!G31+GIC!G31 -> 0 | H31: =INTMARB!H31+GIC!H31 -> 0 | I31: =INTMARB!I31+GIC!I31 -> 0 | J31: =INTMARB!J31+GIC!J31 -> 0 | ... X31: =INTMARB!X31+GIC!X31 -> 0
A32: Other hydrocarbons | B32: O4500 | C32: =INTMARB!C32+GIC!C32 -> 0 | D32: =INTMARB!D32+GIC!D32 -> 0 | E32: =INTMARB!E32+GIC!E32 -> 0 | F32: =INTMARB!F32+GIC!F32 -> 0 | G32: =INTMARB!G32+GIC!G32 -> 0 | H32: =INTMARB!H32+GIC!H32 -> 0 | I32: =INTMARB!I32+GIC!I32 -> 0 | J32: =INTMARB!J32+GIC!J32 -> 0 | ... X32: =INTMARB!X32+GIC!X32 -> 0
A33: Oil products (excluding biofuel portion) | B33: O4600XBIO | C33: =SUM(C34:C50) -> 17148.567 | D33: =SUM(D34:D50) -> 16904.937 | E33: =SUM(E34:E50) -> 16113.894 | F33: =SUM(F34:F50) -> 15955.244 | G33: =SUM(G34:G50) -> 15539.401 | H33: =SUM(H34:H50) -> 16052.416 | I33: =SUM(I34:I50) -> 17123.63 | J33: =SUM(J34:J50) -> 16769.262 | ... X33: =SUM(X34:X50) -> 18717.951
A34: Refinery gas | B34: O4610 | C34: =INTMARB!C34+GIC!C34 -> 424.8288 | D34: =INTMARB!D34+GIC!D34 -> 490.4064 | E34: =INTMARB!E34+GIC!E34 -> 564.5376 | F34: =INTMARB!F34+GIC!F34 -> 479.0016 | G34: =INTMARB!G34+GIC!G34 -> 458.95673 | H34: =INTMARB!H34+GIC!H34 -> 470.01586 | I34: =INTMARB!I34+GIC!I34 -> 464.4864 | J34: =INTMARB!J34+GIC!J34 -> 472.7808 | ... X34: =INTMARB!X34+GIC!X34 -> 485.44013
A35: Ethane | B35: O4620 | C35: =INTMARB!C35+GIC!C35 -> 0 | D35: =INTMARB!D35+GIC!D35 -> 0 | E35: =INTMARB!E35+GIC!E35 -> 0 | F35: =INTMARB!F35+GIC!F35 -> 0 | G35: =INTMARB!G35+GIC!G35 -> 0 | H35: =INTMARB!H35+GIC!H35 -> 0 | I35: =INTMARB!I35+GIC!I35 -> 0 | J35: =INTMARB!J35+GIC!J35 -> 0 | ... X35: =INTMARB!X35+GIC!X35 -> 0
A36: Liquefied petroleum gases | B36: O4630 | C36: =INTMARB!C36+GIC!C36 -> 975.97409 | D36: =INTMARB!D36+GIC!D36 -> 841.66574 | E36: =INTMARB!E36+GIC!E36 -> 913.29678 | F36: =INTMARB!F36+GIC!F36 -> 901.35861 | G36: =INTMARB!G36+GIC!G36 -> 711.76815 | H36: =INTMARB!H36+GIC!H36 -> 744.39083 | I36: =INTMARB!I36+GIC!I36 -> 667.28318 | J36: =INTMARB!J36+GIC!J36 -> 524.92905 | ... X36: =INTMARB!X36+GIC!X36 -> 701.65567
A37: Motor gasoline (excluding biofuel portion) | B37: O4652XR5210B | C37: =INTMARB!C37+GIC!C37 -> 4101.5066 | D37: =INTMARB!D37+GIC!D37 -> 4270.3561 | E37: =INTMARB!E37+GIC!E37 -> 4374.7358 | F37: =INTMARB!F37+GIC!F37 -> 4371.6657 | G37: =INTMARB!G37+GIC!G37 -> 4426.9256 | H37: =INTMARB!H37+GIC!H37 -> 4549.7251 | I37: =INTMARB!I37+GIC!I37 -> 4635.6849 | J37: =INTMARB!J37+GIC!J37 -> 4706.2948 | ... X37: =INTMARB!X37+GIC!X37 -> 4027.9933
A38: Aviation gasoline | B38: O4651 | C38: =INTMARB!C38+GIC!C38 -> 12.403944 | D38: =INTMARB!D38+GIC!D38 -> 6.201972 | E38: =INTMARB!E38+GIC!E38 -> 6.201972 | F38: =INTMARB!F38+GIC!F38 -> 6.201972 | G38: =INTMARB!G38+GIC!G38 -> 8.82 | H38: =INTMARB!H38+GIC!H38 -> 8.82 | I38: =INTMARB!I38+GIC!I38 -> 5.879916 | J38: =INTMARB!J38+GIC!J38 -> 0 | ... X38: =INTMARB!X38+GIC!X38 -> 3.152016
A39: Gasoline-type jet fuel | B39: O4653 | C39: =INTMARB!C39+GIC!C39 -> 0 | D39: =INTMARB!D39+GIC!D39 -> 0 | E39: =INTMARB!E39+GIC!E39 -> 0 | F39: =INTMARB!F39+GIC!F39 -> 0 | G39: =INTMARB!G39+GIC!G39 -> 0 | H39: =INTMARB!H39+GIC!H39 -> 0 | I39: =INTMARB!I39+GIC!I39 -> 0 | J39: =INTMARB!J39+GIC!J39 -> 0 | ... X39: =INTMARB!X39+GIC!X39 -> 0
A40: Kerosene-type jet fuel (excluding biofuel portion) | B40: O4661XR5230B | C40: =INTMARB!C40+GIC!C40 -> 710.25696 | D40: =INTMARB!D40+GIC!D40 -> 672.20748 | E40: =INTMARB!E40+GIC!E40 -> 634.158 | F40: =INTMARB!F40+GIC!F40 -> 621.47484 | G40: =INTMARB!G40+GIC!G40 -> 676.2195 | H40: =INTMARB!H40+GIC!H40 -> 784.41462 | I40: =INTMARB!I40+GIC!I40 -> 797.2272 | J40: =INTMARB!J40+GIC!J40 -> 730.79151 | ... X40: =INTMARB!X40+GIC!X40 -> 426.73475
...

Sheet INTMARB
A1: International maritime bunkers | B1: INTMARB | C1: 2000 | D1: 2001 | E1: 2002 | F1: 2003 | G1: 2004 | H1: 2005 | I1: 2006 | J1: 2007 | K1: 2008 | L1: 2009 | M1: 2010 | N1: 2011 | O1: 2012 | P1: 2013 | Q1: 2014 | R1: 2015 | S1: 2016 | T1: 2017 | U1: 2018 | V1: 2019 | W1: 2020 | X1: 2021
A2: Total | B2: TOTAL | C2: =SUM(C3,C17,C22,C25,C26,C51,C52) -> 0 | D2: =SUM(D3,D17,D22,D25,D26,D51,D52) -> 0 | E2: =SUM(E3,E17,E22,E25,E26,E51,E52) -> 0 | F2: =SUM(F3,F17,F22,F25,F26,F51,F52) -> 0 | G2: =SUM(G3,G17,G22,G25,G26,G51,G52) -> 0 | H2: =SUM(H3,H17,H22,H25,H26,H51,H52) -> 0 | I2: =SUM(I3,I17,I22,I25,I26,I51,I52) -> 0 | J2: =SUM(J3,J17,J22,J25,J26,J51,J52) -> 0 | ... X2: =SUM(X3,X17,X22,X25,X26,X51,X52) -> 0
A3: Solid fossil fuels | B3: C0000X0350-0370 | C3: =SUM(C4,C8,C11) -> 0 | D3: =SUM(D4,D8,D11) -> 0 | E3: =SUM(E4,E8,E11) -> 0 | F3: =SUM(F4,F8,F11) -> 0 | G3: =SUM(G4,G8,G11) -> 0 | H3: =SUM(H4,H8,H11) -> 0 | I3: =SUM(I4,I8,I11) -> 0 | J3: =SUM(J4,J8,J11) -> 0 | ... X3: =SUM(X4,X8,X11) -> 0
A4: Hard coal | B4: C0100 | C4: =SUM(C5:C7) -> 0 | D4: =SUM(D5:D7) -> 0 | E4: =SUM(E5:E7) -> 0 | F4: =SUM(F5:F7) -> 0 | G4: =SUM(G5:G7) -> 0 | H4: =SUM(H5:H7) -> 0 | I4: =SUM(I5:I7) -> 0 | J4: =SUM(J5:J7) -> 0 | ... X4: =SUM(X5:X7) -> 0
A5: Anthracite | B5: C0110 | C5: =INTMARB_IN!C5+INTMARB_EX!C5 -> 0 | D5: =INTMARB_IN!D5+INTMARB_EX!D5 -> 0 | E5: =INTMARB_IN!E5+INTMARB_EX!E5 -> 0 | F5: =INTMARB_IN!F5+INTMARB_EX!F5 -> 0 | G5: =INTMARB_IN!G5+INTMARB_EX!G5 -> 0 | H5: =INTMARB_IN!H5+INTMARB_EX!H5 -> 0 | I5: =INTMARB_IN!I5+INTMARB_EX!I5 -> 0 | J5: =INTMARB_IN!J5+INTMARB_EX!J5 -> 0 | ... X5: =INTMARB_IN!X5+INTMARB_EX!X5 -> 0
A6: Coking coal | B6: C0121 | C6: =INTMARB_IN!C6+INTMARB_EX!C6 -> 0 | D6: =INTMARB_IN!D6+INTMARB_EX!D6 -> 0 | E6: =INTMARB_IN!E6+INTMARB_EX!E6 -> 0 | F6: =INTMARB_IN!F6+INTMARB_EX!F6 -> 0 | G6: =INTMARB_IN!G6+INTMARB_EX!G6 -> 0 | H6: =INTMARB_IN!H6+INTMARB_EX!H6 -> 0 | I6: =INTMARB_IN!I6+INTMARB_EX!I6 -> 0 | J6: =INTMARB_IN!J6+INTMARB_EX!J6 -> 0 | ... X6: =INTMARB_IN!X6+INTMARB_EX!X6 -> 0
A7: Other bituminous coal | B7: C0129 | C7: =INTMARB_IN!C7+INTMARB_EX!C7 -> 0 | D7: =INTMARB_IN!D7+INTMARB_EX!D7 -> 0 | E7: =INTMARB_IN!E7+INTMARB_EX!E7 -> 0 | F7: =INTMARB_IN!F7+INTMARB_EX!F7 -> 0 | G7: =INTMARB_IN!G7+INTMARB_EX!G7 -> 0 | H7: =INTMARB_IN!H7+INTMARB_EX!H7 -> 0 | I7: =INTMARB_IN!I7+INTMARB_EX!I7 -> 0 | J7: =INTMARB_IN!J7+INTMARB_EX!J7 -> 0 | ... X7: =INTMARB_IN!X7+INTMARB_EX!X7 -> 0
A8: Brown coal | B8: C0200 | C8: =SUM(C9:C10) -> 0 | D8: =SUM(D9:D10) -> 0 | E8: =SUM(E9:E10) -> 0 | F8: =SUM(F9:F10) -> 0 | G8: =SUM(G9:G10) -> 0 | H8: =SUM(H9:H10) -> 0 | I8: =SUM(I9:I10) -> 0 | J8: =SUM(J9:J10) -> 0 | ... X8: =SUM(X9:X10) -> 0
A9: Sub-bituminous coal | B9: C0210 | C9: =INTMARB_IN!C9+INTMARB_EX!C9 -> 0 | D9: =INTMARB_IN!D9+INTMARB_EX!D9 -> 0 | E9: =INTMARB_IN!E9+INTMARB_EX!E9 -> 0 | F9: =INTMARB_IN!F9+INTMARB_EX!F9 -> 0 | G9: =INTMARB_IN!G9+INTMARB_EX!G9 -> 0 | H9: =INTMARB_IN!H9+INTMARB_EX!H9 -> 0 | I9: =INTMARB_IN!I9+INTMARB_EX!I9 -> 0 | J9: =INTMARB_IN!J9+INTMARB_EX!J9 -> 0 | ... X9: =INTMARB_IN!X9+INTMARB_EX!X9 -> 0
A10: Lignite | B10: C0220 | C10: =INTMARB_IN!C10+INTMARB_EX!C10 -> 0 | D10: =INTMARB_IN!D10+INTMARB_EX!D10 -> 0 | E10: =INTMARB_IN!E10+INTMARB_EX!E10 -> 0 | F10: =INTMARB_IN!F10+INTMARB_EX!F10 -> 0 | G10: =INTMARB_IN!G10+INTMARB_EX!G10 -> 0 | H10: =INTMARB_IN!H10+INTMARB_EX!H10 -> 0 | I10: =INTMARB_IN!I10+INTMARB_EX!I10 -> 0 | J10: =INTMARB_IN!J10+INTMARB_EX!J10 -> 0 | ... X10: =INTMARB_IN!X10+INTMARB_EX!X10 -> 0
A11: Coal products | B11: C0300 | C11: =SUM(C12:C16) -> 0 | D11: =SUM(D12:D16) -> 0 | E11: =SUM(E12:E16) -> 0 | F11: =SUM(F12:F16) -> 0 | G11: =SUM(G12:G16) -> 0 | H11: =SUM(H12:H16) -> 0 | I11: =SUM(I12:I16) -> 0 | J11: =SUM(J12:J16) -> 0 | ... X11: =SUM(X12:X16) -> 0
A12: Patent fuel | B12: C0320 | C12: =INTMARB_IN!C12+INTMARB_EX!C12 -> 0 | D12: =INTMARB_IN!D12+INTMARB_EX!D12 -> 0 | E12: =INTMARB_IN!E12+INTMARB_EX!E12 -> 0 | F12: =INTMARB_IN!F12+INTMARB_EX!F12 -> 0 | G12: =INTMARB_IN!G12+INTMARB_EX!G12 -> 0 | H12: =INTMARB_IN!H12+INTMARB_EX!H12 -> 0 | I12: =INTMARB_IN!I12+INTMARB_EX!I12 -> 0 | J12: =INTMARB_IN!J12+INTMARB_EX!J12 -> 0 | ... X12: =INTMARB_IN!X12+INTMARB_EX!X12 -> 0
A13: Coke oven coke | B13: C0311 | C13: =INTMARB_IN!C13+INTMARB_EX!C13 -> 0 | D13: =INTMARB_IN!D13+INTMARB_EX!D13 -> 0 | E13: =INTMARB_IN!E13+INTMARB_EX!E13 -> 0 | F13: =INTMARB_IN!F13+INTMARB_EX!F13 -> 0 | G13: =INTMARB_IN!G13+INTMARB_EX!G13 -> 0 | H13: =INTMARB_IN!H13+INTMARB_EX!H13 -> 0 | I13: =INTMARB_IN!I13+INTMARB_EX!I13 -> 0 | J13: =INTMARB_IN!J13+INTMARB_EX!J13 -> 0 | ... X13: =INTMARB_IN!X13+INTMARB_EX!X13 -> 0
A14: Gas coke | B14: C0312 | C14: =INTMARB_IN!C14+INTMARB_EX!C14 -> 0 | D14: =INTMARB_IN!D14+INTMARB_EX!D14 -> 0 | E14: =INTMARB_IN!E14+INTMARB_EX!E14 -> 0 | F14: =INTMARB_IN!F14+INTMARB_EX!F14 -> 0 | G14: =INTMARB_IN!G14+INTMARB_EX!G14 -> 0 | H14: =INTMARB_IN!H14+INTMARB_EX!H14 -> 0 | I14: =INTMARB_IN!I14+INTMARB_EX!I14 -> 0 | J14: =INTMARB_IN!J14+INTMARB_EX!J14 -> 0 | ... X14: =INTMARB_IN!X14+INTMARB_EX!X14 -> 0
A15: Coal tar | B15: C0340 | C15: =INTMARB_IN!C15+INTMARB_EX!C15 -> 0 | D15: =INTMARB_IN!D15+INTMARB_EX!D15 -> 0 | E15: =INTMARB_IN!E15+INTMARB_EX!E15 -> 0 | F15: =INTMARB_IN!F15+INTMARB_EX!F15 -> 0 | G15: =INTMARB_IN!G15+INTMARB_EX!G15 -> 0 | H15: =INTMARB_IN!H15+INTMARB_EX!H15 -> 0 | I15: =INTMARB_IN!I15+INTMARB_EX!I15 -> 0 | J15: =INTMARB_IN!J15+INTMARB_EX!J15 -> 0 | ... X15: =INTMARB_IN!X15+INTMARB_EX!X15 -> 0
A16: Brown coal briquettes | B16: C0330 | C16: =INTMARB_IN!C16+INTMARB_EX!C16 -> 0 | D16: =INTMARB_IN!D16+INTMARB_EX!D16 -> 0 | E16: =INTMARB_IN!E16+INTMARB_EX!E16 -> 0 | F16: =INTMARB_IN!F16+INTMARB_EX!F16 -> 0 | G16: =INTMARB_IN!G16+INTMARB_EX!G16 -> 0 | H16: =INTMARB_IN!H16+INTMARB_EX!H16 -> 0 | I16: =INTMARB_IN!I16+INTMARB_EX!I16 -> 0 | J16: =INTMARB_IN!J16+INTMARB_EX!J16 -> 0 | ... X16: =INTMARB_IN!X16+INTMARB_EX!X16 -> 0
A17: Manufactured gases | B17: C0350-0370 | C17: =SUM(C18:C21) -> 0 | D17: =SUM(D18:D21) -> 0 | E17: =SUM(E18:E21) -> 0 | F17: =SUM(F18:F21) -> 0 | G17: =SUM(G18:G21) -> 0 | H17: =SUM(H18:H21) -> 0 | I17: =SUM(I18:I21) -> 0 | J17: =SUM(J18:J21) -> 0 | ... X17: =SUM(X18:X21) -> 0
A18: Gas works gas | B18: C0360 | C18: =INTMARB_IN!C18+INTMARB_EX!C18 -> 0 | D18: =INTMARB_IN!D18+INTMARB_EX!D18 -> 0 | E18: =INTMARB_IN!E18+INTMARB_EX!E18 -> 0 | F18: =INTMARB_IN!F18+INTMARB_EX!F18 -> 0 | G18: =INTMARB_IN!G18+INTMARB_EX!G18 -> 0 | H18: =INTMARB_IN!H18+INTMARB_EX!H18 -> 0 | I18: =INTMARB_IN!I18+INTMARB_EX!I18 -> 0 | J18: =INTMARB_IN!J18+INTMARB_EX!J18 -> 0 | ... X18: =INTMARB_IN!X18+INTMARB_EX!X18 -> 0
A19: Coke oven gas | B19: C0350 | C19: =INTMARB_IN!C19+INTMARB_EX!C19 -> 0 | D19: =INTMARB_IN!D19+INTMARB_EX!D19 -> 0 | E19: =INTMARB_IN!E19+INTMARB_EX!E19 -> 0 | F19: =INTMARB_IN!F19+INTMARB_EX!F19 -> 0 | G19: =INTMARB_IN!G19+INTMARB_EX!G19 -> 0 | H19: =INTMARB_IN!H19+INTMARB_EX!H19 -> 0 | I19: =INTMARB_IN!I19+INTMARB_EX!I19 -> 0 | J19: =INTMARB_IN!J19+INTMARB_EX!J19 -> 0 | ... X19: =INTMARB_IN!X19+INTMARB_EX!X19 -> 0
A20: Blast furnace gas | B20: C0371 | C20: =INTMARB_IN!C20+INTMARB_EX!C20 -> 0 | D20: =INTMARB_IN!D20+INTMARB_EX!D20 -> 0 | E20: =INTMARB_IN!E20+INTMARB_EX!E20 -> 0 | F20: =INTMARB_IN!F20+INTMARB_EX!F20 -> 0 | G20: =INTMARB_IN!G20+INTMARB_EX!G20 -> 0 | H20: =INTMARB_IN!H20+INTMARB_EX!H20 -> 0 | I20: =INTMARB_IN!I20+INTMARB_EX!I20 -> 0 | J20: =INTMARB_IN!J20+INTMARB_EX!J20 -> 0 | ... X20: =INTMARB_IN!X20+INTMARB_EX!X20 -> 0
A21: Other recovered gases | B21: C0379 | C21: =INTMARB_IN!C21+INTMARB_EX!C21 -> 0 | D21: =INTMARB_IN!D21+INTMARB_EX!D21 -> 0 | E21: =INTMARB_IN!E21+INTMARB_EX!E21 -> 0 | F21: =INTMARB_IN!F21+INTMARB_EX!F21 -> 0 | G21: =INTMARB_IN!G21+INTMARB_EX!G21 -> 0 | H21: =INTMARB_IN!H21+INTMARB_EX!H21 -> 0 | I21: =INTMARB_IN!I21+INTMARB_EX!I21 -> 0 | J21: =INTMARB_IN!J21+INTMARB_EX!J21 -> 0 | ... X21: =INTMARB_IN!X21+INTMARB_EX!X21 -> 0
A22: Peat and peat products | B22: P1000 | C22: =SUM(C23:C24) -> 0 | D22: =SUM(D23:D24) -> 0 | E22: =SUM(E23:E24) -> 0 | F22: =SUM(F23:F24) -> 0 | G22: =SUM(G23:G24) -> 0 | H22: =SUM(H23:H24) -> 0 | I22: =SUM(I23:I24) -> 0 | J22: =SUM(J23:J24) -> 0 | ... X22: =SUM(X23:X24) -> 0
A23: Peat | B23: P1100 | C23: =INTMARB_IN!C23+INTMARB_EX!C23 -> 0 | D23: =INTMARB_IN!D23+INTMARB_EX!D23 -> 0 | E23: =INTMARB_IN!E23+INTMARB_EX!E23 -> 0 | F23: =INTMARB_IN!F23+INTMARB_EX!F23 -> 0 | G23: =INTMARB_IN!G23+INTMARB_EX!G23 -> 0 | H23: =INTMARB_IN!H23+INTMARB_EX!H23 -> 0 | I23: =INTMARB_IN!I23+INTMARB_EX!I23 -> 0 | J23: =INTMARB_IN!J23+INTMARB_EX!J23 -> 0 | ... X23: =INTMARB_IN!X23+INTMARB_EX!X23 -> 0
A24: Peat products | B24: P1200 | C24: =INTMARB_IN!C24+INTMARB_EX!C24 -> 0 | D24: =INTMARB_IN!D24+INTMARB_EX!D24 -> 0 | E24: =INTMARB_IN!E24+INTMARB_EX!E24 -> 0 | F24: =INTMARB_IN!F24+INTMARB_EX!F24 -> 0 | G24: =INTMARB_IN!G24+INTMARB_EX!G24 -> 0 | H24: =INTMARB_IN!H24+INTMARB_EX!H24 -> 0 | I24: =INTMARB_IN!I24+INTMARB_EX!I24 -> 0 | J24: =INTMARB_IN!J24+INTMARB_EX!J24 -> 0 | ... X24: =INTMARB_IN!X24+INTMARB_EX!X24 -> 0
A25: Oil shale and oil sands | B25: S2000 | C25: =INTMARB_IN!C25+INTMARB_EX!C25 -> 0 | D25: =INTMARB_IN!D25+INTMARB_EX!D25 -> 0 | E25: =INTMARB_IN!E25+INTMARB_EX!E25 -> 0 | F25: =INTMARB_IN!F25+INTMARB_EX!F25 -> 0 | G25: =INTMARB_IN!G25+INTMARB_EX!G25 -> 0 | H25: =INTMARB_IN!H25+INTMARB_EX!H25 -> 0 | I25: =INTMARB_IN!I25+INTMARB_EX!I25 -> 0 | J25: =INTMARB_IN!J25+INTMARB_EX!J25 -> 0 | ... X25: =INTMARB_IN!X25+INTMARB_EX!X25 -> 0
A26: Oil and petroleum products | B26: O4000XBIO | C26: =SUM(C27,C33) -> 0 | D26: =SUM(D27,D33) -> 0 | E26: =SUM(E27,E33) -> 0 | F26: =SUM(F27,F33) -> 0 | G26: =SUM(G27,G33) -> 0 | H26: =SUM(H27,H33) -> 0 | I26: =SUM(I27,I33) -> 0 | J26: =SUM(J27,J33) -> 0 | ... X26: =SUM(X27,X33) -> 0
A27: Crude oil, NGL, refinery feedstocks, additives and oxygenates and other hydrocarbons (excluding biofuel portion) | B27: O4100_TOT_4200-4500XBIO | C27: =SUM(C28:C32) -> 0 | D27: =SUM(D28:D32) -> 0 | E27: =SUM(E28:E32) -> 0 | F27: =SUM(F28:F32) -> 0 | G27: =SUM(G28:G32) -> 0 | H27: =SUM(H28:H32) -> 0 | I27: =SUM(I28:I32) -> 0 | J27: =SUM(J28:J32) -> 0 | ... X27: =SUM(X28:X32) -> 0
A28: Crude oil | B28: O4100_TOT | C28: =INTMARB_IN!C28+INTMARB_EX!C28 -> 0 | D28: =INTMARB_IN!D28+INTMARB_EX!D28 -> 0 | E28: =INTMARB_IN!E28+INTMARB_EX!E28 -> 0 | F28: =INTMARB_IN!F28+INTMARB_EX!F28 -> 0 | G28: =INTMARB_IN!G28+INTMARB_EX!G28 -> 0 | H28: =INTMARB_IN!H28+INTMARB_EX!H28 -> 0 | I28: =INTMARB_IN!I28+INTMARB_EX!I28 -> 0 | J28: =INTMARB_IN!J28+INTMARB_EX!J28 -> 0 | ... X28: =INTMARB_IN!X28+INTMARB_EX!X28 -> 0
A29: Natural gas liquids | B29: O4200 | C29: =INTMARB_IN!C29+INTMARB_EX!C29 -> 0 | D29: =INTMARB_IN!D29+INTMARB_EX!D29 -> 0 | E29: =INTMARB_IN!E29+INTMARB_EX!E29 -> 0 | F29: =INTMARB_IN!F29+INTMARB_EX!F29 -> 0 | G29: =INTMARB_IN!G29+INTMARB_EX!G29 -> 0 | H29: =INTMARB_IN!H29+INTMARB_EX!H29 -> 0 | I29: =INTMARB_IN!I29+INTMARB_EX!I29 -> 0 | J29: =INTMARB_IN!J29+INTMARB_EX!J29 -> 0 | ... X29: =INTMARB_IN!X29+INTMARB_EX!X29 -> 0
A30: Refinery feedstocks | B30: O4300 | C30: =INTMARB_IN!C30+INTMARB_EX!C30 -> 0 | D30: =INTMARB_IN!D30+INTMARB_EX!D30 -> 0 | E30: =INTMARB_IN!E30+INTMARB_EX!E30 -> 0 | F30: =INTMARB_IN!F30+INTMARB_EX!F30 -> 0 | G30: =INTMARB_IN!G30+INTMARB_EX!G30 -> 0 | H30: =INTMARB_IN!H30+INTMARB_EX!H30 -> 0 | I30: =INTMARB_IN!I30+INTMARB_EX!I30 -> 0 | J30: =INTMARB_IN!J30+INTMARB_EX!J30 -> 0 | ... X30: =INTMARB_IN!X30+INTMARB_EX!X30 -> 0
A31: Additives and oxygenates (excluding biofuel portion) | B31: O4400X4410 | C31: =INTMARB_IN!C31+INTMARB_EX!C31 -> 0 | D31: =INTMARB_IN!D31+INTMARB_EX!D31 -> 0 | E31: =INTMARB_IN!E31+INTMARB_EX!E31 -> 0 | F31: =INTMARB_IN!F31+INTMARB_EX!F31 -> 0 | G31: =INTMARB_IN!G31+INTMARB_EX!G31 -> 0 | H31: =INTMARB_IN!H31+INTMARB_EX!H31 -> 0 | I31: =INTMARB_IN!I31+INTMARB_EX!I31 -> 0 | J31: =INTMARB_IN!J31+INTMARB_EX!J31 -> 0 | ... X31: =INTMARB_IN!X31+INTMARB_EX!X31 -> 0
A32: Other hydrocarbons | B32: O4500 | C32: =INTMARB_IN!C32+INTMARB_EX!C32 -> 0 | D32: =INTMARB_IN!D32+INTMARB_EX!D32 -> 0 | E32: =INTMARB_IN!E32+INTMARB_EX!E32 -> 0 | F32: =INTMARB_IN!F32+INTMARB_EX!F32 -> 0 | G32: =INTMARB_IN!G32+INTMARB_EX!G32 -> 0 | H32: =INTMARB_IN!H32+INTMARB_EX!H32 -> 0 | I32: =INTMARB_IN!I32+INTMARB_EX!I32 -> 0 | J32: =INTMARB_IN!J32+INTMARB_EX!J32 -> 0 | ... X32: =INTMARB_IN!X32+INTMARB_EX!X32 -> 0
A33: Oil products (excluding biofuel portion) | B33: O4600XBIO | C33: =SUM(C34:C50) -> 0 | D33: =SUM(D34:D50) -> 0 | E33: =SUM(E34:E50) -> 0 | F33: =SUM(F34:F50) -> 0 | G33: =SUM(G34:G50) -> 0 | H33: =SUM(H34:H50) -> 0 | I33: =SUM(I34:I50) -> 0 | J33: =SUM(J34:J50) -> 0 | ... X33: =SUM(X34:X50) -> 0
A34: Refinery gas | B34: O4610 | C34: =INTMARB_IN!C34+INTMARB_EX!C34 -> 0 | D34: =INTMARB_IN!D34+INTMARB_EX!D34 -> 0 | E34: =INTMARB_IN!E34+INTMARB_EX!E34 -> 0 | F34: =INTMARB_IN!F34+INTMARB_EX!F34 -> 0 | G34: =INTMARB_IN!G34+INTMARB_EX!G34 -> 0 | H34: =INTMARB_IN!H34+INTMARB_EX!H34 -> 0 | I34: =INTMARB_IN!I34+INTMARB_EX!I34 -> 0 | J34: =INTMARB_IN!J34+INTMARB_EX!J34 -> 0 | ... X34: =INTMARB_IN!X34+INTMARB_EX!X34 -> 0
A35: Ethane | B35: O4620 | C35: =INTMARB_IN!C35+INTMARB_EX!C35 -> 0 | D35: =INTMARB_IN!D35+INTMARB_EX!D35 -> 0 | E35: =INTMARB_IN!E35+INTMARB_EX!E35 -> 0 | F35: =INTMARB_IN!F35+INTMARB_EX!F35 -> 0 | G35: =INTMARB_IN!G35+INTMARB_EX!G35 -> 0 | H35: =INTMARB_IN!H35+INTMARB_EX!H35 -> 0 | I35: =INTMARB_IN!I35+INTMARB_EX!I35 -> 0 | J35: =INTMARB_IN!J35+INTMARB_EX!J35 -> 0 | ... X35: =INTMARB_IN!X35+INTMARB_EX!X35 -> 0
A36: Liquefied petroleum gases | B36: O4630 | C36: =INTMARB_IN!C36+INTMARB_EX!C36 -> 0 | D36: =INTMARB_IN!D36+INTMARB_EX!D36 -> 0 | E36: =INTMARB_IN!E36+INTMARB_EX!E36 -> 0 | F36: =INTMARB_IN!F36+INTMARB_EX!F36 -> 0 | G36: =INTMARB_IN!G36+INTMARB_EX!G36 -> 0 | H36: =INTMARB_IN!H36+INTMARB_EX!H36 -> 0 | I36: =INTMARB_IN!I36+INTMARB_EX!I36 -> 0 | J36: =INTMARB_IN!J36+INTMARB_EX!J36 -> 0 | ... X36: =INTMARB_IN!X36+INTMARB_EX!X36 -> 0
A37: Motor gasoline (excluding biofuel portion) | B37: O4652XR5210B | C37: =INTMARB_IN!C37+INTMARB_EX!C37 -> 0 | D37: =INTMARB_IN!D37+INTMARB_EX!D37 -> 0 | E37: =INTMARB_IN!E37+INTMARB_EX!E37 -> 0 | F37: =INTMARB_IN!F37+INTMARB_EX!F37 -> 0 | G37: =INTMARB_IN!G37+INTMARB_EX!G37 -> 0 | H37: =INTMARB_IN!H37+INTMARB_EX!H37 -> 0 | I37: =INTMARB_IN!I37+INTMARB_EX!I37 -> 0 | J37: =INTMARB_IN!J37+INTMARB_EX!J37 -> 0 | ... X37: =INTMARB_IN!X37+INTMARB_EX!X37 -> 0
A38: Aviation gasoline | B38: O4651 | C38: =INTMARB_IN!C38+INTMARB_EX!C38 -> 0 | D38: =INTMARB_IN!D38+INTMARB_EX!D38 -> 0 | E38: =INTMARB_IN!E38+INTMARB_EX!E38 -> 0 | F38: =INTMARB_IN!F38+INTMARB_EX!F38 -> 0 | G38: =INTMARB_IN!G38+INTMARB_EX!G38 -> 0 | H38: =INTMARB_IN!H38+INTMARB_EX!H38 -> 0 | I38: =INTMARB_IN!I38+INTMARB_EX!I38 -> 0 | J38: =INTMARB_IN!J38+INTMARB_EX!J38 -> 0 | ... X38: =INTMARB_IN!X38+INTMARB_EX!X38 -> 0
A39: Gasoline-type jet fuel | B39: O4653 | C39: =INTMARB_IN!C39+INTMARB_EX!C39 -> 0 | D39: =INTMARB_IN!D39+INTMARB_EX!D39 -> 0 | E39: =INTMARB_IN!E39+INTMARB_EX!E39 -> 0 | F39: =INTMARB_IN!F39+INTMARB_EX!F39 -> 0 | G39: =INTMARB_IN!G39+INTMARB_EX!G39 -> 0 | H39: =INTMARB_IN!H39+INTMARB_EX!H39 -> 0 | I39: =INTMARB_IN!I39+INTMARB_EX!I39 -> 0 | J39: =INTMARB_IN!J39+INTMARB_EX!J39 -> 0 | ... X39: =INTMARB_IN!X39+INTMARB_EX!X39 -> 0
A40: Kerosene-type jet fuel (excluding biofuel portion) | B40: O4661XR5230B | C40: =INTMARB_IN!C40+INTMARB_EX!C40 -> 0 | D40: =INTMARB_IN!D40+INTMARB_EX!D40 -> 0 | E40: =INTMARB_IN!E40+INTMARB_EX!E40 -> 0 | F40: =INTMARB_IN!F40+INTMARB_EX!F40 -> 0 | G40: =INTMARB_IN!G40+INTMARB_EX!G40 -> 0 | H40: =INTMARB_IN!H40+INTMARB_EX!H40 -> 0 | I40: =INTMARB_IN!I40+INTMARB_EX!I40 -> 0 | J40: =INTMARB_IN!J40+INTMARB_EX!J40 -> 0 | ... X40: =INTMARB_IN!X40+INTMARB_EX!X40 -> 0
...

Sheet INTMARB_IN
A1: International Intra-EEA maritime bunkers | B1: INTMARB_IN | C1: 2000 | D1: 2001 | E1: 2002 | F1: 2003 | G1: 2004 | H1: 2005 | I1: 2006 | J1: 2007 | K1: 2008 | L1: 2009 | M1: 2010 | N1: 2011 | O1: 2012 | P1: 2013 | Q1: 2014 | R1: 2015 | S1: 2016 | T1: 2017 | U1: 2018 | V1: 2019 | W1: 2020 | X1: 2021
A2: Total | B2: TOTAL | C2: =SUM(C3,C17,C22,C25,C26,C51,C52) -> 0 | D2: =SUM(D3,D17,D22,D25,D26,D51,D52) -> 0 | E2: =SUM(E3,E17,E22,E25,E26,E51,E52) -> 0 | F2: =SUM(F3,F17,F22,F25,F26,F51,F52) -> 0 | G2: =SUM(G3,G17,G22,G25,G26,G51,G52) -> 0 | H2: =SUM(H3,H17,H22,H25,H26,H51,H52) -> 0 | I2: =SUM(I3,I17,I22,I25,I26,I51,I52) -> 0 | J2: =SUM(J3,J17,J22,J25,J26,J51,J52) -> 0 | ... X2: =SUM(X3,X17,X22,X25,X26,X51,X52) -> 0
A3: Solid fossil fuels | B3: C0000X0350-0370 | C3: =SUM(C4,C8,C11) -> 0 | D3: =SUM(D4,D8,D11) -> 0 | E3: =SUM(E4,E8,E11) -> 0 | F3: =SUM(F4,F8,F11) -> 0 | G3: =SUM(G4,G8,G11) -> 0 | H3: =SUM(H4,H8,H11) -> 0 | I3: =SUM(I4,I8,I11) -> 0 | J3: =SUM(J4,J8,J11) -> 0 | ... X3: =SUM(X4,X8,X11) -> 0
A4: Hard coal | B4: C0100 | C4: =SUM(C5:C7) -> 0 | D4: =SUM(D5:D7) -> 0 | E4: =SUM(E5:E7) -> 0 | F4: =SUM(F5:F7) -> 0 | G4: =SUM(G5:G7) -> 0 | H4: =SUM(H5:H7) -> 0 | I4: =SUM(I5:I7) -> 0 | J4: =SUM(J5:J7) -> 0 | ... X4: =SUM(X5:X7) -> 0
A5: Anthracite | B5: C0110 | C5: 0 | D5: 0 | E5: 0 | F5: 0 | G5: 0 | H5: 0 | I5: 0 | J5: 0 | K5: 0 | L5: 0 | M5: 0 | N5: 0 | O5: 0 | P5: 0 | Q5: 0 | R5: 0 | S5: 0 | T5: 0 | U5: 0 | V5: 0 | W5: 0 | X5: 0
