Workbook

Sheet Input
A1: Subsector | B1: Unit | C1: 2000 | D1: 2001 | E1: 2002 | F1: 2003 | G1: 2004 | H1: 2005 | I1: 2006 | J1: 2007 | K1: 2008 | L1: 2009 | M1: 2010 | N1: 2011 | O1: 2012 | P1: 2013 | Q1: 2014 | R1: 2015 | S1: 2016 | T1: 2017 | U1: 2018 | V1: 2019 | W1: 2020 | X1: 2021
A2: Iron and Steel | B2: ktoe | C2: =Ind_Summary!B52 -> 34962.264 | D2: =Ind_Summary!C52 -> 33652.878 | E2: =Ind_Summary!D52 -> 33212.353 | F2: =Ind_Summary!E52 -> 34789.524 | G2: =Ind_Summary!F52 -> 35078.79 | H2: =Ind_Summary!G52 -> 33523.186 | I2: =Ind_Summary!H52 -> 34387.138 | J2: =Ind_Summary!I52 -> 33041.72 | ... X2: =Ind_Summary!W52 -> 24254.125
A3: Alumina production | B3: ktoe | C3: =Ind_Summary!B56 -> 2096.8088 | D3: =Ind_Summary!C56 -> 1865.7611 | E3: =Ind_Summary!D56 -> 2186.8933 | F3: =Ind_Summary!E56 -> 2244.3132 | G3: =Ind_Summary!F56 -> 2441.3271 | H3: =Ind_Summary!G56 -> 2327.7645 | I3: =Ind_Summary!H56 -> 2394.5086 | J3: =Ind_Summary!I56 -> 2170.0965 | ... X3: =Ind_Summary!W56 -> 2038.6082
A4: Aluminium production | B4: ktoe | C4: =Ind_Summary!B57 -> 4069.95 | D4: =Ind_Summary!C57 -> 4151.2973 | E4: =Ind_Summary!D57 -> 4158.132 | F4: =Ind_Summary!E57 -> 4135.7527 | G4: =Ind_Summary!F57 -> 4305.9417 | H4: =Ind_Summary!G57 -> 4313.4739 | I4: =Ind_Summary!H57 -> 4032.1734 | J4: =Ind_Summary!I57 -> 4209.744 | ... X4: =Ind_Summary!W57 -> 2998.8014
A5: Other non-ferrous metals | B5: ktoe | C5: =Ind_Summary!B60 -> 4939.1116 | D5: =Ind_Summary!C60 -> 5113.3379 | E5: =Ind_Summary!D60 -> 4943.2945 | F5: =Ind_Summary!E60 -> 4703.615 | G5: =Ind_Summary!F60 -> 4794.2546 | H5: =Ind_Summary!G60 -> 4631.1963 | I5: =Ind_Summary!H60 -> 4379.3038 | J5: =Ind_Summary!I60 -> 4496.543 | ... X5: =Ind_Summary!W60 -> 4459.842
A6: Basic chemicals | B6: ktoe | C6: {=Ind_Summary!B62:B64} -> 29023.406 | D6: {=Ind_Summary!C62:C64} -> 28883.147 | E6: {=Ind_Summary!D62:D64} -> 30079.248 | F6: {=Ind_Summary!E62:E64} -> 32198.12 | G6: {=Ind_Summary!F62:F64} -> 30879.451 | H6: {=Ind_Summary!G62:G64} -> 31467.312 | I6: {=Ind_Summary!H62:H64} -> 30959.746 | J6: {=Ind_Summary!I62:I64} -> 32315.036 | ... X6: {=Ind_Summary!W62:W64} -> 33940.034
A7: Other chemicals | B7: ktoe | C7: 17694.748 | D7: 17375.008 | E7: 16371.508 | F7: 17459.757 | G7: 16528.289 | H7: 16537.043 | I7: 15456.134 | J7: 16463.296 | K7: 14979.294 | L7: 13403.308 | M7: 13133.086 | N7: 14655.155 | O7: 14801.768 | P7: 13746.618 | Q7: 13124.868 | R7: 11723.074 | S7: 12110.514 | T7: 11541.317 | U7: 12781.552 | V7: 12231.147 | W7: 13089.524 | X7: 13297.354
A8: Pharmaceutical products | B8: ktoe | C8: 3633.311 | D8: 3917.2429 | E8: 4062.5491 | F8: 4117.6141 | G8: 3992.558 | H8: 4019.0207 | I8: 4076.1281 | J8: 4119.8204 | K8: 4096.4183 | L8: 3959.0242 | M8: 3930.499 | N8: 4007.0064 | O8: 3980.5074 | P8: 3966.5083 | Q8: 4848.2662 | R8: 4533.7834 | S8: 4801.5504 | T8: 4509.3088 | U8: 4449.7859 | V8: 4606.6888 | W8: 4489.2602 | X8: 4525.845
A9: Cement | B9: ktoe | C9: =Ind_Summary!B66 -> 18262.728 | D9: =Ind_Summary!C66 -> 17905.354 | E9: =Ind_Summary!D66 -> 17666.657 | F9: =Ind_Summary!E66 -> 18042.232 | G9: =Ind_Summary!F66 -> 18543.963 | H9: =Ind_Summary!G66 -> 18439.648 | I9: =Ind_Summary!H66 -> 19831.912 | J9: =Ind_Summary!I66 -> 20042.657 | ... X9: =Ind_Summary!W66 -> 12931.981
A10: Ceramics & other non metallic minerals | B10: ktoe | C10: =Ind_Summary!B67 -> 17090.493 | D10: =Ind_Summary!C67 -> 17556.2 | E10: =Ind_Summary!D67 -> 16882.715 | F10: =Ind_Summary!E67 -> 17889.112 | G10: =Ind_Summary!F67 -> 18019.256 | H10: =Ind_Summary!G67 -> 18967.154 | I10: =Ind_Summary!H67 -> 16157.992 | J10: =Ind_Summary!I67 -> 17150.997 | ... X10: =Ind_Summary!W67 -> 16143.532
A11: Glass production | B11: ktoe | C11: =Ind_Summary!B68 -> 6606.2816 | D11: =Ind_Summary!C68 -> 6649.4758 | E11: =Ind_Summary!D68 -> 6606.3339 | F11: =Ind_Summary!E68 -> 6562.161 | G11: =Ind_Summary!F68 -> 6630.9577 | H11: =Ind_Summary!G68 -> 6431.7289 | I11: =Ind_Summary!H68 -> 6630.7509 | J11: =Ind_Summary!I68 -> 6572.8479 | ... X11: =Ind_Summary!W68 -> 5285.277
A12: Pulp | B12: ktoe | C12: =Ind_Summary!B70 -> 11402.536 | D12: =Ind_Summary!C70 -> 10875.657 | E12: =Ind_Summary!D70 -> 10997.329 | F12: =Ind_Summary!E70 -> 11336.455 | G12: =Ind_Summary!F70 -> 11180.016 | H12: =Ind_Summary!G70 -> 11193.386 | I12: =Ind_Summary!H70 -> 11657.385 | J12: =Ind_Summary!I70 -> 12202.246 | ... X12: =Ind_Summary!W70 -> 11469.134
A13: Paper | B13: ktoe | C13: =Ind_Summary!B71 -> 19354.06 | D13: =Ind_Summary!C71 -> 19094.398 | E13: =Ind_Summary!D71 -> 19381.661 | F13: =Ind_Summary!E71 -> 20003.927 | G13: =Ind_Summary!F71 -> 20280.714 | H13: =Ind_Summary!G71 -> 20738.536 | I13: =Ind_Summary!H71 -> 21153.931 | J13: =Ind_Summary!I71 -> 21559.857 | ... X13: =Ind_Summary!W71 -> 19702.793
A14: Printing | B14: ktoe | C14: =Ind_Summary!B72 -> 2125.8535 | D14: =Ind_Summary!C72 -> 2095.9996 | E14: =Ind_Summary!D72 -> 2147.4184 | F14: =Ind_Summary!E72 -> 2254.4389 | G14: =Ind_Summary!F72 -> 2243.2535 | H14: =Ind_Summary!G72 -> 2302.5304 | I14: =Ind_Summary!H72 -> 2267.2044 | J14: =Ind_Summary!I72 -> 2287.8696 | ... X14: =Ind_Summary!W72 -> 1760.1245
A15: Food, beverages and tobacco | B15: ktoe | C15: {=Ind_Summary!B73:B78} -> 27523.258 | D15: {=Ind_Summary!C73:C78} -> 28034.955 | E15: {=Ind_Summary!D73:D78} -> 29053.044 | F15: {=Ind_Summary!E73:E78} -> 29365.401 | G15: {=Ind_Summary!F73:F78} -> 29139.458 | H15: {=Ind_Summary!G73:G78} -> 27792.686 | I15: {=Ind_Summary!H73:H78} -> 26413.493 | J15: {=Ind_Summary!I73:I78} -> 26711.057 | ... X15: {=Ind_Summary!W73:W78} -> 28856.39
A16: Transport | B16: ktoe | C16: 7903.1143 | D16: 8116.6778 | E16: 7786.9555 | F16: 8372.7358 | G16: 8534.5877 | H16: 8168.2974 | I16: 7960.6091 | J16: 8048.9764 | K16: 7620.3167 | L16: 6609.5721 | M16: 7209.1987 | N16: 6970.2777 | O16: 6990.5928 | P16: 7157.1659 | Q16: 6819.5574 | R16: 6848.1311 | S16: 7312.2467 | T16: 7407.4818 | U16: 7541.5283 | V16: 7418.4927 | W16: 6740.075 | X16: 7101.3573
A17: Machinery | B17: ktoe | C17: 16979.065 | D17: 17468.03 | E17: 17198.763 | F17: 18906.963 | G17: 19102.152 | H17: 18915.427 | I17: 18976.044 | J17: 18962.084 | K17: 19855.489 | L17: 17118.53 | M17: 18413.481 | N17: 17949.657 | O17: 17477.503 | P17: 17722.46 | Q17: 17059.18 | R17: 16690.721 | S17: 16920.817 | T17: 17271.153 | U17: 17197.302 | V17: 16962.771 | W17: 15701.618 | X17: 17200.32
A18: Textiles and leather | B18: ktoe | C18: 9756.8662 | D18: 9639.134 | E18: 9577.9515 | F18: 9479.1234 | G18: 8837.7845 | H18: 7195.162 | I18: 6577.9182 | J18: 5987.7418 | K18: 5302.7822 | L18: 4491.0013 | M18: 4438.2117 | N18: 4203.999 | O18: 3998.9403 | P18: 3858.8471 | Q18: 3713.9529 | R18: 3698.6624 | S18: 3691.6153 | T18: 3718.814 | U18: 3698.311 | V18: 3612.7445 | W18: 3216.7386 | X18: 3385.32
A19: Wood and wood products | B19: ktoe | C19: 6474.7755 | D19: 6176.1692 | E19: 6287.0276 | F19: 6877.9886 | G19: 7619.966 | H19: 7275.2361 | I19: 7003.2611 | J19: 7567.0062 | K19: 7440.0606 | L19: 7165.6225 | M19: 7749.0222 | N19: 7893.793 | O19: 7874.2085 | P19: 7987.5183 | Q19: 7834.0084 | R19: 8092.0054 | S19: 8503.8499 | T19: 8635.457 | U19: 8757.0609 | V19: 8542.6089 | W19: 8609.5844 | X19: 9358.8496
A20: Other industrial sectors | B20: ktoe | C20: 29485.491 | D20: 29857.012 | E20: 29705.167 | F20: 26331.401 | G20: 26257.055 | H20: 30691.493 | I20: 29225.235 | J20: 30331.053 | K20: 29560.27 | L20: 24531.86 | M20: 27262.592 | N20: 22754.898 | O20: 23061.201 | P20: 22617.047 | Q20: 22203.601 | R20: 21687.028 | S20: 22128.596 | T20: 22547.57 | U20: 23343.019 | V20: 24263.346 | W20: 22627.902 | X20: 24922.137
A21: Powered two-wheelers | B21: pkm | C21: =Transport_Summary!B6 -> 98941.119 | D21: =Transport_Summary!C6 -> 102907.78 | E21: =Transport_Summary!D6 -> 104221.44 | F21: =Transport_Summary!E6 -> 107273.63 | G21: =Transport_Summary!F6 -> 110798.04 | H21: =Transport_Summary!G6 -> 114310.05 | I21: =Transport_Summary!H6 -> 113240.02 | J21: =Transport_Summary!I6 -> 109248.07 | ... X21: =Transport_Summary!W6 -> 104773.52
A22: Passenger cars | B22: pkm | C22: =Transport_Summary!B7 -> 3660355.1 | D22: =Transport_Summary!C7 -> 3734215.8 | E22: =Transport_Summary!D7 -> 3789305 | F22: =Transport_Summary!E7 -> 3826195.6 | G22: =Transport_Summary!F7 -> 3878162.7 | H22: =Transport_Summary!G7 -> 3839179.5 | I22: =Transport_Summary!H7 -> 3875261.4 | J22: =Transport_Summary!I7 -> 3921256.1 | ... X22: =Transport_Summary!W7 -> 3742236.2
A23: Motor coaches, buses and trolley buses | B23: pkm | C23: =Transport_Summary!B8 -> 496482.35 | D23: =Transport_Summary!C8 -> 495609.93 | E23: =Transport_Summary!D8 -> 492831.8 | F23: =Transport_Summary!E8 -> 495565.18 | G23: =Transport_Summary!F8 -> 500165.37 | H23: =Transport_Summary!G8 -> 497755.43 | I23: =Transport_Summary!H8 -> 497841.22 | J23: =Transport_Summary!I8 -> 507883.21 | ... X23: =Transport_Summary!W8 -> 327011.46
A24: Metro and tram, urban light rail | B24: pkm | C24: =Transport_Summary!B10 -> 67843.841 | D24: =Transport_Summary!C10 -> 68539.657 | E24: =Transport_Summary!D10 -> 69374.813 | F24: =Transport_Summary!E10 -> 70183.362 | G24: =Transport_Summary!F10 -> 72445.633 | H24: =Transport_Summary!G10 -> 73154.697 | I24: =Transport_Summary!H10 -> 74583.334 | J24: =Transport_Summary!I10 -> 76350.816 | ... X24: =Transport_Summary!W10 -> 55543.667
A25: Conventional passenger trains | B25: pkm | C25: =Transport_Summary!B11 -> 279790.79 | D25: =Transport_Summary!C11 -> 274768.58 | E25: =Transport_Summary!D11 -> 263902.8 | F25: =Transport_Summary!E11 -> 256117.95 | G25: =Transport_Summary!F11 -> 256276 | H25: =Transport_Summary!G11 -> 260161 | I25: =Transport_Summary!H11 -> 265968 | J25: =Transport_Summary!I11 -> 265333.41 | ... X25: =Transport_Summary!W11 -> 180012.79
A26: High speed passenger trains | B26: pkm | C26: =Transport_Summary!B12 -> 58796 | D26: =Transport_Summary!C12 -> 65126 | E26: =Transport_Summary!D12 -> 68005 | F26: =Transport_Summary!E12 -> 70661 | G26: =Transport_Summary!F12 -> 75671 | H26: =Transport_Summary!G12 -> 79663 | I26: =Transport_Summary!H12 -> 83411 | J26: =Transport_Summary!I12 -> 87303 | ... X26: =Transport_Summary!W12 -> 85223.348
A27: Aviation-Domestic-pass | B27: pkm | C27: =Transport_Summary!B23 -> 415.25357 | D27: =Transport_Summary!C23 -> 449.12623 | E27: =Transport_Summary!D23 -> 415.26836 | F27: =Transport_Summary!E23 -> 378.82428 | G27: =Transport_Summary!F23 -> 380.32001 | H27: =Transport_Summary!G23 -> 360.57706 | I27: =Transport_Summary!H23 -> 346.13194 | J27: =Transport_Summary!I23 -> 331.94182 | ... X27: =Transport_Summary!W23 -> 272.01753
A28: Aviation -International - Intra-EEAwUK - pass | B28: pkm | C28: =Transport_Summary!B24 -> 1584.2302 | D28: =Transport_Summary!C24 -> 1548.4561 | E28: =Transport_Summary!D24 -> 1535.2549 | F28: =Transport_Summary!E24 -> 1581.5275 | G28: =Transport_Summary!F24 -> 1654.9073 | H28: =Transport_Summary!G24 -> 1736.1596 | I28: =Transport_Summary!H24 -> 1852.1549 | J28: =Transport_Summary!I24 -> 1933.5623 | ... X28: =Transport_Summary!W24 -> 2490.2632
A29: Aviation-International - Extra-EEAwUK - pass | B29: pkm | C29: =Transport_Summary!B25 -> 23991.021 | D29: =Transport_Summary!C25 -> 23152.905 | E29: =Transport_Summary!D25 -> 23661.378 | F29: =Transport_Summary!E25 -> 23815.633 | G29: =Transport_Summary!F25 -> 25302.473 | H29: =Transport_Summary!G25 -> 27064.854 | I29: =Transport_Summary!H25 -> 29060.007 | J29: =Transport_Summary!I25 -> 31412.417 | ... X29: =Transport_Summary!W25 -> 43763.184
A30: Light commercial vehicles | B30: tkm | C30: =Transport_Summary!B19 -> 67104.703 | D30: =Transport_Summary!C19 -> 70599.781 | E30: =Transport_Summary!D19 -> 71782.892 | F30: =Transport_Summary!E19 -> 74503.485 | G30: =Transport_Summary!F19 -> 76766.809 | H30: =Transport_Summary!G19 -> 78469.885 | I30: =Transport_Summary!H19 -> 79352.372 | J30: =Transport_Summary!I19 -> 83381.785 | ... X30: =Transport_Summary!W19 -> 96224.81
A31: Heavy goods vehicles | B31: tkm | C31: =Transport_Summary!B20 -> 1307595.6 | D31: =Transport_Summary!C20 -> 1351666.6 | E31: =Transport_Summary!D20 -> 1399280.5 | F31: =Transport_Summary!E20 -> 1401310.6 | G31: =Transport_Summary!F20 -> 1545325.8 | H31: =Transport_Summary!G20 -> 1588632.5 | I31: =Transport_Summary!H20 -> 1639241.1 | J31: =Transport_Summary!I20 -> 1698163.7 | ... X31: =Transport_Summary!W20 -> 1862843.7
A32: Rail transport | B32: tkm | C32: =Transport_Summary!B21 -> 387920.75 | D32: =Transport_Summary!C21 -> 369253.3 | E32: =Transport_Summary!D21 -> 368161.19 | F32: =Transport_Summary!E21 -> 376309.27 | G32: =Transport_Summary!F21 -> 390035 | H32: =Transport_Summary!G21 -> 394597 | I32: =Transport_Summary!H21 -> 416246 | J32: =Transport_Summary!I21 -> 430724 | ... X32: =Transport_Summary!W21 -> 409571.98
A33: Aviation-Domestic-goods | B33: tkm | C33: =Transport_Summary!B23 -> 415.25357 | D33: =Transport_Summary!C23 -> 449.12623 | E33: =Transport_Summary!D23 -> 415.26836 | F33: =Transport_Summary!E23 -> 378.82428 | G33: =Transport_Summary!F23 -> 380.32001 | H33: =Transport_Summary!G23 -> 360.57706 | I33: =Transport_Summary!H23 -> 346.13194 | J33: =Transport_Summary!I23 -> 331.94182 | ... X33: =Transport_Summary!W23 -> 272.01753
A34: Aviation-International - Intra-EEAwUK - goods | B34: tkm | C34: =Transport_Summary!B24 -> 1584.2302 | D34: =Transport_Summary!C24 -> 1548.4561 | E34: =Transport_Summary!D24 -> 1535.2549 | F34: =Transport_Summary!E24 -> 1581.5275 | G34: =Transport_Summary!F24 -> 1654.9073 | H34: =Transport_Summary!G24 -> 1736.1596 | I34: =Transport_Summary!H24 -> 1852.1549 | J34: =Transport_Summary!I24 -> 1933.5623 | ... X34: =Transport_Summary!W24 -> 2490.2632
A35: Aviation-International - Extra-EEAwUK - goods | B35: tkm | C35: =Transport_Summary!B25 -> 23991.021 | D35: =Transport_Summary!C25 -> 23152.905 | E35: =Transport_Summary!D25 -> 23661.378 | F35: =Transport_Summary!E25 -> 23815.633 | G35: =Transport_Summary!F25 -> 25302.473 | H35: =Transport_Summary!G25 -> 27064.854 | I35: =Transport_Summary!H25 -> 29060.007 | J35: =Transport_Summary!I25 -> 31412.417 | ... X35: =Transport_Summary!W25 -> 43763.184
A36: Shipping-Domestic coastal shipping | B36: tkm | C36: =Transport_Summary!B27 -> 76596.154 | D36: =Transport_Summary!C27 -> 64020.692 | E36: =Transport_Summary!D27 -> 66795.686 | F36: =Transport_Summary!E27 -> 67745.405 | G36: =Transport_Summary!F27 -> 68197.284 | H36: =Transport_Summary!G27 -> 73544.828 | I36: =Transport_Summary!H27 -> 83935.32 | J36: =Transport_Summary!I27 -> 78202.846 | ... X36: =Transport_Summary!W27 -> 76906.865
A37: Inland waterways | B37: tkm | C37: =Transport_Summary!B28 -> 133714.89 | D37: =Transport_Summary!C28 -> 132416.24 | E37: =Transport_Summary!D28 -> 132414.02 | F37: =Transport_Summary!E28 -> 123435.09 | G37: =Transport_Summary!F28 -> 136763.15 | H37: =Transport_Summary!G28 -> 138610.97 | I37: =Transport_Summary!H28 -> 138416.97 | J37: =Transport_Summary!I28 -> 145402 | ... X37: =Transport_Summary!W28 -> 136076
A38: Maritime - Intra -EEA | B38: tkm | C38: =Transport_Summary!B30 -> 753767.24 | D38: =Transport_Summary!C30 -> 780873.54 | E38: =Transport_Summary!D30 -> 793361.74 | F38: =Transport_Summary!E30 -> 807199.9 | G38: =Transport_Summary!F30 -> 831866.45 | H38: =Transport_Summary!G30 -> 834011.02 | I38: =Transport_Summary!H30 -> 820751.75 | J38: =Transport_Summary!I30 -> 821736.85 | ... X38: =Transport_Summary!W30 -> 910620.85
A39: Maritime - Extra -EEA | B39: tkm | C39: =Transport_Summary!B31 -> 4573090.2 | D39: =Transport_Summary!C31 -> 4819707.4 | E39: =Transport_Summary!D31 -> 4967035 | F39: =Transport_Summary!E31 -> 5164281.6 | G39: =Transport_Summary!F31 -> 5478738.6 | H39: =Transport_Summary!G31 -> 5953900.1 | I39: =Transport_Summary!H31 -> 6298476.3 | J39: =Transport_Summary!I31 -> 6547982.1 | ... X39: =Transport_Summary!W31 -> 7225198.3
A40: {=Ind_Summary!A183:A199} -> Physical output (kt steel) | B40: kt steel | C40: {=Ind_Summary!B183:W199} -> 178302.96 | D40: 173967.12 | E40: 176612.33 | F40: 179594.14 | G40: 189153.78 | H40: 182842.14 | I40: 193920.21 | J40: 196436.23 | K40: 185657.5 | L40: 129607.85 | M40: 163517.16 | N40: 168684.94 | O40: 159423.27 | P40: 154916.42 | Q40: 157583.15 | R40: 155891.06 | S40: 155050.79 | T40: 161445.48 | U40: 160522.41 | V40: 150695.08 | W40: 132660.64 | X40: 153098.7
...

Sheet Description
A1: Industry
A35: Transport

Sheet Ind_Summary
A1: =[1]index!$A$1&": Industry Summary" -> EU27: Industry Summary | B1: 2000 | C1: 2001 | D1: 2002 | E1: 2003 | F1: 2004 | G1: 2005 | H1: 2006 | I1: 2007 | J1: 2008 | K1: 2009 | L1: 2010 | M1: 2011 | N1: 2012 | O1: 2013 | P1: 2014 | Q1: 2015 | R1: 2016 | S1: 2017 | T1: 2018 | U1: 2019 | V1: 2020 | W1: 2021
A3: Value added (M€2015) | B3: =[1]ISI!B$3+[1]NFM!B$3+[1]CHI!B$3+[1]NMM!B$3+[1]PPA!B$3+[1]FBT!B$3+[1]TRE!B$3+[1]MAE!B$3+[1]TEL!B$3+[1]WWP!B$3+[1]OIS!B$3 -> 2245126.6 | C3: =[1]ISI!C$3+[1]NFM!C$3+[1]CHI!C$3+[1]NMM!C$3+[1]PPA!C$3+[1]FBT!C$3+[1]TRE!C$3+[1]MAE!C$3+[1]TEL!C$3+[1]WWP!C$3+[1]OIS!C$3 -> 2262880.3 | D3: =[1]ISI!D$3+[1]NFM!D$3+[1]CHI!D$3+[1]NMM!D$3+[1]PPA!D$3+[1]FBT!D$3+[1]TRE!D$3+[1]MAE!D$3+[1]TEL!D$3+[1]WWP!D$3+[1]OIS!D$3 -> 2249191.8 | E3: =[1]ISI!E$3+[1]NFM!E$3+[1]CHI!E$3+[1]NMM!E$3+[1]PPA!E$3+[1]FBT!E$3+[1]TRE!E$3+[1]MAE!E$3+[1]TEL!E$3+[1]WWP!E$3+[1]OIS!E$3 -> 2232384.5 | F3: =[1]ISI!F$3+[1]NFM!F$3+[1]CHI!F$3+[1]NMM!F$3+[1]PPA!F$3+[1]FBT!F$3+[1]TRE!F$3+[1]MAE!F$3+[1]TEL!F$3+[1]WWP!F$3+[1]OIS!F$3 -> 2278946.6 | G3: =[1]ISI!G$3+[1]NFM!G$3+[1]CHI!G$3+[1]NMM!G$3+[1]PPA!G$3+[1]FBT!G$3+[1]TRE!G$3+[1]MAE!G$3+[1]TEL!G$3+[1]WWP!G$3+[1]OIS!G$3 -> 2306363.2 | H3: =[1]ISI!H$3+[1]NFM!H$3+[1]CHI!H$3+[1]NMM!H$3+[1]PPA!H$3+[1]FBT!H$3+[1]TRE!H$3+[1]MAE!H$3+[1]TEL!H$3+[1]WWP!H$3+[1]OIS!H$3 -> 2419628.4 | I3: =[1]ISI!I$3+[1]NFM!I$3+[1]CHI!I$3+[1]NMM!I$3+[1]PPA!I$3+[1]FBT!I$3+[1]TRE!I$3+[1]MAE!I$3+[1]TEL!I$3+[1]WWP!I$3+[1]OIS!I$3 -> 2510080.2 | ... W3: =[1]ISI!W$3+[1]NFM!W$3+[1]CHI!W$3+[1]NMM!W$3+[1]PPA!W$3+[1]FBT!W$3+[1]TRE!W$3+[1]MAE!W$3+[1]TEL!W$3+[1]WWP!W$3+[1]OIS!W$3 -> 2571109.1
A4: Iron and steel | B4: =[1]ISI!B$3 -> 53100.42 | C4: =[1]ISI!C$3 -> 50746.226 | D4: =[1]ISI!D$3 -> 47887.083 | E4: =[1]ISI!E$3 -> 47437.721 | F4: =[1]ISI!F$3 -> 53122.137 | G4: =[1]ISI!G$3 -> 55745.288 | H4: =[1]ISI!H$3 -> 59782.025 | I4: =[1]ISI!I$3 -> 66292.466 | ... W4: =[1]ISI!W$3 -> 42717.513
A5: Non-ferrous metals | B5: =[1]NFM!B$3 -> 18642.886 | C5: =[1]NFM!C$3 -> 17729.882 | D5: =[1]NFM!D$3 -> 16843.148 | E5: =[1]NFM!E$3 -> 16684.733 | F5: =[1]NFM!F$3 -> 18498.375 | G5: =[1]NFM!G$3 -> 19343.217 | H5: =[1]NFM!H$3 -> 20896.192 | I5: =[1]NFM!I$3 -> 23094.301 | ... W5: =[1]NFM!W$3 -> 24635.93
A6: Alumina production | B6: =[1]NFM!B$4 -> 1878.1418 | C6: =[1]NFM!C$4 -> 1841.0587 | D6: =[1]NFM!D$4 -> 1717.3534 | E6: =[1]NFM!E$4 -> 1758.1092 | F6: =[1]NFM!F$4 -> 1862.1894 | G6: =[1]NFM!G$4 -> 1930.9329 | H6: =[1]NFM!H$4 -> 2143.4984 | I6: =[1]NFM!I$4 -> 2141.8637 | ... W6: =[1]NFM!W$4 -> 1611.2178
A7: Aluminium production | B7: =[1]NFM!B$5 -> 8075.7262 | C7: =[1]NFM!C$5 -> 7673.7919 | D7: =[1]NFM!D$5 -> 7211.7123 | E7: =[1]NFM!E$5 -> 7087.1667 | F7: =[1]NFM!F$5 -> 7802.7863 | G7: =[1]NFM!G$5 -> 8172.9447 | H7: =[1]NFM!H$5 -> 8775.444 | I7: =[1]NFM!I$5 -> 9672.3501 | ... W7: =[1]NFM!W$5 -> 9630.8992
A8: Other non-ferrous metals | B8: =[1]NFM!B$8 -> 8689.0183 | C8: =[1]NFM!C$8 -> 8215.0312 | D8: =[1]NFM!D$8 -> 7914.0825 | E8: =[1]NFM!E$8 -> 7839.4574 | F8: =[1]NFM!F$8 -> 8833.3989 | G8: =[1]NFM!G$8 -> 9239.3392 | H8: =[1]NFM!H$8 -> 9977.2494 | I8: =[1]NFM!I$8 -> 11280.088 | ... W8: =[1]NFM!W$8 -> 13393.813
A9: Chemical industry | B9: =[1]CHI!B$3 -> 193919.38 | C9: =[1]CHI!C$3 -> 199916.85 | D9: =[1]CHI!D$3 -> 205177.77 | E9: =[1]CHI!E$3 -> 197591.11 | F9: =[1]CHI!F$3 -> 196428.92 | G9: =[1]CHI!G$3 -> 200474.55 | H9: =[1]CHI!H$3 -> 202142.72 | I9: =[1]CHI!I$3 -> 209114.86 | ... W9: =[1]CHI!W$3 -> 343099.86
A10: Basic chemicals | B10: =[1]CHI!B$5 -> 46231.892 | C10: =[1]CHI!C$5 -> 47451.23 | D10: =[1]CHI!D$5 -> 48230.988 | E10: =[1]CHI!E$5 -> 48337.568 | F10: =[1]CHI!F$5 -> 48758.35 | G10: =[1]CHI!G$5 -> 49158.516 | H10: =[1]CHI!H$5 -> 51309.176 | I10: =[1]CHI!I$5 -> 53506.921 | ... W10: =[1]CHI!W$5 -> 66143.799
A11: Other chemicals | B11: =[1]CHI!B$6 -> 75311.811 | C11: =[1]CHI!C$6 -> 71848.681 | D11: =[1]CHI!D$6 -> 69613.551 | E11: =[1]CHI!E$6 -> 64523.717 | F11: =[1]CHI!F$6 -> 66087.617 | G11: =[1]CHI!G$6 -> 66332.959 | H11: =[1]CHI!H$6 -> 65269.848 | I11: =[1]CHI!I$6 -> 67729.901 | ... W11: =[1]CHI!W$6 -> 78492.072
A12: Pharmaceutical products etc. | B12: =[1]CHI!B$7 -> 72375.675 | C12: =[1]CHI!C$7 -> 80616.942 | D12: =[1]CHI!D$7 -> 87333.227 | E12: =[1]CHI!E$7 -> 84729.822 | F12: =[1]CHI!F$7 -> 81582.956 | G12: =[1]CHI!G$7 -> 84983.071 | H12: =[1]CHI!H$7 -> 85563.694 | I12: =[1]CHI!I$7 -> 87878.037 | ... W12: =[1]CHI!W$7 -> 198463.99
A13: Non-metallic mineral products | B13: =[1]NMM!B$3 -> 83102.523 | C13: =[1]NMM!C$3 -> 81900.153 | D13: =[1]NMM!D$3 -> 81119.792 | E13: =[1]NMM!E$3 -> 78314.095 | F13: =[1]NMM!F$3 -> 78281.438 | G13: =[1]NMM!G$3 -> 78526.001 | H13: =[1]NMM!H$3 -> 81432.881 | I13: =[1]NMM!I$3 -> 85839.803 | ... W13: =[1]NMM!W$3 -> 68801.68
A14: Cement | B14: =[1]NMM!B$4 -> 35196.743 | C14: =[1]NMM!C$4 -> 34087.492 | D14: =[1]NMM!D$4 -> 34295.296 | E14: =[1]NMM!E$4 -> 32659.045 | F14: =[1]NMM!F$4 -> 32888.344 | G14: =[1]NMM!G$4 -> 32140.667 | H14: =[1]NMM!H$4 -> 37443.88 | I14: =[1]NMM!I$4 -> 38496.6 | ... W14: =[1]NMM!W$4 -> 28724.58
A15: Ceramics & other NMM | B15: =[1]NMM!B$5 -> 28926.049 | C15: =[1]NMM!C$5 -> 28863.703 | D15: =[1]NMM!D$5 -> 27823.622 | E15: =[1]NMM!E$5 -> 27820.103 | F15: =[1]NMM!F$5 -> 27906.589 | G15: =[1]NMM!G$5 -> 29329.082 | H15: =[1]NMM!H$5 -> 25891.048 | I15: =[1]NMM!I$5 -> 28751.896 | ... W15: =[1]NMM!W$5 -> 23947.257
A16: Glass production | B16: =[1]NMM!B$6 -> 18979.731 | C16: =[1]NMM!C$6 -> 18948.958 | D16: =[1]NMM!D$6 -> 19000.875 | E16: =[1]NMM!E$6 -> 17834.948 | F16: =[1]NMM!F$6 -> 17486.505 | G16: =[1]NMM!G$6 -> 17056.252 | H16: =[1]NMM!H$6 -> 18097.952 | I16: =[1]NMM!I$6 -> 18591.307 | ... W16: =[1]NMM!W$6 -> 16129.844
A17: Pulp, paper and printing | B17: =[1]PPA!B$3 -> 102266.93 | C17: =[1]PPA!C$3 -> 102223.72 | D17: =[1]PPA!D$3 -> 98398.675 | E17: =[1]PPA!E$3 -> 91628.116 | F17: =[1]PPA!F$3 -> 91118.193 | G17: =[1]PPA!G$3 -> 88785.749 | H17: =[1]PPA!H$3 -> 88766.538 | I17: =[1]PPA!I$3 -> 88320.332 | ... W17: =[1]PPA!W$3 -> 64997.425
A18: Pulp production | B18: =[1]PPA!B$5 -> 3836.0169 | C18: =[1]PPA!C$5 -> 3726.9417 | D18: =[1]PPA!D$5 -> 3451.5807 | E18: =[1]PPA!E$5 -> 3226.4195 | F18: =[1]PPA!F$5 -> 3027.518 | G18: =[1]PPA!G$5 -> 2838.9293 | H18: =[1]PPA!H$5 -> 2864.5394 | I18: =[1]PPA!I$5 -> 2872.6666 | ... W18: =[1]PPA!W$5 -> 2312.9138
A19: Paper production | B19: =[1]PPA!B$6 -> 50660.307 | C19: =[1]PPA!C$6 -> 51606.38 | D19: =[1]PPA!D$6 -> 49260.601 | E19: =[1]PPA!E$6 -> 46159.853 | F19: =[1]PPA!F$6 -> 45559.871 | G19: =[1]PPA!G$6 -> 42938.71 | H19: =[1]PPA!H$6 -> 43131.989 | I19: =[1]PPA!I$6 -> 43718.278 | ... W19: =[1]PPA!W$6 -> 39759.805
A20: Printing and media reproduction | B20: =[1]PPA!B$7 -> 47770.61 | C20: =[1]PPA!C$7 -> 46890.403 | D20: =[1]PPA!D$7 -> 45686.493 | E20: =[1]PPA!E$7 -> 42241.844 | F20: =[1]PPA!F$7 -> 42530.804 | G20: =[1]PPA!G$7 -> 43008.11 | H20: =[1]PPA!H$7 -> 42770.01 | I20: =[1]PPA!I$7 -> 41729.388 | ... W20: =[1]PPA!W$7 -> 22924.705
A21: Food, beverages and tobacco | B21: =[1]FBT!B$3 -> 208952.2 | C21: =[1]FBT!C$3 -> 211827.24 | D21: =[1]FBT!D$3 -> 215633.04 | E21: =[1]FBT!E$3 -> 216594.91 | F21: =[1]FBT!F$3 -> 219048.63 | G21: =[1]FBT!G$3 -> 216546.27 | H21: =[1]FBT!H$3 -> 213861.77 | I21: =[1]FBT!I$3 -> 217217.69 | ... W21: =[1]FBT!W$3 -> 229494.04
A22: Transport equipment | B22: =[1]TRE!B$3 -> 184730.93 | C22: =[1]TRE!C$3 -> 193947.1 | D22: =[1]TRE!D$3 -> 194249.03 | E22: =[1]TRE!E$3 -> 197587.54 | F22: =[1]TRE!F$3 -> 196620.47 | G22: =[1]TRE!G$3 -> 196350.57 | H22: =[1]TRE!H$3 -> 210530.76 | I22: =[1]TRE!I$3 -> 219816.88 | ... W22: =[1]TRE!W$3 -> 245089.08
A23: Machinery equipment | B23: =[1]MAE!B$3 -> 530368.93 | C23: =[1]MAE!C$3 -> 521725.09 | D23: =[1]MAE!D$3 -> 507363.15 | E23: =[1]MAE!E$3 -> 502102.51 | F23: =[1]MAE!F$3 -> 517713.14 | G23: =[1]MAE!G$3 -> 523898.58 | H23: =[1]MAE!H$3 -> 558963.24 | I23: =[1]MAE!I$3 -> 587943.84 | ... W23: =[1]MAE!W$3 -> 582681.34
A24: Textiles and leather | B24: =[1]TEL!B$3 -> 94515.907 | C24: =[1]TEL!C$3 -> 94538.195 | D24: =[1]TEL!D$3 -> 90429.905 | E24: =[1]TEL!E$3 -> 85771.892 | F24: =[1]TEL!F$3 -> 81650.685 | G24: =[1]TEL!G$3 -> 76713.904 | H24: =[1]TEL!H$3 -> 75545.395 | I24: =[1]TEL!I$3 -> 76023.828 | ... W24: =[1]TEL!W$3 -> 60759.691
A25: Wood and wood products | B25: =[1]WWP!B$3 -> 41579.617 | C25: =[1]WWP!C$3 -> 41349.592 | D25: =[1]WWP!D$3 -> 39943.139 | E25: =[1]WWP!E$3 -> 39695.905 | F25: =[1]WWP!F$3 -> 40177.026 | G25: =[1]WWP!G$3 -> 39527.932 | H25: =[1]WWP!H$3 -> 41237.861 | I25: =[1]WWP!I$3 -> 43287.785 | ... W25: =[1]WWP!W$3 -> 43921.251
A26: Other industrial sectors | B26: =[1]OIS!B$3 -> 733946.86 | C26: =[1]OIS!C$3 -> 746976.2 | D26: =[1]OIS!D$3 -> 752147.03 | E26: =[1]OIS!E$3 -> 758975.94 | F26: =[1]OIS!F$3 -> 786287.54 | G26: =[1]OIS!G$3 -> 810451.1 | H26: =[1]OIS!H$3 -> 866468.97 | I26: =[1]OIS!I$3 -> 893128.38 | ... W26: =[1]OIS!W$3 -> 864911.33
A28: Energy consumption (ktoe)
A29: by fuel (EUROSTAT DATA) | B29: =[1]ISI!B25+[1]NFM!B43+[1]CHI!B32+[1]NMM!B31+[1]PPA!B32+[1]FBT!B12+[1]TRE!B12+[1]MAE!B12+[1]TEL!B12+[1]WWP!B12+[1]OIS!B12 -> 269384.12 | C29: =[1]ISI!C25+[1]NFM!C43+[1]CHI!C32+[1]NMM!C31+[1]PPA!C32+[1]FBT!C12+[1]TRE!C12+[1]MAE!C12+[1]TEL!C12+[1]WWP!C12+[1]OIS!C12 -> 268427.73 | D29: =[1]ISI!D25+[1]NFM!D43+[1]CHI!D32+[1]NMM!D31+[1]PPA!D32+[1]FBT!D12+[1]TRE!D12+[1]MAE!D12+[1]TEL!D12+[1]WWP!D12+[1]OIS!D12 -> 268305 | E29: =[1]ISI!E25+[1]NFM!E43+[1]CHI!E32+[1]NMM!E31+[1]PPA!E32+[1]FBT!E12+[1]TRE!E12+[1]MAE!E12+[1]TEL!E12+[1]WWP!E12+[1]OIS!E12 -> 275070.63 | F29: =[1]ISI!F25+[1]NFM!F43+[1]CHI!F32+[1]NMM!F31+[1]PPA!F32+[1]FBT!F12+[1]TRE!F12+[1]MAE!F12+[1]TEL!F12+[1]WWP!F12+[1]OIS!F12 -> 274409.78 | G29: =[1]ISI!G25+[1]NFM!G43+[1]CHI!G32+[1]NMM!G31+[1]PPA!G32+[1]FBT!G12+[1]TRE!G12+[1]MAE!G12+[1]TEL!G12+[1]WWP!G12+[1]OIS!G12 -> 274930.28 | H29: =[1]ISI!H25+[1]NFM!H43+[1]CHI!H32+[1]NMM!H31+[1]PPA!H32+[1]FBT!H12+[1]TRE!H12+[1]MAE!H12+[1]TEL!H12+[1]WWP!H12+[1]OIS!H12 -> 269540.87 | I29: =[1]ISI!I25+[1]NFM!I43+[1]CHI!I32+[1]NMM!I31+[1]PPA!I32+[1]FBT!I12+[1]TRE!I12+[1]MAE!I12+[1]TEL!I12+[1]WWP!I12+[1]OIS!I12 -> 274240.65 | ... W29: =[1]ISI!W25+[1]NFM!W43+[1]CHI!W32+[1]NMM!W31+[1]PPA!W32+[1]FBT!W12+[1]TRE!W12+[1]MAE!W12+[1]TEL!W12+[1]WWP!W12+[1]OIS!W12 -> 243631.82
A30: Solids | B30: =B31+B32 -> 22810.469 | C30: =C31+C32 -> 20365.668 | D30: =D31+D32 -> 19108.771 | E30: =E31+E32 -> 19743.311 | F30: =F31+F32 -> 18499.919 | G30: =G31+G32 -> 17673.43 | H30: =H31+H32 -> 17620.803 | I30: =I31+I32 -> 18226.161 | ... W30: =W31+W32 -> 10983.431
A31: Hard coal and others | B31: =[1]ISI!B27+[1]NFM!B44+[1]CHI!B33+[1]NMM!B32+[1]PPA!B33+[1]FBT!B13+[1]TRE!B13+[1]MAE!B13+[1]TEL!B13+[1]WWP!B13+[1]OIS!B13 -> 18908.226 | C31: =[1]ISI!C27+[1]NFM!C44+[1]CHI!C33+[1]NMM!C32+[1]PPA!C33+[1]FBT!C13+[1]TRE!C13+[1]MAE!C13+[1]TEL!C13+[1]WWP!C13+[1]OIS!C13 -> 17141.663 | D31: =[1]ISI!D27+[1]NFM!D44+[1]CHI!D33+[1]NMM!D32+[1]PPA!D33+[1]FBT!D13+[1]TRE!D13+[1]MAE!D13+[1]TEL!D13+[1]WWP!D13+[1]OIS!D13 -> 15531.269 | E31: =[1]ISI!E27+[1]NFM!E44+[1]CHI!E33+[1]NMM!E32+[1]PPA!E33+[1]FBT!E13+[1]TRE!E13+[1]MAE!E13+[1]TEL!E13+[1]WWP!E13+[1]OIS!E13 -> 15622.627 | F31: =[1]ISI!F27+[1]NFM!F44+[1]CHI!F33+[1]NMM!F32+[1]PPA!F33+[1]FBT!F13+[1]TRE!F13+[1]MAE!F13+[1]TEL!F13+[1]WWP!F13+[1]OIS!F13 -> 15536.374 | G31: =[1]ISI!G27+[1]NFM!G44+[1]CHI!G33+[1]NMM!G32+[1]PPA!G33+[1]FBT!G13+[1]TRE!G13+[1]MAE!G13+[1]TEL!G13+[1]WWP!G13+[1]OIS!G13 -> 14770.242 | H31: =[1]ISI!H27+[1]NFM!H44+[1]CHI!H33+[1]NMM!H32+[1]PPA!H33+[1]FBT!H13+[1]TRE!H13+[1]MAE!H13+[1]TEL!H13+[1]WWP!H13+[1]OIS!H13 -> 14153.426 | I31: =[1]ISI!I27+[1]NFM!I44+[1]CHI!I33+[1]NMM!I32+[1]PPA!I33+[1]FBT!I13+[1]TRE!I13+[1]MAE!I13+[1]TEL!I13+[1]WWP!I13+[1]OIS!I13 -> 15409.763 | ... W31: =[1]ISI!W27+[1]NFM!W44+[1]CHI!W33+[1]NMM!W32+[1]PPA!W33+[1]FBT!W13+[1]TRE!W13+[1]MAE!W13+[1]TEL!W13+[1]WWP!W13+[1]OIS!W13 -> 9769.7688
A32: Coke | B32: =[1]ISI!B28 -> 3902.2433 | C32: =[1]ISI!C28 -> 3224.0046 | D32: =[1]ISI!D28 -> 3577.5015 | E32: =[1]ISI!E28 -> 4120.6841 | F32: =[1]ISI!F28 -> 2963.5447 | G32: =[1]ISI!G28 -> 2903.1874 | H32: =[1]ISI!H28 -> 3467.3772 | I32: =[1]ISI!I28 -> 2816.3981 | ... W32: =[1]ISI!W28 -> 1213.6625
A33: Liquids | B33: =SUM(B34:B38) -> 43589.914 | C33: =SUM(C34:C38) -> 43791.521 | D33: =SUM(D34:D38) -> 43188.051 | E33: =SUM(E34:E38) -> 43838.797 | F33: =SUM(F34:F38) -> 41617.818 | G33: =SUM(G34:G38) -> 40045.485 | H33: =SUM(H34:H38) -> 39689.498 | I33: =SUM(I34:I38) -> 39132.055 | ... W33: =SUM(W34:W38) -> 23482.604
A34: Refinery gas | B34: =[1]ISI!B30+[1]NFM!B46+[1]CHI!B35+[1]NMM!B34+[1]PPA!B35+[1]FBT!B15+[1]TRE!B15+[1]MAE!B15+[1]TEL!B15+[1]WWP!B15+[1]OIS!B15 -> 2910.6894 | C34: =[1]ISI!C30+[1]NFM!C46+[1]CHI!C35+[1]NMM!C34+[1]PPA!C35+[1]FBT!C15+[1]TRE!C15+[1]MAE!C15+[1]TEL!C15+[1]WWP!C15+[1]OIS!C15 -> 3195.0585 | D34: =[1]ISI!D30+[1]NFM!D46+[1]CHI!D35+[1]NMM!D34+[1]PPA!D35+[1]FBT!D15+[1]TRE!D15+[1]MAE!D15+[1]TEL!D15+[1]WWP!D15+[1]OIS!D15 -> 3476.746 | E34: =[1]ISI!E30+[1]NFM!E46+[1]CHI!E35+[1]NMM!E34+[1]PPA!E35+[1]FBT!E15+[1]TRE!E15+[1]MAE!E15+[1]TEL!E15+[1]WWP!E15+[1]OIS!E15 -> 4164.4155 | F34: =[1]ISI!F30+[1]NFM!F46+[1]CHI!F35+[1]NMM!F34+[1]PPA!F35+[1]FBT!F15+[1]TRE!F15+[1]MAE!F15+[1]TEL!F15+[1]WWP!F15+[1]OIS!F15 -> 3707.7802 | G34: =[1]ISI!G30+[1]NFM!G46+[1]CHI!G35+[1]NMM!G34+[1]PPA!G35+[1]FBT!G15+[1]TRE!G15+[1]MAE!G15+[1]TEL!G15+[1]WWP!G15+[1]OIS!G15 -> 3449.2451 | H34: =[1]ISI!H30+[1]NFM!H46+[1]CHI!H35+[1]NMM!H34+[1]PPA!H35+[1]FBT!H15+[1]TRE!H15+[1]MAE!H15+[1]TEL!H15+[1]WWP!H15+[1]OIS!H15 -> 3924.9326 | I34: =[1]ISI!I30+[1]NFM!I46+[1]CHI!I35+[1]NMM!I34+[1]PPA!I35+[1]FBT!I15+[1]TRE!I15+[1]MAE!I15+[1]TEL!I15+[1]WWP!I15+[1]OIS!I15 -> 4682.1703 | ... W34: =[1]ISI!W30+[1]NFM!W46+[1]CHI!W35+[1]NMM!W34+[1]PPA!W35+[1]FBT!W15+[1]TRE!W15+[1]MAE!W15+[1]TEL!W15+[1]WWP!W15+[1]OIS!W15 -> 3958.2578
A35: LPG | B35: =[1]ISI!B31+[1]NFM!B47+[1]CHI!B36+[1]NMM!B35+[1]PPA!B36+[1]FBT!B16+[1]TRE!B16+[1]MAE!B16+[1]TEL!B16+[1]WWP!B16+[1]OIS!B16 -> 4508.7295 | C35: =[1]ISI!C31+[1]NFM!C47+[1]CHI!C36+[1]NMM!C35+[1]PPA!C36+[1]FBT!C16+[1]TRE!C16+[1]MAE!C16+[1]TEL!C16+[1]WWP!C16+[1]OIS!C16 -> 4569.5371 | D35: =[1]ISI!D31+[1]NFM!D47+[1]CHI!D36+[1]NMM!D35+[1]PPA!D36+[1]FBT!D16+[1]TRE!D16+[1]MAE!D16+[1]TEL!D16+[1]WWP!D16+[1]OIS!D16 -> 4115.9481 | E35: =[1]ISI!E31+[1]NFM!E47+[1]CHI!E36+[1]NMM!E35+[1]PPA!E36+[1]FBT!E16+[1]TRE!E16+[1]MAE!E16+[1]TEL!E16+[1]WWP!E16+[1]OIS!E16 -> 3637.2742 | F35: =[1]ISI!F31+[1]NFM!F47+[1]CHI!F36+[1]NMM!F35+[1]PPA!F36+[1]FBT!F16+[1]TRE!F16+[1]MAE!F16+[1]TEL!F16+[1]WWP!F16+[1]OIS!F16 -> 3185.0687 | G35: =[1]ISI!G31+[1]NFM!G47+[1]CHI!G36+[1]NMM!G35+[1]PPA!G36+[1]FBT!G16+[1]TRE!G16+[1]MAE!G16+[1]TEL!G16+[1]WWP!G16+[1]OIS!G16 -> 3143.4832 | H35: =[1]ISI!H31+[1]NFM!H47+[1]CHI!H36+[1]NMM!H35+[1]PPA!H36+[1]FBT!H16+[1]TRE!H16+[1]MAE!H16+[1]TEL!H16+[1]WWP!H16+[1]OIS!H16 -> 3330.8432 | I35: =[1]ISI!I31+[1]NFM!I47+[1]CHI!I36+[1]NMM!I35+[1]PPA!I36+[1]FBT!I16+[1]TRE!I16+[1]MAE!I16+[1]TEL!I16+[1]WWP!I16+[1]OIS!I16 -> 3168.7832 | ... W35: =[1]ISI!W31+[1]NFM!W47+[1]CHI!W36+[1]NMM!W35+[1]PPA!W36+[1]FBT!W16+[1]TRE!W16+[1]MAE!W16+[1]TEL!W16+[1]WWP!W16+[1]OIS!W16 -> 2451.5366
A36: Diesel oil (without biofuels) | B36: =[1]ISI!B32+[1]NFM!B48+[1]CHI!B37+[1]NMM!B36+[1]PPA!B37+[1]FBT!B17+[1]TRE!B17+[1]MAE!B17+[1]TEL!B17+[1]WWP!B17+[1]OIS!B17 -> 10935.737 | C36: =[1]ISI!C32+[1]NFM!C48+[1]CHI!C37+[1]NMM!C36+[1]PPA!C37+[1]FBT!C17+[1]TRE!C17+[1]MAE!C17+[1]TEL!C17+[1]WWP!C17+[1]OIS!C17 -> 11606.358 | D36: =[1]ISI!D32+[1]NFM!D48+[1]CHI!D37+[1]NMM!D36+[1]PPA!D37+[1]FBT!D17+[1]TRE!D17+[1]MAE!D17+[1]TEL!D17+[1]WWP!D17+[1]OIS!D17 -> 11292.645 | E36: =[1]ISI!E32+[1]NFM!E48+[1]CHI!E37+[1]NMM!E36+[1]PPA!E37+[1]FBT!E17+[1]TRE!E17+[1]MAE!E17+[1]TEL!E17+[1]WWP!E17+[1]OIS!E17 -> 11030.764 | F36: =[1]ISI!F32+[1]NFM!F48+[1]CHI!F37+[1]NMM!F36+[1]PPA!F37+[1]FBT!F17+[1]TRE!F17+[1]MAE!F17+[1]TEL!F17+[1]WWP!F17+[1]OIS!F17 -> 10735.901 | G36: =[1]ISI!G32+[1]NFM!G48+[1]CHI!G37+[1]NMM!G36+[1]PPA!G37+[1]FBT!G17+[1]TRE!G17+[1]MAE!G17+[1]TEL!G17+[1]WWP!G17+[1]OIS!G17 -> 10922.678 | H36: =[1]ISI!H32+[1]NFM!H48+[1]CHI!H37+[1]NMM!H36+[1]PPA!H37+[1]FBT!H17+[1]TRE!H17+[1]MAE!H17+[1]TEL!H17+[1]WWP!H17+[1]OIS!H17 -> 9718.1334 | I36: =[1]ISI!I32+[1]NFM!I48+[1]CHI!I37+[1]NMM!I36+[1]PPA!I37+[1]FBT!I17+[1]TRE!I17+[1]MAE!I17+[1]TEL!I17+[1]WWP!I17+[1]OIS!I17 -> 9978.8717 | ... W36: =[1]ISI!W32+[1]NFM!W48+[1]CHI!W37+[1]NMM!W36+[1]PPA!W37+[1]FBT!W17+[1]TRE!W17+[1]MAE!W17+[1]TEL!W17+[1]WWP!W17+[1]OIS!W17 -> 8503.5225
A37: Fuel oil | B37: =[1]ISI!B33+[1]NFM!B49+[1]CHI!B38+[1]NMM!B37+[1]PPA!B38+[1]FBT!B18+[1]TRE!B18+[1]MAE!B18+[1]TEL!B18+[1]WWP!B18+[1]OIS!B18 -> 16604.348 | C37: =[1]ISI!C33+[1]NFM!C49+[1]CHI!C38+[1]NMM!C37+[1]PPA!C38+[1]FBT!C18+[1]TRE!C18+[1]MAE!C18+[1]TEL!C18+[1]WWP!C18+[1]OIS!C18 -> 15974.118 | D37: =[1]ISI!D33+[1]NFM!D49+[1]CHI!D38+[1]NMM!D37+[1]PPA!D38+[1]FBT!D18+[1]TRE!D18+[1]MAE!D18+[1]TEL!D18+[1]WWP!D18+[1]OIS!D18 -> 15314.44 | E37: =[1]ISI!E33+[1]NFM!E49+[1]CHI!E38+[1]NMM!E37+[1]PPA!E38+[1]FBT!E18+[1]TRE!E18+[1]MAE!E18+[1]TEL!E18+[1]WWP!E18+[1]OIS!E18 -> 15156.003 | F37: =[1]ISI!F33+[1]NFM!F49+[1]CHI!F38+[1]NMM!F37+[1]PPA!F38+[1]FBT!F18+[1]TRE!F18+[1]MAE!F18+[1]TEL!F18+[1]WWP!F18+[1]OIS!F18 -> 13190.826 | G37: =[1]ISI!G33+[1]NFM!G49+[1]CHI!G38+[1]NMM!G37+[1]PPA!G38+[1]FBT!G18+[1]TRE!G18+[1]MAE!G18+[1]TEL!G18+[1]WWP!G18+[1]OIS!G18 -> 11642.845 | H37: =[1]ISI!H33+[1]NFM!H49+[1]CHI!H38+[1]NMM!H37+[1]PPA!H38+[1]FBT!H18+[1]TRE!H18+[1]MAE!H18+[1]TEL!H18+[1]WWP!H18+[1]OIS!H18 -> 12223.956 | I37: =[1]ISI!I33+[1]NFM!I49+[1]CHI!I38+[1]NMM!I37+[1]PPA!I38+[1]FBT!I18+[1]TRE!I18+[1]MAE!I18+[1]TEL!I18+[1]WWP!I18+[1]OIS!I18 -> 11122.222 | ... W37: =[1]ISI!W33+[1]NFM!W49+[1]CHI!W38+[1]NMM!W37+[1]PPA!W38+[1]FBT!W18+[1]TRE!W18+[1]MAE!W18+[1]TEL!W18+[1]WWP!W18+[1]OIS!W18 -> 2359.7448
A38: Other liquids | B38: =[1]ISI!B34+[1]NFM!B50+[1]CHI!B39+[1]NMM!B38+[1]PPA!B39+[1]FBT!B19+[1]TRE!B19+[1]MAE!B19+[1]TEL!B19+[1]WWP!B19+[1]OIS!B19 -> 8630.4103 | C38: =[1]ISI!C34+[1]NFM!C50+[1]CHI!C39+[1]NMM!C38+[1]PPA!C39+[1]FBT!C19+[1]TRE!C19+[1]MAE!C19+[1]TEL!C19+[1]WWP!C19+[1]OIS!C19 -> 8446.4489 | D38: =[1]ISI!D34+[1]NFM!D50+[1]CHI!D39+[1]NMM!D38+[1]PPA!D39+[1]FBT!D19+[1]TRE!D19+[1]MAE!D19+[1]TEL!D19+[1]WWP!D19+[1]OIS!D19 -> 8988.2727 | E38: =[1]ISI!E34+[1]NFM!E50+[1]CHI!E39+[1]NMM!E38+[1]PPA!E39+[1]FBT!E19+[1]TRE!E19+[1]MAE!E19+[1]TEL!E19+[1]WWP!E19+[1]OIS!E19 -> 9850.3398 | F38: =[1]ISI!F34+[1]NFM!F50+[1]CHI!F39+[1]NMM!F38+[1]PPA!F39+[1]FBT!F19+[1]TRE!F19+[1]MAE!F19+[1]TEL!F19+[1]WWP!F19+[1]OIS!F19 -> 10798.242 | G38: =[1]ISI!G34+[1]NFM!G50+[1]CHI!G39+[1]NMM!G38+[1]PPA!G39+[1]FBT!G19+[1]TRE!G19+[1]MAE!G19+[1]TEL!G19+[1]WWP!G19+[1]OIS!G19 -> 10887.233 | H38: =[1]ISI!H34+[1]NFM!H50+[1]CHI!H39+[1]NMM!H38+[1]PPA!H39+[1]FBT!H19+[1]TRE!H19+[1]MAE!H19+[1]TEL!H19+[1]WWP!H19+[1]OIS!H19 -> 10491.633 | I38: =[1]ISI!I34+[1]NFM!I50+[1]CHI!I39+[1]NMM!I38+[1]PPA!I39+[1]FBT!I19+[1]TRE!I19+[1]MAE!I19+[1]TEL!I19+[1]WWP!I19+[1]OIS!I19 -> 10180.007 | ... W38: =[1]ISI!W34+[1]NFM!W50+[1]CHI!W39+[1]NMM!W38+[1]PPA!W39+[1]FBT!W19+[1]TRE!W19+[1]MAE!W19+[1]TEL!W19+[1]WWP!W19+[1]OIS!W19 -> 6209.5426
A39: Gases | B39: =B40+B41 -> 95421.942 | C39: =C40+C41 -> 95908.43 | D39: =D40+D41 -> 96180.156 | E39: =E40+E41 -> 97073.898 | F39: =F40+F41 -> 94518.2 | G39: =G40+G41 -> 96126.013 | H39: =H40+H41 -> 89876.153 | I39: =I40+I41 -> 91319.096 | ... W39: =W40+W41 -> 86382.515
A40: Natural gas | B40: =[1]ISI!B36+[1]NFM!B52+[1]CHI!B41+[1]NMM!B40+[1]PPA!B41+[1]FBT!B21+[1]TRE!B21+[1]MAE!B21+[1]TEL!B21+[1]WWP!B21+[1]OIS!B21 -> 87537.774 | C40: =[1]ISI!C36+[1]NFM!C52+[1]CHI!C41+[1]NMM!C40+[1]PPA!C41+[1]FBT!C21+[1]TRE!C21+[1]MAE!C21+[1]TEL!C21+[1]WWP!C21+[1]OIS!C21 -> 88680.819 | D40: =[1]ISI!D36+[1]NFM!D52+[1]CHI!D41+[1]NMM!D40+[1]PPA!D41+[1]FBT!D21+[1]TRE!D21+[1]MAE!D21+[1]TEL!D21+[1]WWP!D21+[1]OIS!D21 -> 89248.663 | E40: =[1]ISI!E36+[1]NFM!E52+[1]CHI!E41+[1]NMM!E40+[1]PPA!E41+[1]FBT!E21+[1]TRE!E21+[1]MAE!E21+[1]TEL!E21+[1]WWP!E21+[1]OIS!E21 -> 90430.873 | F40: =[1]ISI!F36+[1]NFM!F52+[1]CHI!F41+[1]NMM!F40+[1]PPA!F41+[1]FBT!F21+[1]TRE!F21+[1]MAE!F21+[1]TEL!F21+[1]WWP!F21+[1]OIS!F21 -> 87685.509 | G40: =[1]ISI!G36+[1]NFM!G52+[1]CHI!G41+[1]NMM!G40+[1]PPA!G41+[1]FBT!G21+[1]TRE!G21+[1]MAE!G21+[1]TEL!G21+[1]WWP!G21+[1]OIS!G21 -> 89767.745 | H40: =[1]ISI!H36+[1]NFM!H52+[1]CHI!H41+[1]NMM!H40+[1]PPA!H41+[1]FBT!H21+[1]TRE!H21+[1]MAE!H21+[1]TEL!H21+[1]WWP!H21+[1]OIS!H21 -> 83431.613 | I40: =[1]ISI!I36+[1]NFM!I52+[1]CHI!I41+[1]NMM!I40+[1]PPA!I41+[1]FBT!I21+[1]TRE!I21+[1]MAE!I21+[1]TEL!I21+[1]WWP!I21+[1]OIS!I21 -> 85163.836 | ... W40: =[1]ISI!W36+[1]NFM!W52+[1]CHI!W41+[1]NMM!W40+[1]PPA!W41+[1]FBT!W21+[1]TRE!W21+[1]MAE!W21+[1]TEL!W21+[1]WWP!W21+[1]OIS!W21 -> 81920.758
A41: Derived gases | B41: =[1]ISI!B37+[1]NFM!B53+[1]CHI!B42+[1]NMM!B41+[1]PPA!B42+[1]FBT!B22+[1]TRE!B22+[1]MAE!B22+[1]TEL!B22+[1]WWP!B22+[1]OIS!B22 -> 7884.1677 | C41: =[1]ISI!C37+[1]NFM!C53+[1]CHI!C42+[1]NMM!C41+[1]PPA!C42+[1]FBT!C22+[1]TRE!C22+[1]MAE!C22+[1]TEL!C22+[1]WWP!C22+[1]OIS!C22 -> 7227.6107 | D41: =[1]ISI!D37+[1]NFM!D53+[1]CHI!D42+[1]NMM!D41+[1]PPA!D42+[1]FBT!D22+[1]TRE!D22+[1]MAE!D22+[1]TEL!D22+[1]WWP!D22+[1]OIS!D22 -> 6931.4932 | E41: =[1]ISI!E37+[1]NFM!E53+[1]CHI!E42+[1]NMM!E41+[1]PPA!E42+[1]FBT!E22+[1]TRE!E22+[1]MAE!E22+[1]TEL!E22+[1]WWP!E22+[1]OIS!E22 -> 6643.0248 | F41: =[1]ISI!F37+[1]NFM!F53+[1]CHI!F42+[1]NMM!F41+[1]PPA!F42+[1]FBT!F22+[1]TRE!F22+[1]MAE!F22+[1]TEL!F22+[1]WWP!F22+[1]OIS!F22 -> 6832.6905 | G41: =[1]ISI!G37+[1]NFM!G53+[1]CHI!G42+[1]NMM!G41+[1]PPA!G42+[1]FBT!G22+[1]TRE!G22+[1]MAE!G22+[1]TEL!G22+[1]WWP!G22+[1]OIS!G22 -> 6358.2678 | H41: =[1]ISI!H37+[1]NFM!H53+[1]CHI!H42+[1]NMM!H41+[1]PPA!H42+[1]FBT!H22+[1]TRE!H22+[1]MAE!H22+[1]TEL!H22+[1]WWP!H22+[1]OIS!H22 -> 6444.5407 | I41: =[1]ISI!I37+[1]NFM!I53+[1]CHI!I42+[1]NMM!I41+[1]PPA!I42+[1]FBT!I22+[1]TRE!I22+[1]MAE!I22+[1]TEL!I22+[1]WWP!I22+[1]OIS!I22 -> 6155.2597 | ... W41: =[1]ISI!W37+[1]NFM!W53+[1]CHI!W42+[1]NMM!W41+[1]PPA!W42+[1]FBT!W22+[1]TRE!W22+[1]MAE!W22+[1]TEL!W22+[1]WWP!W22+[1]OIS!W22 -> 4461.757
A42: RES and wastes | B42: =SUM(B43:B48) -> 16267.287 | C42: =SUM(C43:C48) -> 15608.252 | D42: =SUM(D43:D48) -> 16229.138 | E42: =SUM(E43:E48) -> 17321.736 | F42: =SUM(F43:F48) -> 18111.497 | G42: =SUM(G43:G48) -> 18742.129 | H42: =SUM(H43:H48) -> 19686.957 | I42: =SUM(I43:I48) -> 20726.467 | ... W42: =SUM(W43:W48) -> 28018.533
...

Sheet Transport_Summary
A1: Transport overview - EU27 - European Union - 27 countries (from 2020) | B1: 2000 | C1: 2001 | D1: 2002 | E1: 2003 | F1: 2004 | G1: 2005 | H1: 2006 | I1: 2007 | J1: 2008 | K1: 2009 | L1: 2010 | M1: 2011 | N1: 2012 | O1: 2013 | P1: 2014 | Q1: 2015 | R1: 2016 | S1: 2017 | T1: 2018 | U1: 2019 | V1: 2020 | W1: 2021 | DA1: Code
A3: Transport activity
A4: Passenger transport (mio pkm) | B4: =B5+B9+B13 -> 5378408.7 | C4: =C5+C9+C13 -> 5443869.2 | D4: =D5+D9+D13 -> 5479333.3 | E4: =E5+E9+E13 -> 5536316.8 | F4: =F5+F9+F13 -> 5680470.9 | G4: =G5+G9+G13 -> 5715831.8 | H4: =H5+H9+H13 -> 5801785.9 | I4: =I5+I9+I13 -> 5915760 | ... W4: =W5+W9+W13 -> 5029112.6 | DA4: Activity.Mpkm.EU27.Tr
A5: Road transport | B5: =B6+B7+B8 -> 4255778.5 | C5: =C6+C7+C8 -> 4332733.5 | D5: =D6+D7+D8 -> 4386358.3 | E5: =E6+E7+E8 -> 4429034.4 | F5: =F6+F7+F8 -> 4489126.2 | G5: =G6+G7+G8 -> 4451245 | H5: =H6+H7+H8 -> 4486342.7 | I5: =I6+I7+I8 -> 4538387.4 | ... W5: =W6+W7+W8 -> 4174021.2 | DA5: Activity.Mpkm.EU27.Tr.Road.Passenger
A6: =[2]TrRoad_act!$A$5 -> Powered two-wheelers | B6: =[2]TrRoad_act!B$5 -> 98941.119 | C6: =[2]TrRoad_act!C$5 -> 102907.78 | D6: =[2]TrRoad_act!D$5 -> 104221.44 | E6: =[2]TrRoad_act!E$5 -> 107273.63 | F6: =[2]TrRoad_act!F$5 -> 110798.04 | G6: =[2]TrRoad_act!G$5 -> 114310.05 | H6: =[2]TrRoad_act!H$5 -> 113240.02 | I6: =[2]TrRoad_act!I$5 -> 109248.07 | ... W6: =[2]TrRoad_act!W$5 -> 104773.52 | DA6: Activity.Mpkm.EU27.Tr.Road.Passenger.P2W
A7: =[2]TrRoad_act!$A$6 -> Passenger cars | B7: =[2]TrRoad_act!B$6 -> 3660355.1 | C7: =[2]TrRoad_act!C$6 -> 3734215.8 | D7: =[2]TrRoad_act!D$6 -> 3789305 | E7: =[2]TrRoad_act!E$6 -> 3826195.6 | F7: =[2]TrRoad_act!F$6 -> 3878162.7 | G7: =[2]TrRoad_act!G$6 -> 3839179.5 | H7: =[2]TrRoad_act!H$6 -> 3875261.4 | I7: =[2]TrRoad_act!I$6 -> 3921256.1 | ... W7: =[2]TrRoad_act!W$6 -> 3742236.2 | DA7: Activity.Mpkm.EU27.Tr.Road.Passenger.Car
A8: =[2]TrRoad_act!$A$13 -> Motor coaches, buses and trolley buses | B8: =[2]TrRoad_act!B$13 -> 496482.35 | C8: =[2]TrRoad_act!C$13 -> 495609.93 | D8: =[2]TrRoad_act!D$13 -> 492831.8 | E8: =[2]TrRoad_act!E$13 -> 495565.18 | F8: =[2]TrRoad_act!F$13 -> 500165.37 | G8: =[2]TrRoad_act!G$13 -> 497755.43 | H8: =[2]TrRoad_act!H$13 -> 497841.22 | I8: =[2]TrRoad_act!I$13 -> 507883.21 | ... W8: =[2]TrRoad_act!W$13 -> 327011.46 | DA8: Activity.Mpkm.EU27.Tr.Road.Passenger.Bus
A9: Rail, metro and tram | B9: =B10+B11+B12 -> 406430.63 | C9: =C10+C11+C12 -> 408434.24 | D9: =D10+D11+D12 -> 401282.62 | E9: =E10+E11+E12 -> 396962.31 | F9: =F10+F11+F12 -> 404392.63 | G9: =G10+G11+G12 -> 412978.7 | H9: =H10+H11+H12 -> 423962.33 | I9: =I10+I11+I12 -> 428987.22 | ... W9: =W10+W11+W12 -> 320779.81 | DA9: Activity.Mpkm.EU27.Tr.Rail.Passenger
A10: =[2]TrRail_act!$A$5 -> Metro and tram, urban light rail | B10: =[2]TrRail_act!B$5 -> 67843.841 | C10: =[2]TrRail_act!C$5 -> 68539.657 | D10: =[2]TrRail_act!D$5 -> 69374.813 | E10: =[2]TrRail_act!E$5 -> 70183.362 | F10: =[2]TrRail_act!F$5 -> 72445.633 | G10: =[2]TrRail_act!G$5 -> 73154.697 | H10: =[2]TrRail_act!H$5 -> 74583.334 | I10: =[2]TrRail_act!I$5 -> 76350.816 | ... W10: =[2]TrRail_act!W$5 -> 55543.667 | DA10: Activity.Mpkm.EU27.Tr.Rail.Passenger.MTU
A11: =[2]TrRail_act!$A$6 -> Conventional passenger trains | B11: =[2]TrRail_act!B$6 -> 279790.79 | C11: =[2]TrRail_act!C$6 -> 274768.58 | D11: =[2]TrRail_act!D$6 -> 263902.8 | E11: =[2]TrRail_act!E$6 -> 256117.95 | F11: =[2]TrRail_act!F$6 -> 256276 | G11: =[2]TrRail_act!G$6 -> 260161 | H11: =[2]TrRail_act!H$6 -> 265968 | I11: =[2]TrRail_act!I$6 -> 265333.41 | ... W11: =[2]TrRail_act!W$6 -> 180012.79 | DA11: Activity.Mpkm.EU27.Tr.Rail.Passenger.CPT
A12: =[2]TrRail_act!$A$9 -> High speed passenger trains | B12: =[2]TrRail_act!B$9 -> 58796 | C12: =[2]TrRail_act!C$9 -> 65126 | D12: =[2]TrRail_act!D$9 -> 68005 | E12: =[2]TrRail_act!E$9 -> 70661 | F12: =[2]TrRail_act!F$9 -> 75671 | G12: =[2]TrRail_act!G$9 -> 79663 | H12: =[2]TrRail_act!H$9 -> 83411 | I12: =[2]TrRail_act!I$9 -> 87303 | ... W12: =[2]TrRail_act!W$9 -> 85223.348 | DA12: Activity.Mpkm.EU27.Tr.Rail.Passenger.HST
A13: Aviation | B13: =B14+B15+B16 -> 716199.54 | C13: =C14+C15+C16 -> 702701.51 | D13: =D14+D15+D16 -> 691692.47 | E13: =E14+E15+E16 -> 710320.05 | F13: =F14+F15+F16 -> 786952.1 | G13: =G14+G15+G16 -> 851608.11 | H13: =H14+H15+H16 -> 891480.93 | I13: =I14+I15+I16 -> 948385.38 | ... W13: =W14+W15+W16 -> 534311.64 | DA13: Activity.Mpkm.EU27.Tr.Avia.Passenger
A14: Domestic | B14: =[2]TrAvia_act!B$5 -> 82338.133 | C14: =[2]TrAvia_act!C$5 -> 79436.4 | D14: =[2]TrAvia_act!D$5 -> 80334.16 | E14: =[2]TrAvia_act!E$5 -> 82499.6 | F14: =[2]TrAvia_act!F$5 -> 85968.387 | G14: =[2]TrAvia_act!G$5 -> 89851.226 | H14: =[2]TrAvia_act!H$5 -> 93342.474 | I14: =[2]TrAvia_act!I$5 -> 99980.35 | ... W14: =[2]TrAvia_act!W$5 -> 68551.55 | DA14: Activity.Mpkm.EU27.Tr.Avia.Passenger.Domestic
A15: International - Intra-EEAwUK | B15: =[2]TrAvia_act!B$6 -> 306172.93 | C15: =[2]TrAvia_act!C$6 -> 305381.9 | D15: =[2]TrAvia_act!D$6 -> 295991.44 | E15: =[2]TrAvia_act!E$6 -> 310109.52 | F15: =[2]TrAvia_act!F$6 -> 332477.5 | G15: =[2]TrAvia_act!G$6 -> 357593.62 | H15: =[2]TrAvia_act!H$6 -> 373354.14 | I15: =[2]TrAvia_act!I$6 -> 387145.49 | ... W15: =[2]TrAvia_act!W$6 -> 233384.26 | DA15: Activity.Mpkm.EU27.Tr.Avia.Passenger.IntraEEAwUK
A16: International - Extra-EEAwUK | B16: =[2]TrAvia_act!B$7 -> 327688.48 | C16: =[2]TrAvia_act!C$7 -> 317883.21 | D16: =[2]TrAvia_act!D$7 -> 315366.87 | E16: =[2]TrAvia_act!E$7 -> 317710.94 | F16: =[2]TrAvia_act!F$7 -> 368506.21 | G16: =[2]TrAvia_act!G$7 -> 404163.26 | H16: =[2]TrAvia_act!H$7 -> 424784.31 | I16: =[2]TrAvia_act!I$7 -> 461259.54 | ... W16: =[2]TrAvia_act!W$7 -> 232375.83 | DA16: Activity.Mpkm.EU27.Tr.Avia.Passenger.ExtraEEAwUK
A17: Freight transport (mio tkm) | B17: =B18+B21+B22+B26 -> 1998922.6 | C17: =C18+C21+C22+C26 -> 2013107.1 | D17: =D18+D21+D22+D26 -> 2064046.2 | E17: =E18+E21+E22+E26 -> 2069079.8 | F17: =F18+F21+F22+F26 -> 2244425.8 | G17: =G18+G21+G22+G26 -> 2303016.8 | H17: =H18+H21+H22+H26 -> 2388450 | I17: =I18+I21+I22+I26 -> 2469552.3 | ... W17: =W18+W21+W22+W26 -> 2628148.8 | DA17: Activity.Mtkm.EU27.Tr
A18: Road transport | B18: =B19+B20 -> 1374700.3 | C18: =C19+C20 -> 1422266.4 | D18: =D19+D20 -> 1471063.4 | E18: =E19+E20 -> 1475814 | F18: =F19+F20 -> 1622092.6 | G18: =G19+G20 -> 1667102.4 | H18: =H19+H20 -> 1718593.4 | I18: =I19+I20 -> 1781545.5 | ... W18: =W19+W20 -> 1959068.5 | DA18: Activity.Mtkm.EU27.Tr.Road.Freight
A19: =[2]TrRoad_act!$A$20 -> Light commercial vehicles | B19: =[2]TrRoad_act!B$20 -> 67104.703 | C19: =[2]TrRoad_act!C$20 -> 70599.781 | D19: =[2]TrRoad_act!D$20 -> 71782.892 | E19: =[2]TrRoad_act!E$20 -> 74503.485 | F19: =[2]TrRoad_act!F$20 -> 76766.809 | G19: =[2]TrRoad_act!G$20 -> 78469.885 | H19: =[2]TrRoad_act!H$20 -> 79352.372 | I19: =[2]TrRoad_act!I$20 -> 83381.785 | ... W19: =[2]TrRoad_act!W$20 -> 96224.81 | DA19: Activity.Mtkm.EU27.Tr.Road.Freight.LCV
A20: =[2]TrRoad_act!$A$26 -> Heavy goods vehicles | B20: =[2]TrRoad_act!B$26 -> 1307595.6 | C20: =[2]TrRoad_act!C$26 -> 1351666.6 | D20: =[2]TrRoad_act!D$26 -> 1399280.5 | E20: =[2]TrRoad_act!E$26 -> 1401310.6 | F20: =[2]TrRoad_act!F$26 -> 1545325.8 | G20: =[2]TrRoad_act!G$26 -> 1588632.5 | H20: =[2]TrRoad_act!H$26 -> 1639241.1 | I20: =[2]TrRoad_act!I$26 -> 1698163.7 | ... W20: =[2]TrRoad_act!W$26 -> 1862843.7 | DA20: Activity.Mtkm.EU27.Tr.Road.Freight.HGV
A21: Rail transport | B21: =[2]TrRail_act!B$10 -> 387920.75 | C21: =[2]TrRail_act!C$10 -> 369253.3 | D21: =[2]TrRail_act!D$10 -> 368161.19 | E21: =[2]TrRail_act!E$10 -> 376309.27 | F21: =[2]TrRail_act!F$10 -> 390035 | G21: =[2]TrRail_act!G$10 -> 394597 | H21: =[2]TrRail_act!H$10 -> 416246 | I21: =[2]TrRail_act!I$10 -> 430724 | ... W21: =[2]TrRail_act!W$10 -> 409571.98 | DA21: Activity.Mtkm.EU27.Tr.Rail.Freight
A22: Aviation | B22: =B23+B24+B25 -> 25990.504 | C22: =C23+C24+C25 -> 25150.487 | D22: =D23+D24+D25 -> 25611.901 | E22: =E23+E24+E25 -> 25775.985 | F22: =F23+F24+F25 -> 27337.701 | G22: =G23+G24+G25 -> 29161.59 | H22: =H23+H24+H25 -> 31258.294 | I22: =I23+I24+I25 -> 33677.921 | ... W22: =W23+W24+W25 -> 46525.465 | DA22: Activity.Mtkm.EU27.Tr.Avia.Freight
A23: Domestic | B23: =[2]TrAvia_act!B$9 -> 415.25357 | C23: =[2]TrAvia_act!C$9 -> 449.12623 | D23: =[2]TrAvia_act!D$9 -> 415.26836 | E23: =[2]TrAvia_act!E$9 -> 378.82428 | F23: =[2]TrAvia_act!F$9 -> 380.32001 | G23: =[2]TrAvia_act!G$9 -> 360.57706 | H23: =[2]TrAvia_act!H$9 -> 346.13194 | I23: =[2]TrAvia_act!I$9 -> 331.94182 | ... W23: =[2]TrAvia_act!W$9 -> 272.01753 | DA23: Activity.Mtkm.EU27.Tr.Avia.Freight.Domestic
A24: International - Intra-EEAwUK | B24: =[2]TrAvia_act!B$10 -> 1584.2302 | C24: =[2]TrAvia_act!C$10 -> 1548.4561 | D24: =[2]TrAvia_act!D$10 -> 1535.2549 | E24: =[2]TrAvia_act!E$10 -> 1581.5275 | F24: =[2]TrAvia_act!F$10 -> 1654.9073 | G24: =[2]TrAvia_act!G$10 -> 1736.1596 | H24: =[2]TrAvia_act!H$10 -> 1852.1549 | I24: =[2]TrAvia_act!I$10 -> 1933.5623 | ... W24: =[2]TrAvia_act!W$10 -> 2490.2632 | DA24: Activity.Mtkm.EU27.Tr.Avia.Freight.IntraEEAwUK
A25: International - Extra-EEAwUK | B25: =[2]TrAvia_act!B$11 -> 23991.021 | C25: =[2]TrAvia_act!C$11 -> 23152.905 | D25: =[2]TrAvia_act!D$11 -> 23661.378 | E25: =[2]TrAvia_act!E$11 -> 23815.633 | F25: =[2]TrAvia_act!F$11 -> 25302.473 | G25: =[2]TrAvia_act!G$11 -> 27064.854 | H25: =[2]TrAvia_act!H$11 -> 29060.007 | I25: =[2]TrAvia_act!I$11 -> 31412.417 | ... W25: =[2]TrAvia_act!W$11 -> 43763.184 | DA25: Activity.Mtkm.EU27.Tr.Avia.Freight.ExtraEEAwUK
A26: Domestic navigation | B26: =B27+B28 -> 210311.04 | C26: =C27+C28 -> 196436.94 | D26: =D27+D28 -> 199209.71 | E26: =E27+E28 -> 191180.49 | F26: =F27+F28 -> 204960.44 | G26: =G27+G28 -> 212155.8 | H26: =H27+H28 -> 222352.29 | I26: =I27+I28 -> 223604.85 | ... W26: =W27+W28 -> 212982.87 | DA26: Activity.Mtkm.EU27.Tr.DNavi.Freight
A27: =[2]TrNavi_act!$A$4 -> Domestic coastal shipping | B27: =[2]TrNavi_act!B4 -> 76596.154 | C27: =[2]TrNavi_act!C4 -> 64020.692 | D27: =[2]TrNavi_act!D4 -> 66795.686 | E27: =[2]TrNavi_act!E4 -> 67745.405 | F27: =[2]TrNavi_act!F4 -> 68197.284 | G27: =[2]TrNavi_act!G4 -> 73544.828 | H27: =[2]TrNavi_act!H4 -> 83935.32 | I27: =[2]TrNavi_act!I4 -> 78202.846 | ... W27: =[2]TrNavi_act!W4 -> 76906.865 | DA27: Activity.Mtkm.EU27.Tr.DNavi.Freight.DCS
A28: =[2]TrNavi_act!$A$5 -> Inland waterways | B28: =[2]TrNavi_act!B5 -> 133714.89 | C28: =[2]TrNavi_act!C5 -> 132416.24 | D28: =[2]TrNavi_act!D5 -> 132414.02 | E28: =[2]TrNavi_act!E5 -> 123435.09 | F28: =[2]TrNavi_act!F5 -> 136763.15 | G28: =[2]TrNavi_act!G5 -> 138610.97 | H28: =[2]TrNavi_act!H5 -> 138416.97 | I28: =[2]TrNavi_act!I5 -> 145402 | ... W28: =[2]TrNavi_act!W5 -> 136076 | DA28: Activity.Mtkm.EU27.Tr.DNavi.Freight.IWW
A29: International maritime bunkers (mio tkm) | B29: =B30+B31 -> 5326857.4 | C29: =C30+C31 -> 5600580.9 | D29: =D30+D31 -> 5760396.8 | E29: =E30+E31 -> 5971481.5 | F29: =F30+F31 -> 6310605.1 | G29: =G30+G31 -> 6787911.1 | H29: =H30+H31 -> 7119228.1 | I29: =I30+I31 -> 7369718.9 | ... W29: =W30+W31 -> 8135819.2 | DA29: Activity.Mtkm.EU27.MBunk.Freight
A30: Intra-EEA | B30: =[2]MBunk_act!B$4 -> 753767.24 | C30: =[2]MBunk_act!C$4 -> 780873.54 | D30: =[2]MBunk_act!D$4 -> 793361.74 | E30: =[2]MBunk_act!E$4 -> 807199.9 | F30: =[2]MBunk_act!F$4 -> 831866.45 | G30: =[2]MBunk_act!G$4 -> 834011.02 | H30: =[2]MBunk_act!H$4 -> 820751.75 | I30: =[2]MBunk_act!I$4 -> 821736.85 | ... W30: =[2]MBunk_act!W$4 -> 910620.85 | DA30: Activity.Mtkm.EU27.MBunk.Freight.IntraEEA
A31: Extra-EEA | B31: =[2]MBunk_act!B$5 -> 4573090.2 | C31: =[2]MBunk_act!C$5 -> 4819707.4 | D31: =[2]MBunk_act!D$5 -> 4967035 | E31: =[2]MBunk_act!E$5 -> 5164281.6 | F31: =[2]MBunk_act!F$5 -> 5478738.6 | G31: =[2]MBunk_act!G$5 -> 5953900.1 | H31: =[2]MBunk_act!H$5 -> 6298476.3 | I31: =[2]MBunk_act!I$5 -> 6547982.1 | ... W31: =[2]MBunk_act!W$5 -> 7225198.3 | DA31: Activity.Mtkm.EU27.MBunk.Freight.ExtraEEA
A33: Energy consumption (ktoe)
A34: Passenger transport | B34: =B35+B39+B43 -> 203854.55 | C34: =C35+C39+C43 -> 205123.88 | D34: =D35+D39+D43 -> 207135.61 | E34: =E35+E39+E43 -> 208430.44 | F34: =F35+F39+F43 -> 212832.94 | G34: =G35+G39+G43 -> 212662.05 | H34: =H35+H39+H43 -> 216583.56 | I34: =I35+I39+I43 -> 220391.82 | ... W34: =W35+W39+W43 -> 191798.4
A35: =$A$5 -> Road transport | B35: =B36+B37+B38 -> 167049.47 | C35: =C36+C37+C38 -> 169193.66 | D35: =D36+D37+D38 -> 172155.91 | E35: =E36+E37+E38 -> 173089.11 | F35: =F36+F37+F38 -> 175497.35 | G35: =G36+G37+G38 -> 174055.05 | H35: =H36+H37+H38 -> 176899.18 | I35: =I36+I37+I38 -> 179052.23 | ... W35: =W36+W37+W38 -> 166999.31 | DA35: FEC.ktoe.EU27.Tr.Road.Passenger
A36: =$A$6 -> Powered two-wheelers | B36: =[2]TrRoad_ene!B$19 -> 3405.2525 | C36: =[2]TrRoad_ene!C$19 -> 3482.8462 | D36: =[2]TrRoad_ene!D$19 -> 3502.2502 | E36: =[2]TrRoad_ene!E$19 -> 3559.2389 | F36: =[2]TrRoad_ene!F$19 -> 3625.4333 | G36: =[2]TrRoad_ene!G$19 -> 3699.6046 | H36: =[2]TrRoad_ene!H$19 -> 3624.2288 | I36: =[2]TrRoad_ene!I$19 -> 3473.6672 | ... W36: =[2]TrRoad_ene!W$19 -> 2939.8797 | DA36: FEC.ktoe.EU27.Tr.Road.Passenger.P2W
A37: =$A$7 -> Passenger cars | B37: =[2]TrRoad_ene!B$21 -> 149935.38 | C37: =[2]TrRoad_ene!C$21 -> 152093.16 | D37: =[2]TrRoad_ene!D$21 -> 155147.73 | E37: =[2]TrRoad_ene!E$21 -> 155902.75 | F37: =[2]TrRoad_ene!F$21 -> 158342.92 | G37: =[2]TrRoad_ene!G$21 -> 157061.47 | H37: =[2]TrRoad_ene!H$21 -> 159856.05 | I37: =[2]TrRoad_ene!I$21 -> 162101.71 | ... W37: =[2]TrRoad_ene!W$21 -> 150346.73 | DA37: FEC.ktoe.EU27.Tr.Road.Passenger.Car
A38: =$A$8 -> Motor coaches, buses and trolley buses | B38: =[2]TrRoad_ene!B$33 -> 13708.833 | C38: =[2]TrRoad_ene!C$33 -> 13617.652 | D38: =[2]TrRoad_ene!D$33 -> 13505.931 | E38: =[2]TrRoad_ene!E$33 -> 13627.116 | F38: =[2]TrRoad_ene!F$33 -> 13529.002 | G38: =[2]TrRoad_ene!G$33 -> 13293.969 | H38: =[2]TrRoad_ene!H$33 -> 13418.894 | I38: =[2]TrRoad_ene!I$33 -> 13476.852 | ... W38: =[2]TrRoad_ene!W$33 -> 13712.699 | DA38: FEC.ktoe.EU27.Tr.Road.Passenger.Bus
A39: =$A$9 -> Rail, metro and tram | B39: =B40+B41+B42 -> 5202.4469 | C39: =C40+C41+C42 -> 4957.6995 | D39: =D40+D41+D42 -> 5011.1327 | E39: =E40+E41+E42 -> 4959.4343 | F39: =F40+F41+F42 -> 5034.9384 | G39: =G40+G41+G42 -> 4993.3212 | H39: =H40+H41+H42 -> 4685.2235 | I39: =I40+I41+I42 -> 4805.5555 | ... W39: =W40+W41+W42 -> 3861.1785 | DA39: FEC.ktoe.EU27.Tr.Rail.Passenger
A40: =$A$10 -> Metro and tram, urban light rail | B40: =[2]TrRail_ene!B$12 -> 374.66872 | C40: =[2]TrRail_ene!C$12 -> 377.04704 | D40: =[2]TrRail_ene!D$12 -> 378.16603 | E40: =[2]TrRail_ene!E$12 -> 385.24982 | F40: =[2]TrRail_ene!F$12 -> 390.64881 | G40: =[2]TrRail_ene!G$12 -> 374.70226 | H40: =[2]TrRail_ene!H$12 -> 374.42952 | I40: =[2]TrRail_ene!I$12 -> 377.42843 | ... W40: =[2]TrRail_ene!W$12 -> 305.65639 | DA40: FEC.ktoe.EU27.Tr.Rail.Passenger.MTU
A41: =$A$11 -> Conventional passenger trains | B41: =[2]TrRail_ene!B$13 -> 4377.1874 | C41: =[2]TrRail_ene!C$13 -> 4069.2163 | D41: =[2]TrRail_ene!D$13 -> 4103.9355 | E41: =[2]TrRail_ene!E$13 -> 4034.3982 | F41: =[2]TrRail_ene!F$13 -> 4066.2076 | G41: =[2]TrRail_ene!G$13 -> 4030.2291 | H41: =[2]TrRail_ene!H$13 -> 3721.8387 | I41: =[2]TrRail_ene!I$13 -> 3831.0585 | ... W41: =[2]TrRail_ene!W$13 -> 2908.9141 | DA41: FEC.ktoe.EU27.Tr.Rail.Passenger.CPT
A42: =$A$12 -> High speed passenger trains | B42: =[2]TrRail_ene!B$16 -> 450.59077 | C42: =[2]TrRail_ene!C$16 -> 511.43617 | D42: =[2]TrRail_ene!D$16 -> 529.03125 | E42: =[2]TrRail_ene!E$16 -> 539.78628 | F42: =[2]TrRail_ene!F$16 -> 578.08197 | G42: =[2]TrRail_ene!G$16 -> 588.38985 | H42: =[2]TrRail_ene!H$16 -> 588.95529 | I42: =[2]TrRail_ene!I$16 -> 597.06847 | ... W42: =[2]TrRail_ene!W$16 -> 646.60797 | DA42: FEC.ktoe.EU27.Tr.Rail.Passenger.HST
...
