Workbook

Sheet Input
A1: Subsector | B1: Unit | C1: 2000 | D1: 2001 | E1: 2002 | F1: 2003 | G1: 2004 | H1: 2005 | I1: 2006 | J1: 2007 | K1: 2008 | L1: 2009 | M1: 2010 | N1: 2011 | O1: 2012 | P1: 2013 | Q1: 2014 | R1: 2015 | S1: 2016 | T1: 2017 | U1: 2018 | V1: 2019 | W1: 2020 | X1: 2021
A2: Iron and Steel | B2: ktoe | C2: =JR_IDEES_Industry!B4 -> 698.88536 | D2: =JR_IDEES_Industry!C4 -> 633.64162 | E2: =JR_IDEES_Industry!D4 -> 534.35508 | F2: =JR_IDEES_Industry!E4 -> 452.64093 | G2: =JR_IDEES_Industry!F4 -> 464.88257 | H2: =JR_IDEES_Industry!G4 -> 425.55509 | I2: =JR_IDEES_Industry!H4 -> 486.99758 | J2: =JR_IDEES_Industry!I4 -> 555.29281 | ... X2: =JR_IDEES_Industry!W4 -> 346.9374
A3: Alumina production | B3: ktoe | C3: =JR_IDEES_Industry!B6 -> 0 | D3: =JR_IDEES_Industry!C6 -> 0 | E3: =JR_IDEES_Industry!D6 -> 0 | F3: =JR_IDEES_Industry!E6 -> 0 | G3: =JR_IDEES_Industry!F6 -> 0 | H3: =JR_IDEES_Industry!G6 -> 0 | I3: =JR_IDEES_Industry!H6 -> 0 | J3: =JR_IDEES_Industry!I6 -> 0 | ... X3: =JR_IDEES_Industry!W6 -> 0
A4: Aluminium production | B4: ktoe | C4: =JR_IDEES_Industry!B7 -> 0 | D4: =JR_IDEES_Industry!C7 -> 0 | E4: =JR_IDEES_Industry!D7 -> 0 | F4: =JR_IDEES_Industry!E7 -> 0 | G4: =JR_IDEES_Industry!F7 -> 0 | H4: =JR_IDEES_Industry!G7 -> 0 | I4: =JR_IDEES_Industry!H7 -> 0 | J4: =JR_IDEES_Industry!I7 -> 0 | ... X4: =JR_IDEES_Industry!W7 -> 0
A5: Other non-ferrous metals | B5: ktoe | C5: =JR_IDEES_Industry!B8 -> 0 | D5: =JR_IDEES_Industry!C8 -> 0 | E5: =JR_IDEES_Industry!D8 -> 0 | F5: =JR_IDEES_Industry!E8 -> 0 | G5: =JR_IDEES_Industry!F8 -> 0 | H5: =JR_IDEES_Industry!G8 -> 0 | I5: =JR_IDEES_Industry!H8 -> 0 | J5: =JR_IDEES_Industry!I8 -> 0 | ... X5: =JR_IDEES_Industry!W8 -> 0
A6: Basic chemicals | B6: ktoe | C6: =JR_IDEES_Industry!B10 -> 0 | D6: =JR_IDEES_Industry!C10 -> 0 | E6: =JR_IDEES_Industry!D10 -> 0 | F6: =JR_IDEES_Industry!E10 -> 0 | G6: =JR_IDEES_Industry!F10 -> 0 | H6: =JR_IDEES_Industry!G10 -> 0 | I6: =JR_IDEES_Industry!H10 -> 0 | J6: =JR_IDEES_Industry!I10 -> 0 | ... X6: =JR_IDEES_Industry!W10 -> 0
A7: Other chemicals | B7: ktoe | C7: =JR_IDEES_Industry!B11 -> 1679.0063 | D7: =JR_IDEES_Industry!C11 -> 1666.4682 | E7: =JR_IDEES_Industry!D11 -> 1511.2109 | F7: =JR_IDEES_Industry!E11 -> 1554.2153 | G7: =JR_IDEES_Industry!F11 -> 1507.6736 | H7: =JR_IDEES_Industry!G11 -> 1539.1131 | I7: =JR_IDEES_Industry!H11 -> 1482.4657 | J7: =JR_IDEES_Industry!I11 -> 1394.1149 | ... X7: =JR_IDEES_Industry!W11 -> 2877.532
A8: Pharmaceutical products | B8: ktoe | C8: =JR_IDEES_Industry!B12 -> 3130.2037 | D8: =JR_IDEES_Industry!C12 -> 3505.6034 | E8: =JR_IDEES_Industry!D12 -> 3107.9547 | F8: =JR_IDEES_Industry!E12 -> 3576.1808 | G8: =JR_IDEES_Industry!F12 -> 3494.7457 | H8: =JR_IDEES_Industry!G12 -> 3609.1718 | I8: =JR_IDEES_Industry!H12 -> 3419.1857 | J8: =JR_IDEES_Industry!I12 -> 3165.9996 | ... X8: =JR_IDEES_Industry!W12 -> 12713.284
A9: Cement | B9: ktoe | C9: =JR_IDEES_Industry!B14 -> 598.04025 | D9: =JR_IDEES_Industry!C14 -> 565.49053 | E9: =JR_IDEES_Industry!D14 -> 587.50361 | F9: =JR_IDEES_Industry!E14 -> 525.98838 | G9: =JR_IDEES_Industry!F14 -> 535.3659 | H9: =JR_IDEES_Industry!G14 -> 518.52305 | I9: =JR_IDEES_Industry!H14 -> 718.01213 | J9: =JR_IDEES_Industry!I14 -> 694.02837 | ... X9: =JR_IDEES_Industry!W14 -> 902.71983
A10: Ceramics & other non metallic minerals | B10: ktoe | C10: =JR_IDEES_Industry!B15 -> 864.4962 | D10: =JR_IDEES_Industry!C15 -> 649.26975 | E10: =JR_IDEES_Industry!D15 -> 674.99401 | F10: =JR_IDEES_Industry!E15 -> 676.17905 | G10: =JR_IDEES_Industry!F15 -> 637.86045 | H10: =JR_IDEES_Industry!G15 -> 713.15812 | I10: =JR_IDEES_Industry!H15 -> 586.3831 | J10: =JR_IDEES_Industry!I15 -> 684.93444 | ... X10: =JR_IDEES_Industry!W15 -> 509.95181
A11: Glass production | B11: ktoe | C11: =JR_IDEES_Industry!B16 -> 145.68637 | D11: =JR_IDEES_Industry!C16 -> 138.79031 | E11: =JR_IDEES_Industry!D16 -> 139.31367 | F11: =JR_IDEES_Industry!E16 -> 124.01337 | G11: =JR_IDEES_Industry!F16 -> 117.32836 | H11: =JR_IDEES_Industry!G16 -> 110.32379 | I11: =JR_IDEES_Industry!H16 -> 149.59802 | J11: =JR_IDEES_Industry!I16 -> 163.49159 | ... X11: =JR_IDEES_Industry!W16 -> 103.42061
A12: Pulp | B12: ktoe | C12: =JR_IDEES_Industry!B18 -> 0 | D12: =JR_IDEES_Industry!C18 -> 0 | E12: =JR_IDEES_Industry!D18 -> 0 | F12: =JR_IDEES_Industry!E18 -> 0 | G12: =JR_IDEES_Industry!F18 -> 0 | H12: =JR_IDEES_Industry!G18 -> 0 | I12: =JR_IDEES_Industry!H18 -> 0 | J12: =JR_IDEES_Industry!I18 -> 0 | ... X12: =JR_IDEES_Industry!W18 -> 1.4426759
A13: Paper | B13: ktoe | C13: =JR_IDEES_Industry!B19 -> 757.46481 | D13: =JR_IDEES_Industry!C19 -> 746.23903 | E13: =JR_IDEES_Industry!D19 -> 740.51139 | F13: =JR_IDEES_Industry!E19 -> 706.83088 | G13: =JR_IDEES_Industry!F19 -> 632.37429 | H13: =JR_IDEES_Industry!G19 -> 550.30552 | I13: =JR_IDEES_Industry!H19 -> 539.19708 | J13: =JR_IDEES_Industry!I19 -> 519.4191 | ... X13: =JR_IDEES_Industry!W19 -> 495.81728
A14: Printing | B14: ktoe | C14: =JR_IDEES_Industry!B20 -> 1244.4065 | D14: =JR_IDEES_Industry!C20 -> 1081.5174 | E14: =JR_IDEES_Industry!D20 -> 1026.7823 | F14: =JR_IDEES_Industry!E20 -> 981.97054 | G14: =JR_IDEES_Industry!F20 -> 943.41261 | H14: =JR_IDEES_Industry!G20 -> 864.17811 | I14: =JR_IDEES_Industry!H20 -> 849.54681 | J14: =JR_IDEES_Industry!I20 -> 786.68405 | ... X14: =JR_IDEES_Industry!W20 -> 297.87302
A15: Food, beverages and tobacco | B15: ktoe | C15: =JR_IDEES_Industry!B21 -> 5540.9107 | D15: =JR_IDEES_Industry!C21 -> 5724.2091 | E15: =JR_IDEES_Industry!D21 -> 6077.2248 | F15: =JR_IDEES_Industry!E21 -> 5789.2331 | G15: =JR_IDEES_Industry!F21 -> 5712.0879 | H15: =JR_IDEES_Industry!G21 -> 5528.5861 | I15: =JR_IDEES_Industry!H21 -> 5032.3874 | J15: =JR_IDEES_Industry!I21 -> 4812.8453 | ... X15: =JR_IDEES_Industry!W21 -> 4243.97
A16: Transport | B16: ktoe | C16: =JR_IDEES_Industry!B22 -> 927.64353 | D16: =JR_IDEES_Industry!C22 -> 912.55507 | E16: =JR_IDEES_Industry!D22 -> 866.42413 | F16: =JR_IDEES_Industry!E22 -> 867.4454 | G16: =JR_IDEES_Industry!F22 -> 715.74794 | H16: =JR_IDEES_Industry!G22 -> 777.4215 | I16: =JR_IDEES_Industry!H22 -> 792.95781 | J16: =JR_IDEES_Industry!I22 -> 687.25272 | ... X16: =JR_IDEES_Industry!W22 -> 483.57834
A17: Machinery | B17: ktoe | C17: =JR_IDEES_Industry!B23 -> 11744.908 | D17: =JR_IDEES_Industry!C23 -> 11919.581 | E17: =JR_IDEES_Industry!D23 -> 12347.576 | F17: =JR_IDEES_Industry!E23 -> 11078.974 | G17: =JR_IDEES_Industry!F23 -> 11072.815 | H17: =JR_IDEES_Industry!G23 -> 10354.044 | I17: =JR_IDEES_Industry!H23 -> 11796.256 | J17: =JR_IDEES_Industry!I23 -> 12497.895 | ... X17: =JR_IDEES_Industry!W23 -> 10698.52
A18: Textiles and leather | B18: ktoe | C18: =JR_IDEES_Industry!B24 -> 927.37233 | D18: =JR_IDEES_Industry!C24 -> 813.85041 | E18: =JR_IDEES_Industry!D24 -> 755.47643 | F18: =JR_IDEES_Industry!E24 -> 697.18131 | G18: =JR_IDEES_Industry!F24 -> 632.37429 | H18: =JR_IDEES_Industry!G24 -> 521.50765 | I18: =JR_IDEES_Industry!H24 -> 542.6375 | J18: =JR_IDEES_Industry!I24 -> 510.76788 | ... X18: =JR_IDEES_Industry!W24 -> 434.13869
A19: Wood and wood products | B19: ktoe | C19: =JR_IDEES_Industry!B25 -> 977.68015 | D19: =JR_IDEES_Industry!C25 -> 917.18599 | E19: =JR_IDEES_Industry!D25 -> 864.74701 | F19: =JR_IDEES_Industry!E25 -> 890.17268 | G19: =JR_IDEES_Industry!F25 -> 908.79766 | H19: =JR_IDEES_Industry!G25 -> 916.44988 | I19: =JR_IDEES_Industry!H25 -> 917.16889 | J19: =JR_IDEES_Industry!I25 -> 918.64395 | ... X19: =JR_IDEES_Industry!W25 -> 604.05978
A20: Other industrial sectors | B20: ktoe | C20: =JR_IDEES_Industry!B26 -> 21733.518 | D20: =JR_IDEES_Industry!C26 -> 20079.387 | E20: =JR_IDEES_Industry!D26 -> 19934.205 | F20: =JR_IDEES_Industry!E26 -> 20145.378 | G20: =JR_IDEES_Industry!F26 -> 21736.827 | H20: =JR_IDEES_Industry!G26 -> 24189.606 | I20: =JR_IDEES_Industry!H26 -> 26603.83 | J20: =JR_IDEES_Industry!I26 -> 26052.738 | ... X20: =JR_IDEES_Industry!W26 -> 19787.17
A21: Powered two-wheelers | B21: pkm | C21: =JR_IDEES_Transport!B6 -> 618.06271 | D21: =JR_IDEES_Transport!C6 -> 586.67394 | E21: =JR_IDEES_Transport!D6 -> 609.87844 | F21: =JR_IDEES_Transport!E6 -> 616.21647 | G21: =JR_IDEES_Transport!F6 -> 615.6463 | H21: =JR_IDEES_Transport!G6 -> 631.84951 | I21: =JR_IDEES_Transport!H6 -> 665.74426 | J21: =JR_IDEES_Transport!I6 -> 712.09003 | ... X21: =JR_IDEES_Transport!W6 -> 613.24874
A22: Passenger cars | B22: pkm | C22: =JR_IDEES_Transport!B7 -> 50615 | D22: =JR_IDEES_Transport!C7 -> 49620 | E22: =JR_IDEES_Transport!D7 -> 49454 | F22: =JR_IDEES_Transport!E7 -> 49695 | G22: =JR_IDEES_Transport!F7 -> 50557 | H22: =JR_IDEES_Transport!G7 -> 49758 | I22: =JR_IDEES_Transport!H7 -> 49648 | J22: =JR_IDEES_Transport!I7 -> 50733 | ... X22: =JR_IDEES_Transport!W7 -> 58910
A23: Motor coaches, buses and trolley buses | B23: pkm | C23: =JR_IDEES_Transport!B8 -> 7418 | D23: =JR_IDEES_Transport!C8 -> 7332 | E23: =JR_IDEES_Transport!D8 -> 7295 | F23: =JR_IDEES_Transport!E8 -> 7272 | G23: =JR_IDEES_Transport!F8 -> 7300 | H23: =JR_IDEES_Transport!G8 -> 7169 | I23: =JR_IDEES_Transport!H8 -> 7054 | J23: =JR_IDEES_Transport!I8 -> 6845 | ... X23: =JR_IDEES_Transport!W8 -> 4834
A24: Metro and tram, urban light rail | B24: pkm | C24: =JR_IDEES_Transport!B10 -> 0 | D24: =JR_IDEES_Transport!C10 -> 0 | E24: =JR_IDEES_Transport!D10 -> 9 | F24: =JR_IDEES_Transport!E10 -> 67 | G24: =JR_IDEES_Transport!F10 -> 128 | H24: =JR_IDEES_Transport!G10 -> 162 | I24: =JR_IDEES_Transport!H10 -> 164 | J24: =JR_IDEES_Transport!I10 -> 177 | ... X24: =JR_IDEES_Transport!W10 -> 331
A25: Conventional passenger trains | B25: pkm | C25: =JR_IDEES_Transport!B11 -> 5537 | D25: =JR_IDEES_Transport!C11 -> 5721 | E25: =JR_IDEES_Transport!D11 -> 5745 | F25: =JR_IDEES_Transport!E11 -> 5826 | G25: =JR_IDEES_Transport!F11 -> 5946 | H25: =JR_IDEES_Transport!G11 -> 5974 | I25: =JR_IDEES_Transport!H11 -> 6110 | J25: =JR_IDEES_Transport!I11 -> 6176 | ... X25: =JR_IDEES_Transport!W11 -> 4181
A26: High speed passenger trains | B26: pkm | C26: =JR_IDEES_Transport!B12 -> 0 | D26: =JR_IDEES_Transport!C12 -> 0 | E26: =JR_IDEES_Transport!D12 -> 0 | F26: =JR_IDEES_Transport!E12 -> 0 | G26: =JR_IDEES_Transport!F12 -> 0 | H26: =JR_IDEES_Transport!G12 -> 0 | I26: =JR_IDEES_Transport!H12 -> 0 | J26: =JR_IDEES_Transport!I12 -> 0 | ... X26: =JR_IDEES_Transport!W12 -> 0
A27: Aviation-Domestic-pass | B27: pkm | C27: =JR_IDEES_Transport!B14 -> 291.40924 | D27: =JR_IDEES_Transport!C14 -> 299.46483 | E27: =JR_IDEES_Transport!D14 -> 270.63505 | F27: =JR_IDEES_Transport!E14 -> 294.26581 | G27: =JR_IDEES_Transport!F14 -> 369.96533 | H27: =JR_IDEES_Transport!G14 -> 371.63024 | I27: =JR_IDEES_Transport!H14 -> 403.57691 | J27: =JR_IDEES_Transport!I14 -> 446.87632 | ... X27: =JR_IDEES_Transport!W14 -> 231.30369
A28: Aviation -International - Intra-EEAwUK - pass | B28: pkm | C28: =JR_IDEES_Transport!B15 -> 10186.298 | D28: =JR_IDEES_Transport!C15 -> 10566.784 | E28: =JR_IDEES_Transport!D15 -> 10520.061 | F28: =JR_IDEES_Transport!E15 -> 10218.513 | G28: =JR_IDEES_Transport!F15 -> 10696.839 | H28: =JR_IDEES_Transport!G15 -> 11149.757 | I28: =JR_IDEES_Transport!H15 -> 11392.019 | J28: =JR_IDEES_Transport!I15 -> 11336.021 | ... X28: =JR_IDEES_Transport!W15 -> 5724.8426
A29: Aviation-International - Extra-EEAwUK - pass | B29: pkm | C29: =JR_IDEES_Transport!B16 -> 6253.8116 | D29: =JR_IDEES_Transport!C16 -> 6454.0407 | E29: =JR_IDEES_Transport!D16 -> 6499.1536 | F29: =JR_IDEES_Transport!E16 -> 6288.9755 | G29: =JR_IDEES_Transport!F16 -> 7273.2448 | H29: =JR_IDEES_Transport!G16 -> 8228.1178 | I29: =JR_IDEES_Transport!H16 -> 8578.7544 | J29: =JR_IDEES_Transport!I16 -> 8577.0951 | ... X29: =JR_IDEES_Transport!W16 -> 3019.5167
A30: Light commercial vehicles | B30: tkm | C30: =JR_IDEES_Transport!B19 -> 967.69162 | D30: =JR_IDEES_Transport!C19 -> 1039.2804 | E30: =JR_IDEES_Transport!D19 -> 1081.8776 | F30: =JR_IDEES_Transport!E19 -> 1145.3659 | G30: =JR_IDEES_Transport!F19 -> 1259.0691 | H30: =JR_IDEES_Transport!G19 -> 1357.8092 | I30: =JR_IDEES_Transport!H19 -> 1498.905 | J30: =JR_IDEES_Transport!I19 -> 1642.3373 | ... X30: =JR_IDEES_Transport!W19 -> 1167.8793
A31: Heavy goods vehicles | B31: tkm | C31: =JR_IDEES_Transport!B20 -> 15135.134 | D31: =JR_IDEES_Transport!C20 -> 15316.427 | E31: =JR_IDEES_Transport!D20 -> 15747.501 | F31: =JR_IDEES_Transport!E20 -> 15777.979 | G31: =JR_IDEES_Transport!F20 -> 16069.63 | H31: =JR_IDEES_Transport!G20 -> 16786.513 | I31: =JR_IDEES_Transport!H20 -> 17692.259 | J31: =JR_IDEES_Transport!I20 -> 18387.594 | ... X31: =JR_IDEES_Transport!W20 -> 20819
A32: Rail transport | B32: tkm | C32: =JR_IDEES_Transport!B21 -> 2025 | D32: =JR_IDEES_Transport!C21 -> 2091 | E32: =JR_IDEES_Transport!D21 -> 1877 | F32: =JR_IDEES_Transport!E21 -> 1985 | G32: =JR_IDEES_Transport!F21 -> 2321 | H32: =JR_IDEES_Transport!G21 -> 1976 | I32: =JR_IDEES_Transport!H21 -> 1892 | J32: =JR_IDEES_Transport!I21 -> 1779 | ... X32: =JR_IDEES_Transport!W21 -> 1986
A33: Aviation-Domestic-goods | B33: tkm | C33: {=JR_IDEES_Transport!B23:B25} -> 0.39172366 | D33: {=JR_IDEES_Transport!C23:C25} -> 0.41211957 | E33: {=JR_IDEES_Transport!D23:D25} -> 0.38472127 | F33: {=JR_IDEES_Transport!E23:E25} -> 0.28773505 | G33: {=JR_IDEES_Transport!F23:F25} -> 0.3010534 | H33: {=JR_IDEES_Transport!G23:G25} -> 0.3332811 | I33: {=JR_IDEES_Transport!H23:H25} -> 0.33346815 | J33: {=JR_IDEES_Transport!I23:I25} -> 0.26982735 | ... X33: {=JR_IDEES_Transport!W23:W25} -> 0.13964973
A34: Aviation-International - Intra-EEAwUK - goods | B34: tkm | C34: 42.905083 | D34: 46.931067 | E34: 41.432123 | F34: 30.287156 | G34: 30.62859 | H34: 35.808121 | I34: 37.802768 | J34: 34.545833 | K34: 73.007464 | L34: 51.799428 | M34: 37.374546 | N34: 37.565585 | O34: 36.271175 | P34: 30.52384 | Q34: 50.036327 | R34: 48.248825 | S34: 42.029275 | T34: 46.221981 | U34: 46.669987 | V34: 53.690768 | W34: 51.588895 | X34: 75.077322
A35: Aviation-International - Extra-EEAwUK - goods | B35: tkm | C35: 8.0154786 | D35: 8.8632525 | E35: 9.692331 | F35: 9.608875 | G35: 9.3271538 | H35: 6.2576859 | I35: 3.158309 | J35: 3.5537514 | K35: 412.30372 | L35: 343.45466 | M35: 410.51992 | N35: 413.41346 | O35: 506.91094 | P35: 441.86273 | Q35: 565.00376 | R35: 517.34147 | S35: 464.34767 | T35: 510.45428 | U35: 406.78995 | V35: 471.4687 | W35: 249.30481 | X35: 339.24578
A36: Shipping-Domestic coastal shipping | B36: tkm | C36: {=JR_IDEES_Transport!B27:B28} -> 1533.178 | D36: {=JR_IDEES_Transport!C27:C28} -> 1880.845 | E36: {=JR_IDEES_Transport!D27:D28} -> 1666.383 | F36: {=JR_IDEES_Transport!E27:E28} -> 1908.069 | G36: {=JR_IDEES_Transport!F27:F28} -> 1803.478 | H36: {=JR_IDEES_Transport!G27:G28} -> 2029.19 | I36: {=JR_IDEES_Transport!H27:H28} -> 2309.768 | J36: {=JR_IDEES_Transport!I27:I28} -> 2467.003 | ... X36: {=JR_IDEES_Transport!W27:W28} -> 1515.121
A37: Inland waterways | B37: tkm | C37: 0 | D37: 0 | E37: 0 | F37: 0 | G37: 0 | H37: 0 | I37: 0 | J37: 0 | K37: 0 | L37: 0 | M37: 0 | N37: 0 | O37: 0 | P37: 0 | Q37: 0 | R37: 0 | S37: 0 | T37: 0 | U37: 0 | V37: 0 | W37: 0 | X37: 0
A38: Maritime - Intra -EEA | B38: tkm | C38: {=JR_IDEES_Transport!B30:B31} -> 21870.694 | D38: {=JR_IDEES_Transport!C30:C31} -> 21927.96 | E38: {=JR_IDEES_Transport!D30:D31} -> 22405.537 | F38: {=JR_IDEES_Transport!E30:E31} -> 23368.593 | G38: {=JR_IDEES_Transport!F30:F31} -> 24548.212 | H38: {=JR_IDEES_Transport!G30:G31} -> 24152.366 | I38: {=JR_IDEES_Transport!H30:H31} -> 22890.939 | J38: {=JR_IDEES_Transport!I30:I31} -> 22088.239 | ... X38: {=JR_IDEES_Transport!W30:W31} -> 22073.122
A39: Maritime - Extra -EEA | B39: tkm | C39: 59410.657 | D39: 61372.406 | E39: 57985.463 | F39: 73567.954 | G39: 59849.677 | H39: 56392.246 | I39: 73273.526 | J39: 65382.899 | K39: 64519.227 | L39: 55781.307 | M39: 47317.017 | N39: 60108.395 | O39: 43488.089 | P39: 44393.392 | Q39: 48019.639 | R39: 67723.682 | S39: 67659.898 | T39: 64538.47 | U39: 67376.787 | V39: 76667.917 | W39: 77644.241 | X39: 81512.483
A40: {=JR_IDEES_Industry!A183:A198} -> Integrated steelworks (kt steel) | B40: kt steel | C40: =JR_IDEES_Industry!B183 -> 0 | D40: =JR_IDEES_Industry!C183 -> 0 | E40: =JR_IDEES_Industry!D183 -> 0 | F40: =JR_IDEES_Industry!E183 -> 0 | G40: =JR_IDEES_Industry!F183 -> 0 | H40: =JR_IDEES_Industry!G183 -> 0 | I40: =JR_IDEES_Industry!H183 -> 0 | J40: =JR_IDEES_Industry!I183 -> 0 | ... X40: =JR_IDEES_Industry!W183 -> 0
...

Sheet Description
A1: Industry
A35: Transport

Sheet JR_IDEES_Industry
A1: DK: Industry Summary | B1: 2000 | C1: 2001 | D1: 2002 | E1: 2003 | F1: 2004 | G1: 2005 | H1: 2006 | I1: 2007 | J1: 2008 | K1: 2009 | L1: 2010 | M1: 2011 | N1: 2012 | O1: 2013 | P1: 2014 | Q1: 2015 | R1: 2016 | S1: 2017 | T1: 2018 | U1: 2019 | V1: 2020 | W1: 2021
A3: Value added (M€2015) | B3: 50970.222 | C3: 49353.789 | D3: 49168.279 | E3: 48066.404 | F3: 49112.294 | G3: 50617.944 | H3: 53916.623 | I3: 53444.107 | J3: 53742.918 | K3: 44670.09 | L3: 44215.45 | M3: 46777.704 | N3: 47136.96 | O3: 47166.582 | P3: 47087.347 | Q3: 47424.4 | R3: 51159.942 | S3: 53356.015 | T3: 55266.914 | U3: 55551.311 | V3: 51744.582 | W3: 54500.416
A4: Iron and steel | B4: 698.88536 | C4: 633.64162 | D4: 534.35508 | E4: 452.64093 | F4: 464.88257 | G4: 425.55509 | H4: 486.99758 | I4: 555.29281 | J4: 497.03477 | K4: 272.16098 | L4: 249.73776 | M4: 308.41329 | N4: 301.32389 | O4: 308.06896 | P4: 329.13658 | Q4: 403.4 | R4: 398.68663 | S4: 401.98735 | T4: 379.38104 | U4: 439.75654 | V4: 343.68785 | W4: 346.9374
A5: Non-ferrous metals | B5: 0 | C5: 0 | D5: 0 | E5: 0 | F5: 0 | G5: 0 | H5: 0 | I5: 0 | J5: 0 | K5: 0 | L5: 0 | M5: 0 | N5: 0 | O5: 0 | P5: 0 | Q5: 0 | R5: 0 | S5: 0 | T5: 0 | U5: 0 | V5: 0 | W5: 0
A6: Alumina production | B6: 0 | C6: 0 | D6: 0 | E6: 0 | F6: 0 | G6: 0 | H6: 0 | I6: 0 | J6: 0 | K6: 0 | L6: 0 | M6: 0 | N6: 0 | O6: 0 | P6: 0 | Q6: 0 | R6: 0 | S6: 0 | T6: 0 | U6: 0 | V6: 0 | W6: 0
A7: Aluminium production | B7: 0 | C7: 0 | D7: 0 | E7: 0 | F7: 0 | G7: 0 | H7: 0 | I7: 0 | J7: 0 | K7: 0 | L7: 0 | M7: 0 | N7: 0 | O7: 0 | P7: 0 | Q7: 0 | R7: 0 | S7: 0 | T7: 0 | U7: 0 | V7: 0 | W7: 0
A8: Other non-ferrous metals | B8: 0 | C8: 0 | D8: 0 | E8: 0 | F8: 0 | G8: 0 | H8: 0 | I8: 0 | J8: 0 | K8: 0 | L8: 0 | M8: 0 | N8: 0 | O8: 0 | P8: 0 | Q8: 0 | R8: 0 | S8: 0 | T8: 0 | U8: 0 | V8: 0 | W8: 0
A9: Chemical industry | B9: 4809.21 | C9: 5172.0716 | D9: 4619.1656 | E9: 5130.3961 | F9: 5002.4193 | G9: 5148.2848 | H9: 4901.6514 | I9: 4560.1144 | J9: 4916.6648 | K9: 5407.092 | L9: 6583.7739 | M9: 6859.1875 | N9: 8169.7173 | O9: 8587.0652 | P9: 9084.8937 | Q9: 10491.7 | R9: 11430.277 | S9: 12315.208 | T9: 13700.674 | U9: 13795.372 | V9: 14008.478 | W9: 15590.816
A10: Basic chemicals | B10: 0 | C10: 0 | D10: 0 | E10: 0 | F10: 0 | G10: 0 | H10: 0 | I10: 0 | J10: 0 | K10: 0 | L10: 0 | M10: 0 | N10: 0 | O10: 0 | P10: 0 | Q10: 0 | R10: 0 | S10: 0 | T10: 0 | U10: 0 | V10: 0 | W10: 0
A11: Other chemicals | B11: 1679.0063 | C11: 1666.4682 | D11: 1511.2109 | E11: 1554.2153 | F11: 1507.6736 | G11: 1539.1131 | H11: 1482.4657 | I11: 1394.1149 | J11: 1518.2213 | K11: 1624.755 | L11: 1712.987 | M11: 1655.3202 | N11: 1997.7764 | O11: 1921.2486 | P11: 2116.2084 | Q11: 2416.2 | R11: 2534.6998 | S11: 2627.7444 | T11: 2630.0888 | U11: 2744.7406 | V11: 2701.1382 | W11: 2877.532
A12: Pharmaceutical products etc. | B12: 3130.2037 | C12: 3505.6034 | D12: 3107.9547 | E12: 3576.1808 | F12: 3494.7457 | G12: 3609.1718 | H12: 3419.1857 | I12: 3165.9996 | J12: 3398.4435 | K12: 3782.3369 | L12: 4870.7869 | M12: 5203.8673 | N12: 6171.9409 | O12: 6665.8166 | P12: 6968.6853 | Q12: 8075.5 | R12: 8895.5773 | S12: 9687.4632 | T12: 11070.585 | U12: 11050.631 | V12: 11307.34 | W12: 12713.284
A13: Non-metallic mineral products | B13: 1608.2228 | C13: 1353.5506 | D13: 1401.8113 | E13: 1326.1808 | F13: 1290.5547 | G13: 1342.005 | H13: 1453.9933 | I13: 1542.4544 | J13: 1418.5718 | K13: 1049.8889 | L13: 849.97722 | M13: 1032.4773 | N13: 994.15265 | O13: 982.45435 | P13: 1065.6463 | Q13: 1090.1 | R13: 1258.9423 | S13: 1343.6236 | T13: 1383.1885 | U13: 1413.703 | V13: 1412.7522 | W13: 1516.0923
... A26: Other industrial sectors | B26: 21733.518 | C26: 20079.387 | D26: 19934.205 | E26: 20145.378 | F26: 21736.827 | G26: 24189.606 | H26: 26603.83 | I26: 26052.738 | J26: 26922.551 | K26: 20485.533 | L26: 19926.891 | M26: 21629.566 | N26: 21440.322 | O26: 20172.906 | P26: 19652.26 | Q26: 18630.1 | R26: 19983.981 | S26: 20599.348 | T26: 21293.469 | U26: 20286.869 | V26: 18823.749 | W26: 19787.17
A28: Energy consumption (ktoe)
A29: by fuel (EUROSTAT DATA) | B29: 2944.0628 | C29: 3035.1762 | D29: 2855.9062 | E29: 2864.5073 | F29: 2906.2907 | G29: 2873.2322 | H29: 2914.1712 | I29: 2832.359 | J29: 2716.4908 | K29: 2352.5038 | L29: 2446.4947 | M29: 2442.2842 | N29: 2303.3635 | O29: 2179.3844 | P29: 2120.5991 | Q29: 2109.3855 | R29: 2165.6236 | S29: 2284.7654 | T29: 2314.6359 | U29: 2257.7165 | V29: 2304.3745 | W29: 2474.7363
A30: Solids | B30: 265.34574 | C30: 231.66604 | D30: 199.95228 | E30: 204.11522 | F30: 229.13431 | G30: 214.3092 | H30: 220.63869 | I30: 215.84265 | J30: 173.67721 | K30: 94.423216 | L30: 105.52399 | M30: 116.36999 | N30: 87.036543 | O30: 93.662167 | P30: 101.56922 | Q30: 100.15082 | R30: 107.05288 | S30: 120.60456 | T30: 124.94987 | U30: 103.41969 | V30: 116.09304 | W30: 135.98332
A31: Hard coal and others | B31: 265.34574 | C31: 231.66604 | D31: 199.95228 | E31: 204.11522 | F31: 229.13431 | G31: 214.3092 | H31: 220.63869 | I31: 215.84265 | J31: 173.67721 | K31: 94.423216 | L31: 105.52399 | M31: 116.36999 | N31: 87.036543 | O31: 93.662167 | P31: 101.56922 | Q31: 100.15082 | R31: 107.05288 | S31: 120.60456 | T31: 124.94987 | U31: 103.41969 | V31: 116.09304 | W31: 135.98332
A32: Coke | B32: 0 | C32: 0 | D32: 0 | E32: 0 | F32: 0 | G32: 0 | H32: 0 | I32: 0 | J32: 0 | K32: 0 | L32: 0 | M32: 0 | N32: 0 | O32: 0 | P32: 0 | Q32: 0 | R32: 0 | S32: 0 | T32: 0 | U32: 0 | V32: 0 | W32: 0
A33: Liquids | B33: 750.30344 | C33: 796.08452 | D33: 779.36277 | E33: 776.95752 | F33: 803.67721 | G33: 764.48727 | H33: 808.41591 | I33: 746.92863 | J33: 645.73887 | K33: 532.95125 | L33: 547.8957 | M33: 518.13328 | N33: 481.36285 | O33: 409.99794 | P33: 391.165 | Q33: 390.1362 | R33: 423.04394 | S33: 438.65942 | T33: 406.92141 | U33: 425.6485 | V33: 448.61866 | W33: 498.42777
A34: Refinery gas | B34: 0 | C34: 0 | D34: 0 | E34: 0 | F34: 0 | G34: 0 | H34: 0 | I34: 0 | J34: 0 | K34: 0 | L34: 0 | M34: 0 | N34: 0 | O34: 0 | P34: 0 | Q34: 0 | R34: 0 | S34: 0 | T34: 0 | U34: 0 | V34: 0 | W34: 0
A35: LPG | B35: 46.145142 | C35: 40.651677 | D35: 39.552966 | E35: 40.651677 | F35: 40.651677 | G35: 41.750387 | H35: 40.651677 | I35: 32.960791 | J35: 31.862081 | K35: 25.269991 | L35: 28.566036 | M35: 26.368702 | N35: 29.664832 | O35: 25.269991 | P35: 21.973947 | Q35: 23.401032 | R35: 25.606105 | S35: 27.606707 | T35: 27.827687 | U35: 28.418659 | V35: 29.298796 | W35: 33.52313
A36: Diesel oil (without biofuels) | B36: 343.69682 | C36: 390.61109 | D36: 366.13405 | E36: 381.43224 | F36: 395.7104 | G36: 386.53138 | H36: 362.05451 | I36: 344.71677 | J36: 326.3589 | K36: 273.32562 | L36: 276.38521 | M36: 244.76922 | N36: 211.11341 | O36: 191.73577 | P36: 164.19931 | Q36: 167.32941 | R36: 172.02287 | S36: 175.09759 | T36: 189.99811 | U36: 179.62889 | V36: 192.36414 | W36: 273.18392
A37: Fuel oil | B37: 196.12347 | C37: 175.73457 | D37: 187.38547 | E37: 164.08349 | F37: 166.02537 | G37: 144.66543 | H37: 202.91995 | I37: 151.46182 | J37: 124.47687 | K37: 94.563887 | L37: 119.65219 | M37: 90.704127 | N37: 80.089682 | O37: 48.246776 | P37: 48.246776 | Q37: 41.747034 | R37: 44.274205 | S37: 46.415477 | T37: 22.842476 | U37: 31.696217 | V37: 37.590714 | W37: 26.482545
A38: Other liquids | B38: 164.33801 | C38: 189.08719 | D38: 186.29028 | E38: 190.79011 | F38: 201.28977 | G38: 191.54007 | H38: 202.78977 | I38: 217.78925 | J38: 163.04101 | K38: 139.79175 | L38: 123.29226 | M38: 156.29123 | N38: 160.49493 | O38: 144.7454 | P38: 156.74497 | Q38: 157.65873 | R38: 181.14076 | S38: 189.53964 | T38: 166.25314 | U38: 185.90473 | V38: 189.365 | W38: 165.23818
A39: Gases | B39: 777.92141 | C39: 837.27653 | D39: 746.93586 | E39: 748.14746 | F39: 714.12124 | G39: 714.47455 | H39: 714.6331 | I39: 716.14359 | J39: 722.92261 | K39: 661.72064 | L39: 713.13981 | M39: 713.63801 | N39: 683.32803 | O39: 676.32537 | P39: 683.39725 | Q39: 657.95959 | R39: 642.56457 | S39: 687.72614 | T39: 716.10653 | U39: 676.89484 | V39: 666.15133 | W39: 726.62408
A40: Natural gas | B40: 777.92141 | C40: 837.27653 | D40: 746.93586 | E40: 748.14746 | F40: 714.12124 | G40: 714.47455 | H40: 714.6331 | I40: 716.14359 | J40: 722.92261 | K40: 661.72064 | L40: 713.13981 | M40: 713.63801 | N40: 683.32803 | O40: 676.32537 | P40: 683.39725 | Q40: 657.95959 | R40: 642.56457 | S40: 687.72614 | T40: 716.10653 | U40: 676.89484 | V40: 666.15133 | W40: 726.62408
... A78: Other industrial sectors | B78: 511.20068 | C78: 541.13359 | D78: 521.89274 | E78: 547.61699 | F78: 554.84431 | G78: 549.06772 | H78: 526.69765 | I78: 498.36541 | J78: 474.28883 | K78: 401.41842 | L78: 412.19944 | M78: 409.10481 | N78: 364.74776 | O78: 347.84043 | P78: 327.60834 | Q78: 347.16012 | R78: 335.49518 | S78: 355.88207 | T78: 349.74562 | U78: 338.70544 | V78: 363.37253 | W78: 422.67339
A80: Non-energy use (ktoe)
A81: by fuel (EUROSTAT DATA) | B81: 251.93224 | C81: 217.21831 | D81: 216.95322 | E81: 229.03414 | F81: 258.50301 | G81: 240.02107 | H81: 248.34248 | I81: 260.82459 | J81: 219.9485 | K81: 211.48134 | L81: 223.83921 | M81: 254.1583 | N81: 233.24497 | O81: 237.22416 | P81: 211.381 | Q81: 210.13293 | R81: 209.23224 | S81: 205.84678 | T81: 203.89226 | U81: 161.13835 | V81: 184.75047 | W81: 181.62674
A82: Solids | B82: 0 | C82: 0 | D82: 0 | E82: 0 | F82: 0 | G82: 0 | H82: 0 | I82: 0 | J82: 0 | K82: 0 | L82: 0 | M82: 0 | N82: 0 | O82: 0 | P82: 0 | Q82: 0 | R82: 0 | S82: 0 | T82: 0 | U82: 0 | V82: 0 | W82: 0
A83: Liquids | B83: 251.93224 | C83: 217.21831 | D83: 216.95322 | E83: 229.03414 | F83: 258.50301 | G83: 240.02107 | H83: 248.34248 | I83: 260.82459 | J83: 219.9485 | K83: 211.48134 | L83: 223.83921 | M83: 254.1583 | N83: 233.24497 | O83: 237.22416 | P83: 211.381 | Q83: 210.13293 | R83: 209.23224 | S83: 205.84678 | T83: 203.89226 | U83: 161.13835 | V83: 184.75047 | W83: 181.62674
A84: Refinery gas | B84: 0 | C84: 0 | D84: 0 | E84: 0 | F84: 0 | G84: 0 | H84: 0 | I84: 0 | J84: 0 | K84: 0 | L84: 0 | M84: 0 | N84: 0 | O84: 0 | P84: 0 | Q84: 0 | R84: 0 | S84: 0 | T84: 0 | U84: 0 | V84: 0 | W84: 0
A85: LPG | B85: 0 | C85: 0 | D85: 0 | E85: 0 | F85: 0 | G85: 0 | H85: 0 | I85: 0 | J85: 0 | K85: 0 | L85: 0 | M85: 0 | N85: 0 | O85: 0 | P85: 0 | Q85: 0 | R85: 0 | S85: 0 | T85: 0 | U85: 0 | V85: 0 | W85: 0
A86: Diesel oil | B86: 0 | C86: 0 | D86: 0 | E86: 0 | F86: 0 | G86: 0 | H86: 0 | I86: 0 | J86: 0 | K86: 0 | L86: 0 | M86: 0 | N86: 0 | O86: 0 | P86: 0 | Q86: 0 | R86: 0 | S86: 0 | T86: 0 | U86: 0 | V86: 0 | W86: 0
A87: Fuel oil | B87: 0 | C87: 0 | D87: 0 | E87: 0 | F87: 0 | G87: 0 | H87: 0 | I87: 0 | J87: 0 | K87: 0 | L87: 0 | M87: 0 | N87: 0 | O87: 0 | P87: 0 | Q87: 0 | R87: 0 | S87: 0 | T87: 0 | U87: 0 | V87: 0 | W87: 0
A88: Other liquids | B88: 251.93224 | C88: 217.21831 | D88: 216.95322 | E88: 229.03414 | F88: 258.50301 | G88: 240.02107 | H88: 243.02812 | I88: 260.82459 | J88: 219.9485 | K88: 211.48134 | L88: 223.83921 | M88: 254.1583 | N88: 233.24497 | O88: 237.22416 | P88: 211.381 | Q88: 210.13293 | R88: 209.23224 | S88: 205.84678 | T88: 203.89226 | U88: 161.13835 | V88: 184.75047 | W88: 181.62674
A89: Naphtha | B89: 0 | C89: 0 | D89: 0 | E89: 0 | F89: 0 | G89: 0 | H89: 5.3143594 | I89: 0 | J89: 0 | K89: 0 | L89: 0 | M89: 0 | N89: 0 | O89: 0 | P89: 0 | Q89: 0 | R89: 0 | S89: 0 | T89: 0 | U89: 0 | V89: 0 | W89: 0
A90: Gas | B90: 0 | C90: 0 | D90: 0 | E90: 0 | F90: 0 | G90: 0 | H90: 0 | I90: 0 | J90: 0 | K90: 0 | L90: 0 | M90: 0 | N90: 0 | O90: 0 | P90: 0 | Q90: 0 | R90: 0 | S90: 0 | T90: 0 | U90: 0 | V90: 0 | W90: 0
A91: Natural gas | B91: 0 | C91: 0 | D91: 0 | E91: 0 | F91: 0 | G91: 0 | H91: 0 | I91: 0 | J91: 0 | K91: 0 | L91: 0 | M91: 0 | N91: 0 | O91: 0 | P91: 0 | Q91: 0 | R91: 0 | S91: 0 | T91: 0 | U91: 0 | V91: 0 | W91: 0
A92: Derived gases | B92: 0 | C92: 0 | D92: 0 | E92: 0 | F92: 0 | G92: 0 | H92: 0 | I92: 0 | J92: 0 | K92: 0 | L92: 0 | M92: 0 | N92: 0 | O92: 0 | P92: 0 | Q92: 0 | R92: 0 | S92: 0 | T92: 0 | U92: 0 | V92: 0 | W92: 0
...

Sheet JR_IDEES_Transport
A1: Transport overview - DK - Denmark | B1: 2000 | C1: 2001 | D1: 2002 | E1: 2003 | F1: 2004 | G1: 2005 | H1: 2006 | I1: 2007 | J1: 2008 | K1: 2009 | L1: 2010 | M1: 2011 | N1: 2012 | O1: 2013 | P1: 2014 | Q1: 2015 | R1: 2016 | S1: 2017 | T1: 2018 | U1: 2019 | V1: 2020 | W1: 2021 | DA1: Code
A3: Transport activity
A4: Passenger transport (mio pkm) | B4: =B5+B9+B13 -> 80919.582 | C4: =C5+C9+C13 -> 80579.964 | D4: =D5+D9+D13 -> 80402.728 | E4: =E5+E9+E13 -> 80277.971 | F4: =F5+F9+F13 -> 82886.695 | G4: =G5+G9+G13 -> 83444.355 | H4: =H5+H9+H13 -> 84016.094 | I4: =I5+I9+I13 -> 85003.083 | ... W4: =W5+W9+W13 -> 77844.912 | DA4: Activity.Mpkm.DK.Tr
A5: Road transport | B5: =B6+B7+B8 -> 58651.063 | C5: =C6+C7+C8 -> 57538.674 | D5: =D6+D7+D8 -> 57358.878 | E5: =E6+E7+E8 -> 57583.216 | F5: =F6+F7+F8 -> 58472.646 | G5: =G6+G7+G8 -> 57558.85 | H5: =H6+H7+H8 -> 57367.744 | I5: =I6+I7+I8 -> 58290.09 | ... W5: =W6+W7+W8 -> 64357.249 | DA5: Activity.Mpkm.DK.Tr.Road.Passenger
A6: =[1]TrRoad_act!$A$5 -> Powered two-wheelers | B6: =[1]TrRoad_act!B$5 -> 618.06271 | C6: =[1]TrRoad_act!C$5 -> 586.67394 | D6: =[1]TrRoad_act!D$5 -> 609.87844 | E6: =[1]TrRoad_act!E$5 -> 616.21647 | F6: =[1]TrRoad_act!F$5 -> 615.6463 | G6: =[1]TrRoad_act!G$5 -> 631.84951 | H6: =[1]TrRoad_act!H$5 -> 665.74426 | I6: =[1]TrRoad_act!I$5 -> 712.09003 | ... W6: =[1]TrRoad_act!W$5 -> 613.24874 | DA6: Activity.Mpkm.DK.Tr.Road.Passenger.P2W
A7: =[1]TrRoad_act!$A$6 -> Passenger cars | B7: =[1]TrRoad_act!B$6 -> 50615 | C7: =[1]TrRoad_act!C$6 -> 49620 | D7: =[1]TrRoad_act!D$6 -> 49454 | E7: =[1]TrRoad_act!E$6 -> 49695 | F7: =[1]TrRoad_act!F$6 -> 50557 | G7: =[1]TrRoad_act!G$6 -> 49758 | H7: =[1]TrRoad_act!H$6 -> 49648 | I7: =[1]TrRoad_act!I$6 -> 50733 | ... W7: =[1]TrRoad_act!W$6 -> 58910 | DA7: Activity.Mpkm.DK.Tr.Road.Passenger.Car
A8: =[1]TrRoad_act!$A$13 -> Motor coaches, buses and trolley buses | B8: =[1]TrRoad_act!B$13 -> 7418 | C8: =[1]TrRoad_act!C$13 -> 7332 | D8: =[1]TrRoad_act!D$13 -> 7295 | E8: =[1]TrRoad_act!E$13 -> 7272 | F8: =[1]TrRoad_act!F$13 -> 7300 | G8: =[1]TrRoad_act!G$13 -> 7169 | H8: =[1]TrRoad_act!H$13 -> 7054 | I8: =[1]TrRoad_act!I$13 -> 6845 | ... W8: =[1]TrRoad_act!W$13 -> 4834 | DA8: Activity.Mpkm.DK.Tr.Road.Passenger.Bus
A9: Rail, metro and tram | B9: =B10+B11+B12 -> 5537 | C9: =C10+C11+C12 -> 5721 | D9: =D10+D11+D12 -> 5754 | E9: =E10+E11+E12 -> 5893 | F9: =F10+F11+F12 -> 6074 | G9: =G10+G11+G12 -> 6136 | H9: =H10+H11+H12 -> 6274 | I9: =I10+I11+I12 -> 6353 | ... W9: =W10+W11+W12 -> 4512 | DA9: Activity.Mpkm.DK.Tr.Rail.Passenger
A10: =[1]TrRail_act!$A$5 -> Metro and tram, urban light rail | B10: =[1]TrRail_act!B$5 -> 0 | C10: =[1]TrRail_act!C$5 -> 0 | D10: =[1]TrRail_act!D$5 -> 9 | E10: =[1]TrRail_act!E$5 -> 67 | F10: =[1]TrRail_act!F$5 -> 128 | G10: =[1]TrRail_act!G$5 -> 162 | H10: =[1]TrRail_act!H$5 -> 164 | I10: =[1]TrRail_act!I$5 -> 177 | ... W10: =[1]TrRail_act!W$5 -> 331 | DA10: Activity.Mpkm.DK.Tr.Rail.Passenger.MTU
A11: =[1]TrRail_act!$A$6 -> Conventional passenger trains | B11: =[1]TrRail_act!B$6 -> 5537 | C11: =[1]TrRail_act!C$6 -> 5721 | D11: =[1]TrRail_act!D$6 -> 5745 | E11: =[1]TrRail_act!E$6 -> 5826 | F11: =[1]TrRail_act!F$6 -> 5946 | G11: =[1]TrRail_act!G$6 -> 5974 | H11: =[1]TrRail_act!H$6 -> 6110 | I11: =[1]TrRail_act!I$6 -> 6176 | ... W11: =[1]TrRail_act!W$6 -> 4181 | DA11: Activity.Mpkm.DK.Tr.Rail.Passenger.CPT
A12: =[1]TrRail_act!$A$9 -> High speed passenger trains | B12: =[1]TrRail_act!B$9 -> 0 | C12: =[1]TrRail_act!C$9 -> 0 | D12: =[1]TrRail_act!D$9 -> 0 | E12: =[1]TrRail_act!E$9 -> 0 | F12: =[1]TrRail_act!F$9 -> 0 | G12: =[1]TrRail_act!G$9 -> 0 | H12: =[1]TrRail_act!H$9 -> 0 | I12: =[1]TrRail_act!I$9 -> 0 | ... W12: =[1]TrRail_act!W$9 -> 0 | DA12: Activity.Mpkm.DK.Tr.Rail.Passenger.HST
A13: Aviation | B13: =B14+B15+B16 -> 16731.519 | C13: =C14+C15+C16 -> 17320.29 | D13: =D14+D15+D16 -> 17289.85 | E13: =E14+E15+E16 -> 16801.755 | F13: =F14+F15+F16 -> 18340.049 | G13: =G14+G15+G16 -> 19749.505 | H13: =H14+H15+H16 -> 20374.35 | I13: =I14+I15+I16 -> 20359.993 | ... W13: =W14+W15+W16 -> 8975.663 | DA13: Activity.Mpkm.DK.Tr.Avia.Passenger
A14: Domestic | B14: =[1]TrAvia_act!B$5 -> 291.40924 | C14: =[1]TrAvia_act!C$5 -> 299.46483 | D14: =[1]TrAvia_act!D$5 -> 270.63505 | E14: =[1]TrAvia_act!E$5 -> 294.26581 | F14: =[1]TrAvia_act!F$5 -> 369.96533 | G14: =[1]TrAvia_act!G$5 -> 371.63024 | H14: =[1]TrAvia_act!H$5 -> 403.57691 | I14: =[1]TrAvia_act!I$5 -> 446.87632 | ... W14: =[1]TrAvia_act!W$5 -> 231.30369 | DA14: Activity.Mpkm.DK.Tr.Avia.Passenger.Domestic
A15: International - Intra-EEAwUK | B15: =[1]TrAvia_act!B$6 -> 10186.298 | C15: =[1]TrAvia_act!C$6 -> 10566.784 | D15: =[1]TrAvia_act!D$6 -> 10520.061 | E15: =[1]TrAvia_act!E$6 -> 10218.513 | F15: =[1]TrAvia_act!F$6 -> 10696.839 | G15: =[1]TrAvia_act!G$6 -> 11149.757 | H15: =[1]TrAvia_act!H$6 -> 11392.019 | I15: =[1]TrAvia_act!I$6 -> 11336.021 | ... W15: =[1]TrAvia_act!W$6 -> 5724.8426 | DA15: Activity.Mpkm.DK.Tr.Avia.Passenger.IntraEEAwUK
A16: International - Extra-EEAwUK | B16: =[1]TrAvia_act!B$7 -> 6253.8116 | C16: =[1]TrAvia_act!C$7 -> 6454.0407 | D16: =[1]TrAvia_act!D$7 -> 6499.1536 | E16: =[1]TrAvia_act!E$7 -> 6288.9755 | F16: =[1]TrAvia_act!F$7 -> 7273.2448 | G16: =[1]TrAvia_act!G$7 -> 8228.1178 | H16: =[1]TrAvia_act!H$7 -> 8578.7544 | I16: =[1]TrAvia_act!I$7 -> 8577.0951 | ... W16: =[1]TrAvia_act!W$7 -> 3019.5167 | DA16: Activity.Mpkm.DK.Tr.Avia.Passenger.ExtraEEAwUK
A17: Freight transport (mio tkm) | B17: =B18+B21+B22+B26 -> 19712.316 | C17: =C18+C21+C22+C26 -> 20383.759 | D17: =D18+D21+D22+D26 -> 20424.27 | E17: =E18+E21+E22+E26 -> 20856.597 | F17: =F18+F21+F22+F26 -> 21493.434 | G17: =G18+G21+G22+G26 -> 22191.912 | H17: =H18+H21+H22+H26 -> 23434.226 | I17: =I18+I21+I22+I26 -> 24314.304 | ... W17: =W18+W21+W22+W26 -> 25902.463 | DA17: Activity.Mtkm.DK.Tr
A18: Road transport | B18: =B19+B20 -> 16102.826 | C18: =C19+C20 -> 16355.707 | D18: =D19+D20 -> 16829.378 | E18: =E19+E20 -> 16923.345 | F18: =F19+F20 -> 17328.699 | G18: =G19+G20 -> 18144.322 | H18: =H19+H20 -> 19191.164 | I18: =I19+I20 -> 20029.931 | ... W18: =W19+W20 -> 21986.879 | DA18: Activity.Mtkm.DK.Tr.Road.Freight
A19: =[1]TrRoad_act!$A$20 -> Light commercial vehicles | B19: =[1]TrRoad_act!B$20 -> 967.69162 | C19: =[1]TrRoad_act!C$20 -> 1039.2804 | D19: =[1]TrRoad_act!D$20 -> 1081.8776 | E19: =[1]TrRoad_act!E$20 -> 1145.3659 | F19: =[1]TrRoad_act!F$20 -> 1259.0691 | G19: =[1]TrRoad_act!G$20 -> 1357.8092 | H19: =[1]TrRoad_act!H$20 -> 1498.905 | I19: =[1]TrRoad_act!I$20 -> 1642.3373 | ... W19: =[1]TrRoad_act!W$20 -> 1167.8793 | DA19: Activity.Mtkm.DK.Tr.Road.Freight.LCV
A20: =[1]TrRoad_act!$A$26 -> Heavy goods vehicles | B20: =[1]TrRoad_act!B$26 -> 15135.134 | C20: =[1]TrRoad_act!C$26 -> 15316.427 | D20: =[1]TrRoad_act!D$26 -> 15747.501 | E20: =[1]TrRoad_act!E$26 -> 15777.979 | F20: =[1]TrRoad_act!F$26 -> 16069.63 | G20: =[1]TrRoad_act!G$26 -> 16786.513 | H20: =[1]TrRoad_act!H$26 -> 17692.259 | I20: =[1]TrRoad_act!I$26 -> 18387.594 | ... W20: =[1]TrRoad_act!W$26 -> 20819 | DA20: Activity.Mtkm.DK.Tr.Road.Freight.HGV
A21: Rail transport | B21: =[1]TrRail_act!B$10 -> 2025 | C21: =[1]TrRail_act!C$10 -> 2091 | D21: =[1]TrRail_act!D$10 -> 1877 | E21: =[1]TrRail_act!E$10 -> 1985 | F21: =[1]TrRail_act!F$10 -> 2321 | G21: =[1]TrRail_act!G$10 -> 1976 | H21: =[1]TrRail_act!H$10 -> 1892 | I21: =[1]TrRail_act!I$10 -> 1779 | ... W21: =[1]TrRail_act!W$10 -> 1986 | DA21: Activity.Mtkm.DK.Tr.Rail.Freight
A22: Aviation | B22: =B23+B24+B25 -> 51.312286 | C22: =C23+C24+C25 -> 56.206439 | D22: =D23+D24+D25 -> 51.509175 | E22: =E23+E24+E25 -> 40.183766 | F22: =F23+F24+F25 -> 40.256797 | G22: =G23+G24+G25 -> 42.399088 | H22: =H23+H24+H25 -> 41.294545 | I22: =I23+I24+I25 -> 38.369412 | ... W22: =W23+W24+W25 -> 414.46275 | DA22: Activity.Mtkm.DK.Tr.Avia.Freight
A23: Domestic | B23: =[1]TrAvia_act!B$9 -> 0.39172366 | C23: =[1]TrAvia_act!C$9 -> 0.41211957 | D23: =[1]TrAvia_act!D$9 -> 0.38472127 | E23: =[1]TrAvia_act!E$9 -> 0.28773505 | F23: =[1]TrAvia_act!F$9 -> 0.3010534 | G23: =[1]TrAvia_act!G$9 -> 0.3332811 | H23: =[1]TrAvia_act!H$9 -> 0.33346815 | I23: =[1]TrAvia_act!I$9 -> 0.26982735 | ... W23: =[1]TrAvia_act!W$9 -> 0.13964973 | DA23: Activity.Mtkm.DK.Tr.Avia.Freight.Domestic
A24: International - Intra-EEAwUK | B24: =[1]TrAvia_act!B$10 -> 42.905083 | C24: =[1]TrAvia_act!C$10 -> 46.931067 | D24: =[1]TrAvia_act!D$10 -> 41.432123 | E24: =[1]TrAvia_act!E$10 -> 30.287156 | F24: =[1]TrAvia_act!F$10 -> 30.62859 | G24: =[1]TrAvia_act!G$10 -> 35.808121 | H24: =[1]TrAvia_act!H$10 -> 37.802768 | I24: =[1]TrAvia_act!I$10 -> 34.545833 | ... W24: =[1]TrAvia_act!W$10 -> 75.077322 | DA24: Activity.Mtkm.DK.Tr.Avia.Freight.IntraEEAwUK
A25: International - Extra-EEAwUK | B25: =[1]TrAvia_act!B$11 -> 8.0154786 | C25: =[1]TrAvia_act!C$11 -> 8.8632525 | D25: =[1]TrAvia_act!D$11 -> 9.692331 | E25: =[1]TrAvia_act!E$11 -> 9.608875 | F25: =[1]TrAvia_act!F$11 -> 9.3271538 | G25: =[1]TrAvia_act!G$11 -> 6.2576859 | H25: =[1]TrAvia_act!H$11 -> 3.158309 | I25: =[1]TrAvia_act!I$11 -> 3.5537514 | ... W25: =[1]TrAvia_act!W$11 -> 339.24578 | DA25: Activity.Mtkm.DK.Tr.Avia.Freight.ExtraEEAwUK
A26: Domestic navigation | B26: =B27+B28 -> 1533.178 | C26: =C27+C28 -> 1880.845 | D26: =D27+D28 -> 1666.383 | E26: =E27+E28 -> 1908.069 | F26: =F27+F28 -> 1803.478 | G26: =G27+G28 -> 2029.19 | H26: =H27+H28 -> 2309.768 | I26: =I27+I28 -> 2467.003 | ... W26: =W27+W28 -> 1515.121 | DA26: Activity.Mtkm.DK.Tr.DNavi.Freight
A27: =[1]TrNavi_act!$A$4 -> Domestic coastal shipping | B27: =[1]TrNavi_act!B4 -> 1533.178 | C27: =[1]TrNavi_act!C4 -> 1880.845 | D27: =[1]TrNavi_act!D4 -> 1666.383 | E27: =[1]TrNavi_act!E4 -> 1908.069 | F27: =[1]TrNavi_act!F4 -> 1803.478 | G27: =[1]TrNavi_act!G4 -> 2029.19 | H27: =[1]TrNavi_act!H4 -> 2309.768 | I27: =[1]TrNavi_act!I4 -> 2467.003 | ... W27: =[1]TrNavi_act!W4 -> 1515.121 | DA27: Activity.Mtkm.DK.Tr.DNavi.Freight.DCS
A28: =[1]TrNavi_act!$A$5 -> Inland waterways | B28: =[1]TrNavi_act!B5 -> 0 | C28: =[1]TrNavi_act!C5 -> 0 | D28: =[1]TrNavi_act!D5 -> 0 | E28: =[1]TrNavi_act!E5 -> 0 | F28: =[1]TrNavi_act!F5 -> 0 | G28: =[1]TrNavi_act!G5 -> 0 | H28: =[1]TrNavi_act!H5 -> 0 | I28: =[1]TrNavi_act!I5 -> 0 | ... W28: =[1]TrNavi_act!W5 -> 0 | DA28: Activity.Mtkm.DK.Tr.DNavi.Freight.IWW
A29: International maritime bunkers (mio tkm) | B29: =B30+B31 -> 81281.35 | C29: =C30+C31 -> 83300.366 | D29: =D30+D31 -> 80390.999 | E29: =E30+E31 -> 96936.548 | F29: =F30+F31 -> 84397.889 | G29: =G30+G31 -> 80544.612 | H29: =H30+H31 -> 96164.465 | I29: =I30+I31 -> 87471.138 | ... W29: =W30+W31 -> 103585.6 | DA29: Activity.Mtkm.DK.MBunk.Freight
A30: Intra-EEA | B30: =[1]MBunk_act!B$4 -> 21870.694 | C30: =[1]MBunk_act!C$4 -> 21927.96 | D30: =[1]MBunk_act!D$4 -> 22405.537 | E30: =[1]MBunk_act!E$4 -> 23368.593 | F30: =[1]MBunk_act!F$4 -> 24548.212 | G30: =[1]MBunk_act!G$4 -> 24152.366 | H30: =[1]MBunk_act!H$4 -> 22890.939 | I30: =[1]MBunk_act!I$4 -> 22088.239 | ... W30: =[1]MBunk_act!W$4 -> 22073.122 | DA30: Activity.Mtkm.DK.MBunk.Freight.IntraEEA
A31: Extra-EEA | B31: =[1]MBunk_act!B$5 -> 59410.657 | C31: =[1]MBunk_act!C$5 -> 61372.406 | D31: =[1]MBunk_act!D$5 -> 57985.463 | E31: =[1]MBunk_act!E$5 -> 73567.954 | F31: =[1]MBunk_act!F$5 -> 59849.677 | G31: =[1]MBunk_act!G$5 -> 56392.246 | H31: =[1]MBunk_act!H$5 -> 73273.526 | I31: =[1]MBunk_act!I$5 -> 65382.899 | ... W31: =[1]MBunk_act!W$5 -> 81512.483 | DA31: Activity.Mtkm.DK.MBunk.Freight.ExtraEEA
A33: Energy consumption (ktoe)
A34: Passenger transport | B34: =B35+B39+B43 -> 3307.4593 | C34: =C35+C39+C43 -> 3281.5652 | D34: =D35+D39+D43 -> 3197.6932 | E34: =E35+E39+E43 -> 3270.3024 | F34: =F35+F39+F43 -> 3380.4604 | G34: =G35+G39+G43 -> 3434.6098 | H34: =H35+H39+H43 -> 3465.808 | I34: =I35+I39+I43 -> 3602.8954 | ... W34: =W35+W39+W43 -> 2976.3005
A35: =$A$5 -> Road transport | B35: =B36+B37+B38 -> 2394.1844 | C35: =C36+C37+C38 -> 2359.589 | D35: =D36+D37+D38 -> 2385.6476 | E35: =E36+E37+E38 -> 2430.4543 | F35: =F36+F37+F38 -> 2443.9265 | G35: =G36+G37+G38 -> 2449.0674 | H35: =H36+H37+H38 -> 2476.5229 | I35: =I36+I37+I38 -> 2587.0712 | ... W35: =W36+W37+W38 -> 2483.6919 | DA35: FEC.ktoe.DK.Tr.Road.Passenger
A36: =$A$6 -> Powered two-wheelers | B36: =[1]TrRoad_ene!B$19 -> 23.705498 | C36: =[1]TrRoad_ene!C$19 -> 22.33404 | D36: =[1]TrRoad_ene!D$19 -> 23.087707 | E36: =[1]TrRoad_ene!E$19 -> 23.246936 | F36: =[1]TrRoad_ene!F$19 -> 23.012006 | G36: =[1]TrRoad_ene!G$19 -> 23.252001 | H36: =[1]TrRoad_ene!H$19 -> 24.15043 | I36: =[1]TrRoad_ene!I$19 -> 25.423038 | ... W36: =[1]TrRoad_ene!W$19 -> 19.048651 | DA36: FEC.ktoe.DK.Tr.Road.Passenger.P2W
A37: =$A$7 -> Passenger cars | B37: =[1]TrRoad_ene!B$21 -> 2026.7729 | C37: =[1]TrRoad_ene!C$21 -> 2003.1332 | D37: =[1]TrRoad_ene!D$21 -> 2036.7311 | E37: =[1]TrRoad_ene!E$21 -> 2077.2016 | F37: =[1]TrRoad_ene!F$21 -> 2096.6248 | G37: =[1]TrRoad_ene!G$21 -> 2098.6092 | H37: =[1]TrRoad_ene!H$21 -> 2122.8742 | I37: =[1]TrRoad_ene!I$21 -> 2235.8474 | ... W37: =[1]TrRoad_ene!W$21 -> 2124.5336 | DA37: FEC.ktoe.DK.Tr.Road.Passenger.Car
A38: =$A$8 -> Motor coaches, buses and trolley buses | B38: =[1]TrRoad_ene!B$33 -> 343.70598 | C38: =[1]TrRoad_ene!C$33 -> 334.12167 | D38: =[1]TrRoad_ene!D$33 -> 325.82878 | E38: =[1]TrRoad_ene!E$33 -> 330.00574 | F38: =[1]TrRoad_ene!F$33 -> 324.28973 | G38: =[1]TrRoad_ene!G$33 -> 327.20618 | H38: =[1]TrRoad_ene!H$33 -> 329.49826 | I38: =[1]TrRoad_ene!I$33 -> 325.80074 | ... W38: =[1]TrRoad_ene!W$33 -> 340.10962 | DA38: FEC.ktoe.DK.Tr.Road.Passenger.Bus
A39: =$A$9 -> Rail, metro and tram | B39: =B40+B41+B42 -> 89.871731 | C39: =C40+C41+C42 -> 85.365322 | D39: =D40+D41+D42 -> 88.050168 | E39: =E40+E41+E42 -> 89.420556 | F39: =F40+F41+F42 -> 88.190394 | G39: =G40+G41+G42 -> 94.597255 | H39: =H40+H41+H42 -> 94.655942 | I39: =I40+I41+I42 -> 93.943689 | ... W39: =W40+W41+W42 -> 89.392959 | DA39: FEC.ktoe.DK.Tr.Rail.Passenger
A40: =$A$10 -> Metro and tram, urban light rail | B40: =[1]TrRail_ene!B$12 -> 0 | C40: =[1]TrRail_ene!C$12 -> 0 | D40: =[1]TrRail_ene!D$12 -> 0.040961843 | E40: =[1]TrRail_ene!E$12 -> 0.31247756 | F40: =[1]TrRail_ene!F$12 -> 0.59371176 | G40: =[1]TrRail_ene!G$12 -> 0.75592417 | H40: =[1]TrRail_ene!H$12 -> 0.76062061 | I40: =[1]TrRail_ene!I$12 -> 0.81070195 | ... W40: =[1]TrRail_ene!W$12 -> 1.7549455 | DA40: FEC.ktoe.DK.Tr.Rail.Passenger.MTU
A41: =$A$11 -> Conventional passenger trains | B41: =[1]TrRail_ene!B$13 -> 89.871731 | C41: =[1]TrRail_ene!C$13 -> 85.365322 | D41: =[1]TrRail_ene!D$13 -> 88.009206 | E41: =[1]TrRail_ene!E$13 -> 89.108078 | F41: =[1]TrRail_ene!F$13 -> 87.596682 | G41: =[1]TrRail_ene!G$13 -> 93.841331 | H41: =[1]TrRail_ene!H$13 -> 93.895321 | I41: =[1]TrRail_ene!I$13 -> 93.132987 | ... W41: =[1]TrRail_ene!W$13 -> 87.638013 | DA41: FEC.ktoe.DK.Tr.Rail.Passenger.CPT
A42: =$A$12 -> High speed passenger trains | B42: =[1]TrRail_ene!B$16 -> 0 | C42: =[1]TrRail_ene!C$16 -> 0 | D42: =[1]TrRail_ene!D$16 -> 0 | E42: =[1]TrRail_ene!E$16 -> 0 | F42: =[1]TrRail_ene!F$16 -> 0 | G42: =[1]TrRail_ene!G$16 -> 0 | H42: =[1]TrRail_ene!H$16 -> 0 | I42: =[1]TrRail_ene!I$16 -> 0 | ... W42: =[1]TrRail_ene!W$16 -> 0 | DA42: FEC.ktoe.DK.Tr.Rail.Passenger.HST
...
