Workbook

Sheet cover
B6: JRC-IDEES-2021 - Integrated Database of the European Energy System
C10: Slovenia
C15: Energy balances
L28: Prepared by JRC C.6
L30: 45432.789
L31: v2021-1.00
B33: Legal Notice
B35: The information made available is property of the Joint Research Centre of the European Commission.
B36: Neither the European Commission nor any person acting on behalf of the Commission is responsible for the use which might be made of this information.
B38: Use conditions
B39: This work is licensed under
B40: CC BY 4.0

Sheet index
A1: Slovenia | B1: SI | C1: 2000 | D1: 2001 | E1: 2002 | F1: 2003 | G1: 2004 | H1: 2005 | I1: 2006 | J1: 2007 | K1: 2008 | L1: 2009 | M1: 2010 | N1: 2011 | O1: 2012 | P1: 2013 | Q1: 2014 | R1: 2015 | S1: 2016 | T1: 2017 | U1: 2018 | V1: 2019 | W1: 2020 | X1: 2021
B2: Click on the link to jump to the sheet
A3: Total | B3: ktoe
A4: Primary production | B4: =HYPERLINK("#"&CELL("address",PPRD!$X$2),"PPRD") -> PPRD | C4: =PPRD!C$2 -> 3198.523 | D4: =PPRD!D$2 -> 3352.0719 | E4: =PPRD!E$2 -> 3443.6553 | F4: =PPRD!F$2 -> 3404.5082 | G4: =PPRD!G$2 -> 3582.0497 | H4: =PPRD!H$2 -> 3730.6003 | I4: =PPRD!I$2 -> 3602.9948 | J4: =PPRD!J$2 -> 3704.6996 | ... X4: =PPRD!X$2 -> 3281.7735
A5: Recovered & recycled products | B5: =HYPERLINK("#"&CELL("address",RCV_RCY!$X$2),"RCV_RCY") -> RCV_RCY | C5: =RCV_RCY!C$2 -> 0 | D5: =RCV_RCY!D$2 -> 0 | E5: =RCV_RCY!E$2 -> 0 | F5: =RCV_RCY!F$2 -> 0 | G5: =RCV_RCY!G$2 -> 0 | H5: =RCV_RCY!H$2 -> 0 | I5: =RCV_RCY!I$2 -> 0 | J5: =RCV_RCY!J$2 -> 0 | ... X5: =RCV_RCY!X$2 -> 0
A6: Imports | B6: =HYPERLINK("#"&CELL("address",IMP!$X$2),"IMP") -> IMP | C6: =IMP!C$2 -> 4117.7063 | D6: =IMP!D$2 -> 3999.8991 | E6: =IMP!E$2 -> 4020.9839 | F6: =IMP!F$2 -> 4324.0187 | G6: =IMP!G$2 -> 4599.2665 | H6: =IMP!H$2 -> 4914.8116 | I6: =IMP!I$2 -> 4929.7571 | J6: =IMP!J$2 -> 4831.7623 | ... X6: =IMP!X$2 -> 5593.7935
A7: Exports | B7: =HYPERLINK("#"&CELL("address",EXP!$X$2),"EXP") -> EXP | C7: =EXP!C$2 -> 715.54712 | D7: =EXP!D$2 -> 586.56991 | E7: =EXP!E$2 -> 544.49475 | F7: =EXP!F$2 -> 598.5534 | G7: =EXP!G$2 -> 850.02683 | H7: =EXP!H$2 -> 1060.0506 | I7: =EXP!I$2 -> 1090.8564 | J7: =EXP!J$2 -> 941.76406 | ... X7: =EXP!X$2 -> 2370.2681
A8: Change in stock | B8: =HYPERLINK("#"&CELL("address",STK_CHG!$X$2),"STK_CHG") -> STK_CHG | C8: =STK_CHG!C$2 -> -39.445658 | D8: =STK_CHG!D$2 -> 209.0804 | E8: =STK_CHG!E$2 -> 67.929665 | F8: =STK_CHG!F$2 -> -29.421496 | G8: =STK_CHG!G$2 -> -34.092175 | H8: =STK_CHG!H$2 -> -1.0979364 | I8: =STK_CHG!I$2 -> 100.55305 | J8: =STK_CHG!J$2 -> 59.565778 | ... X8: =STK_CHG!X$2 -> 125.3988
A9: Gross available energy | B9: =HYPERLINK("#"&CELL("address",GAE!$X$2),"GAE") -> GAE | C9: =GAE!C$2 -> 6561.2365 | D9: =GAE!D$2 -> 6974.4815 | E9: =GAE!E$2 -> 6988.0741 | F9: =GAE!F$2 -> 7100.5519 | G9: =GAE!G$2 -> 7297.1972 | H9: =GAE!H$2 -> 7584.2634 | I9: =GAE!I$2 -> 7542.4486 | J9: =GAE!J$2 -> 7654.2635 | ... X9: =GAE!X$2 -> 6630.6977
A10: International maritime bunkers | B10: =HYPERLINK("#"&CELL("address",INTMARB!$X$2),"INTMARB") -> INTMARB | C10: =INTMARB!C$2 -> 0 | D10: =INTMARB!D$2 -> 0 | E10: =INTMARB!E$2 -> 0 | F10: =INTMARB!F$2 -> 0 | G10: =INTMARB!G$2 -> 0 | H10: =INTMARB!H$2 -> 21.228633 | I10: =INTMARB!I$2 -> 28.948151 | J10: =INTMARB!J$2 -> 48.192433 | ... X10: =INTMARB!X$2 -> 85.820722
A11: International Intra-EEA maritime bunkers | B11: =HYPERLINK("#"&CELL("address",INTMARB_IN!$X$2),"INTMARB_IN") -> INTMARB_IN | C11: =INTMARB_IN!C$2 -> 0 | D11: =INTMARB_IN!D$2 -> 0 | E11: =INTMARB_IN!E$2 -> 0 | F11: =INTMARB_IN!F$2 -> 0 | G11: =INTMARB_IN!G$2 -> 0 | H11: =INTMARB_IN!H$2 -> 7.4330211 | I11: =INTMARB_IN!I$2 -> 10.062368 | J11: =INTMARB_IN!J$2 -> 16.051288 | ... X11: =INTMARB_IN!X$2 -> 13.493166
A12: International Extra-EEA maritime bunkers | B12: =HYPERLINK("#"&CELL("address",INTMARB_EX!$X$2),"INTMARB_EX") -> INTMARB_EX | C12: =INTMARB_EX!C$2 -> 0 | D12: =INTMARB_EX!D$2 -> 0 | E12: =INTMARB_EX!E$2 -> 0 | F12: =INTMARB_EX!F$2 -> 0 | G12: =INTMARB_EX!G$2 -> 0 | H12: =INTMARB_EX!H$2 -> 13.795612 | I12: =INTMARB_EX!I$2 -> 18.885784 | J12: =INTMARB_EX!J$2 -> 32.141146 | ... X12: =INTMARB_EX!X$2 -> 72.327557
A13: Gross inland consumption | B13: =HYPERLINK("#"&CELL("address",GIC!$X$2),"GIC") -> GIC | C13: =GIC!C$2 -> 6561.2365 | D13: =GIC!D$2 -> 6974.4815 | E13: =GIC!E$2 -> 6988.0741 | F13: =GIC!F$2 -> 7100.5519 | G13: =GIC!G$2 -> 7297.1972 | H13: =GIC!H$2 -> 7563.0347 | I13: =GIC!I$2 -> 7513.5004 | J13: =GIC!J$2 -> 7606.0711 | ... X13: =GIC!X$2 -> 6544.877
A14: International aviation | B14: =HYPERLINK("#"&CELL("address",INTAVI!$X$2),"INTAVI") -> INTAVI | C14: =INTAVI!C$2 -> 25.27945 | D14: =INTAVI!D$2 -> 27.386071 | E14: =INTAVI!E$2 -> 29.492691 | F14: =INTAVI!F$2 -> 26.33276 | G14: =INTAVI!G$2 -> 20.012898 | H14: =INTAVI!H$2 -> 23.172829 | I14: =INTAVI!I$2 -> 25.27945 | J14: =INTAVI!J$2 -> 32.238005 | ... X14: =INTAVI!X$2 -> 10.692605
A15: International Intra-EEAwUK passenger aviation | B15: =HYPERLINK("#"&CELL("address",INTAVI_PA_IN!$X$2),"INTAVI_PA_IN") -> INTAVI_PA_IN | C15: =INTAVI_PA_IN!C$2 -> 14.640956 | D15: =INTAVI_PA_IN!D$2 -> 15.885905 | E15: =INTAVI_PA_IN!E$2 -> 17.126259 | F15: =INTAVI_PA_IN!F$2 -> 15.261154 | G15: =INTAVI_PA_IN!G$2 -> 11.538124 | H15: =INTAVI_PA_IN!H$2 -> 13.594441 | I15: =INTAVI_PA_IN!I$2 -> 15.182495 | J15: =INTAVI_PA_IN!J$2 -> 19.088977 | ... X15: =INTAVI_PA_IN!X$2 -> 5.5530045
A16: International Extra-EEAwUK passenger aviation | B16: =HYPERLINK("#"&CELL("address",INTAVI_PA_EX!$X$2),"INTAVI_PA_EX") -> INTAVI_PA_EX | C16: =INTAVI_PA_EX!C$2 -> 10.295875 | D16: =INTAVI_PA_EX!D$2 -> 11.17371 | E16: =INTAVI_PA_EX!E$2 -> 12.044101 | F16: =INTAVI_PA_EX!F$2 -> 10.731255 | G16: =INTAVI_PA_EX!G$2 -> 8.113584 | H16: =INTAVI_PA_EX!H$2 -> 9.2031448 | I16: =INTAVI_PA_EX!I$2 -> 9.6632201 | J16: =INTAVI_PA_EX!J$2 -> 11.91639 | ... X16: =INTAVI_PA_EX!X$2 -> 4.4971625
A17: International Intra-EEAwUK freight aviation | B17: =HYPERLINK("#"&CELL("address",INTAVI_FR_IN!$X$2),"INTAVI_FR_IN") -> INTAVI_FR_IN | C17: =INTAVI_FR_IN!C$2 -> 0.18124711 | D17: =INTAVI_FR_IN!D$2 -> 0.15689592 | E17: =INTAVI_FR_IN!E$2 -> 0.13662483 | F17: =INTAVI_FR_IN!F$2 -> 0.11495503 | G17: =INTAVI_FR_IN!G$2 -> 0.11319683 | H17: =INTAVI_FR_IN!H$2 -> 0.12919576 | I17: =INTAVI_FR_IN!I$2 -> 0.27570781 | J17: =INTAVI_FR_IN!J$2 -> 1.1227256 | ... X17: =INTAVI_FR_IN!X$2 -> 0.58976307
A18: International Extra-EEAwUK freight aviation | B18: =HYPERLINK("#"&CELL("address",INTAVI_FR_EX!$X$2),"INTAVI_FR_EX") -> INTAVI_FR_EX | C18: =INTAVI_FR_EX!C$2 -> 0.16137069 | D18: =INTAVI_FR_EX!D$2 -> 0.16955993 | E18: =INTAVI_FR_EX!E$2 -> 0.18570683 | F18: =INTAVI_FR_EX!F$2 -> 0.22539651 | G18: =INTAVI_FR_EX!G$2 -> 0.24799335 | H18: =INTAVI_FR_EX!H$2 -> 0.24604751 | I18: =INTAVI_FR_EX!I$2 -> 0.15802627 | J18: =INTAVI_FR_EX!J$2 -> 0.10991268 | ... X18: =INTAVI_FR_EX!X$2 -> 0.052675241
A19: Total energy supply | B19: =HYPERLINK("#"&CELL("address",NRGSUP!$X$2),"NRGSUP") -> NRGSUP | C19: =NRGSUP!C$2 -> 6535.9571 | D19: =NRGSUP!D$2 -> 6947.0954 | E19: =NRGSUP!E$2 -> 6958.5814 | F19: =NRGSUP!F$2 -> 7074.2192 | G19: =NRGSUP!G$2 -> 7277.1843 | H19: =NRGSUP!H$2 -> 7539.8619 | I19: =NRGSUP!I$2 -> 7488.221 | J19: =NRGSUP!J$2 -> 7573.8331 | ... X19: =NRGSUP!X$2 -> 6534.1844
A20: Gross inland consumption (Europe 2020-2030) | B20: =HYPERLINK("#"&CELL("address",'GIC2020-2030'!$X$2),"GIC2020-2030") -> GIC2020-2030 | C20: ='GIC2020-2030'!C$2 -> 6560.5806 | D20: ='GIC2020-2030'!D$2 -> 6973.7357 | E20: ='GIC2020-2030'!E$2 -> 6987.2775 | F20: ='GIC2020-2030'!F$2 -> 7099.4755 | G20: ='GIC2020-2030'!G$2 -> 7295.5968 | H20: ='GIC2020-2030'!H$2 -> 7560.6531 | I20: ='GIC2020-2030'!I$2 -> 7510.4127 | J20: ='GIC2020-2030'!J$2 -> 7602.1524 | ... X20: ='GIC2020-2030'!X$2 -> 6486.5443
A21: Primary energy consumption (Europe 2020-2030) | B21: =HYPERLINK("#"&CELL("address",'PEC2020-2030'!$X$2),"PEC2020-2030") -> PEC2020-2030 | C21: ='PEC2020-2030'!C$2 -> 6320.4163 | D21: ='PEC2020-2030'!D$2 -> 6740.7463 | E21: ='PEC2020-2030'!E$2 -> 6771.5158 | F21: ='PEC2020-2030'!F$2 -> 6829.2353 | G21: ='PEC2020-2030'!G$2 -> 6988.5511 | H21: ='PEC2020-2030'!H$2 -> 7249.8016 | I21: ='PEC2020-2030'!I$2 -> 7190.7279 | J21: ='PEC2020-2030'!J$2 -> 7282.9143 | ... X21: ='PEC2020-2030'!X$2 -> 6334.7872
A22: Final energy consumption (Europe 2020-2030) | B22: =HYPERLINK("#"&CELL("address",'FEC2020-2030'!$X$2),"FEC2020-2030") -> FEC2020-2030 | C22: ='FEC2020-2030'!C$2 -> 4567.1107 | D22: ='FEC2020-2030'!D$2 -> 4808.2666 | E22: ='FEC2020-2030'!E$2 -> 4704.1124 | F22: ='FEC2020-2030'!F$2 -> 4861.2788 | G22: ='FEC2020-2030'!G$2 -> 4952.3023 | H22: ='FEC2020-2030'!H$2 -> 5131.6888 | I22: ='FEC2020-2030'!I$2 -> 5121.139 | J22: ='FEC2020-2030'!J$2 -> 5144.5893 | ... X22: ='FEC2020-2030'!X$2 -> 4719.9817
A23: Transformation input | B23: =HYPERLINK("#"&CELL("address",TI_E!$X$2),"TI_E") -> TI_E | C23: =TI_E!C$2 -> 3107.2724 | D23: =TI_E!D$2 -> 3174.9431 | E23: =TI_E!E$2 -> 3350.6118 | F23: =TI_E!F$2 -> 3170.9168 | G23: =TI_E!G$2 -> 3345.1673 | H23: =TI_E!H$2 -> 3412.7212 | I23: =TI_E!I$2 -> 3369.2833 | J23: =TI_E!J$2 -> 3418.1211 | ... X23: =TI_E!X$2 -> 3100.9864
A24: Electricity & heat generation | B24: =HYPERLINK("#"&CELL("address",TI_EHG_E!$X$2),"TI_EHG_E") -> TI_EHG_E | C24: =TI_EHG_E!C$2 -> 2939.316 | D24: =TI_EHG_E!D$2 -> 3174.9431 | E24: =TI_EHG_E!E$2 -> 3350.6118 | F24: =TI_EHG_E!F$2 -> 3170.9168 | G24: =TI_EHG_E!G$2 -> 3345.1673 | H24: =TI_EHG_E!H$2 -> 3412.7212 | I24: =TI_EHG_E!I$2 -> 3364.8766 | J24: =TI_EHG_E!J$2 -> 3404.9009 | ... X24: =TI_EHG_E!X$2 -> 3006.2844
A25: Electricity only | B25: =HYPERLINK("#"&CELL("address",TI_EHG_E_E!$X$2),"TI_EHG_E_E") -> TI_EHG_E_E | C25: =TI_EHG_E_E!C$2 -> 1704.3761 | D25: =TI_EHG_E_E!D$2 -> 1860.031 | E25: =TI_EHG_E_E!E$2 -> 1886.9182 | F25: =TI_EHG_E_E!F$2 -> 1788.882 | G25: =TI_EHG_E_E!G$2 -> 1925.2942 | H25: =TI_EHG_E_E!H$2 -> 1977.1441 | I25: =TI_EHG_E_E!I$2 -> 1928.9709 | J25: =TI_EHG_E_E!J$2 -> 1939.1366 | ... X25: =TI_EHG_E_E!X$2 -> 1816.6414
A26: CHP | B26: =HYPERLINK("#"&CELL("address",TI_EHG_CHP_E!$X$2),"TI_EHG_CHP_E") -> TI_EHG_CHP_E | C26: =TI_EHG_CHP_E!C$2 -> 1155.2322 | D26: =TI_EHG_CHP_E!D$2 -> 1239.1263 | E26: =TI_EHG_CHP_E!E$2 -> 1384.275 | F26: =TI_EHG_CHP_E!F$2 -> 1295.8024 | G26: =TI_EHG_CHP_E!G$2 -> 1340.3913 | H26: =TI_EHG_CHP_E!H$2 -> 1346.2164 | I26: =TI_EHG_CHP_E!I$2 -> 1362.1504 | J26: =TI_EHG_CHP_E!J$2 -> 1410.6801 | ... X26: =TI_EHG_CHP_E!X$2 -> 1087.7917
A27: Heat only | B27: =HYPERLINK("#"&CELL("address",TI_EHG_H_E!$X$2),"TI_EHG_H_E") -> TI_EHG_H_E | C27: =TI_EHG_H_E!C$2 -> 79.707653 | D27: =TI_EHG_H_E!D$2 -> 75.785813 | E27: =TI_EHG_H_E!E$2 -> 79.418573 | F27: =TI_EHG_H_E!F$2 -> 86.232416 | G27: =TI_EHG_H_E!G$2 -> 79.481857 | H27: =TI_EHG_H_E!H$2 -> 89.360791 | I27: =TI_EHG_H_E!I$2 -> 73.755374 | J27: =TI_EHG_H_E!J$2 -> 55.084265 | ... X27: =TI_EHG_H_E!X$2 -> 68.259587
A28: Electrically driven heat pumps | B28: =HYPERLINK("#"&CELL("address",TI_EHG_EDHP!$X$2),"TI_EHG_EDHP") -> TI_EHG_EDHP | C28: =TI_EHG_EDHP!C$2 -> 0 | D28: =TI_EHG_EDHP!D$2 -> 0 | E28: =TI_EHG_EDHP!E$2 -> 0 | F28: =TI_EHG_EDHP!F$2 -> 0 | G28: =TI_EHG_EDHP!G$2 -> 0 | H28: =TI_EHG_EDHP!H$2 -> 0 | I28: =TI_EHG_EDHP!I$2 -> 0 | J28: =TI_EHG_EDHP!J$2 -> 0 | ... X28: =TI_EHG_EDHP!X$2 -> 0
A29: Electric boilers | B29: =HYPERLINK("#"&CELL("address",TI_EHG_EB!$X$2),"TI_EHG_EB") -> TI_EHG_EB | C29: =TI_EHG_EB!C$2 -> 0 | D29: =TI_EHG_EB!D$2 -> 0 | E29: =TI_EHG_EB!E$2 -> 0 | F29: =TI_EHG_EB!F$2 -> 0 | G29: =TI_EHG_EB!G$2 -> 0 | H29: =TI_EHG_EB!H$2 -> 0 | I29: =TI_EHG_EB!I$2 -> 0 | J29: =TI_EHG_EB!J$2 -> 0 | ... X29: =TI_EHG_EB!X$2 -> 0
A30: Electricity for pumped storage | B30: =HYPERLINK("#"&CELL("address",TI_EHG_EPS!$X$2),"TI_EHG_EPS") -> TI_EHG_EPS | C30: =TI_EHG_EPS!C$2 -> 0 | D30: =TI_EHG_EPS!D$2 -> 0 | E30: =TI_EHG_EPS!E$2 -> 0 | F30: =TI_EHG_EPS!F$2 -> 0 | G30: =TI_EHG_EPS!G$2 -> 0 | H30: =TI_EHG_EPS!H$2 -> 0 | I30: =TI_EHG_EPS!I$2 -> 0 | J30: =TI_EHG_EPS!J$2 -> 0 | ... X30: =TI_EHG_EPS!X$2 -> 33.591745
A31: Derived heat for electricity production | B31: =HYPERLINK("#"&CELL("address",TI_EHG_DHEP!$X$2),"TI_EHG_DHEP") -> TI_EHG_DHEP | C31: =TI_EHG_DHEP!C$2 -> 0 | D31: =TI_EHG_DHEP!D$2 -> 0 | E31: =TI_EHG_DHEP!E$2 -> 0 | F31: =TI_EHG_DHEP!F$2 -> 0 | G31: =TI_EHG_DHEP!G$2 -> 0 | H31: =TI_EHG_DHEP!H$2 -> 0 | I31: =TI_EHG_DHEP!I$2 -> 0 | J31: =TI_EHG_DHEP!J$2 -> 0 | ... X31: =TI_EHG_DHEP!X$2 -> 0
A32: Coke ovens | B32: =HYPERLINK("#"&CELL("address",TI_CO_E!$X$2),"TI_CO_E") -> TI_CO_E | C32: =TI_CO_E!C$2 -> 0 | D32: =TI_CO_E!D$2 -> 0 | E32: =TI_CO_E!E$2 -> 0 | F32: =TI_CO_E!F$2 -> 0 | G32: =TI_CO_E!G$2 -> 0 | H32: =TI_CO_E!H$2 -> 0 | I32: =TI_CO_E!I$2 -> 0 | J32: =TI_CO_E!J$2 -> 0 | ... X32: =TI_CO_E!X$2 -> 0
A33: Blast furnaces | B33: =HYPERLINK("#"&CELL("address",TI_BF_E!$X$2),"TI_BF_E") -> TI_BF_E | C33: =TI_BF_E!C$2 -> 0 | D33: =TI_BF_E!D$2 -> 0 | E33: =TI_BF_E!E$2 -> 0 | F33: =TI_BF_E!F$2 -> 0 | G33: =TI_BF_E!G$2 -> 0 | H33: =TI_BF_E!H$2 -> 0 | I33: =TI_BF_E!I$2 -> 0 | J33: =TI_BF_E!J$2 -> 0 | ... X33: =TI_BF_E!X$2 -> 0
A34: Gas works | B34: =HYPERLINK("#"&CELL("address",TI_GW_E!$X$2),"TI_GW_E") -> TI_GW_E | C34: =TI_GW_E!C$2 -> 0 | D34: =TI_GW_E!D$2 -> 0 | E34: =TI_GW_E!E$2 -> 0 | F34: =TI_GW_E!F$2 -> 0 | G34: =TI_GW_E!G$2 -> 0 | H34: =TI_GW_E!H$2 -> 0 | I34: =TI_GW_E!I$2 -> 0 | J34: =TI_GW_E!J$2 -> 0 | ... X34: =TI_GW_E!X$2 -> 0
A35: Refineries & petrochemical industry | B35: =HYPERLINK("#"&CELL("address",TI_RPI_E!$X$2),"TI_RPI_E") -> TI_RPI_E | C35: =TI_RPI_E!C$2 -> 167.95641 | D35: =TI_RPI_E!D$2 -> 0 | E35: =TI_RPI_E!E$2 -> 0 | F35: =TI_RPI_E!F$2 -> 0 | G35: =TI_RPI_E!G$2 -> 0 | H35: =TI_RPI_E!H$2 -> 0 | I35: =TI_RPI_E!I$2 -> 0 | J35: =TI_RPI_E!J$2 -> 0 | ... X35: =TI_RPI_E!X$2 -> 0
A36: Refinery intake | B36: =HYPERLINK("#"&CELL("address",TI_RPI_RI_E!$X$2),"TI_RPI_RI_E") -> TI_RPI_RI_E | C36: =TI_RPI_RI_E!C$2 -> 167.95641 | D36: =TI_RPI_RI_E!D$2 -> 0 | E36: =TI_RPI_RI_E!E$2 -> 0 | F36: =TI_RPI_RI_E!F$2 -> 0 | G36: =TI_RPI_RI_E!G$2 -> 0 | H36: =TI_RPI_RI_E!H$2 -> 0 | I36: =TI_RPI_RI_E!I$2 -> 0 | J36: =TI_RPI_RI_E!J$2 -> 0 | ... X36: =TI_RPI_RI_E!X$2 -> 0
A37: Backflows from petrochemical industry | B37: =HYPERLINK("#"&CELL("address",TI_RPI_BPI_E!$X$2),"TI_RPI_BPI_E") -> TI_RPI_BPI_E | C37: =TI_RPI_BPI_E!C$2 -> 0 | D37: =TI_RPI_BPI_E!D$2 -> 0 | E37: =TI_RPI_BPI_E!E$2 -> 0 | F37: =TI_RPI_BPI_E!F$2 -> 0 | G37: =TI_RPI_BPI_E!G$2 -> 0 | H37: =TI_RPI_BPI_E!H$2 -> 0 | I37: =TI_RPI_BPI_E!I$2 -> 0 | J37: =TI_RPI_BPI_E!J$2 -> 0 | ... X37: =TI_RPI_BPI_E!X$2 -> 0
A38: Products transferred | B38: =HYPERLINK("#"&CELL("address",TI_RPI_PT_E!$X$2),"TI_RPI_PT_E") -> TI_RPI_PT_E | C38: =TI_RPI_PT_E!C$2 -> 0 | D38: =TI_RPI_PT_E!D$2 -> 0 | E38: =TI_RPI_PT_E!E$2 -> 0 | F38: =TI_RPI_PT_E!F$2 -> 0 | G38: =TI_RPI_PT_E!G$2 -> 0 | H38: =TI_RPI_PT_E!H$2 -> 0 | I38: =TI_RPI_PT_E!I$2 -> 0 | J38: =TI_RPI_PT_E!J$2 -> 0 | ... X38: =TI_RPI_PT_E!X$2 -> 0
A39: Interproduct transfers | B39: =HYPERLINK("#"&CELL("address",TI_RPI_IT_E!$X$2),"TI_RPI_IT_E") -> TI_RPI_IT_E | C39: =TI_RPI_IT_E!C$2 -> 0 | D39: =TI_RPI_IT_E!D$2 -> 0 | E39: =TI_RPI_IT_E!E$2 -> 0 | F39: =TI_RPI_IT_E!F$2 -> 0 | G39: =TI_RPI_IT_E!G$2 -> 0 | H39: =TI_RPI_IT_E!H$2 -> 0 | I39: =TI_RPI_IT_E!I$2 -> 0 | J39: =TI_RPI_IT_E!J$2 -> 0 | ... X39: =TI_RPI_IT_E!X$2 -> 0
A40: Direct use | B40: =HYPERLINK("#"&CELL("address",TI_RPI_DU_E!$X$2),"TI_RPI_DU_E") -> TI_RPI_DU_E | C40: =TI_RPI_DU_E!C$2 -> 0 | D40: =TI_RPI_DU_E!D$2 -> 0 | E40: =TI_RPI_DU_E!E$2 -> 0 | F40: =TI_RPI_DU_E!F$2 -> 0 | G40: =TI_RPI_DU_E!G$2 -> 0 | H40: =TI_RPI_DU_E!H$2 -> 0 | I40: =TI_RPI_DU_E!I$2 -> 0 | J40: =TI_RPI_DU_E!J$2 -> 0 | ... X40: =TI_RPI_DU_E!X$2 -> 0
...

Sheet PPRD
A1: Primary production | B1: PPRD | C1: 2000 | D1: 2001 | E1: 2002 | F1: 2003 | G1: 2004 | H1: 2005 | I1: 2006 | J1: 2007 | K1: 2008 | L1: 2009 | M1: 2010 | N1: 2011 | O1: 2012 | P1: 2013 | Q1: 2014 | R1: 2015 | S1: 2016 | T1: 2017 | U1: 2018 | V1: 2019 | W1: 2020 | X1: 2021
A2: Total | B2: TOTAL | C2: =SUM(C3,C17,C22,C25,C26,C51,C52,C71,C74,C75,C76) -> 3198.523 | D2: =SUM(D3,D17,D22,D25,D26,D51,D52,D71,D74,D75,D76) -> 3352.0719 | E2: =SUM(E3,E17,E22,E25,E26,E51,E52,E71,E74,E75,E76) -> 3443.6553 | F2: =SUM(F3,F17,F22,F25,F26,F51,F52,F71,F74,F75,F76) -> 3404.5082 | G2: =SUM(G3,G17,G22,G25,G26,G51,G52,G71,G74,G75,G76) -> 3582.0497 | H2: =SUM(H3,H17,H22,H25,H26,H51,H52,H71,H74,H75,H76) -> 3730.6003 | I2: =SUM(I3,I17,I22,I25,I26,I51,I52,I71,I74,I75,I76) -> 3602.9948 | J2: =SUM(J3,J17,J22,J25,J26,J51,J52,J71,J74,J75,J76) -> 3704.6996 | ... X2: =SUM(X3,X17,X22,X25,X26,X51,X52,X71,X74,X75,X76) -> 3281.7735
A3: Solid fossil fuels | B3: C0000X0350-0370 | C3: =SUM(C4,C8,C11) -> 1062.0044 | D3: =SUM(D4,D8,D11) -> 1007.9789 | E3: =SUM(E4,E8,E11) -> 1175.4173 | F3: =SUM(F4,F8,F11) -> 1184.1967 | G3: =SUM(G4,G8,G11) -> 1200.7568 | H3: =SUM(H4,H8,H11) -> 1184.0131 | I3: =SUM(I4,I8,I11) -> 1209.5604 | J3: =SUM(J4,J8,J11) -> 1239.2504 | ... X3: =SUM(X4,X8,X11) -> 716.07799
A4: Hard coal | B4: C0100 | C4: =SUM(C5:C7) -> 0 | D4: =SUM(D5:D7) -> 0 | E4: =SUM(E5:E7) -> 0 | F4: =SUM(F5:F7) -> 0 | G4: =SUM(G5:G7) -> 0 | H4: =SUM(H5:H7) -> 0 | I4: =SUM(I5:I7) -> 0 | J4: =SUM(J5:J7) -> 0 | ... X4: =SUM(X5:X7) -> 0
A5: Anthracite | B5: C0110 | C5: 0 | D5: 0 | E5: 0 | F5: 0 | G5: 0 | H5: 0 | I5: 0 | J5: 0 | K5: 0 | L5: 0 | M5: 0 | N5: 0 | O5: 0 | P5: 0 | Q5: 0 | R5: 0 | S5: 0 | T5: 0 | U5: 0 | V5: 0 | W5: 0 | X5: 0
A6: Coking coal | B6: C0121 | C6: 0 | D6: 0 | E6: 0 | F6: 0 | G6: 0 | H6: 0 | I6: 0 | J6: 0 | K6: 0 | L6: 0 | M6: 0 | N6: 0 | O6: 0 | P6: 0 | Q6: 0 | R6: 0 | S6: 0 | T6: 0 | U6: 0 | V6: 0 | W6: 0 | X6: 0
A7: Other bituminous coal | B7: C0129 | C7: 0 | D7: 0 | E7: 0 | F7: 0 | G7: 0 | H7: 0 | I7: 0 | J7: 0 | K7: 0 | L7: 0 | M7: 0 | N7: 0 | O7: 0 | P7: 0 | Q7: 0 | R7: 0 | S7: 0 | T7: 0 | U7: 0 | V7: 0 | W7: 0 | X7: 0
A8: Brown coal | B8: C0200 | C8: =SUM(C9:C10) -> 1062.0044 | D8: =SUM(D9:D10) -> 1007.9789 | E8: =SUM(E9:E10) -> 1175.4173 | F8: =SUM(F9:F10) -> 1184.1967 | G8: =SUM(G9:G10) -> 1200.7568 | H8: =SUM(H9:H10) -> 1184.0131 | I8: =SUM(I9:I10) -> 1209.5604 | J8: =SUM(J9:J10) -> 1239.2504 | ... X8: =SUM(X9:X10) -> 716.07799
A9: Sub-bituminous coal | B9: C0210 | C9: 0 | D9: 0 | E9: 0 | F9: 0 | G9: 0 | H9: 0 | I9: 0 | J9: 0 | K9: 0 | L9: 0 | M9: 0 | N9: 0 | O9: 0 | P9: 0 | Q9: 0 | R9: 0 | S9: 0 | T9: 0 | U9: 0 | V9: 0 | W9: 0 | X9: 0
A10: Lignite | B10: C0220 | C10: 1062.0044 | D10: 1007.9789 | E10: 1175.4173 | F10: 1184.1967 | G10: 1200.7568 | H10: 1184.0131 | I10: 1209.5604 | J10: 1239.2504 | K10: 1184.8428 | L10: 1159.8251 | M10: 1195.9561 | N10: 1200.5032 | O10: 1093.2053 | P10: 1074.9077 | Q10: 818.05099 | R10: 862.4454 | S10: 941.87627 | T10: 933.41126 | U10: 901.3742 | V10: 891.31883 | W10: 865.37051 | X10: 716.07799
A11: Coal products | B11: C0300 | C11: =SUM(C12:C16) -> 0 | D11: =SUM(D12:D16) -> 0 | E11: =SUM(E12:E16) -> 0 | F11: =SUM(F12:F16) -> 0 | G11: =SUM(G12:G16) -> 0 | H11: =SUM(H12:H16) -> 0 | I11: =SUM(I12:I16) -> 0 | J11: =SUM(J12:J16) -> 0 | ... X11: =SUM(X12:X16) -> 0
A12: Patent fuel | B12: C0320 | C12: 0 | D12: 0 | E12: 0 | F12: 0 | G12: 0 | H12: 0 | I12: 0 | J12: 0 | K12: 0 | L12: 0 | M12: 0 | N12: 0 | O12: 0 | P12: 0 | Q12: 0 | R12: 0 | S12: 0 | T12: 0 | U12: 0 | V12: 0 | W12: 0 | X12: 0
A13: Coke oven coke | B13: C0311 | C13: 0 | D13: 0 | E13: 0 | F13: 0 | G13: 0 | H13: 0 | I13: 0 | J13: 0 | K13: 0 | L13: 0 | M13: 0 | N13: 0 | O13: 0 | P13: 0 | Q13: 0 | R13: 0 | S13: 0 | T13: 0 | U13: 0 | V13: 0 | W13: 0 | X13: 0
A14: Gas coke | B14: C0312 | C14: 0 | D14: 0 | E14: 0 | F14: 0 | G14: 0 | H14: 0 | I14: 0 | J14: 0 | K14: 0 | L14: 0 | M14: 0 | N14: 0 | O14: 0 | P14: 0 | Q14: 0 | R14: 0 | S14: 0 | T14: 0 | U14: 0 | V14: 0 | W14: 0 | X14: 0
A15: Coal tar | B15: C0340 | C15: 0 | D15: 0 | E15: 0 | F15: 0 | G15: 0 | H15: 0 | I15: 0 | J15: 0 | K15: 0 | L15: 0 | M15: 0 | N15: 0 | O15: 0 | P15: 0 | Q15: 0 | R15: 0 | S15: 0 | T15: 0 | U15: 0 | V15: 0 | W15: 0 | X15: 0
A16: Brown coal briquettes | B16: C0330 | C16: 0 | D16: 0 | E16: 0 | F16: 0 | G16: 0 | H16: 0 | I16: 0 | J16: 0 | K16: 0 | L16: 0 | M16: 0 | N16: 0 | O16: 0 | P16: 0 | Q16: 0 | R16: 0 | S16: 0 | T16: 0 | U16: 0 | V16: 0 | W16: 0 | X16: 0
A17: Manufactured gases | B17: C0350-0370 | C17: =SUM(C18:C21) -> 0 | D17: =SUM(D18:D21) -> 0 | E17: =SUM(E18:E21) -> 0 | F17: =SUM(F18:F21) -> 0 | G17: =SUM(G18:G21) -> 0 | H17: =SUM(H18:H21) -> 0 | I17: =SUM(I18:I21) -> 0 | J17: =SUM(J18:J21) -> 0 | ... X17: =SUM(X18:X21) -> 0
A18: Gas works gas | B18: C0360 | C18: 0 | D18: 0 | E18: 0 | F18: 0 | G18: 0 | H18: 0 | I18: 0 | J18: 0 | K18: 0 | L18: 0 | M18: 0 | N18: 0 | O18: 0 | P18: 0 | Q18: 0 | R18: 0 | S18: 0 | T18: 0 | U18: 0 | V18: 0 | W18: 0 | X18: 0
A19: Coke oven gas | B19: C0350 | C19: 0 | D19: 0 | E19: 0 | F19: 0 | G19: 0 | H19: 0 | I19: 0 | J19: 0 | K19: 0 | L19: 0 | M19: 0 | N19: 0 | O19: 0 | P19: 0 | Q19: 0 | R19: 0 | S19: 0 | T19: 0 | U19: 0 | V19: 0 | W19: 0 | X19: 0
A20: Blast furnace gas | B20: C0371 | C20: 0 | D20: 0 | E20: 0 | F20: 0 | G20: 0 | H20: 0 | I20: 0 | J20: 0 | K20: 0 | L20: 0 | M20: 0 | N20: 0 | O20: 0 | P20: 0 | Q20: 0 | R20: 0 | S20: 0 | T20: 0 | U20: 0 | V20: 0 | W20: 0 | X20: 0
A21: Other recovered gases | B21: C0379 | C21: 0 | D21: 0 | E21: 0 | F21: 0 | G21: 0 | H21: 0 | I21: 0 | J21: 0 | K21: 0 | L21: 0 | M21: 0 | N21: 0 | O21: 0 | P21: 0 | Q21: 0 | R21: 0 | S21: 0 | T21: 0 | U21: 0 | V21: 0 | W21: 0 | X21: 0
A22: Peat and peat products | B22: P1000 | C22: =SUM(C23:C24) -> 0 | D22: =SUM(D23:D24) -> 0 | E22: =SUM(E23:E24) -> 0 | F22: =SUM(F23:F24) -> 0 | G22: =SUM(G23:G24) -> 0 | H22: =SUM(H23:H24) -> 0 | I22: =SUM(I23:I24) -> 0 | J22: =SUM(J23:J24) -> 0 | ... X22: =SUM(X23:X24) -> 0
A23: Peat | B23: P1100 | C23: 0 | D23: 0 | E23: 0 | F23: 0 | G23: 0 | H23: 0 | I23: 0 | J23: 0 | K23: 0 | L23: 0 | M23: 0 | N23: 0 | O23: 0 | P23: 0 | Q23: 0 | R23: 0 | S23: 0 | T23: 0 | U23: 0 | V23: 0 | W23: 0 | X23: 0
A24: Peat products | B24: P1200 | C24: 0 | D24: 0 | E24: 0 | F24: 0 | G24: 0 | H24: 0 | I24: 0 | J24: 0 | K24: 0 | L24: 0 | M24: 0 | N24: 0 | O24: 0 | P24: 0 | Q24: 0 | R24: 0 | S24: 0 | T24: 0 | U24: 0 | V24: 0 | W24: 0 | X24: 0
A25: Oil shale and oil sands | B25: S2000 | C25: 0 | D25: 0 | E25: 0 | F25: 0 | G25: 0 | H25: 0 | I25: 0 | J25: 0 | K25: 0 | L25: 0 | M25: 0 | N25: 0 | O25: 0 | P25: 0 | Q25: 0 | R25: 0 | S25: 0 | T25: 0 | U25: 0 | V25: 0 | W25: 0 | X25: 0
A26: Oil and petroleum products | B26: O4000XBIO | C26: =SUM(C27,C33) -> 0.99363715 | D26: =SUM(D27,D33) -> 0 | E26: =SUM(E27,E33) -> 0.99363715 | F26: =SUM(F27,F33) -> 0 | G26: =SUM(G27,G33) -> 0 | H26: =SUM(H27,H33) -> 0 | I26: =SUM(I27,I33) -> 0 | J26: =SUM(J27,J33) -> 0 | ... X26: =SUM(X27,X33) -> 0.31401548
A27: Crude oil, NGL, refinery feedstocks, additives and oxygenates and other hydrocarbons (excluding biofuel portion) | B27: O4100_TOT_4200-4500XBIO | C27: =SUM(C28:C32) -> 0.99363715 | D27: =SUM(D28:D32) -> 0 | E27: =SUM(E28:E32) -> 0.99363715 | F27: =SUM(F28:F32) -> 0 | G27: =SUM(G28:G32) -> 0 | H27: =SUM(H28:H32) -> 0 | I27: =SUM(I28:I32) -> 0 | J27: =SUM(J28:J32) -> 0 | ... X27: =SUM(X28:X32) -> 0.31401548
A28: Crude oil | B28: O4100_TOT | C28: 0.99363715 | D28: 0 | E28: 0.99363715 | F28: 0 | G28: 0 | H28: 0 | I28: 0 | J28: 0 | K28: 0 | L28: 0 | M28: 0 | N28: 0 | O28: 0 | P28: 0 | Q28: 0 | R28: 0 | S28: 0 | T28: 0.24978504 | U28: 0.27626827 | V28: 0.27119518 | W28: 0.25288048 | X28: 0.14677558
A29: Natural gas liquids | B29: O4200 | C29: 0 | D29: 0 | E29: 0 | F29: 0 | G29: 0 | H29: 0 | I29: 0 | J29: 0 | K29: 0 | L29: 0 | M29: 0 | N29: 0 | O29: 0 | P29: 0 | Q29: 0 | R29: 0 | S29: 0 | T29: 0.28228719 | U29: 0.60283749 | V29: 0.25898538 | W29: 0.16027515 | X29: 0.1672399
A30: Refinery feedstocks | B30: O4300 | C30: 0 | D30: 0 | E30: 0 | F30: 0 | G30: 0 | H30: 0 | I30: 0 | J30: 0 | K30: 0 | L30: 0 | M30: 0 | N30: 0 | O30: 0 | P30: 0 | Q30: 0 | R30: 0 | S30: 0 | T30: 0 | U30: 0 | V30: 0 | W30: 0 | X30: 0
A31: Additives and oxygenates (excluding biofuel portion) | B31: O4400X4410 | C31: 0 | D31: 0 | E31: 0 | F31: 0 | G31: 0 | H31: 0 | I31: 0 | J31: 0 | K31: 0 | L31: 0 | M31: 0 | N31: 0 | O31: 0 | P31: 0 | Q31: 0 | R31: 0 | S31: 0 | T31: 0 | U31: 0 | V31: 0 | W31: 0 | X31: 0
A32: Other hydrocarbons | B32: O4500 | C32: 0 | D32: 0 | E32: 0 | F32: 0 | G32: 0 | H32: 0 | I32: 0 | J32: 0 | K32: 0 | L32: 0 | M32: 0 | N32: 0 | O32: 0 | P32: 0 | Q32: 0 | R32: 0 | S32: 0 | T32: 0 | U32: 0 | V32: 0 | W32: 0 | X32: 0
A33: Oil products (excluding biofuel portion) | B33: O4600XBIO | C33: =SUM(C34:C50) -> 0 | D33: =SUM(D34:D50) -> 0 | E33: =SUM(E34:E50) -> 0 | F33: =SUM(F34:F50) -> 0 | G33: =SUM(G34:G50) -> 0 | H33: =SUM(H34:H50) -> 0 | I33: =SUM(I34:I50) -> 0 | J33: =SUM(J34:J50) -> 0 | ... X33: =SUM(X34:X50) -> 0
A34: Refinery gas | B34: O4610 | C34: 0 | D34: 0 | E34: 0 | F34: 0 | G34: 0 | H34: 0 | I34: 0 | J34: 0 | K34: 0 | L34: 0 | M34: 0 | N34: 0 | O34: 0 | P34: 0 | Q34: 0 | R34: 0 | S34: 0 | T34: 0 | U34: 0 | V34: 0 | W34: 0 | X34: 0
A35: Ethane | B35: O4620 | C35: 0 | D35: 0 | E35: 0 | F35: 0 | G35: 0 | H35: 0 | I35: 0 | J35: 0 | K35: 0 | L35: 0 | M35: 0 | N35: 0 | O35: 0 | P35: 0 | Q35: 0 | R35: 0 | S35: 0 | T35: 0 | U35: 0 | V35: 0 | W35: 0 | X35: 0
A36: Liquefied petroleum gases | B36: O4630 | C36: 0 | D36: 0 | E36: 0 | F36: 0 | G36: 0 | H36: 0 | I36: 0 | J36: 0 | K36: 0 | L36: 0 | M36: 0 | N36: 0 | O36: 0 | P36: 0 | Q36: 0 | R36: 0 | S36: 0 | T36: 0 | U36: 0 | V36: 0 | W36: 0 | X36: 0
A37: Motor gasoline (excluding biofuel portion) | B37: O4652XR5210B | C37: 0 | D37: 0 | E37: 0 | F37: 0 | G37: 0 | H37: 0 | I37: 0 | J37: 0 | K37: 0 | L37: 0 | M37: 0 | N37: 0 | O37: 0 | P37: 0 | Q37: 0 | R37: 0 | S37: 0 | T37: 0 | U37: 0 | V37: 0 | W37: 0 | X37: 0
A38: Aviation gasoline | B38: O4651 | C38: 0 | D38: 0 | E38: 0 | F38: 0 | G38: 0 | H38: 0 | I38: 0 | J38: 0 | K38: 0 | L38: 0 | M38: 0 | N38: 0 | O38: 0 | P38: 0 | Q38: 0 | R38: 0 | S38: 0 | T38: 0 | U38: 0 | V38: 0 | W38: 0 | X38: 0
A39: Gasoline-type jet fuel | B39: O4653 | C39: 0 | D39: 0 | E39: 0 | F39: 0 | G39: 0 | H39: 0 | I39: 0 | J39: 0 | K39: 0 | L39: 0 | M39: 0 | N39: 0 | O39: 0 | P39: 0 | Q39: 0 | R39: 0 | S39: 0 | T39: 0 | U39: 0 | V39: 0 | W39: 0 | X39: 0
A40: Kerosene-type jet fuel (excluding biofuel portion) | B40: O4661XR5230B | C40: 0 | D40: 0 | E40: 0 | F40: 0 | G40: 0 | H40: 0 | I40: 0 | J40: 0 | K40: 0 | L40: 0 | M40: 0 | N40: 0 | O40: 0 | P40: 0 | Q40: 0 | R40: 0 | S40: 0 | T40: 0 | U40: 0 | V40: 0 | W40: 0 | X40: 0
...

Sheet RCV_RCY
A1: Recovered & recycled products | B1: RCV_RCY | C1: 2000 | D1: 2001 | E1: 2002 | F1: 2003 | G1: 2004 | H1: 2005 | I1: 2006 | J1: 2007 | K1: 2008 | L1: 2009 | M1: 2010 | N1: 2011 | O1: 2012 | P1: 2013 | Q1: 2014 | R1: 2015 | S1: 2016 | T1: 2017 | U1: 2018 | V1: 2019 | W1: 2020 | X1: 2021
A2: Total | B2: TOTAL | C2: =SUM(C3,C17,C22,C25,C26,C51,C52,C71,C74,C75,C76) -> 0 | D2: =SUM(D3,D17,D22,D25,D26,D51,D52,D71,D74,D75,D76) -> 0 | E2: =SUM(E3,E17,E22,E25,E26,E51,E52,E71,E74,E75,E76) -> 0 | F2: =SUM(F3,F17,F22,F25,F26,F51,F52,F71,F74,F75,F76) -> 0 | G2: =SUM(G3,G17,G22,G25,G26,G51,G52,G71,G74,G75,G76) -> 0 | H2: =SUM(H3,H17,H22,H25,H26,H51,H52,H71,H74,H75,H76) -> 0 | I2: =SUM(I3,I17,I22,I25,I26,I51,I52,I71,I74,I75,I76) -> 0 | J2: =SUM(J3,J17,J22,J25,J26,J51,J52,J71,J74,J75,J76) -> 0 | ... X2: =SUM(X3,X17,X22,X25,X26,X51,X52,X71,X74,X75,X76) -> 0
A3: Solid fossil fuels | B3: C0000X0350-0370 | C3: =SUM(C4,C8,C11) -> 0 | D3: =SUM(D4,D8,D11) -> 0 | E3: =SUM(E4,E8,E11) -> 0 | F3: =SUM(F4,F8,F11) -> 0 | G3: =SUM(G4,G8,G11) -> 0 | H3: =SUM(H4,H8,H11) -> 0 | I3: =SUM(I4,I8,I11) -> 0 | J3: =SUM(J4,J8,J11) -> 0 | ... X3: =SUM(X4,X8,X11) -> 0
A4: Hard coal | B4: C0100 | C4: =SUM(C5:C7) -> 0 | D4: =SUM(D5:D7) -> 0 | E4: =SUM(E5:E7) -> 0 | F4: =SUM(F5:F7) -> 0 | G4: =SUM(G5:G7) -> 0 | H4: =SUM(H5:H7) -> 0 | I4: =SUM(I5:I7) -> 0 | J4: =SUM(J5:J7) -> 0 | ... X4: =SUM(X5:X7) -> 0
A5: Anthracite | B5: C0110 | C5: 0 | D5: 0 | E5: 0 | F5: 0 | G5: 0 | H5: 0 | I5: 0 | J5: 0 | K5: 0 | L5: 0 | M5: 0 | N5: 0 | O5: 0 | P5: 0 | Q5: 0 | R5: 0 | S5: 0 | T5: 0 | U5: 0 | V5: 0 | W5: 0 | X5: 0
A6: Coking coal | B6: C0121 | C6: 0 | D6: 0 | E6: 0 | F6: 0 | G6: 0 | H6: 0 | I6: 0 | J6: 0 | K6: 0 | L6: 0 | M6: 0 | N6: 0 | O6: 0 | P6: 0 | Q6: 0 | R6: 0 | S6: 0 | T6: 0 | U6: 0 | V6: 0 | W6: 0 | X6: 0
A7: Other bituminous coal | B7: C0129 | C7: 0 | D7: 0 | E7: 0 | F7: 0 | G7: 0 | H7: 0 | I7: 0 | J7: 0 | K7: 0 | L7: 0 | M7: 0 | N7: 0 | O7: 0 | P7: 0 | Q7: 0 | R7: 0 | S7: 0 | T7: 0 | U7: 0 | V7: 0 | W7: 0 | X7: 0
A8: Brown coal | B8: C0200 | C8: =SUM(C9:C10) -> 0 | D8: =SUM(D9:D10) -> 0 | E8: =SUM(E9:E10) -> 0 | F8: =SUM(F9:F10) -> 0 | G8: =SUM(G9:G10) -> 0 | H8: =SUM(H9:H10) -> 0 | I8: =SUM(I9:I10) -> 0 | J8: =SUM(J9:J10) -> 0 | ... X8: =SUM(X9:X10) -> 0
A9: Sub-bituminous coal | B9: C0210 | C9: 0 | D9: 0 | E9: 0 | F9: 0 | G9: 0 | H9: 0 | I9: 0 | J9: 0 | K9: 0 | L9: 0 | M9: 0 | N9: 0 | O9: 0 | P9: 0 | Q9: 0 | R9: 0 | S9: 0 | T9: 0 | U9: 0 | V9: 0 | W9: 0 | X9: 0
A10: Lignite | B10: C0220 | C10: 0 | D10: 0 | E10: 0 | F10: 0 | G10: 0 | H10: 0 | I10: 0 | J10: 0 | K10: 0 | L10: 0 | M10: 0 | N10: 0 | O10: 0 | P10: 0 | Q10: 0 | R10: 0 | S10: 0 | T10: 0 | U10: 0 | V10: 0 | W10: 0 | X10: 0
A11: Coal products | B11: C0300 | C11: =SUM(C12:C16) -> 0 | D11: =SUM(D12:D16) -> 0 | E11: =SUM(E12:E16) -> 0 | F11: =SUM(F12:F16) -> 0 | G11: =SUM(G12:G16) -> 0 | H11: =SUM(H12:H16) -> 0 | I11: =SUM(I12:I16) -> 0 | J11: =SUM(J12:J16) -> 0 | ... X11: =SUM(X12:X16) -> 0
A12: Patent fuel | B12: C0320 | C12: 0 | D12: 0 | E12: 0 | F12: 0 | G12: 0 | H12: 0 | I12: 0 | J12: 0 | K12: 0 | L12: 0 | M12: 0 | N12: 0 | O12: 0 | P12: 0 | Q12: 0 | R12: 0 | S12: 0 | T12: 0 | U12: 0 | V12: 0 | W12: 0 | X12: 0
A13: Coke oven coke | B13: C0311 | C13: 0 | D13: 0 | E13: 0 | F13: 0 | G13: 0 | H13: 0 | I13: 0 | J13: 0 | K13: 0 | L13: 0 | M13: 0 | N13: 0 | O13: 0 | P13: 0 | Q13: 0 | R13: 0 | S13: 0 | T13: 0 | U13: 0 | V13: 0 | W13: 0 | X13: 0
A14: Gas coke | B14: C0312 | C14: 0 | D14: 0 | E14: 0 | F14: 0 | G14: 0 | H14: 0 | I14: 0 | J14: 0 | K14: 0 | L14: 0 | M14: 0 | N14: 0 | O14: 0 | P14: 0 | Q14: 0 | R14: 0 | S14: 0 | T14: 0 | U14: 0 | V14: 0 | W14: 0 | X14: 0
A15: Coal tar | B15: C0340 | C15: 0 | D15: 0 | E15: 0 | F15: 0 | G15: 0 | H15: 0 | I15: 0 | J15: 0 | K15: 0 | L15: 0 | M15: 0 | N15: 0 | O15: 0 | P15: 0 | Q15: 0 | R15: 0 | S15: 0 | T15: 0 | U15: 0 | V15: 0 | W15: 0 | X15: 0
A16: Brown coal briquettes | B16: C0330 | C16: 0 | D16: 0 | E16: 0 | F16: 0 | G16: 0 | H16: 0 | I16: 0 | J16: 0 | K16: 0 | L16: 0 | M16: 0 | N16: 0 | O16: 0 | P16: 0 | Q16: 0 | R16: 0 | S16: 0 | T16: 0 | U16: 0 | V16: 0 | W16: 0 | X16: 0
A17: Manufactured gases | B17: C0350-0370 | C17: =SUM(C18:C21) -> 0 | D17: =SUM(D18:D21) -> 0 | E17: =SUM(E18:E21) -> 0 | F17: =SUM(F18:F21) -> 0 | G17: =SUM(G18:G21) -> 0 | H17: =SUM(H18:H21) -> 0 | I17: =SUM(I18:I21) -> 0 | J17: =SUM(J18:J21) -> 0 | ... X17: =SUM(X18:X21) -> 0
A18: Gas works gas | B18: C0360 | C18: 0 | D18: 0 | E18: 0 | F18: 0 | G18: 0 | H18: 0 | I18: 0 | J18: 0 | K18: 0 | L18: 0 | M18: 0 | N18: 0 | O18: 0 | P18: 0 | Q18: 0 | R18: 0 | S18: 0 | T18: 0 | U18: 0 | V18: 0 | W18: 0 | X18: 0
A19: Coke oven gas | B19: C0350 | C19: 0 | D19: 0 | E19: 0 | F19: 0 | G19: 0 | H19: 0 | I19: 0 | J19: 0 | K19: 0 | L19: 0 | M19: 0 | N19: 0 | O19: 0 | P19: 0 | Q19: 0 | R19: 0 | S19: 0 | T19: 0 | U19: 0 | V19: 0 | W19: 0 | X19: 0
A20: Blast furnace gas | B20: C0371 | C20: 0 | D20: 0 | E20: 0 | F20: 0 | G20: 0 | H20: 0 | I20: 0 | J20: 0 | K20: 0 | L20: 0 | M20: 0 | N20: 0 | O20: 0 | P20: 0 | Q20: 0 | R20: 0 | S20: 0 | T20: 0 | U20: 0 | V20: 0 | W20: 0 | X20: 0
A21: Other recovered gases | B21: C0379 | C21: 0 | D21: 0 | E21: 0 | F21: 0 | G21: 0 | H21: 0 | I21: 0 | J21: 0 | K21: 0 | L21: 0 | M21: 0 | N21: 0 | O21: 0 | P21: 0 | Q21: 0 | R21: 0 | S21: 0 | T21: 0 | U21: 0 | V21: 0 | W21: 0 | X21: 0
A22: Peat and peat products | B22: P1000 | C22: =SUM(C23:C24) -> 0 | D22: =SUM(D23:D24) -> 0 | E22: =SUM(E23:E24) -> 0 | F22: =SUM(F23:F24) -> 0 | G22: =SUM(G23:G24) -> 0 | H22: =SUM(H23:H24) -> 0 | I22: =SUM(I23:I24) -> 0 | J22: =SUM(J23:J24) -> 0 | ... X22: =SUM(X23:X24) -> 0
A23: Peat | B23: P1100 | C23: 0 | D23: 0 | E23: 0 | F23: 0 | G23: 0 | H23: 0 | I23: 0 | J23: 0 | K23: 0 | L23: 0 | M23: 0 | N23: 0 | O23: 0 | P23: 0 | Q23: 0 | R23: 0 | S23: 0 | T23: 0 | U23: 0 | V23: 0 | W23: 0 | X23: 0
A24: Peat products | B24: P1200 | C24: 0 | D24: 0 | E24: 0 | F24: 0 | G24: 0 | H24: 0 | I24: 0 | J24: 0 | K24: 0 | L24: 0 | M24: 0 | N24: 0 | O24: 0 | P24: 0 | Q24: 0 | R24: 0 | S24: 0 | T24: 0 | U24: 0 | V24: 0 | W24: 0 | X24: 0
A25: Oil shale and oil sands | B25: S2000 | C25: 0 | D25: 0 | E25: 0 | F25: 0 | G25: 0 | H25: 0 | I25: 0 | J25: 0 | K25: 0 | L25: 0 | M25: 0 | N25: 0 | O25: 0 | P25: 0 | Q25: 0 | R25: 0 | S25: 0 | T25: 0 | U25: 0 | V25: 0 | W25: 0 | X25: 0
A26: Oil and petroleum products | B26: O4000XBIO | C26: =SUM(C27,C33) -> 0 | D26: =SUM(D27,D33) -> 0 | E26: =SUM(E27,E33) -> 0 | F26: =SUM(F27,F33) -> 0 | G26: =SUM(G27,G33) -> 0 | H26: =SUM(H27,H33) -> 0 | I26: =SUM(I27,I33) -> 0 | J26: =SUM(J27,J33) -> 0 | ... X26: =SUM(X27,X33) -> 0
A27: Crude oil, NGL, refinery feedstocks, additives and oxygenates and other hydrocarbons (excluding biofuel portion) | B27: O4100_TOT_4200-4500XBIO | C27: =SUM(C28:C32) -> 0 | D27: =SUM(D28:D32) -> 0 | E27: =SUM(E28:E32) -> 0 | F27: =SUM(F28:F32) -> 0 | G27: =SUM(G28:G32) -> 0 | H27: =SUM(H28:H32) -> 0 | I27: =SUM(I28:I32) -> 0 | J27: =SUM(J28:J32) -> 0 | ... X27: =SUM(X28:X32) -> 0
A28: Crude oil | B28: O4100_TOT | C28: 0 | D28: 0 | E28: 0 | F28: 0 | G28: 0 | H28: 0 | I28: 0 | J28: 0 | K28: 0 | L28: 0 | M28: 0 | N28: 0 | O28: 0 | P28: 0 | Q28: 0 | R28: 0 | S28: 0 | T28: 0 | U28: 0 | V28: 0 | W28: 0 | X28: 0
A29: Natural gas liquids | B29: O4200 | C29: 0 | D29: 0 | E29: 0 | F29: 0 | G29: 0 | H29: 0 | I29: 0 | J29: 0 | K29: 0 | L29: 0 | M29: 0 | N29: 0 | O29: 0 | P29: 0 | Q29: 0 | R29: 0 | S29: 0 | T29: 0 | U29: 0 | V29: 0 | W29: 0 | X29: 0
A30: Refinery feedstocks | B30: O4300 | C30: 0 | D30: 0 | E30: 0 | F30: 0 | G30: 0 | H30: 0 | I30: 0 | J30: 0 | K30: 0 | L30: 0 | M30: 0 | N30: 0 | O30: 0 | P30: 0 | Q30: 0 | R30: 0 | S30: 0 | T30: 0 | U30: 0 | V30: 0 | W30: 0 | X30: 0
A31: Additives and oxygenates (excluding biofuel portion) | B31: O4400X4410 | C31: 0 | D31: 0 | E31: 0 | F31: 0 | G31: 0 | H31: 0 | I31: 0 | J31: 0 | K31: 0 | L31: 0 | M31: 0 | N31: 0 | O31: 0 | P31: 0 | Q31: 0 | R31: 0 | S31: 0 | T31: 0 | U31: 0 | V31: 0 | W31: 0 | X31: 0
A32: Other hydrocarbons | B32: O4500 | C32: 0 | D32: 0 | E32: 0 | F32: 0 | G32: 0 | H32: 0 | I32: 0 | J32: 0 | K32: 0 | L32: 0 | M32: 0 | N32: 0 | O32: 0 | P32: 0 | Q32: 0 | R32: 0 | S32: 0 | T32: 0 | U32: 0 | V32: 0 | W32: 0 | X32: 0
A33: Oil products (excluding biofuel portion) | B33: O4600XBIO | C33: =SUM(C34:C50) -> 0 | D33: =SUM(D34:D50) -> 0 | E33: =SUM(E34:E50) -> 0 | F33: =SUM(F34:F50) -> 0 | G33: =SUM(G34:G50) -> 0 | H33: =SUM(H34:H50) -> 0 | I33: =SUM(I34:I50) -> 0 | J33: =SUM(J34:J50) -> 0 | ... X33: =SUM(X34:X50) -> 0
A34: Refinery gas | B34: O4610 | C34: 0 | D34: 0 | E34: 0 | F34: 0 | G34: 0 | H34: 0 | I34: 0 | J34: 0 | K34: 0 | L34: 0 | M34: 0 | N34: 0 | O34: 0 | P34: 0 | Q34: 0 | R34: 0 | S34: 0 | T34: 0 | U34: 0 | V34: 0 | W34: 0 | X34: 0
A35: Ethane | B35: O4620 | C35: 0 | D35: 0 | E35: 0 | F35: 0 | G35: 0 | H35: 0 | I35: 0 | J35: 0 | K35: 0 | L35: 0 | M35: 0 | N35: 0 | O35: 0 | P35: 0 | Q35: 0 | R35: 0 | S35: 0 | T35: 0 | U35: 0 | V35: 0 | W35: 0 | X35: 0
A36: Liquefied petroleum gases | B36: O4630 | C36: 0 | D36: 0 | E36: 0 | F36: 0 | G36: 0 | H36: 0 | I36: 0 | J36: 0 | K36: 0 | L36: 0 | M36: 0 | N36: 0 | O36: 0 | P36: 0 | Q36: 0 | R36: 0 | S36: 0 | T36: 0 | U36: 0 | V36: 0 | W36: 0 | X36: 0
A37: Motor gasoline (excluding biofuel portion) | B37: O4652XR5210B | C37: 0 | D37: 0 | E37: 0 | F37: 0 | G37: 0 | H37: 0 | I37: 0 | J37: 0 | K37: 0 | L37: 0 | M37: 0 | N37: 0 | O37: 0 | P37: 0 | Q37: 0 | R37: 0 | S37: 0 | T37: 0 | U37: 0 | V37: 0 | W37: 0 | X37: 0
A38: Aviation gasoline | B38: O4651 | C38: 0 | D38: 0 | E38: 0 | F38: 0 | G38: 0 | H38: 0 | I38: 0 | J38: 0 | K38: 0 | L38: 0 | M38: 0 | N38: 0 | O38: 0 | P38: 0 | Q38: 0 | R38: 0 | S38: 0 | T38: 0 | U38: 0 | V38: 0 | W38: 0 | X38: 0
A39: Gasoline-type jet fuel | B39: O4653 | C39: 0 | D39: 0 | E39: 0 | F39: 0 | G39: 0 | H39: 0 | I39: 0 | J39: 0 | K39: 0 | L39: 0 | M39: 0 | N39: 0 | O39: 0 | P39: 0 | Q39: 0 | R39: 0 | S39: 0 | T39: 0 | U39: 0 | V39: 0 | W39: 0 | X39: 0
A40: Kerosene-type jet fuel (excluding biofuel portion) | B40: O4661XR5230B | C40: 0 | D40: 0 | E40: 0 | F40: 0 | G40: 0 | H40: 0 | I40: 0 | J40: 0 | K40: 0 | L40: 0 | M40: 0 | N40: 0 | O40: 0 | P40: 0 | Q40: 0 | R40: 0 | S40: 0 | T40: 0 | U40: 0 | V40: 0 | W40: 0 | X40: 0
...

Sheet IMP
A1: Imports | B1: IMP | C1: 2000 | D1: 2001 | E1: 2002 | F1: 2003 | G1: 2004 | H1: 2005 | I1: 2006 | J1: 2007 | K1: 2008 | L1: 2009 | M1: 2010 | N1: 2011 | O1: 2012 | P1: 2013 | Q1: 2014 | R1: 2015 | S1: 2016 | T1: 2017 | U1: 2018 | V1: 2019 | W1: 2020 | X1: 2021
A2: Total | B2: TOTAL | C2: =SUM(C3,C17,C22,C25,C26,C51,C52,C71,C74,C75,C76) -> 4117.7063 | D2: =SUM(D3,D17,D22,D25,D26,D51,D52,D71,D74,D75,D76) -> 3999.8991 | E2: =SUM(E3,E17,E22,E25,E26,E51,E52,E71,E74,E75,E76) -> 4020.9839 | F2: =SUM(F3,F17,F22,F25,F26,F51,F52,F71,F74,F75,F76) -> 4324.0187 | G2: =SUM(G3,G17,G22,G25,G26,G51,G52,G71,G74,G75,G76) -> 4599.2665 | H2: =SUM(H3,H17,H22,H25,H26,H51,H52,H71,H74,H75,H76) -> 4914.8116 | I2: =SUM(I3,I17,I22,I25,I26,I51,I52,I71,I74,I75,I76) -> 4929.7571 | J2: =SUM(J3,J17,J22,J25,J26,J51,J52,J71,J74,J75,J76) -> 4831.7623 | ... X2: =SUM(X3,X17,X22,X25,X26,X51,X52,X71,X74,X75,X76) -> 5593.7935
A3: Solid fossil fuels | B3: C0000X0350-0370 | C3: =SUM(C4,C8,C11) -> 245.41711 | D3: =SUM(D4,D8,D11) -> 265.29768 | E3: =SUM(E4,E8,E11) -> 307.50353 | F3: =SUM(F4,F8,F11) -> 309.43233 | G3: =SUM(G4,G8,G11) -> 360.41333 | H3: =SUM(H4,H8,H11) -> 332.81582 | I3: =SUM(I4,I8,I11) -> 330.45752 | J3: =SUM(J4,J8,J11) -> 331.38813 | ... X3: =SUM(X4,X8,X11) -> 102.63637
A4: Hard coal | B4: C0100 | C4: =SUM(C5:C7) -> 8.027945 | D4: =SUM(D5:D7) -> 9.8461737 | E4: =SUM(E5:E7) -> 22.614445 | F4: =SUM(F5:F7) -> 34.716681 | G4: =SUM(G5:G7) -> 29.61092 | H4: =SUM(H5:H7) -> 28.671109 | I4: =SUM(I5:I7) -> 29.296991 | J4: =SUM(J5:J7) -> 46.095959 | ... X4: =SUM(X5:X7) -> 4.0703353
A5: Anthracite | B5: C0110 | C5: 0 | D5: 0 | E5: 0 | F5: 0 | G5: 0 | H5: 0 | I5: 0 | J5: 0 | K5: 0 | L5: 0 | M5: 0 | N5: 0 | O5: 0 | P5: 0 | Q5: 0 | R5: 0 | S5: 0 | T5: 0 | U5: 0 | V5: 0 | W5: 0 | X5: 0
A6: Coking coal | B6: C0121 | C6: 0 | D6: 0 | E6: 0 | F6: 0 | G6: 0 | H6: 0 | I6: 0 | J6: 0 | K6: 0 | L6: 0 | M6: 0 | N6: 0 | O6: 0 | P6: 0 | Q6: 0 | R6: 0 | S6: 0 | T6: 0 | U6: 0 | V6: 0 | W6: 0 | X6: 0
A7: Other bituminous coal | B7: C0129 | C7: 8.027945 | D7: 9.8461737 | E7: 22.614445 | F7: 34.716681 | G7: 29.61092 | H7: 28.671109 | I7: 29.296991 | J7: 46.095959 | K7: 45.489424 | L7: 18.834652 | M7: 16.309114 | N7: 14.526225 | O7: 14.5681 | P7: 14.379106 | Q7: 13.244798 | R7: 9.6861565 | S7: 8.4629407 | T7: 7.1600172 | U7: 6.6198624 | V7: 6.8185727 | W7: 8.1463457 | X7: 4.0703353
A8: Brown coal | B8: C0200 | C8: =SUM(C9:C10) -> 186.9644 | D8: =SUM(D9:D10) -> 213.43087 | E8: =SUM(E9:E10) -> 243.77145 | F8: =SUM(F9:F10) -> 234.54557 | G8: =SUM(G9:G10) -> 288.48512 | H8: =SUM(H9:H10) -> 266.10112 | I8: =SUM(I9:I10) -> 266.52537 | J8: =SUM(J9:J10) -> 250.7693 | ... X8: =SUM(X9:X10) -> 76.584953
A9: Sub-bituminous coal | B9: C0210 | C9: 186.9644 | D9: 213.43087 | E9: 243.77145 | F9: 234.30043 | G9: 288.23844 | H9: 266.10112 | I9: 266.52537 | J9: 226.33749 | K9: 317.22966 | L9: 178.35512 | M9: 215.81445 | N9: 193.04592 | O9: 225.79966 | P9: 181.46457 | Q9: 177.65546 | R9: 165.01109 | S9: 167.06638 | T9: 168.93792 | U9: 185.37094 | V9: 185.55193 | W9: 153.17085 | X9: 76.584953
A10: Lignite | B10: C0220 | C10: 0 | D10: 0 | E10: 0 | F10: 0.24514187 | G10: 0.2466896 | H10: 0 | I10: 0 | J10: 24.431814 | K10: 55.4092 | L10: 43.227085 | M10: 27.348495 | N10: 28.580997 | O10: 39.120292 | P10: 49.999484 | Q10: 12.805933 | R10: 7.0829751 | S10: 2.4504729 | T10: 0 | U10: 0 | V10: 0 | W10: 0 | X10: 0
A11: Coal products | B11: C0300 | C11: =SUM(C12:C16) -> 50.424764 | D11: =SUM(D12:D16) -> 42.020636 | E11: =SUM(E12:E16) -> 41.117627 | F11: =SUM(F12:F16) -> 40.170077 | G11: =SUM(G12:G16) -> 42.317283 | H11: =SUM(H12:H16) -> 38.043594 | I11: =SUM(I12:I16) -> 34.635168 | J11: =SUM(J12:J16) -> 34.522872 | ... X11: =SUM(X12:X16) -> 21.981083
A12: Patent fuel | B12: C0320 | C12: 0 | D12: 0 | E12: 0 | F12: 0 | G12: 0 | H12: 0 | I12: 0 | J12: 0 | K12: 0 | L12: 0 | M12: 0 | N12: 0 | O12: 0 | P12: 0 | Q12: 0 | R12: 0 | S12: 0 | T12: 0 | U12: 0 | V12: 0 | W12: 0 | X12: 0
A13: Coke oven coke | B13: C0311 | C13: 50.424764 | D13: 42.020636 | E13: 41.117627 | F13: 40.170077 | G13: 42.317283 | H13: 38.043594 | I13: 34.635168 | J13: 34.522872 | K13: 23.9546 | L13: 17.613672 | M13: 20.4319 | N13: 21.841015 | O13: 21.238865 | P13: 22.166036 | Q13: 23.027773 | R13: 22.270421 | S13: 20.053052 | T13: 21.845916 | U13: 21.573431 | V13: 21.748409 | W13: 19.709458 | X13: 21.981083
A14: Gas coke | B14: C0312 | C14: 0 | D14: 0 | E14: 0 | F14: 0 | G14: 0 | H14: 0 | I14: 0 | J14: 0 | K14: 0 | L14: 0 | M14: 0 | N14: 0 | O14: 0 | P14: 0 | Q14: 0 | R14: 0 | S14: 0 | T14: 0 | U14: 0 | V14: 0 | W14: 0 | X14: 0
A15: Coal tar | B15: C0340 | C15: 0 | D15: 0 | E15: 0 | F15: 0 | G15: 0 | H15: 0 | I15: 0 | J15: 0 | K15: 0 | L15: 0 | M15: 0 | N15: 0 | O15: 0 | P15: 0 | Q15: 0 | R15: 0 | S15: 0 | T15: 0 | U15: 0 | V15: 0 | W15: 0 | X15: 0
A16: Brown coal briquettes | B16: C0330 | C16: 0 | D16: 0 | E16: 0 | F16: 0 | G16: 0 | H16: 0 | I16: 0 | J16: 0 | K16: 0 | L16: 0 | M16: 0 | N16: 0 | O16: 0 | P16: 0 | Q16: 0 | R16: 0 | S16: 0 | T16: 0 | U16: 0 | V16: 0 | W16: 0 | X16: 0
A17: Manufactured gases | B17: C0350-0370 | C17: =SUM(C18:C21) -> 0 | D17: =SUM(D18:D21) -> 0 | E17: =SUM(E18:E21) -> 0 | F17: =SUM(F18:F21) -> 0 | G17: =SUM(G18:G21) -> 0 | H17: =SUM(H18:H21) -> 0 | I17: =SUM(I18:I21) -> 0 | J17: =SUM(J18:J21) -> 0 | ... X17: =SUM(X18:X21) -> 0
A18: Gas works gas | B18: C0360 | C18: 0 | D18: 0 | E18: 0 | F18: 0 | G18: 0 | H18: 0 | I18: 0 | J18: 0 | K18: 0 | L18: 0 | M18: 0 | N18: 0 | O18: 0 | P18: 0 | Q18: 0 | R18: 0 | S18: 0 | T18: 0 | U18: 0 | V18: 0 | W18: 0 | X18: 0
A19: Coke oven gas | B19: C0350 | C19: 0 | D19: 0 | E19: 0 | F19: 0 | G19: 0 | H19: 0 | I19: 0 | J19: 0 | K19: 0 | L19: 0 | M19: 0 | N19: 0 | O19: 0 | P19: 0 | Q19: 0 | R19: 0 | S19: 0 | T19: 0 | U19: 0 | V19: 0 | W19: 0 | X19: 0
A20: Blast furnace gas | B20: C0371 | C20: 0 | D20: 0 | E20: 0 | F20: 0 | G20: 0 | H20: 0 | I20: 0 | J20: 0 | K20: 0 | L20: 0 | M20: 0 | N20: 0 | O20: 0 | P20: 0 | Q20: 0 | R20: 0 | S20: 0 | T20: 0 | U20: 0 | V20: 0 | W20: 0 | X20: 0
A21: Other recovered gases | B21: C0379 | C21: 0 | D21: 0 | E21: 0 | F21: 0 | G21: 0 | H21: 0 | I21: 0 | J21: 0 | K21: 0 | L21: 0 | M21: 0 | N21: 0 | O21: 0 | P21: 0 | Q21: 0 | R21: 0 | S21: 0 | T21: 0 | U21: 0 | V21: 0 | W21: 0 | X21: 0
A22: Peat and peat products | B22: P1000 | C22: =SUM(C23:C24) -> 0 | D22: =SUM(D23:D24) -> 0 | E22: =SUM(E23:E24) -> 0 | F22: =SUM(F23:F24) -> 0 | G22: =SUM(G23:G24) -> 0 | H22: =SUM(H23:H24) -> 0 | I22: =SUM(I23:I24) -> 0 | J22: =SUM(J23:J24) -> 0 | ... X22: =SUM(X23:X24) -> 0
A23: Peat | B23: P1100 | C23: 0 | D23: 0 | E23: 0 | F23: 0 | G23: 0 | H23: 0 | I23: 0 | J23: 0 | K23: 0 | L23: 0 | M23: 0 | N23: 0 | O23: 0 | P23: 0 | Q23: 0 | R23: 0 | S23: 0 | T23: 0 | U23: 0 | V23: 0 | W23: 0 | X23: 0
A24: Peat products | B24: P1200 | C24: 0 | D24: 0 | E24: 0 | F24: 0 | G24: 0 | H24: 0 | I24: 0 | J24: 0 | K24: 0 | L24: 0 | M24: 0 | N24: 0 | O24: 0 | P24: 0 | Q24: 0 | R24: 0 | S24: 0 | T24: 0 | U24: 0 | V24: 0 | W24: 0 | X24: 0
A25: Oil shale and oil sands | B25: S2000 | C25: 0 | D25: 0 | E25: 0 | F25: 0 | G25: 0 | H25: 0 | I25: 0 | J25: 0 | K25: 0 | L25: 0 | M25: 0 | N25: 0 | O25: 0 | P25: 0 | Q25: 0 | R25: 0 | S25: 0 | T25: 0 | U25: 0 | V25: 0 | W25: 0 | X25: 0
A26: Oil and petroleum products | B26: O4000XBIO | C26: =SUM(C27,C33) -> 2688.8627 | D26: =SUM(D27,D33) -> 2618.6298 | E26: =SUM(E27,E33) -> 2572.5948 | F26: =SUM(F27,F33) -> 2598.3782 | G26: =SUM(G27,G33) -> 2705.3192 | H26: =SUM(H27,H33) -> 2853.3414 | I26: =SUM(I27,I33) -> 3038.9248 | J26: =SUM(J27,J33) -> 3054.3825 | ... X26: =SUM(X27,X33) -> 3893.3873
A27: Crude oil, NGL, refinery feedstocks, additives and oxygenates and other hydrocarbons (excluding biofuel portion) | B27: O4100_TOT_4200-4500XBIO | C27: =SUM(C28:C32) -> 149.93783 | D27: =SUM(D28:D32) -> 0 | E27: =SUM(E28:E32) -> 0 | F27: =SUM(F28:F32) -> 0 | G27: =SUM(G28:G32) -> 0 | H27: =SUM(H28:H32) -> 0 | I27: =SUM(I28:I32) -> 0 | J27: =SUM(J28:J32) -> 0 | ... X27: =SUM(X28:X32) -> 0
A28: Crude oil | B28: O4100_TOT | C28: 93.39828 | D28: 0 | E28: 0 | F28: 0 | G28: 0 | H28: 0 | I28: 0 | J28: 0 | K28: 0 | L28: 0 | M28: 0 | N28: 0 | O28: 0 | P28: 0 | Q28: 0 | R28: 0 | S28: 0 | T28: 0 | U28: 0 | V28: 0 | W28: 0 | X28: 0
A29: Natural gas liquids | B29: O4200 | C29: 29.091402 | D29: 0 | E29: 0 | F29: 0 | G29: 0 | H29: 0 | I29: 0 | J29: 0 | K29: 0 | L29: 0 | M29: 0 | N29: 0 | O29: 0 | P29: 0 | Q29: 0 | R29: 0 | S29: 0 | T29: 0 | U29: 0 | V29: 0 | W29: 0 | X29: 0
A30: Refinery feedstocks | B30: O4300 | C30: 27.448151 | D30: 0 | E30: 0 | F30: 0 | G30: 0 | H30: 0 | I30: 0 | J30: 0 | K30: 0 | L30: 0 | M30: 0 | N30: 0 | O30: 0 | P30: 0 | Q30: 0 | R30: 0 | S30: 0 | T30: 0 | U30: 0 | V30: 0 | W30: 0 | X30: 0
A31: Additives and oxygenates (excluding biofuel portion) | B31: O4400X4410 | C31: 0 | D31: 0 | E31: 0 | F31: 0 | G31: 0 | H31: 0 | I31: 0 | J31: 0 | K31: 0 | L31: 0 | M31: 0 | N31: 0 | O31: 0 | P31: 0 | Q31: 0 | R31: 0 | S31: 0 | T31: 0 | U31: 0 | V31: 0 | W31: 0 | X31: 0
A32: Other hydrocarbons | B32: O4500 | C32: 0 | D32: 0 | E32: 0 | F32: 0 | G32: 0 | H32: 0 | I32: 0 | J32: 0 | K32: 0 | L32: 0 | M32: 0 | N32: 0 | O32: 0 | P32: 0 | Q32: 0 | R32: 0 | S32: 0 | T32: 0 | U32: 0 | V32: 0 | W32: 0 | X32: 0
A33: Oil products (excluding biofuel portion) | B33: O4600XBIO | C33: =SUM(C34:C50) -> 2538.9248 | D33: =SUM(D34:D50) -> 2618.6298 | E33: =SUM(E34:E50) -> 2572.5948 | F33: =SUM(F34:F50) -> 2598.3782 | G33: =SUM(G34:G50) -> 2705.3192 | H33: =SUM(H34:H50) -> 2853.3414 | I33: =SUM(I34:I50) -> 3038.9248 | J33: =SUM(J34:J50) -> 3054.3825 | ... X33: =SUM(X34:X50) -> 3893.3873
A34: Refinery gas | B34: O4610 | C34: 0 | D34: 0 | E34: 0 | F34: 0 | G34: 0 | H34: 0 | I34: 0 | J34: 0 | K34: 0 | L34: 0 | M34: 0 | N34: 0 | O34: 0 | P34: 0 | Q34: 0 | R34: 0 | S34: 0 | T34: 0 | U34: 0 | V34: 0 | W34: 0 | X34: 0
A35: Ethane | B35: O4620 | C35: 0 | D35: 0 | E35: 0 | F35: 0 | G35: 0 | H35: 0 | I35: 0 | J35: 0 | K35: 0 | L35: 0 | M35: 0 | N35: 0 | O35: 0 | P35: 0 | Q35: 0 | R35: 0 | S35: 0 | T35: 0 | U35: 0 | V35: 0 | W35: 0 | X35: 0
A36: Liquefied petroleum gases | B36: O4630 | C36: 105.06595 | D36: 97.157696 | E36: 97.157696 | F36: 99.417197 | G36: 97.157696 | H36: 98.287446 | I36: 109.58487 | J36: 98.989682 | K36: 109.98856 | L36: 102.28934 | M36: 104.48908 | N36: 98.989682 | O36: 89.090714 | P36: 83.591316 | Q36: 81.391488 | R36: 89.090714 | S36: 87.9908 | T36: 97.139639 | U36: 103.59931 | V36: 113.48504 | W36: 96.863629 | X36: 99.511006
A37: Motor gasoline (excluding biofuel portion) | B37: O4652XR5210B | C37: 917.36174 | D37: 852.8184 | E37: 823.19192 | F37: 827.42425 | G37: 759.70671 | H37: 771.34566 | I37: 733.13749 | J37: 696.48057 | K37: 807.49854 | L37: 700.66999 | M37: 757.22631 | N37: 741.51617 | O37: 710.09604 | P37: 596.9834 | Q37: 507.9595 | R37: 567.65787 | S37: 625.26156 | T37: 667.99613 | U37: 628.19304 | V37: 681.85245 | W37: 583.1742 | X37: 472.13113
A38: Aviation gasoline | B38: O4651 | C38: 1.0581255 | D38: 1.0581255 | E38: 1.0581255 | F38: 1.0581255 | G38: 1.0581255 | H38: 1.0581255 | I38: 1.0581255 | J38: 1.0581255 | K38: 1.0581255 | L38: 1.0581255 | M38: 1.0581255 | N38: 1.0581255 | O38: 1.0581255 | P38: 1.0269991 | Q38: 1.0269991 | R38: 1.0269991 | S38: 1.0269991 | T38: 0.39544282 | U38: 0.5227859 | V38: 0.49088564 | W38: 0.4683577 | X38: 0.46732588
A39: Gasoline-type jet fuel | B39: O4653 | C39: 0 | D39: 0 | E39: 0 | F39: 0 | G39: 0 | H39: 0 | I39: 0 | J39: 0 | K39: 0 | L39: 0 | M39: 0 | N39: 0 | O39: 0 | P39: 0 | Q39: 0 | R39: 0 | S39: 0 | T39: 0 | U39: 0 | V39: 0 | W39: 0 | X39: 0
A40: Kerosene-type jet fuel (excluding biofuel portion) | B40: O4661XR5230B | C40: 25.27945 | D40: 28.439381 | E40: 34.759243 | F40: 29.492691 | G40: 23.172829 | H40: 22.119518 | I40: 26.33276 | J40: 33.277902 | K40: 34.317885 | L40: 27.038349 | M40: 25.998366 | N40: 23.918487 | O40: 23.918487 | P40: 25.998366 | Q40: 328.61943 | R40: 329.65942 | S40: 239.18504 | T40: 248.95417 | U40: 240.95606 | V40: 321.37945 | W40: 129.65907 | X40: 31.494411
...

Sheet EXP
A1: Exports | B1: EXP | C1: 2000 | D1: 2001 | E1: 2002 | F1: 2003 | G1: 2004 | H1: 2005 | I1: 2006 | J1: 2007 | K1: 2008 | L1: 2009 | M1: 2010 | N1: 2011 | O1: 2012 | P1: 2013 | Q1: 2014 | R1: 2015 | S1: 2016 | T1: 2017 | U1: 2018 | V1: 2019 | W1: 2020 | X1: 2021
A2: Total | B2: TOTAL | C2: =SUM(C3,C17,C22,C25,C26,C51,C52,C71,C74,C75,C76) -> 715.54712 | D2: =SUM(D3,D17,D22,D25,D26,D51,D52,D71,D74,D75,D76) -> 586.56991 | E2: =SUM(E3,E17,E22,E25,E26,E51,E52,E71,E74,E75,E76) -> 544.49475 | F2: =SUM(F3,F17,F22,F25,F26,F51,F52,F71,F74,F75,F76) -> 598.5534 | G2: =SUM(G3,G17,G22,G25,G26,G51,G52,G71,G74,G75,G76) -> 850.02683 | H2: =SUM(H3,H17,H22,H25,H26,H51,H52,H71,H74,H75,H76) -> 1060.0506 | I2: =SUM(I3,I17,I22,I25,I26,I51,I52,I71,I74,I75,I76) -> 1090.8564 | J2: =SUM(J3,J17,J22,J25,J26,J51,J52,J71,J74,J75,J76) -> 941.76406 | ... X2: =SUM(X3,X17,X22,X25,X26,X51,X52,X71,X74,X75,X76) -> 2370.2681
A3: Solid fossil fuels | B3: C0000X0350-0370 | C3: =SUM(C4,C8,C11) -> 0.23705933 | D3: =SUM(D4,D8,D11) -> 0.24385211 | E3: =SUM(E4,E8,E11) -> 0.25081685 | F3: =SUM(F4,F8,F11) -> 5.0141874 | G3: =SUM(G4,G8,G11) -> 24.143078 | H3: =SUM(H4,H8,H11) -> 9.783147 | I3: =SUM(I4,I8,I11) -> 16.863199 | J3: =SUM(J4,J8,J11) -> 1.5173689 | ... X3: =SUM(X4,X8,X11) -> 0
A4: Hard coal | B4: C0100 | C4: =SUM(C5:C7) -> 0 | D4: =SUM(D5:D7) -> 0 | E4: =SUM(E5:E7) -> 0 | F4: =SUM(F5:F7) -> 0 | G4: =SUM(G5:G7) -> 0 | H4: =SUM(H5:H7) -> 0 | I4: =SUM(I5:I7) -> 0.62330181 | J4: =SUM(J5:J7) -> 0.60653482 | ... X4: =SUM(X5:X7) -> 0
A5: Anthracite | B5: C0110 | C5: 0 | D5: 0 | E5: 0 | F5: 0 | G5: 0 | H5: 0 | I5: 0 | J5: 0 | K5: 0 | L5: 0 | M5: 0 | N5: 0 | O5: 0 | P5: 0 | Q5: 0 | R5: 0 | S5: 0 | T5: 0 | U5: 0 | V5: 0 | W5: 0 | X5: 0
A6: Coking coal | B6: C0121 | C6: 0 | D6: 0 | E6: 0 | F6: 0 | G6: 0 | H6: 0 | I6: 0 | J6: 0 | K6: 0 | L6: 0 | M6: 0 | N6: 0 | O6: 0 | P6: 0 | Q6: 0 | R6: 0 | S6: 0 | T6: 0 | U6: 0 | V6: 0 | W6: 0 | X6: 0
A7: Other bituminous coal | B7: C0129 | C7: 0 | D7: 0 | E7: 0 | F7: 0 | G7: 0 | H7: 0 | I7: 0.62330181 | J7: 0.60653482 | K7: 0.60653482 | L7: 2.8537403 | M7: 0 | N7: 1.2104901 | O7: 0.60696475 | P7: 4.3762683 | Q7: 0.60206363 | R7: 0 | S7: 0 | T7: 0 | U7: 0 | V7: 0 | W7: 0 | X7: 0
A8: Brown coal | B8: C0200 | C8: =SUM(C9:C10) -> 0.23705933 | D8: =SUM(D9:D10) -> 0.24385211 | E8: =SUM(E9:E10) -> 0.25081685 | F8: =SUM(F9:F10) -> 5.0141874 | G8: =SUM(G9:G10) -> 24.143078 | H8: =SUM(H9:H10) -> 9.783147 | I8: =SUM(I9:I10) -> 16.239897 | J8: =SUM(J9:J10) -> 0.91083405 | ... X8: =SUM(X9:X10) -> 0
A9: Sub-bituminous coal | B9: C0210 | C9: 0 | D9: 0 | E9: 0 | F9: 5.0141874 | G9: 24.143078 | H9: 9.783147 | I9: 16.239897 | J9: 0.91083405 | K9: 0 | L9: 0 | M9: 0 | N9: 0 | O9: 0 | P9: 0 | Q9: 0 | R9: 0 | S9: 0 | T9: 0 | U9: 0 | V9: 0 | W9: 0 | X9: 0
A10: Lignite | B10: C0220 | C10: 0.23705933 | D10: 0.24385211 | E10: 0.25081685 | F10: 0 | G10: 0 | H10: 0 | I10: 0 | J10: 0 | K10: 0 | L10: 0 | M10: 0 | N10: 0 | O10: 0 | P10: 0 | Q10: 0 | R10: 0 | S10: 0 | T10: 0 | U10: 0 | V10: 0 | W10: 0 | X10: 0
A11: Coal products | B11: C0300 | C11: =SUM(C12:C16) -> 0 | D11: =SUM(D12:D16) -> 0 | E11: =SUM(E12:E16) -> 0 | F11: =SUM(F12:F16) -> 0 | G11: =SUM(G12:G16) -> 0 | H11: =SUM(H12:H16) -> 0 | I11: =SUM(I12:I16) -> 0 | J11: =SUM(J12:J16) -> 0 | ... X11: =SUM(X12:X16) -> 0
A12: Patent fuel | B12: C0320 | C12: 0 | D12: 0 | E12: 0 | F12: 0 | G12: 0 | H12: 0 | I12: 0 | J12: 0 | K12: 0 | L12: 0 | M12: 0 | N12: 0 | O12: 0 | P12: 0 | Q12: 0 | R12: 0 | S12: 0 | T12: 0 | U12: 0 | V12: 0 | W12: 0 | X12: 0
A13: Coke oven coke | B13: C0311 | C13: 0 | D13: 0 | E13: 0 | F13: 0 | G13: 0 | H13: 0 | I13: 0 | J13: 0 | K13: 0 | L13: 0 | M13: 0 | N13: 0 | O13: 0 | P13: 0 | Q13: 0 | R13: 0 | S13: 0 | T13: 0 | U13: 0 | V13: 0 | W13: 0 | X13: 0
A14: Gas coke | B14: C0312 | C14: 0 | D14: 0 | E14: 0 | F14: 0 | G14: 0 | H14: 0 | I14: 0 | J14: 0 | K14: 0 | L14: 0 | M14: 0 | N14: 0 | O14: 0 | P14: 0 | Q14: 0 | R14: 0 | S14: 0 | T14: 0 | U14: 0 | V14: 0 | W14: 0 | X14: 0
A15: Coal tar | B15: C0340 | C15: 0 | D15: 0 | E15: 0 | F15: 0 | G15: 0 | H15: 0 | I15: 0 | J15: 0 | K15: 0 | L15: 0 | M15: 0 | N15: 0 | O15: 0 | P15: 0 | Q15: 0 | R15: 0 | S15: 0 | T15: 0 | U15: 0 | V15: 0 | W15: 0 | X15: 0
A16: Brown coal briquettes | B16: C0330 | C16: 0 | D16: 0 | E16: 0 | F16: 0 | G16: 0 | H16: 0 | I16: 0 | J16: 0 | K16: 0 | L16: 0 | M16: 0 | N16: 0 | O16: 0 | P16: 0 | Q16: 0 | R16: 0 | S16: 0 | T16: 0 | U16: 0 | V16: 0 | W16: 0 | X16: 0
A17: Manufactured gases | B17: C0350-0370 | C17: =SUM(C18:C21) -> 0 | D17: =SUM(D18:D21) -> 0 | E17: =SUM(E18:E21) -> 0 | F17: =SUM(F18:F21) -> 0 | G17: =SUM(G18:G21) -> 0 | H17: =SUM(H18:H21) -> 0 | I17: =SUM(I18:I21) -> 0 | J17: =SUM(J18:J21) -> 0 | ... X17: =SUM(X18:X21) -> 0
A18: Gas works gas | B18: C0360 | C18: 0 | D18: 0 | E18: 0 | F18: 0 | G18: 0 | H18: 0 | I18: 0 | J18: 0 | K18: 0 | L18: 0 | M18: 0 | N18: 0 | O18: 0 | P18: 0 | Q18: 0 | R18: 0 | S18: 0 | T18: 0 | U18: 0 | V18: 0 | W18: 0 | X18: 0
A19: Coke oven gas | B19: C0350 | C19: 0 | D19: 0 | E19: 0 | F19: 0 | G19: 0 | H19: 0 | I19: 0 | J19: 0 | K19: 0 | L19: 0 | M19: 0 | N19: 0 | O19: 0 | P19: 0 | Q19: 0 | R19: 0 | S19: 0 | T19: 0 | U19: 0 | V19: 0 | W19: 0 | X19: 0
A20: Blast furnace gas | B20: C0371 | C20: 0 | D20: 0 | E20: 0 | F20: 0 | G20: 0 | H20: 0 | I20: 0 | J20: 0 | K20: 0 | L20: 0 | M20: 0 | N20: 0 | O20: 0 | P20: 0 | Q20: 0 | R20: 0 | S20: 0 | T20: 0 | U20: 0 | V20: 0 | W20: 0 | X20: 0
A21: Other recovered gases | B21: C0379 | C21: 0 | D21: 0 | E21: 0 | F21: 0 | G21: 0 | H21: 0 | I21: 0 | J21: 0 | K21: 0 | L21: 0 | M21: 0 | N21: 0 | O21: 0 | P21: 0 | Q21: 0 | R21: 0 | S21: 0 | T21: 0 | U21: 0 | V21: 0 | W21: 0 | X21: 0
A22: Peat and peat products | B22: P1000 | C22: =SUM(C23:C24) -> 0 | D22: =SUM(D23:D24) -> 0 | E22: =SUM(E23:E24) -> 0 | F22: =SUM(F23:F24) -> 0 | G22: =SUM(G23:G24) -> 0 | H22: =SUM(H23:H24) -> 0 | I22: =SUM(I23:I24) -> 0 | J22: =SUM(J23:J24) -> 0 | ... X22: =SUM(X23:X24) -> 0
A23: Peat | B23: P1100 | C23: 0 | D23: 0 | E23: 0 | F23: 0 | G23: 0 | H23: 0 | I23: 0 | J23: 0 | K23: 0 | L23: 0 | M23: 0 | N23: 0 | O23: 0 | P23: 0 | Q23: 0 | R23: 0 | S23: 0 | T23: 0 | U23: 0 | V23: 0 | W23: 0 | X23: 0
A24: Peat products | B24: P1200 | C24: 0 | D24: 0 | E24: 0 | F24: 0 | G24: 0 | H24: 0 | I24: 0 | J24: 0 | K24: 0 | L24: 0 | M24: 0 | N24: 0 | O24: 0 | P24: 0 | Q24: 0 | R24: 0 | S24: 0 | T24: 0 | U24: 0 | V24: 0 | W24: 0 | X24: 0
A25: Oil shale and oil sands | B25: S2000 | C25: 0 | D25: 0 | E25: 0 | F25: 0 | G25: 0 | H25: 0 | I25: 0 | J25: 0 | K25: 0 | L25: 0 | M25: 0 | N25: 0 | O25: 0 | P25: 0 | Q25: 0 | R25: 0 | S25: 0 | T25: 0 | U25: 0 | V25: 0 | W25: 0 | X25: 0
A26: Oil and petroleum products | B26: O4000XBIO | C26: =SUM(C27,C33) -> 237.83801 | D26: =SUM(D27,D33) -> 162.76629 | E26: =SUM(E27,E33) -> 120.51221 | F26: =SUM(F27,F33) -> 93.883147 | G26: =SUM(G27,G33) -> 121.75649 | H26: =SUM(H27,H33) -> 219.05512 | I26: =SUM(I27,I33) -> 415.17979 | J26: =SUM(J27,J33) -> 434.91565 | ... X26: =SUM(X27,X33) -> 1625.555
A27: Crude oil, NGL, refinery feedstocks, additives and oxygenates and other hydrocarbons (excluding biofuel portion) | B27: O4100_TOT_4200-4500XBIO | C27: =SUM(C28:C32) -> 0 | D27: =SUM(D28:D32) -> 0 | E27: =SUM(E28:E32) -> 0.99363715 | F27: =SUM(F28:F32) -> 0 | G27: =SUM(G28:G32) -> 0 | H27: =SUM(H28:H32) -> 0 | I27: =SUM(I28:I32) -> 0 | J27: =SUM(J28:J32) -> 0 | ... X27: =SUM(X28:X32) -> 0.35253654
A28: Crude oil | B28: O4100_TOT | C28: 0 | D28: 0 | E28: 0.99363715 | F28: 0 | G28: 0 | H28: 0 | I28: 0 | J28: 0 | K28: 0 | L28: 0 | M28: 0 | N28: 0 | O28: 0 | P28: 0 | Q28: 0 | R28: 0 | S28: 0 | T28: 0.24574377 | U28: 0.27936371 | V28: 0.28039553 | W28: 0.24772141 | X28: 0.16208083
A29: Natural gas liquids | B29: O4200 | C29: 0 | D29: 0 | E29: 0 | F29: 0 | G29: 0 | H29: 0 | I29: 0 | J29: 0 | K29: 0 | L29: 0 | M29: 0 | N29: 0 | O29: 0 | P29: 0 | Q29: 0 | R29: 0 | S29: 0 | T29: 0.27996561 | U29: 0.62725709 | V29: 0.24625967 | W29: 0.1533104 | X29: 0.19045572
A30: Refinery feedstocks | B30: O4300 | C30: 0 | D30: 0 | E30: 0 | F30: 0 | G30: 0 | H30: 0 | I30: 0 | J30: 0 | K30: 0 | L30: 0 | M30: 0 | N30: 0 | O30: 0 | P30: 0 | Q30: 0 | R30: 0 | S30: 0 | T30: 0 | U30: 0 | V30: 0 | W30: 0 | X30: 0
A31: Additives and oxygenates (excluding biofuel portion) | B31: O4400X4410 | C31: 0 | D31: 0 | E31: 0 | F31: 0 | G31: 0 | H31: 0 | I31: 0 | J31: 0 | K31: 0 | L31: 0 | M31: 0 | N31: 0 | O31: 0 | P31: 0 | Q31: 0 | R31: 0 | S31: 0 | T31: 0 | U31: 0 | V31: 0 | W31: 0 | X31: 0
A32: Other hydrocarbons | B32: O4500 | C32: 0 | D32: 0 | E32: 0 | F32: 0 | G32: 0 | H32: 0 | I32: 0 | J32: 0 | K32: 0 | L32: 0 | M32: 0 | N32: 0 | O32: 0 | P32: 0 | Q32: 0 | R32: 0 | S32: 0 | T32: 0 | U32: 0 | V32: 0 | W32: 0 | X32: 0
A33: Oil products (excluding biofuel portion) | B33: O4600XBIO | C33: =SUM(C34:C50) -> 237.83801 | D33: =SUM(D34:D50) -> 162.76629 | E33: =SUM(E34:E50) -> 119.51857 | F33: =SUM(F34:F50) -> 93.883147 | G33: =SUM(G34:G50) -> 121.75649 | H33: =SUM(H34:H50) -> 219.05512 | I33: =SUM(I34:I50) -> 415.17979 | J33: =SUM(J34:J50) -> 434.91565 | ... X33: =SUM(X34:X50) -> 1625.2025
A34: Refinery gas | B34: O4610 | C34: 0 | D34: 0 | E34: 0 | F34: 0 | G34: 0 | H34: 0 | I34: 0 | J34: 0 | K34: 0 | L34: 0 | M34: 0 | N34: 0 | O34: 0 | P34: 0 | Q34: 0 | R34: 0 | S34: 0 | T34: 0 | U34: 0 | V34: 0 | W34: 0 | X34: 0
A35: Ethane | B35: O4620 | C35: 0 | D35: 0 | E35: 0 | F35: 0 | G35: 0 | H35: 0 | I35: 0 | J35: 0 | K35: 0 | L35: 0 | M35: 0 | N35: 0 | O35: 0 | P35: 0 | Q35: 0 | R35: 0 | S35: 0 | T35: 0 | U35: 0 | V35: 0 | W35: 0 | X35: 0
A36: Liquefied petroleum gases | B36: O4630 | C36: 0 | D36: 0 | E36: 0 | F36: 0 | G36: 0 | H36: 0 | I36: 5.6486672 | J36: 8.7990542 | K36: 14.298538 | L36: 12.09871 | M36: 9.8989682 | N36: 7.6992261 | O36: 1.099914 | P36: 1.099914 | Q36: 0 | R36: 0 | S36: 0 | T36: 0 | U36: 0 | V36: 7.605675 | W36: 5.6522786 | X36: 8.4592433
A37: Motor gasoline (excluding biofuel portion) | B37: O4652XR5210B | C37: 74.066122 | D37: 31.742648 | E37: 19.045572 | F37: 28.568358 | G37: 31.742648 | H37: 65.601376 | I37: 78.550473 | J37: 74.361049 | K37: 104.73396 | L37: 109.97059 | M37: 152.91152 | N37: 150.81685 | O37: 157.10086 | P37: 118.34936 | Q37: 71.219089 | R37: 121.49132 | S37: 175.95297 | T37: 230.12769 | U37: 207.59312 | V37: 272.57008 | W37: 242.64755 | X37: 100.75193
A38: Aviation gasoline | B38: O4651 | C38: 0 | D38: 0 | E38: 0 | F38: 0 | G38: 0 | H38: 0 | I38: 0 | J38: 0 | K38: 0 | L38: 0 | M38: 0 | N38: 0 | O38: 0 | P38: 0 | Q38: 0 | R38: 0 | S38: 0 | T38: 0.013327601 | U38: 0.039036973 | V38: 0 | W38: 0.020550301 | X38: 0
A39: Gasoline-type jet fuel | B39: O4653 | C39: 0 | D39: 0 | E39: 0 | F39: 0 | G39: 0 | H39: 0 | I39: 0 | J39: 0 | K39: 0 | L39: 0 | M39: 0 | N39: 0 | O39: 0 | P39: 0 | Q39: 0 | R39: 0 | S39: 0 | T39: 0 | U39: 0 | V39: 0 | W39: 0 | X39: 0
A40: Kerosene-type jet fuel (excluding biofuel portion) | B40: O4661XR5230B | C40: 0 | D40: 1.0533104 | E40: 6.3198624 | F40: 2.1066208 | G40: 1.0533104 | H40: 0 | I40: 1.0533104 | J40: 0 | K40: 1.0398968 | L40: 0 | M40: 0 | N40: 0 | O40: 1.0398968 | P40: 0 | Q40: 329.65942 | R40: 301.58117 | S40: 187.18831 | T40: 224.3712 | U40: 210.60241 | V40: 275.14187 | W40: 96.292777 | X40: 63.122012
...

Sheet STK_CHG
A1: Change in stock | B1: STK_CHG | C1: 2000 | D1: 2001 | E1: 2002 | F1: 2003 | G1: 2004 | H1: 2005 | I1: 2006 | J1: 2007 | K1: 2008 | L1: 2009 | M1: 2010 | N1: 2011 | O1: 2012 | P1: 2013 | Q1: 2014 | R1: 2015 | S1: 2016 | T1: 2017 | U1: 2018 | V1: 2019 | W1: 2020 | X1: 2021
