Workbook

Sheet cover
B6: JRC-IDEES-2021 - Integrated Database of the European Energy System
C15: Domestic navigation
L28: Prepared by JRC C.6
L30: 45432.79
L31: v2021-1.00
B33: Legal Notice
B35: The information made available is property of the Joint Research Centre of the European Commission.
B36: Neither the European Commission nor any person acting on behalf of the Commission is responsible for the use which might be made of this information.
B38: Use conditions
B39: This work is licensed under
B40: CC BY 4.0

Sheet EEA
A1: EEA - European Economic Area (EU27+IS+NO) | B1: 1990 | C1: 1991 | D1: 1992 | E1: 1993 | F1: 1994 | G1: 1995 | H1: 1996 | I1: 1997 | J1: 1998 | K1: 1999 | L1: 2000 | M1: 2001 | N1: 2002 | O1: 2003 | P1: 2004 | Q1: 2005 | R1: 2006 | S1: 2007 | T1: 2008 | U1: 2009 | V1: 2010 | W1: 2011 | X1: 2012 | Y1: 2013 | Z1: 2014 | AA1: 2015 | AB1: 2016 | AC1: 2017 | AD1: 2018 | AE1: 2019 | AF1: 2020 | AG1: 2021
A3: Transport activity (Mtkm) | B3: =SUM(B4:B5) -> 236722.13 | C3: =SUM(C4:C5) -> 225467.05 | D3: =SUM(D4:D5) -> 206360.19 | E3: =SUM(E4:E5) -> 206974.27 | F3: =SUM(F4:F5) -> 212671.79 | G3: =SUM(G4:G5) -> 215449.79 | H3: =SUM(H4:H5) -> 207707.67 | I3: =SUM(I4:I5) -> 231689.36 | ... AG3: =SUM(AG4:AG5) -> 233002.07
A4: Domestic coastal shipping | B4: =AT!B4+BE!B4+BG!B4+CY!B4+CZ!B4+DE!B4+DK!B4+EE!B4+EL!B4+ES!B4+FI!B4+FR!B4+HR!B4+HU!B4+IE!B4+IT!B4+LT!B4+LU!B4+LV!B4+MT!B4+NL!B4+PL!B4+PT!B4+RO!B4+SE!B4+SI!B4+SK!B4+IS!B4+NO!B4 -> 123420.31 | C4: =AT!C4+BE!C4+BG!C4+CY!C4+CZ!C4+DE!C4+DK!C4+EE!C4+EL!C4+ES!C4+FI!C4+FR!C4+HR!C4+HU!C4+IE!C4+IT!C4+LT!C4+LU!C4+LV!C4+MT!C4+NL!C4+PL!C4+PT!C4+RO!C4+SE!C4+SI!C4+SK!C4+IS!C4+NO!C4 -> 113154.69 | D4: =AT!D4+BE!D4+BG!D4+CY!D4+CZ!D4+DE!D4+DK!D4+EE!D4+EL!D4+ES!D4+FI!D4+FR!D4+HR!D4+HU!D4+IE!D4+IT!D4+LT!D4+LU!D4+LV!D4+MT!D4+NL!D4+PL!D4+PT!D4+RO!D4+SE!D4+SI!D4+SK!D4+IS!D4+NO!D4 -> 94758.022 | E4: =AT!E4+BE!E4+BG!E4+CY!E4+CZ!E4+DE!E4+DK!E4+EE!E4+EL!E4+ES!E4+FI!E4+FR!E4+HR!E4+HU!E4+IE!E4+IT!E4+LT!E4+LU!E4+LV!E4+MT!E4+NL!E4+PL!E4+PT!E4+RO!E4+SE!E4+SI!E4+SK!E4+IS!E4+NO!E4 -> 98371.173 | F4: =AT!F4+BE!F4+BG!F4+CY!F4+CZ!F4+DE!F4+DK!F4+EE!F4+EL!F4+ES!F4+FI!F4+FR!F4+HR!F4+HU!F4+IE!F4+IT!F4+LT!F4+LU!F4+LV!F4+MT!F4+NL!F4+PL!F4+PT!F4+RO!F4+SE!F4+SI!F4+SK!F4+IS!F4+NO!F4 -> 95476.469 | G4: =AT!G4+BE!G4+BG!G4+CY!G4+CZ!G4+DE!G4+DK!G4+EE!G4+EL!G4+ES!G4+FI!G4+FR!G4+HR!G4+HU!G4+IE!G4+IT!G4+LT!G4+LU!G4+LV!G4+MT!G4+NL!G4+PL!G4+PT!G4+RO!G4+SE!G4+SI!G4+SK!G4+IS!G4+NO!G4 -> 95613.485 | H4: =AT!H4+BE!H4+BG!H4+CY!H4+CZ!H4+DE!H4+DK!H4+EE!H4+EL!H4+ES!H4+FI!H4+FR!H4+HR!H4+HU!H4+IE!H4+IT!H4+LT!H4+LU!H4+LV!H4+MT!H4+NL!H4+PL!H4+PT!H4+RO!H4+SE!H4+SI!H4+SK!H4+IS!H4+NO!H4 -> 90284.578 | I4: =AT!I4+BE!I4+BG!I4+CY!I4+CZ!I4+DE!I4+DK!I4+EE!I4+EL!I4+ES!I4+FI!I4+FR!I4+HR!I4+HU!I4+IE!I4+IT!I4+LT!I4+LU!I4+LV!I4+MT!I4+NL!I4+PL!I4+PT!I4+RO!I4+SE!I4+SI!I4+SK!I4+IS!I4+NO!I4 -> 105844.54 | ... AG4: =AT!AG4+BE!AG4+BG!AG4+CY!AG4+CZ!AG4+DE!AG4+DK!AG4+EE!AG4+EL!AG4+ES!AG4+FI!AG4+FR!AG4+HR!AG4+HU!AG4+IE!AG4+IT!AG4+LT!AG4+LU!AG4+LV!AG4+MT!AG4+NL!AG4+PL!AG4+PT!AG4+RO!AG4+SE!AG4+SI!AG4+SK!AG4+IS!AG4+NO!AG4 -> 96926.069
A5: Inland waterways | B5: =AT!B5+BE!B5+BG!B5+CY!B5+CZ!B5+DE!B5+DK!B5+EE!B5+EL!B5+ES!B5+FI!B5+FR!B5+HR!B5+HU!B5+IE!B5+IT!B5+LT!B5+LU!B5+LV!B5+MT!B5+NL!B5+PL!B5+PT!B5+RO!B5+SE!B5+SI!B5+SK!B5+IS!B5+NO!B5 -> 113301.83 | C5: =AT!C5+BE!C5+BG!C5+CY!C5+CZ!C5+DE!C5+DK!C5+EE!C5+EL!C5+ES!C5+FI!C5+FR!C5+HR!C5+HU!C5+IE!C5+IT!C5+LT!C5+LU!C5+LV!C5+MT!C5+NL!C5+PL!C5+PT!C5+RO!C5+SE!C5+SI!C5+SK!C5+IS!C5+NO!C5 -> 112312.36 | D5: =AT!D5+BE!D5+BG!D5+CY!D5+CZ!D5+DE!D5+DK!D5+EE!D5+EL!D5+ES!D5+FI!D5+FR!D5+HR!D5+HU!D5+IE!D5+IT!D5+LT!D5+LU!D5+LV!D5+MT!D5+NL!D5+PL!D5+PT!D5+RO!D5+SE!D5+SI!D5+SK!D5+IS!D5+NO!D5 -> 111602.16 | E5: =AT!E5+BE!E5+BG!E5+CY!E5+CZ!E5+DE!E5+DK!E5+EE!E5+EL!E5+ES!E5+FI!E5+FR!E5+HR!E5+HU!E5+IE!E5+IT!E5+LT!E5+LU!E5+LV!E5+MT!E5+NL!E5+PL!E5+PT!E5+RO!E5+SE!E5+SI!E5+SK!E5+IS!E5+NO!E5 -> 108603.1 | F5: =AT!F5+BE!F5+BG!F5+CY!F5+CZ!F5+DE!F5+DK!F5+EE!F5+EL!F5+ES!F5+FI!F5+FR!F5+HR!F5+HU!F5+IE!F5+IT!F5+LT!F5+LU!F5+LV!F5+MT!F5+NL!F5+PL!F5+PT!F5+RO!F5+SE!F5+SI!F5+SK!F5+IS!F5+NO!F5 -> 117195.32 | G5: =AT!G5+BE!G5+BG!G5+CY!G5+CZ!G5+DE!G5+DK!G5+EE!G5+EL!G5+ES!G5+FI!G5+FR!G5+HR!G5+HU!G5+IE!G5+IT!G5+LT!G5+LU!G5+LV!G5+MT!G5+NL!G5+PL!G5+PT!G5+RO!G5+SE!G5+SI!G5+SK!G5+IS!G5+NO!G5 -> 119836.31 | H5: =AT!H5+BE!H5+BG!H5+CY!H5+CZ!H5+DE!H5+DK!H5+EE!H5+EL!H5+ES!H5+FI!H5+FR!H5+HR!H5+HU!H5+IE!H5+IT!H5+LT!H5+LU!H5+LV!H5+MT!H5+NL!H5+PL!H5+PT!H5+RO!H5+SE!H5+SI!H5+SK!H5+IS!H5+NO!H5 -> 117423.09 | I5: =AT!I5+BE!I5+BG!I5+CY!I5+CZ!I5+DE!I5+DK!I5+EE!I5+EL!I5+ES!I5+FI!I5+FR!I5+HR!I5+HU!I5+IE!I5+IT!I5+LT!I5+LU!I5+LV!I5+MT!I5+NL!I5+PL!I5+PT!I5+RO!I5+SE!I5+SI!I5+SK!I5+IS!I5+NO!I5 -> 125844.83 | ... AG5: =AT!AG5+BE!AG5+BG!AG5+CY!AG5+CZ!AG5+DE!AG5+DK!AG5+EE!AG5+EL!AG5+ES!AG5+FI!AG5+FR!AG5+HR!AG5+HU!AG5+IE!AG5+IT!AG5+LT!AG5+LU!AG5+LV!AG5+MT!AG5+NL!AG5+PL!AG5+PT!AG5+RO!AG5+SE!AG5+SI!AG5+SK!AG5+IS!AG5+NO!AG5 -> 136076
A7: Market shares of activity (% of tkm) | B7: =IF(B3=0,0,B3/B$3) -> 1 | C7: =IF(C3=0,0,C3/C$3) -> 1 | D7: =IF(D3=0,0,D3/D$3) -> 1 | E7: =IF(E3=0,0,E3/E$3) -> 1 | F7: =IF(F3=0,0,F3/F$3) -> 1 | G7: =IF(G3=0,0,G3/G$3) -> 1 | H7: =IF(H3=0,0,H3/H$3) -> 1 | I7: =IF(I3=0,0,I3/I$3) -> 1 | ... AG7: =IF(AG3=0,0,AG3/AG$3) -> 1
A8: Domestic coastal shipping | B8: =IF(B4=0,0,B4/B$3) -> 0.52137206 | C8: =IF(C4=0,0,C4/C$3) -> 0.50186796 | D8: =IF(D4=0,0,D4/D$3) -> 0.45918752 | E8: =IF(E4=0,0,E4/E$3) -> 0.47528213 | F8: =IF(F4=0,0,F4/F$3) -> 0.44893809 | G8: =IF(G4=0,0,G4/G$3) -> 0.44378546 | H8: =IF(H4=0,0,H4/H$3) -> 0.43467137 | I8: =IF(I4=0,0,I4/I$3) -> 0.45683813 | ... AG8: =IF(AG4=0,0,AG4/AG$3) -> 0.41598802
A9: Inland waterways | B9: =IF(B5=0,0,B5/B$3) -> 0.47862794 | C9: =IF(C5=0,0,C5/C$3) -> 0.49813204 | D9: =IF(D5=0,0,D5/D$3) -> 0.54081248 | E9: =IF(E5=0,0,E5/E$3) -> 0.52471787 | F9: =IF(F5=0,0,F5/F$3) -> 0.55106191 | G9: =IF(G5=0,0,G5/G$3) -> 0.55621454 | H9: =IF(H5=0,0,H5/H$3) -> 0.56532863 | I9: =IF(I5=0,0,I5/I$3) -> 0.54316187 | ... AG9: =IF(AG5=0,0,AG5/AG$3) -> 0.58401198
A11: Vehicle-km (Mvkm) | B11: =SUM(B12:B13) -> 273.51 | C11: =SUM(C12:C13) -> 252.82 | D11: =SUM(D12:D13) -> 239.904 | E11: =SUM(E12:E13) -> 232.648 | F11: =SUM(F12:F13) -> 242.849 | G11: =SUM(G12:G13) -> 246.937 | H11: =SUM(H12:H13) -> 241.359 | I11: =SUM(I12:I13) -> 263.859 | ... AG11: =SUM(AG12:AG13) -> 221.944
A12: Domestic coastal shipping | B12: =AT!B12+BE!B12+BG!B12+CY!B12+CZ!B12+DE!B12+DK!B12+EE!B12+EL!B12+ES!B12+FI!B12+FR!B12+HR!B12+HU!B12+IE!B12+IT!B12+LT!B12+LU!B12+LV!B12+MT!B12+NL!B12+PL!B12+PT!B12+RO!B12+SE!B12+SI!B12+SK!B12+IS!B12+NO!B12 -> 69.409 | C12: =AT!C12+BE!C12+BG!C12+CY!C12+CZ!C12+DE!C12+DK!C12+EE!C12+EL!C12+ES!C12+FI!C12+FR!C12+HR!C12+HU!C12+IE!C12+IT!C12+LT!C12+LU!C12+LV!C12+MT!C12+NL!C12+PL!C12+PT!C12+RO!C12+SE!C12+SI!C12+SK!C12+IS!C12+NO!C12 -> 64.023 | D12: =AT!D12+BE!D12+BG!D12+CY!D12+CZ!D12+DE!D12+DK!D12+EE!D12+EL!D12+ES!D12+FI!D12+FR!D12+HR!D12+HU!D12+IE!D12+IT!D12+LT!D12+LU!D12+LV!D12+MT!D12+NL!D12+PL!D12+PT!D12+RO!D12+SE!D12+SI!D12+SK!D12+IS!D12+NO!D12 -> 55.418 | E12: =AT!E12+BE!E12+BG!E12+CY!E12+CZ!E12+DE!E12+DK!E12+EE!E12+EL!E12+ES!E12+FI!E12+FR!E12+HR!E12+HU!E12+IE!E12+IT!E12+LT!E12+LU!E12+LV!E12+MT!E12+NL!E12+PL!E12+PT!E12+RO!E12+SE!E12+SI!E12+SK!E12+IS!E12+NO!E12 -> 57.779 | F12: =AT!F12+BE!F12+BG!F12+CY!F12+CZ!F12+DE!F12+DK!F12+EE!F12+EL!F12+ES!F12+FI!F12+FR!F12+HR!F12+HU!F12+IE!F12+IT!F12+LT!F12+LU!F12+LV!F12+MT!F12+NL!F12+PL!F12+PT!F12+RO!F12+SE!F12+SI!F12+SK!F12+IS!F12+NO!F12 -> 56.915 | G12: =AT!G12+BE!G12+BG!G12+CY!G12+CZ!G12+DE!G12+DK!G12+EE!G12+EL!G12+ES!G12+FI!G12+FR!G12+HR!G12+HU!G12+IE!G12+IT!G12+LT!G12+LU!G12+LV!G12+MT!G12+NL!G12+PL!G12+PT!G12+RO!G12+SE!G12+SI!G12+SK!G12+IS!G12+NO!G12 -> 57.209 | H12: =AT!H12+BE!H12+BG!H12+CY!H12+CZ!H12+DE!H12+DK!H12+EE!H12+EL!H12+ES!H12+FI!H12+FR!H12+HR!H12+HU!H12+IE!H12+IT!H12+LT!H12+LU!H12+LV!H12+MT!H12+NL!H12+PL!H12+PT!H12+RO!H12+SE!H12+SI!H12+SK!H12+IS!H12+NO!H12 -> 54.743 | I12: =AT!I12+BE!I12+BG!I12+CY!I12+CZ!I12+DE!I12+DK!I12+EE!I12+EL!I12+ES!I12+FI!I12+FR!I12+HR!I12+HU!I12+IE!I12+IT!I12+LT!I12+LU!I12+LV!I12+MT!I12+NL!I12+PL!I12+PT!I12+RO!I12+SE!I12+SI!I12+SK!I12+IS!I12+NO!I12 -> 62.811 | ... AG12: =AT!AG12+BE!AG12+BG!AG12+CY!AG12+CZ!AG12+DE!AG12+DK!AG12+EE!AG12+EL!AG12+ES!AG12+FI!AG12+FR!AG12+HR!AG12+HU!AG12+IE!AG12+IT!AG12+LT!AG12+LU!AG12+LV!AG12+MT!AG12+NL!AG12+PL!AG12+PT!AG12+RO!AG12+SE!AG12+SI!AG12+SK!AG12+IS!AG12+NO!AG12 -> 44.469
A13: Inland waterways | B13: =AT!B13+BE!B13+BG!B13+CY!B13+CZ!B13+DE!B13+DK!B13+EE!B13+EL!B13+ES!B13+FI!B13+FR!B13+HR!B13+HU!B13+IE!B13+IT!B13+LT!B13+LU!B13+LV!B13+MT!B13+NL!B13+PL!B13+PT!B13+RO!B13+SE!B13+SI!B13+SK!B13+IS!B13+NO!B13 -> 204.101 | C13: =AT!C13+BE!C13+BG!C13+CY!C13+CZ!C13+DE!C13+DK!C13+EE!C13+EL!C13+ES!C13+FI!C13+FR!C13+HR!C13+HU!C13+IE!C13+IT!C13+LT!C13+LU!C13+LV!C13+MT!C13+NL!C13+PL!C13+PT!C13+RO!C13+SE!C13+SI!C13+SK!C13+IS!C13+NO!C13 -> 188.797 | D13: =AT!D13+BE!D13+BG!D13+CY!D13+CZ!D13+DE!D13+DK!D13+EE!D13+EL!D13+ES!D13+FI!D13+FR!D13+HR!D13+HU!D13+IE!D13+IT!D13+LT!D13+LU!D13+LV!D13+MT!D13+NL!D13+PL!D13+PT!D13+RO!D13+SE!D13+SI!D13+SK!D13+IS!D13+NO!D13 -> 184.486 | E13: =AT!E13+BE!E13+BG!E13+CY!E13+CZ!E13+DE!E13+DK!E13+EE!E13+EL!E13+ES!E13+FI!E13+FR!E13+HR!E13+HU!E13+IE!E13+IT!E13+LT!E13+LU!E13+LV!E13+MT!E13+NL!E13+PL!E13+PT!E13+RO!E13+SE!E13+SI!E13+SK!E13+IS!E13+NO!E13 -> 174.869 | F13: =AT!F13+BE!F13+BG!F13+CY!F13+CZ!F13+DE!F13+DK!F13+EE!F13+EL!F13+ES!F13+FI!F13+FR!F13+HR!F13+HU!F13+IE!F13+IT!F13+LT!F13+LU!F13+LV!F13+MT!F13+NL!F13+PL!F13+PT!F13+RO!F13+SE!F13+SI!F13+SK!F13+IS!F13+NO!F13 -> 185.934 | G13: =AT!G13+BE!G13+BG!G13+CY!G13+CZ!G13+DE!G13+DK!G13+EE!G13+EL!G13+ES!G13+FI!G13+FR!G13+HR!G13+HU!G13+IE!G13+IT!G13+LT!G13+LU!G13+LV!G13+MT!G13+NL!G13+PL!G13+PT!G13+RO!G13+SE!G13+SI!G13+SK!G13+IS!G13+NO!G13 -> 189.728 | H13: =AT!H13+BE!H13+BG!H13+CY!H13+CZ!H13+DE!H13+DK!H13+EE!H13+EL!H13+ES!H13+FI!H13+FR!H13+HR!H13+HU!H13+IE!H13+IT!H13+LT!H13+LU!H13+LV!H13+MT!H13+NL!H13+PL!H13+PT!H13+RO!H13+SE!H13+SI!H13+SK!H13+IS!H13+NO!H13 -> 186.616 | I13: =AT!I13+BE!I13+BG!I13+CY!I13+CZ!I13+DE!I13+DK!I13+EE!I13+EL!I13+ES!I13+FI!I13+FR!I13+HR!I13+HU!I13+IE!I13+IT!I13+LT!I13+LU!I13+LV!I13+MT!I13+NL!I13+PL!I13+PT!I13+RO!I13+SE!I13+SI!I13+SK!I13+IS!I13+NO!I13 -> 201.048 | ... AG13: =AT!AG13+BE!AG13+BG!AG13+CY!AG13+CZ!AG13+DE!AG13+DK!AG13+EE!AG13+EL!AG13+ES!AG13+FI!AG13+FR!AG13+HR!AG13+HU!AG13+IE!AG13+IT!AG13+LT!AG13+LU!AG13+LV!AG13+MT!AG13+NL!AG13+PL!AG13+PT!AG13+RO!AG13+SE!AG13+SI!AG13+SK!AG13+IS!AG13+NO!AG13 -> 177.475
A15: Market shares of vehicle km (% of km) | B15: =IF(B11=0,0,B11/B$11) -> 1 | C15: =IF(C11=0,0,C11/C$11) -> 1 | D15: =IF(D11=0,0,D11/D$11) -> 1 | E15: =IF(E11=0,0,E11/E$11) -> 1 | F15: =IF(F11=0,0,F11/F$11) -> 1 | G15: =IF(G11=0,0,G11/G$11) -> 1 | H15: =IF(H11=0,0,H11/H$11) -> 1 | I15: =IF(I11=0,0,I11/I$11) -> 1 | ... AG15: =IF(AG11=0,0,AG11/AG$11) -> 1
A16: Domestic coastal shipping | B16: =IF(B12=0,0,B12/B$11) -> 0.25377134 | C16: =IF(C12=0,0,C12/C$11) -> 0.2532355 | D16: =IF(D12=0,0,D12/D$11) -> 0.23100073 | E16: =IF(E12=0,0,E12/E$11) -> 0.24835374 | F16: =IF(F12=0,0,F12/F$11) -> 0.23436374 | G16: =IF(G12=0,0,G12/G$11) -> 0.23167448 | H16: =IF(H12=0,0,H12/H$11) -> 0.22681151 | I16: =IF(I12=0,0,I12/I$11) -> 0.23804759 | ... AG16: =IF(AG12=0,0,AG12/AG$11) -> 0.20036135
A17: Inland waterways | B17: =IF(B13=0,0,B13/B$11) -> 0.74622866 | C17: =IF(C13=0,0,C13/C$11) -> 0.7467645 | D17: =IF(D13=0,0,D13/D$11) -> 0.76899927 | E17: =IF(E13=0,0,E13/E$11) -> 0.75164626 | F17: =IF(F13=0,0,F13/F$11) -> 0.76563626 | G17: =IF(G13=0,0,G13/G$11) -> 0.76832552 | H17: =IF(H13=0,0,H13/H$11) -> 0.77318849 | I17: =IF(I13=0,0,I13/I$11) -> 0.76195241 | ... AG17: =IF(AG13=0,0,AG13/AG$11) -> 0.79963865
A19: Load factor of vessels (t/movement) | B19: =IF(B3=0,0,B3/B11) -> 865.49717 | C19: =IF(C3=0,0,C3/C11) -> 891.8086 | D19: =IF(D3=0,0,D3/D11) -> 860.17818 | E19: =IF(E3=0,0,E3/E11) -> 889.64561 | F19: =IF(F3=0,0,F3/F11) -> 875.73675 | G19: =IF(G3=0,0,G3/G11) -> 872.48891 | H19: =IF(H3=0,0,H3/H11) -> 860.57562 | I19: =IF(I3=0,0,I3/I11) -> 878.08019 | ... AG19: =IF(AG3=0,0,AG3/AG11) -> 1049.8237
A20: Domestic coastal shipping | B20: =IF(B4=0,0,B4/B12) -> 1778.16 | C20: =IF(C4=0,0,C4/C12) -> 1767.4068 | D20: =IF(D4=0,0,D4/D12) -> 1709.8781 | E20: =IF(E4=0,0,E4/E12) -> 1702.542 | F20: =IF(F4=0,0,F4/F12) -> 1677.5273 | G20: =IF(G4=0,0,G4/G12) -> 1671.3015 | H20: =IF(H4=0,0,H4/H12) -> 1649.2443 | I20: =IF(I4=0,0,I4/I12) -> 1685.1274 | ... AG20: =IF(AG4=0,0,AG4/AG12) -> 2179.6323
A21: Inland waterways | B21: =IF(B5=0,0,B5/B13) -> 555.12626 | C21: =IF(C5=0,0,C5/C13) -> 594.88425 | D21: =IF(D5=0,0,D5/D13) -> 604.93567 | E21: =IF(E5=0,0,E5/E13) -> 621.05404 | F21: =IF(F5=0,0,F5/F13) -> 630.30605 | G21: =IF(G5=0,0,G5/G13) -> 631.62163 | H21: =IF(H5=0,0,H5/H13) -> 629.22307 | I21: =IF(I5=0,0,I5/I13) -> 625.94419 | ... AG21: =IF(AG5=0,0,AG5/AG13) -> 766.73334
A23: Total energy consumption (ktoe) | B23: =SUM(B24,B30) -> 6114.1184 | C23: =SUM(C24,C30) -> 6133.4981 | D23: =SUM(D24,D30) -> 6186.2451 | E23: =SUM(E24,E30) -> 5970.4725 | F23: =SUM(F24,F30) -> 6038.1968 | G23: =SUM(G24,G30) -> 5860.7525 | H23: =SUM(H24,H30) -> 6334.3611 | I23: =SUM(I24,I30) -> 6177.5926 | ... AG23: =SUM(AG24,AG30) -> 5229.3101
A24: Domestic coastal shipping | B24: =SUM(B25:B29) -> 4418.2513 | C24: =SUM(C25:C29) -> 4432.0443 | D24: =SUM(D25:D29) -> 4471.8927 | E24: =SUM(E25:E29) -> 4487.062 | F24: =SUM(F25:F29) -> 4554.8249 | G24: =SUM(G25:G29) -> 4543.567 | H24: =SUM(H25:H29) -> 4978.3077 | I24: =SUM(I25:I29) -> 4721.674 | ... AG24: =SUM(AG25:AG29) -> 4251.2375
A25: Gas oil and diesel oil (excluding biofuel portion) | B25: =AT!B25+BE!B25+BG!B25+CY!B25+CZ!B25+DE!B25+DK!B25+EE!B25+EL!B25+ES!B25+FI!B25+FR!B25+HR!B25+HU!B25+IE!B25+IT!B25+LT!B25+LU!B25+LV!B25+MT!B25+NL!B25+PL!B25+PT!B25+RO!B25+SE!B25+SI!B25+SK!B25+IS!B25+NO!B25 -> 2785.5481 | C25: =AT!C25+BE!C25+BG!C25+CY!C25+CZ!C25+DE!C25+DK!C25+EE!C25+EL!C25+ES!C25+FI!C25+FR!C25+HR!C25+HU!C25+IE!C25+IT!C25+LT!C25+LU!C25+LV!C25+MT!C25+NL!C25+PL!C25+PT!C25+RO!C25+SE!C25+SI!C25+SK!C25+IS!C25+NO!C25 -> 2881.2015 | D25: =AT!D25+BE!D25+BG!D25+CY!D25+CZ!D25+DE!D25+DK!D25+EE!D25+EL!D25+ES!D25+FI!D25+FR!D25+HR!D25+HU!D25+IE!D25+IT!D25+LT!D25+LU!D25+LV!D25+MT!D25+NL!D25+PL!D25+PT!D25+RO!D25+SE!D25+SI!D25+SK!D25+IS!D25+NO!D25 -> 2968.7987 | E25: =AT!E25+BE!E25+BG!E25+CY!E25+CZ!E25+DE!E25+DK!E25+EE!E25+EL!E25+ES!E25+FI!E25+FR!E25+HR!E25+HU!E25+IE!E25+IT!E25+LT!E25+LU!E25+LV!E25+MT!E25+NL!E25+PL!E25+PT!E25+RO!E25+SE!E25+SI!E25+SK!E25+IS!E25+NO!E25 -> 3075.6433 | F25: =AT!F25+BE!F25+BG!F25+CY!F25+CZ!F25+DE!F25+DK!F25+EE!F25+EL!F25+ES!F25+FI!F25+FR!F25+HR!F25+HU!F25+IE!F25+IT!F25+LT!F25+LU!F25+LV!F25+MT!F25+NL!F25+PL!F25+PT!F25+RO!F25+SE!F25+SI!F25+SK!F25+IS!F25+NO!F25 -> 3068.799 | G25: =AT!G25+BE!G25+BG!G25+CY!G25+CZ!G25+DE!G25+DK!G25+EE!G25+EL!G25+ES!G25+FI!G25+FR!G25+HR!G25+HU!G25+IE!G25+IT!G25+LT!G25+LU!G25+LV!G25+MT!G25+NL!G25+PL!G25+PT!G25+RO!G25+SE!G25+SI!G25+SK!G25+IS!G25+NO!G25 -> 3119.3802 | H25: =AT!H25+BE!H25+BG!H25+CY!H25+CZ!H25+DE!H25+DK!H25+EE!H25+EL!H25+ES!H25+FI!H25+FR!H25+HR!H25+HU!H25+IE!H25+IT!H25+LT!H25+LU!H25+LV!H25+MT!H25+NL!H25+PL!H25+PT!H25+RO!H25+SE!H25+SI!H25+SK!H25+IS!H25+NO!H25 -> 3229.7791 | I25: =AT!I25+BE!I25+BG!I25+CY!I25+CZ!I25+DE!I25+DK!I25+EE!I25+EL!I25+ES!I25+FI!I25+FR!I25+HR!I25+HU!I25+IE!I25+IT!I25+LT!I25+LU!I25+LV!I25+MT!I25+NL!I25+PL!I25+PT!I25+RO!I25+SE!I25+SI!I25+SK!I25+IS!I25+NO!I25 -> 3048.652 | ... AG25: =AT!AG25+BE!AG25+BG!AG25+CY!AG25+CZ!AG25+DE!AG25+DK!AG25+EE!AG25+EL!AG25+ES!AG25+FI!AG25+FR!AG25+HR!AG25+HU!AG25+IE!AG25+IT!AG25+LT!AG25+LU!AG25+LV!AG25+MT!AG25+NL!AG25+PL!AG25+PT!AG25+RO!AG25+SE!AG25+SI!AG25+SK!AG25+IS!AG25+NO!AG25 -> 2720.0905
A26: Fuel oil and Other oil products | B26: =AT!B26+BE!B26+BG!B26+CY!B26+CZ!B26+DE!B26+DK!B26+EE!B26+EL!B26+ES!B26+FI!B26+FR!B26+HR!B26+HU!B26+IE!B26+IT!B26+LT!B26+LU!B26+LV!B26+MT!B26+NL!B26+PL!B26+PT!B26+RO!B26+SE!B26+SI!B26+SK!B26+IS!B26+NO!B26 -> 1632.7031 | C26: =AT!C26+BE!C26+BG!C26+CY!C26+CZ!C26+DE!C26+DK!C26+EE!C26+EL!C26+ES!C26+FI!C26+FR!C26+HR!C26+HU!C26+IE!C26+IT!C26+LT!C26+LU!C26+LV!C26+MT!C26+NL!C26+PL!C26+PT!C26+RO!C26+SE!C26+SI!C26+SK!C26+IS!C26+NO!C26 -> 1550.8428 | D26: =AT!D26+BE!D26+BG!D26+CY!D26+CZ!D26+DE!D26+DK!D26+EE!D26+EL!D26+ES!D26+FI!D26+FR!D26+HR!D26+HU!D26+IE!D26+IT!D26+LT!D26+LU!D26+LV!D26+MT!D26+NL!D26+PL!D26+PT!D26+RO!D26+SE!D26+SI!D26+SK!D26+IS!D26+NO!D26 -> 1503.094 | E26: =AT!E26+BE!E26+BG!E26+CY!E26+CZ!E26+DE!E26+DK!E26+EE!E26+EL!E26+ES!E26+FI!E26+FR!E26+HR!E26+HU!E26+IE!E26+IT!E26+LT!E26+LU!E26+LV!E26+MT!E26+NL!E26+PL!E26+PT!E26+RO!E26+SE!E26+SI!E26+SK!E26+IS!E26+NO!E26 -> 1411.4187 | F26: =AT!F26+BE!F26+BG!F26+CY!F26+CZ!F26+DE!F26+DK!F26+EE!F26+EL!F26+ES!F26+FI!F26+FR!F26+HR!F26+HU!F26+IE!F26+IT!F26+LT!F26+LU!F26+LV!F26+MT!F26+NL!F26+PL!F26+PT!F26+RO!F26+SE!F26+SI!F26+SK!F26+IS!F26+NO!F26 -> 1486.0259 | G26: =AT!G26+BE!G26+BG!G26+CY!G26+CZ!G26+DE!G26+DK!G26+EE!G26+EL!G26+ES!G26+FI!G26+FR!G26+HR!G26+HU!G26+IE!G26+IT!G26+LT!G26+LU!G26+LV!G26+MT!G26+NL!G26+PL!G26+PT!G26+RO!G26+SE!G26+SI!G26+SK!G26+IS!G26+NO!G26 -> 1424.1868 | H26: =AT!H26+BE!H26+BG!H26+CY!H26+CZ!H26+DE!H26+DK!H26+EE!H26+EL!H26+ES!H26+FI!H26+FR!H26+HR!H26+HU!H26+IE!H26+IT!H26+LT!H26+LU!H26+LV!H26+MT!H26+NL!H26+PL!H26+PT!H26+RO!H26+SE!H26+SI!H26+SK!H26+IS!H26+NO!H26 -> 1748.5286 | I26: =AT!I26+BE!I26+BG!I26+CY!I26+CZ!I26+DE!I26+DK!I26+EE!I26+EL!I26+ES!I26+FI!I26+FR!I26+HR!I26+HU!I26+IE!I26+IT!I26+LT!I26+LU!I26+LV!I26+MT!I26+NL!I26+PL!I26+PT!I26+RO!I26+SE!I26+SI!I26+SK!I26+IS!I26+NO!I26 -> 1673.022 | ... AG26: =AT!AG26+BE!AG26+BG!AG26+CY!AG26+CZ!AG26+DE!AG26+DK!AG26+EE!AG26+EL!AG26+ES!AG26+FI!AG26+FR!AG26+HR!AG26+HU!AG26+IE!AG26+IT!AG26+LT!AG26+LU!AG26+LV!AG26+MT!AG26+NL!AG26+PL!AG26+PT!AG26+RO!AG26+SE!AG26+SI!AG26+SK!AG26+IS!AG26+NO!AG26 -> 1504.7923
A27: Blended biofuels | B27: =AT!B27+BE!B27+BG!B27+CY!B27+CZ!B27+DE!B27+DK!B27+EE!B27+EL!B27+ES!B27+FI!B27+FR!B27+HR!B27+HU!B27+IE!B27+IT!B27+LT!B27+LU!B27+LV!B27+MT!B27+NL!B27+PL!B27+PT!B27+RO!B27+SE!B27+SI!B27+SK!B27+IS!B27+NO!B27 -> 0 | C27: =AT!C27+BE!C27+BG!C27+CY!C27+CZ!C27+DE!C27+DK!C27+EE!C27+EL!C27+ES!C27+FI!C27+FR!C27+HR!C27+HU!C27+IE!C27+IT!C27+LT!C27+LU!C27+LV!C27+MT!C27+NL!C27+PL!C27+PT!C27+RO!C27+SE!C27+SI!C27+SK!C27+IS!C27+NO!C27 -> 0 | D27: =AT!D27+BE!D27+BG!D27+CY!D27+CZ!D27+DE!D27+DK!D27+EE!D27+EL!D27+ES!D27+FI!D27+FR!D27+HR!D27+HU!D27+IE!D27+IT!D27+LT!D27+LU!D27+LV!D27+MT!D27+NL!D27+PL!D27+PT!D27+RO!D27+SE!D27+SI!D27+SK!D27+IS!D27+NO!D27 -> 0 | E27: =AT!E27+BE!E27+BG!E27+CY!E27+CZ!E27+DE!E27+DK!E27+EE!E27+EL!E27+ES!E27+FI!E27+FR!E27+HR!E27+HU!E27+IE!E27+IT!E27+LT!E27+LU!E27+LV!E27+MT!E27+NL!E27+PL!E27+PT!E27+RO!E27+SE!E27+SI!E27+SK!E27+IS!E27+NO!E27 -> 0 | F27: =AT!F27+BE!F27+BG!F27+CY!F27+CZ!F27+DE!F27+DK!F27+EE!F27+EL!F27+ES!F27+FI!F27+FR!F27+HR!F27+HU!F27+IE!F27+IT!F27+LT!F27+LU!F27+LV!F27+MT!F27+NL!F27+PL!F27+PT!F27+RO!F27+SE!F27+SI!F27+SK!F27+IS!F27+NO!F27 -> 0 | G27: =AT!G27+BE!G27+BG!G27+CY!G27+CZ!G27+DE!G27+DK!G27+EE!G27+EL!G27+ES!G27+FI!G27+FR!G27+HR!G27+HU!G27+IE!G27+IT!G27+LT!G27+LU!G27+LV!G27+MT!G27+NL!G27+PL!G27+PT!G27+RO!G27+SE!G27+SI!G27+SK!G27+IS!G27+NO!G27 -> 0 | H27: =AT!H27+BE!H27+BG!H27+CY!H27+CZ!H27+DE!H27+DK!H27+EE!H27+EL!H27+ES!H27+FI!H27+FR!H27+HR!H27+HU!H27+IE!H27+IT!H27+LT!H27+LU!H27+LV!H27+MT!H27+NL!H27+PL!H27+PT!H27+RO!H27+SE!H27+SI!H27+SK!H27+IS!H27+NO!H27 -> 0 | I27: =AT!I27+BE!I27+BG!I27+CY!I27+CZ!I27+DE!I27+DK!I27+EE!I27+EL!I27+ES!I27+FI!I27+FR!I27+HR!I27+HU!I27+IE!I27+IT!I27+LT!I27+LU!I27+LV!I27+MT!I27+NL!I27+PL!I27+PT!I27+RO!I27+SE!I27+SI!I27+SK!I27+IS!I27+NO!I27 -> 0 | ... AG27: =AT!AG27+BE!AG27+BG!AG27+CY!AG27+CZ!AG27+DE!AG27+DK!AG27+EE!AG27+EL!AG27+ES!AG27+FI!AG27+FR!AG27+HR!AG27+HU!AG27+IE!AG27+IT!AG27+LT!AG27+LU!AG27+LV!AG27+MT!AG27+NL!AG27+PL!AG27+PT!AG27+RO!AG27+SE!AG27+SI!AG27+SK!AG27+IS!AG27+NO!AG27 -> 26.354723
A28: Natural gas | B28: =AT!B28+BE!B28+BG!B28+CY!B28+CZ!B28+DE!B28+DK!B28+EE!B28+EL!B28+ES!B28+FI!B28+FR!B28+HR!B28+HU!B28+IE!B28+IT!B28+LT!B28+LU!B28+LV!B28+MT!B28+NL!B28+PL!B28+PT!B28+RO!B28+SE!B28+SI!B28+SK!B28+IS!B28+NO!B28 -> 0 | C28: =AT!C28+BE!C28+BG!C28+CY!C28+CZ!C28+DE!C28+DK!C28+EE!C28+EL!C28+ES!C28+FI!C28+FR!C28+HR!C28+HU!C28+IE!C28+IT!C28+LT!C28+LU!C28+LV!C28+MT!C28+NL!C28+PL!C28+PT!C28+RO!C28+SE!C28+SI!C28+SK!C28+IS!C28+NO!C28 -> 0 | D28: =AT!D28+BE!D28+BG!D28+CY!D28+CZ!D28+DE!D28+DK!D28+EE!D28+EL!D28+ES!D28+FI!D28+FR!D28+HR!D28+HU!D28+IE!D28+IT!D28+LT!D28+LU!D28+LV!D28+MT!D28+NL!D28+PL!D28+PT!D28+RO!D28+SE!D28+SI!D28+SK!D28+IS!D28+NO!D28 -> 0 | E28: =AT!E28+BE!E28+BG!E28+CY!E28+CZ!E28+DE!E28+DK!E28+EE!E28+EL!E28+ES!E28+FI!E28+FR!E28+HR!E28+HU!E28+IE!E28+IT!E28+LT!E28+LU!E28+LV!E28+MT!E28+NL!E28+PL!E28+PT!E28+RO!E28+SE!E28+SI!E28+SK!E28+IS!E28+NO!E28 -> 0 | F28: =AT!F28+BE!F28+BG!F28+CY!F28+CZ!F28+DE!F28+DK!F28+EE!F28+EL!F28+ES!F28+FI!F28+FR!F28+HR!F28+HU!F28+IE!F28+IT!F28+LT!F28+LU!F28+LV!F28+MT!F28+NL!F28+PL!F28+PT!F28+RO!F28+SE!F28+SI!F28+SK!F28+IS!F28+NO!F28 -> 0 | G28: =AT!G28+BE!G28+BG!G28+CY!G28+CZ!G28+DE!G28+DK!G28+EE!G28+EL!G28+ES!G28+FI!G28+FR!G28+HR!G28+HU!G28+IE!G28+IT!G28+LT!G28+LU!G28+LV!G28+MT!G28+NL!G28+PL!G28+PT!G28+RO!G28+SE!G28+SI!G28+SK!G28+IS!G28+NO!G28 -> 0 | H28: =AT!H28+BE!H28+BG!H28+CY!H28+CZ!H28+DE!H28+DK!H28+EE!H28+EL!H28+ES!H28+FI!H28+FR!H28+HR!H28+HU!H28+IE!H28+IT!H28+LT!H28+LU!H28+LV!H28+MT!H28+NL!H28+PL!H28+PT!H28+RO!H28+SE!H28+SI!H28+SK!H28+IS!H28+NO!H28 -> 0 | I28: =AT!I28+BE!I28+BG!I28+CY!I28+CZ!I28+DE!I28+DK!I28+EE!I28+EL!I28+ES!I28+FI!I28+FR!I28+HR!I28+HU!I28+IE!I28+IT!I28+LT!I28+LU!I28+LV!I28+MT!I28+NL!I28+PL!I28+PT!I28+RO!I28+SE!I28+SI!I28+SK!I28+IS!I28+NO!I28 -> 0 | ... AG28: =AT!AG28+BE!AG28+BG!AG28+CY!AG28+CZ!AG28+DE!AG28+DK!AG28+EE!AG28+EL!AG28+ES!AG28+FI!AG28+FR!AG28+HR!AG28+HU!AG28+IE!AG28+IT!AG28+LT!AG28+LU!AG28+LV!AG28+MT!AG28+NL!AG28+PL!AG28+PT!AG28+RO!AG28+SE!AG28+SI!AG28+SK!AG28+IS!AG28+NO!AG28 -> 0
A29: Biogases | B29: =AT!B29+BE!B29+BG!B29+CY!B29+CZ!B29+DE!B29+DK!B29+EE!B29+EL!B29+ES!B29+FI!B29+FR!B29+HR!B29+HU!B29+IE!B29+IT!B29+LT!B29+LU!B29+LV!B29+MT!B29+NL!B29+PL!B29+PT!B29+RO!B29+SE!B29+SI!B29+SK!B29+IS!B29+NO!B29 -> 0 | C29: =AT!C29+BE!C29+BG!C29+CY!C29+CZ!C29+DE!C29+DK!C29+EE!C29+EL!C29+ES!C29+FI!C29+FR!C29+HR!C29+HU!C29+IE!C29+IT!C29+LT!C29+LU!C29+LV!C29+MT!C29+NL!C29+PL!C29+PT!C29+RO!C29+SE!C29+SI!C29+SK!C29+IS!C29+NO!C29 -> 0 | D29: =AT!D29+BE!D29+BG!D29+CY!D29+CZ!D29+DE!D29+DK!D29+EE!D29+EL!D29+ES!D29+FI!D29+FR!D29+HR!D29+HU!D29+IE!D29+IT!D29+LT!D29+LU!D29+LV!D29+MT!D29+NL!D29+PL!D29+PT!D29+RO!D29+SE!D29+SI!D29+SK!D29+IS!D29+NO!D29 -> 0 | E29: =AT!E29+BE!E29+BG!E29+CY!E29+CZ!E29+DE!E29+DK!E29+EE!E29+EL!E29+ES!E29+FI!E29+FR!E29+HR!E29+HU!E29+IE!E29+IT!E29+LT!E29+LU!E29+LV!E29+MT!E29+NL!E29+PL!E29+PT!E29+RO!E29+SE!E29+SI!E29+SK!E29+IS!E29+NO!E29 -> 0 | F29: =AT!F29+BE!F29+BG!F29+CY!F29+CZ!F29+DE!F29+DK!F29+EE!F29+EL!F29+ES!F29+FI!F29+FR!F29+HR!F29+HU!F29+IE!F29+IT!F29+LT!F29+LU!F29+LV!F29+MT!F29+NL!F29+PL!F29+PT!F29+RO!F29+SE!F29+SI!F29+SK!F29+IS!F29+NO!F29 -> 0 | G29: =AT!G29+BE!G29+BG!G29+CY!G29+CZ!G29+DE!G29+DK!G29+EE!G29+EL!G29+ES!G29+FI!G29+FR!G29+HR!G29+HU!G29+IE!G29+IT!G29+LT!G29+LU!G29+LV!G29+MT!G29+NL!G29+PL!G29+PT!G29+RO!G29+SE!G29+SI!G29+SK!G29+IS!G29+NO!G29 -> 0 | H29: =AT!H29+BE!H29+BG!H29+CY!H29+CZ!H29+DE!H29+DK!H29+EE!H29+EL!H29+ES!H29+FI!H29+FR!H29+HR!H29+HU!H29+IE!H29+IT!H29+LT!H29+LU!H29+LV!H29+MT!H29+NL!H29+PL!H29+PT!H29+RO!H29+SE!H29+SI!H29+SK!H29+IS!H29+NO!H29 -> 0 | I29: =AT!I29+BE!I29+BG!I29+CY!I29+CZ!I29+DE!I29+DK!I29+EE!I29+EL!I29+ES!I29+FI!I29+FR!I29+HR!I29+HU!I29+IE!I29+IT!I29+LT!I29+LU!I29+LV!I29+MT!I29+NL!I29+PL!I29+PT!I29+RO!I29+SE!I29+SI!I29+SK!I29+IS!I29+NO!I29 -> 0 | ... AG29: =AT!AG29+BE!AG29+BG!AG29+CY!AG29+CZ!AG29+DE!AG29+DK!AG29+EE!AG29+EL!AG29+ES!AG29+FI!AG29+FR!AG29+HR!AG29+HU!AG29+IE!AG29+IT!AG29+LT!AG29+LU!AG29+LV!AG29+MT!AG29+NL!AG29+PL!AG29+PT!AG29+RO!AG29+SE!AG29+SI!AG29+SK!AG29+IS!AG29+NO!AG29 -> 0
A30: Inland waterways | B30: =SUM(B31:B35) -> 1695.8671 | C30: =SUM(C31:C35) -> 1701.4538 | D30: =SUM(D31:D35) -> 1714.3524 | E30: =SUM(E31:E35) -> 1483.4105 | F30: =SUM(F31:F35) -> 1483.3719 | G30: =SUM(G31:G35) -> 1317.1855 | H30: =SUM(H31:H35) -> 1356.0534 | I30: =SUM(I31:I35) -> 1455.9186 | ... AG30: =SUM(AG31:AG35) -> 978.07263
A31: Gas oil and diesel oil (excluding biofuel portion) | B31: =AT!B31+BE!B31+BG!B31+CY!B31+CZ!B31+DE!B31+DK!B31+EE!B31+EL!B31+ES!B31+FI!B31+FR!B31+HR!B31+HU!B31+IE!B31+IT!B31+LT!B31+LU!B31+LV!B31+MT!B31+NL!B31+PL!B31+PT!B31+RO!B31+SE!B31+SI!B31+SK!B31+IS!B31+NO!B31 -> 1127.2051 | C31: =AT!C31+BE!C31+BG!C31+CY!C31+CZ!C31+DE!C31+DK!C31+EE!C31+EL!C31+ES!C31+FI!C31+FR!C31+HR!C31+HU!C31+IE!C31+IT!C31+LT!C31+LU!C31+LV!C31+MT!C31+NL!C31+PL!C31+PT!C31+RO!C31+SE!C31+SI!C31+SK!C31+IS!C31+NO!C31 -> 1116.6358 | D31: =AT!D31+BE!D31+BG!D31+CY!D31+CZ!D31+DE!D31+DK!D31+EE!D31+EL!D31+ES!D31+FI!D31+FR!D31+HR!D31+HU!D31+IE!D31+IT!D31+LT!D31+LU!D31+LV!D31+MT!D31+NL!D31+PL!D31+PT!D31+RO!D31+SE!D31+SI!D31+SK!D31+IS!D31+NO!D31 -> 1280.1286 | E31: =AT!E31+BE!E31+BG!E31+CY!E31+CZ!E31+DE!E31+DK!E31+EE!E31+EL!E31+ES!E31+FI!E31+FR!E31+HR!E31+HU!E31+IE!E31+IT!E31+LT!E31+LU!E31+LV!E31+MT!E31+NL!E31+PL!E31+PT!E31+RO!E31+SE!E31+SI!E31+SK!E31+IS!E31+NO!E31 -> 1219.9289 | F31: =AT!F31+BE!F31+BG!F31+CY!F31+CZ!F31+DE!F31+DK!F31+EE!F31+EL!F31+ES!F31+FI!F31+FR!F31+HR!F31+HU!F31+IE!F31+IT!F31+LT!F31+LU!F31+LV!F31+MT!F31+NL!F31+PL!F31+PT!F31+RO!F31+SE!F31+SI!F31+SK!F31+IS!F31+NO!F31 -> 1191.1307 | G31: =AT!G31+BE!G31+BG!G31+CY!G31+CZ!G31+DE!G31+DK!G31+EE!G31+EL!G31+ES!G31+FI!G31+FR!G31+HR!G31+HU!G31+IE!G31+IT!G31+LT!G31+LU!G31+LV!G31+MT!G31+NL!G31+PL!G31+PT!G31+RO!G31+SE!G31+SI!G31+SK!G31+IS!G31+NO!G31 -> 1031.2601 | H31: =AT!H31+BE!H31+BG!H31+CY!H31+CZ!H31+DE!H31+DK!H31+EE!H31+EL!H31+ES!H31+FI!H31+FR!H31+HR!H31+HU!H31+IE!H31+IT!H31+LT!H31+LU!H31+LV!H31+MT!H31+NL!H31+PL!H31+PT!H31+RO!H31+SE!H31+SI!H31+SK!H31+IS!H31+NO!H31 -> 1017.5952 | I31: =AT!I31+BE!I31+BG!I31+CY!I31+CZ!I31+DE!I31+DK!I31+EE!I31+EL!I31+ES!I31+FI!I31+FR!I31+HR!I31+HU!I31+IE!I31+IT!I31+LT!I31+LU!I31+LV!I31+MT!I31+NL!I31+PL!I31+PT!I31+RO!I31+SE!I31+SI!I31+SK!I31+IS!I31+NO!I31 -> 960.71738 | ... AG31: =AT!AG31+BE!AG31+BG!AG31+CY!AG31+CZ!AG31+DE!AG31+DK!AG31+EE!AG31+EL!AG31+ES!AG31+FI!AG31+FR!AG31+HR!AG31+HU!AG31+IE!AG31+IT!AG31+LT!AG31+LU!AG31+LV!AG31+MT!AG31+NL!AG31+PL!AG31+PT!AG31+RO!AG31+SE!AG31+SI!AG31+SK!AG31+IS!AG31+NO!AG31 -> 900.36166
A32: Fuel oil and Other oil products | B32: =AT!B32+BE!B32+BG!B32+CY!B32+CZ!B32+DE!B32+DK!B32+EE!B32+EL!B32+ES!B32+FI!B32+FR!B32+HR!B32+HU!B32+IE!B32+IT!B32+LT!B32+LU!B32+LV!B32+MT!B32+NL!B32+PL!B32+PT!B32+RO!B32+SE!B32+SI!B32+SK!B32+IS!B32+NO!B32 -> 568.66205 | C32: =AT!C32+BE!C32+BG!C32+CY!C32+CZ!C32+DE!C32+DK!C32+EE!C32+EL!C32+ES!C32+FI!C32+FR!C32+HR!C32+HU!C32+IE!C32+IT!C32+LT!C32+LU!C32+LV!C32+MT!C32+NL!C32+PL!C32+PT!C32+RO!C32+SE!C32+SI!C32+SK!C32+IS!C32+NO!C32 -> 584.818 | D32: =AT!D32+BE!D32+BG!D32+CY!D32+CZ!D32+DE!D32+DK!D32+EE!D32+EL!D32+ES!D32+FI!D32+FR!D32+HR!D32+HU!D32+IE!D32+IT!D32+LT!D32+LU!D32+LV!D32+MT!D32+NL!D32+PL!D32+PT!D32+RO!D32+SE!D32+SI!D32+SK!D32+IS!D32+NO!D32 -> 434.22384 | E32: =AT!E32+BE!E32+BG!E32+CY!E32+CZ!E32+DE!E32+DK!E32+EE!E32+EL!E32+ES!E32+FI!E32+FR!E32+HR!E32+HU!E32+IE!E32+IT!E32+LT!E32+LU!E32+LV!E32+MT!E32+NL!E32+PL!E32+PT!E32+RO!E32+SE!E32+SI!E32+SK!E32+IS!E32+NO!E32 -> 263.48159 | F32: =AT!F32+BE!F32+BG!F32+CY!F32+CZ!F32+DE!F32+DK!F32+EE!F32+EL!F32+ES!F32+FI!F32+FR!F32+HR!F32+HU!F32+IE!F32+IT!F32+LT!F32+LU!F32+LV!F32+MT!F32+NL!F32+PL!F32+PT!F32+RO!F32+SE!F32+SI!F32+SK!F32+IS!F32+NO!F32 -> 292.24125 | G32: =AT!G32+BE!G32+BG!G32+CY!G32+CZ!G32+DE!G32+DK!G32+EE!G32+EL!G32+ES!G32+FI!G32+FR!G32+HR!G32+HU!G32+IE!G32+IT!G32+LT!G32+LU!G32+LV!G32+MT!G32+NL!G32+PL!G32+PT!G32+RO!G32+SE!G32+SI!G32+SK!G32+IS!G32+NO!G32 -> 285.92546 | H32: =AT!H32+BE!H32+BG!H32+CY!H32+CZ!H32+DE!H32+DK!H32+EE!H32+EL!H32+ES!H32+FI!H32+FR!H32+HR!H32+HU!H32+IE!H32+IT!H32+LT!H32+LU!H32+LV!H32+MT!H32+NL!H32+PL!H32+PT!H32+RO!H32+SE!H32+SI!H32+SK!H32+IS!H32+NO!H32 -> 338.4582 | I32: =AT!I32+BE!I32+BG!I32+CY!I32+CZ!I32+DE!I32+DK!I32+EE!I32+EL!I32+ES!I32+FI!I32+FR!I32+HR!I32+HU!I32+IE!I32+IT!I32+LT!I32+LU!I32+LV!I32+MT!I32+NL!I32+PL!I32+PT!I32+RO!I32+SE!I32+SI!I32+SK!I32+IS!I32+NO!I32 -> 495.20126 | ... AG32: =AT!AG32+BE!AG32+BG!AG32+CY!AG32+CZ!AG32+DE!AG32+DK!AG32+EE!AG32+EL!AG32+ES!AG32+FI!AG32+FR!AG32+HR!AG32+HU!AG32+IE!AG32+IT!AG32+LT!AG32+LU!AG32+LV!AG32+MT!AG32+NL!AG32+PL!AG32+PT!AG32+RO!AG32+SE!AG32+SI!AG32+SK!AG32+IS!AG32+NO!AG32 -> 74.903873
A33: Blended biofuels | B33: =AT!B33+BE!B33+BG!B33+CY!B33+CZ!B33+DE!B33+DK!B33+EE!B33+EL!B33+ES!B33+FI!B33+FR!B33+HR!B33+HU!B33+IE!B33+IT!B33+LT!B33+LU!B33+LV!B33+MT!B33+NL!B33+PL!B33+PT!B33+RO!B33+SE!B33+SI!B33+SK!B33+IS!B33+NO!B33 -> 0 | C33: =AT!C33+BE!C33+BG!C33+CY!C33+CZ!C33+DE!C33+DK!C33+EE!C33+EL!C33+ES!C33+FI!C33+FR!C33+HR!C33+HU!C33+IE!C33+IT!C33+LT!C33+LU!C33+LV!C33+MT!C33+NL!C33+PL!C33+PT!C33+RO!C33+SE!C33+SI!C33+SK!C33+IS!C33+NO!C33 -> 0 | D33: =AT!D33+BE!D33+BG!D33+CY!D33+CZ!D33+DE!D33+DK!D33+EE!D33+EL!D33+ES!D33+FI!D33+FR!D33+HR!D33+HU!D33+IE!D33+IT!D33+LT!D33+LU!D33+LV!D33+MT!D33+NL!D33+PL!D33+PT!D33+RO!D33+SE!D33+SI!D33+SK!D33+IS!D33+NO!D33 -> 0 | E33: =AT!E33+BE!E33+BG!E33+CY!E33+CZ!E33+DE!E33+DK!E33+EE!E33+EL!E33+ES!E33+FI!E33+FR!E33+HR!E33+HU!E33+IE!E33+IT!E33+LT!E33+LU!E33+LV!E33+MT!E33+NL!E33+PL!E33+PT!E33+RO!E33+SE!E33+SI!E33+SK!E33+IS!E33+NO!E33 -> 0 | F33: =AT!F33+BE!F33+BG!F33+CY!F33+CZ!F33+DE!F33+DK!F33+EE!F33+EL!F33+ES!F33+FI!F33+FR!F33+HR!F33+HU!F33+IE!F33+IT!F33+LT!F33+LU!F33+LV!F33+MT!F33+NL!F33+PL!F33+PT!F33+RO!F33+SE!F33+SI!F33+SK!F33+IS!F33+NO!F33 -> 0 | G33: =AT!G33+BE!G33+BG!G33+CY!G33+CZ!G33+DE!G33+DK!G33+EE!G33+EL!G33+ES!G33+FI!G33+FR!G33+HR!G33+HU!G33+IE!G33+IT!G33+LT!G33+LU!G33+LV!G33+MT!G33+NL!G33+PL!G33+PT!G33+RO!G33+SE!G33+SI!G33+SK!G33+IS!G33+NO!G33 -> 0 | H33: =AT!H33+BE!H33+BG!H33+CY!H33+CZ!H33+DE!H33+DK!H33+EE!H33+EL!H33+ES!H33+FI!H33+FR!H33+HR!H33+HU!H33+IE!H33+IT!H33+LT!H33+LU!H33+LV!H33+MT!H33+NL!H33+PL!H33+PT!H33+RO!H33+SE!H33+SI!H33+SK!H33+IS!H33+NO!H33 -> 0 | I33: =AT!I33+BE!I33+BG!I33+CY!I33+CZ!I33+DE!I33+DK!I33+EE!I33+EL!I33+ES!I33+FI!I33+FR!I33+HR!I33+HU!I33+IE!I33+IT!I33+LT!I33+LU!I33+LV!I33+MT!I33+NL!I33+PL!I33+PT!I33+RO!I33+SE!I33+SI!I33+SK!I33+IS!I33+NO!I33 -> 0 | ... AG33: =AT!AG33+BE!AG33+BG!AG33+CY!AG33+CZ!AG33+DE!AG33+DK!AG33+EE!AG33+EL!AG33+ES!AG33+FI!AG33+FR!AG33+HR!AG33+HU!AG33+IE!AG33+IT!AG33+LT!AG33+LU!AG33+LV!AG33+MT!AG33+NL!AG33+PL!AG33+PT!AG33+RO!AG33+SE!AG33+SI!AG33+SK!AG33+IS!AG33+NO!AG33 -> 2.8071001
A34: Natural gas | B34: =AT!B34+BE!B34+BG!B34+CY!B34+CZ!B34+DE!B34+DK!B34+EE!B34+EL!B34+ES!B34+FI!B34+FR!B34+HR!B34+HU!B34+IE!B34+IT!B34+LT!B34+LU!B34+LV!B34+MT!B34+NL!B34+PL!B34+PT!B34+RO!B34+SE!B34+SI!B34+SK!B34+IS!B34+NO!B34 -> 0 | C34: =AT!C34+BE!C34+BG!C34+CY!C34+CZ!C34+DE!C34+DK!C34+EE!C34+EL!C34+ES!C34+FI!C34+FR!C34+HR!C34+HU!C34+IE!C34+IT!C34+LT!C34+LU!C34+LV!C34+MT!C34+NL!C34+PL!C34+PT!C34+RO!C34+SE!C34+SI!C34+SK!C34+IS!C34+NO!C34 -> 0 | D34: =AT!D34+BE!D34+BG!D34+CY!D34+CZ!D34+DE!D34+DK!D34+EE!D34+EL!D34+ES!D34+FI!D34+FR!D34+HR!D34+HU!D34+IE!D34+IT!D34+LT!D34+LU!D34+LV!D34+MT!D34+NL!D34+PL!D34+PT!D34+RO!D34+SE!D34+SI!D34+SK!D34+IS!D34+NO!D34 -> 0 | E34: =AT!E34+BE!E34+BG!E34+CY!E34+CZ!E34+DE!E34+DK!E34+EE!E34+EL!E34+ES!E34+FI!E34+FR!E34+HR!E34+HU!E34+IE!E34+IT!E34+LT!E34+LU!E34+LV!E34+MT!E34+NL!E34+PL!E34+PT!E34+RO!E34+SE!E34+SI!E34+SK!E34+IS!E34+NO!E34 -> 0 | F34: =AT!F34+BE!F34+BG!F34+CY!F34+CZ!F34+DE!F34+DK!F34+EE!F34+EL!F34+ES!F34+FI!F34+FR!F34+HR!F34+HU!F34+IE!F34+IT!F34+LT!F34+LU!F34+LV!F34+MT!F34+NL!F34+PL!F34+PT!F34+RO!F34+SE!F34+SI!F34+SK!F34+IS!F34+NO!F34 -> 0 | G34: =AT!G34+BE!G34+BG!G34+CY!G34+CZ!G34+DE!G34+DK!G34+EE!G34+EL!G34+ES!G34+FI!G34+FR!G34+HR!G34+HU!G34+IE!G34+IT!G34+LT!G34+LU!G34+LV!G34+MT!G34+NL!G34+PL!G34+PT!G34+RO!G34+SE!G34+SI!G34+SK!G34+IS!G34+NO!G34 -> 0 | H34: =AT!H34+BE!H34+BG!H34+CY!H34+CZ!H34+DE!H34+DK!H34+EE!H34+EL!H34+ES!H34+FI!H34+FR!H34+HR!H34+HU!H34+IE!H34+IT!H34+LT!H34+LU!H34+LV!H34+MT!H34+NL!H34+PL!H34+PT!H34+RO!H34+SE!H34+SI!H34+SK!H34+IS!H34+NO!H34 -> 0 | I34: =AT!I34+BE!I34+BG!I34+CY!I34+CZ!I34+DE!I34+DK!I34+EE!I34+EL!I34+ES!I34+FI!I34+FR!I34+HR!I34+HU!I34+IE!I34+IT!I34+LT!I34+LU!I34+LV!I34+MT!I34+NL!I34+PL!I34+PT!I34+RO!I34+SE!I34+SI!I34+SK!I34+IS!I34+NO!I34 -> 0 | ... AG34: =AT!AG34+BE!AG34+BG!AG34+CY!AG34+CZ!AG34+DE!AG34+DK!AG34+EE!AG34+EL!AG34+ES!AG34+FI!AG34+FR!AG34+HR!AG34+HU!AG34+IE!AG34+IT!AG34+LT!AG34+LU!AG34+LV!AG34+MT!AG34+NL!AG34+PL!AG34+PT!AG34+RO!AG34+SE!AG34+SI!AG34+SK!AG34+IS!AG34+NO!AG34 -> 0
A35: Biogases | B35: =AT!B35+BE!B35+BG!B35+CY!B35+CZ!B35+DE!B35+DK!B35+EE!B35+EL!B35+ES!B35+FI!B35+FR!B35+HR!B35+HU!B35+IE!B35+IT!B35+LT!B35+LU!B35+LV!B35+MT!B35+NL!B35+PL!B35+PT!B35+RO!B35+SE!B35+SI!B35+SK!B35+IS!B35+NO!B35 -> 0 | C35: =AT!C35+BE!C35+BG!C35+CY!C35+CZ!C35+DE!C35+DK!C35+EE!C35+EL!C35+ES!C35+FI!C35+FR!C35+HR!C35+HU!C35+IE!C35+IT!C35+LT!C35+LU!C35+LV!C35+MT!C35+NL!C35+PL!C35+PT!C35+RO!C35+SE!C35+SI!C35+SK!C35+IS!C35+NO!C35 -> 0 | D35: =AT!D35+BE!D35+BG!D35+CY!D35+CZ!D35+DE!D35+DK!D35+EE!D35+EL!D35+ES!D35+FI!D35+FR!D35+HR!D35+HU!D35+IE!D35+IT!D35+LT!D35+LU!D35+LV!D35+MT!D35+NL!D35+PL!D35+PT!D35+RO!D35+SE!D35+SI!D35+SK!D35+IS!D35+NO!D35 -> 0 | E35: =AT!E35+BE!E35+BG!E35+CY!E35+CZ!E35+DE!E35+DK!E35+EE!E35+EL!E35+ES!E35+FI!E35+FR!E35+HR!E35+HU!E35+IE!E35+IT!E35+LT!E35+LU!E35+LV!E35+MT!E35+NL!E35+PL!E35+PT!E35+RO!E35+SE!E35+SI!E35+SK!E35+IS!E35+NO!E35 -> 0 | F35: =AT!F35+BE!F35+BG!F35+CY!F35+CZ!F35+DE!F35+DK!F35+EE!F35+EL!F35+ES!F35+FI!F35+FR!F35+HR!F35+HU!F35+IE!F35+IT!F35+LT!F35+LU!F35+LV!F35+MT!F35+NL!F35+PL!F35+PT!F35+RO!F35+SE!F35+SI!F35+SK!F35+IS!F35+NO!F35 -> 0 | G35: =AT!G35+BE!G35+BG!G35+CY!G35+CZ!G35+DE!G35+DK!G35+EE!G35+EL!G35+ES!G35+FI!G35+FR!G35+HR!G35+HU!G35+IE!G35+IT!G35+LT!G35+LU!G35+LV!G35+MT!G35+NL!G35+PL!G35+PT!G35+RO!G35+SE!G35+SI!G35+SK!G35+IS!G35+NO!G35 -> 0 | H35: =AT!H35+BE!H35+BG!H35+CY!H35+CZ!H35+DE!H35+DK!H35+EE!H35+EL!H35+ES!H35+FI!H35+FR!H35+HR!H35+HU!H35+IE!H35+IT!H35+LT!H35+LU!H35+LV!H35+MT!H35+NL!H35+PL!H35+PT!H35+RO!H35+SE!H35+SI!H35+SK!H35+IS!H35+NO!H35 -> 0 | I35: =AT!I35+BE!I35+BG!I35+CY!I35+CZ!I35+DE!I35+DK!I35+EE!I35+EL!I35+ES!I35+FI!I35+FR!I35+HR!I35+HU!I35+IE!I35+IT!I35+LT!I35+LU!I35+LV!I35+MT!I35+NL!I35+PL!I35+PT!I35+RO!I35+SE!I35+SI!I35+SK!I35+IS!I35+NO!I35 -> 0 | ... AG35: =AT!AG35+BE!AG35+BG!AG35+CY!AG35+CZ!AG35+DE!AG35+DK!AG35+EE!AG35+EL!AG35+ES!AG35+FI!AG35+FR!AG35+HR!AG35+HU!AG35+IE!AG35+IT!AG35+LT!AG35+LU!AG35+LV!AG35+MT!AG35+NL!AG35+PL!AG35+PT!AG35+RO!AG35+SE!AG35+SI!AG35+SK!AG35+IS!AG35+NO!AG35 -> 0
A36: * As reported in the Eurostat energy balances
A38: Energy intensity over activity (kgoe / 000 tkm) | B38: =IF(B23=0,0,B23/(B3/1000)) -> 25.82825 | C38: =IF(C23=0,0,C23/(C3/1000)) -> 27.203523 | D38: =IF(D23=0,0,D23/(D3/1000)) -> 29.977901 | E38: =IF(E23=0,0,E23/(E3/1000)) -> 28.846448 | F38: =IF(F23=0,0,F23/(F3/1000)) -> 28.392091 | G38: =IF(G23=0,0,G23/(G3/1000)) -> 27.202405 | H38: =IF(H23=0,0,H23/(H3/1000)) -> 30.49652 | I38: =IF(I23=0,0,I23/(I3/1000)) -> 26.663255 | ... AG38: =IF(AG23=0,0,AG23/(AG3/1000)) -> 22.443192
A39: Domestic coastal shipping | B39: =IF(B24=0,0,B24/(B4/1000)) -> 35.798415 | C39: =IF(C24=0,0,C24/(C4/1000)) -> 39.168013 | D39: =IF(D24=0,0,D24/(D4/1000)) -> 47.192761 | E39: =IF(E24=0,0,E24/(E4/1000)) -> 45.613586 | F39: =IF(F24=0,0,F24/(F4/1000)) -> 47.706256 | G39: =IF(G24=0,0,G24/(G4/1000)) -> 47.520149 | H39: =IF(H24=0,0,H24/(H4/1000)) -> 55.140178 | I39: =IF(I24=0,0,I24/(I4/1000)) -> 44.609521 | ... AG39: =IF(AG24=0,0,AG24/(AG4/1000)) -> 43.86062
A40: Inland waterways | B40: =IF(B30=0,0,B30/(B5/1000)) -> 14.967695 | C40: =IF(C30=0,0,C30/(C5/1000)) -> 15.149301 | D40: =IF(D30=0,0,D30/(D5/1000)) -> 15.361283 | E40: =IF(E30=0,0,E30/(E5/1000)) -> 13.659007 | F40: =IF(F30=0,0,F30/(F5/1000)) -> 12.657262 | G40: =IF(G30=0,0,G30/(G5/1000)) -> 10.99154 | H40: =IF(H30=0,0,H30/(H5/1000)) -> 11.548439 | I40: =IF(I30=0,0,I30/(I5/1000)) -> 11.569158 | ... AG40: =IF(AG30=0,0,AG30/(AG5/1000)) -> 7.1876939
A42: Shares of total energy consumption (%) | B42: =IF(B23=0,0,B23/B$23) -> 1 | C42: =IF(C23=0,0,C23/C$23) -> 1 | D42: =IF(D23=0,0,D23/D$23) -> 1 | E42: =IF(E23=0,0,E23/E$23) -> 1 | F42: =IF(F23=0,0,F23/F$23) -> 1 | G42: =IF(G23=0,0,G23/G$23) -> 1 | H42: =IF(H23=0,0,H23/H$23) -> 1 | I42: =IF(I23=0,0,I23/I$23) -> 1 | ... AG42: =IF(AG23=0,0,AG23/AG$23) -> 1
A43: Domestic coastal shipping | B43: =IF(B24=0,0,B24/B$23) -> 0.72263096 | C43: =IF(C24=0,0,C24/C$23) -> 0.72259651 | D43: =IF(D24=0,0,D24/D$23) -> 0.72287674 | E43: =IF(E24=0,0,E24/E$23) -> 0.75154219 | F43: =IF(F24=0,0,F24/F$23) -> 0.75433528 | G43: =IF(G24=0,0,G24/G$23) -> 0.77525318 | H43: =IF(H24=0,0,H24/H$23) -> 0.78592105 | I43: =IF(I24=0,0,I24/I$23) -> 0.76432265 | ... AG43: =IF(AG24=0,0,AG24/AG$23) -> 0.81296335
A44: Inland waterways | B44: =IF(B30=0,0,B30/B$23) -> 0.27736904 | C44: =IF(C30=0,0,C30/C$23) -> 0.27740349 | D44: =IF(D30=0,0,D30/D$23) -> 0.27712326 | E44: =IF(E30=0,0,E30/E$23) -> 0.24845781 | F44: =IF(F30=0,0,F30/F$23) -> 0.24566472 | G44: =IF(G30=0,0,G30/G$23) -> 0.22474682 | H44: =IF(H30=0,0,H30/H$23) -> 0.21407895 | I44: =IF(I30=0,0,I30/I$23) -> 0.23567735 | ... AG44: =IF(AG30=0,0,AG30/AG$23) -> 0.18703665
A46: Vehicle-efficiency - effective (kgoe/100 km) | B46: =IF(B23=0,0,100*B23/B11) -> 2235.4277 | C46: =IF(C23=0,0,100*C23/C11) -> 2426.0336 | D46: =IF(D23=0,0,100*D23/D11) -> 2578.6336 | E46: =IF(E23=0,0,100*E23/E11) -> 2566.3115 | F46: =IF(F23=0,0,100*F23/F11) -> 2486.3997 | G46: =IF(G23=0,0,100*G23/G11) -> 2373.3797 | H46: =IF(H23=0,0,100*H23/H11) -> 2624.4562 | I46: =IF(I23=0,0,100*I23/I11) -> 2341.2476 | ... AG46: =IF(AG23=0,0,100*AG23/AG11) -> 2356.1394
A47: Domestic coastal shipping | B47: =IF(B24=0,0,100*B24/B12) -> 6365.5308 | C47: =IF(C24=0,0,100*C24/C12) -> 6922.5814 | D47: =IF(D24=0,0,100*D24/D12) -> 8069.3867 | E47: =IF(E24=0,0,100*E24/E12) -> 7765.9045 | F47: =IF(F24=0,0,100*F24/F12) -> 8002.8549 | G47: =IF(G24=0,0,100*G24/G12) -> 7942.0494 | H47: =IF(H24=0,0,100*H24/H12) -> 9093.9622 | I47: =IF(I24=0,0,100*I24/I12) -> 7517.2724 | ... AG47: =IF(AG24=0,0,100*AG24/AG12) -> 9560.0025
A48: Inland waterways | B48: =IF(B30=0,0,100*B30/B13) -> 830.89605 | C48: =IF(C30=0,0,100*C30/C13) -> 901.20807 | D48: =IF(D30=0,0,100*D30/D13) -> 929.25881 | E48: =IF(E30=0,0,100*E30/E13) -> 848.29817 | F48: =IF(F30=0,0,100*F30/F13) -> 797.79488 | G48: =IF(G30=0,0,100*G30/G13) -> 694.24941 | H48: =IF(H30=0,0,100*H30/H13) -> 726.65442 | I48: =IF(I30=0,0,100*I30/I13) -> 724.1647 | ... AG48: =IF(AG30=0,0,100*AG30/AG13) -> 551.10445
A49: * Based on the energy consumption figures reported in the Eurostat energy balances
...

Sheet EU27
A1: EU27 - European Union - 27 countries (from 2020) | B1: 1990 | C1: 1991 | D1: 1992 | E1: 1993 | F1: 1994 | G1: 1995 | H1: 1996 | I1: 1997 | J1: 1998 | K1: 1999 | L1: 2000 | M1: 2001 | N1: 2002 | O1: 2003 | P1: 2004 | Q1: 2005 | R1: 2006 | S1: 2007 | T1: 2008 | U1: 2009 | V1: 2010 | W1: 2011 | X1: 2012 | Y1: 2013 | Z1: 2014 | AA1: 2015 | AB1: 2016 | AC1: 2017 | AD1: 2018 | AE1: 2019 | AF1: 2020 | AG1: 2021
A3: Transport activity (Mtkm) | B3: =SUM(B4:B5) -> 216279.73 | C3: =SUM(C4:C5) -> 207331.9 | D3: =SUM(D4:D5) -> 187150.96 | E3: =SUM(E4:E5) -> 186069.86 | F3: =SUM(F4:F5) -> 192858.99 | G3: =SUM(G4:G5) -> 195012.71 | H3: =SUM(H4:H5) -> 187134.2 | I3: =SUM(I4:I5) -> 210029.56 | ... AG3: =SUM(AG4:AG5) -> 212982.87
A4: Domestic coastal shipping | B4: =AT!B4+BE!B4+BG!B4+CY!B4+CZ!B4+DE!B4+DK!B4+EE!B4+EL!B4+ES!B4+FI!B4+FR!B4+HR!B4+HU!B4+IE!B4+IT!B4+LT!B4+LU!B4+LV!B4+MT!B4+NL!B4+PL!B4+PT!B4+RO!B4+SE!B4+SI!B4+SK!B4 -> 102977.9 | C4: =AT!C4+BE!C4+BG!C4+CY!C4+CZ!C4+DE!C4+DK!C4+EE!C4+EL!C4+ES!C4+FI!C4+FR!C4+HR!C4+HU!C4+IE!C4+IT!C4+LT!C4+LU!C4+LV!C4+MT!C4+NL!C4+PL!C4+PT!C4+RO!C4+SE!C4+SI!C4+SK!C4 -> 95019.538 | D4: =AT!D4+BE!D4+BG!D4+CY!D4+CZ!D4+DE!D4+DK!D4+EE!D4+EL!D4+ES!D4+FI!D4+FR!D4+HR!D4+HU!D4+IE!D4+IT!D4+LT!D4+LU!D4+LV!D4+MT!D4+NL!D4+PL!D4+PT!D4+RO!D4+SE!D4+SI!D4+SK!D4 -> 75548.801 | E4: =AT!E4+BE!E4+BG!E4+CY!E4+CZ!E4+DE!E4+DK!E4+EE!E4+EL!E4+ES!E4+FI!E4+FR!E4+HR!E4+HU!E4+IE!E4+IT!E4+LT!E4+LU!E4+LV!E4+MT!E4+NL!E4+PL!E4+PT!E4+RO!E4+SE!E4+SI!E4+SK!E4 -> 77466.757 | F4: =AT!F4+BE!F4+BG!F4+CY!F4+CZ!F4+DE!F4+DK!F4+EE!F4+EL!F4+ES!F4+FI!F4+FR!F4+HR!F4+HU!F4+IE!F4+IT!F4+LT!F4+LU!F4+LV!F4+MT!F4+NL!F4+PL!F4+PT!F4+RO!F4+SE!F4+SI!F4+SK!F4 -> 75663.67 | G4: =AT!G4+BE!G4+BG!G4+CY!G4+CZ!G4+DE!G4+DK!G4+EE!G4+EL!G4+ES!G4+FI!G4+FR!G4+HR!G4+HU!G4+IE!G4+IT!G4+LT!G4+LU!G4+LV!G4+MT!G4+NL!G4+PL!G4+PT!G4+RO!G4+SE!G4+SI!G4+SK!G4 -> 75176.401 | H4: =AT!H4+BE!H4+BG!H4+CY!H4+CZ!H4+DE!H4+DK!H4+EE!H4+EL!H4+ES!H4+FI!H4+FR!H4+HR!H4+HU!H4+IE!H4+IT!H4+LT!H4+LU!H4+LV!H4+MT!H4+NL!H4+PL!H4+PT!H4+RO!H4+SE!H4+SI!H4+SK!H4 -> 69711.11 | I4: =AT!I4+BE!I4+BG!I4+CY!I4+CZ!I4+DE!I4+DK!I4+EE!I4+EL!I4+ES!I4+FI!I4+FR!I4+HR!I4+HU!I4+IE!I4+IT!I4+LT!I4+LU!I4+LV!I4+MT!I4+NL!I4+PL!I4+PT!I4+RO!I4+SE!I4+SI!I4+SK!I4 -> 84184.736 | ... AG4: =AT!AG4+BE!AG4+BG!AG4+CY!AG4+CZ!AG4+DE!AG4+DK!AG4+EE!AG4+EL!AG4+ES!AG4+FI!AG4+FR!AG4+HR!AG4+HU!AG4+IE!AG4+IT!AG4+LT!AG4+LU!AG4+LV!AG4+MT!AG4+NL!AG4+PL!AG4+PT!AG4+RO!AG4+SE!AG4+SI!AG4+SK!AG4 -> 76906.865
A5: Inland waterways | B5: =AT!B5+BE!B5+BG!B5+CY!B5+CZ!B5+DE!B5+DK!B5+EE!B5+EL!B5+ES!B5+FI!B5+FR!B5+HR!B5+HU!B5+IE!B5+IT!B5+LT!B5+LU!B5+LV!B5+MT!B5+NL!B5+PL!B5+PT!B5+RO!B5+SE!B5+SI!B5+SK!B5 -> 113301.83 | C5: =AT!C5+BE!C5+BG!C5+CY!C5+CZ!C5+DE!C5+DK!C5+EE!C5+EL!C5+ES!C5+FI!C5+FR!C5+HR!C5+HU!C5+IE!C5+IT!C5+LT!C5+LU!C5+LV!C5+MT!C5+NL!C5+PL!C5+PT!C5+RO!C5+SE!C5+SI!C5+SK!C5 -> 112312.36 | D5: =AT!D5+BE!D5+BG!D5+CY!D5+CZ!D5+DE!D5+DK!D5+EE!D5+EL!D5+ES!D5+FI!D5+FR!D5+HR!D5+HU!D5+IE!D5+IT!D5+LT!D5+LU!D5+LV!D5+MT!D5+NL!D5+PL!D5+PT!D5+RO!D5+SE!D5+SI!D5+SK!D5 -> 111602.16 | E5: =AT!E5+BE!E5+BG!E5+CY!E5+CZ!E5+DE!E5+DK!E5+EE!E5+EL!E5+ES!E5+FI!E5+FR!E5+HR!E5+HU!E5+IE!E5+IT!E5+LT!E5+LU!E5+LV!E5+MT!E5+NL!E5+PL!E5+PT!E5+RO!E5+SE!E5+SI!E5+SK!E5 -> 108603.1 | F5: =AT!F5+BE!F5+BG!F5+CY!F5+CZ!F5+DE!F5+DK!F5+EE!F5+EL!F5+ES!F5+FI!F5+FR!F5+HR!F5+HU!F5+IE!F5+IT!F5+LT!F5+LU!F5+LV!F5+MT!F5+NL!F5+PL!F5+PT!F5+RO!F5+SE!F5+SI!F5+SK!F5 -> 117195.32 | G5: =AT!G5+BE!G5+BG!G5+CY!G5+CZ!G5+DE!G5+DK!G5+EE!G5+EL!G5+ES!G5+FI!G5+FR!G5+HR!G5+HU!G5+IE!G5+IT!G5+LT!G5+LU!G5+LV!G5+MT!G5+NL!G5+PL!G5+PT!G5+RO!G5+SE!G5+SI!G5+SK!G5 -> 119836.31 | H5: =AT!H5+BE!H5+BG!H5+CY!H5+CZ!H5+DE!H5+DK!H5+EE!H5+EL!H5+ES!H5+FI!H5+FR!H5+HR!H5+HU!H5+IE!H5+IT!H5+LT!H5+LU!H5+LV!H5+MT!H5+NL!H5+PL!H5+PT!H5+RO!H5+SE!H5+SI!H5+SK!H5 -> 117423.09 | I5: =AT!I5+BE!I5+BG!I5+CY!I5+CZ!I5+DE!I5+DK!I5+EE!I5+EL!I5+ES!I5+FI!I5+FR!I5+HR!I5+HU!I5+IE!I5+IT!I5+LT!I5+LU!I5+LV!I5+MT!I5+NL!I5+PL!I5+PT!I5+RO!I5+SE!I5+SI!I5+SK!I5 -> 125844.83 | ... AG5: =AT!AG5+BE!AG5+BG!AG5+CY!AG5+CZ!AG5+DE!AG5+DK!AG5+EE!AG5+EL!AG5+ES!AG5+FI!AG5+FR!AG5+HR!AG5+HU!AG5+IE!AG5+IT!AG5+LT!AG5+LU!AG5+LV!AG5+MT!AG5+NL!AG5+PL!AG5+PT!AG5+RO!AG5+SE!AG5+SI!AG5+SK!AG5 -> 136076
A7: Market shares of activity (% of tkm) | B7: =IF(B3=0,0,B3/B$3) -> 1 | C7: =IF(C3=0,0,C3/C$3) -> 1 | D7: =IF(D3=0,0,D3/D$3) -> 1 | E7: =IF(E3=0,0,E3/E$3) -> 1 | F7: =IF(F3=0,0,F3/F$3) -> 1 | G7: =IF(G3=0,0,G3/G$3) -> 1 | H7: =IF(H3=0,0,H3/H$3) -> 1 | I7: =IF(I3=0,0,I3/I$3) -> 1 | ... AG7: =IF(AG3=0,0,AG3/AG$3) -> 1
A8: Domestic coastal shipping | B8: =IF(B4=0,0,B4/B$3) -> 0.47613293 | C8: =IF(C4=0,0,C4/C$3) -> 0.45829676 | D8: =IF(D4=0,0,D4/D$3) -> 0.4036784 | E8: =IF(E4=0,0,E4/E$3) -> 0.41633158 | F8: =IF(F4=0,0,F4/F$3) -> 0.39232637 | G8: =IF(G4=0,0,G4/G$3) -> 0.38549488 | H8: =IF(H4=0,0,H4/H$3) -> 0.37251934 | I8: =IF(I4=0,0,I4/I$3) -> 0.40082327 | ... AG8: =IF(AG4=0,0,AG4/AG$3) -> 0.36109414
A9: Inland waterways | B9: =IF(B5=0,0,B5/B$3) -> 0.52386707 | C9: =IF(C5=0,0,C5/C$3) -> 0.54170324 | D9: =IF(D5=0,0,D5/D$3) -> 0.5963216 | E9: =IF(E5=0,0,E5/E$3) -> 0.58366842 | F9: =IF(F5=0,0,F5/F$3) -> 0.60767363 | G9: =IF(G5=0,0,G5/G$3) -> 0.61450512 | H9: =IF(H5=0,0,H5/H$3) -> 0.62748066 | I9: =IF(I5=0,0,I5/I$3) -> 0.59917673 | ... AG9: =IF(AG5=0,0,AG5/AG$3) -> 0.63890586
A11: Vehicle-km (Mvkm) | B11: =SUM(B12:B13) -> 261.656 | C11: =SUM(C12:C13) -> 242.304 | D11: =SUM(D12:D13) -> 228.761 | E11: =SUM(E12:E13) -> 220.528 | F11: =SUM(F12:F13) -> 231.335 | G11: =SUM(G12:G13) -> 235.119 | H11: =SUM(H12:H13) -> 229.446 | I11: =SUM(I12:I13) -> 251.341 | ... AG11: =SUM(AG12:AG13) -> 213.349
A12: Domestic coastal shipping | B12: =AT!B12+BE!B12+BG!B12+CY!B12+CZ!B12+DE!B12+DK!B12+EE!B12+EL!B12+ES!B12+FI!B12+FR!B12+HR!B12+HU!B12+IE!B12+IT!B12+LT!B12+LU!B12+LV!B12+MT!B12+NL!B12+PL!B12+PT!B12+RO!B12+SE!B12+SI!B12+SK!B12 -> 57.555 | C12: =AT!C12+BE!C12+BG!C12+CY!C12+CZ!C12+DE!C12+DK!C12+EE!C12+EL!C12+ES!C12+FI!C12+FR!C12+HR!C12+HU!C12+IE!C12+IT!C12+LT!C12+LU!C12+LV!C12+MT!C12+NL!C12+PL!C12+PT!C12+RO!C12+SE!C12+SI!C12+SK!C12 -> 53.507 | D12: =AT!D12+BE!D12+BG!D12+CY!D12+CZ!D12+DE!D12+DK!D12+EE!D12+EL!D12+ES!D12+FI!D12+FR!D12+HR!D12+HU!D12+IE!D12+IT!D12+LT!D12+LU!D12+LV!D12+MT!D12+NL!D12+PL!D12+PT!D12+RO!D12+SE!D12+SI!D12+SK!D12 -> 44.275 | E12: =AT!E12+BE!E12+BG!E12+CY!E12+CZ!E12+DE!E12+DK!E12+EE!E12+EL!E12+ES!E12+FI!E12+FR!E12+HR!E12+HU!E12+IE!E12+IT!E12+LT!E12+LU!E12+LV!E12+MT!E12+NL!E12+PL!E12+PT!E12+RO!E12+SE!E12+SI!E12+SK!E12 -> 45.659 | F12: =AT!F12+BE!F12+BG!F12+CY!F12+CZ!F12+DE!F12+DK!F12+EE!F12+EL!F12+ES!F12+FI!F12+FR!F12+HR!F12+HU!F12+IE!F12+IT!F12+LT!F12+LU!F12+LV!F12+MT!F12+NL!F12+PL!F12+PT!F12+RO!F12+SE!F12+SI!F12+SK!F12 -> 45.401 | G12: =AT!G12+BE!G12+BG!G12+CY!G12+CZ!G12+DE!G12+DK!G12+EE!G12+EL!G12+ES!G12+FI!G12+FR!G12+HR!G12+HU!G12+IE!G12+IT!G12+LT!G12+LU!G12+LV!G12+MT!G12+NL!G12+PL!G12+PT!G12+RO!G12+SE!G12+SI!G12+SK!G12 -> 45.391 | H12: =AT!H12+BE!H12+BG!H12+CY!H12+CZ!H12+DE!H12+DK!H12+EE!H12+EL!H12+ES!H12+FI!H12+FR!H12+HR!H12+HU!H12+IE!H12+IT!H12+LT!H12+LU!H12+LV!H12+MT!H12+NL!H12+PL!H12+PT!H12+RO!H12+SE!H12+SI!H12+SK!H12 -> 42.83 | I12: =AT!I12+BE!I12+BG!I12+CY!I12+CZ!I12+DE!I12+DK!I12+EE!I12+EL!I12+ES!I12+FI!I12+FR!I12+HR!I12+HU!I12+IE!I12+IT!I12+LT!I12+LU!I12+LV!I12+MT!I12+NL!I12+PL!I12+PT!I12+RO!I12+SE!I12+SI!I12+SK!I12 -> 50.293 | ... AG12: =AT!AG12+BE!AG12+BG!AG12+CY!AG12+CZ!AG12+DE!AG12+DK!AG12+EE!AG12+EL!AG12+ES!AG12+FI!AG12+FR!AG12+HR!AG12+HU!AG12+IE!AG12+IT!AG12+LT!AG12+LU!AG12+LV!AG12+MT!AG12+NL!AG12+PL!AG12+PT!AG12+RO!AG12+SE!AG12+SI!AG12+SK!AG12 -> 35.874
A13: Inland waterways | B13: =AT!B13+BE!B13+BG!B13+CY!B13+CZ!B13+DE!B13+DK!B13+EE!B13+EL!B13+ES!B13+FI!B13+FR!B13+HR!B13+HU!B13+IE!B13+IT!B13+LT!B13+LU!B13+LV!B13+MT!B13+NL!B13+PL!B13+PT!B13+RO!B13+SE!B13+SI!B13+SK!B13 -> 204.101 | C13: =AT!C13+BE!C13+BG!C13+CY!C13+CZ!C13+DE!C13+DK!C13+EE!C13+EL!C13+ES!C13+FI!C13+FR!C13+HR!C13+HU!C13+IE!C13+IT!C13+LT!C13+LU!C13+LV!C13+MT!C13+NL!C13+PL!C13+PT!C13+RO!C13+SE!C13+SI!C13+SK!C13 -> 188.797 | D13: =AT!D13+BE!D13+BG!D13+CY!D13+CZ!D13+DE!D13+DK!D13+EE!D13+EL!D13+ES!D13+FI!D13+FR!D13+HR!D13+HU!D13+IE!D13+IT!D13+LT!D13+LU!D13+LV!D13+MT!D13+NL!D13+PL!D13+PT!D13+RO!D13+SE!D13+SI!D13+SK!D13 -> 184.486 | E13: =AT!E13+BE!E13+BG!E13+CY!E13+CZ!E13+DE!E13+DK!E13+EE!E13+EL!E13+ES!E13+FI!E13+FR!E13+HR!E13+HU!E13+IE!E13+IT!E13+LT!E13+LU!E13+LV!E13+MT!E13+NL!E13+PL!E13+PT!E13+RO!E13+SE!E13+SI!E13+SK!E13 -> 174.869 | F13: =AT!F13+BE!F13+BG!F13+CY!F13+CZ!F13+DE!F13+DK!F13+EE!F13+EL!F13+ES!F13+FI!F13+FR!F13+HR!F13+HU!F13+IE!F13+IT!F13+LT!F13+LU!F13+LV!F13+MT!F13+NL!F13+PL!F13+PT!F13+RO!F13+SE!F13+SI!F13+SK!F13 -> 185.934 | G13: =AT!G13+BE!G13+BG!G13+CY!G13+CZ!G13+DE!G13+DK!G13+EE!G13+EL!G13+ES!G13+FI!G13+FR!G13+HR!G13+HU!G13+IE!G13+IT!G13+LT!G13+LU!G13+LV!G13+MT!G13+NL!G13+PL!G13+PT!G13+RO!G13+SE!G13+SI!G13+SK!G13 -> 189.728 | H13: =AT!H13+BE!H13+BG!H13+CY!H13+CZ!H13+DE!H13+DK!H13+EE!H13+EL!H13+ES!H13+FI!H13+FR!H13+HR!H13+HU!H13+IE!H13+IT!H13+LT!H13+LU!H13+LV!H13+MT!H13+NL!H13+PL!H13+PT!H13+RO!H13+SE!H13+SI!H13+SK!H13 -> 186.616 | I13: =AT!I13+BE!I13+BG!I13+CY!I13+CZ!I13+DE!I13+DK!I13+EE!I13+EL!I13+ES!I13+FI!I13+FR!I13+HR!I13+HU!I13+IE!I13+IT!I13+LT!I13+LU!I13+LV!I13+MT!I13+NL!I13+PL!I13+PT!I13+RO!I13+SE!I13+SI!I13+SK!I13 -> 201.048 | ... AG13: =AT!AG13+BE!AG13+BG!AG13+CY!AG13+CZ!AG13+DE!AG13+DK!AG13+EE!AG13+EL!AG13+ES!AG13+FI!AG13+FR!AG13+HR!AG13+HU!AG13+IE!AG13+IT!AG13+LT!AG13+LU!AG13+LV!AG13+MT!AG13+NL!AG13+PL!AG13+PT!AG13+RO!AG13+SE!AG13+SI!AG13+SK!AG13 -> 177.475
A15: Market shares of vehicle km (% of km) | B15: =IF(B11=0,0,B11/B$11) -> 1 | C15: =IF(C11=0,0,C11/C$11) -> 1 | D15: =IF(D11=0,0,D11/D$11) -> 1 | E15: =IF(E11=0,0,E11/E$11) -> 1 | F15: =IF(F11=0,0,F11/F$11) -> 1 | G15: =IF(G11=0,0,G11/G$11) -> 1 | H15: =IF(H11=0,0,H11/H$11) -> 1 | I15: =IF(I11=0,0,I11/I$11) -> 1 | ... AG15: =IF(AG11=0,0,AG11/AG$11) -> 1
A16: Domestic coastal shipping | B16: =IF(B12=0,0,B12/B$11) -> 0.21996438 | C16: =IF(C12=0,0,C12/C$11) -> 0.2208259 | D16: =IF(D12=0,0,D12/D$11) -> 0.19354261 | E16: =IF(E12=0,0,E12/E$11) -> 0.207044 | F16: =IF(F12=0,0,F12/F$11) -> 0.19625651 | G16: =IF(G12=0,0,G12/G$11) -> 0.19305543 | H16: =IF(H12=0,0,H12/H$11) -> 0.18666702 | I16: =IF(I12=0,0,I12/I$11) -> 0.20009867 | ... AG16: =IF(AG12=0,0,AG12/AG$11) -> 0.16814703
A17: Inland waterways | B17: =IF(B13=0,0,B13/B$11) -> 0.78003562 | C17: =IF(C13=0,0,C13/C$11) -> 0.7791741 | D17: =IF(D13=0,0,D13/D$11) -> 0.80645739 | E17: =IF(E13=0,0,E13/E$11) -> 0.792956 | F17: =IF(F13=0,0,F13/F$11) -> 0.80374349 | G17: =IF(G13=0,0,G13/G$11) -> 0.80694457 | H17: =IF(H13=0,0,H13/H$11) -> 0.81333298 | I17: =IF(I13=0,0,I13/I$11) -> 0.79990133 | ... AG17: =IF(AG13=0,0,AG13/AG$11) -> 0.83185297
A19: Load factor of vessels (t/movement) | B19: =IF(B3=0,0,B3/B11) -> 826.58042 | C19: =IF(C3=0,0,C3/C11) -> 855.6685 | D19: =IF(D3=0,0,D3/D11) -> 818.10695 | E19: =IF(E3=0,0,E3/E11) -> 843.74708 | F19: =IF(F3=0,0,F3/F11) -> 833.67841 | G19: =IF(G3=0,0,G3/G11) -> 829.42131 | H19: =IF(H3=0,0,H3/H11) -> 815.59148 | I19: =IF(I3=0,0,I3/I11) -> 835.6359 | ... AG19: =IF(AG3=0,0,AG3/AG11) -> 998.28387
A20: Domestic coastal shipping | B20: =IF(B4=0,0,B4/B12) -> 1789.2086 | C20: =IF(C4=0,0,C4/C12) -> 1775.8338 | D20: =IF(D4=0,0,D4/D12) -> 1706.3535 | E20: =IF(E4=0,0,E4/E12) -> 1696.6372 | F20: =IF(F4=0,0,F4/F12) -> 1666.5639 | G20: =IF(G4=0,0,G4/G12) -> 1656.1962 | H20: =IF(H4=0,0,H4/H12) -> 1627.6234 | I20: =IF(I4=0,0,I4/I12) -> 1673.8858 | ... AG20: =IF(AG4=0,0,AG4/AG12) -> 2143.8051
A21: Inland waterways | B21: =IF(B5=0,0,B5/B13) -> 555.12626 | C21: =IF(C5=0,0,C5/C13) -> 594.88425 | D21: =IF(D5=0,0,D5/D13) -> 604.93567 | E21: =IF(E5=0,0,E5/E13) -> 621.05404 | F21: =IF(F5=0,0,F5/F13) -> 630.30605 | G21: =IF(G5=0,0,G5/G13) -> 631.62163 | H21: =IF(H5=0,0,H5/H13) -> 629.22307 | I21: =IF(I5=0,0,I5/I13) -> 625.94419 | ... AG21: =IF(AG5=0,0,AG5/AG13) -> 766.73334
A23: Total energy consumption (ktoe) | B23: =SUM(B24,B30) -> 5449.9476 | C23: =SUM(C24,C30) -> 5551.9704 | D23: =SUM(D24,D30) -> 5566.034 | E23: =SUM(E24,E30) -> 5289.7617 | F23: =SUM(F24,F30) -> 5394.4594 | G23: =SUM(G24,G30) -> 5199.3071 | H23: =SUM(H24,H30) -> 5666.8156 | I23: =SUM(I24,I30) -> 5472.5433 | ... AG23: =SUM(AG24,AG30) -> 3978.0524
A24: Domestic coastal shipping | B24: =SUM(B25:B29) -> 3754.0805 | C24: =SUM(C25:C29) -> 3850.5166 | D24: =SUM(D25:D29) -> 3851.6816 | E24: =SUM(E25:E29) -> 3806.3511 | F24: =SUM(F25:F29) -> 3911.0875 | G24: =SUM(G25:G29) -> 3882.1215 | H24: =SUM(H25:H29) -> 4310.7622 | I24: =SUM(I25:I29) -> 4016.6247 | ... AG24: =SUM(AG25:AG29) -> 2999.9797
A25: Gas oil and diesel oil (excluding biofuel portion) | B25: =AT!B25+BE!B25+BG!B25+CY!B25+CZ!B25+DE!B25+DK!B25+EE!B25+EL!B25+ES!B25+FI!B25+FR!B25+HR!B25+HU!B25+IE!B25+IT!B25+LT!B25+LU!B25+LV!B25+MT!B25+NL!B25+PL!B25+PT!B25+RO!B25+SE!B25+SI!B25+SK!B25 -> 2242.2454 | C25: =AT!C25+BE!C25+BG!C25+CY!C25+CZ!C25+DE!C25+DK!C25+EE!C25+EL!C25+ES!C25+FI!C25+FR!C25+HR!C25+HU!C25+IE!C25+IT!C25+LT!C25+LU!C25+LV!C25+MT!C25+NL!C25+PL!C25+PT!C25+RO!C25+SE!C25+SI!C25+SK!C25 -> 2344.061 | D25: =AT!D25+BE!D25+BG!D25+CY!D25+CZ!D25+DE!D25+DK!D25+EE!D25+EL!D25+ES!D25+FI!D25+FR!D25+HR!D25+HU!D25+IE!D25+IT!D25+LT!D25+LU!D25+LV!D25+MT!D25+NL!D25+PL!D25+PT!D25+RO!D25+SE!D25+SI!D25+SK!D25 -> 2382.3603 | E25: =AT!E25+BE!E25+BG!E25+CY!E25+CZ!E25+DE!E25+DK!E25+EE!E25+EL!E25+ES!E25+FI!E25+FR!E25+HR!E25+HU!E25+IE!E25+IT!E25+LT!E25+LU!E25+LV!E25+MT!E25+NL!E25+PL!E25+PT!E25+RO!E25+SE!E25+SI!E25+SK!E25 -> 2414.2312 | F25: =AT!F25+BE!F25+BG!F25+CY!F25+CZ!F25+DE!F25+DK!F25+EE!F25+EL!F25+ES!F25+FI!F25+FR!F25+HR!F25+HU!F25+IE!F25+IT!F25+LT!F25+LU!F25+LV!F25+MT!F25+NL!F25+PL!F25+PT!F25+RO!F25+SE!F25+SI!F25+SK!F25 -> 2444.3603 | G25: =AT!G25+BE!G25+BG!G25+CY!G25+CZ!G25+DE!G25+DK!G25+EE!G25+EL!G25+ES!G25+FI!G25+FR!G25+HR!G25+HU!G25+IE!G25+IT!G25+LT!G25+LU!G25+LV!G25+MT!G25+NL!G25+PL!G25+PT!G25+RO!G25+SE!G25+SI!G25+SK!G25 -> 2473.3737 | H25: =AT!H25+BE!H25+BG!H25+CY!H25+CZ!H25+DE!H25+DK!H25+EE!H25+EL!H25+ES!H25+FI!H25+FR!H25+HR!H25+HU!H25+IE!H25+IT!H25+LT!H25+LU!H25+LV!H25+MT!H25+NL!H25+PL!H25+PT!H25+RO!H25+SE!H25+SI!H25+SK!H25 -> 2578.6374 | I25: =AT!I25+BE!I25+BG!I25+CY!I25+CZ!I25+DE!I25+DK!I25+EE!I25+EL!I25+ES!I25+FI!I25+FR!I25+HR!I25+HU!I25+IE!I25+IT!I25+LT!I25+LU!I25+LV!I25+MT!I25+NL!I25+PL!I25+PT!I25+RO!I25+SE!I25+SI!I25+SK!I25 -> 2367.7262 | ... AG25: =AT!AG25+BE!AG25+BG!AG25+CY!AG25+CZ!AG25+DE!AG25+DK!AG25+EE!AG25+EL!AG25+ES!AG25+FI!AG25+FR!AG25+HR!AG25+HU!AG25+IE!AG25+IT!AG25+LT!AG25+LU!AG25+LV!AG25+MT!AG25+NL!AG25+PL!AG25+PT!AG25+RO!AG25+SE!AG25+SI!AG25+SK!AG25 -> 1560.7057
A26: Fuel oil and Other oil products | B26: =AT!B26+BE!B26+BG!B26+CY!B26+CZ!B26+DE!B26+DK!B26+EE!B26+EL!B26+ES!B26+FI!B26+FR!B26+HR!B26+HU!B26+IE!B26+IT!B26+LT!B26+LU!B26+LV!B26+MT!B26+NL!B26+PL!B26+PT!B26+RO!B26+SE!B26+SI!B26+SK!B26 -> 1511.8351 | C26: =AT!C26+BE!C26+BG!C26+CY!C26+CZ!C26+DE!C26+DK!C26+EE!C26+EL!C26+ES!C26+FI!C26+FR!C26+HR!C26+HU!C26+IE!C26+IT!C26+LT!C26+LU!C26+LV!C26+MT!C26+NL!C26+PL!C26+PT!C26+RO!C26+SE!C26+SI!C26+SK!C26 -> 1506.4556 | D26: =AT!D26+BE!D26+BG!D26+CY!D26+CZ!D26+DE!D26+DK!D26+EE!D26+EL!D26+ES!D26+FI!D26+FR!D26+HR!D26+HU!D26+IE!D26+IT!D26+LT!D26+LU!D26+LV!D26+MT!D26+NL!D26+PL!D26+PT!D26+RO!D26+SE!D26+SI!D26+SK!D26 -> 1469.3212 | E26: =AT!E26+BE!E26+BG!E26+CY!E26+CZ!E26+DE!E26+DK!E26+EE!E26+EL!E26+ES!E26+FI!E26+FR!E26+HR!E26+HU!E26+IE!E26+IT!E26+LT!E26+LU!E26+LV!E26+MT!E26+NL!E26+PL!E26+PT!E26+RO!E26+SE!E26+SI!E26+SK!E26 -> 1392.1199 | F26: =AT!F26+BE!F26+BG!F26+CY!F26+CZ!F26+DE!F26+DK!F26+EE!F26+EL!F26+ES!F26+FI!F26+FR!F26+HR!F26+HU!F26+IE!F26+IT!F26+LT!F26+LU!F26+LV!F26+MT!F26+NL!F26+PL!F26+PT!F26+RO!F26+SE!F26+SI!F26+SK!F26 -> 1466.7272 | G26: =AT!G26+BE!G26+BG!G26+CY!G26+CZ!G26+DE!G26+DK!G26+EE!G26+EL!G26+ES!G26+FI!G26+FR!G26+HR!G26+HU!G26+IE!G26+IT!G26+LT!G26+LU!G26+LV!G26+MT!G26+NL!G26+PL!G26+PT!G26+RO!G26+SE!G26+SI!G26+SK!G26 -> 1408.7478 | H26: =AT!H26+BE!H26+BG!H26+CY!H26+CZ!H26+DE!H26+DK!H26+EE!H26+EL!H26+ES!H26+FI!H26+FR!H26+HR!H26+HU!H26+IE!H26+IT!H26+LT!H26+LU!H26+LV!H26+MT!H26+NL!H26+PL!H26+PT!H26+RO!H26+SE!H26+SI!H26+SK!H26 -> 1732.1248 | I26: =AT!I26+BE!I26+BG!I26+CY!I26+CZ!I26+DE!I26+DK!I26+EE!I26+EL!I26+ES!I26+FI!I26+FR!I26+HR!I26+HU!I26+IE!I26+IT!I26+LT!I26+LU!I26+LV!I26+MT!I26+NL!I26+PL!I26+PT!I26+RO!I26+SE!I26+SI!I26+SK!I26 -> 1648.8985 | ... AG26: =AT!AG26+BE!AG26+BG!AG26+CY!AG26+CZ!AG26+DE!AG26+DK!AG26+EE!AG26+EL!AG26+ES!AG26+FI!AG26+FR!AG26+HR!AG26+HU!AG26+IE!AG26+IT!AG26+LT!AG26+LU!AG26+LV!AG26+MT!AG26+NL!AG26+PL!AG26+PT!AG26+RO!AG26+SE!AG26+SI!AG26+SK!AG26 -> 1420.059
A27: Blended biofuels | B27: =AT!B27+BE!B27+BG!B27+CY!B27+CZ!B27+DE!B27+DK!B27+EE!B27+EL!B27+ES!B27+FI!B27+FR!B27+HR!B27+HU!B27+IE!B27+IT!B27+LT!B27+LU!B27+LV!B27+MT!B27+NL!B27+PL!B27+PT!B27+RO!B27+SE!B27+SI!B27+SK!B27 -> 0 | C27: =AT!C27+BE!C27+BG!C27+CY!C27+CZ!C27+DE!C27+DK!C27+EE!C27+EL!C27+ES!C27+FI!C27+FR!C27+HR!C27+HU!C27+IE!C27+IT!C27+LT!C27+LU!C27+LV!C27+MT!C27+NL!C27+PL!C27+PT!C27+RO!C27+SE!C27+SI!C27+SK!C27 -> 0 | D27: =AT!D27+BE!D27+BG!D27+CY!D27+CZ!D27+DE!D27+DK!D27+EE!D27+EL!D27+ES!D27+FI!D27+FR!D27+HR!D27+HU!D27+IE!D27+IT!D27+LT!D27+LU!D27+LV!D27+MT!D27+NL!D27+PL!D27+PT!D27+RO!D27+SE!D27+SI!D27+SK!D27 -> 0 | E27: =AT!E27+BE!E27+BG!E27+CY!E27+CZ!E27+DE!E27+DK!E27+EE!E27+EL!E27+ES!E27+FI!E27+FR!E27+HR!E27+HU!E27+IE!E27+IT!E27+LT!E27+LU!E27+LV!E27+MT!E27+NL!E27+PL!E27+PT!E27+RO!E27+SE!E27+SI!E27+SK!E27 -> 0 | F27: =AT!F27+BE!F27+BG!F27+CY!F27+CZ!F27+DE!F27+DK!F27+EE!F27+EL!F27+ES!F27+FI!F27+FR!F27+HR!F27+HU!F27+IE!F27+IT!F27+LT!F27+LU!F27+LV!F27+MT!F27+NL!F27+PL!F27+PT!F27+RO!F27+SE!F27+SI!F27+SK!F27 -> 0 | G27: =AT!G27+BE!G27+BG!G27+CY!G27+CZ!G27+DE!G27+DK!G27+EE!G27+EL!G27+ES!G27+FI!G27+FR!G27+HR!G27+HU!G27+IE!G27+IT!G27+LT!G27+LU!G27+LV!G27+MT!G27+NL!G27+PL!G27+PT!G27+RO!G27+SE!G27+SI!G27+SK!G27 -> 0 | H27: =AT!H27+BE!H27+BG!H27+CY!H27+CZ!H27+DE!H27+DK!H27+EE!H27+EL!H27+ES!H27+FI!H27+FR!H27+HR!H27+HU!H27+IE!H27+IT!H27+LT!H27+LU!H27+LV!H27+MT!H27+NL!H27+PL!H27+PT!H27+RO!H27+SE!H27+SI!H27+SK!H27 -> 0 | I27: =AT!I27+BE!I27+BG!I27+CY!I27+CZ!I27+DE!I27+DK!I27+EE!I27+EL!I27+ES!I27+FI!I27+FR!I27+HR!I27+HU!I27+IE!I27+IT!I27+LT!I27+LU!I27+LV!I27+MT!I27+NL!I27+PL!I27+PT!I27+RO!I27+SE!I27+SI!I27+SK!I27 -> 0 | ... AG27: =AT!AG27+BE!AG27+BG!AG27+CY!AG27+CZ!AG27+DE!AG27+DK!AG27+EE!AG27+EL!AG27+ES!AG27+FI!AG27+FR!AG27+HR!AG27+HU!AG27+IE!AG27+IT!AG27+LT!AG27+LU!AG27+LV!AG27+MT!AG27+NL!AG27+PL!AG27+PT!AG27+RO!AG27+SE!AG27+SI!AG27+SK!AG27 -> 19.215084
A28: Natural gas | B28: =AT!B28+BE!B28+BG!B28+CY!B28+CZ!B28+DE!B28+DK!B28+EE!B28+EL!B28+ES!B28+FI!B28+FR!B28+HR!B28+HU!B28+IE!B28+IT!B28+LT!B28+LU!B28+LV!B28+MT!B28+NL!B28+PL!B28+PT!B28+RO!B28+SE!B28+SI!B28+SK!B28 -> 0 | C28: =AT!C28+BE!C28+BG!C28+CY!C28+CZ!C28+DE!C28+DK!C28+EE!C28+EL!C28+ES!C28+FI!C28+FR!C28+HR!C28+HU!C28+IE!C28+IT!C28+LT!C28+LU!C28+LV!C28+MT!C28+NL!C28+PL!C28+PT!C28+RO!C28+SE!C28+SI!C28+SK!C28 -> 0 | D28: =AT!D28+BE!D28+BG!D28+CY!D28+CZ!D28+DE!D28+DK!D28+EE!D28+EL!D28+ES!D28+FI!D28+FR!D28+HR!D28+HU!D28+IE!D28+IT!D28+LT!D28+LU!D28+LV!D28+MT!D28+NL!D28+PL!D28+PT!D28+RO!D28+SE!D28+SI!D28+SK!D28 -> 0 | E28: =AT!E28+BE!E28+BG!E28+CY!E28+CZ!E28+DE!E28+DK!E28+EE!E28+EL!E28+ES!E28+FI!E28+FR!E28+HR!E28+HU!E28+IE!E28+IT!E28+LT!E28+LU!E28+LV!E28+MT!E28+NL!E28+PL!E28+PT!E28+RO!E28+SE!E28+SI!E28+SK!E28 -> 0 | F28: =AT!F28+BE!F28+BG!F28+CY!F28+CZ!F28+DE!F28+DK!F28+EE!F28+EL!F28+ES!F28+FI!F28+FR!F28+HR!F28+HU!F28+IE!F28+IT!F28+LT!F28+LU!F28+LV!F28+MT!F28+NL!F28+PL!F28+PT!F28+RO!F28+SE!F28+SI!F28+SK!F28 -> 0 | G28: =AT!G28+BE!G28+BG!G28+CY!G28+CZ!G28+DE!G28+DK!G28+EE!G28+EL!G28+ES!G28+FI!G28+FR!G28+HR!G28+HU!G28+IE!G28+IT!G28+LT!G28+LU!G28+LV!G28+MT!G28+NL!G28+PL!G28+PT!G28+RO!G28+SE!G28+SI!G28+SK!G28 -> 0 | H28: =AT!H28+BE!H28+BG!H28+CY!H28+CZ!H28+DE!H28+DK!H28+EE!H28+EL!H28+ES!H28+FI!H28+FR!H28+HR!H28+HU!H28+IE!H28+IT!H28+LT!H28+LU!H28+LV!H28+MT!H28+NL!H28+PL!H28+PT!H28+RO!H28+SE!H28+SI!H28+SK!H28 -> 0 | I28: =AT!I28+BE!I28+BG!I28+CY!I28+CZ!I28+DE!I28+DK!I28+EE!I28+EL!I28+ES!I28+FI!I28+FR!I28+HR!I28+HU!I28+IE!I28+IT!I28+LT!I28+LU!I28+LV!I28+MT!I28+NL!I28+PL!I28+PT!I28+RO!I28+SE!I28+SI!I28+SK!I28 -> 0 | ... AG28: =AT!AG28+BE!AG28+BG!AG28+CY!AG28+CZ!AG28+DE!AG28+DK!AG28+EE!AG28+EL!AG28+ES!AG28+FI!AG28+FR!AG28+HR!AG28+HU!AG28+IE!AG28+IT!AG28+LT!AG28+LU!AG28+LV!AG28+MT!AG28+NL!AG28+PL!AG28+PT!AG28+RO!AG28+SE!AG28+SI!AG28+SK!AG28 -> 0
