Workbook

Sheet cover
B6: JRC-IDEES-2021 - Integrated Database of the European Energy System
C10: European Union (27 countries from 2020)
C15: Energy balances
L28: Prepared by JRC C.6
L30: 45432.79
L31: v2021-1.00
B33: Legal Notice
B35: The information made available is property of the Joint Research Centre of the European Commission.
B36: Neither the European Commission nor any person acting on behalf of the Commission is responsible for the use which might be made of this information.
B38: Use conditions
B39: This work is licensed under
B40: CC BY 4.0

Sheet index
A1: European Union (27 countries from 2020) | B1: EU27 | C1: 2000 | D1: 2001 | E1: 2002 | F1: 2003 | G1: 2004 | H1: 2005 | I1: 2006 | J1: 2007 | K1: 2008 | L1: 2009 | M1: 2010 | N1: 2011 | O1: 2012 | P1: 2013 | Q1: 2014 | R1: 2015 | S1: 2016 | T1: 2017 | U1: 2018 | V1: 2019 | W1: 2020 | X1: 2021
B2: Click on the link to jump to the sheet
A3: Total | B3: ktoe
A4: Primary production | B4: =HYPERLINK("#"&CELL("address",PPRD!$W$2),"PPRD") -> PPRD | C4: =PPRD!C$2 -> 675865.22 | D4: =PPRD!D$2 -> 685360.73 | E4: =PPRD!E$2 -> 689533.44 | F4: =PPRD!F$2 -> 694347.83 | G4: =PPRD!G$2 -> 710302.95 | H4: =PPRD!H$2 -> 703209.69 | I4: =PPRD!I$2 -> 703762.09 | J4: =PPRD!J$2 -> 690378.62 | ... X4: =PPRD!X$2 -> 598126.74
A5: Recovered & recycled products | B5: =HYPERLINK("#"&CELL("address",RCV_RCY!$W$2),"RCV_RCY") -> RCV_RCY | C5: =RCV_RCY!C$2 -> 2215.6619 | D5: =RCV_RCY!D$2 -> 1861.5356 | E5: =RCV_RCY!E$2 -> 2024.4978 | F5: =RCV_RCY!F$2 -> 2142.2032 | G5: =RCV_RCY!G$2 -> 3242.3794 | H5: =RCV_RCY!H$2 -> 1835.6799 | I5: =RCV_RCY!I$2 -> 1740.9143 | J5: =RCV_RCY!J$2 -> 1928.6833 | ... X5: =RCV_RCY!X$2 -> 1447.3628
A6: Imports | B6: =HYPERLINK("#"&CELL("address",IMP!$W$2),"IMP") -> IMP | C6: =IMP!C$2 -> 1172345 | D6: =IMP!D$2 -> 1190822.6 | E6: =IMP!E$2 -> 1206557.5 | F6: =IMP!F$2 -> 1249419.6 | G6: =IMP!G$2 -> 1296364.6 | H6: =IMP!H$2 -> 1339489.5 | I6: =IMP!I$2 -> 1361921.6 | J6: =IMP!J$2 -> 1327293.1 | ... X6: =IMP!X$2 -> 1224290.7
A7: Exports | B7: =HYPERLINK("#"&CELL("address",EXP!$W$2),"EXP") -> EXP | C7: =EXP!C$2 -> 306387.77 | D7: =EXP!D$2 -> 310943.31 | E7: =EXP!E$2 -> 317179.43 | F7: =EXP!F$2 -> 328023.63 | G7: =EXP!G$2 -> 362134.61 | H7: =EXP!H$2 -> 384902.63 | I7: =EXP!I$2 -> 390436.26 | J7: =EXP!J$2 -> 383641.1 | ... X7: =EXP!X$2 -> 412377.39
A8: Change in stock | B8: =HYPERLINK("#"&CELL("address",STK_CHG!$W$2),"STK_CHG") -> STK_CHG | C8: =STK_CHG!C$2 -> -5503.1859 | D8: =STK_CHG!D$2 -> 10616.241 | E8: =STK_CHG!E$2 -> 3.9048151 | F8: =STK_CHG!F$2 -> 2063.3333 | G8: =STK_CHG!G$2 -> -4569.1306 | H8: =STK_CHG!H$2 -> -8643.3816 | I8: =STK_CHG!I$2 -> -9035.809 | J8: =STK_CHG!J$2 -> 13230.007 | ... X8: =STK_CHG!X$2 -> 50854.821
A9: Gross available energy | B9: =HYPERLINK("#"&CELL("address",GAE!$W$2),"GAE") -> GAE | C9: =GAE!C$2 -> 1538534.9 | D9: =GAE!D$2 -> 1577717.8 | E9: =GAE!E$2 -> 1580939.9 | F9: =GAE!F$2 -> 1619949.4 | G9: =GAE!G$2 -> 1643206.2 | H9: =GAE!H$2 -> 1650988.9 | I9: =GAE!I$2 -> 1667952.6 | J9: =GAE!J$2 -> 1649189.3 | ... X9: =GAE!X$2 -> 1462342.2
A10: International maritime bunkers | B10: =HYPERLINK("#"&CELL("address",INTMARB!$W$2),"INTMARB") -> INTMARB | C10: =INTMARB!C$2 -> 40355.427 | D10: =INTMARB!D$2 -> 41594.502 | E10: =INTMARB!E$2 -> 42789.175 | F10: =INTMARB!F$2 -> 44042.576 | G10: =INTMARB!G$2 -> 46270.016 | H10: =INTMARB!H$2 -> 47173.61 | I10: =INTMARB!I$2 -> 50290.715 | J10: =INTMARB!J$2 -> 52441.628 | ... X10: =INTMARB!X$2 -> 40756.205
A11: International Intra-EEA maritime bunkers | B11: =HYPERLINK("#"&CELL("address",INTMARB_IN!$W$2),"INTMARB_IN") -> INTMARB_IN | C11: =INTMARB_IN!C$2 -> 12349.039 | D11: =INTMARB_IN!D$2 -> 12250.785 | E11: =INTMARB_IN!E$2 -> 12230.393 | F11: =INTMARB_IN!F$2 -> 12685.051 | G11: =INTMARB_IN!G$2 -> 12932.515 | H11: =INTMARB_IN!H$2 -> 12476.202 | I11: =INTMARB_IN!I$2 -> 12775.809 | J11: =INTMARB_IN!J$2 -> 13049.184 | ... X11: =INTMARB_IN!X$2 -> 10796.207
A12: International Extra-EEA maritime bunkers | B12: =HYPERLINK("#"&CELL("address",INTMARB_EX!$W$2),"INTMARB_EX") -> INTMARB_EX | C12: =INTMARB_EX!C$2 -> 28006.387 | D12: =INTMARB_EX!D$2 -> 29343.717 | E12: =INTMARB_EX!E$2 -> 30558.782 | F12: =INTMARB_EX!F$2 -> 31357.525 | G12: =INTMARB_EX!G$2 -> 33337.502 | H12: =INTMARB_EX!H$2 -> 34697.407 | I12: =INTMARB_EX!I$2 -> 37514.906 | J12: =INTMARB_EX!J$2 -> 39392.444 | ... X12: =INTMARB_EX!X$2 -> 29959.997
A13: Gross inland consumption | B13: =HYPERLINK("#"&CELL("address",GIC!$W$2),"GIC") -> GIC | C13: =GIC!C$2 -> 1498179.5 | D13: =GIC!D$2 -> 1536123.3 | E13: =GIC!E$2 -> 1538150.7 | F13: =GIC!F$2 -> 1575906.8 | G13: =GIC!G$2 -> 1596936.2 | H13: =GIC!H$2 -> 1603815.3 | I13: =GIC!I$2 -> 1617661.8 | J13: =GIC!J$2 -> 1596747.7 | ... X13: =GIC!X$2 -> 1421586
A14: International aviation | B14: =HYPERLINK("#"&CELL("address",INTAVI!$W$2),"INTAVI") -> INTAVI | C14: =INTAVI!C$2 -> 28574.846 | D14: =INTAVI!D$2 -> 27914.304 | E14: =INTAVI!E$2 -> 27431.284 | F14: =INTAVI!F$2 -> 27956.278 | G14: =INTAVI!G$2 -> 29937.816 | H14: =INTAVI!H$2 -> 31148.201 | I14: =INTAVI!I$2 -> 32737.147 | J14: =INTAVI!J$2 -> 34156.137 | ... X14: =INTAVI!X$2 -> 21528.6
A15: International Intra-EEAwUK passenger aviation | B15: =HYPERLINK("#"&CELL("address",INTAVI_PA_IN!$W$2),"INTAVI_PA_IN") -> INTAVI_PA_IN | C15: =INTAVI_PA_IN!C$2 -> 10936.748 | D15: =INTAVI_PA_IN!D$2 -> 10960.316 | E15: =INTAVI_PA_IN!E$2 -> 10424.234 | F15: =INTAVI_PA_IN!F$2 -> 11161.416 | G15: =INTAVI_PA_IN!G$2 -> 11738.626 | H15: =INTAVI_PA_IN!H$2 -> 12212.729 | I15: =INTAVI_PA_IN!I$2 -> 13011.081 | J15: =INTAVI_PA_IN!J$2 -> 13800.913 | ... X15: =INTAVI_PA_IN!X$2 -> 7236.0424
A16: International Extra-EEAwUK passenger aviation | B16: =HYPERLINK("#"&CELL("address",INTAVI_PA_EX!$W$2),"INTAVI_PA_EX") -> INTAVI_PA_EX | C16: =INTAVI_PA_EX!C$2 -> 15185.274 | D16: =INTAVI_PA_EX!D$2 -> 14688.635 | E16: =INTAVI_PA_EX!E$2 -> 14535.748 | F16: =INTAVI_PA_EX!F$2 -> 14141.299 | G16: =INTAVI_PA_EX!G$2 -> 15305.231 | H16: =INTAVI_PA_EX!H$2 -> 15769.753 | I16: =INTAVI_PA_EX!I$2 -> 16219.544 | J16: =INTAVI_PA_EX!J$2 -> 16669.855 | ... X16: =INTAVI_PA_EX!X$2 -> 9549.365
A17: International Intra-EEAwUK freight aviation | B17: =HYPERLINK("#"&CELL("address",INTAVI_FR_IN!$W$2),"INTAVI_FR_IN") -> INTAVI_FR_IN | C17: =INTAVI_FR_IN!C$2 -> 287.54706 | D17: =INTAVI_FR_IN!D$2 -> 257.2144 | E17: =INTAVI_FR_IN!E$2 -> 274.5675 | F17: =INTAVI_FR_IN!F$2 -> 272.93932 | G17: =INTAVI_FR_IN!G$2 -> 306.20406 | H17: =INTAVI_FR_IN!H$2 -> 327.71216 | I17: =INTAVI_FR_IN!I$2 -> 414.10973 | J17: =INTAVI_FR_IN!J$2 -> 444.18587 | ... X17: =INTAVI_FR_IN!X$2 -> 581.77801
A18: International Extra-EEAwUK freight aviation | B18: =HYPERLINK("#"&CELL("address",INTAVI_FR_EX!$W$2),"INTAVI_FR_EX") -> INTAVI_FR_EX | C18: =INTAVI_FR_EX!C$2 -> 2165.2777 | D18: =INTAVI_FR_EX!D$2 -> 2008.1386 | E18: =INTAVI_FR_EX!E$2 -> 2196.7348 | F18: =INTAVI_FR_EX!F$2 -> 2380.6232 | G18: =INTAVI_FR_EX!G$2 -> 2587.7546 | H18: =INTAVI_FR_EX!H$2 -> 2838.0067 | I18: =INTAVI_FR_EX!I$2 -> 3092.4118 | J18: =INTAVI_FR_EX!J$2 -> 3241.1833 | ... X18: =INTAVI_FR_EX!X$2 -> 4161.4146
A19: Total energy supply | B19: =HYPERLINK("#"&CELL("address",NRGSUP!$W$2),"NRGSUP") -> NRGSUP | C19: =NRGSUP!C$2 -> 1469604.6 | D19: =NRGSUP!D$2 -> 1508209 | E19: =NRGSUP!E$2 -> 1510719.4 | F19: =NRGSUP!F$2 -> 1547950.5 | G19: =NRGSUP!G$2 -> 1566998.4 | H19: =NRGSUP!H$2 -> 1572667.1 | I19: =NRGSUP!I$2 -> 1584924.7 | J19: =NRGSUP!J$2 -> 1562591.5 | ... X19: =NRGSUP!X$2 -> 1400057.4
A20: Gross inland consumption (Europe 2020-2030) | B20: =HYPERLINK("#"&CELL("address",'GIC2020-2030'!$W$2),"GIC2020-2030") -> GIC2020-2030 | C20: ='GIC2020-2030'!C$2 -> 1498093.6 | D20: ='GIC2020-2030'!D$2 -> 1536033.2 | E20: ='GIC2020-2030'!E$2 -> 1538054.9 | F20: ='GIC2020-2030'!F$2 -> 1575626.9 | G20: ='GIC2020-2030'!G$2 -> 1596516 | H20: ='GIC2020-2030'!H$2 -> 1603184.1 | I20: ='GIC2020-2030'!I$2 -> 1616802.5 | J20: ='GIC2020-2030'!J$2 -> 1595610.9 | ... X20: ='GIC2020-2030'!X$2 -> 1406340.2
A21: Primary energy consumption (Europe 2020-2030) | B21: =HYPERLINK("#"&CELL("address",'PEC2020-2030'!$W$2),"PEC2020-2030") -> PEC2020-2030 | C21: ='PEC2020-2030'!C$2 -> 1395242.3 | D21: ='PEC2020-2030'!D$2 -> 1433373 | E21: ='PEC2020-2030'!E$2 -> 1435902.2 | F21: ='PEC2020-2030'!F$2 -> 1474790.9 | G21: ='PEC2020-2030'!G$2 -> 1493687 | H21: ='PEC2020-2030'!H$2 -> 1498149.1 | I21: ='PEC2020-2030'!I$2 -> 1511936.3 | J21: ='PEC2020-2030'!J$2 -> 1490756.2 | ... X21: ='PEC2020-2030'!X$2 -> 1314355.3
A22: Final energy consumption (Europe 2020-2030) | B22: =HYPERLINK("#"&CELL("address",'FEC2020-2030'!$W$2),"FEC2020-2030") -> FEC2020-2030 | C22: ='FEC2020-2030'!C$2 -> 978447.3 | D22: ='FEC2020-2030'!D$2 -> 1001740.8 | E22: ='FEC2020-2030'!E$2 -> 995297.45 | F22: ='FEC2020-2030'!F$2 -> 1025756.9 | G22: ='FEC2020-2030'!G$2 -> 1035910.7 | H22: ='FEC2020-2030'!H$2 -> 1041109.9 | I22: ='FEC2020-2030'!I$2 -> 1045837.3 | J22: ='FEC2020-2030'!J$2 -> 1028508.9 | ... X22: ='FEC2020-2030'!X$2 -> 967454.34
A23: Transformation input | B23: =HYPERLINK("#"&CELL("address",TI_E!$W$2),"TI_E") -> TI_E | C23: =TI_E!C$2 -> 1385181.8 | D23: =TI_E!D$2 -> 1399621.4 | E23: =TI_E!E$2 -> 1409382.2 | F23: =TI_E!F$2 -> 1444173 | G23: =TI_E!G$2 -> 1472583 | H23: =TI_E!H$2 -> 1471893.7 | I23: =TI_E!I$2 -> 1489133.3 | J23: =TI_E!J$2 -> 1481136.2 | ... X23: =TI_E!X$2 -> 1291089.3
A24: Electricity & heat generation | B24: =HYPERLINK("#"&CELL("address",TI_EHG_E!$W$2),"TI_EHG_E") -> TI_EHG_E | C24: =TI_EHG_E!C$2 -> 604018.59 | D24: =TI_EHG_E!D$2 -> 620989.38 | E24: =TI_EHG_E!E$2 -> 630130.49 | F24: =TI_EHG_E!F$2 -> 650462.94 | G24: =TI_EHG_E!G$2 -> 663245.53 | H24: =TI_EHG_E!H$2 -> 663486.81 | I24: =TI_EHG_E!I$2 -> 672114.01 | J24: =TI_EHG_E!J$2 -> 667636.79 | ... X24: =TI_EHG_E!X$2 -> 565926.16
A25: Electricity only | B25: =HYPERLINK("#"&CELL("address",TI_EHG_E_E!$W$2),"TI_EHG_E_E") -> TI_EHG_E_E | C25: =TI_EHG_E_E!C$2 -> 456710.69 | D25: =TI_EHG_E_E!D$2 -> 469181.3 | E25: =TI_EHG_E_E!E$2 -> 475266.74 | F25: =TI_EHG_E_E!F$2 -> 475034.57 | G25: =TI_EHG_E_E!G$2 -> 488254.23 | H25: =TI_EHG_E_E!H$2 -> 486142.86 | I25: =TI_EHG_E_E!I$2 -> 489573.74 | J25: =TI_EHG_E_E!J$2 -> 487319.15 | ... X25: =TI_EHG_E_E!X$2 -> 395862.62
A26: CHP | B26: =HYPERLINK("#"&CELL("address",TI_EHG_CHP_E!$W$2),"TI_EHG_CHP_E") -> TI_EHG_CHP_E | C26: =TI_EHG_CHP_E!C$2 -> 123915.62 | D26: =TI_EHG_CHP_E!D$2 -> 127904.81 | E26: =TI_EHG_CHP_E!E$2 -> 130703.97 | F26: =TI_EHG_CHP_E!F$2 -> 150109.96 | G26: =TI_EHG_CHP_E!G$2 -> 151150.05 | H26: =TI_EHG_CHP_E!H$2 -> 154141.37 | I26: =TI_EHG_CHP_E!I$2 -> 160368.83 | J26: =TI_EHG_CHP_E!J$2 -> 158646.77 | ... X26: =TI_EHG_CHP_E!X$2 -> 145739.13
A27: Heat only | B27: =HYPERLINK("#"&CELL("address",TI_EHG_H_E!$W$2),"TI_EHG_H_E") -> TI_EHG_H_E | C27: =TI_EHG_H_E!C$2 -> 19198.8 | D27: =TI_EHG_H_E!D$2 -> 19862.927 | E27: =TI_EHG_H_E!E$2 -> 19553.997 | F27: =TI_EHG_H_E!F$2 -> 20831.391 | G27: =TI_EHG_H_E!G$2 -> 18986.12 | H27: =TI_EHG_H_E!H$2 -> 18261.605 | I27: =TI_EHG_H_E!I$2 -> 17349.696 | J27: =TI_EHG_H_E!J$2 -> 17037.282 | ... X27: =TI_EHG_H_E!X$2 -> 19501.77
A28: Electrically driven heat pumps | B28: =HYPERLINK("#"&CELL("address",TI_EHG_EDHP!$W$2),"TI_EHG_EDHP") -> TI_EHG_EDHP | C28: =TI_EHG_EDHP!C$2 -> 191.6595 | D28: =TI_EHG_EDHP!D$2 -> 190.79966 | E28: =TI_EHG_EDHP!E$2 -> 184.09286 | F28: =TI_EHG_EDHP!F$2 -> 174.63457 | G28: =TI_EHG_EDHP!G$2 -> 165.52021 | H28: =TI_EHG_EDHP!H$2 -> 160.61909 | I28: =TI_EHG_EDHP!I$2 -> 142.30439 | J28: =TI_EHG_EDHP!J$2 -> 145.82889 | ... X28: =TI_EHG_EDHP!X$2 -> 176.35976
A29: Electric boilers | B29: =HYPERLINK("#"&CELL("address",TI_EHG_EB!$W$2),"TI_EHG_EB") -> TI_EHG_EB | C29: =TI_EHG_EB!C$2 -> 186.32846 | D29: =TI_EHG_EB!D$2 -> 154.34222 | E29: =TI_EHG_EB!E$2 -> 119.34652 | F29: =TI_EHG_EB!F$2 -> 48.581255 | G29: =TI_EHG_EB!G$2 -> 39.466896 | H29: =TI_EHG_EB!H$2 -> 31.126397 | I29: =TI_EHG_EB!I$2 -> 26.139295 | J29: =TI_EHG_EB!J$2 -> 26.05331 | ... X29: =TI_EHG_EB!X$2 -> 113.15709
A30: Electricity for pumped storage | B30: =HYPERLINK("#"&CELL("address",TI_EHG_EPS!$W$2),"TI_EHG_EPS") -> TI_EHG_EPS | C30: =TI_EHG_EPS!C$2 -> 3444.3825 | D30: =TI_EHG_EPS!D$2 -> 3359.4711 | E30: =TI_EHG_EPS!E$2 -> 3915.6841 | F30: =TI_EHG_EPS!F$2 -> 3827.8383 | G30: =TI_EHG_EPS!G$2 -> 3929.5396 | H30: =TI_EHG_EPS!H$2 -> 3994.8987 | I30: =TI_EHG_EPS!I$2 -> 3861.3125 | J30: =TI_EHG_EPS!J$2 -> 3675.8727 | ... X30: =TI_EHG_EPS!X$2 -> 3219.7359
A31: Derived heat for electricity production | B31: =HYPERLINK("#"&CELL("address",TI_EHG_DHEP!$W$2),"TI_EHG_DHEP") -> TI_EHG_DHEP | C31: =TI_EHG_DHEP!C$2 -> 371.1141 | D31: =TI_EHG_DHEP!D$2 -> 335.73138 | E31: =TI_EHG_DHEP!E$2 -> 386.66767 | F31: =TI_EHG_DHEP!F$2 -> 435.96062 | G31: =TI_EHG_DHEP!G$2 -> 720.6123 | H31: =TI_EHG_DHEP!H$2 -> 754.33568 | I31: =TI_EHG_DHEP!I$2 -> 791.98005 | J31: =TI_EHG_DHEP!J$2 -> 785.82984 | ... X31: =TI_EHG_DHEP!X$2 -> 1313.3889
A32: Coke ovens | B32: =HYPERLINK("#"&CELL("address",TI_CO_E!$W$2),"TI_CO_E") -> TI_CO_E | C32: =TI_CO_E!C$2 -> 45980.79 | D32: =TI_CO_E!D$2 -> 43845.765 | E32: =TI_CO_E!E$2 -> 42325.601 | F32: =TI_CO_E!F$2 -> 43592.605 | G32: =TI_CO_E!G$2 -> 43998.199 | H32: =TI_CO_E!H$2 -> 41814.701 | I32: =TI_CO_E!I$2 -> 44685.421 | J32: =TI_CO_E!J$2 -> 44799.526 | ... X32: =TI_CO_E!X$2 -> 29326.275
A33: Blast furnaces | B33: =HYPERLINK("#"&CELL("address",TI_BF_E!$W$2),"TI_BF_E") -> TI_BF_E | C33: =TI_BF_E!C$2 -> 36614.899 | D33: =TI_BF_E!D$2 -> 36169.858 | E33: =TI_BF_E!E$2 -> 35145.873 | F33: =TI_BF_E!F$2 -> 36624.456 | G33: =TI_BF_E!G$2 -> 36991.626 | H33: =TI_BF_E!H$2 -> 35412.154 | I33: =TI_BF_E!I$2 -> 35764.07 | J33: =TI_BF_E!J$2 -> 36250.257 | ... X33: =TI_BF_E!X$2 -> 31164.417
A34: Gas works | B34: =HYPERLINK("#"&CELL("address",TI_GW_E!$W$2),"TI_GW_E") -> TI_GW_E | C34: =TI_GW_E!C$2 -> 741.55297 | D34: =TI_GW_E!D$2 -> 657.93611 | E34: =TI_GW_E!E$2 -> 652.43646 | F34: =TI_GW_E!F$2 -> 651.45546 | G34: =TI_GW_E!G$2 -> 625.55838 | H34: =TI_GW_E!H$2 -> 609.71006 | I34: =TI_GW_E!I$2 -> 664.98186 | J34: =TI_GW_E!J$2 -> 562.79518 | ... X34: =TI_GW_E!X$2 -> 1.1306965
A35: Refineries & petrochemical industry | B35: =HYPERLINK("#"&CELL("address",TI_RPI_E!$W$2),"TI_RPI_E") -> TI_RPI_E | C35: =TI_RPI_E!C$2 -> 692193.35 | D35: =TI_RPI_E!D$2 -> 692330.44 | E35: =TI_RPI_E!E$2 -> 695421.7 | F35: =TI_RPI_E!F$2 -> 707035.47 | G35: =TI_RPI_E!G$2 -> 721381.98 | H35: =TI_RPI_E!H$2 -> 723425.27 | I35: =TI_RPI_E!I$2 -> 727357.52 | J35: =TI_RPI_E!J$2 -> 721427.65 | ... X35: =TI_RPI_E!X$2 -> 638244.56
A36: Refinery intake | B36: =HYPERLINK("#"&CELL("address",TI_RPI_RI_E!$W$2),"TI_RPI_RI_E") -> TI_RPI_RI_E | C36: =TI_RPI_RI_E!C$2 -> 623669.45 | D36: =TI_RPI_RI_E!D$2 -> 626320.99 | E36: =TI_RPI_RI_E!E$2 -> 620043.89 | F36: =TI_RPI_RI_E!F$2 -> 633314.65 | G36: =TI_RPI_RI_E!G$2 -> 644612.67 | H36: =TI_RPI_RI_E!H$2 -> 646854.5 | I36: =TI_RPI_RI_E!I$2 -> 648954 | J36: =TI_RPI_RI_E!J$2 -> 641859.53 | ... X36: =TI_RPI_RI_E!X$2 -> 525567.9
A37: Backflows from petrochemical industry | B37: =HYPERLINK("#"&CELL("address",TI_RPI_BPI_E!$W$2),"TI_RPI_BPI_E") -> TI_RPI_BPI_E | C37: =TI_RPI_BPI_E!C$2 -> 15723.231 | D37: =TI_RPI_BPI_E!D$2 -> 15204.244 | E37: =TI_RPI_BPI_E!E$2 -> 15415.996 | F37: =TI_RPI_BPI_E!F$2 -> 15850.398 | G37: =TI_RPI_BPI_E!G$2 -> 15934.655 | H37: =TI_RPI_BPI_E!H$2 -> 16114.535 | I37: =TI_RPI_BPI_E!I$2 -> 15997.74 | J37: =TI_RPI_BPI_E!J$2 -> 16192.054 | ... X37: =TI_RPI_BPI_E!X$2 -> 15254.407
A38: Products transferred | B38: =HYPERLINK("#"&CELL("address",TI_RPI_PT_E!$W$2),"TI_RPI_PT_E") -> TI_RPI_PT_E | C38: =TI_RPI_PT_E!C$2 -> 20720.092 | D38: =TI_RPI_PT_E!D$2 -> 17982.263 | E38: =TI_RPI_PT_E!E$2 -> 24110.062 | F38: =TI_RPI_PT_E!F$2 -> 18909.377 | G38: =TI_RPI_PT_E!G$2 -> 18630.412 | H38: =TI_RPI_PT_E!H$2 -> 16684.339 | I38: =TI_RPI_PT_E!I$2 -> 20099.012 | J38: =TI_RPI_PT_E!J$2 -> 21726.134 | ... X38: =TI_RPI_PT_E!X$2 -> 30263.849
A39: Interproduct transfers | B39: =HYPERLINK("#"&CELL("address",TI_RPI_IT_E!$W$2),"TI_RPI_IT_E") -> TI_RPI_IT_E | C39: =TI_RPI_IT_E!C$2 -> 5747.4937 | D39: =TI_RPI_IT_E!D$2 -> 6538.5916 | E39: =TI_RPI_IT_E!E$2 -> 7351.4547 | F39: =TI_RPI_IT_E!F$2 -> 10436.036 | G39: =TI_RPI_IT_E!G$2 -> 13129.328 | H39: =TI_RPI_IT_E!H$2 -> 15420.983 | I39: =TI_RPI_IT_E!I$2 -> 14243.144 | J39: =TI_RPI_IT_E!J$2 -> 13669.686 | ... X39: =TI_RPI_IT_E!X$2 -> 37737.857
A40: Direct use | B40: =HYPERLINK("#"&CELL("address",TI_RPI_DU_E!$W$2),"TI_RPI_DU_E") -> TI_RPI_DU_E | C40: =TI_RPI_DU_E!C$2 -> 10731.407 | D40: =TI_RPI_DU_E!D$2 -> 11218.237 | E40: =TI_RPI_DU_E!E$2 -> 13193.352 | F40: =TI_RPI_DU_E!F$2 -> 12764.91 | G40: =TI_RPI_DU_E!G$2 -> 13230.107 | H40: =TI_RPI_DU_E!H$2 -> 12536.956 | I40: =TI_RPI_DU_E!I$2 -> 12445.815 | J40: =TI_RPI_DU_E!J$2 -> 11896.975 | ... X40: =TI_RPI_DU_E!X$2 -> 14012.228
...

Sheet PPRD
A1: Primary production | B1: PPRD | C1: 2000 | D1: 2001 | E1: 2002 | F1: 2003 | G1: 2004 | H1: 2005 | I1: 2006 | J1: 2007 | K1: 2008 | L1: 2009 | M1: 2010 | N1: 2011 | O1: 2012 | P1: 2013 | Q1: 2014 | R1: 2015 | S1: 2016 | T1: 2017 | U1: 2018 | V1: 2019 | W1: 2020 | X1: 2021
A2: Total | B2: TOTAL | C2: =SUM(C3,C17,C22,C25,C26,C51,C52,C71,C74,C75,C76) -> 675865.22 | D2: =SUM(D3,D17,D22,D25,D26,D51,D52,D71,D74,D75,D76) -> 685360.73 | E2: =SUM(E3,E17,E22,E25,E26,E51,E52,E71,E74,E75,E76) -> 689533.44 | F2: =SUM(F3,F17,F22,F25,F26,F51,F52,F71,F74,F75,F76) -> 694347.83 | G2: =SUM(G3,G17,G22,G25,G26,G51,G52,G71,G74,G75,G76) -> 710302.95 | H2: =SUM(H3,H17,H22,H25,H26,H51,H52,H71,H74,H75,H76) -> 703209.69 | I2: =SUM(I3,I17,I22,I25,I26,I51,I52,I71,I74,I75,I76) -> 703762.09 | J2: =SUM(J3,J17,J22,J25,J26,J51,J52,J71,J74,J75,J76) -> 690378.62 | ... X2: =SUM(X3,X17,X22,X25,X26,X51,X52,X71,X74,X75,X76) -> 598126.74
A3: Solid fossil fuels | B3: C0000X0350-0370 | C3: =SUM(C4,C8,C11) -> 189777.52 | D3: =SUM(D4,D8,D11) -> 187255.72 | E3: =SUM(E4,E8,E11) -> 186021.87 | F3: =SUM(F4,F8,F11) -> 184797.34 | G3: =SUM(G4,G8,G11) -> 180931.8 | H3: =SUM(H4,H8,H11) -> 176851.48 | I3: =SUM(I4,I8,I11) -> 172733.68 | J3: =SUM(J4,J8,J11) -> 169273.73 | ... X3: =SUM(X4,X8,X11) -> 90966.491
A4: Hard coal | B4: C0100 | C4: =SUM(C5:C7) -> 99737.751 | D4: =SUM(D5:D7) -> 94607.394 | E4: =SUM(E5:E7) -> 92230.542 | F4: =SUM(F5:F7) -> 90817.471 | G4: =SUM(G5:G7) -> 87454.779 | H4: =SUM(H5:H7) -> 86314.766 | I4: =SUM(I5:I7) -> 82004.232 | J4: =SUM(J5:J7) -> 77738.701 | ... X4: =SUM(X5:X7) -> 33163.082
A5: Anthracite | B5: C0110 | C5: 0 | D5: 0 | E5: 0 | F5: 1347.1546 | G5: 3138.3833 | H5: 3205.9152 | I5: 3042.5115 | J5: 2971.2023 | K5: 2760.4196 | L5: 3101.2979 | M5: 2798.4771 | N5: 2569.2797 | O5: 2439.5878 | P5: 1784.5702 | Q5: 2058.0728 | R5: 1557.7782 | S5: 1149.0843 | T5: 908.88745 | U5: 732.15537 | V5: 0 | W5: 0 | X5: 0
A6: Coking coal | B6: C0121 | C6: 30685.891 | D6: 29255.277 | E6: 28790.867 | F6: 28677.724 | G6: 28178.028 | H6: 25300.127 | I6: 24655.139 | J6: 24369.673 | K6: 20928.118 | L6: 16346.276 | M6: 17969.499 | N6: 16681.154 | O6: 16165.533 | P6: 14992.27 | Q6: 15099.456 | R6: 14614.988 | S6: 13128.826 | T6: 12407.597 | U6: 11019.176 | V6: 9893.9624 | W6: 9367.2893 | X6: 9902.3477
A7: Other bituminous coal | B7: C0129 | C7: 69051.86 | D7: 65352.117 | E7: 63439.675 | F7: 60792.593 | G7: 56138.368 | H7: 57808.723 | I7: 54306.582 | J7: 50397.826 | K7: 48252.777 | L7: 44554.339 | M7: 42006.146 | N7: 41231.256 | O7: 42852.314 | P7: 39358.232 | Q7: 36419.456 | R7: 35900.003 | S7: 33936.641 | T7: 30684.861 | U7: 28999.365 | V7: 27171.27 | W7: 23213.606 | X7: 23260.735
A8: Brown coal | B8: C0200 | C8: =SUM(C9:C10) -> 90039.771 | D8: =SUM(D9:D10) -> 92648.326 | E8: =SUM(E9:E10) -> 93791.331 | F8: =SUM(F9:F10) -> 93979.874 | G8: =SUM(G9:G10) -> 93477.02 | H8: =SUM(H9:H10) -> 90536.719 | I8: =SUM(I9:I10) -> 90729.447 | J8: =SUM(J9:J10) -> 91535.031 | ... X8: =SUM(X9:X10) -> 57803.409
A9: Sub-bituminous coal | B9: C0210 | C9: 1054.1982 | D9: 1008.4001 | E9: 1092.6708 | F9: 958.45727 | G9: 983.0693 | H9: 978.52648 | I9: 1018.1017 | J9: 885.20834 | K9: 900.31212 | L9: 785.82175 | M9: 767.77171 | N9: 771.21608 | O9: 770.20937 | P9: 605.27713 | Q9: 448.65193 | R9: 427.30473 | S9: 235.73138 | T9: 586.03801 | U9: 522.10378 | V9: 0 | W9: 0 | X9: 0
A10: Lignite | B10: C0220 | C10: 88985.573 | D10: 91639.926 | E10: 92698.661 | F10: 93021.417 | G10: 92493.951 | H10: 89558.192 | I10: 89711.345 | J10: 90649.822 | K10: 88212.575 | L10: 85070.69 | M10: 83079.525 | N10: 88166.586 | O10: 88793.819 | P10: 84069.907 | Q10: 81201.76 | R10: 81280.701 | S10: 76219.087 | T10: 78041.292 | U10: 74817.676 | V10: 63000.54 | W10: 51009.18 | X10: 57803.409
A11: Coal products | B11: C0300 | C11: =SUM(C12:C16) -> 0 | D11: =SUM(D12:D16) -> 0 | E11: =SUM(E12:E16) -> 0 | F11: =SUM(F12:F16) -> 0 | G11: =SUM(G12:G16) -> 0 | H11: =SUM(H12:H16) -> 0 | I11: =SUM(I12:I16) -> 0 | J11: =SUM(J12:J16) -> 0 | ... X11: =SUM(X12:X16) -> 0
A12: Patent fuel | B12: C0320 | C12: 0 | D12: 0 | E12: 0 | F12: 0 | G12: 0 | H12: 0 | I12: 0 | J12: 0 | K12: 0 | L12: 0 | M12: 0 | N12: 0 | O12: 0 | P12: 0 | Q12: 0 | R12: 0 | S12: 0 | T12: 0 | U12: 0 | V12: 0 | W12: 0 | X12: 0
A13: Coke oven coke | B13: C0311 | C13: 0 | D13: 0 | E13: 0 | F13: 0 | G13: 0 | H13: 0 | I13: 0 | J13: 0 | K13: 0 | L13: 0 | M13: 0 | N13: 0 | O13: 0 | P13: 0 | Q13: 0 | R13: 0 | S13: 0 | T13: 0 | U13: 0 | V13: 0 | W13: 0 | X13: 0
A14: Gas coke | B14: C0312 | C14: 0 | D14: 0 | E14: 0 | F14: 0 | G14: 0 | H14: 0 | I14: 0 | J14: 0 | K14: 0 | L14: 0 | M14: 0 | N14: 0 | O14: 0 | P14: 0 | Q14: 0 | R14: 0 | S14: 0 | T14: 0 | U14: 0 | V14: 0 | W14: 0 | X14: 0
A15: Coal tar | B15: C0340 | C15: 0 | D15: 0 | E15: 0 | F15: 0 | G15: 0 | H15: 0 | I15: 0 | J15: 0 | K15: 0 | L15: 0 | M15: 0 | N15: 0 | O15: 0 | P15: 0 | Q15: 0 | R15: 0 | S15: 0 | T15: 0 | U15: 0 | V15: 0 | W15: 0 | X15: 0
A16: Brown coal briquettes | B16: C0330 | C16: 0 | D16: 0 | E16: 0 | F16: 0 | G16: 0 | H16: 0 | I16: 0 | J16: 0 | K16: 0 | L16: 0 | M16: 0 | N16: 0 | O16: 0 | P16: 0 | Q16: 0 | R16: 0 | S16: 0 | T16: 0 | U16: 0 | V16: 0 | W16: 0 | X16: 0
A17: Manufactured gases | B17: C0350-0370 | C17: =SUM(C18:C21) -> 0 | D17: =SUM(D18:D21) -> 0 | E17: =SUM(E18:E21) -> 0 | F17: =SUM(F18:F21) -> 0 | G17: =SUM(G18:G21) -> 0 | H17: =SUM(H18:H21) -> 0 | I17: =SUM(I18:I21) -> 0 | J17: =SUM(J18:J21) -> 0 | ... X17: =SUM(X18:X21) -> 0
A18: Gas works gas | B18: C0360 | C18: 0 | D18: 0 | E18: 0 | F18: 0 | G18: 0 | H18: 0 | I18: 0 | J18: 0 | K18: 0 | L18: 0 | M18: 0 | N18: 0 | O18: 0 | P18: 0 | Q18: 0 | R18: 0 | S18: 0 | T18: 0 | U18: 0 | V18: 0 | W18: 0 | X18: 0
A19: Coke oven gas | B19: C0350 | C19: 0 | D19: 0 | E19: 0 | F19: 0 | G19: 0 | H19: 0 | I19: 0 | J19: 0 | K19: 0 | L19: 0 | M19: 0 | N19: 0 | O19: 0 | P19: 0 | Q19: 0 | R19: 0 | S19: 0 | T19: 0 | U19: 0 | V19: 0 | W19: 0 | X19: 0
A20: Blast furnace gas | B20: C0371 | C20: 0 | D20: 0 | E20: 0 | F20: 0 | G20: 0 | H20: 0 | I20: 0 | J20: 0 | K20: 0 | L20: 0 | M20: 0 | N20: 0 | O20: 0 | P20: 0 | Q20: 0 | R20: 0 | S20: 0 | T20: 0 | U20: 0 | V20: 0 | W20: 0 | X20: 0
A21: Other recovered gases | B21: C0379 | C21: 0 | D21: 0 | E21: 0 | F21: 0 | G21: 0 | H21: 0 | I21: 0 | J21: 0 | K21: 0 | L21: 0 | M21: 0 | N21: 0 | O21: 0 | P21: 0 | Q21: 0 | R21: 0 | S21: 0 | T21: 0 | U21: 0 | V21: 0 | W21: 0 | X21: 0
A22: Peat and peat products | B22: P1000 | C22: =SUM(C23:C24) -> 2356.0899 | D22: =SUM(D23:D24) -> 2893.0291 | E22: =SUM(E23:E24) -> 3269.5747 | F22: =SUM(F23:F24) -> 3260.872 | G22: =SUM(G23:G24) -> 2179.8077 | H22: =SUM(H23:H24) -> 3328.5882 | I22: =SUM(I23:I24) -> 4329.3129 | J22: =SUM(J23:J24) -> 2022.6701 | ... X22: =SUM(X23:X24) -> 447.99828
A23: Peat | B23: P1100 | C23: 2356.0899 | D23: 2893.0291 | E23: 3269.5747 | F23: 3260.872 | G23: 2179.8077 | H23: 3328.5882 | I23: 4329.3129 | J23: 2022.6701 | K23: 2041.2907 | L23: 3086.315 | M23: 3156.9915 | N23: 2773.2573 | O23: 1513.4501 | P23: 3305.51 | Q23: 2814.7981 | R23: 1768.8083 | S23: 1559.5444 | T23: 1603.7806 | U23: 2865.8622 | V23: 1573.8372 | W23: 779.57231 | X23: 447.99828
A24: Peat products | B24: P1200 | C24: 0 | D24: 0 | E24: 0 | F24: 0 | G24: 0 | H24: 0 | I24: 0 | J24: 0 | K24: 0 | L24: 0 | M24: 0 | N24: 0 | O24: 0 | P24: 0 | Q24: 0 | R24: 0 | S24: 0 | T24: 0 | U24: 0 | V24: 0 | W24: 0 | X24: 0
A25: Oil shale and oil sands | B25: S2000 | C25: 2788.5256 | D25: 2771.5089 | E25: 2756.5676 | F25: 3177.151 | G25: 3231.9274 | H25: 3262.9112 | I25: 3248.042 | J25: 3851.958 | K25: 3395.8366 | L25: 2849.089 | M25: 3975.2726 | N25: 4019.89 | O25: 3655.1006 | P25: 4111.8911 | Q25: 4014.4894 | R25: 3514.8617 | S25: 3716.0374 | T25: 4293.097 | U25: 4179.5801 | V25: 3177.7143 | W25: 2516.5557 | X25: 2428.3206
A26: Oil and petroleum products | B26: O4000XBIO | C26: =SUM(C27,C33) -> 44566.879 | D26: =SUM(D27,D33) -> 42388.784 | E26: =SUM(E27,E33) -> 47302.886 | F26: =SUM(F27,F33) -> 47393.579 | G26: =SUM(G27,G33) -> 46923.635 | H26: =SUM(H27,H33) -> 45881.248 | I26: =SUM(I27,I33) -> 42877.687 | J26: =SUM(J27,J33) -> 40664.728 | ... X26: =SUM(X27,X33) -> 20149.572
A27: Crude oil, NGL, refinery feedstocks, additives and oxygenates and other hydrocarbons (excluding biofuel portion) | B27: O4100_TOT_4200-4500XBIO | C27: =SUM(C28:C32) -> 44566.879 | D27: =SUM(D28:D32) -> 42388.784 | E27: =SUM(E28:E32) -> 47302.886 | F27: =SUM(F28:F32) -> 47393.579 | G27: =SUM(G28:G32) -> 46923.635 | H27: =SUM(H28:H32) -> 45881.248 | I27: =SUM(I28:I32) -> 42877.687 | J27: =SUM(J28:J32) -> 40664.728 | ... X27: =SUM(X28:X32) -> 20149.572
A28: Crude oil | B28: O4100_TOT | C28: 39980.137 | D28: 38446.782 | E28: 41985.644 | F28: 42051.999 | G28: 42493.121 | H28: 40701.601 | I28: 37731.808 | J28: 36216.615 | K28: 33728.75 | L28: 30808.107 | M28: 29624.305 | N28: 28303.734 | O28: 27274.6 | P28: 26680.398 | Q28: 26481.386 | R28: 25479.532 | S28: 22377.327 | T28: 22059.905 | U28: 21388.427 | V28: 19797.012 | W28: 18764.891 | X28: 17630.139
A29: Natural gas liquids | B29: O4200 | C29: 2376.1512 | D29: 2264.8905 | E29: 2263.0818 | F29: 2062.3949 | G29: 2125.2345 | H29: 1998.4096 | I29: 1774.0505 | J29: 1501.3648 | K29: 1380.8696 | L29: 1276.6996 | M29: 1212.0833 | N29: 1099.7702 | O29: 1017.7543 | P29: 919.48126 | Q29: 829.34764 | R29: 864.88512 | S29: 783.90129 | T29: 766.25959 | U29: 654.9049 | V29: 563.61359 | W29: 495.54729 | X29: 483.49415
A30: Refinery feedstocks | B30: O4300 | C30: 0 | D30: 0 | E30: 0 | F30: 0 | G30: 0 | H30: 0 | I30: 0 | J30: 0 | K30: 0 | L30: 0 | M30: 0 | N30: 0 | O30: 0 | P30: 0 | Q30: 0 | R30: 0 | S30: 0 | T30: 0 | U30: 0 | V30: 0 | W30: 0 | X30: 0
A31: Additives and oxygenates (excluding biofuel portion) | B31: O4400X4410 | C31: 2011.6929 | D31: 1499.4844 | E31: 1607.6497 | F31: 1840.795 | G31: 2042.3696 | H31: 2620.9058 | I31: 2618.6277 | J31: 2689.5106 | K31: 2899.1518 | L31: 2591.2393 | M31: 2267.1948 | N31: 2024.9371 | O31: 1904.5077 | P31: 1792.4235 | Q31: 1687.1917 | R31: 1922.0882 | S31: 2087.9265 | T31: 2230.8189 | U31: 2481.2935 | V31: 2314.1357 | W31: 2032.0997 | X31: 1954.7641
A32: Other hydrocarbons | B32: O4500 | C32: 198.89828 | D32: 177.62657 | E32: 1446.5105 | F32: 1438.3897 | G32: 262.90963 | H32: 560.33242 | I32: 753.20052 | J32: 257.23706 | K32: 0 | L32: 0 | M32: 0 | N32: 5.7323302 | O32: 64.966122 | P32: 0 | Q32: 3.8214961 | R32: 5.7323302 | S32: 0 | T32: 0 | U32: 0 | V32: 0 | W32: 32.714617 | X32: 81.174635
A33: Oil products (excluding biofuel portion) | B33: O4600XBIO | C33: =SUM(C34:C50) -> 0 | D33: =SUM(D34:D50) -> 0 | E33: =SUM(E34:E50) -> 0 | F33: =SUM(F34:F50) -> 0 | G33: =SUM(G34:G50) -> 0 | H33: =SUM(H34:H50) -> 0 | I33: =SUM(I34:I50) -> 0 | J33: =SUM(J34:J50) -> 0 | ... X33: =SUM(X34:X50) -> 0
A34: Refinery gas | B34: O4610 | C34: 0 | D34: 0 | E34: 0 | F34: 0 | G34: 0 | H34: 0 | I34: 0 | J34: 0 | K34: 0 | L34: 0 | M34: 0 | N34: 0 | O34: 0 | P34: 0 | Q34: 0 | R34: 0 | S34: 0 | T34: 0 | U34: 0 | V34: 0 | W34: 0 | X34: 0
A35: Ethane | B35: O4620 | C35: 0 | D35: 0 | E35: 0 | F35: 0 | G35: 0 | H35: 0 | I35: 0 | J35: 0 | K35: 0 | L35: 0 | M35: 0 | N35: 0 | O35: 0 | P35: 0 | Q35: 0 | R35: 0 | S35: 0 | T35: 0 | U35: 0 | V35: 0 | W35: 0 | X35: 0
A36: Liquefied petroleum gases | B36: O4630 | C36: 0 | D36: 0 | E36: 0 | F36: 0 | G36: 0 | H36: 0 | I36: 0 | J36: 0 | K36: 0 | L36: 0 | M36: 0 | N36: 0 | O36: 0 | P36: 0 | Q36: 0 | R36: 0 | S36: 0 | T36: 0 | U36: 0 | V36: 0 | W36: 0 | X36: 0
A37: Motor gasoline (excluding biofuel portion) | B37: O4652XR5210B | C37: 0 | D37: 0 | E37: 0 | F37: 0 | G37: 0 | H37: 0 | I37: 0 | J37: 0 | K37: 0 | L37: 0 | M37: 0 | N37: 0 | O37: 0 | P37: 0 | Q37: 0 | R37: 0 | S37: 0 | T37: 0 | U37: 0 | V37: 0 | W37: 0 | X37: 0
A38: Aviation gasoline | B38: O4651 | C38: 0 | D38: 0 | E38: 0 | F38: 0 | G38: 0 | H38: 0 | I38: 0 | J38: 0 | K38: 0 | L38: 0 | M38: 0 | N38: 0 | O38: 0 | P38: 0 | Q38: 0 | R38: 0 | S38: 0 | T38: 0 | U38: 0 | V38: 0 | W38: 0 | X38: 0
A39: Gasoline-type jet fuel | B39: O4653 | C39: 0 | D39: 0 | E39: 0 | F39: 0 | G39: 0 | H39: 0 | I39: 0 | J39: 0 | K39: 0 | L39: 0 | M39: 0 | N39: 0 | O39: 0 | P39: 0 | Q39: 0 | R39: 0 | S39: 0 | T39: 0 | U39: 0 | V39: 0 | W39: 0 | X39: 0
A40: Kerosene-type jet fuel (excluding biofuel portion) | B40: O4661XR5230B | C40: 0 | D40: 0 | E40: 0 | F40: 0 | G40: 0 | H40: 0 | I40: 0 | J40: 0 | K40: 0 | L40: 0 | M40: 0 | N40: 0 | O40: 0 | P40: 0 | Q40: 0 | R40: 0 | S40: 0 | T40: 0 | U40: 0 | V40: 0 | W40: 0 | X40: 0
...

Sheet RCV_RCY
A1: Recovered & recycled products | B1: RCV_RCY | C1: 2000 | D1: 2001 | E1: 2002 | F1: 2003 | G1: 2004 | H1: 2005 | I1: 2006 | J1: 2007 | K1: 2008 | L1: 2009 | M1: 2010 | N1: 2011 | O1: 2012 | P1: 2013 | Q1: 2014 | R1: 2015 | S1: 2016 | T1: 2017 | U1: 2018 | V1: 2019 | W1: 2020 | X1: 2021
A2: Total | B2: TOTAL | C2: =SUM(C3,C17,C22,C25,C26,C51,C52,C71,C74,C75,C76) -> 2215.6619 | D2: =SUM(D3,D17,D22,D25,D26,D51,D52,D71,D74,D75,D76) -> 1861.5356 | E2: =SUM(E3,E17,E22,E25,E26,E51,E52,E71,E74,E75,E76) -> 2024.4978 | F2: =SUM(F3,F17,F22,F25,F26,F51,F52,F71,F74,F75,F76) -> 2142.2032 | G2: =SUM(G3,G17,G22,G25,G26,G51,G52,G71,G74,G75,G76) -> 3242.3794 | H2: =SUM(H3,H17,H22,H25,H26,H51,H52,H71,H74,H75,H76) -> 1835.6799 | I2: =SUM(I3,I17,I22,I25,I26,I51,I52,I71,I74,I75,I76) -> 1740.9143 | J2: =SUM(J3,J17,J22,J25,J26,J51,J52,J71,J74,J75,J76) -> 1928.6833 | ... X2: =SUM(X3,X17,X22,X25,X26,X51,X52,X71,X74,X75,X76) -> 1447.3628
A3: Solid fossil fuels | B3: C0000X0350-0370 | C3: =SUM(C4,C8,C11) -> 1189.6704 | D3: =SUM(D4,D8,D11) -> 712.2681 | E3: =SUM(E4,E8,E11) -> 878.4761 | F3: =SUM(F4,F8,F11) -> 1043.5072 | G3: =SUM(G4,G8,G11) -> 2228.7135 | H3: =SUM(H4,H8,H11) -> 923.57687 | I3: =SUM(I4,I8,I11) -> 808.41161 | J3: =SUM(J4,J8,J11) -> 905.24678 | ... X3: =SUM(X4,X8,X11) -> 265.76406
A4: Hard coal | B4: C0100 | C4: =SUM(C5:C7) -> 984.09579 | D4: =SUM(D5:D7) -> 602.46234 | E4: =SUM(E5:E7) -> 787.70774 | F4: =SUM(F5:F7) -> 975.82442 | G4: =SUM(G5:G7) -> 2133.7477 | H4: =SUM(H5:H7) -> 866.38753 | I4: =SUM(I5:I7) -> 793.19613 | J4: =SUM(J5:J7) -> 905.24678 | ... X4: =SUM(X5:X7) -> 227.22158
A5: Anthracite | B5: C0110 | C5: 0 | D5: 0 | E5: 0 | F5: 0 | G5: 0 | H5: 0 | I5: 0 | J5: 0 | K5: 0 | L5: 0 | M5: 0 | N5: 0 | O5: 0 | P5: 0 | Q5: 0 | R5: 0 | S5: 0 | T5: 0 | U5: 0 | V5: 0 | W5: 0 | X5: 0
A6: Coking coal | B6: C0121 | C6: 0 | D6: 0 | E6: 0 | F6: 0 | G6: 0 | H6: 0 | I6: 0 | J6: 0 | K6: 0 | L6: 0 | M6: 0 | N6: 11.502752 | O6: 25.059501 | P6: 0 | Q6: 0 | R6: 0 | S6: 0 | T6: 0 | U6: 0 | V6: 0 | W6: 0 | X6: 0
A7: Other bituminous coal | B7: C0129 | C7: 984.09579 | D7: 602.46234 | E7: 787.70774 | F7: 975.82442 | G7: 2133.7477 | H7: 866.38753 | I7: 793.19613 | J7: 905.24678 | K7: 597.18882 | L7: 501.69089 | M7: 654.70937 | N7: 696.1104 | O7: 680.88022 | P7: 660.9129 | Q7: 821.23233 | R7: 483.42253 | S7: 429.56174 | T7: 467.52769 | U7: 411.38693 | V7: 339.62717 | W7: 237.53405 | X7: 227.22158
A8: Brown coal | B8: C0200 | C8: =SUM(C9:C10) -> 205.57463 | D8: =SUM(D9:D10) -> 109.80576 | E8: =SUM(E9:E10) -> 90.768358 | F8: =SUM(F9:F10) -> 67.682803 | G8: =SUM(G9:G10) -> 94.965778 | H8: =SUM(H9:H10) -> 57.189338 | I8: =SUM(I9:I10) -> 15.215477 | J8: =SUM(J9:J10) -> 0 | ... X8: =SUM(X9:X10) -> 38.542476
A9: Sub-bituminous coal | B9: C0210 | C9: 205.57463 | D9: 109.80576 | E9: 90.768358 | F9: 67.682803 | G9: 94.965778 | H9: 57.189338 | I9: 15.215477 | J9: 0 | K9: 0 | L9: 0 | M9: 0 | N9: 0 | O9: 0 | P9: 16.782115 | Q9: 17.47601 | R9: 14.504815 | S9: 24.357782 | T9: 22.73147 | U9: 27.661307 | V9: 29.481513 | W9: 31.030954 | X9: 24.452537
A10: Lignite | B10: C0220 | C10: 0 | D10: 0 | E10: 0 | F10: 0 | G10: 0 | H10: 0 | I10: 0 | J10: 0 | K10: 45.694325 | L10: 0 | M10: 0 | N10: 0 | O10: 0 | P10: 0 | Q10: 0 | R10: 0 | S10: 0 | T10: 0 | U10: 62.43104 | V10: 57.554256 | W10: 42.551935 | X10: 14.08994
A11: Coal products | B11: C0300 | C11: =SUM(C12:C16) -> 0 | D11: =SUM(D12:D16) -> 0 | E11: =SUM(E12:E16) -> 0 | F11: =SUM(F12:F16) -> 0 | G11: =SUM(G12:G16) -> 0 | H11: =SUM(H12:H16) -> 0 | I11: =SUM(I12:I16) -> 0 | J11: =SUM(J12:J16) -> 0 | ... X11: =SUM(X12:X16) -> 0
A12: Patent fuel | B12: C0320 | C12: 0 | D12: 0 | E12: 0 | F12: 0 | G12: 0 | H12: 0 | I12: 0 | J12: 0 | K12: 0 | L12: 0 | M12: 0 | N12: 0 | O12: 0 | P12: 0 | Q12: 0 | R12: 0 | S12: 0 | T12: 0 | U12: 0 | V12: 0 | W12: 0 | X12: 0
A13: Coke oven coke | B13: C0311 | C13: 0 | D13: 0 | E13: 0 | F13: 0 | G13: 0 | H13: 0 | I13: 0 | J13: 0 | K13: 0 | L13: 0 | M13: 0 | N13: 0 | O13: 0 | P13: 0 | Q13: 0 | R13: 0 | S13: 0 | T13: 0 | U13: 0 | V13: 0 | W13: 0 | X13: 0
A14: Gas coke | B14: C0312 | C14: 0 | D14: 0 | E14: 0 | F14: 0 | G14: 0 | H14: 0 | I14: 0 | J14: 0 | K14: 0 | L14: 0 | M14: 0 | N14: 0 | O14: 0 | P14: 0 | Q14: 0 | R14: 0 | S14: 0 | T14: 0 | U14: 0 | V14: 0 | W14: 0 | X14: 0
A15: Coal tar | B15: C0340 | C15: 0 | D15: 0 | E15: 0 | F15: 0 | G15: 0 | H15: 0 | I15: 0 | J15: 0 | K15: 0 | L15: 0 | M15: 0 | N15: 0 | O15: 0 | P15: 0 | Q15: 0 | R15: 0 | S15: 0 | T15: 0 | U15: 0 | V15: 0 | W15: 0 | X15: 0
A16: Brown coal briquettes | B16: C0330 | C16: 0 | D16: 0 | E16: 0 | F16: 0 | G16: 0 | H16: 0 | I16: 0 | J16: 0 | K16: 0 | L16: 0 | M16: 0 | N16: 0 | O16: 0 | P16: 0 | Q16: 0 | R16: 0 | S16: 0 | T16: 0 | U16: 0 | V16: 0 | W16: 0 | X16: 0
A17: Manufactured gases | B17: C0350-0370 | C17: =SUM(C18:C21) -> 0 | D17: =SUM(D18:D21) -> 0 | E17: =SUM(E18:E21) -> 0 | F17: =SUM(F18:F21) -> 0 | G17: =SUM(G18:G21) -> 0 | H17: =SUM(H18:H21) -> 0 | I17: =SUM(I18:I21) -> 0 | J17: =SUM(J18:J21) -> 0 | ... X17: =SUM(X18:X21) -> 0
A18: Gas works gas | B18: C0360 | C18: 0 | D18: 0 | E18: 0 | F18: 0 | G18: 0 | H18: 0 | I18: 0 | J18: 0 | K18: 0 | L18: 0 | M18: 0 | N18: 0 | O18: 0 | P18: 0 | Q18: 0 | R18: 0 | S18: 0 | T18: 0 | U18: 0 | V18: 0 | W18: 0 | X18: 0
A19: Coke oven gas | B19: C0350 | C19: 0 | D19: 0 | E19: 0 | F19: 0 | G19: 0 | H19: 0 | I19: 0 | J19: 0 | K19: 0 | L19: 0 | M19: 0 | N19: 0 | O19: 0 | P19: 0 | Q19: 0 | R19: 0 | S19: 0 | T19: 0 | U19: 0 | V19: 0 | W19: 0 | X19: 0
A20: Blast furnace gas | B20: C0371 | C20: 0 | D20: 0 | E20: 0 | F20: 0 | G20: 0 | H20: 0 | I20: 0 | J20: 0 | K20: 0 | L20: 0 | M20: 0 | N20: 0 | O20: 0 | P20: 0 | Q20: 0 | R20: 0 | S20: 0 | T20: 0 | U20: 0 | V20: 0 | W20: 0 | X20: 0
A21: Other recovered gases | B21: C0379 | C21: 0 | D21: 0 | E21: 0 | F21: 0 | G21: 0 | H21: 0 | I21: 0 | J21: 0 | K21: 0 | L21: 0 | M21: 0 | N21: 0 | O21: 0 | P21: 0 | Q21: 0 | R21: 0 | S21: 0 | T21: 0 | U21: 0 | V21: 0 | W21: 0 | X21: 0
A22: Peat and peat products | B22: P1000 | C22: =SUM(C23:C24) -> 0 | D22: =SUM(D23:D24) -> 0 | E22: =SUM(E23:E24) -> 0 | F22: =SUM(F23:F24) -> 0 | G22: =SUM(G23:G24) -> 0 | H22: =SUM(H23:H24) -> 0 | I22: =SUM(I23:I24) -> 0 | J22: =SUM(J23:J24) -> 0 | ... X22: =SUM(X23:X24) -> 0
A23: Peat | B23: P1100 | C23: 0 | D23: 0 | E23: 0 | F23: 0 | G23: 0 | H23: 0 | I23: 0 | J23: 0 | K23: 0 | L23: 0 | M23: 0 | N23: 0 | O23: 0 | P23: 0 | Q23: 0 | R23: 0 | S23: 0 | T23: 0 | U23: 0 | V23: 0 | W23: 0 | X23: 0
A24: Peat products | B24: P1200 | C24: 0 | D24: 0 | E24: 0 | F24: 0 | G24: 0 | H24: 0 | I24: 0 | J24: 0 | K24: 0 | L24: 0 | M24: 0 | N24: 0 | O24: 0 | P24: 0 | Q24: 0 | R24: 0 | S24: 0 | T24: 0 | U24: 0 | V24: 0 | W24: 0 | X24: 0
A25: Oil shale and oil sands | B25: S2000 | C25: 0 | D25: 0 | E25: 0 | F25: 0 | G25: 0 | H25: 0 | I25: 0 | J25: 0 | K25: 0 | L25: 0 | M25: 0 | N25: 0 | O25: 0 | P25: 0 | Q25: 0 | R25: 0 | S25: 0 | T25: 0 | U25: 0 | V25: 0 | W25: 0 | X25: 0
A26: Oil and petroleum products | B26: O4000XBIO | C26: =SUM(C27,C33) -> 1025.9915 | D26: =SUM(D27,D33) -> 1149.2675 | E26: =SUM(E27,E33) -> 1146.0217 | F26: =SUM(F27,F33) -> 1098.696 | G26: =SUM(G27,G33) -> 1013.666 | H26: =SUM(H27,H33) -> 912.10301 | I26: =SUM(I27,I33) -> 932.50267 | J26: =SUM(J27,J33) -> 1023.4365 | ... X26: =SUM(X27,X33) -> 1181.3741
A27: Crude oil, NGL, refinery feedstocks, additives and oxygenates and other hydrocarbons (excluding biofuel portion) | B27: O4100_TOT_4200-4500XBIO | C27: =SUM(C28:C32) -> 0 | D27: =SUM(D28:D32) -> 0 | E27: =SUM(E28:E32) -> 0 | F27: =SUM(F28:F32) -> 0 | G27: =SUM(G28:G32) -> 0 | H27: =SUM(H28:H32) -> 0 | I27: =SUM(I28:I32) -> 0 | J27: =SUM(J28:J32) -> 0 | ... X27: =SUM(X28:X32) -> 0
A28: Crude oil | B28: O4100_TOT | C28: 0 | D28: 0 | E28: 0 | F28: 0 | G28: 0 | H28: 0 | I28: 0 | J28: 0 | K28: 0 | L28: 0 | M28: 0 | N28: 0 | O28: 0 | P28: 0 | Q28: 0 | R28: 0 | S28: 0 | T28: 0 | U28: 0 | V28: 0 | W28: 0 | X28: 0
A29: Natural gas liquids | B29: O4200 | C29: 0 | D29: 0 | E29: 0 | F29: 0 | G29: 0 | H29: 0 | I29: 0 | J29: 0 | K29: 0 | L29: 0 | M29: 0 | N29: 0 | O29: 0 | P29: 0 | Q29: 0 | R29: 0 | S29: 0 | T29: 0 | U29: 0 | V29: 0 | W29: 0 | X29: 0
A30: Refinery feedstocks | B30: O4300 | C30: 0 | D30: 0 | E30: 0 | F30: 0 | G30: 0 | H30: 0 | I30: 0 | J30: 0 | K30: 0 | L30: 0 | M30: 0 | N30: 0 | O30: 0 | P30: 0 | Q30: 0 | R30: 0 | S30: 0 | T30: 0 | U30: 0 | V30: 0 | W30: 0 | X30: 0
A31: Additives and oxygenates (excluding biofuel portion) | B31: O4400X4410 | C31: 0 | D31: 0 | E31: 0 | F31: 0 | G31: 0 | H31: 0 | I31: 0 | J31: 0 | K31: 0 | L31: 0 | M31: 0 | N31: 0 | O31: 0 | P31: 0 | Q31: 0 | R31: 0 | S31: 0 | T31: 0 | U31: 0 | V31: 0 | W31: 0 | X31: 0
A32: Other hydrocarbons | B32: O4500 | C32: 0 | D32: 0 | E32: 0 | F32: 0 | G32: 0 | H32: 0 | I32: 0 | J32: 0 | K32: 0 | L32: 0 | M32: 0 | N32: 0 | O32: 0 | P32: 0 | Q32: 0 | R32: 0 | S32: 0 | T32: 0 | U32: 0 | V32: 0 | W32: 0 | X32: 0
A33: Oil products (excluding biofuel portion) | B33: O4600XBIO | C33: =SUM(C34:C50) -> 1025.9915 | D33: =SUM(D34:D50) -> 1149.2675 | E33: =SUM(E34:E50) -> 1146.0217 | F33: =SUM(F34:F50) -> 1098.696 | G33: =SUM(G34:G50) -> 1013.666 | H33: =SUM(H34:H50) -> 912.10301 | I33: =SUM(I34:I50) -> 932.50267 | J33: =SUM(J34:J50) -> 1023.4365 | ... X33: =SUM(X34:X50) -> 1181.3741
A34: Refinery gas | B34: O4610 | C34: 301.17713 | D34: 289.30275 | E34: 270.9515 | F34: 250.44119 | G34: 261.23611 | H34: 262.31556 | I34: 290.38229 | J34: 367.02588 | K34: 367.02588 | L34: 255.83861 | M34: 322.7669 | N34: 357.31049 | O34: 425.28366 | P34: 395.77154 | Q34: 544.71496 | R34: 393.14334 | S34: 335.00653 | T34: 354.12003 | U34: 291.59312 | V34: 329.76638 | W34: 300.28865 | X34: 273.66569
A35: Ethane | B35: O4620 | C35: 0 | D35: 0 | E35: 0 | F35: 0 | G35: 0 | H35: 0 | I35: 0 | J35: 0 | K35: 0 | L35: 0 | M35: 0 | N35: 0 | O35: 0 | P35: 0 | Q35: 0 | R35: 0 | S35: 0 | T35: 0 | U35: 0 | V35: 0 | W35: 0 | X35: 0
A36: Liquefied petroleum gases | B36: O4630 | C36: 0 | D36: 0 | E36: 0 | F36: 0 | G36: 0 | H36: 0 | I36: 0 | J36: 0 | K36: 0 | L36: 0 | M36: 0 | N36: 0 | O36: 0 | P36: 0 | Q36: 0 | R36: 0 | S36: 0 | T36: 0 | U36: 0 | V36: 0 | W36: 0.31341359 | X36: 0.44101462
A37: Motor gasoline (excluding biofuel portion) | B37: O4652XR5210B | C37: 0 | D37: 0 | E37: 0 | F37: 0 | G37: 0 | H37: 0 | I37: 0 | J37: 0 | K37: 0 | L37: 0 | M37: 0 | N37: 0 | O37: 0 | P37: 0 | Q37: 0 | R37: 0 | S37: 0 | T37: 0 | U37: 0 | V37: 0 | W37: 0.5466896 | X37: 0.46732588
A38: Aviation gasoline | B38: O4651 | C38: 0 | D38: 0 | E38: 0 | F38: 0 | G38: 0 | H38: 0 | I38: 0 | J38: 0 | K38: 0 | L38: 0 | M38: 0 | N38: 0 | O38: 0 | P38: 0 | Q38: 0 | R38: 0 | S38: 0 | T38: 0 | U38: 0 | V38: 0 | W38: 0 | X38: 0.018916595
A39: Gasoline-type jet fuel | B39: O4653 | C39: 0 | D39: 0 | E39: 0 | F39: 0 | G39: 0 | H39: 0 | I39: 0 | J39: 0 | K39: 0 | L39: 0 | M39: 0 | N39: 0 | O39: 0 | P39: 0 | Q39: 0 | R39: 0 | S39: 0 | T39: 0 | U39: 0 | V39: 0 | W39: 0 | X39: 0
A40: Kerosene-type jet fuel (excluding biofuel portion) | B40: O4661XR5230B | C40: 0 | D40: 0 | E40: 0 | F40: 0 | G40: 0 | H40: 0 | I40: 0 | J40: 0 | K40: 0 | L40: 0 | M40: 0 | N40: 0 | O40: 0 | P40: 0 | Q40: 0 | R40: 0 | S40: 0 | T40: 0 | U40: 0 | V40: 0 | W40: 0 | X40: 0
...

Sheet IMP
A1: Imports | B1: IMP | C1: 2000 | D1: 2001 | E1: 2002 | F1: 2003 | G1: 2004 | H1: 2005 | I1: 2006 | J1: 2007 | K1: 2008 | L1: 2009 | M1: 2010 | N1: 2011 | O1: 2012 | P1: 2013 | Q1: 2014 | R1: 2015 | S1: 2016 | T1: 2017 | U1: 2018 | V1: 2019 | W1: 2020 | X1: 2021
A2: Total | B2: TOTAL | C2: =SUM(C3,C17,C22,C25,C26,C51,C52,C71,C74,C75,C76) -> 1172345 | D2: =SUM(D3,D17,D22,D25,D26,D51,D52,D71,D74,D75,D76) -> 1190822.6 | E2: =SUM(E3,E17,E22,E25,E26,E51,E52,E71,E74,E75,E76) -> 1206557.5 | F2: =SUM(F3,F17,F22,F25,F26,F51,F52,F71,F74,F75,F76) -> 1249419.6 | G2: =SUM(G3,G17,G22,G25,G26,G51,G52,G71,G74,G75,G76) -> 1296364.6 | H2: =SUM(H3,H17,H22,H25,H26,H51,H52,H71,H74,H75,H76) -> 1339489.5 | I2: =SUM(I3,I17,I22,I25,I26,I51,I52,I71,I74,I75,I76) -> 1361921.6 | J2: =SUM(J3,J17,J22,J25,J26,J51,J52,J71,J74,J75,J76) -> 1327293.1 | ... X2: =SUM(X3,X17,X22,X25,X26,X51,X52,X71,X74,X75,X76) -> 1224290.7
A3: Solid fossil fuels | B3: C0000X0350-0370 | C3: =SUM(C4,C8,C11) -> 110153.93 | D3: =SUM(D4,D8,D11) -> 114041.56 | E3: =SUM(E4,E8,E11) -> 115148.31 | F3: =SUM(F4,F8,F11) -> 119238.41 | G3: =SUM(G4,G8,G11) -> 127448.36 | H3: =SUM(H4,H8,H11) -> 121064.49 | I3: =SUM(I4,I8,I11) -> 131089.85 | J3: =SUM(J4,J8,J11) -> 131239.45 | ... X3: =SUM(X4,X8,X11) -> 75097.225
A4: Hard coal | B4: C0100 | C4: =SUM(C5:C7) -> 99258.433 | D4: =SUM(D5:D7) -> 101993.85 | E4: =SUM(E5:E7) -> 104392.17 | F4: =SUM(F5:F7) -> 107652.67 | G4: =SUM(G5:G7) -> 116853.68 | H4: =SUM(H5:H7) -> 111265.75 | I4: =SUM(I5:I7) -> 120721.28 | J4: =SUM(J5:J7) -> 120338.24 | ... X4: =SUM(X5:X7) -> 67883.595
A5: Anthracite | B5: C0110 | C5: 94.865692 | D5: 93.009974 | E5: 871.87334 | F5: 2153.5041 | G5: 2941.5752 | H5: 2852.38 | I5: 2325.9482 | J5: 3081.7748 | K5: 3931.016 | L5: 2872.4272 | M5: 3000.653 | N5: 4695.1251 | O5: 4193.654 | P5: 3699.9064 | Q5: 3366.5132 | R5: 3260.8685 | S5: 2202.4893 | T5: 2392.2547 | U5: 2702.7443 | V5: 2901.3735 | W5: 2698.9223 | X5: 2348.7162
A6: Coking coal | B6: C0121 | C6: 31242.945 | D6: 30303.999 | E6: 28694.178 | F6: 27856.608 | G6: 31662.026 | H6: 31931.336 | I6: 33368.503 | J6: 35311.242 | K6: 34541.448 | L6: 21455.014 | M6: 28831.107 | N6: 28228.957 | O6: 27185.713 | P6: 25526.61 | Q6: 26826.41 | R6: 24450.029 | S6: 27756.263 | T6: 29225.664 | U6: 28790.746 | V6: 26758.112 | W6: 21851.315 | X6: 23560.359
A7: Other bituminous coal | B7: C0129 | C7: 67920.623 | D7: 71596.838 | E7: 74826.114 | F7: 77642.558 | G7: 82250.082 | H7: 76482.038 | I7: 85026.83 | J7: 81945.222 | K7: 79913.581 | L7: 71955.95 | M7: 72247.651 | N7: 77217.02 | O7: 77665.338 | P7: 77181 | Q7: 75896.018 | R7: 77378.326 | S7: 71964.637 | T7: 70474.471 | U7: 66178.976 | V7: 50157.139 | W7: 32605.123 | X7: 41974.52
A8: Brown coal | B8: C0200 | C8: =SUM(C9:C10) -> 1574.1162 | D8: =SUM(D9:D10) -> 1679.6328 | E8: =SUM(E9:E10) -> 1069.8773 | F8: =SUM(F9:F10) -> 1213.7032 | G8: =SUM(G9:G10) -> 1153.5044 | H8: =SUM(H9:H10) -> 1514.9954 | I8: =SUM(I9:I10) -> 1701.9218 | J8: =SUM(J9:J10) -> 2158.4298 | ... X8: =SUM(X9:X10) -> 615.40705
A9: Sub-bituminous coal | B9: C0210 | C9: 502.62777 | D9: 432.33345 | E9: 499.10817 | F9: 543.55426 | G9: 856.31049 | H9: 1126.6319 | I9: 1181.6871 | J9: 1594.6396 | K9: 1463.0071 | L9: 1087.7996 | M9: 1017.8722 | N9: 879.66165 | O9: 1183.227 | P9: 951.61316 | Q9: 831.90387 | R9: 875.71599 | S9: 697.94961 | T9: 603.0877 | U9: 542.52502 | V9: 699.56612 | W9: 452.77154 | X9: 427.0221
A10: Lignite | B10: C0220 | C10: 1071.4884 | D10: 1247.2993 | E10: 570.76913 | F10: 670.14893 | G10: 297.1939 | H10: 388.36346 | I10: 520.23465 | J10: 563.79011 | K10: 556.87059 | L10: 460.54901 | M10: 382.83749 | N10: 417.86053 | O10: 520.2258 | P10: 493.89071 | Q10: 787.43938 | R10: 685.21565 | S10: 425.27945 | T10: 483.22691 | U10: 459.12726 | V10: 346.37747 | W10: 292.25426 | X10: 188.38495
A11: Coal products | B11: C0300 | C11: =SUM(C12:C16) -> 9321.3856 | D11: =SUM(D12:D16) -> 10368.08 | E11: =SUM(E12:E16) -> 9686.2703 | F11: =SUM(F12:F16) -> 10372.036 | G11: =SUM(G12:G16) -> 9441.1702 | H11: =SUM(H12:H16) -> 8283.7445 | I11: =SUM(I12:I16) -> 8666.6482 | J11: =SUM(J12:J16) -> 8742.7837 | ... X11: =SUM(X12:X16) -> 6598.2229
A12: Patent fuel | B12: C0320 | C12: 92.247721 | D12: 94.056836 | E12: 93.817111 | F12: 76.9908 | G12: 75.800258 | H12: 117.71625 | I12: 117.63061 | J12: 112.75916 | K12: 149.89811 | L12: 151.18151 | M12: 365.96406 | N12: 273.8595 | O12: 199.13689 | P12: 179.41298 | Q12: 123.89682 | R12: 158.0589 | S12: 147.78942 | T12: 128.39097 | U12: 128.60249 | V12: 82.786156 | W12: 67.008512 | X12: 74.451161
A13: Coke oven coke | B13: C0311 | C13: 8864.8316 | D13: 9875.1103 | E13: 9002.2598 | F13: 9683.6536 | G13: 8677.3784 | H13: 7560.9392 | I13: 7845.0534 | J13: 7934.8815 | K13: 7855.4659 | L13: 4599.9312 | M13: 7379.7853 | N13: 6112.9409 | O13: 5179.9966 | P13: 5855.0708 | Q13: 6441.2796 | R13: 5256.9175 | S13: 4980.4823 | T13: 4947.4834 | U13: 5224.2095 | V13: 5186.1918 | W13: 4244.8236 | X13: 5778.3844
A14: Gas coke | B14: C0312 | C14: 0 | D14: 0 | E14: 0 | F14: 0 | G14: 0 | H14: 0 | I14: 0 | J14: 0 | K14: 0 | L14: 0 | M14: 0 | N14: 0 | O14: 0 | P14: 0 | Q14: 0 | R14: 0 | S14: 0 | T14: 0 | U14: 0 | V14: 0 | W14: 0 | X14: 0
A15: Coal tar | B15: C0340 | C15: 96.155804 | D15: 134.56371 | E15: 347.29665 | F15: 367.96002 | G15: 477.38074 | H15: 382.28409 | I15: 415.47558 | J15: 406.12451 | K15: 408.35658 | L15: 404.3405 | M15: 371.84875 | N15: 350.35477 | O15: 419.90954 | P15: 464.7491 | Q15: 502.01617 | R15: 524.68607 | S15: 519.58598 | T15: 461.19699 | U15: 465.09493 | V15: 461.38856 | W15: 410.37197 | X15: 413.2681
A16: Brown coal briquettes | B16: C0330 | C16: 268.15039 | D16: 264.34875 | E16: 242.89682 | F16: 243.43164 | G16: 210.61075 | H16: 222.80499 | I16: 288.48865 | J16: 289.01849 | K16: 280.57635 | L16: 295 | M16: 361.16836 | N16: 433.57885 | O16: 432.47206 | P16: 452.3448 | Q16: 421.07532 | R16: 376.18306 | S16: 372.69596 | T16: 393.18659 | U16: 398.80026 | V16: 370.67326 | W16: 271.77988 | X16: 332.11926
A17: Manufactured gases | B17: C0350-0370 | C17: =SUM(C18:C21) -> 0 | D17: =SUM(D18:D21) -> 0 | E17: =SUM(E18:E21) -> 0 | F17: =SUM(F18:F21) -> 0 | G17: =SUM(G18:G21) -> 0 | H17: =SUM(H18:H21) -> 0 | I17: =SUM(I18:I21) -> 0 | J17: =SUM(J18:J21) -> 0 | ... X17: =SUM(X18:X21) -> 0
A18: Gas works gas | B18: C0360 | C18: 0 | D18: 0 | E18: 0 | F18: 0 | G18: 0 | H18: 0 | I18: 0 | J18: 0 | K18: 0 | L18: 0 | M18: 0 | N18: 0 | O18: 0 | P18: 0 | Q18: 0 | R18: 0 | S18: 0 | T18: 0 | U18: 0 | V18: 0 | W18: 0 | X18: 0
A19: Coke oven gas | B19: C0350 | C19: 0 | D19: 0 | E19: 0 | F19: 0 | G19: 0 | H19: 0 | I19: 0 | J19: 0 | K19: 0 | L19: 0 | M19: 0 | N19: 0 | O19: 0 | P19: 0 | Q19: 0 | R19: 0 | S19: 0 | T19: 0 | U19: 0 | V19: 0 | W19: 0 | X19: 0
A20: Blast furnace gas | B20: C0371 | C20: 0 | D20: 0 | E20: 0 | F20: 0 | G20: 0 | H20: 0 | I20: 0 | J20: 0 | K20: 0 | L20: 0 | M20: 0 | N20: 0 | O20: 0 | P20: 0 | Q20: 0 | R20: 0 | S20: 0 | T20: 0 | U20: 0 | V20: 0 | W20: 0 | X20: 0
A21: Other recovered gases | B21: C0379 | C21: 0 | D21: 0 | E21: 0 | F21: 0 | G21: 0 | H21: 0 | I21: 0 | J21: 0 | K21: 0 | L21: 0 | M21: 0 | N21: 0 | O21: 0 | P21: 0 | Q21: 0 | R21: 0 | S21: 0 | T21: 0 | U21: 0 | V21: 0 | W21: 0 | X21: 0
A22: Peat and peat products | B22: P1000 | C22: =SUM(C23:C24) -> 69.685211 | D22: =SUM(D23:D24) -> 82.106191 | E22: =SUM(E23:E24) -> 103.33353 | F22: =SUM(F23:F24) -> 104.25383 | G22: =SUM(G23:G24) -> 131.00533 | H22: =SUM(H23:H24) -> 104.465 | I22: =SUM(I23:I24) -> 92.698624 | J22: =SUM(J23:J24) -> 143.2638 | ... X22: =SUM(X23:X24) -> 43.607051
A23: Peat | B23: P1100 | C23: 69.685211 | D23: 82.106191 | E23: 103.33353 | F23: 103.30086 | G23: 129.73465 | H23: 100.97068 | I23: 87.93362 | J23: 135.63981 | K23: 166.48409 | L23: 169.19888 | M23: 122.26681 | N23: 144.78581 | O23: 133.27283 | P23: 62.63147 | Q23: 52.822614 | R23: 47.543938 | S23: 36.498968 | T23: 39.529579 | U23: 54.342476 | V23: 46.720808 | W23: 28.08779 | X23: 27.374377
A24: Peat products | B24: P1200 | C24: 0 | D24: 0 | E24: 0 | F24: 0.95296647 | G24: 1.2706793 | H24: 3.494325 | I24: 4.7650043 | J24: 7.6239897 | K24: 11.118315 | L24: 12.706621 | M24: 16.518573 | N24: 21.601204 | O24: 24.142562 | P24: 27.319175 | Q24: 18.106879 | R24: 14.294927 | S24: 19.059931 | T24: 18.774033 | U24: 23.307051 | V24: 18.361049 | W24: 12.261909 | X24: 16.232674
A25: Oil shale and oil sands | B25: S2000 | C25: 261.78504 | D25: 226.48512 | E25: 137.35821 | F25: 213.13534 | G25: 229.25004 | H25: 34.531384 | I25: 0 | J25: 0 | K25: 5.9470335 | L25: 4.3947549 | M25: 0 | N25: 0 | O25: 0 | P25: 0 | Q25: 0 | R25: 0 | S25: 0 | T25: 0 | U25: 0 | V25: 0 | W25: 0 | X25: 0
A26: Oil and petroleum products | B26: O4000XBIO | C26: =SUM(C27,C33) -> 798954.47 | D26: =SUM(D27,D33) -> 808755.05 | E26: =SUM(E27,E33) -> 802937.33 | F26: =SUM(F27,F33) -> 824687.94 | G26: =SUM(G27,G33) -> 853034.67 | H26: =SUM(H27,H33) -> 877161.38 | I26: =SUM(I27,I33) -> 883759.48 | J26: =SUM(J27,J33) -> 861151.3 | ... X26: =SUM(X27,X33) -> 780658
A27: Crude oil, NGL, refinery feedstocks, additives and oxygenates and other hydrocarbons (excluding biofuel portion) | B27: O4100_TOT_4200-4500XBIO | C27: =SUM(C28:C32) -> 576965.85 | D27: =SUM(D28:D32) -> 579481.27 | E27: =SUM(E28:E32) -> 565690.08 | F27: =SUM(F28:F32) -> 586382.79 | G27: =SUM(G28:G32) -> 600512.27 | H27: =SUM(H28:H32) -> 603280.83 | I27: =SUM(I28:I32) -> 603022.81 | J27: =SUM(J28:J32) -> 594811.97 | ... X27: =SUM(X28:X32) -> 480258.22
A28: Crude oil | B28: O4100_TOT | C28: 553537.18 | D28: 553577.73 | E28: 537935.99 | F28: 560624.98 | G28: 575650.4 | H28: 577740.83 | I28: 571024.77 | J28: 562522.7 | K28: 566738.91 | L28: 519148.33 | M28: 518799.87 | N28: 499694.85 | O28: 508059.27 | P28: 482077.18 | Q28: 480623.27 | R28: 515230.08 | S28: 512195.09 | T28: 525770.35 | U28: 514735.55 | V28: 512982.43 | W28: 444800.49 | X28: 451777.56
A29: Natural gas liquids | B29: O4200 | C29: 6770.6216 | D29: 7678.3468 | E29: 9560.249 | F29: 10146.614 | G29: 9380.531 | H29: 10385.856 | I29: 13368.305 | J29: 11001.372 | K29: 9374.8922 | L29: 10748.736 | M29: 9510.4948 | N29: 8797.2357 | O29: 8796.3532 | P29: 9155.88 | Q29: 8829.2027 | R29: 6322.9485 | S29: 6780.0426 | T29: 7030.3396 | U29: 5488.3921 | V29: 5857.6869 | W29: 7582.4493 | X29: 5534.5832
A30: Refinery feedstocks | B30: O4300 | C30: 14857.975 | D30: 16438.213 | E30: 16816.73 | F30: 14447.808 | G30: 13748.485 | H30: 13738.704 | I30: 16688.461 | J30: 19220.348 | K30: 18235.37 | L30: 18198.248 | M30: 15878.279 | N30: 17776.892 | O30: 17378.679 | P30: 24956.857 | Q30: 24200.573 | R30: 21076.494 | S30: 19864.133 | T30: 18228.559 | U30: 17063.644 | V30: 16290.76 | W30: 16646.38 | X30: 20746.805
A31: Additives and oxygenates (excluding biofuel portion) | B31: O4400X4410 | C31: 876.76586 | D31: 908.90567 | E31: 852.0595 | F31: 1103.4388 | G31: 1286.5989 | H31: 1363.3612 | I31: 1880.0087 | J31: 2040.2932 | K31: 1784.4193 | L31: 1709.8414 | M31: 1949.1129 | N31: 1770.5469 | O31: 1527.0242 | P31: 1596.368 | Q31: 1608.3105 | R31: 1543.1037 | S31: 1529.3541 | T31: 1459.1996 | U31: 2077.2199 | V31: 1864.6314 | W31: 1739.6662 | X31: 2199.268
A32: Other hydrocarbons | B32: O4500 | C32: 923.30017 | D32: 878.07635 | E32: 525.04755 | F32: 59.944368 | G32: 446.25348 | H32: 52.076268 | I32: 61.263972 | J32: 27.25589 | K32: 35.732588 | L32: 1.8797077 | M32: 6.9552021 | N32: 3.7594153 | O32: 19.954428 | P32: 8.5519347 | Q32: 3.7904557 | R32: 0.93989682 | S32: 0.93989682 | T32: 0.43233018 | U32: 0.20017197 | V32: 0.20868444 | W32: 0.01883061 | X32: 0.00094582975
A33: Oil products (excluding biofuel portion) | B33: O4600XBIO | C33: =SUM(C34:C50) -> 221988.63 | D33: =SUM(D34:D50) -> 229273.78 | E33: =SUM(E34:E50) -> 237247.25 | F33: =SUM(F34:F50) -> 238305.16 | G33: =SUM(G34:G50) -> 252522.4 | H33: =SUM(H34:H50) -> 273880.56 | I33: =SUM(I34:I50) -> 280736.67 | J33: =SUM(J34:J50) -> 266339.33 | ... X33: =SUM(X34:X50) -> 300399.78
A34: Refinery gas | B34: O4610 | C34: 0 | D34: 0 | E34: 0 | F34: 0 | G34: 0 | H34: 0 | I34: 0 | J34: 0 | K34: 0 | L34: 0 | M34: 0 | N34: 0 | O34: 0 | P34: 0 | Q34: 0 | R34: 0 | S34: 0 | T34: 0 | U34: 0 | V34: 0 | W34: 0 | X34: 0
A35: Ethane | B35: O4620 | C35: 14.407223 | D35: 212.78306 | E35: 294.79312 | F35: 264.87051 | G35: 262.65408 | H35: 347.98891 | I35: 377.91152 | J35: 396.75168 | K35: 363.50439 | L35: 324.71574 | M35: 370.15383 | N35: 391.21049 | O35: 384.56096 | P35: 339.12296 | Q35: 381.23629 | R35: 291.46844 | S35: 425.56604 | T35: 490.99484 | U35: 502.07825 | V35: 495.4282 | W35: 170.12132 | X35: 392.97756
A36: Liquefied petroleum gases | B36: O4630 | C36: 11932.965 | D36: 11880.2 | E36: 12368.28 | F36: 11887.625 | G36: 13185.17 | H36: 13886.087 | I36: 14731.341 | J36: 14739.343 | K36: 15590.16 | L36: 15480.558 | M36: 15937.377 | N36: 16754.431 | O36: 16002.762 | P36: 18813.338 | Q36: 20818.485 | R36: 22179.897 | S36: 22421 | T36: 21889.817 | U36: 23134.498 | V36: 23195.518 | W36: 21573.443 | X36: 22038.152
A37: Motor gasoline (excluding biofuel portion) | B37: O4652XR5210B | C37: 29867.981 | D37: 27077.849 | E37: 25060.131 | F37: 24055.237 | G37: 23165.649 | H37: 25065.337 | I37: 24144.238 | J37: 23302.659 | K37: 24320.118 | L37: 23938.737 | M37: 23760.185 | N37: 24031.163 | O37: 24150.946 | P37: 22104.179 | Q37: 22722.003 | R37: 24448.419 | S37: 25290.743 | T37: 25731.349 | U37: 22416.635 | V37: 24020.169 | W37: 21288.66 | X37: 23288.827
A38: Aviation gasoline | B38: O4651 | C38: 131.27859 | D38: 82.492003 | E38: 69.237833 | F38: 68.787274 | G38: 75.963285 | H38: 96.504987 | I38: 127.17438 | J38: 61.699484 | K38: 64.047979 | L38: 73.321754 | M38: 80.199656 | N38: 71.665864 | O38: 49.916767 | P38: 44.21092 | Q38: 57.445744 | R38: 93.89166 | S38: 83.553052 | T38: 62.83448 | U38: 54.827171 | V38: 62.10129 | W38: 70.027601 | X38: 42.825623
A39: Gasoline-type jet fuel | B39: O4653 | C39: 10.550301 | D39: 27.189252 | E39: 18.816337 | F39: 16.791831 | G39: 30.332932 | H39: 14.526913 | I39: 9.3926053 | J39: 9.4824592 | K39: 5.2904557 | L39: 0 | M39: 0 | N39: 0 | O39: 12.384609 | P39: 1.0320722 | Q39: 0 | R39: 0 | S39: 0 | T39: 0.0010318143 | U39: 0.0041272571 | V39: 0 | W39: 0 | X39: 0
A40: Kerosene-type jet fuel (excluding biofuel portion) | B40: O4661XR5230B | C40: 10574.381 | D40: 12612.496 | E40: 11868.819 | F40: 12343.028 | G40: 14555.515 | H40: 17350.621 | I40: 18123.711 | J40: 19857.176 | K40: 22584.791 | L40: 23067.785 | M40: 22745.983 | N40: 21828.904 | O40: 21922.071 | P40: 22614.107 | Q40: 21468.557 | R40: 23487.663 | S40: 25103.912 | T40: 26324.766 | U40: 28078.363 | V40: 29057.094 | W40: 18366.691 | X40: 19676.142
...

Sheet EXP
A1: Exports | B1: EXP | C1: 2000 | D1: 2001 | E1: 2002 | F1: 2003 | G1: 2004 | H1: 2005 | I1: 2006 | J1: 2007 | K1: 2008 | L1: 2009 | M1: 2010 | N1: 2011 | O1: 2012 | P1: 2013 | Q1: 2014 | R1: 2015 | S1: 2016 | T1: 2017 | U1: 2018 | V1: 2019 | W1: 2020 | X1: 2021
A2: Total | B2: TOTAL | C2: =SUM(C3,C17,C22,C25,C26,C51,C52,C71,C74,C75,C76) -> 306387.77 | D2: =SUM(D3,D17,D22,D25,D26,D51,D52,D71,D74,D75,D76) -> 310943.31 | E2: =SUM(E3,E17,E22,E25,E26,E51,E52,E71,E74,E75,E76) -> 317179.43 | F2: =SUM(F3,F17,F22,F25,F26,F51,F52,F71,F74,F75,F76) -> 328023.63 | G2: =SUM(G3,G17,G22,G25,G26,G51,G52,G71,G74,G75,G76) -> 362134.61 | H2: =SUM(H3,H17,H22,H25,H26,H51,H52,H71,H74,H75,H76) -> 384902.63 | I2: =SUM(I3,I17,I22,I25,I26,I51,I52,I71,I74,I75,I76) -> 390436.26 | J2: =SUM(J3,J17,J22,J25,J26,J51,J52,J71,J74,J75,J76) -> 383641.1 | ... X2: =SUM(X3,X17,X22,X25,X26,X51,X52,X71,X74,X75,X76) -> 412377.39
A3: Solid fossil fuels | B3: C0000X0350-0370 | C3: =SUM(C4,C8,C11) -> 26867.098 | D3: =SUM(D4,D8,D11) -> 26904.741 | E3: =SUM(E4,E8,E11) -> 26089.258 | F3: =SUM(F4,F8,F11) -> 24226.311 | G3: =SUM(G4,G8,G11) -> 24941.912 | H3: =SUM(H4,H8,H11) -> 23125.046 | I3: =SUM(I4,I8,I11) -> 25170.573 | J3: =SUM(J4,J8,J11) -> 22859.975 | ... X3: =SUM(X4,X8,X11) -> 14224.367
A4: Hard coal | B4: C0100 | C4: =SUM(C5:C7) -> 20253.314 | D4: =SUM(D5:D7) -> 20275.241 | E4: =SUM(E5:E7) -> 19698.685 | F4: =SUM(F5:F7) -> 17472.928 | G4: =SUM(G5:G7) -> 17421.611 | H4: =SUM(H5:H7) -> 16441.866 | I4: =SUM(I5:I7) -> 16191.61 | J4: =SUM(J5:J7) -> 14215.209 | ... X4: =SUM(X5:X7) -> 6464.5494
A5: Anthracite | B5: C0110 | C5: 0 | D5: 0 | E5: 577.50267 | F5: 490.20318 | G5: 561.9313 | H5: 475.92657 | I5: 405.0485 | J5: 518.93302 | K5: 508.96449 | L5: 612.61986 | M5: 623.41771 | N5: 506.36466 | O5: 544.10499 | P5: 259.75684 | Q5: 358.74764 | R5: 247.33259 | S5: 164.22812 | T5: 153.50292 | U5: 136.50499 | V5: 607.26965 | W5: 885.8399 | X5: 182.57369
A6: Coking coal | B6: C0121 | C6: 6186.2682 | D6: 4881.3813 | E6: 4773.7537 | F6: 4439.0885 | G6: 4419.7261 | H6: 4365.6559 | I6: 5484.0774 | J6: 4980.2509 | K6: 3992.1821 | L6: 4103.2329 | M6: 3837.6715 | N6: 2909.9774 | O6: 3207.477 | P6: 3109.6169 | Q6: 3171.4416 | R6: 2932.5006 | S6: 3115.2751 | T6: 2956.7735 | U6: 2882.6655 | V6: 2427.5371 | W6: 2227.9381 | X6: 3133.572
A7: Other bituminous coal | B7: C0129 | C7: 14067.046 | D7: 15393.859 | E7: 14347.428 | F7: 12543.636 | G7: 12439.954 | H7: 11600.284 | I7: 10302.484 | J7: 8716.025 | K7: 7487.0377 | L7: 7096.6327 | M7: 7660.1185 | N7: 6190.5787 | O7: 6152.2605 | P7: 7875.0216 | Q7: 6442.917 | R7: 5980.2527 | S7: 5411.6206 | T7: 3497.4358 | U7: 1897.5837 | V7: 2151.8608 | W7: 2299.478 | X7: 3148.4038
A8: Brown coal | B8: C0200 | C8: =SUM(C9:C10) -> 940.0098 | D8: =SUM(D9:D10) -> 1029.0772 | E8: =SUM(E9:E10) -> 710.97954 | F8: =SUM(F9:F10) -> 412.26122 | G8: =SUM(G9:G10) -> 425.1632 | H8: =SUM(H9:H10) -> 478.58083 | I8: =SUM(I9:I10) -> 639.7031 | J8: =SUM(J9:J10) -> 495.43852 | ... X8: =SUM(X9:X10) -> 148.08555
A9: Sub-bituminous coal | B9: C0210 | C9: 26.682803 | D9: 16.937919 | E9: 15.600688 | F9: 20.614875 | G9: 45.092605 | H9: 22.011092 | I9: 29.679708 | J9: 5.2492691 | K9: 7.8152193 | L9: 10.436973 | M9: 25.039811 | N9: 3.2538263 | O9: 7.0289768 | P9: 0 | Q9: 0 | R9: 0.1950129 | S9: 0.1950129 | T9: 1.4299226 | U9: 0.216681 | V9: 0.2816853 | W9: 0.043336199 | X9: 0.043336199
A10: Lignite | B10: C0220 | C10: 913.327 | D10: 1012.1393 | E10: 695.37885 | F10: 391.64635 | G10: 380.07059 | H10: 456.56973 | I10: 610.02339 | J10: 490.18925 | K10: 602.37077 | L10: 483.54893 | M10: 459.30103 | N10: 527.68917 | O10: 606.37051 | P10: 578.79407 | Q10: 820.14566 | R10: 774.56019 | S10: 448.35744 | T10: 461.18547 | U10: 422.41677 | V10: 332.42631 | W10: 224.66922 | X10: 148.04222
A11: Coal products | B11: C0300 | C11: =SUM(C12:C16) -> 5673.7739 | D11: =SUM(D12:D16) -> 5600.423 | E11: =SUM(E12:E16) -> 5679.5941 | F11: =SUM(F12:F16) -> 6341.122 | G11: =SUM(G12:G16) -> 7095.1372 | H11: =SUM(H12:H16) -> 6204.5992 | I11: =SUM(I12:I16) -> 8339.2604 | J11: =SUM(J12:J16) -> 8149.3278 | ... X11: =SUM(X12:X16) -> 7611.7322
A12: Patent fuel | B12: C0320 | C12: 55.170593 | D12: 57.23448 | E12: 60.034566 | F12: 49.498968 | G12: 48.248753 | H12: 41.104127 | I12: 48.987962 | J12: 35.984781 | K12: 10.7 | L12: 11.735856 | M12: 9.2630267 | N12: 21.250301 | O12: 12.022098 | P12: 8.4102322 | Q12: 10.445658 | R12: 11.538779 | S12: 6.9106621 | T12: 6.1412726 | U12: 7.8067928 | V12: 15.566036 | W12: 12.962855 | X12: 14.882717
A13: Coke oven coke | B13: C0311 | C13: 5221.991 | D13: 5076.9052 | E13: 5039.9361 | F13: 5753.988 | G13: 6149.0479 | H13: 5229.2535 | I13: 7176.6357 | J13: 7058.5167 | K13: 6661.3568 | L13: 5231.5983 | M13: 6404.3596 | N13: 5930.9355 | O13: 6029.146 | P13: 6111.0497 | Q13: 6502.7197 | R13: 5671.6606 | S13: 6341.5858 | T13: 6100.5344 | U13: 6134.0089 | V13: 5794.007 | W13: 5900.3932 | X13: 6401.6921
