Workbook

Sheet cover
B6: JRC-IDEES-2021 - Integrated Database of the European Energy System
C10: European Union (27 countries from 2020)
C15: Energy balances
L28: Prepared by JRC C.6
L30: 45432.79
L31: v2021-1.00
B33: Legal Notice
B35: The information made available is property of the Joint Research Centre of the European Commission.
B36: Neither the European Commission nor any person acting on behalf of the Commission is responsible for the use which might be made of this information.
B38: Use conditions
B39: This work is licensed under
B40: CC BY 4.0

Sheet index
A1: European Union (27 countries from 2020) | B1: EU27 | C1: 2000 | D1: 2001 | E1: 2002 | F1: 2003 | G1: 2004 | H1: 2005 | I1: 2006 | J1: 2007 | K1: 2008 | L1: 2009 | M1: 2010 | N1: 2011 | O1: 2012 | P1: 2013 | Q1: 2014 | R1: 2015 | S1: 2016 | T1: 2017 | U1: 2018 | V1: 2019 | W1: 2020 | X1: 2021
B2: Click on the link to jump to the sheet
A3: Total | B3: kt CO2
A4: Gross available energy | B4: =HYPERLINK("#"&CELL("address",GAE!$X$2),"GAE") -> GAE | C4: =GAE!C$2 -> 3498695.1 | D4: =GAE!D$2 -> 3557370.3 | E4: =GAE!E$2 -> 3563371.7 | F4: =GAE!F$2 -> 3650413.4 | G4: =GAE!G$2 -> 3667999.3 | H4: =GAE!H$2 -> 3655044.5 | I4: =GAE!I$2 -> 3681002.6 | J4: =GAE!J$2 -> 3638814.6 | ... X4: =GAE!X$2 -> 2776871.6
A5: International maritime bunkers | B5: =HYPERLINK("#"&CELL("address",INTMARB!$X$2),"INTMARB") -> INTMARB | C5: =INTMARB!C$2 -> 129755.56 | D5: =INTMARB!D$2 -> 133806.23 | E5: =INTMARB!E$2 -> 137724.48 | F5: =INTMARB!F$2 -> 141828.47 | G5: =INTMARB!G$2 -> 149118.53 | H5: =INTMARB!H$2 -> 152050.66 | I5: =INTMARB!I$2 -> 162126.1 | J5: =INTMARB!J$2 -> 169125.02 | ... X5: =INTMARB!X$2 -> 129708.69
A6: International Intra-EEA maritime bunkers | B6: =HYPERLINK("#"&CELL("address",index!$X$2),"index") -> index | C6: =index!C$2 -> 0 | D6: =index!D$2 -> 0 | E6: =index!E$2 -> 0 | F6: =index!F$2 -> 0 | G6: =index!G$2 -> 0 | H6: =index!H$2 -> 0 | I6: =index!I$2 -> 0 | J6: =index!J$2 -> 0 | ... X6: =index!X$2 -> 0
A7: International Extra-EEA maritime bunkers | B7: =HYPERLINK("#"&CELL("address",INTMARB_EX!$X$2),"INTMARB_EX") -> INTMARB_EX | C7: =INTMARB_EX!C$2 -> 90414.266 | D7: =INTMARB_EX!D$2 -> 94747.265 | E7: =INTMARB_EX!E$2 -> 98698.751 | F7: =INTMARB_EX!F$2 -> 101302.2 | G7: =INTMARB_EX!G$2 -> 107737.98 | H7: =INTMARB_EX!H$2 -> 112131.3 | I7: =INTMARB_EX!I$2 -> 121244.79 | J7: =INTMARB_EX!J$2 -> 127331.96 | ... X7: =INTMARB_EX!X$2 -> 95818.143
A8: Gross inland consumption | B8: =HYPERLINK("#"&CELL("address",GIC!$X$2),"GIC") -> GIC | C8: =GIC!C$2 -> 3368939.6 | D8: =GIC!D$2 -> 3423564 | E8: =GIC!E$2 -> 3425647.3 | F8: =GIC!F$2 -> 3508584.9 | G8: =GIC!G$2 -> 3518880.8 | H8: =GIC!H$2 -> 3502993.8 | I8: =GIC!I$2 -> 3518876.5 | J8: =GIC!J$2 -> 3469689.6 | ... X8: =GIC!X$2 -> 2647163
A9: International aviation | B9: =HYPERLINK("#"&CELL("address",INTAVI!$X$2),"INTAVI") -> INTAVI | C9: =INTAVI!C$2 -> 86018.368 | D9: =INTAVI!D$2 -> 84030.351 | E9: =INTAVI!E$2 -> 82576.137 | F9: =INTAVI!F$2 -> 84156.863 | G9: =INTAVI!G$2 -> 90121.752 | H9: =INTAVI!H$2 -> 93765.213 | I9: =INTAVI!I$2 -> 98548.682 | J9: =INTAVI!J$2 -> 102820.45 | ... X9: =INTAVI!X$2 -> 64807.705
A10: International Intra-EEAwUK passenger aviation | B10: =HYPERLINK("#"&CELL("address",INTAVI_PA_IN!$X$2),"INTAVI_PA_IN") -> INTAVI_PA_IN | C10: =INTAVI_PA_IN!C$2 -> 32922.595 | D10: =INTAVI_PA_IN!D$2 -> 32993.75 | E10: =INTAVI_PA_IN!E$2 -> 31379.967 | F10: =INTAVI_PA_IN!F$2 -> 33599.209 | G10: =INTAVI_PA_IN!G$2 -> 35336.649 | H10: =INTAVI_PA_IN!H$2 -> 36763.67 | I10: =INTAVI_PA_IN!I$2 -> 39167.153 | J10: =INTAVI_PA_IN!J$2 -> 41544.944 | ... X10: =INTAVI_PA_IN!X$2 -> 21782.696
A11: International Extra-EEAwUK passenger aviation | B11: =HYPERLINK("#"&CELL("address",INTAVI_PA_EX!$X$2),"INTAVI_PA_EX") -> INTAVI_PA_EX | C11: =INTAVI_PA_EX!C$2 -> 45712.06 | D11: =INTAVI_PA_EX!D$2 -> 44217.206 | E11: =INTAVI_PA_EX!E$2 -> 43756.834 | F11: =INTAVI_PA_EX!F$2 -> 42569.615 | G11: =INTAVI_PA_EX!G$2 -> 46073.398 | H11: =INTAVI_PA_EX!H$2 -> 47471.755 | I11: =INTAVI_PA_EX!I$2 -> 48825.817 | J11: =INTAVI_PA_EX!J$2 -> 50181.404 | ... X11: =INTAVI_PA_EX!X$2 -> 28746.533
A12: International Intra-EEAwUK freight aviation | B12: =HYPERLINK("#"&CELL("address",INTAVI_FR_IN!$X$2),"INTAVI_FR_IN") -> INTAVI_FR_IN | C12: =INTAVI_FR_IN!C$2 -> 865.59567 | D12: =INTAVI_FR_IN!D$2 -> 774.29012 | E12: =INTAVI_FR_IN!E$2 -> 826.52707 | F12: =INTAVI_FR_IN!F$2 -> 821.62828 | G12: =INTAVI_FR_IN!G$2 -> 921.76429 | H12: =INTAVI_FR_IN!H$2 -> 986.51115 | I12: =INTAVI_FR_IN!I$2 -> 1246.5964 | J12: =INTAVI_FR_IN!J$2 -> 1337.1364 | ... X12: =INTAVI_FR_IN!X$2 -> 1751.3313
A13: International Extra-EEAwUK freight aviation | B13: =HYPERLINK("#"&CELL("address",INTAVI_FR_EX!$X$2),"INTAVI_FR_EX") -> INTAVI_FR_EX | C13: =INTAVI_FR_EX!C$2 -> 6518.1177 | D13: =INTAVI_FR_EX!D$2 -> 6045.1044 | E13: =INTAVI_FR_EX!E$2 -> 6612.8095 | F13: =INTAVI_FR_EX!F$2 -> 7166.4102 | G13: =INTAVI_FR_EX!G$2 -> 7789.9408 | H13: =INTAVI_FR_EX!H$2 -> 8543.2765 | I13: =INTAVI_FR_EX!I$2 -> 9309.1153 | J13: =INTAVI_FR_EX!J$2 -> 9756.9638 | ... X13: =INTAVI_FR_EX!X$2 -> 12527.144
A14: Total energy supply | B14: =HYPERLINK("#"&CELL("address",NRGSUP!$X$2),"NRGSUP") -> NRGSUP | C14: =NRGSUP!C$2 -> 3282921.2 | D14: =NRGSUP!D$2 -> 3339533.7 | E14: =NRGSUP!E$2 -> 3343071.1 | F14: =NRGSUP!F$2 -> 3424428.1 | G14: =NRGSUP!G$2 -> 3428759 | H14: =NRGSUP!H$2 -> 3409228.6 | I14: =NRGSUP!I$2 -> 3420327.8 | J14: =NRGSUP!J$2 -> 3366869.1 | ... X14: =NRGSUP!X$2 -> 2582355.2
A15: Electricity & heat generation | B15: =HYPERLINK("#"&CELL("address",TI_EHG_E!$X$2),"TI_EHG_E") -> TI_EHG_E | C15: =TI_EHG_E!C$2 -> 1239023.6 | D15: =TI_EHG_E!D$2 -> 1262695 | E15: =TI_EHG_E!E$2 -> 1288298.4 | F15: =TI_EHG_E!F$2 -> 1333687.2 | G15: =TI_EHG_E!G$2 -> 1333357.5 | H15: =TI_EHG_E!H$2 -> 1322373.3 | I15: =TI_EHG_E!I$2 -> 1340756.5 | J15: =TI_EHG_E!J$2 -> 1355021.9 | ... X15: =TI_EHG_E!X$2 -> 824229.05
A16: Electricity only | B16: =HYPERLINK("#"&CELL("address",TI_EHG_E_E!$X$2),"TI_EHG_E_E") -> TI_EHG_E_E | C16: =TI_EHG_E_E!C$2 -> 770925.7 | D16: =TI_EHG_E_E!D$2 -> 783673.68 | E16: =TI_EHG_E_E!E$2 -> 805798.26 | F16: =TI_EHG_E_E!F$2 -> 789376.68 | G16: =TI_EHG_E_E!G$2 -> 804685.83 | H16: =TI_EHG_E_E!H$2 -> 797523.04 | I16: =TI_EHG_E_E!I$2 -> 800915.21 | J16: =TI_EHG_E_E!J$2 -> 827078.91 | ... X16: =TI_EHG_E_E!X$2 -> 418563.26
A17: CHP | B17: =HYPERLINK("#"&CELL("address",TI_EHG_CHP_E!$X$2),"TI_EHG_CHP_E") -> TI_EHG_CHP_E | C17: =TI_EHG_CHP_E!C$2 -> 416012.08 | D17: =TI_EHG_CHP_E!D$2 -> 425335.18 | E17: =TI_EHG_CHP_E!E$2 -> 430707.59 | F17: =TI_EHG_CHP_E!F$2 -> 489459.13 | G17: =TI_EHG_CHP_E!G$2 -> 480047.86 | H17: =TI_EHG_CHP_E!H$2 -> 480843.51 | I17: =TI_EHG_CHP_E!I$2 -> 498765.36 | J17: =TI_EHG_CHP_E!J$2 -> 486715.51 | ... X17: =TI_EHG_CHP_E!X$2 -> 370755.76
A18: Heat only | B18: =HYPERLINK("#"&CELL("address",TI_EHG_H_E!$X$2),"TI_EHG_H_E") -> TI_EHG_H_E | C18: =TI_EHG_H_E!C$2 -> 52085.83 | D18: =TI_EHG_H_E!D$2 -> 53686.165 | E18: =TI_EHG_H_E!E$2 -> 51792.564 | F18: =TI_EHG_H_E!F$2 -> 54851.412 | G18: =TI_EHG_H_E!G$2 -> 48623.812 | H18: =TI_EHG_H_E!H$2 -> 44006.719 | I18: =TI_EHG_H_E!I$2 -> 41075.965 | J18: =TI_EHG_H_E!J$2 -> 41227.525 | ... X18: =TI_EHG_H_E!X$2 -> 34910.028
A19: Energy sector | B19: =HYPERLINK("#"&CELL("address",NRG_E!$X$2),"NRG_E") -> NRG_E | C19: =NRG_E!C$2 -> 154794.96 | D19: =NRG_E!D$2 -> 150768.48 | E19: =NRG_E!E$2 -> 151719.83 | F19: =NRG_E!F$2 -> 148185.5 | G19: =NRG_E!G$2 -> 151736.56 | H19: =NRG_E!H$2 -> 151884.66 | I19: =NRG_E!I$2 -> 153124.5 | J19: =NRG_E!J$2 -> 155514.01 | ... X19: =NRG_E!X$2 -> 132265.52
A20: Coal mines | B20: =HYPERLINK("#"&CELL("address",NRG_CM_E!$X$2),"NRG_CM_E") -> NRG_CM_E | C20: =NRG_CM_E!C$2 -> 3862.0799 | D20: =NRG_CM_E!D$2 -> 3474.6284 | E20: =NRG_CM_E!E$2 -> 2017.3573 | F20: =NRG_CM_E!F$2 -> 2196.9077 | G20: =NRG_CM_E!G$2 -> 2016.2076 | H20: =NRG_CM_E!H$2 -> 1284.4475 | I20: =NRG_CM_E!I$2 -> 1285.0246 | J20: =NRG_CM_E!J$2 -> 2034.5218 | ... X20: =NRG_CM_E!X$2 -> 715.09374
A21: Oil & natural gas extraction plants | B21: =HYPERLINK("#"&CELL("address",NRG_OIL_NG_E!$X$2),"NRG_OIL_NG_E") -> NRG_OIL_NG_E | C21: =NRG_OIL_NG_E!C$2 -> 9499.8683 | D21: =NRG_OIL_NG_E!D$2 -> 8794.0383 | E21: =NRG_OIL_NG_E!E$2 -> 8872.7942 | F21: =NRG_OIL_NG_E!F$2 -> 7739.6032 | G21: =NRG_OIL_NG_E!G$2 -> 8443.8365 | H21: =NRG_OIL_NG_E!H$2 -> 8561.242 | I21: =NRG_OIL_NG_E!I$2 -> 7132.846 | J21: =NRG_OIL_NG_E!J$2 -> 6075.9852 | ... X21: =NRG_OIL_NG_E!X$2 -> 4906.9763
A22: Patent fuel plants | B22: =HYPERLINK("#"&CELL("address",NRG_PF_E!$X$2),"NRG_PF_E") -> NRG_PF_E | C22: =NRG_PF_E!C$2 -> 0 | D22: =NRG_PF_E!D$2 -> 0 | E22: =NRG_PF_E!E$2 -> 3.9929366 | F22: =NRG_PF_E!F$2 -> 0 | G22: =NRG_PF_E!G$2 -> 0 | H22: =NRG_PF_E!H$2 -> 0 | I22: =NRG_PF_E!I$2 -> 0 | J22: =NRG_PF_E!J$2 -> 0 | ... X22: =NRG_PF_E!X$2 -> 0
A23: Coke ovens | B23: =HYPERLINK("#"&CELL("address",NRG_CO_E!$X$2),"NRG_CO_E") -> NRG_CO_E | C23: =NRG_CO_E!C$2 -> 19870.38 | D23: =NRG_CO_E!D$2 -> 18759.876 | E23: =NRG_CO_E!E$2 -> 19405.777 | F23: =NRG_CO_E!F$2 -> 17422.607 | G23: =NRG_CO_E!G$2 -> 17828.242 | H23: =NRG_CO_E!H$2 -> 18623.603 | I23: =NRG_CO_E!I$2 -> 17718.409 | J23: =NRG_CO_E!J$2 -> 18019.722 | ... X23: =NRG_CO_E!X$2 -> 14100.748
A24: BKB & PB plants | B24: =HYPERLINK("#"&CELL("address",NRG_BKBPB_E!$X$2),"NRG_BKBPB_E") -> NRG_BKBPB_E | C24: =NRG_BKBPB_E!C$2 -> 846.98983 | D24: =NRG_BKBPB_E!D$2 -> 858.33654 | E24: =NRG_BKBPB_E!E$2 -> 1155.9973 | F24: =NRG_BKBPB_E!F$2 -> 1299.7248 | G24: =NRG_BKBPB_E!G$2 -> 1335.533 | H24: =NRG_BKBPB_E!H$2 -> 1172.3542 | I24: =NRG_BKBPB_E!I$2 -> 1219.0665 | J24: =NRG_BKBPB_E!J$2 -> 1336.8082 | ... X24: =NRG_BKBPB_E!X$2 -> 693.45233
A25: Gas works | B25: =HYPERLINK("#"&CELL("address",NRG_GW_E!$X$2),"NRG_GW_E") -> NRG_GW_E | C25: =NRG_GW_E!C$2 -> 12.29742 | D25: =NRG_GW_E!D$2 -> 8.84277 | E25: =NRG_GW_E!E$2 -> 33.860871 | F25: =NRG_GW_E!F$2 -> 38.216977 | G25: =NRG_GW_E!G$2 -> 42.254691 | H25: =NRG_GW_E!H$2 -> 34.294007 | I25: =NRG_GW_E!I$2 -> 33.919862 | J25: =NRG_GW_E!J$2 -> 12.473719 | ... X25: =NRG_GW_E!X$2 -> 0
A26: Blast furnaces | B26: =HYPERLINK("#"&CELL("address",NRG_BF_E!$X$2),"NRG_BF_E") -> NRG_BF_E | C26: =NRG_BF_E!C$2 -> 18270.414 | D26: =NRG_BF_E!D$2 -> 16769.606 | E26: =NRG_BF_E!E$2 -> 18465.352 | F26: =NRG_BF_E!F$2 -> 20731.823 | G26: =NRG_BF_E!G$2 -> 20848.677 | H26: =NRG_BF_E!H$2 -> 20320.247 | I26: =NRG_BF_E!I$2 -> 20242.545 | J26: =NRG_BF_E!J$2 -> 20198.641 | ... X26: =NRG_BF_E!X$2 -> 24757.617
A27: Petroleum refineries (oil refineries) | B27: =HYPERLINK("#"&CELL("address",NRG_PR_E!$X$2),"NRG_PR_E") -> NRG_PR_E | C27: =NRG_PR_E!C$2 -> 102432.93 | D27: =NRG_PR_E!D$2 -> 102103.15 | E27: =NRG_PR_E!E$2 -> 101764.7 | F27: =NRG_PR_E!F$2 -> 98756.619 | G27: =NRG_PR_E!G$2 -> 101193.17 | H27: =NRG_PR_E!H$2 -> 101825.49 | I27: =NRG_PR_E!I$2 -> 105409.47 | J27: =NRG_PR_E!J$2 -> 107656.08 | ... X27: =NRG_PR_E!X$2 -> 86590.04
A28: Nuclear industry | B28: =HYPERLINK("#"&CELL("address",NRG_NI_E!$X$2),"NRG_NI_E") -> NRG_NI_E | C28: =NRG_NI_E!C$2 -> 0 | D28: =NRG_NI_E!D$2 -> 0 | E28: =NRG_NI_E!E$2 -> 0 | F28: =NRG_NI_E!F$2 -> 0 | G28: =NRG_NI_E!G$2 -> 0 | H28: =NRG_NI_E!H$2 -> 0 | I28: =NRG_NI_E!I$2 -> 0 | J28: =NRG_NI_E!J$2 -> 0 | ... X28: =NRG_NI_E!X$2 -> 0
A29: Coal liquefaction plants | B29: =HYPERLINK("#"&CELL("address",NRG_CL_E!$X$2),"NRG_CL_E") -> NRG_CL_E | C29: =NRG_CL_E!C$2 -> 0 | D29: =NRG_CL_E!D$2 -> 0 | E29: =NRG_CL_E!E$2 -> 0 | F29: =NRG_CL_E!F$2 -> 0 | G29: =NRG_CL_E!G$2 -> 0 | H29: =NRG_CL_E!H$2 -> 0 | I29: =NRG_CL_E!I$2 -> 0 | J29: =NRG_CL_E!J$2 -> 0 | ... X29: =NRG_CL_E!X$2 -> 25.88401
A30: Liquefaction & regasification plants (LNG) | B30: =HYPERLINK("#"&CELL("address",NRG_LNG_E!$X$2),"NRG_LNG_E") -> NRG_LNG_E | C30: =NRG_LNG_E!C$2 -> 0 | D30: =NRG_LNG_E!D$2 -> 0 | E30: =NRG_LNG_E!E$2 -> 0 | F30: =NRG_LNG_E!F$2 -> 0 | G30: =NRG_LNG_E!G$2 -> 28.647218 | H30: =NRG_LNG_E!H$2 -> 32.406098 | I30: =NRG_LNG_E!I$2 -> 42.360504 | J30: =NRG_LNG_E!J$2 -> 142.10188 | ... X30: =NRG_LNG_E!X$2 -> 475.70305
A31: Gasification plants for biogas | B31: =HYPERLINK("#"&CELL("address",NRG_BIOG_E!$X$2),"NRG_BIOG_E") -> NRG_BIOG_E | C31: =NRG_BIOG_E!C$2 -> 0 | D31: =NRG_BIOG_E!D$2 -> 0 | E31: =NRG_BIOG_E!E$2 -> 0 | F31: =NRG_BIOG_E!F$2 -> 0 | G31: =NRG_BIOG_E!G$2 -> 0 | H31: =NRG_BIOG_E!H$2 -> 0 | I31: =NRG_BIOG_E!I$2 -> 0 | J31: =NRG_BIOG_E!J$2 -> 0 | ... X31: =NRG_BIOG_E!X$2 -> 0
A32: Gas-to-liquids (GTL) plants | B32: =HYPERLINK("#"&CELL("address",NRG_GTL_E!$X$2),"NRG_GTL_E") -> NRG_GTL_E | C32: =NRG_GTL_E!C$2 -> 0 | D32: =NRG_GTL_E!D$2 -> 0 | E32: =NRG_GTL_E!E$2 -> 0 | F32: =NRG_GTL_E!F$2 -> 0 | G32: =NRG_GTL_E!G$2 -> 0 | H32: =NRG_GTL_E!H$2 -> 0 | I32: =NRG_GTL_E!I$2 -> 0 | J32: =NRG_GTL_E!J$2 -> 0 | ... X32: =NRG_GTL_E!X$2 -> 0
A33: Charcoal production plants | B33: =HYPERLINK("#"&CELL("address",NRG_CPP_E!$X$2),"NRG_CPP_E") -> NRG_CPP_E | C33: =NRG_CPP_E!C$2 -> 0 | D33: =NRG_CPP_E!D$2 -> 0 | E33: =NRG_CPP_E!E$2 -> 0 | F33: =NRG_CPP_E!F$2 -> 0 | G33: =NRG_CPP_E!G$2 -> 0 | H33: =NRG_CPP_E!H$2 -> 0 | I33: =NRG_CPP_E!I$2 -> 0 | J33: =NRG_CPP_E!J$2 -> 0 | ... X33: =NRG_CPP_E!X$2 -> 0
A34: Not elsewhere specified (energy) | B34: =HYPERLINK("#"&CELL("address",NRG_NSP_E!$X$2),"NRG_NSP_E") -> NRG_NSP_E | C34: =NRG_NSP_E!C$2 -> 0 | D34: =NRG_NSP_E!D$2 -> 0 | E34: =NRG_NSP_E!E$2 -> 0 | F34: =NRG_NSP_E!F$2 -> 0 | G34: =NRG_NSP_E!G$2 -> 0 | H34: =NRG_NSP_E!H$2 -> 30.574853 | I34: =NRG_NSP_E!I$2 -> 40.862245 | J34: =NRG_NSP_E!J$2 -> 37.678855 | ... X34: =NRG_NSP_E!X$2 -> 0
A35: Final energy consumption | B35: =HYPERLINK("#"&CELL("address",FC_E!$X$2),"FC_E") -> FC_E | C35: =FC_E!C$2 -> 1889102.6 | D35: =FC_E!D$2 -> 1926070.2 | E35: =FC_E!E$2 -> 1903052.9 | F35: =FC_E!F$2 -> 1942555.3 | G35: =FC_E!G$2 -> 1943664.9 | H35: =FC_E!H$2 -> 1934970.7 | I35: =FC_E!I$2 -> 1926446.8 | J35: =FC_E!J$2 -> 1856333.1 | ... X35: =FC_E!X$2 -> 1625860.7
A36: Industry sector | B36: =HYPERLINK("#"&CELL("address",FC_IND_E!$X$2),"FC_IND_E") -> FC_IND_E | C36: =FC_IND_E!C$2 -> 501970.67 | D36: =FC_IND_E!D$2 -> 490035.81 | E36: =FC_IND_E!E$2 -> 483113.08 | F36: =FC_IND_E!F$2 -> 491361.82 | G36: =FC_IND_E!G$2 -> 475243.3 | H36: =FC_IND_E!H$2 -> 468632.22 | I36: =FC_IND_E!I$2 -> 453268.25 | J36: =FC_IND_E!J$2 -> 454544.29 | ... X36: =FC_IND_E!X$2 -> 368495.17
A37: Iron & steel | B37: =HYPERLINK("#"&CELL("address",FC_IND_IS_E!$X$2),"FC_IND_IS_E") -> FC_IND_IS_E | C37: =FC_IND_IS_E!C$2 -> 107937.71 | D37: =FC_IND_IS_E!D$2 -> 99534.522 | E37: =FC_IND_IS_E!E$2 -> 98568.604 | F37: =FC_IND_IS_E!F$2 -> 102816.77 | G37: =FC_IND_IS_E!G$2 -> 102061.07 | H37: =FC_IND_IS_E!H$2 -> 96242.231 | I37: =FC_IND_IS_E!I$2 -> 98324.81 | J37: =FC_IND_IS_E!J$2 -> 91896.785 | ... X37: =FC_IND_IS_E!X$2 -> 60068.329
A38: Iron & steel - Integrated steelworks | B38: =HYPERLINK("#"&CELL("address",FC_IND_IS_BF_E!$X$2),"FC_IND_IS_BF_E") -> FC_IND_IS_BF_E | C38: =FC_IND_IS_BF_E!C$2 -> 95546.851 | D38: =FC_IND_IS_BF_E!D$2 -> 87467.401 | E38: =FC_IND_IS_BF_E!E$2 -> 87054.376 | F38: =FC_IND_IS_BF_E!F$2 -> 91008.668 | G38: =FC_IND_IS_BF_E!G$2 -> 89997.629 | H38: =FC_IND_IS_BF_E!H$2 -> 84797.464 | I38: =FC_IND_IS_BF_E!I$2 -> 86188.837 | J38: =FC_IND_IS_BF_E!J$2 -> 80286.636 | ... X38: =FC_IND_IS_BF_E!X$2 -> 51781.93
A39: Iron & steel - Electric arc | B39: =HYPERLINK("#"&CELL("address",FC_IND_IS_EA_E!$X$2),"FC_IND_IS_EA_E") -> FC_IND_IS_EA_E | C39: =FC_IND_IS_EA_E!C$2 -> 12390.857 | D39: =FC_IND_IS_EA_E!D$2 -> 12067.121 | E39: =FC_IND_IS_EA_E!E$2 -> 11514.228 | F39: =FC_IND_IS_EA_E!F$2 -> 11808.106 | G39: =FC_IND_IS_EA_E!G$2 -> 12063.445 | H39: =FC_IND_IS_EA_E!H$2 -> 11444.767 | I39: =FC_IND_IS_EA_E!I$2 -> 12135.972 | J39: =FC_IND_IS_EA_E!J$2 -> 11610.149 | ... X39: =FC_IND_IS_EA_E!X$2 -> 8286.3989
A40: Non-ferrous metals | B40: =HYPERLINK("#"&CELL("address",FC_IND_NFM_E!$X$2),"FC_IND_NFM_E") -> FC_IND_NFM_E | C40: =FC_IND_NFM_E!C$2 -> 13912.45 | D40: =FC_IND_NFM_E!D$2 -> 13274.462 | E40: =FC_IND_NFM_E!E$2 -> 13640.568 | F40: =FC_IND_NFM_E!F$2 -> 12967.982 | G40: =FC_IND_NFM_E!G$2 -> 13043.626 | H40: =FC_IND_NFM_E!H$2 -> 12650.66 | I40: =FC_IND_NFM_E!I$2 -> 12128.81 | J40: =FC_IND_NFM_E!J$2 -> 11697.154 | ... X40: =FC_IND_NFM_E!X$2 -> 10647.635
...

Sheet ef
A1: CO2 emission factors (t CO2 / toe) | B1: ef | C1: 2000 | D1: 2001 | E1: 2002 | F1: 2003 | G1: 2004 | H1: 2005 | I1: 2006 | J1: 2007 | K1: 2008 | L1: 2009 | M1: 2010 | N1: 2011 | O1: 2012 | P1: 2013 | Q1: 2014 | R1: 2015 | S1: 2016 | T1: 2017 | U1: 2018 | V1: 2019 | W1: 2020 | X1: 2021
A2: Total | B2: TOTAL
A3: Solid fossil fuels | B3: C0000X0350-0370
A4: Hard coal | B4: C0100
A5: Anthracite | B5: C0110 | C5: 4.1227813 | D5: 4.1148197 | E5: 4.1136434 | F5: 4.1175857 | G5: 4.1476328 | H5: 4.1484823 | I5: 4.1545703 | J5: 4.1342928 | K5: 4.1847761 | L5: 4.1658338 | M5: 4.158428 | N5: 4.1284612 | O5: 4.109372 | P5: 4.1036122 | Q5: 4.1217058 | R5: 4.1143304 | S5: 4.1299568 | T5: 4.1346211 | U5: 4.1345958 | V5: 4.1411888 | W5: 4.1468927 | X5: 4.1402042
A6: Coking coal | B6: C0121 | C6: 3.9605672 | D6: 3.9605141 | E6: 3.9606867 | F6: 3.9606964 | G6: 3.9606391 | H6: 3.958149 | I6: 3.9605503 | J6: 3.9606152 | K6: 3.9607125 | L6: 3.9606744 | M6: 3.9606526 | N6: 3.960979 | O6: 3.9608415 | P6: 3.9602385 | Q6: 3.9604277 | R6: 3.9591886 | S6: 3.960402 | T6: 3.96038 | U6: 3.9602872 | V6: 3.955358 | W6: 3.9557667 | X6: 3.9554751
A7: Other bituminous coal | B7: C0129 | C7: 3.9832155 | D7: 3.9792722 | E7: 3.9863366 | F7: 3.9798421 | G7: 3.9875814 | H7: 3.9875329 | I7: 3.9826023 | J7: 3.9849024 | K7: 3.9835781 | L7: 3.978788 | M7: 3.980876 | N7: 3.9858214 | O7: 3.9814109 | P7: 3.9912469 | Q7: 3.9920335 | R7: 3.9958378 | S7: 3.9876574 | T7: 3.9806041 | U7: 3.9953945 | V7: 4.0106256 | W7: 4.001928 | X7: 3.9906941
A8: Brown coal | B8: C0200
A9: Sub-bituminous coal | B9: C0210 | C9: 4.1329798 | D9: 4.1206456 | E9: 4.1367108 | F9: 4.1399749 | G9: 4.0905612 | H9: 4.084101 | I9: 4.0878257 | J9: 4.0213687 | K9: 3.9922307 | L9: 4.0312813 | M9: 4.008569 | N9: 4.0492191 | O9: 4.058463 | P9: 4.0696733 | Q9: 4.0604285 | R9: 4.0314031 | S9: 3.9284451 | T9: 3.9831778 | U9: 3.975921 | V9: 4.009544 | W9: 3.9956666 | X9: 3.9550053
A10: Lignite | B10: C0220 | C10: 4.5111353 | D10: 4.5164307 | E10: 4.5242978 | F10: 4.510872 | G10: 4.5200821 | H10: 4.5220621 | I10: 4.5113109 | J10: 4.531094 | K10: 4.5220185 | L10: 4.5220925 | M10: 4.5184206 | N10: 4.5153516 | O10: 4.5488155 | P10: 4.5356226 | Q10: 4.5517087 | R10: 4.5343383 | S10: 4.5303712 | T10: 4.5076335 | U10: 4.4864793 | V10: 4.4911539 | W10: 4.4948129 | X10: 4.4917756
A11: Coal products | B11: C0300
A12: Patent fuel | B12: C0320 | C12: 4.2976896 | D12: 4.2960146 | E12: 4.2890809 | F12: 4.2857483 | G12: 4.3219106 | H12: 4.3403747 | I12: 4.3392294 | J12: 4.3309994 | K12: 4.3256548 | L12: 4.2998985 | M12: 4.1808316 | N12: 4.1530024 | O12: 4.2377417 | P12: 4.1937463 | Q12: 4.1795349 | R12: 4.1703706 | S12: 4.1758359 | T12: 4.1772344 | U12: 4.0995402 | V12: 4.1426358 | W12: 4.151774 | X12: 4.1727316
A13: Coke oven coke | B13: C0311 | C13: 4.4949922 | D13: 4.5011682 | E13: 4.5000583 | F13: 4.4923583 | G13: 4.4917498 | H13: 4.5244109 | I13: 4.5194051 | J13: 4.5280442 | K13: 4.4957912 | L13: 4.5297897 | M13: 4.5250558 | N13: 4.4865073 | O13: 4.5002795 | P13: 4.4901318 | Q13: 4.5263942 | R13: 4.5216118 | S13: 4.5091909 | T13: 4.476952 | U13: 4.4802592 | V13: 4.4693262 | W13: 4.454262 | X13: 4.4445687
A14: Gas coke | B14: C0312 | C14: 0 | D14: 0 | E14: 0 | F14: 0 | G14: 0 | H14: 0 | I14: 0 | J14: 0 | K14: 0 | L14: 0 | M14: 0 | N14: 0 | O14: 0 | P14: 0 | Q14: 0 | R14: 0 | S14: 0 | T14: 0 | U14: 0 | V14: 0 | W14: 0 | X14: 0
A15: Coal tar | B15: C0340 | C15: 3.3787476 | D15: 3.3592367 | E15: 3.3703841 | F15: 3.3769721 | G15: 3.3689863 | H15: 3.364134 | I15: 3.3708517 | J15: 3.3611187 | K15: 3.3571358 | L15: 3.3674 | M15: 3.3527017 | N15: 3.3537357 | O15: 3.3517412 | P15: 3.3467454 | Q15: 3.3470486 | R15: 3.3773246 | S15: 3.3766164 | T15: 3.3763589 | U15: 3.3767533 | V15: 3.371789 | W15: 3.3619051 | X15: 3.3746849
A16: Brown coal briquettes | B16: C0330 | C16: 4.0847093 | D16: 4.0828381 | E16: 4.096967 | F16: 4.1116087 | G16: 4.1281341 | H16: 4.1269913 | I16: 4.1163199 | J16: 4.1281673 | K16: 4.1466795 | L16: 4.129118 | M16: 4.1005148 | N16: 4.1149908 | O16: 4.1292252 | P16: 4.1194859 | Q16: 4.1335901 | R16: 4.1237769 | S16: 4.1268055 | T16: 4.124233 | U16: 4.1159247 | V16: 4.1179245 | W16: 4.1237014 | X16: 4.1206781
A17: Manufactured gases | B17: C0350-0370
A18: Gas works gas | B18: C0360 | C18: 1.8589392 | D18: 1.8589392 | E18: 1.8589392 | F18: 1.8589392 | G18: 1.8589392 | H18: 1.8589392 | I18: 1.8589392 | J18: 1.8589392 | K18: 1.8589392 | L18: 1.8589392 | M18: 1.8589392 | N18: 1.8589392 | O18: 1.8589392 | P18: 1.8589392 | Q18: 1.8589392 | R18: 1.8589392 | S18: 1.8589392 | T18: 1.8589392 | U18: 1.8589392 | V18: 1.8589392 | W18: 1.8589392 | X18: 1.8589392
A19: Coke oven gas | B19: C0350 | C19: 1.8589392 | D19: 1.8589392 | E19: 1.8589392 | F19: 1.8589392 | G19: 1.8589392 | H19: 1.8589392 | I19: 1.8589392 | J19: 1.8589392 | K19: 1.8589392 | L19: 1.8589392 | M19: 1.8589392 | N19: 1.8589392 | O19: 1.8589392 | P19: 1.8589392 | Q19: 1.8589392 | R19: 1.8589392 | S19: 1.8589392 | T19: 1.8589392 | U19: 1.8589392 | V19: 1.8589392 | W19: 1.8589392 | X19: 1.8589392
A20: Blast furnace gas | B20: C0371 | C20: 10.88568 | D20: 10.88568 | E20: 10.88568 | F20: 10.88568 | G20: 10.88568 | H20: 10.88568 | I20: 10.88568 | J20: 10.88568 | K20: 10.88568 | L20: 10.88568 | M20: 10.88568 | N20: 10.88568 | O20: 10.88568 | P20: 10.88568 | Q20: 10.88568 | R20: 10.88568 | S20: 10.88568 | T20: 10.88568 | U20: 10.88568 | V20: 10.88568 | W20: 10.88568 | X20: 10.88568
A21: Other recovered gases | B21: C0379 | C21: 7.619976 | D21: 7.619976 | E21: 7.619976 | F21: 7.619976 | G21: 7.619976 | H21: 7.619976 | I21: 7.619976 | J21: 7.619976 | K21: 7.619976 | L21: 7.619976 | M21: 7.619976 | N21: 7.619976 | O21: 7.619976 | P21: 7.619976 | Q21: 7.619976 | R21: 7.619976 | S21: 7.619976 | T21: 7.619976 | U21: 7.619976 | V21: 7.619976 | W21: 7.619976 | X21: 7.619976
A22: Peat and peat products | B22: P1000
A23: Peat | B23: P1100 | C23: 4.3975049 | D23: 4.394618 | E23: 4.3943473 | F23: 4.3927386 | G23: 4.3914537 | H23: 4.3962147 | I23: 4.3925462 | J23: 4.3915617 | K23: 4.395684 | L23: 4.3969833 | M23: 4.3925659 | N23: 4.4242101 | O23: 4.4439857 | P23: 4.434252 | Q23: 4.4258436 | R23: 4.4262389 | S23: 4.4354653 | T23: 4.4357631 | U23: 4.4255126 | V23: 4.4062456 | W23: 4.4046254 | X23: 4.4131491
A24: Peat products | B24: P1200 | C24: 4.432056 | D24: 4.435014 | E24: 4.4347545 | F24: 4.4323042 | G24: 4.4323686 | H24: 4.4323063 | I24: 4.4307707 | J24: 4.4290734 | K24: 4.4231413 | L24: 4.423429 | M24: 4.4223914 | N24: 4.4235388 | O24: 4.4255109 | P24: 4.4235893 | Q24: 4.4219481 | R24: 4.4248413 | S24: 4.422547 | T24: 4.420378 | U24: 4.4199106 | V24: 4.4191277 | W24: 4.424431 | X24: 4.420635
A25: Oil shale and oil sands | B25: S2000 | C25: 4.2754206 | D25: 4.2754206 | E25: 4.2754206 | F25: 4.2754206 | G25: 4.2471284 | H25: 4.2643029 | I25: 4.2529743 | J25: 4.2298973 | K25: 4.2214619 | L25: 4.226115 | M25: 4.232043 | N25: 4.2301305 | O25: 4.2380708 | P25: 4.2990537 | Q25: 4.4007581 | R25: 4.3408402 | S25: 4.3785295 | T25: 4.3851238 | U25: 4.4536429 | V25: 4.3972273 | W25: 4.2733179 | X25: 4.1860683
A26: Oil and petroleum products | B26: O4000XBIO
A27: Crude oil, NGL, refinery feedstocks, additives and oxygenates and other hydrocarbons (excluding biofuel portion) | B27: O4100_TOT_4200-4500XBIO
A28: Crude oil | B28: O4100_TOT | C28: 3.0689244 | D28: 3.0689244 | E28: 3.0689244 | F28: 3.0689244 | G28: 3.0689244 | H28: 3.0689244 | I28: 3.0689244 | J28: 3.0689244 | K28: 3.0689244 | L28: 3.0689244 | M28: 3.0689244 | N28: 3.0689244 | O28: 3.0689244 | P28: 3.0689244 | Q28: 3.0689244 | R28: 3.0689244 | S28: 3.0689244 | T28: 3.0689244 | U28: 3.0689244 | V28: 3.0689244 | W28: 3.0689244 | X28: 3.0689244
A29: Natural gas liquids | B29: O4200 | C29: 2.6879256 | D29: 2.6879256 | E29: 2.6879256 | F29: 2.6879256 | G29: 2.6879256 | H29: 2.6879256 | I29: 2.6879256 | J29: 2.6879256 | K29: 2.6879256 | L29: 2.6879256 | M29: 2.6879256 | N29: 2.6879256 | O29: 2.6879256 | P29: 2.6879256 | Q29: 2.6879256 | R29: 2.6879256 | S29: 2.6879256 | T29: 2.6879256 | U29: 2.6879256 | V29: 2.6879256 | W29: 2.6879256 | X29: 2.6879256
A30: Refinery feedstocks | B30: O4300 | C30: 0 | D30: 0 | E30: 0 | F30: 0 | G30: 0 | H30: 0 | I30: 0 | J30: 0 | K30: 0 | L30: 0 | M30: 0 | N30: 0 | O30: 0 | P30: 0 | Q30: 0 | R30: 0 | S30: 0 | T30: 0 | U30: 0 | V30: 0 | W30: 0 | X30: 0
A31: Additives and oxygenates (excluding biofuel portion) | B31: O4400X4410 | C31: 0 | D31: 0 | E31: 0 | F31: 0 | G31: 0 | H31: 0 | I31: 0 | J31: 0 | K31: 0 | L31: 0 | M31: 0 | N31: 0 | O31: 0 | P31: 0 | Q31: 0 | R31: 0 | S31: 0 | T31: 0 | U31: 0 | V31: 0 | W31: 0 | X31: 0
A32: Other hydrocarbons | B32: O4500 | C32: 0 | D32: 0 | E32: 0 | F32: 0 | G32: 0 | H32: 0 | I32: 0 | J32: 0 | K32: 0 | L32: 0 | M32: 0 | N32: 0 | O32: 0 | P32: 0 | Q32: 0 | R32: 0 | S32: 0 | T32: 0 | U32: 0 | V32: 0 | W32: 0 | X32: 0
A33: Oil products (excluding biofuel portion) | B33: O4600XBIO
A34: Refinery gas | B34: O4610 | C34: 2.4115968 | D34: 2.4115968 | E34: 2.4115968 | F34: 2.4115968 | G34: 2.4115968 | H34: 2.4115968 | I34: 2.4115968 | J34: 2.4115968 | K34: 2.4115968 | L34: 2.4115968 | M34: 2.4115968 | N34: 2.4115968 | O34: 2.4115968 | P34: 2.4115968 | Q34: 2.4115968 | R34: 2.4115968 | S34: 2.4115968 | T34: 2.4115968 | U34: 2.4115968 | V34: 2.4115968 | W34: 2.4115968 | X34: 2.4115968
A35: Ethane | B35: O4620 | C35: 2.5790688 | D35: 2.5790688 | E35: 2.5790688 | F35: 2.5790688 | G35: 2.5790688 | H35: 2.5790688 | I35: 2.5790688 | J35: 2.5790688 | K35: 2.5790688 | L35: 2.5790688 | M35: 2.5790688 | N35: 2.5790688 | O35: 2.5790688 | P35: 2.5790688 | Q35: 2.5790688 | R35: 2.5790688 | S35: 2.5790688 | T35: 2.5790688 | U35: 2.5790688 | V35: 2.5790688 | W35: 2.5790688 | X35: 2.5790688
A36: Liquefied petroleum gases | B36: O4630 | C36: 2.6418708 | D36: 2.6418708 | E36: 2.6418708 | F36: 2.6418708 | G36: 2.6418708 | H36: 2.6418708 | I36: 2.6418708 | J36: 2.6418708 | K36: 2.6418708 | L36: 2.6418708 | M36: 2.6418708 | N36: 2.6418708 | O36: 2.6418708 | P36: 2.6418708 | Q36: 2.6418708 | R36: 2.6418708 | S36: 2.6418708 | T36: 2.6418708 | U36: 2.6418708 | V36: 2.6418708 | W36: 2.6418708 | X36: 2.6418708
A37: Motor gasoline (excluding biofuel portion) | B37: O4652XR5210B | C37: 2.9014524 | D37: 2.9014524 | E37: 2.9014524 | F37: 2.9014524 | G37: 2.9014524 | H37: 2.9014524 | I37: 2.9014524 | J37: 2.9014524 | K37: 2.9014524 | L37: 2.9014524 | M37: 2.9014524 | N37: 2.9014524 | O37: 2.9014524 | P37: 2.9014524 | Q37: 2.9014524 | R37: 2.9014524 | S37: 2.9014524 | T37: 2.9014524 | U37: 2.9014524 | V37: 2.9014524 | W37: 2.9014524 | X37: 2.9014524
A38: Aviation gasoline | B38: O4651 | C38: 2.93076 | D38: 2.93076 | E38: 2.93076 | F38: 2.93076 | G38: 2.93076 | H38: 2.93076 | I38: 2.93076 | J38: 2.93076 | K38: 2.93076 | L38: 2.93076 | M38: 2.93076 | N38: 2.93076 | O38: 2.93076 | P38: 2.93076 | Q38: 2.93076 | R38: 2.93076 | S38: 2.93076 | T38: 2.93076 | U38: 2.93076 | V38: 2.93076 | W38: 2.93076 | X38: 2.93076
A39: Gasoline-type jet fuel | B39: O4653 | C39: 3.0103092 | D39: 3.0103092 | E39: 3.0103092 | F39: 3.0103092 | G39: 3.0103092 | H39: 3.0103092 | I39: 3.0103092 | J39: 3.0103092 | K39: 3.0103092 | L39: 0 | M39: 0 | N39: 0 | O39: 0 | P39: 0 | Q39: 0 | R39: 0 | S39: 0 | T39: 0 | U39: 0 | V39: 0 | W39: 0 | X39: 0
A40: Kerosene-type jet fuel (excluding biofuel portion) | B40: O4661XR5230B | C40: 3.0103092 | D40: 3.0103092 | E40: 3.0103092 | F40: 3.0103092 | G40: 3.0103092 | H40: 3.0103092 | I40: 3.0103092 | J40: 3.0103092 | K40: 3.0103092 | L40: 3.0103092 | M40: 3.0103092 | N40: 3.0103092 | O40: 3.0103092 | P40: 3.0103092 | Q40: 3.0103092 | R40: 3.0103092 | S40: 3.0103092 | T40: 3.0103092 | U40: 3.0103092 | V40: 3.0103092 | W40: 3.0103092 | X40: 3.0103092
...

Sheet GAE
A1: Gross available energy | B1: GAE | C1: 2000 | D1: 2001 | E1: 2002 | F1: 2003 | G1: 2004 | H1: 2005 | I1: 2006 | J1: 2007 | K1: 2008 | L1: 2009 | M1: 2010 | N1: 2011 | O1: 2012 | P1: 2013 | Q1: 2014 | R1: 2015 | S1: 2016 | T1: 2017 | U1: 2018 | V1: 2019 | W1: 2020 | X1: 2021
A2: Total | B2: TOTAL | C2: =SUM(C3,C17,C22,C25,C26,C51,C52) -> 3498695.1 | D2: =SUM(D3,D17,D22,D25,D26,D51,D52) -> 3557370.3 | E2: =SUM(E3,E17,E22,E25,E26,E51,E52) -> 3563371.7 | F2: =SUM(F3,F17,F22,F25,F26,F51,F52) -> 3650413.4 | G2: =SUM(G3,G17,G22,G25,G26,G51,G52) -> 3667999.3 | H2: =SUM(H3,H17,H22,H25,H26,H51,H52) -> 3655044.5 | I2: =SUM(I3,I17,I22,I25,I26,I51,I52) -> 3681002.6 | J2: =SUM(J3,J17,J22,J25,J26,J51,J52) -> 3638814.6 | ... X2: =SUM(X3,X17,X22,X25,X26,X51,X52) -> 2776871.6
A3: Solid fossil fuels | B3: C0000X0350-0370 | C3: =SUM(C4,C8,C11) -> 964986.45 | D3: =SUM(D4,D8,D11) -> 963353.03 | E3: =SUM(E4,E8,E11) -> 971195.16 | F3: =SUM(F4,F8,F11) -> 1007609.3 | G3: =SUM(G4,G8,G11) -> 991993.55 | H3: =SUM(H4,H8,H11) -> 960488.96 | I3: =SUM(I4,I8,I11) -> 975617.78 | J3: =SUM(J4,J8,J11) -> 983098.66 | ... X3: =SUM(X4,X8,X11) -> 513563.4
A4: Hard coal | B4: C0100 | C4: =SUM(C5:C7) -> 522153.24 | D4: =SUM(D5:D7) -> 516147.39 | E4: =SUM(E5:E7) -> 524599.87 | F4: =SUM(F5:F7) -> 555417.23 | G4: =SUM(G5:G7) -> 549754.75 | H4: =SUM(H5:H7) -> 528382.22 | I4: =SUM(I5:I7) -> 543636.52 | J4: =SUM(J5:J7) -> 550691.29 | ... X4: =SUM(X5:X7) -> 245928.16
A5: Anthracite | B5: C0110 | C5: =INTMARB!C5+GIC!C5 -> 403.18249 | D5: =INTMARB!D5+GIC!D5 -> 395.51307 | E5: =INTMARB!E5+GIC!E5 -> 1478.7554 | F5: =INTMARB!F5+GIC!F5 -> 11291.752 | G5: =INTMARB!G5+GIC!G5 -> 20725.355 | H5: =INTMARB!H5+GIC!H5 -> 21363.951 | I5: =INTMARB!I5+GIC!I5 -> 19393.565 | J5: =INTMARB!J5+GIC!J5 -> 22484.509 | ... X5: =INTMARB!X5+GIC!X5 -> 5967.9829
A6: Coking coal | B6: C0121 | C6: =INTMARB!C6+GIC!C6 -> 36339.87 | D6: =INTMARB!D6+GIC!D6 -> 34076.269 | E6: =INTMARB!E6+GIC!E6 -> 36233.211 | F6: =INTMARB!F6+GIC!F6 -> 37897.976 | G6: =INTMARB!G6+GIC!G6 -> 38363.756 | H6: =INTMARB!H6+GIC!H6 -> 35387.074 | I6: =INTMARB!I6+GIC!I6 -> 32117.471 | J6: =INTMARB!J6+GIC!J6 -> 35439.639 | ... X6: =INTMARB!X6+GIC!X6 -> 591.03709
A7: Other bituminous coal | B7: C0129 | C7: =INTMARB!C7+GIC!C7 -> 485410.19 | D7: =INTMARB!D7+GIC!D7 -> 481675.61 | E7: =INTMARB!E7+GIC!E7 -> 486887.91 | F7: =INTMARB!F7+GIC!F7 -> 506227.5 | G7: =INTMARB!G7+GIC!G7 -> 490665.64 | H7: =INTMARB!H7+GIC!H7 -> 471631.19 | I7: =INTMARB!I7+GIC!I7 -> 492125.49 | J7: =INTMARB!J7+GIC!J7 -> 492767.14 | ... X7: =INTMARB!X7+GIC!X7 -> 239369.14
A8: Brown coal | B8: C0200 | C8: =SUM(C9:C10) -> 396000.95 | D8: =SUM(D9:D10) -> 404846.87 | E8: =SUM(E9:E10) -> 405341.37 | F8: =SUM(F9:F10) -> 408359.58 | G8: =SUM(G9:G10) -> 405947.65 | H8: =SUM(H9:H10) -> 397369.38 | I8: =SUM(I9:I10) -> 395154.36 | J8: =SUM(J9:J10) -> 398051.7 | ... X8: =SUM(X9:X10) -> 247428.89
A9: Sub-bituminous coal | B9: C0210 | C9: =INTMARB!C9+GIC!C9 -> 8221.2758 | D9: =INTMARB!D9+GIC!D9 -> 6334.036 | E9: =INTMARB!E9+GIC!E9 -> 7770.0336 | F9: =INTMARB!F9+GIC!F9 -> 6713.138 | G9: =INTMARB!G9+GIC!G9 -> 7961.925 | H9: =INTMARB!H9+GIC!H9 -> 8922.5478 | I9: =INTMARB!I9+GIC!I9 -> 9161.8518 | J9: =INTMARB!J9+GIC!J9 -> 9381.9814 | ... X9: =INTMARB!X9+GIC!X9 -> 2132.0763
A10: Lignite | B10: C0220 | C10: =INTMARB!C10+GIC!C10 -> 387779.67 | D10: =INTMARB!D10+GIC!D10 -> 398512.84 | E10: =INTMARB!E10+GIC!E10 -> 397571.33 | F10: =INTMARB!F10+GIC!F10 -> 401646.44 | G10: =INTMARB!G10+GIC!G10 -> 397985.72 | H10: =INTMARB!H10+GIC!H10 -> 388446.83 | I10: =INTMARB!I10+GIC!I10 -> 385992.51 | J10: =INTMARB!J10+GIC!J10 -> 388669.72 | ... X10: =INTMARB!X10+GIC!X10 -> 245296.82
A11: Coal products | B11: C0300 | C11: =SUM(C12:C16) -> 46832.262 | D11: =SUM(D12:D16) -> 42358.761 | E11: =SUM(E12:E16) -> 41253.921 | F11: =SUM(F12:F16) -> 43832.455 | G11: =SUM(G12:G16) -> 36291.153 | H11: =SUM(H12:H16) -> 34737.367 | I11: =SUM(I12:I16) -> 36826.894 | J11: =SUM(J12:J16) -> 34355.666 | ... X11: =SUM(X12:X16) -> 20206.351
A12: Patent fuel | B12: C0320 | C12: =INTMARB!C12+GIC!C12 -> 1204.8745 | D12: =INTMARB!D12+GIC!D12 -> 904.18954 | E12: =INTMARB!E12+GIC!E12 -> 938.36682 | F12: =INTMARB!F12+GIC!F12 -> 794.05962 | G12: =INTMARB!G12+GIC!G12 -> 677.81122 | H12: =INTMARB!H12+GIC!H12 -> 773.61711 | I12: =INTMARB!I12+GIC!I12 -> 748.13015 | J12: =INTMARB!J12+GIC!J12 -> 700.16023 | ... X12: =INTMARB!X12+GIC!X12 -> 270.00193
A13: Coke oven coke | B13: C0311 | C13: =INTMARB!C13+GIC!C13 -> 32834.706 | D13: =INTMARB!D13+GIC!D13 -> 29245.712 | E13: =INTMARB!E13+GIC!E13 -> 28068.026 | F13: =INTMARB!F13+GIC!F13 -> 29571.556 | G13: =INTMARB!G13+GIC!G13 -> 22436.74 | H13: =INTMARB!H13+GIC!H13 -> 20446.628 | I13: =INTMARB!I13+GIC!I13 -> 22816.025 | J13: =INTMARB!J13+GIC!J13 -> 20095.631 | ... X13: =INTMARB!X13+GIC!X13 -> 8886.9559
A14: Gas coke | B14: C0312 | C14: =INTMARB!C14+GIC!C14 -> 0 | D14: =INTMARB!D14+GIC!D14 -> 0 | E14: =INTMARB!E14+GIC!E14 -> 0 | F14: =INTMARB!F14+GIC!F14 -> 0 | G14: =INTMARB!G14+GIC!G14 -> 0 | H14: =INTMARB!H14+GIC!H14 -> 0 | I14: =INTMARB!I14+GIC!I14 -> 0 | J14: =INTMARB!J14+GIC!J14 -> 0 | ... X14: =INTMARB!X14+GIC!X14 -> 0
A15: Coal tar | B15: C0340 | C15: =INTMARB!C15+GIC!C15 -> 121.95042 | D15: =INTMARB!D15+GIC!D15 -> 153.94778 | E15: =INTMARB!E15+GIC!E15 -> 624.57159 | F15: =INTMARB!F15+GIC!F15 -> 566.89228 | G15: =INTMARB!G15+GIC!G15 -> 637.77807 | H15: =INTMARB!H15+GIC!H15 -> 669.44588 | I15: =INTMARB!I15+GIC!I15 -> 343.70282 | J15: =INTMARB!J15+GIC!J15 -> 400.54333 | ... X15: =INTMARB!X15+GIC!X15 -> 131.57412
A16: Brown coal briquettes | B16: C0330 | C16: =INTMARB!C16+GIC!C16 -> 12670.732 | D16: =INTMARB!D16+GIC!D16 -> 12054.912 | E16: =INTMARB!E16+GIC!E16 -> 11622.957 | F16: =INTMARB!F16+GIC!F16 -> 12899.947 | G16: =INTMARB!G16+GIC!G16 -> 12538.823 | H16: =INTMARB!H16+GIC!H16 -> 12847.676 | I16: =INTMARB!I16+GIC!I16 -> 12919.036 | J16: =INTMARB!J16+GIC!J16 -> 13159.331 | ... X16: =INTMARB!X16+GIC!X16 -> 10917.819
A17: Manufactured gases | B17: C0350-0370 | C17: =SUM(C18:C21) -> 156427 | D17: =SUM(D18:D21) -> 149667.83 | E17: =SUM(E18:E21) -> 151956.11 | F17: =SUM(F18:F21) -> 150333.94 | G17: =SUM(G18:G21) -> 155681.92 | H17: =SUM(H18:H21) -> 152725.72 | I17: =SUM(I18:I21) -> 155428.83 | J17: =SUM(J18:J21) -> 159058.72 | ... X17: =SUM(X18:X21) -> 128293.91
A18: Gas works gas | B18: C0360 | C18: =INTMARB!C18+GIC!C18 -> 965.18968 | D18: =INTMARB!D18+GIC!D18 -> 837.3984 | E18: =INTMARB!E18+GIC!E18 -> 845.92619 | F18: =INTMARB!F18+GIC!F18 -> 870.92836 | G18: =INTMARB!G18+GIC!G18 -> 855.63471 | H18: =INTMARB!H18+GIC!H18 -> 901.01105 | I18: =INTMARB!I18+GIC!I18 -> 930.71204 | J18: =INTMARB!J18+GIC!J18 -> 890.15951 | ... X18: =INTMARB!X18+GIC!X18 -> 105.75238
A19: Coke oven gas | B19: C0350 | C19: =INTMARB!C19+GIC!C19 -> 15304.114 | D19: =INTMARB!D19+GIC!D19 -> 13883.623 | E19: =INTMARB!E19+GIC!E19 -> 13501.705 | F19: =INTMARB!F19+GIC!F19 -> 13319.112 | G19: =INTMARB!G19+GIC!G19 -> 13583.546 | H19: =INTMARB!H19+GIC!H19 -> 13141.793 | I19: =INTMARB!I19+GIC!I19 -> 13642.476 | J19: =INTMARB!J19+GIC!J19 -> 14216.464 | ... X19: =INTMARB!X19+GIC!X19 -> 10397.619
A20: Blast furnace gas | B20: C0371 | C20: =INTMARB!C20+GIC!C20 -> 135321.42 | D20: =INTMARB!D20+GIC!D20 -> 130091.78 | E20: =INTMARB!E20+GIC!E20 -> 132508.48 | F20: =INTMARB!F20+GIC!F20 -> 129915.5 | G20: =INTMARB!G20+GIC!G20 -> 134596.28 | H20: =INTMARB!H20+GIC!H20 -> 131974.06 | I20: =INTMARB!I20+GIC!I20 -> 134485.4 | J20: =INTMARB!J20+GIC!J20 -> 137326.46 | ... X20: =INTMARB!X20+GIC!X20 -> 110728.29
A21: Other recovered gases | B21: C0379 | C21: =INTMARB!C21+GIC!C21 -> 4836.2854 | D21: =INTMARB!D21+GIC!D21 -> 4855.0307 | E21: =INTMARB!E21+GIC!E21 -> 5100.0034 | F21: =INTMARB!F21+GIC!F21 -> 6228.4039 | G21: =INTMARB!G21+GIC!G21 -> 6646.4589 | H21: =INTMARB!H21+GIC!H21 -> 6708.8542 | I21: =INTMARB!I21+GIC!I21 -> 6370.2456 | J21: =INTMARB!J21+GIC!J21 -> 6625.6347 | ... X21: =INTMARB!X21+GIC!X21 -> 7062.2501
A22: Peat and peat products | B22: P1000 | C22: =SUM(C23:C24) -> 11697.453 | D22: =SUM(D23:D24) -> 14611.442 | E22: =SUM(E23:E24) -> 15588.17 | F22: =SUM(F23:F24) -> 16284.166 | G22: =SUM(G23:G24) -> 14484.34 | H22: =SUM(H23:H24) -> 12628.095 | I22: =SUM(I23:I24) -> 14936.109 | J22: =SUM(J23:J24) -> 15930.473 | ... X22: =SUM(X23:X24) -> 5653.7185
A23: Peat | B23: P1100 | C23: =INTMARB!C23+GIC!C23 -> 11081.225 | D23: =INTMARB!D23+GIC!D23 -> 14067.308 | E23: =INTMARB!E23+GIC!E23 -> 15029.408 | F23: =INTMARB!F23+GIC!F23 -> 15806.718 | G23: =INTMARB!G23+GIC!G23 -> 14035.276 | H23: =INTMARB!H23+GIC!H23 -> 12175.385 | I23: =INTMARB!I23+GIC!I23 -> 14483.437 | J23: =INTMARB!J23+GIC!J23 -> 15479.987 | ... X23: =INTMARB!X23+GIC!X23 -> 5348.204
A24: Peat products | B24: P1200 | C24: =INTMARB!C24+GIC!C24 -> 616.22842 | D24: =INTMARB!D24+GIC!D24 -> 544.13427 | E24: =INTMARB!E24+GIC!E24 -> 558.7619 | F24: =INTMARB!F24+GIC!F24 -> 477.44758 | G24: =INTMARB!G24+GIC!G24 -> 449.06372 | H24: =INTMARB!H24+GIC!H24 -> 452.70959 | I24: =INTMARB!I24+GIC!I24 -> 452.67161 | J24: =INTMARB!J24+GIC!J24 -> 450.48551 | ... X24: =INTMARB!X24+GIC!X24 -> 305.51453
A25: Oil shale and oil sands | B25: S2000 | C25: =INTMARB!C25+GIC!C25 -> 9707.0447 | D25: =INTMARB!D25+GIC!D25 -> 9333.6626 | E25: =INTMARB!E25+GIC!E25 -> 9056.6106 | F25: =INTMARB!F25+GIC!F25 -> 10861.617 | G25: =INTMARB!G25+GIC!G25 -> 10720.924 | H25: =INTMARB!H25+GIC!H25 -> 10579.734 | I25: =INTMARB!I25+GIC!I25 -> 9743.0462 | J25: =INTMARB!J25+GIC!J25 -> 12667.722 | ... X25: =INTMARB!X25+GIC!X25 -> 3656.45
A26: Oil and petroleum products | B26: O4000XBIO | C26: =SUM(C27,C33) -> 1651646.1 | D26: =SUM(D27,D33) -> 1687435.9 | E26: =SUM(E27,E33) -> 1675026.4 | F26: =SUM(F27,F33) -> 1689680.6 | G26: =SUM(G27,G33) -> 1698837.7 | H26: =SUM(H27,H33) -> 1694081.9 | I26: =SUM(I27,I33) -> 1696295.9 | J26: =SUM(J27,J33) -> 1652563.7 | ... X26: =SUM(X27,X33) -> 1288359.8
A27: Crude oil, NGL, refinery feedstocks, additives and oxygenates and other hydrocarbons (excluding biofuel portion) | B27: O4100_TOT_4200-4500XBIO | C27: =SUM(C28:C32) -> 435.30568 | D27: =SUM(D28:D32) -> 276.49452 | E27: =SUM(E28:E32) -> 266.42992 | F27: =SUM(F28:F32) -> 276.30282 | G27: =SUM(G28:G32) -> 499.48715 | H27: =SUM(H28:H32) -> 170.42927 | I27: =SUM(I28:I32) -> 82.890249 | J27: =SUM(J28:J32) -> 171.57729 | ... X27: =SUM(X28:X32) -> 147.86895
A28: Crude oil | B28: O4100_TOT | C28: =INTMARB!C28+GIC!C28 -> 435.30568 | D28: =INTMARB!D28+GIC!D28 -> 276.49452 | E28: =INTMARB!E28+GIC!E28 -> 135.08835 | F28: =INTMARB!F28+GIC!F28 -> 173.80271 | G28: =INTMARB!G28+GIC!G28 -> 468.273 | H28: =INTMARB!H28+GIC!H28 -> 170.42927 | I28: =INTMARB!I28+GIC!I28 -> 82.890249 | J28: =INTMARB!J28+GIC!J28 -> 43.362081 | ... X28: =INTMARB!X28+GIC!X28 -> 4.7508955
A29: Natural gas liquids | B29: O4200 | C29: =INTMARB!C29+GIC!C29 -> 0 | D29: =INTMARB!D29+GIC!D29 -> 0 | E29: =INTMARB!E29+GIC!E29 -> 131.34157 | F29: =INTMARB!F29+GIC!F29 -> 102.5001 | G29: =INTMARB!G29+GIC!G29 -> 31.214143 | H29: =INTMARB!H29+GIC!H29 -> 0 | I29: =INTMARB!I29+GIC!I29 -> 0 | J29: =INTMARB!J29+GIC!J29 -> 128.21521 | ... X29: =INTMARB!X29+GIC!X29 -> 143.11806
A30: Refinery feedstocks | B30: O4300 | C30: =INTMARB!C30+GIC!C30 -> 0 | D30: =INTMARB!D30+GIC!D30 -> 0 | E30: =INTMARB!E30+GIC!E30 -> 0 | F30: =INTMARB!F30+GIC!F30 -> 0 | G30: =INTMARB!G30+GIC!G30 -> 0 | H30: =INTMARB!H30+GIC!H30 -> 0 | I30: =INTMARB!I30+GIC!I30 -> 0 | J30: =INTMARB!J30+GIC!J30 -> 0 | ... X30: =INTMARB!X30+GIC!X30 -> 0
A31: Additives and oxygenates (excluding biofuel portion) | B31: O4400X4410 | C31: =INTMARB!C31+GIC!C31 -> 0 | D31: =INTMARB!D31+GIC!D31 -> 0 | E31: =INTMARB!E31+GIC!E31 -> 0 | F31: =INTMARB!F31+GIC!F31 -> 0 | G31: =INTMARB!G31+GIC!G31 -> 0 | H31: =INTMARB!H31+GIC!H31 -> 0 | I31: =INTMARB!I31+GIC!I31 -> 0 | J31: =INTMARB!J31+GIC!J31 -> 0 | ... X31: =INTMARB!X31+GIC!X31 -> 0
A32: Other hydrocarbons | B32: O4500 | C32: =INTMARB!C32+GIC!C32 -> 0 | D32: =INTMARB!D32+GIC!D32 -> 0 | E32: =INTMARB!E32+GIC!E32 -> 0 | F32: =INTMARB!F32+GIC!F32 -> 0 | G32: =INTMARB!G32+GIC!G32 -> 0 | H32: =INTMARB!H32+GIC!H32 -> 0 | I32: =INTMARB!I32+GIC!I32 -> 0 | J32: =INTMARB!J32+GIC!J32 -> 0 | ... X32: =INTMARB!X32+GIC!X32 -> 0
A33: Oil products (excluding biofuel portion) | B33: O4600XBIO | C33: =SUM(C34:C50) -> 1651210.8 | D33: =SUM(D34:D50) -> 1687159.4 | E33: =SUM(E34:E50) -> 1674759.9 | F33: =SUM(F34:F50) -> 1689404.3 | G33: =SUM(G34:G50) -> 1698338.2 | H33: =SUM(H34:H50) -> 1693911.4 | I33: =SUM(I34:I50) -> 1696213.1 | J33: =SUM(J34:J50) -> 1652392.1 | ... X33: =SUM(X34:X50) -> 1288211.9
A34: Refinery gas | B34: O4610 | C34: =INTMARB!C34+GIC!C34 -> 53560.028 | D34: =INTMARB!D34+GIC!D34 -> 53212.676 | E34: =INTMARB!E34+GIC!E34 -> 54531.128 | F34: =INTMARB!F34+GIC!F34 -> 59096.205 | G34: =INTMARB!G34+GIC!G34 -> 61616.98 | H34: =INTMARB!H34+GIC!H34 -> 62078.787 | I34: =INTMARB!I34+GIC!I34 -> 61792.963 | J34: =INTMARB!J34+GIC!J34 -> 64488.891 | ... X34: =INTMARB!X34+GIC!X34 -> 57470.07
A35: Ethane | B35: O4620 | C35: =INTMARB!C35+GIC!C35 -> 28.582425 | D35: =INTMARB!D35+GIC!D35 -> 22.865895 | E35: =INTMARB!E35+GIC!E35 -> 25.72416 | F35: =INTMARB!F35+GIC!F35 -> 27.443465 | G35: =INTMARB!G35+GIC!G35 -> 58.502062 | H35: =INTMARB!H35+GIC!H35 -> 67.458727 | I35: =INTMARB!I35+GIC!I35 -> 38.876524 | J35: =INTMARB!J35+GIC!J35 -> 38.734597 | ... X35: =INTMARB!X35+GIC!X35 -> 1.1234362
A36: Liquefied petroleum gases | B36: O4630 | C36: =INTMARB!C36+GIC!C36 -> 52714.078 | D36: =INTMARB!D36+GIC!D36 -> 52387.672 | E36: =INTMARB!E36+GIC!E36 -> 52060.552 | F36: =INTMARB!F36+GIC!F36 -> 51928.973 | G36: =INTMARB!G36+GIC!G36 -> 52141.672 | H36: =INTMARB!H36+GIC!H36 -> 53172.897 | I36: =INTMARB!I36+GIC!I36 -> 51710.124 | J36: =INTMARB!J36+GIC!J36 -> 50686.157 | ... X36: =INTMARB!X36+GIC!X36 -> 42837.149
A37: Motor gasoline (excluding biofuel portion) | B37: O4652XR5210B | C37: =INTMARB!C37+GIC!C37 -> 320345.03 | D37: =INTMARB!D37+GIC!D37 -> 315577.95 | E37: =INTMARB!E37+GIC!E37 -> 310556.94 | F37: =INTMARB!F37+GIC!F37 -> 300286.55 | G37: =INTMARB!G37+GIC!G37 -> 290894.46 | H37: =INTMARB!H37+GIC!H37 -> 277883.22 | I37: =INTMARB!I37+GIC!I37 -> 268152.1 | J37: =INTMARB!J37+GIC!J37 -> 259318.04 | ... X37: =INTMARB!X37+GIC!X37 -> 184375.79
A38: Aviation gasoline | B38: O4651 | C38: =INTMARB!C38+GIC!C38 -> 351.04154 | D38: =INTMARB!D38+GIC!D38 -> 335.36311 | E38: =INTMARB!E38+GIC!E38 -> 341.32342 | F38: =INTMARB!F38+GIC!F38 -> 317.68229 | G38: =INTMARB!G38+GIC!G38 -> 319.84319 | H38: =INTMARB!H38+GIC!H38 -> 377.528 | I38: =INTMARB!I38+GIC!I38 -> 309.51421 | J38: =INTMARB!J38+GIC!J38 -> 284.45206 | ... X38: =INTMARB!X38+GIC!X38 -> 172.09987
A39: Gasoline-type jet fuel | B39: O4653 | C39: =INTMARB!C39+GIC!C39 -> 372.66489 | D39: =INTMARB!D39+GIC!D39 -> 317.50505 | E39: =INTMARB!E39+GIC!E39 -> 104.42046 | F39: =INTMARB!F39+GIC!F39 -> 95.094969 | G39: =INTMARB!G39+GIC!G39 -> 142.27425 | H39: =INTMARB!H39+GIC!H39 -> 44.592438 | I39: =INTMARB!I39+GIC!I39 -> 47.777464 | J39: =INTMARB!J39+GIC!J39 -> 9.5555963 | ... X39: =INTMARB!X39+GIC!X39 -> 0
A40: Kerosene-type jet fuel (excluding biofuel portion) | B40: O4661XR5230B | C40: =INTMARB!C40+GIC!C40 -> 105625.38 | D40: =INTMARB!D40+GIC!D40 -> 102751.43 | E40: =INTMARB!E40+GIC!E40 -> 100325.33 | F40: =INTMARB!F40+GIC!F40 -> 102324.53 | G40: =INTMARB!G40+GIC!G40 -> 108819.9 | H40: =INTMARB!H40+GIC!H40 -> 113768.73 | I40: =INTMARB!I40+GIC!I40 -> 118794.09 | J40: =INTMARB!J40+GIC!J40 -> 123867.98 | ... X40: =INTMARB!X40+GIC!X40 -> 80010.238
...

Sheet INTMARB
A1: International maritime bunkers | B1: INTMARB | C1: 2000 | D1: 2001 | E1: 2002 | F1: 2003 | G1: 2004 | H1: 2005 | I1: 2006 | J1: 2007 | K1: 2008 | L1: 2009 | M1: 2010 | N1: 2011 | O1: 2012 | P1: 2013 | Q1: 2014 | R1: 2015 | S1: 2016 | T1: 2017 | U1: 2018 | V1: 2019 | W1: 2020 | X1: 2021
A2: Total | B2: TOTAL | C2: =SUM(C3,C17,C22,C25,C26,C51,C52) -> 129755.56 | D2: =SUM(D3,D17,D22,D25,D26,D51,D52) -> 133806.23 | E2: =SUM(E3,E17,E22,E25,E26,E51,E52) -> 137724.48 | F2: =SUM(F3,F17,F22,F25,F26,F51,F52) -> 141828.47 | G2: =SUM(G3,G17,G22,G25,G26,G51,G52) -> 149118.53 | H2: =SUM(H3,H17,H22,H25,H26,H51,H52) -> 152050.66 | I2: =SUM(I3,I17,I22,I25,I26,I51,I52) -> 162126.1 | J2: =SUM(J3,J17,J22,J25,J26,J51,J52) -> 169125.02 | ... X2: =SUM(X3,X17,X22,X25,X26,X51,X52) -> 129708.69
A3: Solid fossil fuels | B3: C0000X0350-0370 | C3: =SUM(C4,C8,C11) -> 0 | D3: =SUM(D4,D8,D11) -> 0 | E3: =SUM(E4,E8,E11) -> 0 | F3: =SUM(F4,F8,F11) -> 0 | G3: =SUM(G4,G8,G11) -> 0 | H3: =SUM(H4,H8,H11) -> 0 | I3: =SUM(I4,I8,I11) -> 0 | J3: =SUM(J4,J8,J11) -> 0 | ... X3: =SUM(X4,X8,X11) -> 0
A4: Hard coal | B4: C0100 | C4: =SUM(C5:C7) -> 0 | D4: =SUM(D5:D7) -> 0 | E4: =SUM(E5:E7) -> 0 | F4: =SUM(F5:F7) -> 0 | G4: =SUM(G5:G7) -> 0 | H4: =SUM(H5:H7) -> 0 | I4: =SUM(I5:I7) -> 0 | J4: =SUM(J5:J7) -> 0 | ... X4: =SUM(X5:X7) -> 0
A5: Anthracite | B5: C0110 | C5: =INTMARB_IN!C5+INTMARB_EX!C5 -> 0 | D5: =INTMARB_IN!D5+INTMARB_EX!D5 -> 0 | E5: =INTMARB_IN!E5+INTMARB_EX!E5 -> 0 | F5: =INTMARB_IN!F5+INTMARB_EX!F5 -> 0 | G5: =INTMARB_IN!G5+INTMARB_EX!G5 -> 0 | H5: =INTMARB_IN!H5+INTMARB_EX!H5 -> 0 | I5: =INTMARB_IN!I5+INTMARB_EX!I5 -> 0 | J5: =INTMARB_IN!J5+INTMARB_EX!J5 -> 0 | ... X5: =INTMARB_IN!X5+INTMARB_EX!X5 -> 0
A6: Coking coal | B6: C0121 | C6: =INTMARB_IN!C6+INTMARB_EX!C6 -> 0 | D6: =INTMARB_IN!D6+INTMARB_EX!D6 -> 0 | E6: =INTMARB_IN!E6+INTMARB_EX!E6 -> 0 | F6: =INTMARB_IN!F6+INTMARB_EX!F6 -> 0 | G6: =INTMARB_IN!G6+INTMARB_EX!G6 -> 0 | H6: =INTMARB_IN!H6+INTMARB_EX!H6 -> 0 | I6: =INTMARB_IN!I6+INTMARB_EX!I6 -> 0 | J6: =INTMARB_IN!J6+INTMARB_EX!J6 -> 0 | ... X6: =INTMARB_IN!X6+INTMARB_EX!X6 -> 0
A7: Other bituminous coal | B7: C0129 | C7: =INTMARB_IN!C7+INTMARB_EX!C7 -> 0 | D7: =INTMARB_IN!D7+INTMARB_EX!D7 -> 0 | E7: =INTMARB_IN!E7+INTMARB_EX!E7 -> 0 | F7: =INTMARB_IN!F7+INTMARB_EX!F7 -> 0 | G7: =INTMARB_IN!G7+INTMARB_EX!G7 -> 0 | H7: =INTMARB_IN!H7+INTMARB_EX!H7 -> 0 | I7: =INTMARB_IN!I7+INTMARB_EX!I7 -> 0 | J7: =INTMARB_IN!J7+INTMARB_EX!J7 -> 0 | ... X7: =INTMARB_IN!X7+INTMARB_EX!X7 -> 0
A8: Brown coal | B8: C0200 | C8: =SUM(C9:C10) -> 0 | D8: =SUM(D9:D10) -> 0 | E8: =SUM(E9:E10) -> 0 | F8: =SUM(F9:F10) -> 0 | G8: =SUM(G9:G10) -> 0 | H8: =SUM(H9:H10) -> 0 | I8: =SUM(I9:I10) -> 0 | J8: =SUM(J9:J10) -> 0 | ... X8: =SUM(X9:X10) -> 0
A9: Sub-bituminous coal | B9: C0210 | C9: =INTMARB_IN!C9+INTMARB_EX!C9 -> 0 | D9: =INTMARB_IN!D9+INTMARB_EX!D9 -> 0 | E9: =INTMARB_IN!E9+INTMARB_EX!E9 -> 0 | F9: =INTMARB_IN!F9+INTMARB_EX!F9 -> 0 | G9: =INTMARB_IN!G9+INTMARB_EX!G9 -> 0 | H9: =INTMARB_IN!H9+INTMARB_EX!H9 -> 0 | I9: =INTMARB_IN!I9+INTMARB_EX!I9 -> 0 | J9: =INTMARB_IN!J9+INTMARB_EX!J9 -> 0 | ... X9: =INTMARB_IN!X9+INTMARB_EX!X9 -> 0
A10: Lignite | B10: C0220 | C10: =INTMARB_IN!C10+INTMARB_EX!C10 -> 0 | D10: =INTMARB_IN!D10+INTMARB_EX!D10 -> 0 | E10: =INTMARB_IN!E10+INTMARB_EX!E10 -> 0 | F10: =INTMARB_IN!F10+INTMARB_EX!F10 -> 0 | G10: =INTMARB_IN!G10+INTMARB_EX!G10 -> 0 | H10: =INTMARB_IN!H10+INTMARB_EX!H10 -> 0 | I10: =INTMARB_IN!I10+INTMARB_EX!I10 -> 0 | J10: =INTMARB_IN!J10+INTMARB_EX!J10 -> 0 | ... X10: =INTMARB_IN!X10+INTMARB_EX!X10 -> 0
A11: Coal products | B11: C0300 | C11: =SUM(C12:C16) -> 0 | D11: =SUM(D12:D16) -> 0 | E11: =SUM(E12:E16) -> 0 | F11: =SUM(F12:F16) -> 0 | G11: =SUM(G12:G16) -> 0 | H11: =SUM(H12:H16) -> 0 | I11: =SUM(I12:I16) -> 0 | J11: =SUM(J12:J16) -> 0 | ... X11: =SUM(X12:X16) -> 0
A12: Patent fuel | B12: C0320 | C12: =INTMARB_IN!C12+INTMARB_EX!C12 -> 0 | D12: =INTMARB_IN!D12+INTMARB_EX!D12 -> 0 | E12: =INTMARB_IN!E12+INTMARB_EX!E12 -> 0 | F12: =INTMARB_IN!F12+INTMARB_EX!F12 -> 0 | G12: =INTMARB_IN!G12+INTMARB_EX!G12 -> 0 | H12: =INTMARB_IN!H12+INTMARB_EX!H12 -> 0 | I12: =INTMARB_IN!I12+INTMARB_EX!I12 -> 0 | J12: =INTMARB_IN!J12+INTMARB_EX!J12 -> 0 | ... X12: =INTMARB_IN!X12+INTMARB_EX!X12 -> 0
A13: Coke oven coke | B13: C0311 | C13: =INTMARB_IN!C13+INTMARB_EX!C13 -> 0 | D13: =INTMARB_IN!D13+INTMARB_EX!D13 -> 0 | E13: =INTMARB_IN!E13+INTMARB_EX!E13 -> 0 | F13: =INTMARB_IN!F13+INTMARB_EX!F13 -> 0 | G13: =INTMARB_IN!G13+INTMARB_EX!G13 -> 0 | H13: =INTMARB_IN!H13+INTMARB_EX!H13 -> 0 | I13: =INTMARB_IN!I13+INTMARB_EX!I13 -> 0 | J13: =INTMARB_IN!J13+INTMARB_EX!J13 -> 0 | ... X13: =INTMARB_IN!X13+INTMARB_EX!X13 -> 0
A14: Gas coke | B14: C0312 | C14: =INTMARB_IN!C14+INTMARB_EX!C14 -> 0 | D14: =INTMARB_IN!D14+INTMARB_EX!D14 -> 0 | E14: =INTMARB_IN!E14+INTMARB_EX!E14 -> 0 | F14: =INTMARB_IN!F14+INTMARB_EX!F14 -> 0 | G14: =INTMARB_IN!G14+INTMARB_EX!G14 -> 0 | H14: =INTMARB_IN!H14+INTMARB_EX!H14 -> 0 | I14: =INTMARB_IN!I14+INTMARB_EX!I14 -> 0 | J14: =INTMARB_IN!J14+INTMARB_EX!J14 -> 0 | ... X14: =INTMARB_IN!X14+INTMARB_EX!X14 -> 0
A15: Coal tar | B15: C0340 | C15: =INTMARB_IN!C15+INTMARB_EX!C15 -> 0 | D15: =INTMARB_IN!D15+INTMARB_EX!D15 -> 0 | E15: =INTMARB_IN!E15+INTMARB_EX!E15 -> 0 | F15: =INTMARB_IN!F15+INTMARB_EX!F15 -> 0 | G15: =INTMARB_IN!G15+INTMARB_EX!G15 -> 0 | H15: =INTMARB_IN!H15+INTMARB_EX!H15 -> 0 | I15: =INTMARB_IN!I15+INTMARB_EX!I15 -> 0 | J15: =INTMARB_IN!J15+INTMARB_EX!J15 -> 0 | ... X15: =INTMARB_IN!X15+INTMARB_EX!X15 -> 0
A16: Brown coal briquettes | B16: C0330 | C16: =INTMARB_IN!C16+INTMARB_EX!C16 -> 0 | D16: =INTMARB_IN!D16+INTMARB_EX!D16 -> 0 | E16: =INTMARB_IN!E16+INTMARB_EX!E16 -> 0 | F16: =INTMARB_IN!F16+INTMARB_EX!F16 -> 0 | G16: =INTMARB_IN!G16+INTMARB_EX!G16 -> 0 | H16: =INTMARB_IN!H16+INTMARB_EX!H16 -> 0 | I16: =INTMARB_IN!I16+INTMARB_EX!I16 -> 0 | J16: =INTMARB_IN!J16+INTMARB_EX!J16 -> 0 | ... X16: =INTMARB_IN!X16+INTMARB_EX!X16 -> 0
A17: Manufactured gases | B17: C0350-0370 | C17: =SUM(C18:C21) -> 0 | D17: =SUM(D18:D21) -> 0 | E17: =SUM(E18:E21) -> 0 | F17: =SUM(F18:F21) -> 0 | G17: =SUM(G18:G21) -> 0 | H17: =SUM(H18:H21) -> 0 | I17: =SUM(I18:I21) -> 0 | J17: =SUM(J18:J21) -> 0 | ... X17: =SUM(X18:X21) -> 0
A18: Gas works gas | B18: C0360 | C18: =INTMARB_IN!C18+INTMARB_EX!C18 -> 0 | D18: =INTMARB_IN!D18+INTMARB_EX!D18 -> 0 | E18: =INTMARB_IN!E18+INTMARB_EX!E18 -> 0 | F18: =INTMARB_IN!F18+INTMARB_EX!F18 -> 0 | G18: =INTMARB_IN!G18+INTMARB_EX!G18 -> 0 | H18: =INTMARB_IN!H18+INTMARB_EX!H18 -> 0 | I18: =INTMARB_IN!I18+INTMARB_EX!I18 -> 0 | J18: =INTMARB_IN!J18+INTMARB_EX!J18 -> 0 | ... X18: =INTMARB_IN!X18+INTMARB_EX!X18 -> 0
A19: Coke oven gas | B19: C0350 | C19: =INTMARB_IN!C19+INTMARB_EX!C19 -> 0 | D19: =INTMARB_IN!D19+INTMARB_EX!D19 -> 0 | E19: =INTMARB_IN!E19+INTMARB_EX!E19 -> 0 | F19: =INTMARB_IN!F19+INTMARB_EX!F19 -> 0 | G19: =INTMARB_IN!G19+INTMARB_EX!G19 -> 0 | H19: =INTMARB_IN!H19+INTMARB_EX!H19 -> 0 | I19: =INTMARB_IN!I19+INTMARB_EX!I19 -> 0 | J19: =INTMARB_IN!J19+INTMARB_EX!J19 -> 0 | ... X19: =INTMARB_IN!X19+INTMARB_EX!X19 -> 0
A20: Blast furnace gas | B20: C0371 | C20: =INTMARB_IN!C20+INTMARB_EX!C20 -> 0 | D20: =INTMARB_IN!D20+INTMARB_EX!D20 -> 0 | E20: =INTMARB_IN!E20+INTMARB_EX!E20 -> 0 | F20: =INTMARB_IN!F20+INTMARB_EX!F20 -> 0 | G20: =INTMARB_IN!G20+INTMARB_EX!G20 -> 0 | H20: =INTMARB_IN!H20+INTMARB_EX!H20 -> 0 | I20: =INTMARB_IN!I20+INTMARB_EX!I20 -> 0 | J20: =INTMARB_IN!J20+INTMARB_EX!J20 -> 0 | ... X20: =INTMARB_IN!X20+INTMARB_EX!X20 -> 0
A21: Other recovered gases | B21: C0379 | C21: =INTMARB_IN!C21+INTMARB_EX!C21 -> 0 | D21: =INTMARB_IN!D21+INTMARB_EX!D21 -> 0 | E21: =INTMARB_IN!E21+INTMARB_EX!E21 -> 0 | F21: =INTMARB_IN!F21+INTMARB_EX!F21 -> 0 | G21: =INTMARB_IN!G21+INTMARB_EX!G21 -> 0 | H21: =INTMARB_IN!H21+INTMARB_EX!H21 -> 0 | I21: =INTMARB_IN!I21+INTMARB_EX!I21 -> 0 | J21: =INTMARB_IN!J21+INTMARB_EX!J21 -> 0 | ... X21: =INTMARB_IN!X21+INTMARB_EX!X21 -> 0
A22: Peat and peat products | B22: P1000 | C22: =SUM(C23:C24) -> 0 | D22: =SUM(D23:D24) -> 0 | E22: =SUM(E23:E24) -> 0 | F22: =SUM(F23:F24) -> 0 | G22: =SUM(G23:G24) -> 0 | H22: =SUM(H23:H24) -> 0 | I22: =SUM(I23:I24) -> 0 | J22: =SUM(J23:J24) -> 0 | ... X22: =SUM(X23:X24) -> 0
A23: Peat | B23: P1100 | C23: =INTMARB_IN!C23+INTMARB_EX!C23 -> 0 | D23: =INTMARB_IN!D23+INTMARB_EX!D23 -> 0 | E23: =INTMARB_IN!E23+INTMARB_EX!E23 -> 0 | F23: =INTMARB_IN!F23+INTMARB_EX!F23 -> 0 | G23: =INTMARB_IN!G23+INTMARB_EX!G23 -> 0 | H23: =INTMARB_IN!H23+INTMARB_EX!H23 -> 0 | I23: =INTMARB_IN!I23+INTMARB_EX!I23 -> 0 | J23: =INTMARB_IN!J23+INTMARB_EX!J23 -> 0 | ... X23: =INTMARB_IN!X23+INTMARB_EX!X23 -> 0
A24: Peat products | B24: P1200 | C24: =INTMARB_IN!C24+INTMARB_EX!C24 -> 0 | D24: =INTMARB_IN!D24+INTMARB_EX!D24 -> 0 | E24: =INTMARB_IN!E24+INTMARB_EX!E24 -> 0 | F24: =INTMARB_IN!F24+INTMARB_EX!F24 -> 0 | G24: =INTMARB_IN!G24+INTMARB_EX!G24 -> 0 | H24: =INTMARB_IN!H24+INTMARB_EX!H24 -> 0 | I24: =INTMARB_IN!I24+INTMARB_EX!I24 -> 0 | J24: =INTMARB_IN!J24+INTMARB_EX!J24 -> 0 | ... X24: =INTMARB_IN!X24+INTMARB_EX!X24 -> 0
A25: Oil shale and oil sands | B25: S2000 | C25: =INTMARB_IN!C25+INTMARB_EX!C25 -> 0 | D25: =INTMARB_IN!D25+INTMARB_EX!D25 -> 0 | E25: =INTMARB_IN!E25+INTMARB_EX!E25 -> 0 | F25: =INTMARB_IN!F25+INTMARB_EX!F25 -> 0 | G25: =INTMARB_IN!G25+INTMARB_EX!G25 -> 0 | H25: =INTMARB_IN!H25+INTMARB_EX!H25 -> 0 | I25: =INTMARB_IN!I25+INTMARB_EX!I25 -> 0 | J25: =INTMARB_IN!J25+INTMARB_EX!J25 -> 0 | ... X25: =INTMARB_IN!X25+INTMARB_EX!X25 -> 0
A26: Oil and petroleum products | B26: O4000XBIO | C26: =SUM(C27,C33) -> 129755.56 | D26: =SUM(D27,D33) -> 133806.23 | E26: =SUM(E27,E33) -> 137724.48 | F26: =SUM(F27,F33) -> 141828.47 | G26: =SUM(G27,G33) -> 149118.53 | H26: =SUM(H27,H33) -> 152050.66 | I26: =SUM(I27,I33) -> 162126.1 | J26: =SUM(J27,J33) -> 169125.02 | ... X26: =SUM(X27,X33) -> 129088.5
A27: Crude oil, NGL, refinery feedstocks, additives and oxygenates and other hydrocarbons (excluding biofuel portion) | B27: O4100_TOT_4200-4500XBIO | C27: =SUM(C28:C32) -> 0 | D27: =SUM(D28:D32) -> 0 | E27: =SUM(E28:E32) -> 0 | F27: =SUM(F28:F32) -> 0 | G27: =SUM(G28:G32) -> 0 | H27: =SUM(H28:H32) -> 0 | I27: =SUM(I28:I32) -> 0 | J27: =SUM(J28:J32) -> 0 | ... X27: =SUM(X28:X32) -> 0
A28: Crude oil | B28: O4100_TOT | C28: =INTMARB_IN!C28+INTMARB_EX!C28 -> 0 | D28: =INTMARB_IN!D28+INTMARB_EX!D28 -> 0 | E28: =INTMARB_IN!E28+INTMARB_EX!E28 -> 0 | F28: =INTMARB_IN!F28+INTMARB_EX!F28 -> 0 | G28: =INTMARB_IN!G28+INTMARB_EX!G28 -> 0 | H28: =INTMARB_IN!H28+INTMARB_EX!H28 -> 0 | I28: =INTMARB_IN!I28+INTMARB_EX!I28 -> 0 | J28: =INTMARB_IN!J28+INTMARB_EX!J28 -> 0 | ... X28: =INTMARB_IN!X28+INTMARB_EX!X28 -> 0
A29: Natural gas liquids | B29: O4200 | C29: =INTMARB_IN!C29+INTMARB_EX!C29 -> 0 | D29: =INTMARB_IN!D29+INTMARB_EX!D29 -> 0 | E29: =INTMARB_IN!E29+INTMARB_EX!E29 -> 0 | F29: =INTMARB_IN!F29+INTMARB_EX!F29 -> 0 | G29: =INTMARB_IN!G29+INTMARB_EX!G29 -> 0 | H29: =INTMARB_IN!H29+INTMARB_EX!H29 -> 0 | I29: =INTMARB_IN!I29+INTMARB_EX!I29 -> 0 | J29: =INTMARB_IN!J29+INTMARB_EX!J29 -> 0 | ... X29: =INTMARB_IN!X29+INTMARB_EX!X29 -> 0
A30: Refinery feedstocks | B30: O4300 | C30: =INTMARB_IN!C30+INTMARB_EX!C30 -> 0 | D30: =INTMARB_IN!D30+INTMARB_EX!D30 -> 0 | E30: =INTMARB_IN!E30+INTMARB_EX!E30 -> 0 | F30: =INTMARB_IN!F30+INTMARB_EX!F30 -> 0 | G30: =INTMARB_IN!G30+INTMARB_EX!G30 -> 0 | H30: =INTMARB_IN!H30+INTMARB_EX!H30 -> 0 | I30: =INTMARB_IN!I30+INTMARB_EX!I30 -> 0 | J30: =INTMARB_IN!J30+INTMARB_EX!J30 -> 0 | ... X30: =INTMARB_IN!X30+INTMARB_EX!X30 -> 0
A31: Additives and oxygenates (excluding biofuel portion) | B31: O4400X4410 | C31: =INTMARB_IN!C31+INTMARB_EX!C31 -> 0 | D31: =INTMARB_IN!D31+INTMARB_EX!D31 -> 0 | E31: =INTMARB_IN!E31+INTMARB_EX!E31 -> 0 | F31: =INTMARB_IN!F31+INTMARB_EX!F31 -> 0 | G31: =INTMARB_IN!G31+INTMARB_EX!G31 -> 0 | H31: =INTMARB_IN!H31+INTMARB_EX!H31 -> 0 | I31: =INTMARB_IN!I31+INTMARB_EX!I31 -> 0 | J31: =INTMARB_IN!J31+INTMARB_EX!J31 -> 0 | ... X31: =INTMARB_IN!X31+INTMARB_EX!X31 -> 0
A32: Other hydrocarbons | B32: O4500 | C32: =INTMARB_IN!C32+INTMARB_EX!C32 -> 0 | D32: =INTMARB_IN!D32+INTMARB_EX!D32 -> 0 | E32: =INTMARB_IN!E32+INTMARB_EX!E32 -> 0 | F32: =INTMARB_IN!F32+INTMARB_EX!F32 -> 0 | G32: =INTMARB_IN!G32+INTMARB_EX!G32 -> 0 | H32: =INTMARB_IN!H32+INTMARB_EX!H32 -> 0 | I32: =INTMARB_IN!I32+INTMARB_EX!I32 -> 0 | J32: =INTMARB_IN!J32+INTMARB_EX!J32 -> 0 | ... X32: =INTMARB_IN!X32+INTMARB_EX!X32 -> 0
A33: Oil products (excluding biofuel portion) | B33: O4600XBIO | C33: =SUM(C34:C50) -> 129755.56 | D33: =SUM(D34:D50) -> 133806.23 | E33: =SUM(E34:E50) -> 137724.48 | F33: =SUM(F34:F50) -> 141828.47 | G33: =SUM(G34:G50) -> 149118.53 | H33: =SUM(H34:H50) -> 152050.66 | I33: =SUM(I34:I50) -> 162126.1 | J33: =SUM(J34:J50) -> 169125.02 | ... X33: =SUM(X34:X50) -> 129088.5
A34: Refinery gas | B34: O4610 | C34: =INTMARB_IN!C34+INTMARB_EX!C34 -> 0 | D34: =INTMARB_IN!D34+INTMARB_EX!D34 -> 0 | E34: =INTMARB_IN!E34+INTMARB_EX!E34 -> 0 | F34: =INTMARB_IN!F34+INTMARB_EX!F34 -> 0 | G34: =INTMARB_IN!G34+INTMARB_EX!G34 -> 0 | H34: =INTMARB_IN!H34+INTMARB_EX!H34 -> 0 | I34: =INTMARB_IN!I34+INTMARB_EX!I34 -> 0 | J34: =INTMARB_IN!J34+INTMARB_EX!J34 -> 0 | ... X34: =INTMARB_IN!X34+INTMARB_EX!X34 -> 0
A35: Ethane | B35: O4620 | C35: =INTMARB_IN!C35+INTMARB_EX!C35 -> 0 | D35: =INTMARB_IN!D35+INTMARB_EX!D35 -> 0 | E35: =INTMARB_IN!E35+INTMARB_EX!E35 -> 0 | F35: =INTMARB_IN!F35+INTMARB_EX!F35 -> 0 | G35: =INTMARB_IN!G35+INTMARB_EX!G35 -> 0 | H35: =INTMARB_IN!H35+INTMARB_EX!H35 -> 0 | I35: =INTMARB_IN!I35+INTMARB_EX!I35 -> 0 | J35: =INTMARB_IN!J35+INTMARB_EX!J35 -> 0 | ... X35: =INTMARB_IN!X35+INTMARB_EX!X35 -> 0
A36: Liquefied petroleum gases | B36: O4630 | C36: =INTMARB_IN!C36+INTMARB_EX!C36 -> 0 | D36: =INTMARB_IN!D36+INTMARB_EX!D36 -> 0 | E36: =INTMARB_IN!E36+INTMARB_EX!E36 -> 0 | F36: =INTMARB_IN!F36+INTMARB_EX!F36 -> 0 | G36: =INTMARB_IN!G36+INTMARB_EX!G36 -> 0 | H36: =INTMARB_IN!H36+INTMARB_EX!H36 -> 0 | I36: =INTMARB_IN!I36+INTMARB_EX!I36 -> 0 | J36: =INTMARB_IN!J36+INTMARB_EX!J36 -> 0 | ... X36: =INTMARB_IN!X36+INTMARB_EX!X36 -> 0
A37: Motor gasoline (excluding biofuel portion) | B37: O4652XR5210B | C37: =INTMARB_IN!C37+INTMARB_EX!C37 -> 0 | D37: =INTMARB_IN!D37+INTMARB_EX!D37 -> 0 | E37: =INTMARB_IN!E37+INTMARB_EX!E37 -> 0 | F37: =INTMARB_IN!F37+INTMARB_EX!F37 -> 0 | G37: =INTMARB_IN!G37+INTMARB_EX!G37 -> 0 | H37: =INTMARB_IN!H37+INTMARB_EX!H37 -> 0 | I37: =INTMARB_IN!I37+INTMARB_EX!I37 -> 0 | J37: =INTMARB_IN!J37+INTMARB_EX!J37 -> 0 | ... X37: =INTMARB_IN!X37+INTMARB_EX!X37 -> 0
A38: Aviation gasoline | B38: O4651 | C38: =INTMARB_IN!C38+INTMARB_EX!C38 -> 0 | D38: =INTMARB_IN!D38+INTMARB_EX!D38 -> 0 | E38: =INTMARB_IN!E38+INTMARB_EX!E38 -> 0 | F38: =INTMARB_IN!F38+INTMARB_EX!F38 -> 0 | G38: =INTMARB_IN!G38+INTMARB_EX!G38 -> 0 | H38: =INTMARB_IN!H38+INTMARB_EX!H38 -> 0 | I38: =INTMARB_IN!I38+INTMARB_EX!I38 -> 0 | J38: =INTMARB_IN!J38+INTMARB_EX!J38 -> 0 | ... X38: =INTMARB_IN!X38+INTMARB_EX!X38 -> 0
A39: Gasoline-type jet fuel | B39: O4653 | C39: =INTMARB_IN!C39+INTMARB_EX!C39 -> 0 | D39: =INTMARB_IN!D39+INTMARB_EX!D39 -> 0 | E39: =INTMARB_IN!E39+INTMARB_EX!E39 -> 0 | F39: =INTMARB_IN!F39+INTMARB_EX!F39 -> 0 | G39: =INTMARB_IN!G39+INTMARB_EX!G39 -> 0 | H39: =INTMARB_IN!H39+INTMARB_EX!H39 -> 0 | I39: =INTMARB_IN!I39+INTMARB_EX!I39 -> 0 | J39: =INTMARB_IN!J39+INTMARB_EX!J39 -> 0 | ... X39: =INTMARB_IN!X39+INTMARB_EX!X39 -> 0
A40: Kerosene-type jet fuel (excluding biofuel portion) | B40: O4661XR5230B | C40: =INTMARB_IN!C40+INTMARB_EX!C40 -> 0 | D40: =INTMARB_IN!D40+INTMARB_EX!D40 -> 0 | E40: =INTMARB_IN!E40+INTMARB_EX!E40 -> 0 | F40: =INTMARB_IN!F40+INTMARB_EX!F40 -> 0 | G40: =INTMARB_IN!G40+INTMARB_EX!G40 -> 0 | H40: =INTMARB_IN!H40+INTMARB_EX!H40 -> 0 | I40: =INTMARB_IN!I40+INTMARB_EX!I40 -> 0 | J40: =INTMARB_IN!J40+INTMARB_EX!J40 -> 0 | ... X40: =INTMARB_IN!X40+INTMARB_EX!X40 -> 0
...

Sheet INTMARB_IN
A1: International Intra-EEA maritime bunkers | B1: INTMARB_IN | C1: 2000 | D1: 2001 | E1: 2002 | F1: 2003 | G1: 2004 | H1: 2005 | I1: 2006 | J1: 2007 | K1: 2008 | L1: 2009 | M1: 2010 | N1: 2011 | O1: 2012 | P1: 2013 | Q1: 2014 | R1: 2015 | S1: 2016 | T1: 2017 | U1: 2018 | V1: 2019 | W1: 2020 | X1: 2021
A2: Total | B2: TOTAL | C2: =SUM(C3,C17,C22,C25,C26,C51,C52) -> 39341.296 | D2: =SUM(D3,D17,D22,D25,D26,D51,D52) -> 39058.965 | E2: =SUM(E3,E17,E22,E25,E26,E51,E52) -> 39025.728 | F2: =SUM(F3,F17,F22,F25,F26,F51,F52) -> 40526.27 | G2: =SUM(G3,G17,G22,G25,G26,G51,G52) -> 41380.555 | H2: =SUM(H3,H17,H22,H25,H26,H51,H52) -> 39919.363 | I2: =SUM(I3,I17,I22,I25,I26,I51,I52) -> 40881.312 | J2: =SUM(J3,J17,J22,J25,J26,J51,J52) -> 41793.063 | ... X2: =SUM(X3,X17,X22,X25,X26,X51,X52) -> 33890.55
