Workbook

Sheet cover
B6: JRC-IDEES-2021 - Integrated Database of the European Energy System
C15: International maritime bunkers - EU split
L28: Prepared by JRC C.6
L30: 45432.79
L31: v2021-1.00
B33: Legal Notice
B35: The information made available is property of the Joint Research Centre of the European Commission.
B36: Neither the European Commission nor any person acting on behalf of the Commission is responsible for the use which might be made of this information.
B38: Use conditions
B39: This work is licensed under
B40: CC BY 4.0

Sheet EU27
A1: EU27 - European Union - 27 countries (from 2020) | B1: 1990 | C1: 1991 | D1: 1992 | E1: 1993 | F1: 1994 | G1: 1995 | H1: 1996 | I1: 1997 | J1: 1998 | K1: 1999 | L1: 2000 | M1: 2001 | N1: 2002 | O1: 2003 | P1: 2004 | Q1: 2005 | R1: 2006 | S1: 2007 | T1: 2008 | U1: 2009 | V1: 2010 | W1: 2011 | X1: 2012 | Y1: 2013 | Z1: 2014 | AA1: 2015 | AB1: 2016 | AC1: 2017 | AD1: 2018 | AE1: 2019 | AF1: 2020 | AG1: 2021
A3: Transport activity (Mtkm) | B3: =SUM(B4:B5) -> 5260244.1 | C3: =SUM(C4:C5) -> 5056483.1 | D3: =SUM(D4:D5) -> 4958716.1 | E3: =SUM(E4:E5) -> 4927827.7 | F3: =SUM(F4:F5) -> 4816013.9 | G3: =SUM(G4:G5) -> 4787796.6 | H3: =SUM(H4:H5) -> 4835398.5 | I3: =SUM(I4:I5) -> 5047205 | ... AG3: =SUM(AG4:AG5) -> 8135819.2
A4: Intra-EU27 | B4: =AT!B4+BE!B4+BG!B4+CY!B4+CZ!B4+DE!B4+DK!B4+EE!B4+EL!B4+ES!B4+FI!B4+FR!B4+HR!B4+HU!B4+IE!B4+IT!B4+LT!B4+LU!B4+LV!B4+MT!B4+NL!B4+PL!B4+PT!B4+RO!B4+SE!B4+SI!B4+SK!B4 -> 675560.78 | C4: =AT!C4+BE!C4+BG!C4+CY!C4+CZ!C4+DE!C4+DK!C4+EE!C4+EL!C4+ES!C4+FI!C4+FR!C4+HR!C4+HU!C4+IE!C4+IT!C4+LT!C4+LU!C4+LV!C4+MT!C4+NL!C4+PL!C4+PT!C4+RO!C4+SE!C4+SI!C4+SK!C4 -> 631381.38 | D4: =AT!D4+BE!D4+BG!D4+CY!D4+CZ!D4+DE!D4+DK!D4+EE!D4+EL!D4+ES!D4+FI!D4+FR!D4+HR!D4+HU!D4+IE!D4+IT!D4+LT!D4+LU!D4+LV!D4+MT!D4+NL!D4+PL!D4+PT!D4+RO!D4+SE!D4+SI!D4+SK!D4 -> 637361.83 | E4: =AT!E4+BE!E4+BG!E4+CY!E4+CZ!E4+DE!E4+DK!E4+EE!E4+EL!E4+ES!E4+FI!E4+FR!E4+HR!E4+HU!E4+IE!E4+IT!E4+LT!E4+LU!E4+LV!E4+MT!E4+NL!E4+PL!E4+PT!E4+RO!E4+SE!E4+SI!E4+SK!E4 -> 626240.24 | F4: =AT!F4+BE!F4+BG!F4+CY!F4+CZ!F4+DE!F4+DK!F4+EE!F4+EL!F4+ES!F4+FI!F4+FR!F4+HR!F4+HU!F4+IE!F4+IT!F4+LT!F4+LU!F4+LV!F4+MT!F4+NL!F4+PL!F4+PT!F4+RO!F4+SE!F4+SI!F4+SK!F4 -> 618441.68 | G4: =AT!G4+BE!G4+BG!G4+CY!G4+CZ!G4+DE!G4+DK!G4+EE!G4+EL!G4+ES!G4+FI!G4+FR!G4+HR!G4+HU!G4+IE!G4+IT!G4+LT!G4+LU!G4+LV!G4+MT!G4+NL!G4+PL!G4+PT!G4+RO!G4+SE!G4+SI!G4+SK!G4 -> 596189.02 | H4: =AT!H4+BE!H4+BG!H4+CY!H4+CZ!H4+DE!H4+DK!H4+EE!H4+EL!H4+ES!H4+FI!H4+FR!H4+HR!H4+HU!H4+IE!H4+IT!H4+LT!H4+LU!H4+LV!H4+MT!H4+NL!H4+PL!H4+PT!H4+RO!H4+SE!H4+SI!H4+SK!H4 -> 609855.98 | I4: =AT!I4+BE!I4+BG!I4+CY!I4+CZ!I4+DE!I4+DK!I4+EE!I4+EL!I4+ES!I4+FI!I4+FR!I4+HR!I4+HU!I4+IE!I4+IT!I4+LT!I4+LU!I4+LV!I4+MT!I4+NL!I4+PL!I4+PT!I4+RO!I4+SE!I4+SI!I4+SK!I4 -> 614714.87 | ... AG4: =AT!AG4+BE!AG4+BG!AG4+CY!AG4+CZ!AG4+DE!AG4+DK!AG4+EE!AG4+EL!AG4+ES!AG4+FI!AG4+FR!AG4+HR!AG4+HU!AG4+IE!AG4+IT!AG4+LT!AG4+LU!AG4+LV!AG4+MT!AG4+NL!AG4+PL!AG4+PT!AG4+RO!AG4+SE!AG4+SI!AG4+SK!AG4 -> 855766.18
A5: Extra-EU27 | B5: =AT!B5+BE!B5+BG!B5+CY!B5+CZ!B5+DE!B5+DK!B5+EE!B5+EL!B5+ES!B5+FI!B5+FR!B5+HR!B5+HU!B5+IE!B5+IT!B5+LT!B5+LU!B5+LV!B5+MT!B5+NL!B5+PL!B5+PT!B5+RO!B5+SE!B5+SI!B5+SK!B5 -> 4584683.4 | C5: =AT!C5+BE!C5+BG!C5+CY!C5+CZ!C5+DE!C5+DK!C5+EE!C5+EL!C5+ES!C5+FI!C5+FR!C5+HR!C5+HU!C5+IE!C5+IT!C5+LT!C5+LU!C5+LV!C5+MT!C5+NL!C5+PL!C5+PT!C5+RO!C5+SE!C5+SI!C5+SK!C5 -> 4425101.7 | D5: =AT!D5+BE!D5+BG!D5+CY!D5+CZ!D5+DE!D5+DK!D5+EE!D5+EL!D5+ES!D5+FI!D5+FR!D5+HR!D5+HU!D5+IE!D5+IT!D5+LT!D5+LU!D5+LV!D5+MT!D5+NL!D5+PL!D5+PT!D5+RO!D5+SE!D5+SI!D5+SK!D5 -> 4321354.3 | E5: =AT!E5+BE!E5+BG!E5+CY!E5+CZ!E5+DE!E5+DK!E5+EE!E5+EL!E5+ES!E5+FI!E5+FR!E5+HR!E5+HU!E5+IE!E5+IT!E5+LT!E5+LU!E5+LV!E5+MT!E5+NL!E5+PL!E5+PT!E5+RO!E5+SE!E5+SI!E5+SK!E5 -> 4301587.5 | F5: =AT!F5+BE!F5+BG!F5+CY!F5+CZ!F5+DE!F5+DK!F5+EE!F5+EL!F5+ES!F5+FI!F5+FR!F5+HR!F5+HU!F5+IE!F5+IT!F5+LT!F5+LU!F5+LV!F5+MT!F5+NL!F5+PL!F5+PT!F5+RO!F5+SE!F5+SI!F5+SK!F5 -> 4197572.2 | G5: =AT!G5+BE!G5+BG!G5+CY!G5+CZ!G5+DE!G5+DK!G5+EE!G5+EL!G5+ES!G5+FI!G5+FR!G5+HR!G5+HU!G5+IE!G5+IT!G5+LT!G5+LU!G5+LV!G5+MT!G5+NL!G5+PL!G5+PT!G5+RO!G5+SE!G5+SI!G5+SK!G5 -> 4191607.6 | H5: =AT!H5+BE!H5+BG!H5+CY!H5+CZ!H5+DE!H5+DK!H5+EE!H5+EL!H5+ES!H5+FI!H5+FR!H5+HR!H5+HU!H5+IE!H5+IT!H5+LT!H5+LU!H5+LV!H5+MT!H5+NL!H5+PL!H5+PT!H5+RO!H5+SE!H5+SI!H5+SK!H5 -> 4225542.5 | I5: =AT!I5+BE!I5+BG!I5+CY!I5+CZ!I5+DE!I5+DK!I5+EE!I5+EL!I5+ES!I5+FI!I5+FR!I5+HR!I5+HU!I5+IE!I5+IT!I5+LT!I5+LU!I5+LV!I5+MT!I5+NL!I5+PL!I5+PT!I5+RO!I5+SE!I5+SI!I5+SK!I5 -> 4432490.1 | ... AG5: =AT!AG5+BE!AG5+BG!AG5+CY!AG5+CZ!AG5+DE!AG5+DK!AG5+EE!AG5+EL!AG5+ES!AG5+FI!AG5+FR!AG5+HR!AG5+HU!AG5+IE!AG5+IT!AG5+LT!AG5+LU!AG5+LV!AG5+MT!AG5+NL!AG5+PL!AG5+PT!AG5+RO!AG5+SE!AG5+SI!AG5+SK!AG5 -> 7280053
A6: * Considering both inwards and outwards flows of goods transported with half of the distance of the voyages (thus the total distance for Intra-EU in the EU aggregation)
A8: Market shares of activity (% of tkm) | B8: =IF(B3=0,0,B3/B$3) -> 1 | C8: =IF(C3=0,0,C3/C$3) -> 1 | D8: =IF(D3=0,0,D3/D$3) -> 1 | E8: =IF(E3=0,0,E3/E$3) -> 1 | F8: =IF(F3=0,0,F3/F$3) -> 1 | G8: =IF(G3=0,0,G3/G$3) -> 1 | H8: =IF(H3=0,0,H3/H$3) -> 1 | I8: =IF(I3=0,0,I3/I$3) -> 1 | ... AG8: =IF(AG3=0,0,AG3/AG$3) -> 1
A9: Intra-EU27 | B9: =IF(B4=0,0,B4/B$3) -> 0.12842765 | C9: =IF(C4=0,0,C4/C$3) -> 0.12486572 | D9: =IF(D4=0,0,D4/D$3) -> 0.12853364 | E9: =IF(E4=0,0,E4/E$3) -> 0.12708241 | F9: =IF(F4=0,0,F4/F$3) -> 0.1284136 | G9: =IF(G4=0,0,G4/G$3) -> 0.12452263 | H9: =IF(H4=0,0,H4/H$3) -> 0.12612321 | I9: =IF(I4=0,0,I4/I$3) -> 0.12179313 | ... AG9: =IF(AG4=0,0,AG4/AG$3) -> 0.105185
A10: Extra-EU27 | B10: =IF(B5=0,0,B5/B$3) -> 0.87157235 | C10: =IF(C5=0,0,C5/C$3) -> 0.87513428 | D10: =IF(D5=0,0,D5/D$3) -> 0.87146636 | E10: =IF(E5=0,0,E5/E$3) -> 0.87291759 | F10: =IF(F5=0,0,F5/F$3) -> 0.8715864 | G10: =IF(G5=0,0,G5/G$3) -> 0.87547737 | H10: =IF(H5=0,0,H5/H$3) -> 0.87387679 | I10: =IF(I5=0,0,I5/I$3) -> 0.87820687 | ... AG10: =IF(AG5=0,0,AG5/AG$3) -> 0.894815
A12: Vehicle-km (Mvkm) | B12: =SUM(B13:B14) -> 362.91279 | C12: =SUM(C13:C14) -> 334.56875 | D12: =SUM(D13:D14) -> 331.78253 | E12: =SUM(E13:E14) -> 332.52903 | F12: =SUM(F13:F14) -> 331.3739 | G12: =SUM(G13:G14) -> 326.6431 | H12: =SUM(H13:H14) -> 326.43785 | I12: =SUM(I13:I14) -> 331.64998 | ... AG12: =SUM(AG13:AG14) -> 301.27333
A13: Intra-EU27 | B13: =AT!B13+BE!B13+BG!B13+CY!B13+CZ!B13+DE!B13+DK!B13+EE!B13+EL!B13+ES!B13+FI!B13+FR!B13+HR!B13+HU!B13+IE!B13+IT!B13+LT!B13+LU!B13+LV!B13+MT!B13+NL!B13+PL!B13+PT!B13+RO!B13+SE!B13+SI!B13+SK!B13 -> 137.55843 | C13: =AT!C13+BE!C13+BG!C13+CY!C13+CZ!C13+DE!C13+DK!C13+EE!C13+EL!C13+ES!C13+FI!C13+FR!C13+HR!C13+HU!C13+IE!C13+IT!C13+LT!C13+LU!C13+LV!C13+MT!C13+NL!C13+PL!C13+PT!C13+RO!C13+SE!C13+SI!C13+SK!C13 -> 124.47235 | D13: =AT!D13+BE!D13+BG!D13+CY!D13+CZ!D13+DE!D13+DK!D13+EE!D13+EL!D13+ES!D13+FI!D13+FR!D13+HR!D13+HU!D13+IE!D13+IT!D13+LT!D13+LU!D13+LV!D13+MT!D13+NL!D13+PL!D13+PT!D13+RO!D13+SE!D13+SI!D13+SK!D13 -> 126.00158 | E13: =AT!E13+BE!E13+BG!E13+CY!E13+CZ!E13+DE!E13+DK!E13+EE!E13+EL!E13+ES!E13+FI!E13+FR!E13+HR!E13+HU!E13+IE!E13+IT!E13+LT!E13+LU!E13+LV!E13+MT!E13+NL!E13+PL!E13+PT!E13+RO!E13+SE!E13+SI!E13+SK!E13 -> 125.37252 | F13: =AT!F13+BE!F13+BG!F13+CY!F13+CZ!F13+DE!F13+DK!F13+EE!F13+EL!F13+ES!F13+FI!F13+FR!F13+HR!F13+HU!F13+IE!F13+IT!F13+LT!F13+LU!F13+LV!F13+MT!F13+NL!F13+PL!F13+PT!F13+RO!F13+SE!F13+SI!F13+SK!F13 -> 126.09139 | G13: =AT!G13+BE!G13+BG!G13+CY!G13+CZ!G13+DE!G13+DK!G13+EE!G13+EL!G13+ES!G13+FI!G13+FR!G13+HR!G13+HU!G13+IE!G13+IT!G13+LT!G13+LU!G13+LV!G13+MT!G13+NL!G13+PL!G13+PT!G13+RO!G13+SE!G13+SI!G13+SK!G13 -> 121.92408 | H13: =AT!H13+BE!H13+BG!H13+CY!H13+CZ!H13+DE!H13+DK!H13+EE!H13+EL!H13+ES!H13+FI!H13+FR!H13+HR!H13+HU!H13+IE!H13+IT!H13+LT!H13+LU!H13+LV!H13+MT!H13+NL!H13+PL!H13+PT!H13+RO!H13+SE!H13+SI!H13+SK!H13 -> 122.28962 | I13: =AT!I13+BE!I13+BG!I13+CY!I13+CZ!I13+DE!I13+DK!I13+EE!I13+EL!I13+ES!I13+FI!I13+FR!I13+HR!I13+HU!I13+IE!I13+IT!I13+LT!I13+LU!I13+LV!I13+MT!I13+NL!I13+PL!I13+PT!I13+RO!I13+SE!I13+SI!I13+SK!I13 -> 121.62621 | ... AG13: =AT!AG13+BE!AG13+BG!AG13+CY!AG13+CZ!AG13+DE!AG13+DK!AG13+EE!AG13+EL!AG13+ES!AG13+FI!AG13+FR!AG13+HR!AG13+HU!AG13+IE!AG13+IT!AG13+LT!AG13+LU!AG13+LV!AG13+MT!AG13+NL!AG13+PL!AG13+PT!AG13+RO!AG13+SE!AG13+SI!AG13+SK!AG13 -> 110.70642
A14: Extra-EU27 | B14: =AT!B14+BE!B14+BG!B14+CY!B14+CZ!B14+DE!B14+DK!B14+EE!B14+EL!B14+ES!B14+FI!B14+FR!B14+HR!B14+HU!B14+IE!B14+IT!B14+LT!B14+LU!B14+LV!B14+MT!B14+NL!B14+PL!B14+PT!B14+RO!B14+SE!B14+SI!B14+SK!B14 -> 225.35436 | C14: =AT!C14+BE!C14+BG!C14+CY!C14+CZ!C14+DE!C14+DK!C14+EE!C14+EL!C14+ES!C14+FI!C14+FR!C14+HR!C14+HU!C14+IE!C14+IT!C14+LT!C14+LU!C14+LV!C14+MT!C14+NL!C14+PL!C14+PT!C14+RO!C14+SE!C14+SI!C14+SK!C14 -> 210.0964 | D14: =AT!D14+BE!D14+BG!D14+CY!D14+CZ!D14+DE!D14+DK!D14+EE!D14+EL!D14+ES!D14+FI!D14+FR!D14+HR!D14+HU!D14+IE!D14+IT!D14+LT!D14+LU!D14+LV!D14+MT!D14+NL!D14+PL!D14+PT!D14+RO!D14+SE!D14+SI!D14+SK!D14 -> 205.78094 | E14: =AT!E14+BE!E14+BG!E14+CY!E14+CZ!E14+DE!E14+DK!E14+EE!E14+EL!E14+ES!E14+FI!E14+FR!E14+HR!E14+HU!E14+IE!E14+IT!E14+LT!E14+LU!E14+LV!E14+MT!E14+NL!E14+PL!E14+PT!E14+RO!E14+SE!E14+SI!E14+SK!E14 -> 207.1565 | F14: =AT!F14+BE!F14+BG!F14+CY!F14+CZ!F14+DE!F14+DK!F14+EE!F14+EL!F14+ES!F14+FI!F14+FR!F14+HR!F14+HU!F14+IE!F14+IT!F14+LT!F14+LU!F14+LV!F14+MT!F14+NL!F14+PL!F14+PT!F14+RO!F14+SE!F14+SI!F14+SK!F14 -> 205.2825 | G14: =AT!G14+BE!G14+BG!G14+CY!G14+CZ!G14+DE!G14+DK!G14+EE!G14+EL!G14+ES!G14+FI!G14+FR!G14+HR!G14+HU!G14+IE!G14+IT!G14+LT!G14+LU!G14+LV!G14+MT!G14+NL!G14+PL!G14+PT!G14+RO!G14+SE!G14+SI!G14+SK!G14 -> 204.71903 | H14: =AT!H14+BE!H14+BG!H14+CY!H14+CZ!H14+DE!H14+DK!H14+EE!H14+EL!H14+ES!H14+FI!H14+FR!H14+HR!H14+HU!H14+IE!H14+IT!H14+LT!H14+LU!H14+LV!H14+MT!H14+NL!H14+PL!H14+PT!H14+RO!H14+SE!H14+SI!H14+SK!H14 -> 204.14823 | I14: =AT!I14+BE!I14+BG!I14+CY!I14+CZ!I14+DE!I14+DK!I14+EE!I14+EL!I14+ES!I14+FI!I14+FR!I14+HR!I14+HU!I14+IE!I14+IT!I14+LT!I14+LU!I14+LV!I14+MT!I14+NL!I14+PL!I14+PT!I14+RO!I14+SE!I14+SI!I14+SK!I14 -> 210.02377 | ... AG14: =AT!AG14+BE!AG14+BG!AG14+CY!AG14+CZ!AG14+DE!AG14+DK!AG14+EE!AG14+EL!AG14+ES!AG14+FI!AG14+FR!AG14+HR!AG14+HU!AG14+IE!AG14+IT!AG14+LT!AG14+LU!AG14+LV!AG14+MT!AG14+NL!AG14+PL!AG14+PT!AG14+RO!AG14+SE!AG14+SI!AG14+SK!AG14 -> 190.56691
A15: * Considering half of the distance of the voyages (thus the total distance for Intra-EU in the EU aggregation)
A17: Market shares of vehicle km (% of km) | B17: =IF(B12=0,0,B12/B$12) -> 1 | C17: =IF(C12=0,0,C12/C$12) -> 1 | D17: =IF(D12=0,0,D12/D$12) -> 1 | E17: =IF(E12=0,0,E12/E$12) -> 1 | F17: =IF(F12=0,0,F12/F$12) -> 1 | G17: =IF(G12=0,0,G12/G$12) -> 1 | H17: =IF(H12=0,0,H12/H$12) -> 1 | I17: =IF(I12=0,0,I12/I$12) -> 1 | ... AG17: =IF(AG12=0,0,AG12/AG$12) -> 1
A18: Intra-EU27 | B18: =IF(B13=0,0,B13/B$12) -> 0.3790399 | C18: =IF(C13=0,0,C13/C$12) -> 0.37203818 | D18: =IF(D13=0,0,D13/D$12) -> 0.37977161 | E18: =IF(E13=0,0,E13/E$12) -> 0.37702731 | F18: =IF(F13=0,0,F13/F$12) -> 0.38051094 | G18: =IF(G13=0,0,G13/G$12) -> 0.37326389 | H18: =IF(H13=0,0,H13/H$12) -> 0.37461839 | I18: =IF(I13=0,0,I13/I$12) -> 0.36673063 | ... AG18: =IF(AG13=0,0,AG13/AG$12) -> 0.36746173
A19: Extra-EU27 | B19: =IF(B14=0,0,B14/B$12) -> 0.6209601 | C19: =IF(C14=0,0,C14/C$12) -> 0.62796182 | D19: =IF(D14=0,0,D14/D$12) -> 0.62022839 | E19: =IF(E14=0,0,E14/E$12) -> 0.62297269 | F19: =IF(F14=0,0,F14/F$12) -> 0.61948906 | G19: =IF(G14=0,0,G14/G$12) -> 0.62673611 | H19: =IF(H14=0,0,H14/H$12) -> 0.62538161 | I19: =IF(I14=0,0,I14/I$12) -> 0.63326937 | ... AG19: =IF(AG14=0,0,AG14/AG$12) -> 0.63253827
A21: Load factor of vessels (t/movement) | B21: =IF(B3=0,0,B3/B12) -> 14494.513 | C21: =IF(C3=0,0,C3/C12) -> 15113.435 | D21: =IF(D3=0,0,D3/D12) -> 14945.682 | E21: =IF(E3=0,0,E3/E12) -> 14819.241 | F21: =IF(F3=0,0,F3/F12) -> 14533.474 | G21: =IF(G3=0,0,G3/G12) -> 14657.577 | H21: =IF(H3=0,0,H3/H12) -> 14812.616 | I21: =IF(I3=0,0,I3/I12) -> 15218.469 | ... AG21: =IF(AG3=0,0,AG3/AG12) -> 27004.777
A22: Intra-EU27 | B22: =IF(B4=0,0,B4/B13) -> 4911.0825 | C22: =IF(C4=0,0,C4/C13) -> 5072.463 | D22: =IF(D4=0,0,D4/D13) -> 5058.3636 | E22: =IF(E4=0,0,E4/E13) -> 4995.0357 | F22: =IF(F4=0,0,F4/F13) -> 4904.7096 | G22: =IF(G4=0,0,G4/G13) -> 4889.8383 | H22: =IF(H4=0,0,H4/H13) -> 4986.9806 | I22: =IF(I4=0,0,I4/I13) -> 5054.1317 | ... AG22: =IF(AG4=0,0,AG4/AG13) -> 7730.0504
A23: Extra-EU27 | B23: =IF(B5=0,0,B5/B14) -> 20344.329 | C23: =IF(C5=0,0,C5/C14) -> 21062.244 | D23: =IF(D5=0,0,D5/D14) -> 20999.779 | E23: =IF(E5=0,0,E5/E14) -> 20764.916 | F23: =IF(F5=0,0,F5/F14) -> 20447.783 | G23: =IF(G5=0,0,G5/G14) -> 20474.929 | H23: =IF(H5=0,0,H5/H14) -> 20698.404 | I23: =IF(I5=0,0,I5/I14) -> 21104.707 | ... AG23: =IF(AG5=0,0,AG5/AG14) -> 38202.083
A25: Total energy consumption (ktoe) | B25: =SUM(B26,B32) -> 33136.348 | C25: =SUM(C26,C32) -> 32882.736 | D25: =SUM(D26,D32) -> 33177.888 | E25: =SUM(E26,E32) -> 33059.931 | F25: =SUM(F26,F32) -> 32585.648 | G25: =SUM(G26,G32) -> 32778.737 | H25: =SUM(H26,H32) -> 34472.748 | I25: =SUM(I26,I32) -> 36998.102 | ... AG25: =SUM(AG26,AG32) -> 40756.205
A26: Intra-EU27 | B26: =SUM(B27:B31) -> 8807.0163 | C26: =SUM(C27:C31) -> 8621.1681 | D26: =SUM(D27:D31) -> 8892.8083 | E26: =SUM(E27:E31) -> 8989.4812 | F26: =SUM(F27:F31) -> 8953.8183 | G26: =SUM(G27:G31) -> 9044.7408 | H26: =SUM(H27:H31) -> 9542.9335 | I26: =SUM(I27:I31) -> 10194.121 | ... AG26: =SUM(AG27:AG31) -> 10190.723
A27: Gas oil and diesel oil (excluding biofuel portion) | B27: =AT!B27+BE!B27+BG!B27+CY!B27+CZ!B27+DE!B27+DK!B27+EE!B27+EL!B27+ES!B27+FI!B27+FR!B27+HR!B27+HU!B27+IE!B27+IT!B27+LT!B27+LU!B27+LV!B27+MT!B27+NL!B27+PL!B27+PT!B27+RO!B27+SE!B27+SI!B27+SK!B27 -> 4500.282 | C27: =AT!C27+BE!C27+BG!C27+CY!C27+CZ!C27+DE!C27+DK!C27+EE!C27+EL!C27+ES!C27+FI!C27+FR!C27+HR!C27+HU!C27+IE!C27+IT!C27+LT!C27+LU!C27+LV!C27+MT!C27+NL!C27+PL!C27+PT!C27+RO!C27+SE!C27+SI!C27+SK!C27 -> 4471.163 | D27: =AT!D27+BE!D27+BG!D27+CY!D27+CZ!D27+DE!D27+DK!D27+EE!D27+EL!D27+ES!D27+FI!D27+FR!D27+HR!D27+HU!D27+IE!D27+IT!D27+LT!D27+LU!D27+LV!D27+MT!D27+NL!D27+PL!D27+PT!D27+RO!D27+SE!D27+SI!D27+SK!D27 -> 4789.6758 | E27: =AT!E27+BE!E27+BG!E27+CY!E27+CZ!E27+DE!E27+DK!E27+EE!E27+EL!E27+ES!E27+FI!E27+FR!E27+HR!E27+HU!E27+IE!E27+IT!E27+LT!E27+LU!E27+LV!E27+MT!E27+NL!E27+PL!E27+PT!E27+RO!E27+SE!E27+SI!E27+SK!E27 -> 4369.3352 | F27: =AT!F27+BE!F27+BG!F27+CY!F27+CZ!F27+DE!F27+DK!F27+EE!F27+EL!F27+ES!F27+FI!F27+FR!F27+HR!F27+HU!F27+IE!F27+IT!F27+LT!F27+LU!F27+LV!F27+MT!F27+NL!F27+PL!F27+PT!F27+RO!F27+SE!F27+SI!F27+SK!F27 -> 4233.3953 | G27: =AT!G27+BE!G27+BG!G27+CY!G27+CZ!G27+DE!G27+DK!G27+EE!G27+EL!G27+ES!G27+FI!G27+FR!G27+HR!G27+HU!G27+IE!G27+IT!G27+LT!G27+LU!G27+LV!G27+MT!G27+NL!G27+PL!G27+PT!G27+RO!G27+SE!G27+SI!G27+SK!G27 -> 4656.1994 | H27: =AT!H27+BE!H27+BG!H27+CY!H27+CZ!H27+DE!H27+DK!H27+EE!H27+EL!H27+ES!H27+FI!H27+FR!H27+HR!H27+HU!H27+IE!H27+IT!H27+LT!H27+LU!H27+LV!H27+MT!H27+NL!H27+PL!H27+PT!H27+RO!H27+SE!H27+SI!H27+SK!H27 -> 4955.3874 | I27: =AT!I27+BE!I27+BG!I27+CY!I27+CZ!I27+DE!I27+DK!I27+EE!I27+EL!I27+ES!I27+FI!I27+FR!I27+HR!I27+HU!I27+IE!I27+IT!I27+LT!I27+LU!I27+LV!I27+MT!I27+NL!I27+PL!I27+PT!I27+RO!I27+SE!I27+SI!I27+SK!I27 -> 5245.7676 | ... AG27: =AT!AG27+BE!AG27+BG!AG27+CY!AG27+CZ!AG27+DE!AG27+DK!AG27+EE!AG27+EL!AG27+ES!AG27+FI!AG27+FR!AG27+HR!AG27+HU!AG27+IE!AG27+IT!AG27+LT!AG27+LU!AG27+LV!AG27+MT!AG27+NL!AG27+PL!AG27+PT!AG27+RO!AG27+SE!AG27+SI!AG27+SK!AG27 -> 6528.7287
A28: Fuel oil and Other oil products | B28: =AT!B28+BE!B28+BG!B28+CY!B28+CZ!B28+DE!B28+DK!B28+EE!B28+EL!B28+ES!B28+FI!B28+FR!B28+HR!B28+HU!B28+IE!B28+IT!B28+LT!B28+LU!B28+LV!B28+MT!B28+NL!B28+PL!B28+PT!B28+RO!B28+SE!B28+SI!B28+SK!B28 -> 4306.7343 | C28: =AT!C28+BE!C28+BG!C28+CY!C28+CZ!C28+DE!C28+DK!C28+EE!C28+EL!C28+ES!C28+FI!C28+FR!C28+HR!C28+HU!C28+IE!C28+IT!C28+LT!C28+LU!C28+LV!C28+MT!C28+NL!C28+PL!C28+PT!C28+RO!C28+SE!C28+SI!C28+SK!C28 -> 4150.0051 | D28: =AT!D28+BE!D28+BG!D28+CY!D28+CZ!D28+DE!D28+DK!D28+EE!D28+EL!D28+ES!D28+FI!D28+FR!D28+HR!D28+HU!D28+IE!D28+IT!D28+LT!D28+LU!D28+LV!D28+MT!D28+NL!D28+PL!D28+PT!D28+RO!D28+SE!D28+SI!D28+SK!D28 -> 4103.1325 | E28: =AT!E28+BE!E28+BG!E28+CY!E28+CZ!E28+DE!E28+DK!E28+EE!E28+EL!E28+ES!E28+FI!E28+FR!E28+HR!E28+HU!E28+IE!E28+IT!E28+LT!E28+LU!E28+LV!E28+MT!E28+NL!E28+PL!E28+PT!E28+RO!E28+SE!E28+SI!E28+SK!E28 -> 4620.1459 | F28: =AT!F28+BE!F28+BG!F28+CY!F28+CZ!F28+DE!F28+DK!F28+EE!F28+EL!F28+ES!F28+FI!F28+FR!F28+HR!F28+HU!F28+IE!F28+IT!F28+LT!F28+LU!F28+LV!F28+MT!F28+NL!F28+PL!F28+PT!F28+RO!F28+SE!F28+SI!F28+SK!F28 -> 4720.423 | G28: =AT!G28+BE!G28+BG!G28+CY!G28+CZ!G28+DE!G28+DK!G28+EE!G28+EL!G28+ES!G28+FI!G28+FR!G28+HR!G28+HU!G28+IE!G28+IT!G28+LT!G28+LU!G28+LV!G28+MT!G28+NL!G28+PL!G28+PT!G28+RO!G28+SE!G28+SI!G28+SK!G28 -> 4388.5415 | H28: =AT!H28+BE!H28+BG!H28+CY!H28+CZ!H28+DE!H28+DK!H28+EE!H28+EL!H28+ES!H28+FI!H28+FR!H28+HR!H28+HU!H28+IE!H28+IT!H28+LT!H28+LU!H28+LV!H28+MT!H28+NL!H28+PL!H28+PT!H28+RO!H28+SE!H28+SI!H28+SK!H28 -> 4587.5461 | I28: =AT!I28+BE!I28+BG!I28+CY!I28+CZ!I28+DE!I28+DK!I28+EE!I28+EL!I28+ES!I28+FI!I28+FR!I28+HR!I28+HU!I28+IE!I28+IT!I28+LT!I28+LU!I28+LV!I28+MT!I28+NL!I28+PL!I28+PT!I28+RO!I28+SE!I28+SI!I28+SK!I28 -> 4948.3532 | ... AG28: =AT!AG28+BE!AG28+BG!AG28+CY!AG28+CZ!AG28+DE!AG28+DK!AG28+EE!AG28+EL!AG28+ES!AG28+FI!AG28+FR!AG28+HR!AG28+HU!AG28+IE!AG28+IT!AG28+LT!AG28+LU!AG28+LV!AG28+MT!AG28+NL!AG28+PL!AG28+PT!AG28+RO!AG28+SE!AG28+SI!AG28+SK!AG28 -> 3577.9652
A29: Blended biofuels | B29: =AT!B29+BE!B29+BG!B29+CY!B29+CZ!B29+DE!B29+DK!B29+EE!B29+EL!B29+ES!B29+FI!B29+FR!B29+HR!B29+HU!B29+IE!B29+IT!B29+LT!B29+LU!B29+LV!B29+MT!B29+NL!B29+PL!B29+PT!B29+RO!B29+SE!B29+SI!B29+SK!B29 -> 0 | C29: =AT!C29+BE!C29+BG!C29+CY!C29+CZ!C29+DE!C29+DK!C29+EE!C29+EL!C29+ES!C29+FI!C29+FR!C29+HR!C29+HU!C29+IE!C29+IT!C29+LT!C29+LU!C29+LV!C29+MT!C29+NL!C29+PL!C29+PT!C29+RO!C29+SE!C29+SI!C29+SK!C29 -> 0 | D29: =AT!D29+BE!D29+BG!D29+CY!D29+CZ!D29+DE!D29+DK!D29+EE!D29+EL!D29+ES!D29+FI!D29+FR!D29+HR!D29+HU!D29+IE!D29+IT!D29+LT!D29+LU!D29+LV!D29+MT!D29+NL!D29+PL!D29+PT!D29+RO!D29+SE!D29+SI!D29+SK!D29 -> 0 | E29: =AT!E29+BE!E29+BG!E29+CY!E29+CZ!E29+DE!E29+DK!E29+EE!E29+EL!E29+ES!E29+FI!E29+FR!E29+HR!E29+HU!E29+IE!E29+IT!E29+LT!E29+LU!E29+LV!E29+MT!E29+NL!E29+PL!E29+PT!E29+RO!E29+SE!E29+SI!E29+SK!E29 -> 0 | F29: =AT!F29+BE!F29+BG!F29+CY!F29+CZ!F29+DE!F29+DK!F29+EE!F29+EL!F29+ES!F29+FI!F29+FR!F29+HR!F29+HU!F29+IE!F29+IT!F29+LT!F29+LU!F29+LV!F29+MT!F29+NL!F29+PL!F29+PT!F29+RO!F29+SE!F29+SI!F29+SK!F29 -> 0 | G29: =AT!G29+BE!G29+BG!G29+CY!G29+CZ!G29+DE!G29+DK!G29+EE!G29+EL!G29+ES!G29+FI!G29+FR!G29+HR!G29+HU!G29+IE!G29+IT!G29+LT!G29+LU!G29+LV!G29+MT!G29+NL!G29+PL!G29+PT!G29+RO!G29+SE!G29+SI!G29+SK!G29 -> 0 | H29: =AT!H29+BE!H29+BG!H29+CY!H29+CZ!H29+DE!H29+DK!H29+EE!H29+EL!H29+ES!H29+FI!H29+FR!H29+HR!H29+HU!H29+IE!H29+IT!H29+LT!H29+LU!H29+LV!H29+MT!H29+NL!H29+PL!H29+PT!H29+RO!H29+SE!H29+SI!H29+SK!H29 -> 0 | I29: =AT!I29+BE!I29+BG!I29+CY!I29+CZ!I29+DE!I29+DK!I29+EE!I29+EL!I29+ES!I29+FI!I29+FR!I29+HR!I29+HU!I29+IE!I29+IT!I29+LT!I29+LU!I29+LV!I29+MT!I29+NL!I29+PL!I29+PT!I29+RO!I29+SE!I29+SI!I29+SK!I29 -> 0 | ... AG29: =AT!AG29+BE!AG29+BG!AG29+CY!AG29+CZ!AG29+DE!AG29+DK!AG29+EE!AG29+EL!AG29+ES!AG29+FI!AG29+FR!AG29+HR!AG29+HU!AG29+IE!AG29+IT!AG29+LT!AG29+LU!AG29+LV!AG29+MT!AG29+NL!AG29+PL!AG29+PT!AG29+RO!AG29+SE!AG29+SI!AG29+SK!AG29 -> 23.561438
A30: Natural gas | B30: =AT!B30+BE!B30+BG!B30+CY!B30+CZ!B30+DE!B30+DK!B30+EE!B30+EL!B30+ES!B30+FI!B30+FR!B30+HR!B30+HU!B30+IE!B30+IT!B30+LT!B30+LU!B30+LV!B30+MT!B30+NL!B30+PL!B30+PT!B30+RO!B30+SE!B30+SI!B30+SK!B30 -> 0 | C30: =AT!C30+BE!C30+BG!C30+CY!C30+CZ!C30+DE!C30+DK!C30+EE!C30+EL!C30+ES!C30+FI!C30+FR!C30+HR!C30+HU!C30+IE!C30+IT!C30+LT!C30+LU!C30+LV!C30+MT!C30+NL!C30+PL!C30+PT!C30+RO!C30+SE!C30+SI!C30+SK!C30 -> 0 | D30: =AT!D30+BE!D30+BG!D30+CY!D30+CZ!D30+DE!D30+DK!D30+EE!D30+EL!D30+ES!D30+FI!D30+FR!D30+HR!D30+HU!D30+IE!D30+IT!D30+LT!D30+LU!D30+LV!D30+MT!D30+NL!D30+PL!D30+PT!D30+RO!D30+SE!D30+SI!D30+SK!D30 -> 0 | E30: =AT!E30+BE!E30+BG!E30+CY!E30+CZ!E30+DE!E30+DK!E30+EE!E30+EL!E30+ES!E30+FI!E30+FR!E30+HR!E30+HU!E30+IE!E30+IT!E30+LT!E30+LU!E30+LV!E30+MT!E30+NL!E30+PL!E30+PT!E30+RO!E30+SE!E30+SI!E30+SK!E30 -> 0 | F30: =AT!F30+BE!F30+BG!F30+CY!F30+CZ!F30+DE!F30+DK!F30+EE!F30+EL!F30+ES!F30+FI!F30+FR!F30+HR!F30+HU!F30+IE!F30+IT!F30+LT!F30+LU!F30+LV!F30+MT!F30+NL!F30+PL!F30+PT!F30+RO!F30+SE!F30+SI!F30+SK!F30 -> 0 | G30: =AT!G30+BE!G30+BG!G30+CY!G30+CZ!G30+DE!G30+DK!G30+EE!G30+EL!G30+ES!G30+FI!G30+FR!G30+HR!G30+HU!G30+IE!G30+IT!G30+LT!G30+LU!G30+LV!G30+MT!G30+NL!G30+PL!G30+PT!G30+RO!G30+SE!G30+SI!G30+SK!G30 -> 0 | H30: =AT!H30+BE!H30+BG!H30+CY!H30+CZ!H30+DE!H30+DK!H30+EE!H30+EL!H30+ES!H30+FI!H30+FR!H30+HR!H30+HU!H30+IE!H30+IT!H30+LT!H30+LU!H30+LV!H30+MT!H30+NL!H30+PL!H30+PT!H30+RO!H30+SE!H30+SI!H30+SK!H30 -> 0 | I30: =AT!I30+BE!I30+BG!I30+CY!I30+CZ!I30+DE!I30+DK!I30+EE!I30+EL!I30+ES!I30+FI!I30+FR!I30+HR!I30+HU!I30+IE!I30+IT!I30+LT!I30+LU!I30+LV!I30+MT!I30+NL!I30+PL!I30+PT!I30+RO!I30+SE!I30+SI!I30+SK!I30 -> 0 | ... AG30: =AT!AG30+BE!AG30+BG!AG30+CY!AG30+CZ!AG30+DE!AG30+DK!AG30+EE!AG30+EL!AG30+ES!AG30+FI!AG30+FR!AG30+HR!AG30+HU!AG30+IE!AG30+IT!AG30+LT!AG30+LU!AG30+LV!AG30+MT!AG30+NL!AG30+PL!AG30+PT!AG30+RO!AG30+SE!AG30+SI!AG30+SK!AG30 -> 60.467536
A31: Biogases | B31: =AT!B31+BE!B31+BG!B31+CY!B31+CZ!B31+DE!B31+DK!B31+EE!B31+EL!B31+ES!B31+FI!B31+FR!B31+HR!B31+HU!B31+IE!B31+IT!B31+LT!B31+LU!B31+LV!B31+MT!B31+NL!B31+PL!B31+PT!B31+RO!B31+SE!B31+SI!B31+SK!B31 -> 0 | C31: =AT!C31+BE!C31+BG!C31+CY!C31+CZ!C31+DE!C31+DK!C31+EE!C31+EL!C31+ES!C31+FI!C31+FR!C31+HR!C31+HU!C31+IE!C31+IT!C31+LT!C31+LU!C31+LV!C31+MT!C31+NL!C31+PL!C31+PT!C31+RO!C31+SE!C31+SI!C31+SK!C31 -> 0 | D31: =AT!D31+BE!D31+BG!D31+CY!D31+CZ!D31+DE!D31+DK!D31+EE!D31+EL!D31+ES!D31+FI!D31+FR!D31+HR!D31+HU!D31+IE!D31+IT!D31+LT!D31+LU!D31+LV!D31+MT!D31+NL!D31+PL!D31+PT!D31+RO!D31+SE!D31+SI!D31+SK!D31 -> 0 | E31: =AT!E31+BE!E31+BG!E31+CY!E31+CZ!E31+DE!E31+DK!E31+EE!E31+EL!E31+ES!E31+FI!E31+FR!E31+HR!E31+HU!E31+IE!E31+IT!E31+LT!E31+LU!E31+LV!E31+MT!E31+NL!E31+PL!E31+PT!E31+RO!E31+SE!E31+SI!E31+SK!E31 -> 0 | F31: =AT!F31+BE!F31+BG!F31+CY!F31+CZ!F31+DE!F31+DK!F31+EE!F31+EL!F31+ES!F31+FI!F31+FR!F31+HR!F31+HU!F31+IE!F31+IT!F31+LT!F31+LU!F31+LV!F31+MT!F31+NL!F31+PL!F31+PT!F31+RO!F31+SE!F31+SI!F31+SK!F31 -> 0 | G31: =AT!G31+BE!G31+BG!G31+CY!G31+CZ!G31+DE!G31+DK!G31+EE!G31+EL!G31+ES!G31+FI!G31+FR!G31+HR!G31+HU!G31+IE!G31+IT!G31+LT!G31+LU!G31+LV!G31+MT!G31+NL!G31+PL!G31+PT!G31+RO!G31+SE!G31+SI!G31+SK!G31 -> 0 | H31: =AT!H31+BE!H31+BG!H31+CY!H31+CZ!H31+DE!H31+DK!H31+EE!H31+EL!H31+ES!H31+FI!H31+FR!H31+HR!H31+HU!H31+IE!H31+IT!H31+LT!H31+LU!H31+LV!H31+MT!H31+NL!H31+PL!H31+PT!H31+RO!H31+SE!H31+SI!H31+SK!H31 -> 0 | I31: =AT!I31+BE!I31+BG!I31+CY!I31+CZ!I31+DE!I31+DK!I31+EE!I31+EL!I31+ES!I31+FI!I31+FR!I31+HR!I31+HU!I31+IE!I31+IT!I31+LT!I31+LU!I31+LV!I31+MT!I31+NL!I31+PL!I31+PT!I31+RO!I31+SE!I31+SI!I31+SK!I31 -> 0 | ... AG31: =AT!AG31+BE!AG31+BG!AG31+CY!AG31+CZ!AG31+DE!AG31+DK!AG31+EE!AG31+EL!AG31+ES!AG31+FI!AG31+FR!AG31+HR!AG31+HU!AG31+IE!AG31+IT!AG31+LT!AG31+LU!AG31+LV!AG31+MT!AG31+NL!AG31+PL!AG31+PT!AG31+RO!AG31+SE!AG31+SI!AG31+SK!AG31 -> 0
A32: Extra-EU27 | B32: =SUM(B33:B37) -> 24329.332 | C32: =SUM(C33:C37) -> 24261.568 | D32: =SUM(D33:D37) -> 24285.08 | E32: =SUM(E33:E37) -> 24070.45 | F32: =SUM(F33:F37) -> 23631.83 | G32: =SUM(G33:G37) -> 23733.996 | H32: =SUM(H33:H37) -> 24929.815 | I32: =SUM(I33:I37) -> 26803.981 | ... AG32: =SUM(AG33:AG37) -> 30565.482
A33: Gas oil and diesel oil (excluding biofuel portion) | B33: =AT!B33+BE!B33+BG!B33+CY!B33+CZ!B33+DE!B33+DK!B33+EE!B33+EL!B33+ES!B33+FI!B33+FR!B33+HR!B33+HU!B33+IE!B33+IT!B33+LT!B33+LU!B33+LV!B33+MT!B33+NL!B33+PL!B33+PT!B33+RO!B33+SE!B33+SI!B33+SK!B33 -> 2672.1781 | C33: =AT!C33+BE!C33+BG!C33+CY!C33+CZ!C33+DE!C33+DK!C33+EE!C33+EL!C33+ES!C33+FI!C33+FR!C33+HR!C33+HU!C33+IE!C33+IT!C33+LT!C33+LU!C33+LV!C33+MT!C33+NL!C33+PL!C33+PT!C33+RO!C33+SE!C33+SI!C33+SK!C33 -> 2709.3584 | D33: =AT!D33+BE!D33+BG!D33+CY!D33+CZ!D33+DE!D33+DK!D33+EE!D33+EL!D33+ES!D33+FI!D33+FR!D33+HR!D33+HU!D33+IE!D33+IT!D33+LT!D33+LU!D33+LV!D33+MT!D33+NL!D33+PL!D33+PT!D33+RO!D33+SE!D33+SI!D33+SK!D33 -> 2787.7601 | E33: =AT!E33+BE!E33+BG!E33+CY!E33+CZ!E33+DE!E33+DK!E33+EE!E33+EL!E33+ES!E33+FI!E33+FR!E33+HR!E33+HU!E33+IE!E33+IT!E33+LT!E33+LU!E33+LV!E33+MT!E33+NL!E33+PL!E33+PT!E33+RO!E33+SE!E33+SI!E33+SK!E33 -> 2503.3826 | F33: =AT!F33+BE!F33+BG!F33+CY!F33+CZ!F33+DE!F33+DK!F33+EE!F33+EL!F33+ES!F33+FI!F33+FR!F33+HR!F33+HU!F33+IE!F33+IT!F33+LT!F33+LU!F33+LV!F33+MT!F33+NL!F33+PL!F33+PT!F33+RO!F33+SE!F33+SI!F33+SK!F33 -> 2288.4124 | G33: =AT!G33+BE!G33+BG!G33+CY!G33+CZ!G33+DE!G33+DK!G33+EE!G33+EL!G33+ES!G33+FI!G33+FR!G33+HR!G33+HU!G33+IE!G33+IT!G33+LT!G33+LU!G33+LV!G33+MT!G33+NL!G33+PL!G33+PT!G33+RO!G33+SE!G33+SI!G33+SK!G33 -> 2485.2589 | H33: =AT!H33+BE!H33+BG!H33+CY!H33+CZ!H33+DE!H33+DK!H33+EE!H33+EL!H33+ES!H33+FI!H33+FR!H33+HR!H33+HU!H33+IE!H33+IT!H33+LT!H33+LU!H33+LV!H33+MT!H33+NL!H33+PL!H33+PT!H33+RO!H33+SE!H33+SI!H33+SK!H33 -> 2622.9272 | I33: =AT!I33+BE!I33+BG!I33+CY!I33+CZ!I33+DE!I33+DK!I33+EE!I33+EL!I33+ES!I33+FI!I33+FR!I33+HR!I33+HU!I33+IE!I33+IT!I33+LT!I33+LU!I33+LV!I33+MT!I33+NL!I33+PL!I33+PT!I33+RO!I33+SE!I33+SI!I33+SK!I33 -> 2759.5811 | ... AG33: =AT!AG33+BE!AG33+BG!AG33+CY!AG33+CZ!AG33+DE!AG33+DK!AG33+EE!AG33+EL!AG33+ES!AG33+FI!AG33+FR!AG33+HR!AG33+HU!AG33+IE!AG33+IT!AG33+LT!AG33+LU!AG33+LV!AG33+MT!AG33+NL!AG33+PL!AG33+PT!AG33+RO!AG33+SE!AG33+SI!AG33+SK!AG33 -> 4763.8051
A34: Fuel oil and Other oil products | B34: =AT!B34+BE!B34+BG!B34+CY!B34+CZ!B34+DE!B34+DK!B34+EE!B34+EL!B34+ES!B34+FI!B34+FR!B34+HR!B34+HU!B34+IE!B34+IT!B34+LT!B34+LU!B34+LV!B34+MT!B34+NL!B34+PL!B34+PT!B34+RO!B34+SE!B34+SI!B34+SK!B34 -> 21657.154 | C34: =AT!C34+BE!C34+BG!C34+CY!C34+CZ!C34+DE!C34+DK!C34+EE!C34+EL!C34+ES!C34+FI!C34+FR!C34+HR!C34+HU!C34+IE!C34+IT!C34+LT!C34+LU!C34+LV!C34+MT!C34+NL!C34+PL!C34+PT!C34+RO!C34+SE!C34+SI!C34+SK!C34 -> 21552.21 | D34: =AT!D34+BE!D34+BG!D34+CY!D34+CZ!D34+DE!D34+DK!D34+EE!D34+EL!D34+ES!D34+FI!D34+FR!D34+HR!D34+HU!D34+IE!D34+IT!D34+LT!D34+LU!D34+LV!D34+MT!D34+NL!D34+PL!D34+PT!D34+RO!D34+SE!D34+SI!D34+SK!D34 -> 21497.32 | E34: =AT!E34+BE!E34+BG!E34+CY!E34+CZ!E34+DE!E34+DK!E34+EE!E34+EL!E34+ES!E34+FI!E34+FR!E34+HR!E34+HU!E34+IE!E34+IT!E34+LT!E34+LU!E34+LV!E34+MT!E34+NL!E34+PL!E34+PT!E34+RO!E34+SE!E34+SI!E34+SK!E34 -> 21567.067 | F34: =AT!F34+BE!F34+BG!F34+CY!F34+CZ!F34+DE!F34+DK!F34+EE!F34+EL!F34+ES!F34+FI!F34+FR!F34+HR!F34+HU!F34+IE!F34+IT!F34+LT!F34+LU!F34+LV!F34+MT!F34+NL!F34+PL!F34+PT!F34+RO!F34+SE!F34+SI!F34+SK!F34 -> 21343.417 | G34: =AT!G34+BE!G34+BG!G34+CY!G34+CZ!G34+DE!G34+DK!G34+EE!G34+EL!G34+ES!G34+FI!G34+FR!G34+HR!G34+HU!G34+IE!G34+IT!G34+LT!G34+LU!G34+LV!G34+MT!G34+NL!G34+PL!G34+PT!G34+RO!G34+SE!G34+SI!G34+SK!G34 -> 21248.737 | H34: =AT!H34+BE!H34+BG!H34+CY!H34+CZ!H34+DE!H34+DK!H34+EE!H34+EL!H34+ES!H34+FI!H34+FR!H34+HR!H34+HU!H34+IE!H34+IT!H34+LT!H34+LU!H34+LV!H34+MT!H34+NL!H34+PL!H34+PT!H34+RO!H34+SE!H34+SI!H34+SK!H34 -> 22306.888 | I34: =AT!I34+BE!I34+BG!I34+CY!I34+CZ!I34+DE!I34+DK!I34+EE!I34+EL!I34+ES!I34+FI!I34+FR!I34+HR!I34+HU!I34+IE!I34+IT!I34+LT!I34+LU!I34+LV!I34+MT!I34+NL!I34+PL!I34+PT!I34+RO!I34+SE!I34+SI!I34+SK!I34 -> 24044.4 | ... AG34: =AT!AG34+BE!AG34+BG!AG34+CY!AG34+CZ!AG34+DE!AG34+DK!AG34+EE!AG34+EL!AG34+ES!AG34+FI!AG34+FR!AG34+HR!AG34+HU!AG34+IE!AG34+IT!AG34+LT!AG34+LU!AG34+LV!AG34+MT!AG34+NL!AG34+PL!AG34+PT!AG34+RO!AG34+SE!AG34+SI!AG34+SK!AG34 -> 25454.273
A35: Blended biofuels | B35: =AT!B35+BE!B35+BG!B35+CY!B35+CZ!B35+DE!B35+DK!B35+EE!B35+EL!B35+ES!B35+FI!B35+FR!B35+HR!B35+HU!B35+IE!B35+IT!B35+LT!B35+LU!B35+LV!B35+MT!B35+NL!B35+PL!B35+PT!B35+RO!B35+SE!B35+SI!B35+SK!B35 -> 0 | C35: =AT!C35+BE!C35+BG!C35+CY!C35+CZ!C35+DE!C35+DK!C35+EE!C35+EL!C35+ES!C35+FI!C35+FR!C35+HR!C35+HU!C35+IE!C35+IT!C35+LT!C35+LU!C35+LV!C35+MT!C35+NL!C35+PL!C35+PT!C35+RO!C35+SE!C35+SI!C35+SK!C35 -> 0 | D35: =AT!D35+BE!D35+BG!D35+CY!D35+CZ!D35+DE!D35+DK!D35+EE!D35+EL!D35+ES!D35+FI!D35+FR!D35+HR!D35+HU!D35+IE!D35+IT!D35+LT!D35+LU!D35+LV!D35+MT!D35+NL!D35+PL!D35+PT!D35+RO!D35+SE!D35+SI!D35+SK!D35 -> 0 | E35: =AT!E35+BE!E35+BG!E35+CY!E35+CZ!E35+DE!E35+DK!E35+EE!E35+EL!E35+ES!E35+FI!E35+FR!E35+HR!E35+HU!E35+IE!E35+IT!E35+LT!E35+LU!E35+LV!E35+MT!E35+NL!E35+PL!E35+PT!E35+RO!E35+SE!E35+SI!E35+SK!E35 -> 0 | F35: =AT!F35+BE!F35+BG!F35+CY!F35+CZ!F35+DE!F35+DK!F35+EE!F35+EL!F35+ES!F35+FI!F35+FR!F35+HR!F35+HU!F35+IE!F35+IT!F35+LT!F35+LU!F35+LV!F35+MT!F35+NL!F35+PL!F35+PT!F35+RO!F35+SE!F35+SI!F35+SK!F35 -> 0 | G35: =AT!G35+BE!G35+BG!G35+CY!G35+CZ!G35+DE!G35+DK!G35+EE!G35+EL!G35+ES!G35+FI!G35+FR!G35+HR!G35+HU!G35+IE!G35+IT!G35+LT!G35+LU!G35+LV!G35+MT!G35+NL!G35+PL!G35+PT!G35+RO!G35+SE!G35+SI!G35+SK!G35 -> 0 | H35: =AT!H35+BE!H35+BG!H35+CY!H35+CZ!H35+DE!H35+DK!H35+EE!H35+EL!H35+ES!H35+FI!H35+FR!H35+HR!H35+HU!H35+IE!H35+IT!H35+LT!H35+LU!H35+LV!H35+MT!H35+NL!H35+PL!H35+PT!H35+RO!H35+SE!H35+SI!H35+SK!H35 -> 0 | I35: =AT!I35+BE!I35+BG!I35+CY!I35+CZ!I35+DE!I35+DK!I35+EE!I35+EL!I35+ES!I35+FI!I35+FR!I35+HR!I35+HU!I35+IE!I35+IT!I35+LT!I35+LU!I35+LV!I35+MT!I35+NL!I35+PL!I35+PT!I35+RO!I35+SE!I35+SI!I35+SK!I35 -> 0 | ... AG35: =AT!AG35+BE!AG35+BG!AG35+CY!AG35+CZ!AG35+DE!AG35+DK!AG35+EE!AG35+EL!AG35+ES!AG35+FI!AG35+FR!AG35+HR!AG35+HU!AG35+IE!AG35+IT!AG35+LT!AG35+LU!AG35+LV!AG35+MT!AG35+NL!AG35+PL!AG35+PT!AG35+RO!AG35+SE!AG35+SI!AG35+SK!AG35 -> 143.82429
A36: Natural gas | B36: =AT!B36+BE!B36+BG!B36+CY!B36+CZ!B36+DE!B36+DK!B36+EE!B36+EL!B36+ES!B36+FI!B36+FR!B36+HR!B36+HU!B36+IE!B36+IT!B36+LT!B36+LU!B36+LV!B36+MT!B36+NL!B36+PL!B36+PT!B36+RO!B36+SE!B36+SI!B36+SK!B36 -> 0 | C36: =AT!C36+BE!C36+BG!C36+CY!C36+CZ!C36+DE!C36+DK!C36+EE!C36+EL!C36+ES!C36+FI!C36+FR!C36+HR!C36+HU!C36+IE!C36+IT!C36+LT!C36+LU!C36+LV!C36+MT!C36+NL!C36+PL!C36+PT!C36+RO!C36+SE!C36+SI!C36+SK!C36 -> 0 | D36: =AT!D36+BE!D36+BG!D36+CY!D36+CZ!D36+DE!D36+DK!D36+EE!D36+EL!D36+ES!D36+FI!D36+FR!D36+HR!D36+HU!D36+IE!D36+IT!D36+LT!D36+LU!D36+LV!D36+MT!D36+NL!D36+PL!D36+PT!D36+RO!D36+SE!D36+SI!D36+SK!D36 -> 0 | E36: =AT!E36+BE!E36+BG!E36+CY!E36+CZ!E36+DE!E36+DK!E36+EE!E36+EL!E36+ES!E36+FI!E36+FR!E36+HR!E36+HU!E36+IE!E36+IT!E36+LT!E36+LU!E36+LV!E36+MT!E36+NL!E36+PL!E36+PT!E36+RO!E36+SE!E36+SI!E36+SK!E36 -> 0 | F36: =AT!F36+BE!F36+BG!F36+CY!F36+CZ!F36+DE!F36+DK!F36+EE!F36+EL!F36+ES!F36+FI!F36+FR!F36+HR!F36+HU!F36+IE!F36+IT!F36+LT!F36+LU!F36+LV!F36+MT!F36+NL!F36+PL!F36+PT!F36+RO!F36+SE!F36+SI!F36+SK!F36 -> 0 | G36: =AT!G36+BE!G36+BG!G36+CY!G36+CZ!G36+DE!G36+DK!G36+EE!G36+EL!G36+ES!G36+FI!G36+FR!G36+HR!G36+HU!G36+IE!G36+IT!G36+LT!G36+LU!G36+LV!G36+MT!G36+NL!G36+PL!G36+PT!G36+RO!G36+SE!G36+SI!G36+SK!G36 -> 0 | H36: =AT!H36+BE!H36+BG!H36+CY!H36+CZ!H36+DE!H36+DK!H36+EE!H36+EL!H36+ES!H36+FI!H36+FR!H36+HR!H36+HU!H36+IE!H36+IT!H36+LT!H36+LU!H36+LV!H36+MT!H36+NL!H36+PL!H36+PT!H36+RO!H36+SE!H36+SI!H36+SK!H36 -> 0 | I36: =AT!I36+BE!I36+BG!I36+CY!I36+CZ!I36+DE!I36+DK!I36+EE!I36+EL!I36+ES!I36+FI!I36+FR!I36+HR!I36+HU!I36+IE!I36+IT!I36+LT!I36+LU!I36+LV!I36+MT!I36+NL!I36+PL!I36+PT!I36+RO!I36+SE!I36+SI!I36+SK!I36 -> 0 | ... AG36: =AT!AG36+BE!AG36+BG!AG36+CY!AG36+CZ!AG36+DE!AG36+DK!AG36+EE!AG36+EL!AG36+ES!AG36+FI!AG36+FR!AG36+HR!AG36+HU!AG36+IE!AG36+IT!AG36+LT!AG36+LU!AG36+LV!AG36+MT!AG36+NL!AG36+PL!AG36+PT!AG36+RO!AG36+SE!AG36+SI!AG36+SK!AG36 -> 203.57924
A37: Biogases | B37: =AT!B37+BE!B37+BG!B37+CY!B37+CZ!B37+DE!B37+DK!B37+EE!B37+EL!B37+ES!B37+FI!B37+FR!B37+HR!B37+HU!B37+IE!B37+IT!B37+LT!B37+LU!B37+LV!B37+MT!B37+NL!B37+PL!B37+PT!B37+RO!B37+SE!B37+SI!B37+SK!B37 -> 0 | C37: =AT!C37+BE!C37+BG!C37+CY!C37+CZ!C37+DE!C37+DK!C37+EE!C37+EL!C37+ES!C37+FI!C37+FR!C37+HR!C37+HU!C37+IE!C37+IT!C37+LT!C37+LU!C37+LV!C37+MT!C37+NL!C37+PL!C37+PT!C37+RO!C37+SE!C37+SI!C37+SK!C37 -> 0 | D37: =AT!D37+BE!D37+BG!D37+CY!D37+CZ!D37+DE!D37+DK!D37+EE!D37+EL!D37+ES!D37+FI!D37+FR!D37+HR!D37+HU!D37+IE!D37+IT!D37+LT!D37+LU!D37+LV!D37+MT!D37+NL!D37+PL!D37+PT!D37+RO!D37+SE!D37+SI!D37+SK!D37 -> 0 | E37: =AT!E37+BE!E37+BG!E37+CY!E37+CZ!E37+DE!E37+DK!E37+EE!E37+EL!E37+ES!E37+FI!E37+FR!E37+HR!E37+HU!E37+IE!E37+IT!E37+LT!E37+LU!E37+LV!E37+MT!E37+NL!E37+PL!E37+PT!E37+RO!E37+SE!E37+SI!E37+SK!E37 -> 0 | F37: =AT!F37+BE!F37+BG!F37+CY!F37+CZ!F37+DE!F37+DK!F37+EE!F37+EL!F37+ES!F37+FI!F37+FR!F37+HR!F37+HU!F37+IE!F37+IT!F37+LT!F37+LU!F37+LV!F37+MT!F37+NL!F37+PL!F37+PT!F37+RO!F37+SE!F37+SI!F37+SK!F37 -> 0 | G37: =AT!G37+BE!G37+BG!G37+CY!G37+CZ!G37+DE!G37+DK!G37+EE!G37+EL!G37+ES!G37+FI!G37+FR!G37+HR!G37+HU!G37+IE!G37+IT!G37+LT!G37+LU!G37+LV!G37+MT!G37+NL!G37+PL!G37+PT!G37+RO!G37+SE!G37+SI!G37+SK!G37 -> 0 | H37: =AT!H37+BE!H37+BG!H37+CY!H37+CZ!H37+DE!H37+DK!H37+EE!H37+EL!H37+ES!H37+FI!H37+FR!H37+HR!H37+HU!H37+IE!H37+IT!H37+LT!H37+LU!H37+LV!H37+MT!H37+NL!H37+PL!H37+PT!H37+RO!H37+SE!H37+SI!H37+SK!H37 -> 0 | I37: =AT!I37+BE!I37+BG!I37+CY!I37+CZ!I37+DE!I37+DK!I37+EE!I37+EL!I37+ES!I37+FI!I37+FR!I37+HR!I37+HU!I37+IE!I37+IT!I37+LT!I37+LU!I37+LV!I37+MT!I37+NL!I37+PL!I37+PT!I37+RO!I37+SE!I37+SI!I37+SK!I37 -> 0 | ... AG37: =AT!AG37+BE!AG37+BG!AG37+CY!AG37+CZ!AG37+DE!AG37+DK!AG37+EE!AG37+EL!AG37+ES!AG37+FI!AG37+FR!AG37+HR!AG37+HU!AG37+IE!AG37+IT!AG37+LT!AG37+LU!AG37+LV!AG37+MT!AG37+NL!AG37+PL!AG37+PT!AG37+RO!AG37+SE!AG37+SI!AG37+SK!AG37 -> 0
A38: * As reported in the Eurostat energy balances
A40: Energy intensity over activity (kgoe / 000 tkm) | B40: =IF(B25=0,0,B25/(B3/1000)) -> 6.2993936 | C40: =IF(C25=0,0,C25/(C3/1000)) -> 6.5030844 | D40: =IF(D25=0,0,D25/(D3/1000)) -> 6.6908223 | E40: =IF(E25=0,0,E25/(E3/1000)) -> 6.7088244 | F40: =IF(F25=0,0,F25/(F3/1000)) -> 6.7661035 | G40: =IF(G25=0,0,G25/(G3/1000)) -> 6.8463095 | H40: =IF(H25=0,0,H25/(H3/1000)) -> 7.1292466 | I40: =IF(I25=0,0,I25/(I3/1000)) -> 7.330414 | ... AG40: =IF(AG25=0,0,AG25/(AG3/1000)) -> 5.0094777
A41: Intra-EU27 | B41: =IF(B26=0,0,B26/(B4/1000)) -> 13.036601 | C41: =IF(C26=0,0,C26/(C4/1000)) -> 13.654454 | D41: =IF(D26=0,0,D26/(D4/1000)) -> 13.952527 | E41: =IF(E26=0,0,E26/(E4/1000)) -> 14.354685 | F41: =IF(F26=0,0,F26/(F4/1000)) -> 14.478032 | G41: =IF(G26=0,0,G26/(G4/1000)) -> 15.170928 | H41: =IF(H26=0,0,H26/(H4/1000)) -> 15.647848 | I41: =IF(I26=0,0,I26/(I4/1000)) -> 16.583495 | ... AG41: =IF(AG26=0,0,AG26/(AG4/1000)) -> 11.908303
A42: Extra-EU27 | B42: =IF(B32=0,0,B32/(B5/1000)) -> 5.3066548 | C42: =IF(C32=0,0,C32/(C5/1000)) -> 5.4827142 | D42: =IF(D32=0,0,D32/(D5/1000)) -> 5.6197846 | E42: =IF(E32=0,0,E32/(E5/1000)) -> 5.5957132 | F42: =IF(F32=0,0,F32/(F5/1000)) -> 5.6298805 | G42: =IF(G32=0,0,G32/(G5/1000)) -> 5.6622658 | H42: =IF(H32=0,0,H32/(H5/1000)) -> 5.8997903 | I42: =IF(I32=0,0,I32/(I5/1000)) -> 6.047161 | ... AG42: =IF(AG32=0,0,AG32/(AG5/1000)) -> 4.1985246
A44: Shares of total energy consumption (%) | B44: =IF(B25=0,0,B25/B$25) -> 1 | C44: =IF(C25=0,0,C25/C$25) -> 1 | D44: =IF(D25=0,0,D25/D$25) -> 1 | E44: =IF(E25=0,0,E25/E$25) -> 1 | F44: =IF(F25=0,0,F25/F$25) -> 1 | G44: =IF(G25=0,0,G25/G$25) -> 1 | H44: =IF(H25=0,0,H25/H$25) -> 1 | I44: =IF(I25=0,0,I25/I$25) -> 1 | ... AG44: =IF(AG25=0,0,AG25/AG$25) -> 1
A45: Intra-EU27 | B45: =IF(B26=0,0,B26/B$25) -> 0.26578114 | C45: =IF(C26=0,0,C26/C$25) -> 0.26217916 | D45: =IF(D26=0,0,D26/D$25) -> 0.26803418 | E45: =IF(E26=0,0,E26/E$25) -> 0.2719147 | F45: =IF(F26=0,0,F26/F$25) -> 0.27477797 | G45: =IF(G26=0,0,G26/G$25) -> 0.27593317 | H45: =IF(H26=0,0,H26/H$25) -> 0.27682543 | I45: =IF(I26=0,0,I26/I$25) -> 0.27553091 | ... AG45: =IF(AG26=0,0,AG26/AG$25) -> 0.25004102
A46: Extra-EU27 | B46: =IF(B32=0,0,B32/B$25) -> 0.73421886 | C46: =IF(C32=0,0,C32/C$25) -> 0.73782084 | D46: =IF(D32=0,0,D32/D$25) -> 0.73196582 | E46: =IF(E32=0,0,E32/E$25) -> 0.7280853 | F46: =IF(F32=0,0,F32/F$25) -> 0.72522203 | G46: =IF(G32=0,0,G32/G$25) -> 0.72406683 | H46: =IF(H32=0,0,H32/H$25) -> 0.72317457 | I46: =IF(I32=0,0,I32/I$25) -> 0.72446909 | ... AG46: =IF(AG32=0,0,AG32/AG$25) -> 0.74995898
A48: Vehicle-efficiency - effective (kgoe/100 km) | B48: =IF(B25=0,0,100*B25/B12) -> 9130.6643 | C48: =IF(C25=0,0,100*C25/C12) -> 9828.3945 | D48: =IF(D25=0,0,100*D25/D12) -> 9999.8901 | E48: =IF(E25=0,0,100*E25/E12) -> 9941.9684 | F48: =IF(F25=0,0,100*F25/F12) -> 9833.4986 | G48: =IF(G25=0,0,100*G25/G12) -> 10035.031 | H48: =IF(H25=0,0,100*H25/H12) -> 10560.279 | I48: =IF(I25=0,0,100*I25/I12) -> 11155.768 | ... AG48: =IF(AG25=0,0,100*AG25/AG12) -> 13527.983
A49: Intra-EU27 | B49: =IF(B26=0,0,100*B26/B13) -> 6402.3823 | C49: =IF(C26=0,0,100*C26/C13) -> 6926.1714 | D49: =IF(D26=0,0,100*D26/D13) -> 7057.6955 | E49: =IF(E26=0,0,100*E26/E13) -> 7170.2163 | F49: =IF(F26=0,0,100*F26/F13) -> 7101.0542 | G49: =IF(G26=0,0,100*G26/G13) -> 7418.3386 | H49: =IF(H26=0,0,100*H26/H13) -> 7803.5513 | I49: =IF(I26=0,0,100*I26/I13) -> 8381.5168 | ... AG49: =IF(AG26=0,0,100*AG26/AG13) -> 9205.1782
...

Sheet AT
A1: AT - Austria | B1: 1990 | C1: 1991 | D1: 1992 | E1: 1993 | F1: 1994 | G1: 1995 | H1: 1996 | I1: 1997 | J1: 1998 | K1: 1999 | L1: 2000 | M1: 2001 | N1: 2002 | O1: 2003 | P1: 2004 | Q1: 2005 | R1: 2006 | S1: 2007 | T1: 2008 | U1: 2009 | V1: 2010 | W1: 2011 | X1: 2012 | Y1: 2013 | Z1: 2014 | AA1: 2015 | AB1: 2016 | AC1: 2017 | AD1: 2018 | AE1: 2019 | AF1: 2020 | AG1: 2021
A3: Transport activity (Mtkm) | B3: =SUM(B4:B5) -> 0 | C3: =SUM(C4:C5) -> 0 | D3: =SUM(D4:D5) -> 0 | E3: =SUM(E4:E5) -> 0 | F3: =SUM(F4:F5) -> 0 | G3: =SUM(G4:G5) -> 0 | H3: =SUM(H4:H5) -> 0 | I3: =SUM(I4:I5) -> 0 | ... AG3: =SUM(AG4:AG5) -> 0
A4: Intra-EU27 | B4: 0 | C4: 0 | D4: 0 | E4: 0 | F4: 0 | G4: 0 | H4: 0 | I4: 0 | J4: 0 | K4: 0 | L4: 0 | M4: 0 | N4: 0 | O4: 0 | P4: 0 | Q4: 0 | R4: 0 | S4: 0 | T4: 0 | U4: 0 | V4: 0 | W4: 0 | X4: 0 | Y4: 0 | Z4: 0 | AA4: 0 | AB4: 0 | AC4: 0 | AD4: 0 | AE4: 0 | AF4: 0 | AG4: 0
A5: Extra-EU27 | B5: 0 | C5: 0 | D5: 0 | E5: 0 | F5: 0 | G5: 0 | H5: 0 | I5: 0 | J5: 0 | K5: 0 | L5: 0 | M5: 0 | N5: 0 | O5: 0 | P5: 0 | Q5: 0 | R5: 0 | S5: 0 | T5: 0 | U5: 0 | V5: 0 | W5: 0 | X5: 0 | Y5: 0 | Z5: 0 | AA5: 0 | AB5: 0 | AC5: 0 | AD5: 0 | AE5: 0 | AF5: 0 | AG5: 0
A6: * Considering both inwards and outwards flows of goods transported with half of the distance of the voyages (thus the total distance for Intra-EU in the EU aggregation)
A8: Market shares of activity (% of tkm) | B8: =IF(B3=0,0,B3/B$3) -> 0 | C8: =IF(C3=0,0,C3/C$3) -> 0 | D8: =IF(D3=0,0,D3/D$3) -> 0 | E8: =IF(E3=0,0,E3/E$3) -> 0 | F8: =IF(F3=0,0,F3/F$3) -> 0 | G8: =IF(G3=0,0,G3/G$3) -> 0 | H8: =IF(H3=0,0,H3/H$3) -> 0 | I8: =IF(I3=0,0,I3/I$3) -> 0 | ... AG8: =IF(AG3=0,0,AG3/AG$3) -> 0
A9: Intra-EU27 | B9: =IF(B4=0,0,B4/B$3) -> 0 | C9: =IF(C4=0,0,C4/C$3) -> 0 | D9: =IF(D4=0,0,D4/D$3) -> 0 | E9: =IF(E4=0,0,E4/E$3) -> 0 | F9: =IF(F4=0,0,F4/F$3) -> 0 | G9: =IF(G4=0,0,G4/G$3) -> 0 | H9: =IF(H4=0,0,H4/H$3) -> 0 | I9: =IF(I4=0,0,I4/I$3) -> 0 | ... AG9: =IF(AG4=0,0,AG4/AG$3) -> 0
A10: Extra-EU27 | B10: =IF(B5=0,0,B5/B$3) -> 0 | C10: =IF(C5=0,0,C5/C$3) -> 0 | D10: =IF(D5=0,0,D5/D$3) -> 0 | E10: =IF(E5=0,0,E5/E$3) -> 0 | F10: =IF(F5=0,0,F5/F$3) -> 0 | G10: =IF(G5=0,0,G5/G$3) -> 0 | H10: =IF(H5=0,0,H5/H$3) -> 0 | I10: =IF(I5=0,0,I5/I$3) -> 0 | ... AG10: =IF(AG5=0,0,AG5/AG$3) -> 0
A12: Vehicle-km (Mvkm) | B12: =SUM(B13:B14) -> 0 | C12: =SUM(C13:C14) -> 0 | D12: =SUM(D13:D14) -> 0 | E12: =SUM(E13:E14) -> 0 | F12: =SUM(F13:F14) -> 0 | G12: =SUM(G13:G14) -> 0 | H12: =SUM(H13:H14) -> 0 | I12: =SUM(I13:I14) -> 0 | ... AG12: =SUM(AG13:AG14) -> 0
A13: Intra-EU27 | B13: 0 | C13: 0 | D13: 0 | E13: 0 | F13: 0 | G13: 0 | H13: 0 | I13: 0 | J13: 0 | K13: 0 | L13: 0 | M13: 0 | N13: 0 | O13: 0 | P13: 0 | Q13: 0 | R13: 0 | S13: 0 | T13: 0 | U13: 0 | V13: 0 | W13: 0 | X13: 0 | Y13: 0 | Z13: 0 | AA13: 0 | AB13: 0 | AC13: 0 | AD13: 0 | AE13: 0 | AF13: 0 | AG13: 0
A14: Extra-EU27 | B14: 0 | C14: 0 | D14: 0 | E14: 0 | F14: 0 | G14: 0 | H14: 0 | I14: 0 | J14: 0 | K14: 0 | L14: 0 | M14: 0 | N14: 0 | O14: 0 | P14: 0 | Q14: 0 | R14: 0 | S14: 0 | T14: 0 | U14: 0 | V14: 0 | W14: 0 | X14: 0 | Y14: 0 | Z14: 0 | AA14: 0 | AB14: 0 | AC14: 0 | AD14: 0 | AE14: 0 | AF14: 0 | AG14: 0
A15: * Considering half of the distance of the voyages (thus the total distance for Intra-EU in the EU aggregation)
A17: Market shares of vehicle km (% of km) | B17: =IF(B12=0,0,B12/B$12) -> 0 | C17: =IF(C12=0,0,C12/C$12) -> 0 | D17: =IF(D12=0,0,D12/D$12) -> 0 | E17: =IF(E12=0,0,E12/E$12) -> 0 | F17: =IF(F12=0,0,F12/F$12) -> 0 | G17: =IF(G12=0,0,G12/G$12) -> 0 | H17: =IF(H12=0,0,H12/H$12) -> 0 | I17: =IF(I12=0,0,I12/I$12) -> 0 | ... AG17: =IF(AG12=0,0,AG12/AG$12) -> 0
A18: Intra-EU27 | B18: =IF(B13=0,0,B13/B$12) -> 0 | C18: =IF(C13=0,0,C13/C$12) -> 0 | D18: =IF(D13=0,0,D13/D$12) -> 0 | E18: =IF(E13=0,0,E13/E$12) -> 0 | F18: =IF(F13=0,0,F13/F$12) -> 0 | G18: =IF(G13=0,0,G13/G$12) -> 0 | H18: =IF(H13=0,0,H13/H$12) -> 0 | I18: =IF(I13=0,0,I13/I$12) -> 0 | ... AG18: =IF(AG13=0,0,AG13/AG$12) -> 0
A19: Extra-EU27 | B19: =IF(B14=0,0,B14/B$12) -> 0 | C19: =IF(C14=0,0,C14/C$12) -> 0 | D19: =IF(D14=0,0,D14/D$12) -> 0 | E19: =IF(E14=0,0,E14/E$12) -> 0 | F19: =IF(F14=0,0,F14/F$12) -> 0 | G19: =IF(G14=0,0,G14/G$12) -> 0 | H19: =IF(H14=0,0,H14/H$12) -> 0 | I19: =IF(I14=0,0,I14/I$12) -> 0 | ... AG19: =IF(AG14=0,0,AG14/AG$12) -> 0
A21: Load factor of vessels (t/movement) | B21: =IF(B3=0,0,B3/B12) -> 0 | C21: =IF(C3=0,0,C3/C12) -> 0 | D21: =IF(D3=0,0,D3/D12) -> 0 | E21: =IF(E3=0,0,E3/E12) -> 0 | F21: =IF(F3=0,0,F3/F12) -> 0 | G21: =IF(G3=0,0,G3/G12) -> 0 | H21: =IF(H3=0,0,H3/H12) -> 0 | I21: =IF(I3=0,0,I3/I12) -> 0 | ... AG21: =IF(AG3=0,0,AG3/AG12) -> 0
A22: Intra-EU27 | B22: =IF(B4=0,0,B4/B13) -> 0 | C22: =IF(C4=0,0,C4/C13) -> 0 | D22: =IF(D4=0,0,D4/D13) -> 0 | E22: =IF(E4=0,0,E4/E13) -> 0 | F22: =IF(F4=0,0,F4/F13) -> 0 | G22: =IF(G4=0,0,G4/G13) -> 0 | H22: =IF(H4=0,0,H4/H13) -> 0 | I22: =IF(I4=0,0,I4/I13) -> 0 | ... AG22: =IF(AG4=0,0,AG4/AG13) -> 0
A23: Extra-EU27 | B23: =IF(B5=0,0,B5/B14) -> 0 | C23: =IF(C5=0,0,C5/C14) -> 0 | D23: =IF(D5=0,0,D5/D14) -> 0 | E23: =IF(E5=0,0,E5/E14) -> 0 | F23: =IF(F5=0,0,F5/F14) -> 0 | G23: =IF(G5=0,0,G5/G14) -> 0 | H23: =IF(H5=0,0,H5/H14) -> 0 | I23: =IF(I5=0,0,I5/I14) -> 0 | ... AG23: =IF(AG5=0,0,AG5/AG14) -> 0
A25: Total energy consumption (ktoe) | B25: =SUM(B26,B32) -> 0 | C25: =SUM(C26,C32) -> 0 | D25: =SUM(D26,D32) -> 0 | E25: =SUM(E26,E32) -> 0 | F25: =SUM(F26,F32) -> 0 | G25: =SUM(G26,G32) -> 0 | H25: =SUM(H26,H32) -> 0 | I25: =SUM(I26,I32) -> 0 | ... AG25: =SUM(AG26,AG32) -> 0
A26: Intra-EU27 | B26: =SUM(B27:B31) -> 0 | C26: =SUM(C27:C31) -> 0 | D26: =SUM(D27:D31) -> 0 | E26: =SUM(E27:E31) -> 0 | F26: =SUM(F27:F31) -> 0 | G26: =SUM(G27:G31) -> 0 | H26: =SUM(H27:H31) -> 0 | I26: =SUM(I27:I31) -> 0 | ... AG26: =SUM(AG27:AG31) -> 0
A27: Gas oil and diesel oil (excluding biofuel portion) | B27: 0 | C27: 0 | D27: 0 | E27: 0 | F27: 0 | G27: 0 | H27: 0 | I27: 0 | J27: 0 | K27: 0 | L27: 0 | M27: 0 | N27: 0 | O27: 0 | P27: 0 | Q27: 0 | R27: 0 | S27: 0 | T27: 0 | U27: 0 | V27: 0 | W27: 0 | X27: 0 | Y27: 0 | Z27: 0 | AA27: 0 | AB27: 0 | AC27: 0 | AD27: 0 | AE27: 0 | AF27: 0 | AG27: 0
A28: Fuel oil and Other oil products | B28: 0 | C28: 0 | D28: 0 | E28: 0 | F28: 0 | G28: 0 | H28: 0 | I28: 0 | J28: 0 | K28: 0 | L28: 0 | M28: 0 | N28: 0 | O28: 0 | P28: 0 | Q28: 0 | R28: 0 | S28: 0 | T28: 0 | U28: 0 | V28: 0 | W28: 0 | X28: 0 | Y28: 0 | Z28: 0 | AA28: 0 | AB28: 0 | AC28: 0 | AD28: 0 | AE28: 0 | AF28: 0 | AG28: 0
A29: Blended biofuels | B29: 0 | C29: 0 | D29: 0 | E29: 0 | F29: 0 | G29: 0 | H29: 0 | I29: 0 | J29: 0 | K29: 0 | L29: 0 | M29: 0 | N29: 0 | O29: 0 | P29: 0 | Q29: 0 | R29: 0 | S29: 0 | T29: 0 | U29: 0 | V29: 0 | W29: 0 | X29: 0 | Y29: 0 | Z29: 0 | AA29: 0 | AB29: 0 | AC29: 0 | AD29: 0 | AE29: 0 | AF29: 0 | AG29: 0
A30: Natural gas | B30: 0 | C30: 0 | D30: 0 | E30: 0 | F30: 0 | G30: 0 | H30: 0 | I30: 0 | J30: 0 | K30: 0 | L30: 0 | M30: 0 | N30: 0 | O30: 0 | P30: 0 | Q30: 0 | R30: 0 | S30: 0 | T30: 0 | U30: 0 | V30: 0 | W30: 0 | X30: 0 | Y30: 0 | Z30: 0 | AA30: 0 | AB30: 0 | AC30: 0 | AD30: 0 | AE30: 0 | AF30: 0 | AG30: 0
A31: Biogases | B31: 0 | C31: 0 | D31: 0 | E31: 0 | F31: 0 | G31: 0 | H31: 0 | I31: 0 | J31: 0 | K31: 0 | L31: 0 | M31: 0 | N31: 0 | O31: 0 | P31: 0 | Q31: 0 | R31: 0 | S31: 0 | T31: 0 | U31: 0 | V31: 0 | W31: 0 | X31: 0 | Y31: 0 | Z31: 0 | AA31: 0 | AB31: 0 | AC31: 0 | AD31: 0 | AE31: 0 | AF31: 0 | AG31: 0
A32: Extra-EU27 | B32: =SUM(B33:B37) -> 0 | C32: =SUM(C33:C37) -> 0 | D32: =SUM(D33:D37) -> 0 | E32: =SUM(E33:E37) -> 0 | F32: =SUM(F33:F37) -> 0 | G32: =SUM(G33:G37) -> 0 | H32: =SUM(H33:H37) -> 0 | I32: =SUM(I33:I37) -> 0 | ... AG32: =SUM(AG33:AG37) -> 0
A33: Gas oil and diesel oil (excluding biofuel portion) | B33: 0 | C33: 0 | D33: 0 | E33: 0 | F33: 0 | G33: 0 | H33: 0 | I33: 0 | J33: 0 | K33: 0 | L33: 0 | M33: 0 | N33: 0 | O33: 0 | P33: 0 | Q33: 0 | R33: 0 | S33: 0 | T33: 0 | U33: 0 | V33: 0 | W33: 0 | X33: 0 | Y33: 0 | Z33: 0 | AA33: 0 | AB33: 0 | AC33: 0 | AD33: 0 | AE33: 0 | AF33: 0 | AG33: 0
A34: Fuel oil and Other oil products | B34: 0 | C34: 0 | D34: 0 | E34: 0 | F34: 0 | G34: 0 | H34: 0 | I34: 0 | J34: 0 | K34: 0 | L34: 0 | M34: 0 | N34: 0 | O34: 0 | P34: 0 | Q34: 0 | R34: 0 | S34: 0 | T34: 0 | U34: 0 | V34: 0 | W34: 0 | X34: 0 | Y34: 0 | Z34: 0 | AA34: 0 | AB34: 0 | AC34: 0 | AD34: 0 | AE34: 0 | AF34: 0 | AG34: 0
A35: Blended biofuels | B35: 0 | C35: 0 | D35: 0 | E35: 0 | F35: 0 | G35: 0 | H35: 0 | I35: 0 | J35: 0 | K35: 0 | L35: 0 | M35: 0 | N35: 0 | O35: 0 | P35: 0 | Q35: 0 | R35: 0 | S35: 0 | T35: 0 | U35: 0 | V35: 0 | W35: 0 | X35: 0 | Y35: 0 | Z35: 0 | AA35: 0 | AB35: 0 | AC35: 0 | AD35: 0 | AE35: 0 | AF35: 0 | AG35: 0
A36: Natural gas | B36: 0 | C36: 0 | D36: 0 | E36: 0 | F36: 0 | G36: 0 | H36: 0 | I36: 0 | J36: 0 | K36: 0 | L36: 0 | M36: 0 | N36: 0 | O36: 0 | P36: 0 | Q36: 0 | R36: 0 | S36: 0 | T36: 0 | U36: 0 | V36: 0 | W36: 0 | X36: 0 | Y36: 0 | Z36: 0 | AA36: 0 | AB36: 0 | AC36: 0 | AD36: 0 | AE36: 0 | AF36: 0 | AG36: 0
A37: Biogases | B37: 0 | C37: 0 | D37: 0 | E37: 0 | F37: 0 | G37: 0 | H37: 0 | I37: 0 | J37: 0 | K37: 0 | L37: 0 | M37: 0 | N37: 0 | O37: 0 | P37: 0 | Q37: 0 | R37: 0 | S37: 0 | T37: 0 | U37: 0 | V37: 0 | W37: 0 | X37: 0 | Y37: 0 | Z37: 0 | AA37: 0 | AB37: 0 | AC37: 0 | AD37: 0 | AE37: 0 | AF37: 0 | AG37: 0
A38: * As reported in the Eurostat energy balances
A40: Energy intensity over activity (kgoe / 000 tkm) | B40: =IF(B25=0,0,B25/(B3/1000)) -> 0 | C40: =IF(C25=0,0,C25/(C3/1000)) -> 0 | D40: =IF(D25=0,0,D25/(D3/1000)) -> 0 | E40: =IF(E25=0,0,E25/(E3/1000)) -> 0 | F40: =IF(F25=0,0,F25/(F3/1000)) -> 0 | G40: =IF(G25=0,0,G25/(G3/1000)) -> 0 | H40: =IF(H25=0,0,H25/(H3/1000)) -> 0 | I40: =IF(I25=0,0,I25/(I3/1000)) -> 0 | ... AG40: =IF(AG25=0,0,AG25/(AG3/1000)) -> 0
A41: Intra-EU27 | B41: =IF(B26=0,0,B26/(B4/1000)) -> 0 | C41: =IF(C26=0,0,C26/(C4/1000)) -> 0 | D41: =IF(D26=0,0,D26/(D4/1000)) -> 0 | E41: =IF(E26=0,0,E26/(E4/1000)) -> 0 | F41: =IF(F26=0,0,F26/(F4/1000)) -> 0 | G41: =IF(G26=0,0,G26/(G4/1000)) -> 0 | H41: =IF(H26=0,0,H26/(H4/1000)) -> 0 | I41: =IF(I26=0,0,I26/(I4/1000)) -> 0 | ... AG41: =IF(AG26=0,0,AG26/(AG4/1000)) -> 0
A42: Extra-EU27 | B42: =IF(B32=0,0,B32/(B5/1000)) -> 0 | C42: =IF(C32=0,0,C32/(C5/1000)) -> 0 | D42: =IF(D32=0,0,D32/(D5/1000)) -> 0 | E42: =IF(E32=0,0,E32/(E5/1000)) -> 0 | F42: =IF(F32=0,0,F32/(F5/1000)) -> 0 | G42: =IF(G32=0,0,G32/(G5/1000)) -> 0 | H42: =IF(H32=0,0,H32/(H5/1000)) -> 0 | I42: =IF(I32=0,0,I32/(I5/1000)) -> 0 | ... AG42: =IF(AG32=0,0,AG32/(AG5/1000)) -> 0
A44: Shares of total energy consumption (%) | B44: =IF(B25=0,0,B25/B$25) -> 0 | C44: =IF(C25=0,0,C25/C$25) -> 0 | D44: =IF(D25=0,0,D25/D$25) -> 0 | E44: =IF(E25=0,0,E25/E$25) -> 0 | F44: =IF(F25=0,0,F25/F$25) -> 0 | G44: =IF(G25=0,0,G25/G$25) -> 0 | H44: =IF(H25=0,0,H25/H$25) -> 0 | I44: =IF(I25=0,0,I25/I$25) -> 0 | ... AG44: =IF(AG25=0,0,AG25/AG$25) -> 0
A45: Intra-EU27 | B45: =IF(B26=0,0,B26/B$25) -> 0 | C45: =IF(C26=0,0,C26/C$25) -> 0 | D45: =IF(D26=0,0,D26/D$25) -> 0 | E45: =IF(E26=0,0,E26/E$25) -> 0 | F45: =IF(F26=0,0,F26/F$25) -> 0 | G45: =IF(G26=0,0,G26/G$25) -> 0 | H45: =IF(H26=0,0,H26/H$25) -> 0 | I45: =IF(I26=0,0,I26/I$25) -> 0 | ... AG45: =IF(AG26=0,0,AG26/AG$25) -> 0
A46: Extra-EU27 | B46: =IF(B32=0,0,B32/B$25) -> 0 | C46: =IF(C32=0,0,C32/C$25) -> 0 | D46: =IF(D32=0,0,D32/D$25) -> 0 | E46: =IF(E32=0,0,E32/E$25) -> 0 | F46: =IF(F32=0,0,F32/F$25) -> 0 | G46: =IF(G32=0,0,G32/G$25) -> 0 | H46: =IF(H32=0,0,H32/H$25) -> 0 | I46: =IF(I32=0,0,I32/I$25) -> 0 | ... AG46: =IF(AG32=0,0,AG32/AG$25) -> 0
A48: Vehicle-efficiency - effective (kgoe/100 km) | B48: =IF(B25=0,0,100*B25/B12) -> 0 | C48: =IF(C25=0,0,100*C25/C12) -> 0 | D48: =IF(D25=0,0,100*D25/D12) -> 0 | E48: =IF(E25=0,0,100*E25/E12) -> 0 | F48: =IF(F25=0,0,100*F25/F12) -> 0 | G48: =IF(G25=0,0,100*G25/G12) -> 0 | H48: =IF(H25=0,0,100*H25/H12) -> 0 | I48: =IF(I25=0,0,100*I25/I12) -> 0 | ... AG48: =IF(AG25=0,0,100*AG25/AG12) -> 0
A49: Intra-EU27 | B49: =IF(B26=0,0,100*B26/B13) -> 0 | C49: =IF(C26=0,0,100*C26/C13) -> 0 | D49: =IF(D26=0,0,100*D26/D13) -> 0 | E49: =IF(E26=0,0,100*E26/E13) -> 0 | F49: =IF(F26=0,0,100*F26/F13) -> 0 | G49: =IF(G26=0,0,100*G26/G13) -> 0 | H49: =IF(H26=0,0,100*H26/H13) -> 0 | I49: =IF(I26=0,0,100*I26/I13) -> 0 | ... AG49: =IF(AG26=0,0,100*AG26/AG13) -> 0
...

Sheet BE
A1: BE - Belgium | B1: 1990 | C1: 1991 | D1: 1992 | E1: 1993 | F1: 1994 | G1: 1995 | H1: 1996 | I1: 1997 | J1: 1998 | K1: 1999 | L1: 2000 | M1: 2001 | N1: 2002 | O1: 2003 | P1: 2004 | Q1: 2005 | R1: 2006 | S1: 2007 | T1: 2008 | U1: 2009 | V1: 2010 | W1: 2011 | X1: 2012 | Y1: 2013 | Z1: 2014 | AA1: 2015 | AB1: 2016 | AC1: 2017 | AD1: 2018 | AE1: 2019 | AF1: 2020 | AG1: 2021
A3: Transport activity (Mtkm) | B3: =SUM(B4:B5) -> 403139.07 | C3: =SUM(C4:C5) -> 412620.92 | D3: =SUM(D4:D5) -> 410253.67 | E3: =SUM(E4:E5) -> 421760.58 | F3: =SUM(F4:F5) -> 403786.84 | G3: =SUM(G4:G5) -> 384852.6 | H3: =SUM(H4:H5) -> 444144.57 | I3: =SUM(I4:I5) -> 502383.58 | ... AG3: =SUM(AG4:AG5) -> 996096.75
A4: Intra-EU27 | B4: 31740.465 | C4: 32487.002 | D4: 32300.621 | E4: 33206.598 | F4: 31791.466 | G4: 30300.711 | H4: 36229.191 | I4: 40972.136 | J4: 41939.087 | K4: 40587.618 | L4: 46238.616 | M4: 46952.356 | N4: 44512.442 | O4: 47891.084 | P4: 44126.823 | Q4: 40645.749 | R4: 41955.666 | S4: 44342.347 | T4: 45251.768 | U4: 36764.839 | V4: 45378.725 | W4: 43081.067 | X4: 44906.362 | Y4: 48018.925 | Z4: 51540.992 | AA4: 56783.204 | AB4: 70323.869 | AC4: 67350.483 | AD4: 65125.672 | AE4: 70466.454 | AF4: 69142.404 | AG4: 73326.301
A5: Extra-EU27 | B5: 371398.6 | C5: 380133.92 | D5: 377953.05 | E5: 388553.98 | F5: 371995.37 | G5: 354551.89 | H5: 407915.38 | I5: 461411.44 | J5: 493719.41 | K5: 423285.81 | L5: 490677.95 | M5: 473739.47 | N5: 487083.06 | O5: 526529.19 | P5: 569644.32 | Q5: 624228.38 | R5: 667013.08 | S5: 736979.91 | T5: 768329.74 | U5: 632740 | V5: 693861.15 | W5: 747556.1 | X5: 693178.56 | Y5: 702269.01 | Z5: 724544.02 | AA5: 739087.01 | AB5: 736972.23 | AC5: 819021.84 | AD5: 859432.04 | AE5: 886566.69 | AF5: 858696.41 | AG5: 922770.44
A6: * Considering both inwards and outwards flows of goods transported with half of the distance of the voyages (thus the total distance for Intra-EU in the EU aggregation)
A8: Market shares of activity (% of tkm) | B8: =IF(B3=0,0,B3/B$3) -> 1 | C8: =IF(C3=0,0,C3/C$3) -> 1 | D8: =IF(D3=0,0,D3/D$3) -> 1 | E8: =IF(E3=0,0,E3/E$3) -> 1 | F8: =IF(F3=0,0,F3/F$3) -> 1 | G8: =IF(G3=0,0,G3/G$3) -> 1 | H8: =IF(H3=0,0,H3/H$3) -> 1 | I8: =IF(I3=0,0,I3/I$3) -> 1 | ... AG8: =IF(AG3=0,0,AG3/AG$3) -> 1
A9: Intra-EU27 | B9: =IF(B4=0,0,B4/B$3) -> 0.078733289 | C9: =IF(C4=0,0,C4/C$3) -> 0.078733289 | D9: =IF(D4=0,0,D4/D$3) -> 0.078733289 | E9: =IF(E4=0,0,E4/E$3) -> 0.078733289 | F9: =IF(F4=0,0,F4/F$3) -> 0.078733289 | G9: =IF(G4=0,0,G4/G$3) -> 0.078733289 | H9: =IF(H4=0,0,H4/H$3) -> 0.081570716 | I9: =IF(I4=0,0,I4/I$3) -> 0.081555484 | ... AG9: =IF(AG4=0,0,AG4/AG$3) -> 0.073613634
A10: Extra-EU27 | B10: =IF(B5=0,0,B5/B$3) -> 0.92126671 | C10: =IF(C5=0,0,C5/C$3) -> 0.92126671 | D10: =IF(D5=0,0,D5/D$3) -> 0.92126671 | E10: =IF(E5=0,0,E5/E$3) -> 0.92126671 | F10: =IF(F5=0,0,F5/F$3) -> 0.92126671 | G10: =IF(G5=0,0,G5/G$3) -> 0.92126671 | H10: =IF(H5=0,0,H5/H$3) -> 0.91842928 | I10: =IF(I5=0,0,I5/I$3) -> 0.91844452 | ... AG10: =IF(AG5=0,0,AG5/AG$3) -> 0.92638637
A12: Vehicle-km (Mvkm) | B12: =SUM(B13:B14) -> 19.398313 | C12: =SUM(C13:C14) -> 19.854562 | D12: =SUM(D13:D14) -> 19.740655 | E12: =SUM(E13:E14) -> 20.294346 | F12: =SUM(F13:F14) -> 19.429483 | G12: =SUM(G13:G14) -> 18.518402 | H12: =SUM(H13:H14) -> 21.498909 | I12: =SUM(I13:I14) -> 24.297724 | ... AG12: =SUM(AG13:AG14) -> 27.333707
A13: Intra-EU27 | B13: 4.728506 | C13: 4.839721 | D13: 4.811955 | E13: 4.946922 | F13: 4.736104 | G13: 4.51402 | H13: 5.39721 | I13: 6.103786 | J13: 6.247837 | K13: 6.046503 | L13: 6.888355 | M13: 6.732888 | N13: 6.111633 | O13: 6.489208 | P13: 5.594001 | Q13: 5.039658 | R13: 4.932581 | S13: 4.989044 | T13: 5.128249 | U13: 3.893919 | V13: 4.797991 | W13: 4.45333 | X13: 4.589854 | Y13: 4.720935 | Z13: 4.990042 | AA13: 5.351378 | AB13: 6.453002 | AC13: 6.112825 | AD13: 5.913178 | AE13: 6.540444 | AF13: 5.778975 | AG13: 6.560652
A14: Extra-EU27 | B14: 14.669807 | C14: 15.014841 | D14: 14.9287 | E14: 15.347424 | F14: 14.693379 | G14: 14.004382 | H14: 16.101699 | I14: 18.193938 | J14: 19.458595 | K14: 16.793714 | L14: 19.508308 | M14: 17.947976 | N14: 17.789633 | O14: 19.484061 | P14: 20.387777 | Q14: 22.407811 | R14: 22.751429 | S14: 24.058762 | T14: 24.621793 | U14: 19.197387 | V14: 20.183441 | W14: 21.020179 | X14: 19.034816 | Y14: 18.528501 | Z14: 18.851116 | AA14: 18.591539 | AB14: 18.209034 | AC14: 19.769888 | AD14: 20.521684 | AE14: 21.098916 | AF14: 19.988208 | AG14: 20.773055
A15: * Considering half of the distance of the voyages (thus the total distance for Intra-EU in the EU aggregation)
A17: Market shares of vehicle km (% of km) | B17: =IF(B12=0,0,B12/B$12) -> 1 | C17: =IF(C12=0,0,C12/C$12) -> 1 | D17: =IF(D12=0,0,D12/D$12) -> 1 | E17: =IF(E12=0,0,E12/E$12) -> 1 | F17: =IF(F12=0,0,F12/F$12) -> 1 | G17: =IF(G12=0,0,G12/G$12) -> 1 | H17: =IF(H12=0,0,H12/H$12) -> 1 | I17: =IF(I12=0,0,I12/I$12) -> 1 | ... AG17: =IF(AG12=0,0,AG12/AG$12) -> 1
A18: Intra-EU27 | B18: =IF(B13=0,0,B13/B$12) -> 0.24375862 | C18: =IF(C13=0,0,C13/C$12) -> 0.24375864 | D18: =IF(D13=0,0,D13/D$12) -> 0.24375863 | E18: =IF(E13=0,0,E13/E$12) -> 0.24375863 | F18: =IF(F13=0,0,F13/F$12) -> 0.24375862 | G18: =IF(G13=0,0,G13/G$12) -> 0.24375861 | H18: =IF(H13=0,0,H13/H$12) -> 0.25104576 | I18: =IF(I13=0,0,I13/I$12) -> 0.25120814 | ... AG18: =IF(AG13=0,0,AG13/AG$12) -> 0.24002057
A19: Extra-EU27 | B19: =IF(B14=0,0,B14/B$12) -> 0.75624138 | C19: =IF(C14=0,0,C14/C$12) -> 0.75624136 | D19: =IF(D14=0,0,D14/D$12) -> 0.75624137 | E19: =IF(E14=0,0,E14/E$12) -> 0.75624137 | F19: =IF(F14=0,0,F14/F$12) -> 0.75624138 | G19: =IF(G14=0,0,G14/G$12) -> 0.75624139 | H19: =IF(H14=0,0,H14/H$12) -> 0.74895424 | I19: =IF(I14=0,0,I14/I$12) -> 0.74879186 | ... AG19: =IF(AG14=0,0,AG14/AG$12) -> 0.75997943
A21: Load factor of vessels (t/movement) | B21: =IF(B3=0,0,B3/B12) -> 20782.171 | C21: =IF(C3=0,0,C3/C12) -> 20782.172 | D21: =IF(D3=0,0,D3/D12) -> 20782.171 | E21: =IF(E3=0,0,E3/E12) -> 20782.171 | F21: =IF(F3=0,0,F3/F12) -> 20782.171 | G21: =IF(G3=0,0,G3/G12) -> 20782.171 | H21: =IF(H3=0,0,H3/H12) -> 20658.935 | I21: =IF(I3=0,0,I3/I12) -> 20676.158 | ... AG21: =IF(AG3=0,0,AG3/AG12) -> 36442.066
A22: Intra-EU27 | B22: =IF(B4=0,0,B4/B13) -> 6712.5779 | C22: =IF(C4=0,0,C4/C13) -> 6712.5775 | D22: =IF(D4=0,0,D4/D13) -> 6712.5774 | E22: =IF(E4=0,0,E4/E13) -> 6712.5775 | F22: =IF(F4=0,0,F4/F13) -> 6712.5777 | G22: =IF(G4=0,0,G4/G13) -> 6712.5779 | H22: =IF(H4=0,0,H4/H13) -> 6712.5775 | I22: =IF(I4=0,0,I4/I13) -> 6712.5774 | ... AG22: =IF(AG4=0,0,AG4/AG13) -> 11176.679
A23: Extra-EU27 | B23: =IF(B5=0,0,B5/B14) -> 25317.211 | C23: =IF(C5=0,0,C5/C14) -> 25317.212 | D23: =IF(D5=0,0,D5/D14) -> 25317.211 | E23: =IF(E5=0,0,E5/E14) -> 25317.211 | F23: =IF(F5=0,0,F5/F14) -> 25317.211 | G23: =IF(G5=0,0,G5/G14) -> 25317.211 | H23: =IF(H5=0,0,H5/H14) -> 25333.686 | I23: =IF(I5=0,0,I5/I14) -> 25360.724 | ... AG23: =IF(AG5=0,0,AG5/AG14) -> 44421.509
A25: Total energy consumption (ktoe) | B25: =SUM(B26,B32) -> 4052.0445 | C25: =SUM(C26,C32) -> 4147.3488 | D25: =SUM(D26,D32) -> 4123.555 | E25: =SUM(E26,E32) -> 4239.2137 | F25: =SUM(F26,F32) -> 4058.5555 | G25: =SUM(G26,G32) -> 3868.243 | H25: =SUM(H26,H32) -> 4451.4952 | I25: =SUM(I26,I32) -> 5037.2218 | ... AG25: =SUM(AG26,AG32) -> 7575.1033
A26: Intra-EU27 | B26: =SUM(B27:B31) -> 901.96422 | C26: =SUM(C27:C31) -> 923.17847 | D26: =SUM(D27:D31) -> 917.88209 | E26: =SUM(E27:E31) -> 943.6271 | F26: =SUM(F27:F31) -> 903.41351 | G26: =SUM(G27:G31) -> 861.05094 | H26: =SUM(H27:H31) -> 1017.7336 | I26: =SUM(I27:I31) -> 1152.8287 | ... AG26: =SUM(AG27:AG31) -> 1489.4969
A27: Gas oil and diesel oil (excluding biofuel portion) | B27: 380.39716 | C27: 396.57152 | D27: 434.31171 | E27: 388.78383 | F27: 351.04364 | G27: 422.92971 | H27: 396.10986 | I27: 415.77351 | J27: 429.13156 | K27: 354.51375 | L27: 486.05446 | M27: 486.09329 | N27: 469.47197 | O27: 407.08984 | P27: 287.3629 | Q27: 280.14214 | R27: 343.07559 | S27: 275.89803 | T27: 189.57025 | U27: 182.77796 | V27: 267.78511 | W27: 223.81516 | X27: 271.53571 | Y27: 280.2428 | Z27: 337.15577 | AA27: 875.81082 | AB27: 896.01483 | AC27: 625.8883 | AD27: 748.75833 | AE27: 685.17705 | AF27: 744.07628 | AG27: 846.55014
A28: Fuel oil and Other oil products | B28: 521.56706 | C28: 526.60695 | D28: 483.57037 | E28: 554.84327 | F28: 552.36987 | G28: 438.12122 | H28: 621.62371 | I28: 737.05515 | J28: 768.79826 | K28: 748.60177 | L28: 774.34427 | M28: 790.24948 | N28: 1118.134 | O28: 1319.0877 | P28: 1325.0774 | Q28: 1131.0669 | R28: 1145.4637 | S28: 1339.2844 | T28: 1453.8077 | U28: 1010.8025 | V28: 1152.8826 | W28: 931.54244 | X28: 854.46841 | Y28: 911.09539 | Z28: 727.58872 | AA28: 344.25375 | AB28: 703.9249 | AC28: 1016.8366 | AD28: 1181.8432 | AE28: 1090.477 | AF28: 461.42837 | AG28: 641.79625
A29: Blended biofuels | B29: 0 | C29: 0 | D29: 0 | E29: 0 | F29: 0 | G29: 0 | H29: 0 | I29: 0 | J29: 0 | K29: 0 | L29: 0 | M29: 0 | N29: 0 | O29: 0 | P29: 0 | Q29: 0 | R29: 0 | S29: 0 | T29: 0 | U29: 0 | V29: 0 | W29: 0 | X29: 0 | Y29: 0 | Z29: 0 | AA29: 0 | AB29: 0 | AC29: 0 | AD29: 0 | AE29: 0 | AF29: 0 | AG29: 0
A30: Natural gas | B30: 0 | C30: 0 | D30: 0 | E30: 0 | F30: 0 | G30: 0 | H30: 0 | I30: 0 | J30: 0 | K30: 0 | L30: 0 | M30: 0 | N30: 0 | O30: 0 | P30: 0 | Q30: 0 | R30: 0 | S30: 0 | T30: 0 | U30: 0 | V30: 0 | W30: 0 | X30: 0 | Y30: 0 | Z30: 0 | AA30: 0 | AB30: 0.12065495 | AC30: 1.4495238 | AD30: 1.8031592 | AE30: 1.9760221 | AF30: 0.53234072 | AG30: 1.1505509
A31: Biogases | B31: 0 | C31: 0 | D31: 0 | E31: 0 | F31: 0 | G31: 0 | H31: 0 | I31: 0 | J31: 0 | K31: 0 | L31: 0 | M31: 0 | N31: 0 | O31: 0 | P31: 0 | Q31: 0 | R31: 0 | S31: 0 | T31: 0 | U31: 0 | V31: 0 | W31: 0 | X31: 0 | Y31: 0 | Z31: 0 | AA31: 0 | AB31: 0 | AC31: 0 | AD31: 0 | AE31: 0 | AF31: 0 | AG31: 0
A32: Extra-EU27 | B32: =SUM(B33:B37) -> 3150.0803 | C32: =SUM(C33:C37) -> 3224.1704 | D32: =SUM(D33:D37) -> 3205.6729 | E32: =SUM(E33:E37) -> 3295.5866 | F32: =SUM(F33:F37) -> 3155.1419 | G32: =SUM(G33:G37) -> 3007.1921 | H32: =SUM(H33:H37) -> 3433.7616 | I32: =SUM(I33:I37) -> 3884.3931 | ... AG32: =SUM(AG33:AG37) -> 6085.6063
A33: Gas oil and diesel oil (excluding biofuel portion) | B33: 265.70491 | C33: 277.00259 | D33: 303.36387 | E33: 271.56294 | F33: 245.20167 | G33: 295.41362 | H33: 267.28937 | I33: 280.18522 | J33: 300.40413 | K33: 225.45186 | L33: 314.70504 | M33: 300.4215 | N33: 308.90292 | O33: 269.53673 | P33: 217.3089 | Q33: 246.91436 | R33: 312.18382 | S33: 260.31581 | T33: 181.81127 | U33: 177.4112 | V33: 232.81678 | W33: 216.75517 | X33: 237.20608 | Y33: 233.58635 | Z33: 273.33434 | AA33: 660.58926 | AB33: 567.12644 | AC33: 445.31832 | AD33: 569.59506 | AE33: 494.90033 | AF33: 638.0079 | AG33: 691.74642
A34: Fuel oil and Other oil products | B34: 2884.3754 | C34: 2947.1678 | D34: 2902.3091 | E34: 3024.0236 | F34: 2909.9403 | G34: 2711.7784 | H34: 3166.4722 | I34: 3604.2079 | J34: 3892.5182 | K34: 3282.1616 | L34: 3765.6385 | M34: 3643.6858 | N34: 4914.158 | O34: 5445.0281 | P34: 5879.4702 | Q34: 5972.2101 | R34: 6460.3451 | S34: 7359.4832 | T34: 7698.767 | U34: 5615.2604 | V34: 5942.9424 | W34: 5377.8108 | X34: 4681.0241 | Y34: 4731.4 | Z34: 4042.6415 | AA34: 3940.6416 | AB34: 4496.228 | AC34: 5398.6597 | AD34: 6773.6359 | AE34: 5917.8348 | AF34: 4530.2894 | AG34: 5389.1591
A35: Blended biofuels | B35: 0 | C35: 0 | D35: 0 | E35: 0 | F35: 0 | G35: 0 | H35: 0 | I35: 0 | J35: 0 | K35: 0 | L35: 0 | M35: 0 | N35: 0 | O35: 0 | P35: 0 | Q35: 0 | R35: 0 | S35: 0 | T35: 0 | U35: 0 | V35: 0 | W35: 0 | X35: 0 | Y35: 0 | Z35: 0 | AA35: 0 | AB35: 0 | AC35: 0 | AD35: 0 | AE35: 0 | AF35: 0 | AG35: 0
