Workbook

Sheet cover
B6: JRC-IDEES-2021 - Integrated Database of the European Energy System
C15: CO2 Emissions - comparison to UNFCC submissions
L28: Prepared by JRC C.6
L30: 45432.79
L31: v2021-1.00
B33: Legal Notice
B35: The information made available is property of the Joint Research Centre of the European Commission.
B36: Neither the European Commission nor any person acting on behalf of the Commission is responsible for the use which might be made of this information.
B38: Use conditions
B39: This work is licensed under
B40: CC BY 4.0

Sheet summary
B1: 2000 | C1: 2001 | D1: 2002 | E1: 2003 | F1: 2004 | G1: 2005 | H1: 2006 | I1: 2007 | J1: 2008 | K1: 2009 | L1: 2010 | M1: 2011 | N1: 2012 | O1: 2013 | P1: 2014 | Q1: 2015 | R1: 2016 | S1: 2017 | T1: 2018 | U1: 2019 | V1: 2020 | W1: 2021
A3: Total UNFCCC CO2 emissions without LULUCF, with international transport (kt CO2)
A4: EU27 | B4: ='EU27'!B$3 -> 3818849.5 | C4: ='EU27'!C$3 -> 3879795.6 | D4: ='EU27'!D$3 -> 3884306.2 | E4: ='EU27'!E$3 -> 3975076.2 | F4: ='EU27'!F$3 -> 3999434.8 | G4: ='EU27'!G$3 -> 3990337.6 | H4: ='EU27'!H$3 -> 4015844.6 | I4: ='EU27'!I$3 -> 3991636.3 | ... W4: ='EU27'!W$3 -> 3010556
A5: AT | B5: =AT!B$3 -> 67934.449 | C5: =AT!C$3 -> 71893.566 | D5: =AT!D$3 -> 73595.615 | E5: =AT!E$3 -> 78918.516 | F5: =AT!F$3 -> 79500.133 | G5: =AT!G$3 -> 81131.778 | H5: =AT!H$3 -> 78931.534 | I5: =AT!I$3 -> 76363.568 | ... W5: =AT!W$3 -> 67307.935
A6: BE | B6: =BE!B$3 -> 147612.69 | C6: =BE!C$3 -> 146621.39 | D6: =BE!D$3 -> 153270.44 | E6: =BE!E$3 -> 155306 | F6: =BE!F$3 -> 157022.12 | G6: =BE!G$3 -> 154416.39 | H6: =BE!H$3 -> 155159.33 | I6: =BE!I$3 -> 155226.91 | ... W6: =BE!W$3 -> 125769.29
A7: BG | B7: =BG!B$3 -> 45853.872 | C7: =BG!C$3 -> 49533.248 | D7: =BG!D$3 -> 46800.484 | E7: =BG!E$3 -> 51379.639 | F7: =BG!F$3 -> 50345.613 | G7: =BG!G$3 -> 51507.165 | H7: =BG!H$3 -> 52705.024 | I7: =BG!I$3 -> 56390.897 | ... W7: =BG!W$3 -> 43036.969
A8: CY | B8: =CY!B$3 -> 8538.365 | C8: =CY!C$3 -> 8552.3483 | D8: =CY!D$3 -> 8537.825 | E8: =CY!E$3 -> 8950.8842 | F8: =CY!F$3 -> 8875.0423 | G8: =CY!G$3 -> 9707.4696 | H8: =CY!H$3 -> 9956.7225 | I8: =CY!I$3 -> 10196.831 | ... W8: =CY!W$3 -> 8384.7133
A9: CZ | B9: =CZ!B$3 -> 127730.34 | C9: =CZ!C$3 -> 127642.07 | D9: =CZ!D$3 -> 124483.41 | E9: =CZ!E$3 -> 128192.25 | F9: =CZ!F$3 -> 129179.93 | G9: =CZ!G$3 -> 126660.94 | H9: =CZ!H$3 -> 127578.89 | I9: =CZ!I$3 -> 129434.19 | ... W9: =CZ!W$3 -> 97040.075
A10: DE | B10: =DE!B$3 -> 924582.21 | C10: =DE!C$3 -> 940443.55 | D10: =DE!D$3 -> 924421.9 | E10: =DE!E$3 -> 926537.28 | F10: =DE!F$3 -> 913249.91 | G10: =DE!G$3 -> 895781.46 | H10: =DE!H$3 -> 909305.65 | I10: =DE!I$3 -> 884175.35 | ... W10: =DE!W$3 -> 700694.53
A11: DK | B11: =DK!B$3 -> 60667.303 | C11: =DK!C$3 -> 61572.37 | D11: =DK!D$3 -> 60295.003 | E11: =DK!E$3 -> 65627.738 | F11: =DK!F$3 -> 59834.246 | G11: =DK!G$3 -> 56441.854 | H11: =DK!H$3 -> 65204.133 | I11: =DK!I$3 -> 60631.107 | ... W11: =DK!W$3 -> 32236.313
A12: EE | B12: =EE!B$3 -> 15877.256 | C12: =EE!C$3 -> 16249.795 | D12: =EE!D$3 -> 15796.6 | E12: =EE!E$3 -> 17679.633 | F12: =EE!F$3 -> 17894.238 | G12: =EE!G$3 -> 17611.679 | H12: =EE!H$3 -> 17261.658 | I12: =EE!I$3 -> 20898.793 | ... W12: =EE!W$3 -> 11490.192
A13: EL | B13: =EL!B$3 -> 116991.65 | C13: =EL!C$3 -> 118875.52 | D13: =EL!D$3 -> 117342.51 | E13: =EL!E$3 -> 122370.92 | F13: =EL!F$3 -> 122959.47 | G13: =EL!G$3 -> 125704.06 | H13: =EL!H$3 -> 125147.08 | I13: =EL!I$3 -> 127649.49 | ... W13: =EL!W$3 -> 65992.727
A14: ES | B14: =ES!B$3 -> 338961.34 | C14: =ES!C$3 -> 343129.04 | D14: =ES!D$3 -> 363547.47 | E14: =ES!E$3 -> 368946.55 | F14: =ES!F$3 -> 387394.77 | G14: =ES!G$3 -> 405764.91 | H14: =ES!H$3 -> 398739.53 | I14: =ES!I$3 -> 407995.95 | ... W14: =ES!W$3 -> 262028.52
A15: FI | B15: =FI!B$3 -> 60120.079 | C15: =FI!C$3 -> 65436.534 | D15: =FI!D$3 -> 68187.71 | E15: =FI!E$3 -> 75822.257 | F15: =FI!F$3 -> 71870.122 | G15: =FI!G$3 -> 59951.644 | H15: =FI!H$3 -> 71593.135 | I15: =FI!I$3 -> 69873.979 | ... W15: =FI!W$3 -> 39648.637
A16: FR | B16: =FR!B$3 -> 436441.4 | C16: =FR!C$3 -> 440004.25 | D16: =FR!D$3 -> 435400.01 | E16: =FR!E$3 -> 442459.86 | F16: =FR!F$3 -> 446382.02 | G16: =FR!G$3 -> 448664.07 | H16: =FR!H$3 -> 440135.94 | I16: =FR!I$3 -> 431239.85 | ... W16: =FR!W$3 -> 327335.69
A17: HR | B17: =HR!B$3 -> 19918.792 | C17: =HR!C$3 -> 21073.766 | D17: =HR!D$3 -> 22149.895 | E17: =HR!E$3 -> 23464.823 | F17: =HR!F$3 -> 23169.285 | G17: =HR!G$3 -> 23677.585 | H17: =HR!H$3 -> 23872.415 | I17: =HR!I$3 -> 25212.768 | ... W17: =HR!W$3 -> 17783.391
A18: HU | B18: =HU!B$3 -> 59225.129 | C18: =HU!C$3 -> 60784.063 | D18: =HU!D$3 -> 59723.257 | E18: =HU!E$3 -> 62485.346 | F18: =HU!F$3 -> 60964.719 | G18: =HU!G$3 -> 61224.369 | H18: =HU!H$3 -> 60542.896 | I18: =HU!I$3 -> 59496.027 | ... W18: =HU!W$3 -> 48938.606
A19: IE | B19: =IE!B$3 -> 47541.923 | C19: =IE!C$3 -> 50310.753 | D19: =IE!D$3 -> 48868.754 | E19: =IE!E$3 -> 48501.046 | F19: =IE!F$3 -> 48798.252 | G19: =IE!G$3 -> 50973.536 | H19: =IE!H$3 -> 50875.443 | I19: =IE!I$3 -> 51060.295 | ... W19: =IE!W$3 -> 39390.795
A20: IT | B20: =IT!B$3 -> 482332.02 | C20: =IT!C$3 -> 482957.43 | D20: =IT!D$3 -> 490043.75 | E20: =IT!E$3 -> 510071.8 | F20: =IT!F$3 -> 516137.46 | G20: =IT!G$3 -> 517483.29 | H20: =IT!H$3 -> 513319.95 | I20: =IT!I$3 -> 507961.79 | ... W20: =IT!W$3 -> 347824.34
A21: LT | B21: =LT!B$3 -> 12205.868 | C21: =LT!C$3 -> 13002.168 | D21: =LT!D$3 -> 13098.396 | E21: =LT!E$3 -> 13101.079 | F21: =LT!F$3 -> 13718.609 | G21: =LT!G$3 -> 14458.342 | H21: =LT!H$3 -> 14791.761 | I21: =LT!I$3 -> 16053.883 | ... W21: =LT!W$3 -> 14608.331
A22: LU | B22: =LU!B$3 -> 9664.2588 | C22: =LU!C$3 -> 10244.492 | D22: =LU!D$3 -> 11106.327 | E22: =LU!E$3 -> 11625.22 | F22: =LU!F$3 -> 13097.707 | G22: =LU!G$3 -> 13376.085 | H22: =LU!H$3 -> 13124.323 | I22: =LU!I$3 -> 12611.082 | ... W22: =LU!W$3 -> 10296.676
A23: LV | B23: =LV!B$3 -> 7188.9669 | C23: =LV!C$3 -> 8200.8489 | D23: =LV!D$3 -> 8261.9435 | E23: =LV!E$3 -> 8448.0039 | F23: =LV!F$3 -> 8526.3033 | G23: =LV!G$3 -> 8823.0946 | H23: =LV!H$3 -> 9142.1979 | I23: =LV!I$3 -> 9454.1002 | ... W23: =LV!W$3 -> 8151.6953
A24: MT | B24: =MT!B$3 -> 5035.633 | C24: =MT!C$3 -> 5333.5164 | D24: =MT!D$3 -> 5774.0719 | E24: =MT!E$3 -> 6164.1687 | F24: =MT!F$3 -> 6263.2992 | G24: =MT!G$3 -> 5035.747 | H24: =MT!H$3 -> 5339.2139 | I24: =MT!I$3 -> 5709.9936 | ... W24: =MT!W$3 -> 8085.0211
A25: NL | B25: =NL!B$3 -> 224229.48 | C25: =NL!C$3 -> 233079.15 | D25: =NL!D$3 -> 232436.09 | E25: =NL!E$3 -> 232898.59 | F25: =NL!F$3 -> 239368.85 | G25: =NL!G$3 -> 239108.51 | H25: =NL!H$3 -> 237752.97 | I25: =NL!I$3 -> 238867.68 | ... W25: =NL!W$3 -> 182892.34
A26: PL | B26: =PL!B$3 -> 319162.25 | C26: =PL!C$3 -> 315119.19 | D26: =PL!D$3 -> 307755.92 | E26: =PL!E$3 -> 320692.45 | F26: =PL!F$3 -> 325421.48 | G26: =PL!G$3 -> 324712.31 | H26: =PL!H$3 -> 338748.22 | I26: =PL!I$3 -> 338003.53 | ... W26: =PL!W$3 -> 333929.12
A27: PT | B27: =PT!B$3 -> 69280.689 | C27: =PT!C$3 -> 68264.794 | D27: =PT!D$3 -> 72643.925 | E27: =PT!E$3 -> 68012.121 | F27: =PT!F$3 -> 71271.317 | G27: =PT!G$3 -> 73467.331 | H27: =PT!H$3 -> 68948.954 | I27: =PT!I$3 -> 66681.714 | ... W27: =PT!W$3 -> 44081.38
A28: RO | B28: =RO!B$3 -> 93762.838 | C28: =RO!C$3 -> 99371.169 | D28: =RO!D$3 -> 99625.083 | E28: =RO!E$3 -> 104215.02 | F28: =RO!F$3 -> 103740.04 | G28: =RO!G$3 -> 102215.12 | H28: =RO!H$3 -> 104761.87 | I28: =RO!I$3 -> 109497.75 | ... W28: =RO!W$3 -> 77541.035
A29: SE | B29: =SE!B$3 -> 61681.945 | C29: =SE!C$3 -> 62425.071 | D29: =SE!D$3 -> 62442.02 | E29: =SE!E$3 -> 64471.845 | F29: =SE!F$3 -> 64805.103 | G29: =SE!G$3 -> 62438.85 | H29: =SE!H$3 -> 62803.924 | I29: =SE!I$3 -> 62179.06 | ... W29: =SE!W$3 -> 47451.806
A30: SI | B30: =SI!B$3 -> 15122.617 | C30: =SI!C$3 -> 16380.623 | D30: =SI!D$3 -> 16644.965 | E30: =SI!E$3 -> 16348.076 | F30: =SI!F$3 -> 16761.83 | G30: =SI!G$3 -> 17061.387 | H30: =SI!H$3 -> 17342.174 | I30: =SI!I$3 -> 17592.823 | ... W30: =SI!W$3 -> 13366.748
A31: SK | B31: =SK!B$3 -> 41186.122 | C31: =SK!C$3 -> 43294.924 | D31: =SK!D$3 -> 42052.835 | E31: =SK!E$3 -> 42385.041 | F31: =SK!F$3 -> 42882.92 | G31: =SK!G$3 -> 42938.612 | H31: =SK!H$3 -> 42759.616 | I31: =SK!I$3 -> 41176.86 | ... W31: =SK!W$3 -> 35249.083
A33: JRC-IDEES CO2 emissions (kt CO2)
A34: EU27 | B34: ='EU27'!B$49 -> 3830190.7 | C34: ='EU27'!C$49 -> 3876518.2 | D34: ='EU27'!D$49 -> 3883906.4 | E34: ='EU27'!E$49 -> 3980671.1 | F34: ='EU27'!F$49 -> 4009444.9 | G34: ='EU27'!G$49 -> 3995248.7 | H34: ='EU27'!H$49 -> 4027680.7 | I34: ='EU27'!I$49 -> 3988873.8 | ... W34: ='EU27'!W$49 -> 3046101.8
A35: AT | B35: =AT!B$49 -> 75246.493 | C35: =AT!C$49 -> 79148.28 | D35: =AT!D$49 -> 81671.073 | E35: =AT!E$49 -> 86619.891 | F35: =AT!F$49 -> 88330.07 | G35: =AT!G$49 -> 89651.708 | H35: =AT!H$49 -> 87974.234 | I35: =AT!I$49 -> 85765.481 | ... W35: =AT!W$49 -> 75938.367
A36: BE | B36: =BE!B$49 -> 153654.66 | C36: =BE!C$49 -> 151701.21 | D36: =BE!D$49 -> 154033.01 | E36: =BE!E$49 -> 161399.54 | F36: =BE!F$49 -> 161114.27 | G36: =BE!G$49 -> 156948.04 | H36: =BE!H$49 -> 156388.81 | I36: =BE!I$49 -> 154309.97 | ... W36: =BE!W$49 -> 130315.22
A37: BG | B37: =BG!B$49 -> 50509.056 | C37: =BG!C$49 -> 53681.436 | D37: =BG!D$49 -> 50455.541 | E37: =BG!E$49 -> 55609.026 | F37: =BG!F$49 -> 54566.511 | G37: =BG!G$49 -> 55653.125 | H37: =BG!H$49 -> 56669.477 | I37: =BG!I$49 -> 60185.286 | ... W37: =BG!W$49 -> 44467.913
A38: CY | B38: =CY!B$49 -> 8655.6797 | C38: =CY!C$49 -> 8663.2133 | D38: =CY!D$49 -> 8643.6248 | E38: =CY!E$49 -> 9350.9415 | F38: =CY!F$49 -> 8994.7771 | G38: =CY!G$49 -> 9842.5698 | H38: =CY!H$49 -> 9988.3523 | I38: =CY!I$49 -> 10189.464 | ... W38: =CY!W$49 -> 8244.4589
A39: CZ | B39: =CZ!B$49 -> 132571.12 | C39: =CZ!C$49 -> 132263.29 | D39: =CZ!D$49 -> 129168.09 | E39: =CZ!E$49 -> 133238.58 | F39: =CZ!F$49 -> 134803.35 | G39: =CZ!G$49 -> 131998.74 | H39: =CZ!H$49 -> 134221.58 | I39: =CZ!I$49 -> 135315.96 | ... W39: =CZ!W$49 -> 103989.07
A40: DE | B40: =DE!B$49 -> 921257.86 | C40: =DE!C$49 -> 934337.97 | D40: =DE!D$49 -> 919728.74 | E40: =DE!E$49 -> 923319.33 | F40: =DE!F$49 -> 910227.58 | G40: =DE!G$49 -> 889545.15 | H40: =DE!H$49 -> 904059.58 | I40: =DE!I$49 -> 873393.14 | ... W40: =DE!W$49 -> 700515.2
A41: DK | B41: =DK!B$49 -> 61528.509 | C41: =DK!C$49 -> 62262.082 | D41: =DK!D$49 -> 60725.998 | E41: =DK!E$49 -> 65313.563 | F41: =DK!F$49 -> 59651.312 | G41: =DK!G$49 -> 56328.65 | H41: =DK!H$49 -> 64939.123 | I41: =DK!I$49 -> 60425.543 | ... W41: =DK!W$49 -> 32708.291
A42: EE | B42: =EE!B$49 -> 15248.944 | C42: =EE!C$49 -> 15515.297 | D42: =EE!D$49 -> 14980.283 | E42: =EE!E$49 -> 16811.768 | F42: =EE!F$49 -> 17086.968 | G42: =EE!G$49 -> 16970.022 | H42: =EE!H$49 -> 16561.172 | I42: =EE!I$49 -> 20112.336 | ... W42: =EE!W$49 -> 9380.1263
...

Sheet EU27
A1: EU27 - European Union - 27 countries (from 2020) | B1: 2000 | C1: 2001 | D1: 2002 | E1: 2003 | F1: 2004 | G1: 2005 | H1: 2006 | I1: 2007 | J1: 2008 | K1: 2009 | L1: 2010 | M1: 2011 | N1: 2012 | O1: 2013 | P1: 2014 | Q1: 2015 | R1: 2016 | S1: 2017 | T1: 2018 | U1: 2019 | V1: 2020 | W1: 2021
A3: Total UNFCCC CO2 emissions without LULUCF, with international transport (kt CO2) | B3: =SUM(AT!B3,BE!B3,BG!B3,CY!B3,CZ!B3,DE!B3,DK!B3,EE!B3,EL!B3,ES!B3,FI!B3,FR!B3,HR!B3,HU!B3,IE!B3,IT!B3,LT!B3,LU!B3,LV!B3,MT!B3,NL!B3,PL!B3,PT!B3,RO!B3,SE!B3,SI!B3,SK!B3) -> 3818849.5 | C3: =SUM(AT!C3,BE!C3,BG!C3,CY!C3,CZ!C3,DE!C3,DK!C3,EE!C3,EL!C3,ES!C3,FI!C3,FR!C3,HR!C3,HU!C3,IE!C3,IT!C3,LT!C3,LU!C3,LV!C3,MT!C3,NL!C3,PL!C3,PT!C3,RO!C3,SE!C3,SI!C3,SK!C3) -> 3879795.6 | D3: =SUM(AT!D3,BE!D3,BG!D3,CY!D3,CZ!D3,DE!D3,DK!D3,EE!D3,EL!D3,ES!D3,FI!D3,FR!D3,HR!D3,HU!D3,IE!D3,IT!D3,LT!D3,LU!D3,LV!D3,MT!D3,NL!D3,PL!D3,PT!D3,RO!D3,SE!D3,SI!D3,SK!D3) -> 3884306.2 | E3: =SUM(AT!E3,BE!E3,BG!E3,CY!E3,CZ!E3,DE!E3,DK!E3,EE!E3,EL!E3,ES!E3,FI!E3,FR!E3,HR!E3,HU!E3,IE!E3,IT!E3,LT!E3,LU!E3,LV!E3,MT!E3,NL!E3,PL!E3,PT!E3,RO!E3,SE!E3,SI!E3,SK!E3) -> 3975076.2 | F3: =SUM(AT!F3,BE!F3,BG!F3,CY!F3,CZ!F3,DE!F3,DK!F3,EE!F3,EL!F3,ES!F3,FI!F3,FR!F3,HR!F3,HU!F3,IE!F3,IT!F3,LT!F3,LU!F3,LV!F3,MT!F3,NL!F3,PL!F3,PT!F3,RO!F3,SE!F3,SI!F3,SK!F3) -> 3999434.8 | G3: =SUM(AT!G3,BE!G3,BG!G3,CY!G3,CZ!G3,DE!G3,DK!G3,EE!G3,EL!G3,ES!G3,FI!G3,FR!G3,HR!G3,HU!G3,IE!G3,IT!G3,LT!G3,LU!G3,LV!G3,MT!G3,NL!G3,PL!G3,PT!G3,RO!G3,SE!G3,SI!G3,SK!G3) -> 3990337.6 | H3: =SUM(AT!H3,BE!H3,BG!H3,CY!H3,CZ!H3,DE!H3,DK!H3,EE!H3,EL!H3,ES!H3,FI!H3,FR!H3,HR!H3,HU!H3,IE!H3,IT!H3,LT!H3,LU!H3,LV!H3,MT!H3,NL!H3,PL!H3,PT!H3,RO!H3,SE!H3,SI!H3,SK!H3) -> 4015844.6 | I3: =SUM(AT!I3,BE!I3,BG!I3,CY!I3,CZ!I3,DE!I3,DK!I3,EE!I3,EL!I3,ES!I3,FI!I3,FR!I3,HR!I3,HU!I3,IE!I3,IT!I3,LT!I3,LU!I3,LV!I3,MT!I3,NL!I3,PL!I3,PT!I3,RO!I3,SE!I3,SI!I3,SK!I3) -> 3991636.3 | ... W3: =SUM(AT!W3,BE!W3,BG!W3,CY!W3,CZ!W3,DE!W3,DK!W3,EE!W3,EL!W3,ES!W3,FI!W3,FR!W3,HR!W3,HU!W3,IE!W3,IT!W3,LT!W3,LU!W3,LV!W3,MT!W3,NL!W3,PL!W3,PT!W3,RO!W3,SE!W3,SI!W3,SK!W3) -> 3010556
A4: 1 - Energy | B4: =SUM(B5,B31,B32) -> 3305876.6 | C4: =SUM(C5,C31,C32) -> 3373780.3 | D4: =SUM(D5,D31,D32) -> 3374186.6 | E4: =SUM(E5,E31,E32) -> 3450622 | F4: =SUM(F5,F31,F32) -> 3450680.8 | G4: =SUM(G5,G31,G32) -> 3434388.5 | H4: =SUM(H5,H31,H32) -> 3438638.1 | I4: =SUM(I5,I31,I32) -> 3399036.2 | ... W4: =SUM(W5,W31,W32) -> 2570164.5
A5: 1.AA - Fuel Combustion - Sectoral approach | B5: =SUM(B6,B10,B18,B24,B28) -> 3285063.7 | C5: =SUM(C6,C10,C18,C24,C28) -> 3354098.7 | D5: =SUM(D6,D10,D18,D24,D28) -> 3353845.9 | E5: =SUM(E6,E10,E18,E24,E28) -> 3429279.6 | F5: =SUM(F6,F10,F18,F24,F28) -> 3430595.2 | G5: =SUM(G6,G10,G18,G24,G28) -> 3413454.3 | H5: =SUM(H6,H10,H18,H24,H28) -> 3415759.8 | I5: =SUM(I6,I10,I18,I24,I28) -> 3376363.4 | ... W5: =SUM(W6,W10,W18,W24,W28) -> 2552388.8
A6: 1.A.1 - Energy Industries | B6: =SUM(B7:B9) -> 1297000.4 | C6: =SUM(C7:C9) -> 1321798.5 | D6: =SUM(D7:D9) -> 1344197.2 | E6: =SUM(E7:E9) -> 1390946.1 | F6: =SUM(F7:F9) -> 1383689.6 | G6: =SUM(G7:G9) -> 1375062.9 | H6: =SUM(H7:H9) -> 1382279 | I6: =SUM(I7:I9) -> 1396148.3 | ... W6: =SUM(W7:W9) -> 831627.87
A7: 1.A.1.a - Public Electricity and Heat Production | B7: =SUM(AT!B7,BE!B7,BG!B7,CY!B7,CZ!B7,DE!B7,DK!B7,EE!B7,EL!B7,ES!B7,FI!B7,FR!B7,HR!B7,HU!B7,IE!B7,IT!B7,LT!B7,LU!B7,LV!B7,MT!B7,NL!B7,PL!B7,PT!B7,RO!B7,SE!B7,SI!B7,SK!B7) -> 1119458.5 | C7: =SUM(AT!C7,BE!C7,BG!C7,CY!C7,CZ!C7,DE!C7,DK!C7,EE!C7,EL!C7,ES!C7,FI!C7,FR!C7,HR!C7,HU!C7,IE!C7,IT!C7,LT!C7,LU!C7,LV!C7,MT!C7,NL!C7,PL!C7,PT!C7,RO!C7,SE!C7,SI!C7,SK!C7) -> 1146425.6 | D7: =SUM(AT!D7,BE!D7,BG!D7,CY!D7,CZ!D7,DE!D7,DK!D7,EE!D7,EL!D7,ES!D7,FI!D7,FR!D7,HR!D7,HU!D7,IE!D7,IT!D7,LT!D7,LU!D7,LV!D7,MT!D7,NL!D7,PL!D7,PT!D7,RO!D7,SE!D7,SI!D7,SK!D7) -> 1168163.6 | E7: =SUM(AT!E7,BE!E7,BG!E7,CY!E7,CZ!E7,DE!E7,DK!E7,EE!E7,EL!E7,ES!E7,FI!E7,FR!E7,HR!E7,HU!E7,IE!E7,IT!E7,LT!E7,LU!E7,LV!E7,MT!E7,NL!E7,PL!E7,PT!E7,RO!E7,SE!E7,SI!E7,SK!E7) -> 1214807.2 | F7: =SUM(AT!F7,BE!F7,BG!F7,CY!F7,CZ!F7,DE!F7,DK!F7,EE!F7,EL!F7,ES!F7,FI!F7,FR!F7,HR!F7,HU!F7,IE!F7,IT!F7,LT!F7,LU!F7,LV!F7,MT!F7,NL!F7,PL!F7,PT!F7,RO!F7,SE!F7,SI!F7,SK!F7) -> 1201244.3 | G7: =SUM(AT!G7,BE!G7,BG!G7,CY!G7,CZ!G7,DE!G7,DK!G7,EE!G7,EL!G7,ES!G7,FI!G7,FR!G7,HR!G7,HU!G7,IE!G7,IT!G7,LT!G7,LU!G7,LV!G7,MT!G7,NL!G7,PL!G7,PT!G7,RO!G7,SE!G7,SI!G7,SK!G7) -> 1188922.5 | H7: =SUM(AT!H7,BE!H7,BG!H7,CY!H7,CZ!H7,DE!H7,DK!H7,EE!H7,EL!H7,ES!H7,FI!H7,FR!H7,HR!H7,HU!H7,IE!H7,IT!H7,LT!H7,LU!H7,LV!H7,MT!H7,NL!H7,PL!H7,PT!H7,RO!H7,SE!H7,SI!H7,SK!H7) -> 1194306.9 | I7: =SUM(AT!I7,BE!I7,BG!I7,CY!I7,CZ!I7,DE!I7,DK!I7,EE!I7,EL!I7,ES!I7,FI!I7,FR!I7,HR!I7,HU!I7,IE!I7,IT!I7,LT!I7,LU!I7,LV!I7,MT!I7,NL!I7,PL!I7,PT!I7,RO!I7,SE!I7,SI!I7,SK!I7) -> 1208732.7 | ... W7: =SUM(AT!W7,BE!W7,BG!W7,CY!W7,CZ!W7,DE!W7,DK!W7,EE!W7,EL!W7,ES!W7,FI!W7,FR!W7,HR!W7,HU!W7,IE!W7,IT!W7,LT!W7,LU!W7,LV!W7,MT!W7,NL!W7,PL!W7,PT!W7,RO!W7,SE!W7,SI!W7,SK!W7) -> 708860.71
A8: 1.A.1.b - Petroleum Refining | B8: =SUM(AT!B8,BE!B8,BG!B8,CY!B8,CZ!B8,DE!B8,DK!B8,EE!B8,EL!B8,ES!B8,FI!B8,FR!B8,HR!B8,HU!B8,IE!B8,IT!B8,LT!B8,LU!B8,LV!B8,MT!B8,NL!B8,PL!B8,PT!B8,RO!B8,SE!B8,SI!B8,SK!B8) -> 116262.77 | C8: =SUM(AT!C8,BE!C8,BG!C8,CY!C8,CZ!C8,DE!C8,DK!C8,EE!C8,EL!C8,ES!C8,FI!C8,FR!C8,HR!C8,HU!C8,IE!C8,IT!C8,LT!C8,LU!C8,LV!C8,MT!C8,NL!C8,PL!C8,PT!C8,RO!C8,SE!C8,SI!C8,SK!C8) -> 116824.2 | D8: =SUM(AT!D8,BE!D8,BG!D8,CY!D8,CZ!D8,DE!D8,DK!D8,EE!D8,EL!D8,ES!D8,FI!D8,FR!D8,HR!D8,HU!D8,IE!D8,IT!D8,LT!D8,LU!D8,LV!D8,MT!D8,NL!D8,PL!D8,PT!D8,RO!D8,SE!D8,SI!D8,SK!D8) -> 117090.54 | E8: =SUM(AT!E8,BE!E8,BG!E8,CY!E8,CZ!E8,DE!E8,DK!E8,EE!E8,EL!E8,ES!E8,FI!E8,FR!E8,HR!E8,HU!E8,IE!E8,IT!E8,LT!E8,LU!E8,LV!E8,MT!E8,NL!E8,PL!E8,PT!E8,RO!E8,SE!E8,SI!E8,SK!E8) -> 116593.55 | F8: =SUM(AT!F8,BE!F8,BG!F8,CY!F8,CZ!F8,DE!F8,DK!F8,EE!F8,EL!F8,ES!F8,FI!F8,FR!F8,HR!F8,HU!F8,IE!F8,IT!F8,LT!F8,LU!F8,LV!F8,MT!F8,NL!F8,PL!F8,PT!F8,RO!F8,SE!F8,SI!F8,SK!F8) -> 121558.15 | G8: =SUM(AT!G8,BE!G8,BG!G8,CY!G8,CZ!G8,DE!G8,DK!G8,EE!G8,EL!G8,ES!G8,FI!G8,FR!G8,HR!G8,HU!G8,IE!G8,IT!G8,LT!G8,LU!G8,LV!G8,MT!G8,NL!G8,PL!G8,PT!G8,RO!G8,SE!G8,SI!G8,SK!G8) -> 123493.71 | H8: =SUM(AT!H8,BE!H8,BG!H8,CY!H8,CZ!H8,DE!H8,DK!H8,EE!H8,EL!H8,ES!H8,FI!H8,FR!H8,HR!H8,HU!H8,IE!H8,IT!H8,LT!H8,LU!H8,LV!H8,MT!H8,NL!H8,PL!H8,PT!H8,RO!H8,SE!H8,SI!H8,SK!H8) -> 123658.1 | I8: =SUM(AT!I8,BE!I8,BG!I8,CY!I8,CZ!I8,DE!I8,DK!I8,EE!I8,EL!I8,ES!I8,FI!I8,FR!I8,HR!I8,HU!I8,IE!I8,IT!I8,LT!I8,LU!I8,LV!I8,MT!I8,NL!I8,PL!I8,PT!I8,RO!I8,SE!I8,SI!I8,SK!I8) -> 125544.3 | ... W8: =SUM(AT!W8,BE!W8,BG!W8,CY!W8,CZ!W8,DE!W8,DK!W8,EE!W8,EL!W8,ES!W8,FI!W8,FR!W8,HR!W8,HU!W8,IE!W8,IT!W8,LT!W8,LU!W8,LV!W8,MT!W8,NL!W8,PL!W8,PT!W8,RO!W8,SE!W8,SI!W8,SK!W8) -> 92505.062
A9: 1.A.1.c - Manufacture of Solid Fuels and Other Energy Industries | B9: =SUM(AT!B9,BE!B9,BG!B9,CY!B9,CZ!B9,DE!B9,DK!B9,EE!B9,EL!B9,ES!B9,FI!B9,FR!B9,HR!B9,HU!B9,IE!B9,IT!B9,LT!B9,LU!B9,LV!B9,MT!B9,NL!B9,PL!B9,PT!B9,RO!B9,SE!B9,SI!B9,SK!B9) -> 61279.129 | C9: =SUM(AT!C9,BE!C9,BG!C9,CY!C9,CZ!C9,DE!C9,DK!C9,EE!C9,EL!C9,ES!C9,FI!C9,FR!C9,HR!C9,HU!C9,IE!C9,IT!C9,LT!C9,LU!C9,LV!C9,MT!C9,NL!C9,PL!C9,PT!C9,RO!C9,SE!C9,SI!C9,SK!C9) -> 58548.703 | D9: =SUM(AT!D9,BE!D9,BG!D9,CY!D9,CZ!D9,DE!D9,DK!D9,EE!D9,EL!D9,ES!D9,FI!D9,FR!D9,HR!D9,HU!D9,IE!D9,IT!D9,LT!D9,LU!D9,LV!D9,MT!D9,NL!D9,PL!D9,PT!D9,RO!D9,SE!D9,SI!D9,SK!D9) -> 58943.04 | E9: =SUM(AT!E9,BE!E9,BG!E9,CY!E9,CZ!E9,DE!E9,DK!E9,EE!E9,EL!E9,ES!E9,FI!E9,FR!E9,HR!E9,HU!E9,IE!E9,IT!E9,LT!E9,LU!E9,LV!E9,MT!E9,NL!E9,PL!E9,PT!E9,RO!E9,SE!E9,SI!E9,SK!E9) -> 59545.327 | F9: =SUM(AT!F9,BE!F9,BG!F9,CY!F9,CZ!F9,DE!F9,DK!F9,EE!F9,EL!F9,ES!F9,FI!F9,FR!F9,HR!F9,HU!F9,IE!F9,IT!F9,LT!F9,LU!F9,LV!F9,MT!F9,NL!F9,PL!F9,PT!F9,RO!F9,SE!F9,SI!F9,SK!F9) -> 60887.199 | G9: =SUM(AT!G9,BE!G9,BG!G9,CY!G9,CZ!G9,DE!G9,DK!G9,EE!G9,EL!G9,ES!G9,FI!G9,FR!G9,HR!G9,HU!G9,IE!G9,IT!G9,LT!G9,LU!G9,LV!G9,MT!G9,NL!G9,PL!G9,PT!G9,RO!G9,SE!G9,SI!G9,SK!G9) -> 62646.708 | H9: =SUM(AT!H9,BE!H9,BG!H9,CY!H9,CZ!H9,DE!H9,DK!H9,EE!H9,EL!H9,ES!H9,FI!H9,FR!H9,HR!H9,HU!H9,IE!H9,IT!H9,LT!H9,LU!H9,LV!H9,MT!H9,NL!H9,PL!H9,PT!H9,RO!H9,SE!H9,SI!H9,SK!H9) -> 64313.941 | I9: =SUM(AT!I9,BE!I9,BG!I9,CY!I9,CZ!I9,DE!I9,DK!I9,EE!I9,EL!I9,ES!I9,FI!I9,FR!I9,HR!I9,HU!I9,IE!I9,IT!I9,LT!I9,LU!I9,LV!I9,MT!I9,NL!I9,PL!I9,PT!I9,RO!I9,SE!I9,SI!I9,SK!I9) -> 61871.272 | ... W9: =SUM(AT!W9,BE!W9,BG!W9,CY!W9,CZ!W9,DE!W9,DK!W9,EE!W9,EL!W9,ES!W9,FI!W9,FR!W9,HR!W9,HU!W9,IE!W9,IT!W9,LT!W9,LU!W9,LV!W9,MT!W9,NL!W9,PL!W9,PT!W9,RO!W9,SE!W9,SI!W9,SK!W9) -> 30262.099
A10: 1.A.2 - Manufacturing Industries and Construction | B10: =SUM(B11:B17) -> 581139.27 | C10: =SUM(C11:C17) -> 569512.48 | D10: =SUM(D11:D17) -> 559883.6 | E10: =SUM(E11:E17) -> 565458.74 | F10: =SUM(F11:F17) -> 558342.64 | G10: =SUM(G11:G17) -> 550116.01 | H10: =SUM(H11:H17) -> 540008.08 | I10: =SUM(I11:I17) -> 552705.2 | ... W10: =SUM(W11:W17) -> 433739.78
A11: 1.A.2.a - Iron and Steel | B11: =SUM(AT!B11,BE!B11,BG!B11,CY!B11,CZ!B11,DE!B11,DK!B11,EE!B11,EL!B11,ES!B11,FI!B11,FR!B11,HR!B11,HU!B11,IE!B11,IT!B11,LT!B11,LU!B11,LV!B11,MT!B11,NL!B11,PL!B11,PT!B11,RO!B11,SE!B11,SI!B11,SK!B11) -> 116386.27 | C11: =SUM(AT!C11,BE!C11,BG!C11,CY!C11,CZ!C11,DE!C11,DK!C11,EE!C11,EL!C11,ES!C11,FI!C11,FR!C11,HR!C11,HU!C11,IE!C11,IT!C11,LT!C11,LU!C11,LV!C11,MT!C11,NL!C11,PL!C11,PT!C11,RO!C11,SE!C11,SI!C11,SK!C11) -> 108405.81 | D11: =SUM(AT!D11,BE!D11,BG!D11,CY!D11,CZ!D11,DE!D11,DK!D11,EE!D11,EL!D11,ES!D11,FI!D11,FR!D11,HR!D11,HU!D11,IE!D11,IT!D11,LT!D11,LU!D11,LV!D11,MT!D11,NL!D11,PL!D11,PT!D11,RO!D11,SE!D11,SI!D11,SK!D11) -> 104965.93 | E11: =SUM(AT!E11,BE!E11,BG!E11,CY!E11,CZ!E11,DE!E11,DK!E11,EE!E11,EL!E11,ES!E11,FI!E11,FR!E11,HR!E11,HU!E11,IE!E11,IT!E11,LT!E11,LU!E11,LV!E11,MT!E11,NL!E11,PL!E11,PT!E11,RO!E11,SE!E11,SI!E11,SK!E11) -> 103887.98 | F11: =SUM(AT!F11,BE!F11,BG!F11,CY!F11,CZ!F11,DE!F11,DK!F11,EE!F11,EL!F11,ES!F11,FI!F11,FR!F11,HR!F11,HU!F11,IE!F11,IT!F11,LT!F11,LU!F11,LV!F11,MT!F11,NL!F11,PL!F11,PT!F11,RO!F11,SE!F11,SI!F11,SK!F11) -> 105831.47 | G11: =SUM(AT!G11,BE!G11,BG!G11,CY!G11,CZ!G11,DE!G11,DK!G11,EE!G11,EL!G11,ES!G11,FI!G11,FR!G11,HR!G11,HU!G11,IE!G11,IT!G11,LT!G11,LU!G11,LV!G11,MT!G11,NL!G11,PL!G11,PT!G11,RO!G11,SE!G11,SI!G11,SK!G11) -> 104614.36 | H11: =SUM(AT!H11,BE!H11,BG!H11,CY!H11,CZ!H11,DE!H11,DK!H11,EE!H11,EL!H11,ES!H11,FI!H11,FR!H11,HR!H11,HU!H11,IE!H11,IT!H11,LT!H11,LU!H11,LV!H11,MT!H11,NL!H11,PL!H11,PT!H11,RO!H11,SE!H11,SI!H11,SK!H11) -> 105242.37 | I11: =SUM(AT!I11,BE!I11,BG!I11,CY!I11,CZ!I11,DE!I11,DK!I11,EE!I11,EL!I11,ES!I11,FI!I11,FR!I11,HR!I11,HU!I11,IE!I11,IT!I11,LT!I11,LU!I11,LV!I11,MT!I11,NL!I11,PL!I11,PT!I11,RO!I11,SE!I11,SI!I11,SK!I11) -> 112561.17 | ... W11: =SUM(AT!W11,BE!W11,BG!W11,CY!W11,CZ!W11,DE!W11,DK!W11,EE!W11,EL!W11,ES!W11,FI!W11,FR!W11,HR!W11,HU!W11,IE!W11,IT!W11,LT!W11,LU!W11,LV!W11,MT!W11,NL!W11,PL!W11,PT!W11,RO!W11,SE!W11,SI!W11,SK!W11) -> 79248.097
A12: 1.A.2.b - Non-Ferrous Metals | B12: =SUM(AT!B12,BE!B12,BG!B12,CY!B12,CZ!B12,DE!B12,DK!B12,EE!B12,EL!B12,ES!B12,FI!B12,FR!B12,HR!B12,HU!B12,IE!B12,IT!B12,LT!B12,LU!B12,LV!B12,MT!B12,NL!B12,PL!B12,PT!B12,RO!B12,SE!B12,SI!B12,SK!B12) -> 12830.711 | C12: =SUM(AT!C12,BE!C12,BG!C12,CY!C12,CZ!C12,DE!C12,DK!C12,EE!C12,EL!C12,ES!C12,FI!C12,FR!C12,HR!C12,HU!C12,IE!C12,IT!C12,LT!C12,LU!C12,LV!C12,MT!C12,NL!C12,PL!C12,PT!C12,RO!C12,SE!C12,SI!C12,SK!C12) -> 13376.353 | D12: =SUM(AT!D12,BE!D12,BG!D12,CY!D12,CZ!D12,DE!D12,DK!D12,EE!D12,EL!D12,ES!D12,FI!D12,FR!D12,HR!D12,HU!D12,IE!D12,IT!D12,LT!D12,LU!D12,LV!D12,MT!D12,NL!D12,PL!D12,PT!D12,RO!D12,SE!D12,SI!D12,SK!D12) -> 13036.4 | E12: =SUM(AT!E12,BE!E12,BG!E12,CY!E12,CZ!E12,DE!E12,DK!E12,EE!E12,EL!E12,ES!E12,FI!E12,FR!E12,HR!E12,HU!E12,IE!E12,IT!E12,LT!E12,LU!E12,LV!E12,MT!E12,NL!E12,PL!E12,PT!E12,RO!E12,SE!E12,SI!E12,SK!E12) -> 12672.084 | F12: =SUM(AT!F12,BE!F12,BG!F12,CY!F12,CZ!F12,DE!F12,DK!F12,EE!F12,EL!F12,ES!F12,FI!F12,FR!F12,HR!F12,HU!F12,IE!F12,IT!F12,LT!F12,LU!F12,LV!F12,MT!F12,NL!F12,PL!F12,PT!F12,RO!F12,SE!F12,SI!F12,SK!F12) -> 12516.94 | G12: =SUM(AT!G12,BE!G12,BG!G12,CY!G12,CZ!G12,DE!G12,DK!G12,EE!G12,EL!G12,ES!G12,FI!G12,FR!G12,HR!G12,HU!G12,IE!G12,IT!G12,LT!G12,LU!G12,LV!G12,MT!G12,NL!G12,PL!G12,PT!G12,RO!G12,SE!G12,SI!G12,SK!G12) -> 11435.789 | H12: =SUM(AT!H12,BE!H12,BG!H12,CY!H12,CZ!H12,DE!H12,DK!H12,EE!H12,EL!H12,ES!H12,FI!H12,FR!H12,HR!H12,HU!H12,IE!H12,IT!H12,LT!H12,LU!H12,LV!H12,MT!H12,NL!H12,PL!H12,PT!H12,RO!H12,SE!H12,SI!H12,SK!H12) -> 11465.068 | I12: =SUM(AT!I12,BE!I12,BG!I12,CY!I12,CZ!I12,DE!I12,DK!I12,EE!I12,EL!I12,ES!I12,FI!I12,FR!I12,HR!I12,HU!I12,IE!I12,IT!I12,LT!I12,LU!I12,LV!I12,MT!I12,NL!I12,PL!I12,PT!I12,RO!I12,SE!I12,SI!I12,SK!I12) -> 11548.033 | ... W12: =SUM(AT!W12,BE!W12,BG!W12,CY!W12,CZ!W12,DE!W12,DK!W12,EE!W12,EL!W12,ES!W12,FI!W12,FR!W12,HR!W12,HU!W12,IE!W12,IT!W12,LT!W12,LU!W12,LV!W12,MT!W12,NL!W12,PL!W12,PT!W12,RO!W12,SE!W12,SI!W12,SK!W12) -> 9430.6799
A13: 1.A.2.c - Chemicals | B13: =SUM(AT!B13,BE!B13,BG!B13,CY!B13,CZ!B13,DE!B13,DK!B13,EE!B13,EL!B13,ES!B13,FI!B13,FR!B13,HR!B13,HU!B13,IE!B13,IT!B13,LT!B13,LU!B13,LV!B13,MT!B13,NL!B13,PL!B13,PT!B13,RO!B13,SE!B13,SI!B13,SK!B13) -> 86687.901 | C13: =SUM(AT!C13,BE!C13,BG!C13,CY!C13,CZ!C13,DE!C13,DK!C13,EE!C13,EL!C13,ES!C13,FI!C13,FR!C13,HR!C13,HU!C13,IE!C13,IT!C13,LT!C13,LU!C13,LV!C13,MT!C13,NL!C13,PL!C13,PT!C13,RO!C13,SE!C13,SI!C13,SK!C13) -> 85124.619 | D13: =SUM(AT!D13,BE!D13,BG!D13,CY!D13,CZ!D13,DE!D13,DK!D13,EE!D13,EL!D13,ES!D13,FI!D13,FR!D13,HR!D13,HU!D13,IE!D13,IT!D13,LT!D13,LU!D13,LV!D13,MT!D13,NL!D13,PL!D13,PT!D13,RO!D13,SE!D13,SI!D13,SK!D13) -> 81493.9 | E13: =SUM(AT!E13,BE!E13,BG!E13,CY!E13,CZ!E13,DE!E13,DK!E13,EE!E13,EL!E13,ES!E13,FI!E13,FR!E13,HR!E13,HU!E13,IE!E13,IT!E13,LT!E13,LU!E13,LV!E13,MT!E13,NL!E13,PL!E13,PT!E13,RO!E13,SE!E13,SI!E13,SK!E13) -> 83488.909 | F13: =SUM(AT!F13,BE!F13,BG!F13,CY!F13,CZ!F13,DE!F13,DK!F13,EE!F13,EL!F13,ES!F13,FI!F13,FR!F13,HR!F13,HU!F13,IE!F13,IT!F13,LT!F13,LU!F13,LV!F13,MT!F13,NL!F13,PL!F13,PT!F13,RO!F13,SE!F13,SI!F13,SK!F13) -> 84428.329 | G13: =SUM(AT!G13,BE!G13,BG!G13,CY!G13,CZ!G13,DE!G13,DK!G13,EE!G13,EL!G13,ES!G13,FI!G13,FR!G13,HR!G13,HU!G13,IE!G13,IT!G13,LT!G13,LU!G13,LV!G13,MT!G13,NL!G13,PL!G13,PT!G13,RO!G13,SE!G13,SI!G13,SK!G13) -> 83964.828 | H13: =SUM(AT!H13,BE!H13,BG!H13,CY!H13,CZ!H13,DE!H13,DK!H13,EE!H13,EL!H13,ES!H13,FI!H13,FR!H13,HR!H13,HU!H13,IE!H13,IT!H13,LT!H13,LU!H13,LV!H13,MT!H13,NL!H13,PL!H13,PT!H13,RO!H13,SE!H13,SI!H13,SK!H13) -> 82632.253 | I13: =SUM(AT!I13,BE!I13,BG!I13,CY!I13,CZ!I13,DE!I13,DK!I13,EE!I13,EL!I13,ES!I13,FI!I13,FR!I13,HR!I13,HU!I13,IE!I13,IT!I13,LT!I13,LU!I13,LV!I13,MT!I13,NL!I13,PL!I13,PT!I13,RO!I13,SE!I13,SI!I13,SK!I13) -> 83320.484 | ... W13: =SUM(AT!W13,BE!W13,BG!W13,CY!W13,CZ!W13,DE!W13,DK!W13,EE!W13,EL!W13,ES!W13,FI!W13,FR!W13,HR!W13,HU!W13,IE!W13,IT!W13,LT!W13,LU!W13,LV!W13,MT!W13,NL!W13,PL!W13,PT!W13,RO!W13,SE!W13,SI!W13,SK!W13) -> 71147.489
A14: 1.A.2.d - Pulp, Paper and Print | B14: =SUM(AT!B14,BE!B14,BG!B14,CY!B14,CZ!B14,DE!B14,DK!B14,EE!B14,EL!B14,ES!B14,FI!B14,FR!B14,HR!B14,HU!B14,IE!B14,IT!B14,LT!B14,LU!B14,LV!B14,MT!B14,NL!B14,PL!B14,PT!B14,RO!B14,SE!B14,SI!B14,SK!B14) -> 31780.77 | C14: =SUM(AT!C14,BE!C14,BG!C14,CY!C14,CZ!C14,DE!C14,DK!C14,EE!C14,EL!C14,ES!C14,FI!C14,FR!C14,HR!C14,HU!C14,IE!C14,IT!C14,LT!C14,LU!C14,LV!C14,MT!C14,NL!C14,PL!C14,PT!C14,RO!C14,SE!C14,SI!C14,SK!C14) -> 30538.414 | D14: =SUM(AT!D14,BE!D14,BG!D14,CY!D14,CZ!D14,DE!D14,DK!D14,EE!D14,EL!D14,ES!D14,FI!D14,FR!D14,HR!D14,HU!D14,IE!D14,IT!D14,LT!D14,LU!D14,LV!D14,MT!D14,NL!D14,PL!D14,PT!D14,RO!D14,SE!D14,SI!D14,SK!D14) -> 30844.345 | E14: =SUM(AT!E14,BE!E14,BG!E14,CY!E14,CZ!E14,DE!E14,DK!E14,EE!E14,EL!E14,ES!E14,FI!E14,FR!E14,HR!E14,HU!E14,IE!E14,IT!E14,LT!E14,LU!E14,LV!E14,MT!E14,NL!E14,PL!E14,PT!E14,RO!E14,SE!E14,SI!E14,SK!E14) -> 31052.622 | F14: =SUM(AT!F14,BE!F14,BG!F14,CY!F14,CZ!F14,DE!F14,DK!F14,EE!F14,EL!F14,ES!F14,FI!F14,FR!F14,HR!F14,HU!F14,IE!F14,IT!F14,LT!F14,LU!F14,LV!F14,MT!F14,NL!F14,PL!F14,PT!F14,RO!F14,SE!F14,SI!F14,SK!F14) -> 30126.769 | G14: =SUM(AT!G14,BE!G14,BG!G14,CY!G14,CZ!G14,DE!G14,DK!G14,EE!G14,EL!G14,ES!G14,FI!G14,FR!G14,HR!G14,HU!G14,IE!G14,IT!G14,LT!G14,LU!G14,LV!G14,MT!G14,NL!G14,PL!G14,PT!G14,RO!G14,SE!G14,SI!G14,SK!G14) -> 30217.191 | H14: =SUM(AT!H14,BE!H14,BG!H14,CY!H14,CZ!H14,DE!H14,DK!H14,EE!H14,EL!H14,ES!H14,FI!H14,FR!H14,HR!H14,HU!H14,IE!H14,IT!H14,LT!H14,LU!H14,LV!H14,MT!H14,NL!H14,PL!H14,PT!H14,RO!H14,SE!H14,SI!H14,SK!H14) -> 29802.082 | I14: =SUM(AT!I14,BE!I14,BG!I14,CY!I14,CZ!I14,DE!I14,DK!I14,EE!I14,EL!I14,ES!I14,FI!I14,FR!I14,HR!I14,HU!I14,IE!I14,IT!I14,LT!I14,LU!I14,LV!I14,MT!I14,NL!I14,PL!I14,PT!I14,RO!I14,SE!I14,SI!I14,SK!I14) -> 28918.085 | ... W14: =SUM(AT!W14,BE!W14,BG!W14,CY!W14,CZ!W14,DE!W14,DK!W14,EE!W14,EL!W14,ES!W14,FI!W14,FR!W14,HR!W14,HU!W14,IE!W14,IT!W14,LT!W14,LU!W14,LV!W14,MT!W14,NL!W14,PL!W14,PT!W14,RO!W14,SE!W14,SI!W14,SK!W14) -> 23096.235
A15: 1.A.2.e - Food Processing, Beverages and Tobacco | B15: =SUM(AT!B15,BE!B15,BG!B15,CY!B15,CZ!B15,DE!B15,DK!B15,EE!B15,EL!B15,ES!B15,FI!B15,FR!B15,HR!B15,HU!B15,IE!B15,IT!B15,LT!B15,LU!B15,LV!B15,MT!B15,NL!B15,PL!B15,PT!B15,RO!B15,SE!B15,SI!B15,SK!B15) -> 48556.125 | C15: =SUM(AT!C15,BE!C15,BG!C15,CY!C15,CZ!C15,DE!C15,DK!C15,EE!C15,EL!C15,ES!C15,FI!C15,FR!C15,HR!C15,HU!C15,IE!C15,IT!C15,LT!C15,LU!C15,LV!C15,MT!C15,NL!C15,PL!C15,PT!C15,RO!C15,SE!C15,SI!C15,SK!C15) -> 49224.728 | D15: =SUM(AT!D15,BE!D15,BG!D15,CY!D15,CZ!D15,DE!D15,DK!D15,EE!D15,EL!D15,ES!D15,FI!D15,FR!D15,HR!D15,HU!D15,IE!D15,IT!D15,LT!D15,LU!D15,LV!D15,MT!D15,NL!D15,PL!D15,PT!D15,RO!D15,SE!D15,SI!D15,SK!D15) -> 49640.805 | E15: =SUM(AT!E15,BE!E15,BG!E15,CY!E15,CZ!E15,DE!E15,DK!E15,EE!E15,EL!E15,ES!E15,FI!E15,FR!E15,HR!E15,HU!E15,IE!E15,IT!E15,LT!E15,LU!E15,LV!E15,MT!E15,NL!E15,PL!E15,PT!E15,RO!E15,SE!E15,SI!E15,SK!E15) -> 48724.218 | F15: =SUM(AT!F15,BE!F15,BG!F15,CY!F15,CZ!F15,DE!F15,DK!F15,EE!F15,EL!F15,ES!F15,FI!F15,FR!F15,HR!F15,HU!F15,IE!F15,IT!F15,LT!F15,LU!F15,LV!F15,MT!F15,NL!F15,PL!F15,PT!F15,RO!F15,SE!F15,SI!F15,SK!F15) -> 45934.37 | G15: =SUM(AT!G15,BE!G15,BG!G15,CY!G15,CZ!G15,DE!G15,DK!G15,EE!G15,EL!G15,ES!G15,FI!G15,FR!G15,HR!G15,HU!G15,IE!G15,IT!G15,LT!G15,LU!G15,LV!G15,MT!G15,NL!G15,PL!G15,PT!G15,RO!G15,SE!G15,SI!G15,SK!G15) -> 44988.368 | H15: =SUM(AT!H15,BE!H15,BG!H15,CY!H15,CZ!H15,DE!H15,DK!H15,EE!H15,EL!H15,ES!H15,FI!H15,FR!H15,HR!H15,HU!H15,IE!H15,IT!H15,LT!H15,LU!H15,LV!H15,MT!H15,NL!H15,PL!H15,PT!H15,RO!H15,SE!H15,SI!H15,SK!H15) -> 40850.271 | I15: =SUM(AT!I15,BE!I15,BG!I15,CY!I15,CZ!I15,DE!I15,DK!I15,EE!I15,EL!I15,ES!I15,FI!I15,FR!I15,HR!I15,HU!I15,IE!I15,IT!I15,LT!I15,LU!I15,LV!I15,MT!I15,NL!I15,PL!I15,PT!I15,RO!I15,SE!I15,SI!I15,SK!I15) -> 40153.126 | ... W15: =SUM(AT!W15,BE!W15,BG!W15,CY!W15,CZ!W15,DE!W15,DK!W15,EE!W15,EL!W15,ES!W15,FI!W15,FR!W15,HR!W15,HU!W15,IE!W15,IT!W15,LT!W15,LU!W15,LV!W15,MT!W15,NL!W15,PL!W15,PT!W15,RO!W15,SE!W15,SI!W15,SK!W15) -> 36143.19
A16: 1.A.2.f - Non-metallic minerals | B16: =SUM(AT!B16,BE!B16,BG!B16,CY!B16,CZ!B16,DE!B16,DK!B16,EE!B16,EL!B16,ES!B16,FI!B16,FR!B16,HR!B16,HU!B16,IE!B16,IT!B16,LT!B16,LU!B16,LV!B16,MT!B16,NL!B16,PL!B16,PT!B16,RO!B16,SE!B16,SI!B16,SK!B16) -> 119281.72 | C16: =SUM(AT!C16,BE!C16,BG!C16,CY!C16,CZ!C16,DE!C16,DK!C16,EE!C16,EL!C16,ES!C16,FI!C16,FR!C16,HR!C16,HU!C16,IE!C16,IT!C16,LT!C16,LU!C16,LV!C16,MT!C16,NL!C16,PL!C16,PT!C16,RO!C16,SE!C16,SI!C16,SK!C16) -> 118733.57 | D16: =SUM(AT!D16,BE!D16,BG!D16,CY!D16,CZ!D16,DE!D16,DK!D16,EE!D16,EL!D16,ES!D16,FI!D16,FR!D16,HR!D16,HU!D16,IE!D16,IT!D16,LT!D16,LU!D16,LV!D16,MT!D16,NL!D16,PL!D16,PT!D16,RO!D16,SE!D16,SI!D16,SK!D16) -> 116479.1 | E16: =SUM(AT!E16,BE!E16,BG!E16,CY!E16,CZ!E16,DE!E16,DK!E16,EE!E16,EL!E16,ES!E16,FI!E16,FR!E16,HR!E16,HU!E16,IE!E16,IT!E16,LT!E16,LU!E16,LV!E16,MT!E16,NL!E16,PL!E16,PT!E16,RO!E16,SE!E16,SI!E16,SK!E16) -> 120573.14 | F16: =SUM(AT!F16,BE!F16,BG!F16,CY!F16,CZ!F16,DE!F16,DK!F16,EE!F16,EL!F16,ES!F16,FI!F16,FR!F16,HR!F16,HU!F16,IE!F16,IT!F16,LT!F16,LU!F16,LV!F16,MT!F16,NL!F16,PL!F16,PT!F16,RO!F16,SE!F16,SI!F16,SK!F16) -> 119954.04 | G16: =SUM(AT!G16,BE!G16,BG!G16,CY!G16,CZ!G16,DE!G16,DK!G16,EE!G16,EL!G16,ES!G16,FI!G16,FR!G16,HR!G16,HU!G16,IE!G16,IT!G16,LT!G16,LU!G16,LV!G16,MT!G16,NL!G16,PL!G16,PT!G16,RO!G16,SE!G16,SI!G16,SK!G16) -> 123451.58 | H16: =SUM(AT!H16,BE!H16,BG!H16,CY!H16,CZ!H16,DE!H16,DK!H16,EE!H16,EL!H16,ES!H16,FI!H16,FR!H16,HR!H16,HU!H16,IE!H16,IT!H16,LT!H16,LU!H16,LV!H16,MT!H16,NL!H16,PL!H16,PT!H16,RO!H16,SE!H16,SI!H16,SK!H16) -> 121819.31 | I16: =SUM(AT!I16,BE!I16,BG!I16,CY!I16,CZ!I16,DE!I16,DK!I16,EE!I16,EL!I16,ES!I16,FI!I16,FR!I16,HR!I16,HU!I16,IE!I16,IT!I16,LT!I16,LU!I16,LV!I16,MT!I16,NL!I16,PL!I16,PT!I16,RO!I16,SE!I16,SI!I16,SK!I16) -> 124427.12 | ... W16: =SUM(AT!W16,BE!W16,BG!W16,CY!W16,CZ!W16,DE!W16,DK!W16,EE!W16,EL!W16,ES!W16,FI!W16,FR!W16,HR!W16,HU!W16,IE!W16,IT!W16,LT!W16,LU!W16,LV!W16,MT!W16,NL!W16,PL!W16,PT!W16,RO!W16,SE!W16,SI!W16,SK!W16) -> 83196.02
A17: 1.A.2.g - Other Manufacturing Industries and Constructions | B17: =SUM(AT!B17,BE!B17,BG!B17,CY!B17,CZ!B17,DE!B17,DK!B17,EE!B17,EL!B17,ES!B17,FI!B17,FR!B17,HR!B17,HU!B17,IE!B17,IT!B17,LT!B17,LU!B17,LV!B17,MT!B17,NL!B17,PL!B17,PT!B17,RO!B17,SE!B17,SI!B17,SK!B17) -> 165615.77 | C17: =SUM(AT!C17,BE!C17,BG!C17,CY!C17,CZ!C17,DE!C17,DK!C17,EE!C17,EL!C17,ES!C17,FI!C17,FR!C17,HR!C17,HU!C17,IE!C17,IT!C17,LT!C17,LU!C17,LV!C17,MT!C17,NL!C17,PL!C17,PT!C17,RO!C17,SE!C17,SI!C17,SK!C17) -> 164108.98 | D17: =SUM(AT!D17,BE!D17,BG!D17,CY!D17,CZ!D17,DE!D17,DK!D17,EE!D17,EL!D17,ES!D17,FI!D17,FR!D17,HR!D17,HU!D17,IE!D17,IT!D17,LT!D17,LU!D17,LV!D17,MT!D17,NL!D17,PL!D17,PT!D17,RO!D17,SE!D17,SI!D17,SK!D17) -> 163423.11 | E17: =SUM(AT!E17,BE!E17,BG!E17,CY!E17,CZ!E17,DE!E17,DK!E17,EE!E17,EL!E17,ES!E17,FI!E17,FR!E17,HR!E17,HU!E17,IE!E17,IT!E17,LT!E17,LU!E17,LV!E17,MT!E17,NL!E17,PL!E17,PT!E17,RO!E17,SE!E17,SI!E17,SK!E17) -> 165059.8 | F17: =SUM(AT!F17,BE!F17,BG!F17,CY!F17,CZ!F17,DE!F17,DK!F17,EE!F17,EL!F17,ES!F17,FI!F17,FR!F17,HR!F17,HU!F17,IE!F17,IT!F17,LT!F17,LU!F17,LV!F17,MT!F17,NL!F17,PL!F17,PT!F17,RO!F17,SE!F17,SI!F17,SK!F17) -> 159550.72 | G17: =SUM(AT!G17,BE!G17,BG!G17,CY!G17,CZ!G17,DE!G17,DK!G17,EE!G17,EL!G17,ES!G17,FI!G17,FR!G17,HR!G17,HU!G17,IE!G17,IT!G17,LT!G17,LU!G17,LV!G17,MT!G17,NL!G17,PL!G17,PT!G17,RO!G17,SE!G17,SI!G17,SK!G17) -> 151443.91 | H17: =SUM(AT!H17,BE!H17,BG!H17,CY!H17,CZ!H17,DE!H17,DK!H17,EE!H17,EL!H17,ES!H17,FI!H17,FR!H17,HR!H17,HU!H17,IE!H17,IT!H17,LT!H17,LU!H17,LV!H17,MT!H17,NL!H17,PL!H17,PT!H17,RO!H17,SE!H17,SI!H17,SK!H17) -> 148196.73 | I17: =SUM(AT!I17,BE!I17,BG!I17,CY!I17,CZ!I17,DE!I17,DK!I17,EE!I17,EL!I17,ES!I17,FI!I17,FR!I17,HR!I17,HU!I17,IE!I17,IT!I17,LT!I17,LU!I17,LV!I17,MT!I17,NL!I17,PL!I17,PT!I17,RO!I17,SE!I17,SI!I17,SK!I17) -> 151777.18 | ... W17: =SUM(AT!W17,BE!W17,BG!W17,CY!W17,CZ!W17,DE!W17,DK!W17,EE!W17,EL!W17,ES!W17,FI!W17,FR!W17,HR!W17,HU!W17,IE!W17,IT!W17,LT!W17,LU!W17,LV!W17,MT!W17,NL!W17,PL!W17,PT!W17,RO!W17,SE!W17,SI!W17,SK!W17) -> 131478.07
A18: 1.A.3 - Transport | B18: =SUM(B19:B23) -> 785734.53 | C18: =SUM(C19:C23) -> 800237.54 | D18: =SUM(D19:D23) -> 809962.47 | E18: =SUM(E19:E23) -> 820094.56 | F18: =SUM(F19:F23) -> 838685.12 | G18: =SUM(G19:G23) -> 837867.27 | H18: =SUM(H19:H23) -> 846150.28 | I18: =SUM(I19:I23) -> 854708.88 | ... W18: =SUM(W19:W23) -> 773397.18
A19: 1.A.3.a - Domestic Aviation | B19: =SUM(AT!B19,BE!B19,BG!B19,CY!B19,CZ!B19,DE!B19,DK!B19,EE!B19,EL!B19,ES!B19,FI!B19,FR!B19,HR!B19,HU!B19,IE!B19,IT!B19,LT!B19,LU!B19,LV!B19,MT!B19,NL!B19,PL!B19,PT!B19,RO!B19,SE!B19,SI!B19,SK!B19) -> 17159.54 | C19: =SUM(AT!C19,BE!C19,BG!C19,CY!C19,CZ!C19,DE!C19,DK!C19,EE!C19,EL!C19,ES!C19,FI!C19,FR!C19,HR!C19,HU!C19,IE!C19,IT!C19,LT!C19,LU!C19,LV!C19,MT!C19,NL!C19,PL!C19,PT!C19,RO!C19,SE!C19,SI!C19,SK!C19) -> 16641.531 | D19: =SUM(AT!D19,BE!D19,BG!D19,CY!D19,CZ!D19,DE!D19,DK!D19,EE!D19,EL!D19,ES!D19,FI!D19,FR!D19,HR!D19,HU!D19,IE!D19,IT!D19,LT!D19,LU!D19,LV!D19,MT!D19,NL!D19,PL!D19,PT!D19,RO!D19,SE!D19,SI!D19,SK!D19) -> 16290.512 | E19: =SUM(AT!E19,BE!E19,BG!E19,CY!E19,CZ!E19,DE!E19,DK!E19,EE!E19,EL!E19,ES!E19,FI!E19,FR!E19,HR!E19,HU!E19,IE!E19,IT!E19,LT!E19,LU!E19,LV!E19,MT!E19,NL!E19,PL!E19,PT!E19,RO!E19,SE!E19,SI!E19,SK!E19) -> 16159.697 | F19: =SUM(AT!F19,BE!F19,BG!F19,CY!F19,CZ!F19,DE!F19,DK!F19,EE!F19,EL!F19,ES!F19,FI!F19,FR!F19,HR!F19,HU!F19,IE!F19,IT!F19,LT!F19,LU!F19,LV!F19,MT!F19,NL!F19,PL!F19,PT!F19,RO!F19,SE!F19,SI!F19,SK!F19) -> 16515.187 | G19: =SUM(AT!G19,BE!G19,BG!G19,CY!G19,CZ!G19,DE!G19,DK!G19,EE!G19,EL!G19,ES!G19,FI!G19,FR!G19,HR!G19,HU!G19,IE!G19,IT!G19,LT!G19,LU!G19,LV!G19,MT!G19,NL!G19,PL!G19,PT!G19,RO!G19,SE!G19,SI!G19,SK!G19) -> 16592.126 | H19: =SUM(AT!H19,BE!H19,BG!H19,CY!H19,CZ!H19,DE!H19,DK!H19,EE!H19,EL!H19,ES!H19,FI!H19,FR!H19,HR!H19,HU!H19,IE!H19,IT!H19,LT!H19,LU!H19,LV!H19,MT!H19,NL!H19,PL!H19,PT!H19,RO!H19,SE!H19,SI!H19,SK!H19) -> 16548.83 | I19: =SUM(AT!I19,BE!I19,BG!I19,CY!I19,CZ!I19,DE!I19,DK!I19,EE!I19,EL!I19,ES!I19,FI!I19,FR!I19,HR!I19,HU!I19,IE!I19,IT!I19,LT!I19,LU!I19,LV!I19,MT!I19,NL!I19,PL!I19,PT!I19,RO!I19,SE!I19,SI!I19,SK!I19) -> 16960.226 | ... W19: =SUM(AT!W19,BE!W19,BG!W19,CY!W19,CZ!W19,DE!W19,DK!W19,EE!W19,EL!W19,ES!W19,FI!W19,FR!W19,HR!W19,HU!W19,IE!W19,IT!W19,LT!W19,LU!W19,LV!W19,MT!W19,NL!W19,PL!W19,PT!W19,RO!W19,SE!W19,SI!W19,SK!W19) -> 9735.4578
A20: 1.A.3.b - Road Transportation | B20: =SUM(AT!B20,BE!B20,BG!B20,CY!B20,CZ!B20,DE!B20,DK!B20,EE!B20,EL!B20,ES!B20,FI!B20,FR!B20,HR!B20,HU!B20,IE!B20,IT!B20,LT!B20,LU!B20,LV!B20,MT!B20,NL!B20,PL!B20,PT!B20,RO!B20,SE!B20,SI!B20,SK!B20) -> 735382.2 | C20: =SUM(AT!C20,BE!C20,BG!C20,CY!C20,CZ!C20,DE!C20,DK!C20,EE!C20,EL!C20,ES!C20,FI!C20,FR!C20,HR!C20,HU!C20,IE!C20,IT!C20,LT!C20,LU!C20,LV!C20,MT!C20,NL!C20,PL!C20,PT!C20,RO!C20,SE!C20,SI!C20,SK!C20) -> 750997 | D20: =SUM(AT!D20,BE!D20,BG!D20,CY!D20,CZ!D20,DE!D20,DK!D20,EE!D20,EL!D20,ES!D20,FI!D20,FR!D20,HR!D20,HU!D20,IE!D20,IT!D20,LT!D20,LU!D20,LV!D20,MT!D20,NL!D20,PL!D20,PT!D20,RO!D20,SE!D20,SI!D20,SK!D20) -> 761348.81 | E20: =SUM(AT!E20,BE!E20,BG!E20,CY!E20,CZ!E20,DE!E20,DK!E20,EE!E20,EL!E20,ES!E20,FI!E20,FR!E20,HR!E20,HU!E20,IE!E20,IT!E20,LT!E20,LU!E20,LV!E20,MT!E20,NL!E20,PL!E20,PT!E20,RO!E20,SE!E20,SI!E20,SK!E20) -> 771311.65 | F20: =SUM(AT!F20,BE!F20,BG!F20,CY!F20,CZ!F20,DE!F20,DK!F20,EE!F20,EL!F20,ES!F20,FI!F20,FR!F20,HR!F20,HU!F20,IE!F20,IT!F20,LT!F20,LU!F20,LV!F20,MT!F20,NL!F20,PL!F20,PT!F20,RO!F20,SE!F20,SI!F20,SK!F20) -> 788403.59 | G20: =SUM(AT!G20,BE!G20,BG!G20,CY!G20,CZ!G20,DE!G20,DK!G20,EE!G20,EL!G20,ES!G20,FI!G20,FR!G20,HR!G20,HU!G20,IE!G20,IT!G20,LT!G20,LU!G20,LV!G20,MT!G20,NL!G20,PL!G20,PT!G20,RO!G20,SE!G20,SI!G20,SK!G20) -> 787866.59 | H20: =SUM(AT!H20,BE!H20,BG!H20,CY!H20,CZ!H20,DE!H20,DK!H20,EE!H20,EL!H20,ES!H20,FI!H20,FR!H20,HR!H20,HU!H20,IE!H20,IT!H20,LT!H20,LU!H20,LV!H20,MT!H20,NL!H20,PL!H20,PT!H20,RO!H20,SE!H20,SI!H20,SK!H20) -> 796019.95 | I20: =SUM(AT!I20,BE!I20,BG!I20,CY!I20,CZ!I20,DE!I20,DK!I20,EE!I20,EL!I20,ES!I20,FI!I20,FR!I20,HR!I20,HU!I20,IE!I20,IT!I20,LT!I20,LU!I20,LV!I20,MT!I20,NL!I20,PL!I20,PT!I20,RO!I20,SE!I20,SI!I20,SK!I20) -> 805520.7 | ... W20: =SUM(AT!W20,BE!W20,BG!W20,CY!W20,CZ!W20,DE!W20,DK!W20,EE!W20,EL!W20,ES!W20,FI!W20,FR!W20,HR!W20,HU!W20,IE!W20,IT!W20,LT!W20,LU!W20,LV!W20,MT!W20,NL!W20,PL!W20,PT!W20,RO!W20,SE!W20,SI!W20,SK!W20) -> 739758.42
A21: 1.A.3.c - Railways | B21: =SUM(AT!B21,BE!B21,BG!B21,CY!B21,CZ!B21,DE!B21,DK!B21,EE!B21,EL!B21,ES!B21,FI!B21,FR!B21,HR!B21,HU!B21,IE!B21,IT!B21,LT!B21,LU!B21,LV!B21,MT!B21,NL!B21,PL!B21,PT!B21,RO!B21,SE!B21,SI!B21,SK!B21) -> 7732.509 | C21: =SUM(AT!C21,BE!C21,BG!C21,CY!C21,CZ!C21,DE!C21,DK!C21,EE!C21,EL!C21,ES!C21,FI!C21,FR!C21,HR!C21,HU!C21,IE!C21,IT!C21,LT!C21,LU!C21,LV!C21,MT!C21,NL!C21,PL!C21,PT!C21,RO!C21,SE!C21,SI!C21,SK!C21) -> 6858.586 | D21: =SUM(AT!D21,BE!D21,BG!D21,CY!D21,CZ!D21,DE!D21,DK!D21,EE!D21,EL!D21,ES!D21,FI!D21,FR!D21,HR!D21,HU!D21,IE!D21,IT!D21,LT!D21,LU!D21,LV!D21,MT!D21,NL!D21,PL!D21,PT!D21,RO!D21,SE!D21,SI!D21,SK!D21) -> 6850.9212 | E21: =SUM(AT!E21,BE!E21,BG!E21,CY!E21,CZ!E21,DE!E21,DK!E21,EE!E21,EL!E21,ES!E21,FI!E21,FR!E21,HR!E21,HU!E21,IE!E21,IT!E21,LT!E21,LU!E21,LV!E21,MT!E21,NL!E21,PL!E21,PT!E21,RO!E21,SE!E21,SI!E21,SK!E21) -> 6754.7167 | F21: =SUM(AT!F21,BE!F21,BG!F21,CY!F21,CZ!F21,DE!F21,DK!F21,EE!F21,EL!F21,ES!F21,FI!F21,FR!F21,HR!F21,HU!F21,IE!F21,IT!F21,LT!F21,LU!F21,LV!F21,MT!F21,NL!F21,PL!F21,PT!F21,RO!F21,SE!F21,SI!F21,SK!F21) -> 6645.0577 | G21: =SUM(AT!G21,BE!G21,BG!G21,CY!G21,CZ!G21,DE!G21,DK!G21,EE!G21,EL!G21,ES!G21,FI!G21,FR!G21,HR!G21,HU!G21,IE!G21,IT!G21,LT!G21,LU!G21,LV!G21,MT!G21,NL!G21,PL!G21,PT!G21,RO!G21,SE!G21,SI!G21,SK!G21) -> 5979.4481 | H21: =SUM(AT!H21,BE!H21,BG!H21,CY!H21,CZ!H21,DE!H21,DK!H21,EE!H21,EL!H21,ES!H21,FI!H21,FR!H21,HR!H21,HU!H21,IE!H21,IT!H21,LT!H21,LU!H21,LV!H21,MT!H21,NL!H21,PL!H21,PT!H21,RO!H21,SE!H21,SI!H21,SK!H21) -> 5854.6016 | I21: =SUM(AT!I21,BE!I21,BG!I21,CY!I21,CZ!I21,DE!I21,DK!I21,EE!I21,EL!I21,ES!I21,FI!I21,FR!I21,HR!I21,HU!I21,IE!I21,IT!I21,LT!I21,LU!I21,LV!I21,MT!I21,NL!I21,PL!I21,PT!I21,RO!I21,SE!I21,SI!I21,SK!I21) -> 6069.2965 | ... W21: =SUM(AT!W21,BE!W21,BG!W21,CY!W21,CZ!W21,DE!W21,DK!W21,EE!W21,EL!W21,ES!W21,FI!W21,FR!W21,HR!W21,HU!W21,IE!W21,IT!W21,LT!W21,LU!W21,LV!W21,MT!W21,NL!W21,PL!W21,PT!W21,RO!W21,SE!W21,SI!W21,SK!W21) -> 3576.4539
A22: 1.A.3.d - Domestic Navigation | B22: =SUM(AT!B22,BE!B22,BG!B22,CY!B22,CZ!B22,DE!B22,DK!B22,EE!B22,EL!B22,ES!B22,FI!B22,FR!B22,HR!B22,HU!B22,IE!B22,IT!B22,LT!B22,LU!B22,LV!B22,MT!B22,NL!B22,PL!B22,PT!B22,RO!B22,SE!B22,SI!B22,SK!B22) -> 18705.076 | C22: =SUM(AT!C22,BE!C22,BG!C22,CY!C22,CZ!C22,DE!C22,DK!C22,EE!C22,EL!C22,ES!C22,FI!C22,FR!C22,HR!C22,HU!C22,IE!C22,IT!C22,LT!C22,LU!C22,LV!C22,MT!C22,NL!C22,PL!C22,PT!C22,RO!C22,SE!C22,SI!C22,SK!C22) -> 19150.557 | D22: =SUM(AT!D22,BE!D22,BG!D22,CY!D22,CZ!D22,DE!D22,DK!D22,EE!D22,EL!D22,ES!D22,FI!D22,FR!D22,HR!D22,HU!D22,IE!D22,IT!D22,LT!D22,LU!D22,LV!D22,MT!D22,NL!D22,PL!D22,PT!D22,RO!D22,SE!D22,SI!D22,SK!D22) -> 18863.106 | E22: =SUM(AT!E22,BE!E22,BG!E22,CY!E22,CZ!E22,DE!E22,DK!E22,EE!E22,EL!E22,ES!E22,FI!E22,FR!E22,HR!E22,HU!E22,IE!E22,IT!E22,LT!E22,LU!E22,LV!E22,MT!E22,NL!E22,PL!E22,PT!E22,RO!E22,SE!E22,SI!E22,SK!E22) -> 19355.381 | F22: =SUM(AT!F22,BE!F22,BG!F22,CY!F22,CZ!F22,DE!F22,DK!F22,EE!F22,EL!F22,ES!F22,FI!F22,FR!F22,HR!F22,HU!F22,IE!F22,IT!F22,LT!F22,LU!F22,LV!F22,MT!F22,NL!F22,PL!F22,PT!F22,RO!F22,SE!F22,SI!F22,SK!F22) -> 19528.365 | G22: =SUM(AT!G22,BE!G22,BG!G22,CY!G22,CZ!G22,DE!G22,DK!G22,EE!G22,EL!G22,ES!G22,FI!G22,FR!G22,HR!G22,HU!G22,IE!G22,IT!G22,LT!G22,LU!G22,LV!G22,MT!G22,NL!G22,PL!G22,PT!G22,RO!G22,SE!G22,SI!G22,SK!G22) -> 19339.159 | H22: =SUM(AT!H22,BE!H22,BG!H22,CY!H22,CZ!H22,DE!H22,DK!H22,EE!H22,EL!H22,ES!H22,FI!H22,FR!H22,HR!H22,HU!H22,IE!H22,IT!H22,LT!H22,LU!H22,LV!H22,MT!H22,NL!H22,PL!H22,PT!H22,RO!H22,SE!H22,SI!H22,SK!H22) -> 19659.047 | I22: =SUM(AT!I22,BE!I22,BG!I22,CY!I22,CZ!I22,DE!I22,DK!I22,EE!I22,EL!I22,ES!I22,FI!I22,FR!I22,HR!I22,HU!I22,IE!I22,IT!I22,LT!I22,LU!I22,LV!I22,MT!I22,NL!I22,PL!I22,PT!I22,RO!I22,SE!I22,SI!I22,SK!I22) -> 18718.898 | ... W22: =SUM(AT!W22,BE!W22,BG!W22,CY!W22,CZ!W22,DE!W22,DK!W22,EE!W22,EL!W22,ES!W22,FI!W22,FR!W22,HR!W22,HU!W22,IE!W22,IT!W22,LT!W22,LU!W22,LV!W22,MT!W22,NL!W22,PL!W22,PT!W22,RO!W22,SE!W22,SI!W22,SK!W22) -> 15674.707
A23: 1.A.3.e - Other Transportation | B23: =SUM(AT!B23,BE!B23,BG!B23,CY!B23,CZ!B23,DE!B23,DK!B23,EE!B23,EL!B23,ES!B23,FI!B23,FR!B23,HR!B23,HU!B23,IE!B23,IT!B23,LT!B23,LU!B23,LV!B23,MT!B23,NL!B23,PL!B23,PT!B23,RO!B23,SE!B23,SI!B23,SK!B23) -> 6755.2009 | C23: =SUM(AT!C23,BE!C23,BG!C23,CY!C23,CZ!C23,DE!C23,DK!C23,EE!C23,EL!C23,ES!C23,FI!C23,FR!C23,HR!C23,HU!C23,IE!C23,IT!C23,LT!C23,LU!C23,LV!C23,MT!C23,NL!C23,PL!C23,PT!C23,RO!C23,SE!C23,SI!C23,SK!C23) -> 6589.8673 | D23: =SUM(AT!D23,BE!D23,BG!D23,CY!D23,CZ!D23,DE!D23,DK!D23,EE!D23,EL!D23,ES!D23,FI!D23,FR!D23,HR!D23,HU!D23,IE!D23,IT!D23,LT!D23,LU!D23,LV!D23,MT!D23,NL!D23,PL!D23,PT!D23,RO!D23,SE!D23,SI!D23,SK!D23) -> 6609.1265 | E23: =SUM(AT!E23,BE!E23,BG!E23,CY!E23,CZ!E23,DE!E23,DK!E23,EE!E23,EL!E23,ES!E23,FI!E23,FR!E23,HR!E23,HU!E23,IE!E23,IT!E23,LT!E23,LU!E23,LV!E23,MT!E23,NL!E23,PL!E23,PT!E23,RO!E23,SE!E23,SI!E23,SK!E23) -> 6513.1101 | F23: =SUM(AT!F23,BE!F23,BG!F23,CY!F23,CZ!F23,DE!F23,DK!F23,EE!F23,EL!F23,ES!F23,FI!F23,FR!F23,HR!F23,HU!F23,IE!F23,IT!F23,LT!F23,LU!F23,LV!F23,MT!F23,NL!F23,PL!F23,PT!F23,RO!F23,SE!F23,SI!F23,SK!F23) -> 7592.9145 | G23: =SUM(AT!G23,BE!G23,BG!G23,CY!G23,CZ!G23,DE!G23,DK!G23,EE!G23,EL!G23,ES!G23,FI!G23,FR!G23,HR!G23,HU!G23,IE!G23,IT!G23,LT!G23,LU!G23,LV!G23,MT!G23,NL!G23,PL!G23,PT!G23,RO!G23,SE!G23,SI!G23,SK!G23) -> 8089.9406 | H23: =SUM(AT!H23,BE!H23,BG!H23,CY!H23,CZ!H23,DE!H23,DK!H23,EE!H23,EL!H23,ES!H23,FI!H23,FR!H23,HR!H23,HU!H23,IE!H23,IT!H23,LT!H23,LU!H23,LV!H23,MT!H23,NL!H23,PL!H23,PT!H23,RO!H23,SE!H23,SI!H23,SK!H23) -> 8067.8504 | I23: =SUM(AT!I23,BE!I23,BG!I23,CY!I23,CZ!I23,DE!I23,DK!I23,EE!I23,EL!I23,ES!I23,FI!I23,FR!I23,HR!I23,HU!I23,IE!I23,IT!I23,LT!I23,LU!I23,LV!I23,MT!I23,NL!I23,PL!I23,PT!I23,RO!I23,SE!I23,SI!I23,SK!I23) -> 7439.7669 | ... W23: =SUM(AT!W23,BE!W23,BG!W23,CY!W23,CZ!W23,DE!W23,DK!W23,EE!W23,EL!W23,ES!W23,FI!W23,FR!W23,HR!W23,HU!W23,IE!W23,IT!W23,LT!W23,LU!W23,LV!W23,MT!W23,NL!W23,PL!W23,PT!W23,RO!W23,SE!W23,SI!W23,SK!W23) -> 4652.1389
A24: 1.A.4 - Other Sectors | B24: =SUM(B25:B27) -> 612783.97 | C24: =SUM(C25:C27) -> 654610.94 | D24: =SUM(D25:D27) -> 631506.73 | E24: =SUM(E25:E27) -> 643748.94 | F24: =SUM(F25:F27) -> 639748.29 | G24: =SUM(G25:G27) -> 639840.41 | H24: =SUM(H25:H27) -> 637830.72 | I24: =SUM(I25:I27) -> 563374.66 | ... W24: =SUM(W25:W27) -> 506732.77
A25: 1.A.4.a - Commercial/Institutional | B25: =SUM(AT!B25,BE!B25,BG!B25,CY!B25,CZ!B25,DE!B25,DK!B25,EE!B25,EL!B25,ES!B25,FI!B25,FR!B25,HR!B25,HU!B25,IE!B25,IT!B25,LT!B25,LU!B25,LV!B25,MT!B25,NL!B25,PL!B25,PT!B25,RO!B25,SE!B25,SI!B25,SK!B25) -> 142785.56 | C25: =SUM(AT!C25,BE!C25,BG!C25,CY!C25,CZ!C25,DE!C25,DK!C25,EE!C25,EL!C25,ES!C25,FI!C25,FR!C25,HR!C25,HU!C25,IE!C25,IT!C25,LT!C25,LU!C25,LV!C25,MT!C25,NL!C25,PL!C25,PT!C25,RO!C25,SE!C25,SI!C25,SK!C25) -> 156098.73 | D25: =SUM(AT!D25,BE!D25,BG!D25,CY!D25,CZ!D25,DE!D25,DK!D25,EE!D25,EL!D25,ES!D25,FI!D25,FR!D25,HR!D25,HU!D25,IE!D25,IT!D25,LT!D25,LU!D25,LV!D25,MT!D25,NL!D25,PL!D25,PT!D25,RO!D25,SE!D25,SI!D25,SK!D25) -> 149880.61 | E25: =SUM(AT!E25,BE!E25,BG!E25,CY!E25,CZ!E25,DE!E25,DK!E25,EE!E25,EL!E25,ES!E25,FI!E25,FR!E25,HR!E25,HU!E25,IE!E25,IT!E25,LT!E25,LU!E25,LV!E25,MT!E25,NL!E25,PL!E25,PT!E25,RO!E25,SE!E25,SI!E25,SK!E25) -> 150678.7 | F25: =SUM(AT!F25,BE!F25,BG!F25,CY!F25,CZ!F25,DE!F25,DK!F25,EE!F25,EL!F25,ES!F25,FI!F25,FR!F25,HR!F25,HU!F25,IE!F25,IT!F25,LT!F25,LU!F25,LV!F25,MT!F25,NL!F25,PL!F25,PT!F25,RO!F25,SE!F25,SI!F25,SK!F25) -> 153003.39 | G25: =SUM(AT!G25,BE!G25,BG!G25,CY!G25,CZ!G25,DE!G25,DK!G25,EE!G25,EL!G25,ES!G25,FI!G25,FR!G25,HR!G25,HU!G25,IE!G25,IT!G25,LT!G25,LU!G25,LV!G25,MT!G25,NL!G25,PL!G25,PT!G25,RO!G25,SE!G25,SI!G25,SK!G25) -> 153079.99 | H25: =SUM(AT!H25,BE!H25,BG!H25,CY!H25,CZ!H25,DE!H25,DK!H25,EE!H25,EL!H25,ES!H25,FI!H25,FR!H25,HR!H25,HU!H25,IE!H25,IT!H25,LT!H25,LU!H25,LV!H25,MT!H25,NL!H25,PL!H25,PT!H25,RO!H25,SE!H25,SI!H25,SK!H25) -> 160666.39 | I25: =SUM(AT!I25,BE!I25,BG!I25,CY!I25,CZ!I25,DE!I25,DK!I25,EE!I25,EL!I25,ES!I25,FI!I25,FR!I25,HR!I25,HU!I25,IE!I25,IT!I25,LT!I25,LU!I25,LV!I25,MT!I25,NL!I25,PL!I25,PT!I25,RO!I25,SE!I25,SI!I25,SK!I25) -> 141416.33 | ... W25: =SUM(AT!W25,BE!W25,BG!W25,CY!W25,CZ!W25,DE!W25,DK!W25,EE!W25,EL!W25,ES!W25,FI!W25,FR!W25,HR!W25,HU!W25,IE!W25,IT!W25,LT!W25,LU!W25,LV!W25,MT!W25,NL!W25,PL!W25,PT!W25,RO!W25,SE!W25,SI!W25,SK!W25) -> 128500.07
A26: 1.A.4.b - Residential | B26: =SUM(AT!B26,BE!B26,BG!B26,CY!B26,CZ!B26,DE!B26,DK!B26,EE!B26,EL!B26,ES!B26,FI!B26,FR!B26,HR!B26,HU!B26,IE!B26,IT!B26,LT!B26,LU!B26,LV!B26,MT!B26,NL!B26,PL!B26,PT!B26,RO!B26,SE!B26,SI!B26,SK!B26) -> 389747.9 | C26: =SUM(AT!C26,BE!C26,BG!C26,CY!C26,CZ!C26,DE!C26,DK!C26,EE!C26,EL!C26,ES!C26,FI!C26,FR!C26,HR!C26,HU!C26,IE!C26,IT!C26,LT!C26,LU!C26,LV!C26,MT!C26,NL!C26,PL!C26,PT!C26,RO!C26,SE!C26,SI!C26,SK!C26) -> 418321.32 | D26: =SUM(AT!D26,BE!D26,BG!D26,CY!D26,CZ!D26,DE!D26,DK!D26,EE!D26,EL!D26,ES!D26,FI!D26,FR!D26,HR!D26,HU!D26,IE!D26,IT!D26,LT!D26,LU!D26,LV!D26,MT!D26,NL!D26,PL!D26,PT!D26,RO!D26,SE!D26,SI!D26,SK!D26) -> 403505.79 | E26: =SUM(AT!E26,BE!E26,BG!E26,CY!E26,CZ!E26,DE!E26,DK!E26,EE!E26,EL!E26,ES!E26,FI!E26,FR!E26,HR!E26,HU!E26,IE!E26,IT!E26,LT!E26,LU!E26,LV!E26,MT!E26,NL!E26,PL!E26,PT!E26,RO!E26,SE!E26,SI!E26,SK!E26) -> 414324.38 | F26: =SUM(AT!F26,BE!F26,BG!F26,CY!F26,CZ!F26,DE!F26,DK!F26,EE!F26,EL!F26,ES!F26,FI!F26,FR!F26,HR!F26,HU!F26,IE!F26,IT!F26,LT!F26,LU!F26,LV!F26,MT!F26,NL!F26,PL!F26,PT!F26,RO!F26,SE!F26,SI!F26,SK!F26) -> 407483.55 | G26: =SUM(AT!G26,BE!G26,BG!G26,CY!G26,CZ!G26,DE!G26,DK!G26,EE!G26,EL!G26,ES!G26,FI!G26,FR!G26,HR!G26,HU!G26,IE!G26,IT!G26,LT!G26,LU!G26,LV!G26,MT!G26,NL!G26,PL!G26,PT!G26,RO!G26,SE!G26,SI!G26,SK!G26) -> 407489.94 | H26: =SUM(AT!H26,BE!H26,BG!H26,CY!H26,CZ!H26,DE!H26,DK!H26,EE!H26,EL!H26,ES!H26,FI!H26,FR!H26,HR!H26,HU!H26,IE!H26,IT!H26,LT!H26,LU!H26,LV!H26,MT!H26,NL!H26,PL!H26,PT!H26,RO!H26,SE!H26,SI!H26,SK!H26) -> 400814.46 | I26: =SUM(AT!I26,BE!I26,BG!I26,CY!I26,CZ!I26,DE!I26,DK!I26,EE!I26,EL!I26,ES!I26,FI!I26,FR!I26,HR!I26,HU!I26,IE!I26,IT!I26,LT!I26,LU!I26,LV!I26,MT!I26,NL!I26,PL!I26,PT!I26,RO!I26,SE!I26,SI!I26,SK!I26) -> 348634.62 | ... W26: =SUM(AT!W26,BE!W26,BG!W26,CY!W26,CZ!W26,DE!W26,DK!W26,EE!W26,EL!W26,ES!W26,FI!W26,FR!W26,HR!W26,HU!W26,IE!W26,IT!W26,LT!W26,LU!W26,LV!W26,MT!W26,NL!W26,PL!W26,PT!W26,RO!W26,SE!W26,SI!W26,SK!W26) -> 305879.08
A27: 1.A.4.c - Agriculture/Forestry/Fishing | B27: =SUM(AT!B27,BE!B27,BG!B27,CY!B27,CZ!B27,DE!B27,DK!B27,EE!B27,EL!B27,ES!B27,FI!B27,FR!B27,HR!B27,HU!B27,IE!B27,IT!B27,LT!B27,LU!B27,LV!B27,MT!B27,NL!B27,PL!B27,PT!B27,RO!B27,SE!B27,SI!B27,SK!B27) -> 80250.515 | C27: =SUM(AT!C27,BE!C27,BG!C27,CY!C27,CZ!C27,DE!C27,DK!C27,EE!C27,EL!C27,ES!C27,FI!C27,FR!C27,HR!C27,HU!C27,IE!C27,IT!C27,LT!C27,LU!C27,LV!C27,MT!C27,NL!C27,PL!C27,PT!C27,RO!C27,SE!C27,SI!C27,SK!C27) -> 80190.884 | D27: =SUM(AT!D27,BE!D27,BG!D27,CY!D27,CZ!D27,DE!D27,DK!D27,EE!D27,EL!D27,ES!D27,FI!D27,FR!D27,HR!D27,HU!D27,IE!D27,IT!D27,LT!D27,LU!D27,LV!D27,MT!D27,NL!D27,PL!D27,PT!D27,RO!D27,SE!D27,SI!D27,SK!D27) -> 78120.322 | E27: =SUM(AT!E27,BE!E27,BG!E27,CY!E27,CZ!E27,DE!E27,DK!E27,EE!E27,EL!E27,ES!E27,FI!E27,FR!E27,HR!E27,HU!E27,IE!E27,IT!E27,LT!E27,LU!E27,LV!E27,MT!E27,NL!E27,PL!E27,PT!E27,RO!E27,SE!E27,SI!E27,SK!E27) -> 78745.867 | F27: =SUM(AT!F27,BE!F27,BG!F27,CY!F27,CZ!F27,DE!F27,DK!F27,EE!F27,EL!F27,ES!F27,FI!F27,FR!F27,HR!F27,HU!F27,IE!F27,IT!F27,LT!F27,LU!F27,LV!F27,MT!F27,NL!F27,PL!F27,PT!F27,RO!F27,SE!F27,SI!F27,SK!F27) -> 79261.346 | G27: =SUM(AT!G27,BE!G27,BG!G27,CY!G27,CZ!G27,DE!G27,DK!G27,EE!G27,EL!G27,ES!G27,FI!G27,FR!G27,HR!G27,HU!G27,IE!G27,IT!G27,LT!G27,LU!G27,LV!G27,MT!G27,NL!G27,PL!G27,PT!G27,RO!G27,SE!G27,SI!G27,SK!G27) -> 79270.483 | H27: =SUM(AT!H27,BE!H27,BG!H27,CY!H27,CZ!H27,DE!H27,DK!H27,EE!H27,EL!H27,ES!H27,FI!H27,FR!H27,HR!H27,HU!H27,IE!H27,IT!H27,LT!H27,LU!H27,LV!H27,MT!H27,NL!H27,PL!H27,PT!H27,RO!H27,SE!H27,SI!H27,SK!H27) -> 76349.872 | I27: =SUM(AT!I27,BE!I27,BG!I27,CY!I27,CZ!I27,DE!I27,DK!I27,EE!I27,EL!I27,ES!I27,FI!I27,FR!I27,HR!I27,HU!I27,IE!I27,IT!I27,LT!I27,LU!I27,LV!I27,MT!I27,NL!I27,PL!I27,PT!I27,RO!I27,SE!I27,SI!I27,SK!I27) -> 73323.708 | ... W27: =SUM(AT!W27,BE!W27,BG!W27,CY!W27,CZ!W27,DE!W27,DK!W27,EE!W27,EL!W27,ES!W27,FI!W27,FR!W27,HR!W27,HU!W27,IE!W27,IT!W27,LT!W27,LU!W27,LV!W27,MT!W27,NL!W27,PL!W27,PT!W27,RO!W27,SE!W27,SI!W27,SK!W27) -> 72353.621
A28: 1.A.5 - Other Other Sectors | B28: =SUM(B29:B30) -> 8405.5034 | C28: =SUM(C29:C30) -> 7939.2234 | D28: =SUM(D29:D30) -> 8295.9516 | E28: =SUM(E29:E30) -> 9031.2863 | F28: =SUM(F29:F30) -> 10129.537 | G28: =SUM(G29:G30) -> 10567.726 | H28: =SUM(H29:H30) -> 9491.7448 | I28: =SUM(I29:I30) -> 9426.3602 | ... W28: =SUM(W29:W30) -> 6891.2098
A29: 1.A.5.a - Stationary | B29: =SUM(AT!B29,BE!B29,BG!B29,CY!B29,CZ!B29,DE!B29,DK!B29,EE!B29,EL!B29,ES!B29,FI!B29,FR!B29,HR!B29,HU!B29,IE!B29,IT!B29,LT!B29,LU!B29,LV!B29,MT!B29,NL!B29,PL!B29,PT!B29,RO!B29,SE!B29,SI!B29,SK!B29) -> 4682.2346 | C29: =SUM(AT!C29,BE!C29,BG!C29,CY!C29,CZ!C29,DE!C29,DK!C29,EE!C29,EL!C29,ES!C29,FI!C29,FR!C29,HR!C29,HU!C29,IE!C29,IT!C29,LT!C29,LU!C29,LV!C29,MT!C29,NL!C29,PL!C29,PT!C29,RO!C29,SE!C29,SI!C29,SK!C29) -> 5075.2208 | D29: =SUM(AT!D29,BE!D29,BG!D29,CY!D29,CZ!D29,DE!D29,DK!D29,EE!D29,EL!D29,ES!D29,FI!D29,FR!D29,HR!D29,HU!D29,IE!D29,IT!D29,LT!D29,LU!D29,LV!D29,MT!D29,NL!D29,PL!D29,PT!D29,RO!D29,SE!D29,SI!D29,SK!D29) -> 5387.6167 | E29: =SUM(AT!E29,BE!E29,BG!E29,CY!E29,CZ!E29,DE!E29,DK!E29,EE!E29,EL!E29,ES!E29,FI!E29,FR!E29,HR!E29,HU!E29,IE!E29,IT!E29,LT!E29,LU!E29,LV!E29,MT!E29,NL!E29,PL!E29,PT!E29,RO!E29,SE!E29,SI!E29,SK!E29) -> 5738.6451 | F29: =SUM(AT!F29,BE!F29,BG!F29,CY!F29,CZ!F29,DE!F29,DK!F29,EE!F29,EL!F29,ES!F29,FI!F29,FR!F29,HR!F29,HU!F29,IE!F29,IT!F29,LT!F29,LU!F29,LV!F29,MT!F29,NL!F29,PL!F29,PT!F29,RO!F29,SE!F29,SI!F29,SK!F29) -> 6446.0909 | G29: =SUM(AT!G29,BE!G29,BG!G29,CY!G29,CZ!G29,DE!G29,DK!G29,EE!G29,EL!G29,ES!G29,FI!G29,FR!G29,HR!G29,HU!G29,IE!G29,IT!G29,LT!G29,LU!G29,LV!G29,MT!G29,NL!G29,PL!G29,PT!G29,RO!G29,SE!G29,SI!G29,SK!G29) -> 6159.0709 | H29: =SUM(AT!H29,BE!H29,BG!H29,CY!H29,CZ!H29,DE!H29,DK!H29,EE!H29,EL!H29,ES!H29,FI!H29,FR!H29,HR!H29,HU!H29,IE!H29,IT!H29,LT!H29,LU!H29,LV!H29,MT!H29,NL!H29,PL!H29,PT!H29,RO!H29,SE!H29,SI!H29,SK!H29) -> 5455.8064 | I29: =SUM(AT!I29,BE!I29,BG!I29,CY!I29,CZ!I29,DE!I29,DK!I29,EE!I29,EL!I29,ES!I29,FI!I29,FR!I29,HR!I29,HU!I29,IE!I29,IT!I29,LT!I29,LU!I29,LV!I29,MT!I29,NL!I29,PL!I29,PT!I29,RO!I29,SE!I29,SI!I29,SK!I29) -> 5516.189 | ... W29: =SUM(AT!W29,BE!W29,BG!W29,CY!W29,CZ!W29,DE!W29,DK!W29,EE!W29,EL!W29,ES!W29,FI!W29,FR!W29,HR!W29,HU!W29,IE!W29,IT!W29,LT!W29,LU!W29,LV!W29,MT!W29,NL!W29,PL!W29,PT!W29,RO!W29,SE!W29,SI!W29,SK!W29) -> 4606.3061
A30: 1.A.5.b - Mobile | B30: =SUM(AT!B30,BE!B30,BG!B30,CY!B30,CZ!B30,DE!B30,DK!B30,EE!B30,EL!B30,ES!B30,FI!B30,FR!B30,HR!B30,HU!B30,IE!B30,IT!B30,LT!B30,LU!B30,LV!B30,MT!B30,NL!B30,PL!B30,PT!B30,RO!B30,SE!B30,SI!B30,SK!B30) -> 3723.2689 | C30: =SUM(AT!C30,BE!C30,BG!C30,CY!C30,CZ!C30,DE!C30,DK!C30,EE!C30,EL!C30,ES!C30,FI!C30,FR!C30,HR!C30,HU!C30,IE!C30,IT!C30,LT!C30,LU!C30,LV!C30,MT!C30,NL!C30,PL!C30,PT!C30,RO!C30,SE!C30,SI!C30,SK!C30) -> 2864.0025 | D30: =SUM(AT!D30,BE!D30,BG!D30,CY!D30,CZ!D30,DE!D30,DK!D30,EE!D30,EL!D30,ES!D30,FI!D30,FR!D30,HR!D30,HU!D30,IE!D30,IT!D30,LT!D30,LU!D30,LV!D30,MT!D30,NL!D30,PL!D30,PT!D30,RO!D30,SE!D30,SI!D30,SK!D30) -> 2908.3349 | E30: =SUM(AT!E30,BE!E30,BG!E30,CY!E30,CZ!E30,DE!E30,DK!E30,EE!E30,EL!E30,ES!E30,FI!E30,FR!E30,HR!E30,HU!E30,IE!E30,IT!E30,LT!E30,LU!E30,LV!E30,MT!E30,NL!E30,PL!E30,PT!E30,RO!E30,SE!E30,SI!E30,SK!E30) -> 3292.6411 | F30: =SUM(AT!F30,BE!F30,BG!F30,CY!F30,CZ!F30,DE!F30,DK!F30,EE!F30,EL!F30,ES!F30,FI!F30,FR!F30,HR!F30,HU!F30,IE!F30,IT!F30,LT!F30,LU!F30,LV!F30,MT!F30,NL!F30,PL!F30,PT!F30,RO!F30,SE!F30,SI!F30,SK!F30) -> 3683.4465 | G30: =SUM(AT!G30,BE!G30,BG!G30,CY!G30,CZ!G30,DE!G30,DK!G30,EE!G30,EL!G30,ES!G30,FI!G30,FR!G30,HR!G30,HU!G30,IE!G30,IT!G30,LT!G30,LU!G30,LV!G30,MT!G30,NL!G30,PL!G30,PT!G30,RO!G30,SE!G30,SI!G30,SK!G30) -> 4408.6551 | H30: =SUM(AT!H30,BE!H30,BG!H30,CY!H30,CZ!H30,DE!H30,DK!H30,EE!H30,EL!H30,ES!H30,FI!H30,FR!H30,HR!H30,HU!H30,IE!H30,IT!H30,LT!H30,LU!H30,LV!H30,MT!H30,NL!H30,PL!H30,PT!H30,RO!H30,SE!H30,SI!H30,SK!H30) -> 4035.9384 | I30: =SUM(AT!I30,BE!I30,BG!I30,CY!I30,CZ!I30,DE!I30,DK!I30,EE!I30,EL!I30,ES!I30,FI!I30,FR!I30,HR!I30,HU!I30,IE!I30,IT!I30,LT!I30,LU!I30,LV!I30,MT!I30,NL!I30,PL!I30,PT!I30,RO!I30,SE!I30,SI!I30,SK!I30) -> 3910.1712 | ... W30: =SUM(AT!W30,BE!W30,BG!W30,CY!W30,CZ!W30,DE!W30,DK!W30,EE!W30,EL!W30,ES!W30,FI!W30,FR!W30,HR!W30,HU!W30,IE!W30,IT!W30,LT!W30,LU!W30,LV!W30,MT!W30,NL!W30,PL!W30,PT!W30,RO!W30,SE!W30,SI!W30,SK!W30) -> 2284.9036
A31: 1.B - Fugitive Emissions from Fuels | B31: =SUM(AT!B31,BE!B31,BG!B31,CY!B31,CZ!B31,DE!B31,DK!B31,EE!B31,EL!B31,ES!B31,FI!B31,FR!B31,HR!B31,HU!B31,IE!B31,IT!B31,LT!B31,LU!B31,LV!B31,MT!B31,NL!B31,PL!B31,PT!B31,RO!B31,SE!B31,SI!B31,SK!B31) -> 20812.913 | C31: =SUM(AT!C31,BE!C31,BG!C31,CY!C31,CZ!C31,DE!C31,DK!C31,EE!C31,EL!C31,ES!C31,FI!C31,FR!C31,HR!C31,HU!C31,IE!C31,IT!C31,LT!C31,LU!C31,LV!C31,MT!C31,NL!C31,PL!C31,PT!C31,RO!C31,SE!C31,SI!C31,SK!C31) -> 19681.65 | D31: =SUM(AT!D31,BE!D31,BG!D31,CY!D31,CZ!D31,DE!D31,DK!D31,EE!D31,EL!D31,ES!D31,FI!D31,FR!D31,HR!D31,HU!D31,IE!D31,IT!D31,LT!D31,LU!D31,LV!D31,MT!D31,NL!D31,PL!D31,PT!D31,RO!D31,SE!D31,SI!D31,SK!D31) -> 20340.639 | E31: =SUM(AT!E31,BE!E31,BG!E31,CY!E31,CZ!E31,DE!E31,DK!E31,EE!E31,EL!E31,ES!E31,FI!E31,FR!E31,HR!E31,HU!E31,IE!E31,IT!E31,LT!E31,LU!E31,LV!E31,MT!E31,NL!E31,PL!E31,PT!E31,RO!E31,SE!E31,SI!E31,SK!E31) -> 21342.325 | F31: =SUM(AT!F31,BE!F31,BG!F31,CY!F31,CZ!F31,DE!F31,DK!F31,EE!F31,EL!F31,ES!F31,FI!F31,FR!F31,HR!F31,HU!F31,IE!F31,IT!F31,LT!F31,LU!F31,LV!F31,MT!F31,NL!F31,PL!F31,PT!F31,RO!F31,SE!F31,SI!F31,SK!F31) -> 20085.598 | G31: =SUM(AT!G31,BE!G31,BG!G31,CY!G31,CZ!G31,DE!G31,DK!G31,EE!G31,EL!G31,ES!G31,FI!G31,FR!G31,HR!G31,HU!G31,IE!G31,IT!G31,LT!G31,LU!G31,LV!G31,MT!G31,NL!G31,PL!G31,PT!G31,RO!G31,SE!G31,SI!G31,SK!G31) -> 20934.192 | H31: =SUM(AT!H31,BE!H31,BG!H31,CY!H31,CZ!H31,DE!H31,DK!H31,EE!H31,EL!H31,ES!H31,FI!H31,FR!H31,HR!H31,HU!H31,IE!H31,IT!H31,LT!H31,LU!H31,LV!H31,MT!H31,NL!H31,PL!H31,PT!H31,RO!H31,SE!H31,SI!H31,SK!H31) -> 22878.288 | I31: =SUM(AT!I31,BE!I31,BG!I31,CY!I31,CZ!I31,DE!I31,DK!I31,EE!I31,EL!I31,ES!I31,FI!I31,FR!I31,HR!I31,HU!I31,IE!I31,IT!I31,LT!I31,LU!I31,LV!I31,MT!I31,NL!I31,PL!I31,PT!I31,RO!I31,SE!I31,SI!I31,SK!I31) -> 22672.788 | ... W31: =SUM(AT!W31,BE!W31,BG!W31,CY!W31,CZ!W31,DE!W31,DK!W31,EE!W31,EL!W31,ES!W31,FI!W31,FR!W31,HR!W31,HU!W31,IE!W31,IT!W31,LT!W31,LU!W31,LV!W31,MT!W31,NL!W31,PL!W31,PT!W31,RO!W31,SE!W31,SI!W31,SK!W31) -> 17775.713
A32: 1.C - CO2 Transport and Storage | B32: =SUM(AT!B32,BE!B32,BG!B32,CY!B32,CZ!B32,DE!B32,DK!B32,EE!B32,EL!B32,ES!B32,FI!B32,FR!B32,HR!B32,HU!B32,IE!B32,IT!B32,LT!B32,LU!B32,LV!B32,MT!B32,NL!B32,PL!B32,PT!B32,RO!B32,SE!B32,SI!B32,SK!B32) -> 0 | C32: =SUM(AT!C32,BE!C32,BG!C32,CY!C32,CZ!C32,DE!C32,DK!C32,EE!C32,EL!C32,ES!C32,FI!C32,FR!C32,HR!C32,HU!C32,IE!C32,IT!C32,LT!C32,LU!C32,LV!C32,MT!C32,NL!C32,PL!C32,PT!C32,RO!C32,SE!C32,SI!C32,SK!C32) -> 0 | D32: =SUM(AT!D32,BE!D32,BG!D32,CY!D32,CZ!D32,DE!D32,DK!D32,EE!D32,EL!D32,ES!D32,FI!D32,FR!D32,HR!D32,HU!D32,IE!D32,IT!D32,LT!D32,LU!D32,LV!D32,MT!D32,NL!D32,PL!D32,PT!D32,RO!D32,SE!D32,SI!D32,SK!D32) -> 0 | E32: =SUM(AT!E32,BE!E32,BG!E32,CY!E32,CZ!E32,DE!E32,DK!E32,EE!E32,EL!E32,ES!E32,FI!E32,FR!E32,HR!E32,HU!E32,IE!E32,IT!E32,LT!E32,LU!E32,LV!E32,MT!E32,NL!E32,PL!E32,PT!E32,RO!E32,SE!E32,SI!E32,SK!E32) -> 0 | F32: =SUM(AT!F32,BE!F32,BG!F32,CY!F32,CZ!F32,DE!F32,DK!F32,EE!F32,EL!F32,ES!F32,FI!F32,FR!F32,HR!F32,HU!F32,IE!F32,IT!F32,LT!F32,LU!F32,LV!F32,MT!F32,NL!F32,PL!F32,PT!F32,RO!F32,SE!F32,SI!F32,SK!F32) -> 0 | G32: =SUM(AT!G32,BE!G32,BG!G32,CY!G32,CZ!G32,DE!G32,DK!G32,EE!G32,EL!G32,ES!G32,FI!G32,FR!G32,HR!G32,HU!G32,IE!G32,IT!G32,LT!G32,LU!G32,LV!G32,MT!G32,NL!G32,PL!G32,PT!G32,RO!G32,SE!G32,SI!G32,SK!G32) -> 0 | H32: =SUM(AT!H32,BE!H32,BG!H32,CY!H32,CZ!H32,DE!H32,DK!H32,EE!H32,EL!H32,ES!H32,FI!H32,FR!H32,HR!H32,HU!H32,IE!H32,IT!H32,LT!H32,LU!H32,LV!H32,MT!H32,NL!H32,PL!H32,PT!H32,RO!H32,SE!H32,SI!H32,SK!H32) -> 0 | I32: =SUM(AT!I32,BE!I32,BG!I32,CY!I32,CZ!I32,DE!I32,DK!I32,EE!I32,EL!I32,ES!I32,FI!I32,FR!I32,HR!I32,HU!I32,IE!I32,IT!I32,LT!I32,LU!I32,LV!I32,MT!I32,NL!I32,PL!I32,PT!I32,RO!I32,SE!I32,SI!I32,SK!I32) -> 0 | ... W32: =SUM(AT!W32,BE!W32,BG!W32,CY!W32,CZ!W32,DE!W32,DK!W32,EE!W32,EL!W32,ES!W32,FI!W32,FR!W32,HR!W32,HU!W32,IE!W32,IT!W32,LT!W32,LU!W32,LV!W32,MT!W32,NL!W32,PL!W32,PT!W32,RO!W32,SE!W32,SI!W32,SK!W32) -> 0
A33: 2 - Industrial Processes and Product Use | B33: =SUM(B34:B41) -> 288856.49 | C33: =SUM(C34:C41) -> 278331.55 | D33: =SUM(D34:D41) -> 278793.2 | E33: =SUM(E34:E41) -> 286703.83 | F33: =SUM(F34:F41) -> 298554.22 | G33: =SUM(G34:G41) -> 296115.53 | H33: =SUM(H34:H41) -> 301929.86 | I33: =SUM(I34:I41) -> 305647.34 | ... W33: =SUM(W34:W41) -> 231737.37
